/datasets/pentschev/miniconda3/envs/gdf/lib/python3.8/site-packages/distributed/node.py:182: UserWarning: Port 8787 is already in use.
Perhaps you already have a cluster running?
Hosting the HTTP server on port 42065 instead
  warnings.warn(
2023-03-27 22:47:49,484 - distributed.preloading - INFO - Creating preload: dask_cuda.initialize
2023-03-27 22:47:49,484 - distributed.preloading - INFO - Import preload module: dask_cuda.initialize
2023-03-27 22:47:49,526 - distributed.preloading - INFO - Creating preload: dask_cuda.initialize
2023-03-27 22:47:49,526 - distributed.preloading - INFO - Import preload module: dask_cuda.initialize
2023-03-27 22:47:49,526 - distributed.preloading - INFO - Creating preload: dask_cuda.initialize
2023-03-27 22:47:49,526 - distributed.preloading - INFO - Import preload module: dask_cuda.initialize
2023-03-27 22:47:49,528 - distributed.preloading - INFO - Creating preload: dask_cuda.initialize
2023-03-27 22:47:49,528 - distributed.preloading - INFO - Import preload module: dask_cuda.initialize
2023-03-27 22:47:49,531 - distributed.preloading - INFO - Creating preload: dask_cuda.initialize
2023-03-27 22:47:49,532 - distributed.preloading - INFO - Import preload module: dask_cuda.initialize
2023-03-27 22:47:49,533 - distributed.preloading - INFO - Creating preload: dask_cuda.initialize
2023-03-27 22:47:49,533 - distributed.preloading - INFO - Import preload module: dask_cuda.initialize
2023-03-27 22:47:49,535 - distributed.preloading - INFO - Creating preload: dask_cuda.initialize
2023-03-27 22:47:49,535 - distributed.preloading - INFO - Import preload module: dask_cuda.initialize
2023-03-27 22:47:49,568 - distributed.preloading - INFO - Creating preload: dask_cuda.initialize
2023-03-27 22:47:49,568 - distributed.preloading - INFO - Import preload module: dask_cuda.initialize
[dgx13:13122:0:13122] Caught signal 11 (Segmentation fault: address not mapped to object at address 0x448)
==== backtrace (tid:  13122) ====
 0  /datasets/pentschev/miniconda3/envs/gdf/lib/libucs.so.0(ucs_handle_error+0x2d4) [0x7f5e9d9286b4]
 1  /datasets/pentschev/miniconda3/envs/gdf/lib/libucs.so.0(+0x2d88f) [0x7f5e9d92888f]
 2  /datasets/pentschev/miniconda3/envs/gdf/lib/libucs.so.0(+0x2dbb4) [0x7f5e9d928bb4]
 3  /lib/x86_64-linux-gnu/libpthread.so.0(+0x12980) [0x7f5f1338e980]
 4  /datasets/pentschev/miniconda3/envs/gdf/lib/libucp.so.0(ucp_mem_type_unpack+0x17) [0x7f5e9dba41b7]
 5  /datasets/pentschev/miniconda3/envs/gdf/lib/libucp.so.0(ucp_rndv_data_handler+0x508) [0x7f5e9dbcd638]
 6  /datasets/pentschev/miniconda3/envs/gdf/lib/libuct.so.0(+0x1f0ff) [0x7f5e9d6e00ff]
 7  /datasets/pentschev/miniconda3/envs/gdf/lib/libuct.so.0(+0x1f674) [0x7f5e9d6e0674]
 8  /datasets/pentschev/miniconda3/envs/gdf/lib/libuct.so.0(+0x21a78) [0x7f5e9d6e2a78]
 9  /datasets/pentschev/miniconda3/envs/gdf/lib/libucs.so.0(ucs_event_set_wait+0xb9) [0x7f5e9d9328a9]
10  /datasets/pentschev/miniconda3/envs/gdf/lib/libuct.so.0(uct_tcp_iface_progress+0x7b) [0x7f5e9d6e2b1b]
11  /datasets/pentschev/miniconda3/envs/gdf/lib/libucp.so.0(ucp_worker_progress+0x6a) [0x7f5e9dba0f5a]
12  /datasets/pentschev/miniconda3/envs/gdf/lib/python3.8/site-packages/ucp/_libs/ucx_api.cpython-38-x86_64-linux-gnu.so(+0x272b9) [0x7f5e9de4d2b9]
13  /datasets/pentschev/miniconda3/envs/gdf/bin/python(+0x12e343) [0x5570ca109343]
14  /datasets/pentschev/miniconda3/envs/gdf/bin/python(PyObject_Call+0x24a) [0x5570ca1141fa]
15  /datasets/pentschev/miniconda3/envs/gdf/bin/python(_PyEval_EvalFrameDefault+0x680b) [0x5570ca0fab8b]
16  /datasets/pentschev/miniconda3/envs/gdf/bin/python(_PyEval_EvalCodeWithName+0x2f1) [0x5570ca0f32f1]
17  /datasets/pentschev/miniconda3/envs/gdf/bin/python(_PyFunction_Vectorcall+0x19c) [0x5570ca10493c]
18  /datasets/pentschev/miniconda3/envs/gdf/bin/python(_PyEval_EvalFrameDefault+0x6d5) [0x5570ca0f4a55]
19  /datasets/pentschev/miniconda3/envs/gdf/bin/python(_PyFunction_Vectorcall+0x106) [0x5570ca1048a6]
20  /datasets/pentschev/miniconda3/envs/gdf/bin/python(+0x136c36) [0x5570ca111c36]
21  /datasets/pentschev/miniconda3/envs/gdf/bin/python(+0x23565a) [0x5570ca21065a]
22  /datasets/pentschev/miniconda3/envs/gdf/bin/python(+0xe0b07) [0x5570ca0bbb07]
23  /datasets/pentschev/miniconda3/envs/gdf/bin/python(+0x120f96) [0x5570ca0fbf96]
24  /datasets/pentschev/miniconda3/envs/gdf/bin/python(PyVectorcall_Call+0x7a) [0x5570ca1121ea]
25  /datasets/pentschev/miniconda3/envs/gdf/bin/python(_PyEval_EvalFrameDefault+0x5df8) [0x5570ca0fa178]
26  /datasets/pentschev/miniconda3/envs/gdf/bin/python(_PyFunction_Vectorcall+0x106) [0x5570ca1048a6]
27  /datasets/pentschev/miniconda3/envs/gdf/bin/python(_PyEval_EvalFrameDefault+0x6d5) [0x5570ca0f4a55]
28  /datasets/pentschev/miniconda3/envs/gdf/bin/python(_PyFunction_Vectorcall+0x106) [0x5570ca1048a6]
29  /datasets/pentschev/miniconda3/envs/gdf/bin/python(_PyEval_EvalFrameDefault+0x6d5) [0x5570ca0f4a55]
30  /datasets/pentschev/miniconda3/envs/gdf/bin/python(_PyFunction_Vectorcall+0x106) [0x5570ca1048a6]
31  /datasets/pentschev/miniconda3/envs/gdf/bin/python(_PyEval_EvalFrameDefault+0x6d5) [0x5570ca0f4a55]
32  /datasets/pentschev/miniconda3/envs/gdf/bin/python(_PyFunction_Vectorcall+0x106) [0x5570ca1048a6]
33  /datasets/pentschev/miniconda3/envs/gdf/bin/python(_PyEval_EvalFrameDefault+0x6d5) [0x5570ca0f4a55]
34  /datasets/pentschev/miniconda3/envs/gdf/bin/python(_PyEval_EvalCodeWithName+0x2f1) [0x5570ca0f32f1]
35  /datasets/pentschev/miniconda3/envs/gdf/bin/python(_PyFunction_Vectorcall+0x19c) [0x5570ca10493c]
36  /datasets/pentschev/miniconda3/envs/gdf/bin/python(_PyEval_EvalFrameDefault+0x4b7b) [0x5570ca0f8efb]
37  /datasets/pentschev/miniconda3/envs/gdf/bin/python(_PyEval_EvalCodeWithName+0x2f1) [0x5570ca0f32f1]
38  /datasets/pentschev/miniconda3/envs/gdf/bin/python(_PyFunction_Vectorcall+0x19c) [0x5570ca10493c]
39  /datasets/pentschev/miniconda3/envs/gdf/bin/python(+0x136e8c) [0x5570ca111e8c]
40  /datasets/pentschev/miniconda3/envs/gdf/bin/python(_PyObject_FastCallDict+0x282) [0x5570ca0fca92]
41  /datasets/pentschev/miniconda3/envs/gdf/bin/python(+0x1ee049) [0x5570ca1c9049]
42  /datasets/pentschev/miniconda3/envs/gdf/bin/python(PyObject_Call+0x2d3) [0x5570ca114283]
43  /datasets/pentschev/miniconda3/envs/gdf/bin/python(_PyEval_EvalFrameDefault+0x205e) [0x5570ca0f63de]
44  /datasets/pentschev/miniconda3/envs/gdf/bin/python(_PyFunction_Vectorcall+0x106) [0x5570ca1048a6]
45  /datasets/pentschev/miniconda3/envs/gdf/bin/python(+0x136e8c) [0x5570ca111e8c]
46  /datasets/pentschev/miniconda3/envs/gdf/bin/python(PyObject_Call+0x24a) [0x5570ca1141fa]
47  /datasets/pentschev/miniconda3/envs/gdf/bin/python(_PyEval_EvalFrameDefault+0x205e) [0x5570ca0f63de]
48  /datasets/pentschev/miniconda3/envs/gdf/bin/python(_PyFunction_Vectorcall+0x106) [0x5570ca1048a6]
49  /datasets/pentschev/miniconda3/envs/gdf/bin/python(_PyEval_EvalFrameDefault+0x6d5) [0x5570ca0f4a55]
50  /datasets/pentschev/miniconda3/envs/gdf/bin/python(_PyEval_EvalCodeWithName+0x2f1) [0x5570ca0f32f1]
51  /datasets/pentschev/miniconda3/envs/gdf/bin/python(_PyFunction_Vectorcall+0x19c) [0x5570ca10493c]
52  /datasets/pentschev/miniconda3/envs/gdf/bin/python(_PyEval_EvalFrameDefault+0x6d5) [0x5570ca0f4a55]
53  /datasets/pentschev/miniconda3/envs/gdf/bin/python(_PyFunction_Vectorcall+0x106) [0x5570ca1048a6]
54  /datasets/pentschev/miniconda3/envs/gdf/bin/python(_PyEval_EvalFrameDefault+0x3a9) [0x5570ca0f4729]
55  /datasets/pentschev/miniconda3/envs/gdf/bin/python(_PyEval_EvalCodeWithName+0x2f1) [0x5570ca0f32f1]
56  /datasets/pentschev/miniconda3/envs/gdf/bin/python(_PyFunction_Vectorcall+0x19c) [0x5570ca10493c]
57  /datasets/pentschev/miniconda3/envs/gdf/bin/python(_PyEval_EvalFrameDefault+0x11bf) [0x5570ca0f553f]
58  /datasets/pentschev/miniconda3/envs/gdf/bin/python(_PyEval_EvalCodeWithName+0x2f1) [0x5570ca0f32f1]
59  /datasets/pentschev/miniconda3/envs/gdf/bin/python(PyEval_EvalCodeEx+0x39) [0x5570ca1a5e99]
60  /datasets/pentschev/miniconda3/envs/gdf/bin/python(PyEval_EvalCode+0x1b) [0x5570ca1a5e5b]
61  /datasets/pentschev/miniconda3/envs/gdf/bin/python(+0x1eb7f9) [0x5570ca1c67f9]
=================================
2023-03-27 22:47:58,336 - distributed.worker - ERROR - failed during get data with ucx://127.0.0.1:38491 -> ucx://127.0.0.1:47667
Traceback (most recent call last):
  File "/datasets/pentschev/miniconda3/envs/gdf/lib/python3.8/site-packages/distributed/comm/ucx.py", line 333, in write
    await self.ep.send(each_frame)
  File "/datasets/pentschev/miniconda3/envs/gdf/lib/python3.8/site-packages/ucp/core.py", line 650, in send
    return await comm.tag_send(self._ep, buffer, nbytes, tag, name=log)
ucp._libs.exceptions.UCXError: <[Send #007] ep: 0x7fd090102100, tag: 0x509288f6308dc5c4, nbytes: 800000000, type: <class 'cudf.core.buffer.buffer.Buffer'>>: Endpoint timeout

During handling of the above exception, another exception occurred:

Traceback (most recent call last):
  File "/datasets/pentschev/miniconda3/envs/gdf/lib/python3.8/site-packages/distributed/worker.py", line 1792, in get_data
    compressed = await comm.write(msg, serializers=serializers)
  File "/datasets/pentschev/miniconda3/envs/gdf/lib/python3.8/site-packages/distributed/utils.py", line 752, in wrapper
    return await func(*args, **kwargs)
  File "/datasets/pentschev/miniconda3/envs/gdf/lib/python3.8/site-packages/distributed/comm/ucx.py", line 337, in write
    raise CommClosedError("While writing, the connection was closed")
distributed.comm.core.CommClosedError: While writing, the connection was closed
2023-03-27 22:47:58,470 - distributed.nanny - WARNING - Restarting worker
[dgx13:13120:0:13120] Caught signal 11 (Segmentation fault: address not mapped to object at address 0x448)
==== backtrace (tid:  13120) ====
 0  /datasets/pentschev/miniconda3/envs/gdf/lib/libucs.so.0(ucs_handle_error+0x2d4) [0x7fe589c0d6b4]
 1  /datasets/pentschev/miniconda3/envs/gdf/lib/libucs.so.0(+0x2d88f) [0x7fe589c0d88f]
 2  /datasets/pentschev/miniconda3/envs/gdf/lib/libucs.so.0(+0x2dbb4) [0x7fe589c0dbb4]
 3  /lib/x86_64-linux-gnu/libpthread.so.0(+0x12980) [0x7fe5ff677980]
 4  /datasets/pentschev/miniconda3/envs/gdf/lib/libucp.so.0(ucp_mem_type_unpack+0x17) [0x7fe589e891b7]
 5  /datasets/pentschev/miniconda3/envs/gdf/lib/libucp.so.0(ucp_rndv_data_handler+0x508) [0x7fe589eb2638]
 6  /datasets/pentschev/miniconda3/envs/gdf/lib/libuct.so.0(+0x1f0ff) [0x7fe5899c50ff]
 7  /datasets/pentschev/miniconda3/envs/gdf/lib/libuct.so.0(+0x1f674) [0x7fe5899c5674]
 8  /datasets/pentschev/miniconda3/envs/gdf/lib/libuct.so.0(+0x21a78) [0x7fe5899c7a78]
 9  /datasets/pentschev/miniconda3/envs/gdf/lib/libucs.so.0(ucs_event_set_wait+0xb9) [0x7fe589c178a9]
10  /datasets/pentschev/miniconda3/envs/gdf/lib/libuct.so.0(uct_tcp_iface_progress+0x7b) [0x7fe5899c7b1b]
11  /datasets/pentschev/miniconda3/envs/gdf/lib/libucp.so.0(ucp_worker_progress+0x6a) [0x7fe589e85f5a]
12  /datasets/pentschev/miniconda3/envs/gdf/lib/python3.8/site-packages/ucp/_libs/ucx_api.cpython-38-x86_64-linux-gnu.so(+0x272b9) [0x7fe58a1322b9]
13  /datasets/pentschev/miniconda3/envs/gdf/bin/python(+0x12e343) [0x559d89ae1343]
14  /datasets/pentschev/miniconda3/envs/gdf/bin/python(PyObject_Call+0x24a) [0x559d89aec1fa]
15  /datasets/pentschev/miniconda3/envs/gdf/bin/python(_PyEval_EvalFrameDefault+0x680b) [0x559d89ad2b8b]
16  /datasets/pentschev/miniconda3/envs/gdf/bin/python(_PyEval_EvalCodeWithName+0x2f1) [0x559d89acb2f1]
17  /datasets/pentschev/miniconda3/envs/gdf/bin/python(_PyFunction_Vectorcall+0x19c) [0x559d89adc93c]
18  /datasets/pentschev/miniconda3/envs/gdf/bin/python(_PyEval_EvalFrameDefault+0x6d5) [0x559d89acca55]
19  /datasets/pentschev/miniconda3/envs/gdf/bin/python(_PyFunction_Vectorcall+0x106) [0x559d89adc8a6]
20  /datasets/pentschev/miniconda3/envs/gdf/bin/python(+0x136c36) [0x559d89ae9c36]
21  /datasets/pentschev/miniconda3/envs/gdf/bin/python(+0x23565a) [0x559d89be865a]
22  /datasets/pentschev/miniconda3/envs/gdf/bin/python(+0xe0b07) [0x559d89a93b07]
23  /datasets/pentschev/miniconda3/envs/gdf/bin/python(+0x120f96) [0x559d89ad3f96]
24  /datasets/pentschev/miniconda3/envs/gdf/bin/python(PyVectorcall_Call+0x7a) [0x559d89aea1ea]
25  /datasets/pentschev/miniconda3/envs/gdf/bin/python(_PyEval_EvalFrameDefault+0x5df8) [0x559d89ad2178]
26  /datasets/pentschev/miniconda3/envs/gdf/bin/python(_PyFunction_Vectorcall+0x106) [0x559d89adc8a6]
27  /datasets/pentschev/miniconda3/envs/gdf/bin/python(_PyEval_EvalFrameDefault+0x6d5) [0x559d89acca55]
28  /datasets/pentschev/miniconda3/envs/gdf/bin/python(_PyFunction_Vectorcall+0x106) [0x559d89adc8a6]
29  /datasets/pentschev/miniconda3/envs/gdf/bin/python(_PyEval_EvalFrameDefault+0x6d5) [0x559d89acca55]
30  /datasets/pentschev/miniconda3/envs/gdf/bin/python(_PyFunction_Vectorcall+0x106) [0x559d89adc8a6]
31  /datasets/pentschev/miniconda3/envs/gdf/bin/python(_PyEval_EvalFrameDefault+0x6d5) [0x559d89acca55]
32  /datasets/pentschev/miniconda3/envs/gdf/bin/python(_PyFunction_Vectorcall+0x106) [0x559d89adc8a6]
33  /datasets/pentschev/miniconda3/envs/gdf/bin/python(_PyEval_EvalFrameDefault+0x6d5) [0x559d89acca55]
34  /datasets/pentschev/miniconda3/envs/gdf/bin/python(_PyEval_EvalCodeWithName+0x2f1) [0x559d89acb2f1]
35  /datasets/pentschev/miniconda3/envs/gdf/bin/python(_PyFunction_Vectorcall+0x19c) [0x559d89adc93c]
36  /datasets/pentschev/miniconda3/envs/gdf/bin/python(_PyEval_EvalFrameDefault+0x4b7b) [0x559d89ad0efb]
37  /datasets/pentschev/miniconda3/envs/gdf/bin/python(_PyEval_EvalCodeWithName+0x2f1) [0x559d89acb2f1]
38  /datasets/pentschev/miniconda3/envs/gdf/bin/python(_PyFunction_Vectorcall+0x19c) [0x559d89adc93c]
39  /datasets/pentschev/miniconda3/envs/gdf/bin/python(+0x136e8c) [0x559d89ae9e8c]
40  /datasets/pentschev/miniconda3/envs/gdf/bin/python(_PyObject_FastCallDict+0x282) [0x559d89ad4a92]
41  /datasets/pentschev/miniconda3/envs/gdf/bin/python(+0x1ee049) [0x559d89ba1049]
42  /datasets/pentschev/miniconda3/envs/gdf/bin/python(PyObject_Call+0x2d3) [0x559d89aec283]
43  /datasets/pentschev/miniconda3/envs/gdf/bin/python(_PyEval_EvalFrameDefault+0x205e) [0x559d89ace3de]
44  /datasets/pentschev/miniconda3/envs/gdf/bin/python(_PyFunction_Vectorcall+0x106) [0x559d89adc8a6]
45  /datasets/pentschev/miniconda3/envs/gdf/bin/python(+0x136e8c) [0x559d89ae9e8c]
46  /datasets/pentschev/miniconda3/envs/gdf/bin/python(PyObject_Call+0x24a) [0x559d89aec1fa]
47  /datasets/pentschev/miniconda3/envs/gdf/bin/python(_PyEval_EvalFrameDefault+0x205e) [0x559d89ace3de]
48  /datasets/pentschev/miniconda3/envs/gdf/bin/python(_PyFunction_Vectorcall+0x106) [0x559d89adc8a6]
49  /datasets/pentschev/miniconda3/envs/gdf/bin/python(_PyEval_EvalFrameDefault+0x6d5) [0x559d89acca55]
50  /datasets/pentschev/miniconda3/envs/gdf/bin/python(_PyEval_EvalCodeWithName+0x2f1) [0x559d89acb2f1]
51  /datasets/pentschev/miniconda3/envs/gdf/bin/python(_PyFunction_Vectorcall+0x19c) [0x559d89adc93c]
52  /datasets/pentschev/miniconda3/envs/gdf/bin/python(_PyEval_EvalFrameDefault+0x6d5) [0x559d89acca55]
53  /datasets/pentschev/miniconda3/envs/gdf/bin/python(_PyFunction_Vectorcall+0x106) [0x559d89adc8a6]
54  /datasets/pentschev/miniconda3/envs/gdf/bin/python(_PyEval_EvalFrameDefault+0x3a9) [0x559d89acc729]
55  /datasets/pentschev/miniconda3/envs/gdf/bin/python(_PyEval_EvalCodeWithName+0x2f1) [0x559d89acb2f1]
56  /datasets/pentschev/miniconda3/envs/gdf/bin/python(_PyFunction_Vectorcall+0x19c) [0x559d89adc93c]
57  /datasets/pentschev/miniconda3/envs/gdf/bin/python(_PyEval_EvalFrameDefault+0x11bf) [0x559d89acd53f]
58  /datasets/pentschev/miniconda3/envs/gdf/bin/python(_PyEval_EvalCodeWithName+0x2f1) [0x559d89acb2f1]
59  /datasets/pentschev/miniconda3/envs/gdf/bin/python(PyEval_EvalCodeEx+0x39) [0x559d89b7de99]
60  /datasets/pentschev/miniconda3/envs/gdf/bin/python(PyEval_EvalCode+0x1b) [0x559d89b7de5b]
61  /datasets/pentschev/miniconda3/envs/gdf/bin/python(+0x1eb7f9) [0x559d89b9e7f9]
=================================
2023-03-27 22:47:58,697 - distributed.worker - ERROR - failed during get data with ucx://127.0.0.1:38491 -> ucx://127.0.0.1:57949
Traceback (most recent call last):
  File "/datasets/pentschev/miniconda3/envs/gdf/lib/python3.8/site-packages/distributed/comm/ucx.py", line 333, in write
    await self.ep.send(each_frame)
  File "/datasets/pentschev/miniconda3/envs/gdf/lib/python3.8/site-packages/ucp/core.py", line 650, in send
    return await comm.tag_send(self._ep, buffer, nbytes, tag, name=log)
ucp._libs.exceptions.UCXError: <[Send #007] ep: 0x7fd090102100, tag: 0x16c480a10f19cc6b, nbytes: 800000000, type: <class 'cudf.core.buffer.buffer.Buffer'>>: Endpoint timeout

During handling of the above exception, another exception occurred:

Traceback (most recent call last):
  File "/datasets/pentschev/miniconda3/envs/gdf/lib/python3.8/site-packages/distributed/worker.py", line 1792, in get_data
    compressed = await comm.write(msg, serializers=serializers)
  File "/datasets/pentschev/miniconda3/envs/gdf/lib/python3.8/site-packages/distributed/utils.py", line 752, in wrapper
    return await func(*args, **kwargs)
  File "/datasets/pentschev/miniconda3/envs/gdf/lib/python3.8/site-packages/distributed/comm/ucx.py", line 337, in write
    raise CommClosedError("While writing, the connection was closed")
distributed.comm.core.CommClosedError: While writing, the connection was closed
2023-03-27 22:47:58,789 - distributed.nanny - WARNING - Restarting worker
[dgx13:13111:0:13111] Caught signal 11 (Segmentation fault: address not mapped to object at address 0x448)
==== backtrace (tid:  13111) ====
 0  /datasets/pentschev/miniconda3/envs/gdf/lib/libucs.so.0(ucs_handle_error+0x2d4) [0x7fe1bd6226b4]
 1  /datasets/pentschev/miniconda3/envs/gdf/lib/libucs.so.0(+0x2d88f) [0x7fe1bd62288f]
 2  /datasets/pentschev/miniconda3/envs/gdf/lib/libucs.so.0(+0x2dbb4) [0x7fe1bd622bb4]
 3  /lib/x86_64-linux-gnu/libpthread.so.0(+0x12980) [0x7fe2330be980]
 4  /datasets/pentschev/miniconda3/envs/gdf/lib/libucp.so.0(ucp_mem_type_unpack+0x17) [0x7fe1bd89e1b7]
 5  /datasets/pentschev/miniconda3/envs/gdf/lib/libucp.so.0(ucp_rndv_data_handler+0x508) [0x7fe1bd8c7638]
 6  /datasets/pentschev/miniconda3/envs/gdf/lib/libuct.so.0(+0x1f0ff) [0x7fe1bd3da0ff]
 7  /datasets/pentschev/miniconda3/envs/gdf/lib/libuct.so.0(+0x1f674) [0x7fe1bd3da674]
 8  /datasets/pentschev/miniconda3/envs/gdf/lib/libuct.so.0(+0x21a78) [0x7fe1bd3dca78]
 9  /datasets/pentschev/miniconda3/envs/gdf/lib/libucs.so.0(ucs_event_set_wait+0xb9) [0x7fe1bd62c8a9]
10  /datasets/pentschev/miniconda3/envs/gdf/lib/libuct.so.0(uct_tcp_iface_progress+0x7b) [0x7fe1bd3dcb1b]
11  /datasets/pentschev/miniconda3/envs/gdf/lib/libucp.so.0(ucp_worker_progress+0x6a) [0x7fe1bd89af5a]
12  /datasets/pentschev/miniconda3/envs/gdf/lib/python3.8/site-packages/ucp/_libs/ucx_api.cpython-38-x86_64-linux-gnu.so(+0x272b9) [0x7fe1bdb472b9]
13  /datasets/pentschev/miniconda3/envs/gdf/bin/python(+0x12e343) [0x55fd14694343]
14  /datasets/pentschev/miniconda3/envs/gdf/bin/python(PyObject_Call+0x24a) [0x55fd1469f1fa]
15  /datasets/pentschev/miniconda3/envs/gdf/bin/python(_PyEval_EvalFrameDefault+0x680b) [0x55fd14685b8b]
16  /datasets/pentschev/miniconda3/envs/gdf/bin/python(_PyEval_EvalCodeWithName+0x2f1) [0x55fd1467e2f1]
17  /datasets/pentschev/miniconda3/envs/gdf/bin/python(_PyFunction_Vectorcall+0x19c) [0x55fd1468f93c]
18  /datasets/pentschev/miniconda3/envs/gdf/bin/python(_PyEval_EvalFrameDefault+0x6d5) [0x55fd1467fa55]
19  /datasets/pentschev/miniconda3/envs/gdf/bin/python(_PyFunction_Vectorcall+0x106) [0x55fd1468f8a6]
20  /datasets/pentschev/miniconda3/envs/gdf/bin/python(+0x136c36) [0x55fd1469cc36]
21  /datasets/pentschev/miniconda3/envs/gdf/bin/python(+0x23565a) [0x55fd1479b65a]
22  /datasets/pentschev/miniconda3/envs/gdf/bin/python(+0xe0b07) [0x55fd14646b07]
23  /datasets/pentschev/miniconda3/envs/gdf/bin/python(+0x120f96) [0x55fd14686f96]
24  /datasets/pentschev/miniconda3/envs/gdf/bin/python(PyVectorcall_Call+0x7a) [0x55fd1469d1ea]
25  /datasets/pentschev/miniconda3/envs/gdf/bin/python(_PyEval_EvalFrameDefault+0x5df8) [0x55fd14685178]
26  /datasets/pentschev/miniconda3/envs/gdf/bin/python(_PyFunction_Vectorcall+0x106) [0x55fd1468f8a6]
27  /datasets/pentschev/miniconda3/envs/gdf/bin/python(_PyEval_EvalFrameDefault+0x6d5) [0x55fd1467fa55]
28  /datasets/pentschev/miniconda3/envs/gdf/bin/python(_PyFunction_Vectorcall+0x106) [0x55fd1468f8a6]
29  /datasets/pentschev/miniconda3/envs/gdf/bin/python(_PyEval_EvalFrameDefault+0x6d5) [0x55fd1467fa55]
30  /datasets/pentschev/miniconda3/envs/gdf/bin/python(_PyFunction_Vectorcall+0x106) [0x55fd1468f8a6]
31  /datasets/pentschev/miniconda3/envs/gdf/bin/python(_PyEval_EvalFrameDefault+0x6d5) [0x55fd1467fa55]
32  /datasets/pentschev/miniconda3/envs/gdf/bin/python(_PyFunction_Vectorcall+0x106) [0x55fd1468f8a6]
33  /datasets/pentschev/miniconda3/envs/gdf/bin/python(_PyEval_EvalFrameDefault+0x6d5) [0x55fd1467fa55]
34  /datasets/pentschev/miniconda3/envs/gdf/bin/python(_PyEval_EvalCodeWithName+0x2f1) [0x55fd1467e2f1]
35  /datasets/pentschev/miniconda3/envs/gdf/bin/python(_PyFunction_Vectorcall+0x19c) [0x55fd1468f93c]
36  /datasets/pentschev/miniconda3/envs/gdf/bin/python(_PyEval_EvalFrameDefault+0x4b7b) [0x55fd14683efb]
37  /datasets/pentschev/miniconda3/envs/gdf/bin/python(_PyEval_EvalCodeWithName+0x2f1) [0x55fd1467e2f1]
38  /datasets/pentschev/miniconda3/envs/gdf/bin/python(_PyFunction_Vectorcall+0x19c) [0x55fd1468f93c]
39  /datasets/pentschev/miniconda3/envs/gdf/bin/python(+0x136e8c) [0x55fd1469ce8c]
40  /datasets/pentschev/miniconda3/envs/gdf/bin/python(_PyObject_FastCallDict+0x282) [0x55fd14687a92]
41  /datasets/pentschev/miniconda3/envs/gdf/bin/python(+0x1ee049) [0x55fd14754049]
42  /datasets/pentschev/miniconda3/envs/gdf/bin/python(PyObject_Call+0x2d3) [0x55fd1469f283]
43  /datasets/pentschev/miniconda3/envs/gdf/bin/python(_PyEval_EvalFrameDefault+0x205e) [0x55fd146813de]
44  /datasets/pentschev/miniconda3/envs/gdf/bin/python(_PyFunction_Vectorcall+0x106) [0x55fd1468f8a6]
45  /datasets/pentschev/miniconda3/envs/gdf/bin/python(+0x136e8c) [0x55fd1469ce8c]
46  /datasets/pentschev/miniconda3/envs/gdf/bin/python(PyObject_Call+0x24a) [0x55fd1469f1fa]
47  /datasets/pentschev/miniconda3/envs/gdf/bin/python(_PyEval_EvalFrameDefault+0x205e) [0x55fd146813de]
48  /datasets/pentschev/miniconda3/envs/gdf/bin/python(_PyFunction_Vectorcall+0x106) [0x55fd1468f8a6]
49  /datasets/pentschev/miniconda3/envs/gdf/bin/python(_PyEval_EvalFrameDefault+0x6d5) [0x55fd1467fa55]
50  /datasets/pentschev/miniconda3/envs/gdf/bin/python(_PyEval_EvalCodeWithName+0x2f1) [0x55fd1467e2f1]
51  /datasets/pentschev/miniconda3/envs/gdf/bin/python(_PyFunction_Vectorcall+0x19c) [0x55fd1468f93c]
52  /datasets/pentschev/miniconda3/envs/gdf/bin/python(_PyEval_EvalFrameDefault+0x6d5) [0x55fd1467fa55]
53  /datasets/pentschev/miniconda3/envs/gdf/bin/python(_PyFunction_Vectorcall+0x106) [0x55fd1468f8a6]
54  /datasets/pentschev/miniconda3/envs/gdf/bin/python(_PyEval_EvalFrameDefault+0x3a9) [0x55fd1467f729]
55  /datasets/pentschev/miniconda3/envs/gdf/bin/python(_PyEval_EvalCodeWithName+0x2f1) [0x55fd1467e2f1]
56  /datasets/pentschev/miniconda3/envs/gdf/bin/python(_PyFunction_Vectorcall+0x19c) [0x55fd1468f93c]
57  /datasets/pentschev/miniconda3/envs/gdf/bin/python(_PyEval_EvalFrameDefault+0x11bf) [0x55fd1468053f]
58  /datasets/pentschev/miniconda3/envs/gdf/bin/python(_PyEval_EvalCodeWithName+0x2f1) [0x55fd1467e2f1]
59  /datasets/pentschev/miniconda3/envs/gdf/bin/python(PyEval_EvalCodeEx+0x39) [0x55fd14730e99]
60  /datasets/pentschev/miniconda3/envs/gdf/bin/python(PyEval_EvalCode+0x1b) [0x55fd14730e5b]
61  /datasets/pentschev/miniconda3/envs/gdf/bin/python(+0x1eb7f9) [0x55fd147517f9]
=================================
[dgx13:13116:0:13116] Caught signal 11 (Segmentation fault: address not mapped to object at address 0x448)
==== backtrace (tid:  13116) ====
 0  /datasets/pentschev/miniconda3/envs/gdf/lib/libucs.so.0(ucs_handle_error+0x2d4) [0x7f1a28e256b4]
 1  /datasets/pentschev/miniconda3/envs/gdf/lib/libucs.so.0(+0x2d88f) [0x7f1a28e2588f]
 2  /datasets/pentschev/miniconda3/envs/gdf/lib/libucs.so.0(+0x2dbb4) [0x7f1a28e25bb4]
 3  /lib/x86_64-linux-gnu/libpthread.so.0(+0x12980) [0x7f1aaca29980]
 4  /datasets/pentschev/miniconda3/envs/gdf/lib/libucp.so.0(ucp_mem_type_unpack+0x17) [0x7f1a290a11b7]
 5  /datasets/pentschev/miniconda3/envs/gdf/lib/libucp.so.0(ucp_rndv_data_handler+0x508) [0x7f1a290ca638]
 6  /datasets/pentschev/miniconda3/envs/gdf/lib/libuct.so.0(+0x1f0ff) [0x7f1a28bdd0ff]
 7  /datasets/pentschev/miniconda3/envs/gdf/lib/libuct.so.0(+0x1f674) [0x7f1a28bdd674]
 8  /datasets/pentschev/miniconda3/envs/gdf/lib/libuct.so.0(+0x21a78) [0x7f1a28bdfa78]
 9  /datasets/pentschev/miniconda3/envs/gdf/lib/libucs.so.0(ucs_event_set_wait+0xb9) [0x7f1a28e2f8a9]
10  /datasets/pentschev/miniconda3/envs/gdf/lib/libuct.so.0(uct_tcp_iface_progress+0x7b) [0x7f1a28bdfb1b]
11  /datasets/pentschev/miniconda3/envs/gdf/lib/libucp.so.0(ucp_worker_progress+0x6a) [0x7f1a2909df5a]
12  /datasets/pentschev/miniconda3/envs/gdf/lib/python3.8/site-packages/ucp/_libs/ucx_api.cpython-38-x86_64-linux-gnu.so(+0x272b9) [0x7f1a2934a2b9]
13  /datasets/pentschev/miniconda3/envs/gdf/bin/python(+0x12e343) [0x55ef600cc343]
14  /datasets/pentschev/miniconda3/envs/gdf/bin/python(PyObject_Call+0x24a) [0x55ef600d71fa]
15  /datasets/pentschev/miniconda3/envs/gdf/bin/python(_PyEval_EvalFrameDefault+0x680b) [0x55ef600bdb8b]
16  /datasets/pentschev/miniconda3/envs/gdf/bin/python(_PyEval_EvalCodeWithName+0x2f1) [0x55ef600b62f1]
17  /datasets/pentschev/miniconda3/envs/gdf/bin/python(_PyFunction_Vectorcall+0x19c) [0x55ef600c793c]
18  /datasets/pentschev/miniconda3/envs/gdf/bin/python(_PyEval_EvalFrameDefault+0x6d5) [0x55ef600b7a55]
19  /datasets/pentschev/miniconda3/envs/gdf/bin/python(_PyFunction_Vectorcall+0x106) [0x55ef600c78a6]
20  /datasets/pentschev/miniconda3/envs/gdf/bin/python(+0x136c36) [0x55ef600d4c36]
21  /datasets/pentschev/miniconda3/envs/gdf/bin/python(+0x23565a) [0x55ef601d365a]
22  /datasets/pentschev/miniconda3/envs/gdf/bin/python(+0xe0b07) [0x55ef6007eb07]
23  /datasets/pentschev/miniconda3/envs/gdf/bin/python(+0x120f96) [0x55ef600bef96]
24  /datasets/pentschev/miniconda3/envs/gdf/bin/python(PyVectorcall_Call+0x7a) [0x55ef600d51ea]
25  /datasets/pentschev/miniconda3/envs/gdf/bin/python(_PyEval_EvalFrameDefault+0x5df8) [0x55ef600bd178]
26  /datasets/pentschev/miniconda3/envs/gdf/bin/python(_PyFunction_Vectorcall+0x106) [0x55ef600c78a6]
27  /datasets/pentschev/miniconda3/envs/gdf/bin/python(_PyEval_EvalFrameDefault+0x6d5) [0x55ef600b7a55]
28  /datasets/pentschev/miniconda3/envs/gdf/bin/python(_PyFunction_Vectorcall+0x106) [0x55ef600c78a6]
29  /datasets/pentschev/miniconda3/envs/gdf/bin/python(_PyEval_EvalFrameDefault+0x6d5) [0x55ef600b7a55]
30  /datasets/pentschev/miniconda3/envs/gdf/bin/python(_PyFunction_Vectorcall+0x106) [0x55ef600c78a6]
31  /datasets/pentschev/miniconda3/envs/gdf/bin/python(_PyEval_EvalFrameDefault+0x6d5) [0x55ef600b7a55]
32  /datasets/pentschev/miniconda3/envs/gdf/bin/python(_PyFunction_Vectorcall+0x106) [0x55ef600c78a6]
33  /datasets/pentschev/miniconda3/envs/gdf/bin/python(_PyEval_EvalFrameDefault+0x6d5) [0x55ef600b7a55]
34  /datasets/pentschev/miniconda3/envs/gdf/bin/python(_PyEval_EvalCodeWithName+0x2f1) [0x55ef600b62f1]
35  /datasets/pentschev/miniconda3/envs/gdf/bin/python(_PyFunction_Vectorcall+0x19c) [0x55ef600c793c]
36  /datasets/pentschev/miniconda3/envs/gdf/bin/python(_PyEval_EvalFrameDefault+0x4b7b) [0x55ef600bbefb]
37  /datasets/pentschev/miniconda3/envs/gdf/bin/python(_PyEval_EvalCodeWithName+0x2f1) [0x55ef600b62f1]
38  /datasets/pentschev/miniconda3/envs/gdf/bin/python(_PyFunction_Vectorcall+0x19c) [0x55ef600c793c]
39  /datasets/pentschev/miniconda3/envs/gdf/bin/python(+0x136e8c) [0x55ef600d4e8c]
40  /datasets/pentschev/miniconda3/envs/gdf/bin/python(_PyObject_FastCallDict+0x282) [0x55ef600bfa92]
41  /datasets/pentschev/miniconda3/envs/gdf/bin/python(+0x1ee049) [0x55ef6018c049]
42  /datasets/pentschev/miniconda3/envs/gdf/bin/python(PyObject_Call+0x2d3) [0x55ef600d7283]
43  /datasets/pentschev/miniconda3/envs/gdf/bin/python(_PyEval_EvalFrameDefault+0x205e) [0x55ef600b93de]
44  /datasets/pentschev/miniconda3/envs/gdf/bin/python(_PyFunction_Vectorcall+0x106) [0x55ef600c78a6]
45  /datasets/pentschev/miniconda3/envs/gdf/bin/python(+0x136e8c) [0x55ef600d4e8c]
46  /datasets/pentschev/miniconda3/envs/gdf/bin/python(PyObject_Call+0x24a) [0x55ef600d71fa]
47  /datasets/pentschev/miniconda3/envs/gdf/bin/python(_PyEval_EvalFrameDefault+0x205e) [0x55ef600b93de]
48  /datasets/pentschev/miniconda3/envs/gdf/bin/python(_PyFunction_Vectorcall+0x106) [0x55ef600c78a6]
49  /datasets/pentschev/miniconda3/envs/gdf/bin/python(_PyEval_EvalFrameDefault+0x6d5) [0x55ef600b7a55]
50  /datasets/pentschev/miniconda3/envs/gdf/bin/python(_PyEval_EvalCodeWithName+0x2f1) [0x55ef600b62f1]
51  /datasets/pentschev/miniconda3/envs/gdf/bin/python(_PyFunction_Vectorcall+0x19c) [0x55ef600c793c]
52  /datasets/pentschev/miniconda3/envs/gdf/bin/python(_PyEval_EvalFrameDefault+0x6d5) [0x55ef600b7a55]
53  /datasets/pentschev/miniconda3/envs/gdf/bin/python(_PyFunction_Vectorcall+0x106) [0x55ef600c78a6]
54  /datasets/pentschev/miniconda3/envs/gdf/bin/python(_PyEval_EvalFrameDefault+0x3a9) [0x55ef600b7729]
55  /datasets/pentschev/miniconda3/envs/gdf/bin/python(_PyEval_EvalCodeWithName+0x2f1) [0x55ef600b62f1]
56  /datasets/pentschev/miniconda3/envs/gdf/bin/python(_PyFunction_Vectorcall+0x19c) [0x55ef600c793c]
57  /datasets/pentschev/miniconda3/envs/gdf/bin/python(_PyEval_EvalFrameDefault+0x11bf) [0x55ef600b853f]
58  /datasets/pentschev/miniconda3/envs/gdf/bin/python(_PyEval_EvalCodeWithName+0x2f1) [0x55ef600b62f1]
59  /datasets/pentschev/miniconda3/envs/gdf/bin/python(PyEval_EvalCodeEx+0x39) [0x55ef60168e99]
60  /datasets/pentschev/miniconda3/envs/gdf/bin/python(PyEval_EvalCode+0x1b) [0x55ef60168e5b]
61  /datasets/pentschev/miniconda3/envs/gdf/bin/python(+0x1eb7f9) [0x55ef601897f9]
=================================
[dgx13:13102:0:13102] Caught signal 11 (Segmentation fault: address not mapped to object at address 0x448)
==== backtrace (tid:  13102) ====
 0  /datasets/pentschev/miniconda3/envs/gdf/lib/libucs.so.0(ucs_handle_error+0x2d4) [0x7fd0906246b4]
 1  /datasets/pentschev/miniconda3/envs/gdf/lib/libucs.so.0(+0x2d88f) [0x7fd09062488f]
 2  /datasets/pentschev/miniconda3/envs/gdf/lib/libucs.so.0(+0x2dbb4) [0x7fd090624bb4]
 3  /lib/x86_64-linux-gnu/libpthread.so.0(+0x12980) [0x7fd1140c2980]
 4  /datasets/pentschev/miniconda3/envs/gdf/lib/libucp.so.0(ucp_mem_type_unpack+0x17) [0x7fd0908a01b7]
 5  /datasets/pentschev/miniconda3/envs/gdf/lib/libucp.so.0(ucp_rndv_data_handler+0x508) [0x7fd0908c9638]
 6  /datasets/pentschev/miniconda3/envs/gdf/lib/libuct.so.0(+0x1f0ff) [0x7fd0903dc0ff]
 7  /datasets/pentschev/miniconda3/envs/gdf/lib/libuct.so.0(+0x1f674) [0x7fd0903dc674]
 8  /datasets/pentschev/miniconda3/envs/gdf/lib/libuct.so.0(+0x21a78) [0x7fd0903dea78]
 9  /datasets/pentschev/miniconda3/envs/gdf/lib/libucs.so.0(ucs_event_set_wait+0xb9) [0x7fd09062e8a9]
10  /datasets/pentschev/miniconda3/envs/gdf/lib/libuct.so.0(uct_tcp_iface_progress+0x7b) [0x7fd0903deb1b]
11  /datasets/pentschev/miniconda3/envs/gdf/lib/libucp.so.0(ucp_worker_progress+0x6a) [0x7fd09089cf5a]
12  /datasets/pentschev/miniconda3/envs/gdf/lib/python3.8/site-packages/ucp/_libs/ucx_api.cpython-38-x86_64-linux-gnu.so(+0x272b9) [0x7fd090b492b9]
13  /datasets/pentschev/miniconda3/envs/gdf/bin/python(+0x12e343) [0x558c9a261343]
14  /datasets/pentschev/miniconda3/envs/gdf/bin/python(PyObject_Call+0x24a) [0x558c9a26c1fa]
15  /datasets/pentschev/miniconda3/envs/gdf/bin/python(_PyEval_EvalFrameDefault+0x680b) [0x558c9a252b8b]
16  /datasets/pentschev/miniconda3/envs/gdf/bin/python(_PyEval_EvalCodeWithName+0x2f1) [0x558c9a24b2f1]
17  /datasets/pentschev/miniconda3/envs/gdf/bin/python(_PyFunction_Vectorcall+0x19c) [0x558c9a25c93c]
18  /datasets/pentschev/miniconda3/envs/gdf/bin/python(_PyEval_EvalFrameDefault+0x6d5) [0x558c9a24ca55]
19  /datasets/pentschev/miniconda3/envs/gdf/bin/python(+0x13e1e8) [0x558c9a2711e8]
20  /datasets/pentschev/miniconda3/envs/gdf/lib/python3.8/lib-dynload/_asyncio.cpython-38-x86_64-linux-gnu.so(+0x7003) [0x7fd0ae7c0003]
21  /datasets/pentschev/miniconda3/envs/gdf/bin/python(_PyObject_MakeTpCall+0x3db) [0x558c9a25530b]
22  /datasets/pentschev/miniconda3/envs/gdf/bin/python(+0xe0b07) [0x558c9a213b07]
23  /datasets/pentschev/miniconda3/envs/gdf/bin/python(+0x120f96) [0x558c9a253f96]
24  /datasets/pentschev/miniconda3/envs/gdf/bin/python(PyVectorcall_Call+0x7a) [0x558c9a26a1ea]
25  /datasets/pentschev/miniconda3/envs/gdf/bin/python(_PyEval_EvalFrameDefault+0x5df8) [0x558c9a252178]
26  /datasets/pentschev/miniconda3/envs/gdf/bin/python(_PyFunction_Vectorcall+0x106) [0x558c9a25c8a6]
27  /datasets/pentschev/miniconda3/envs/gdf/bin/python(_PyEval_EvalFrameDefault+0x6d5) [0x558c9a24ca55]
28  /datasets/pentschev/miniconda3/envs/gdf/bin/python(_PyFunction_Vectorcall+0x106) [0x558c9a25c8a6]
29  /datasets/pentschev/miniconda3/envs/gdf/bin/python(_PyEval_EvalFrameDefault+0x6d5) [0x558c9a24ca55]
30  /datasets/pentschev/miniconda3/envs/gdf/bin/python(_PyFunction_Vectorcall+0x106) [0x558c9a25c8a6]
31  /datasets/pentschev/miniconda3/envs/gdf/bin/python(_PyEval_EvalFrameDefault+0x6d5) [0x558c9a24ca55]
32  /datasets/pentschev/miniconda3/envs/gdf/bin/python(_PyFunction_Vectorcall+0x106) [0x558c9a25c8a6]
33  /datasets/pentschev/miniconda3/envs/gdf/bin/python(_PyEval_EvalFrameDefault+0x6d5) [0x558c9a24ca55]
34  /datasets/pentschev/miniconda3/envs/gdf/bin/python(_PyEval_EvalCodeWithName+0x2f1) [0x558c9a24b2f1]
35  /datasets/pentschev/miniconda3/envs/gdf/bin/python(_PyFunction_Vectorcall+0x19c) [0x558c9a25c93c]
36  /datasets/pentschev/miniconda3/envs/gdf/bin/python(_PyEval_EvalFrameDefault+0x4b7b) [0x558c9a250efb]
37  /datasets/pentschev/miniconda3/envs/gdf/bin/python(_PyEval_EvalCodeWithName+0x2f1) [0x558c9a24b2f1]
38  /datasets/pentschev/miniconda3/envs/gdf/bin/python(_PyFunction_Vectorcall+0x19c) [0x558c9a25c93c]
39  /datasets/pentschev/miniconda3/envs/gdf/bin/python(+0x136e8c) [0x558c9a269e8c]
40  /datasets/pentschev/miniconda3/envs/gdf/bin/python(_PyObject_FastCallDict+0x282) [0x558c9a254a92]
41  /datasets/pentschev/miniconda3/envs/gdf/bin/python(+0x1ee049) [0x558c9a321049]
42  /datasets/pentschev/miniconda3/envs/gdf/bin/python(PyObject_Call+0x2d3) [0x558c9a26c283]
43  /datasets/pentschev/miniconda3/envs/gdf/bin/python(_PyEval_EvalFrameDefault+0x205e) [0x558c9a24e3de]
44  /datasets/pentschev/miniconda3/envs/gdf/bin/python(_PyFunction_Vectorcall+0x106) [0x558c9a25c8a6]
45  /datasets/pentschev/miniconda3/envs/gdf/bin/python(+0x136e8c) [0x558c9a269e8c]
46  /datasets/pentschev/miniconda3/envs/gdf/bin/python(PyObject_Call+0x24a) [0x558c9a26c1fa]
47  /datasets/pentschev/miniconda3/envs/gdf/bin/python(_PyEval_EvalFrameDefault+0x205e) [0x558c9a24e3de]
48  /datasets/pentschev/miniconda3/envs/gdf/bin/python(_PyFunction_Vectorcall+0x106) [0x558c9a25c8a6]
49  /datasets/pentschev/miniconda3/envs/gdf/bin/python(_PyEval_EvalFrameDefault+0x6d5) [0x558c9a24ca55]
50  /datasets/pentschev/miniconda3/envs/gdf/bin/python(_PyEval_EvalCodeWithName+0x2f1) [0x558c9a24b2f1]
51  /datasets/pentschev/miniconda3/envs/gdf/bin/python(_PyFunction_Vectorcall+0x19c) [0x558c9a25c93c]
52  /datasets/pentschev/miniconda3/envs/gdf/bin/python(_PyEval_EvalFrameDefault+0x6d5) [0x558c9a24ca55]
53  /datasets/pentschev/miniconda3/envs/gdf/bin/python(_PyFunction_Vectorcall+0x106) [0x558c9a25c8a6]
54  /datasets/pentschev/miniconda3/envs/gdf/bin/python(_PyEval_EvalFrameDefault+0x3a9) [0x558c9a24c729]
55  /datasets/pentschev/miniconda3/envs/gdf/bin/python(_PyEval_EvalCodeWithName+0x2f1) [0x558c9a24b2f1]
56  /datasets/pentschev/miniconda3/envs/gdf/bin/python(_PyFunction_Vectorcall+0x19c) [0x558c9a25c93c]
57  /datasets/pentschev/miniconda3/envs/gdf/bin/python(_PyEval_EvalFrameDefault+0x11bf) [0x558c9a24d53f]
58  /datasets/pentschev/miniconda3/envs/gdf/bin/python(_PyEval_EvalCodeWithName+0x2f1) [0x558c9a24b2f1]
59  /datasets/pentschev/miniconda3/envs/gdf/bin/python(PyEval_EvalCodeEx+0x39) [0x558c9a2fde99]
60  /datasets/pentschev/miniconda3/envs/gdf/bin/python(PyEval_EvalCode+0x1b) [0x558c9a2fde5b]
61  /datasets/pentschev/miniconda3/envs/gdf/bin/python(+0x1eb7f9) [0x558c9a31e7f9]
=================================
Task exception was never retrieved
future: <Task finished name='Task-1055' coro=<_listener_handler_coroutine() done, defined at /datasets/pentschev/miniconda3/envs/gdf/lib/python3.8/site-packages/ucp/core.py:128> exception=UCXError('<stream_send>: Endpoint timeout')>
Traceback (most recent call last):
  File "/datasets/pentschev/miniconda3/envs/gdf/lib/python3.8/site-packages/ucp/core.py", line 143, in _listener_handler_coroutine
    peer_info = await exchange_peer_info(
  File "/datasets/pentschev/miniconda3/envs/gdf/lib/python3.8/site-packages/ucp/core.py", line 51, in exchange_peer_info
    await comm.stream_send(endpoint, my_info_arr, my_info_arr.nbytes)
ucp._libs.exceptions.UCXError: <stream_send>: Endpoint timeout
2023-03-27 22:47:59,291 - distributed.worker - ERROR - Worker stream died during communication: ucx://127.0.0.1:58591
Traceback (most recent call last):
  File "/datasets/pentschev/miniconda3/envs/gdf/lib/python3.8/site-packages/distributed/core.py", line 1427, in _connect
    comm = await connect(
  File "/datasets/pentschev/miniconda3/envs/gdf/lib/python3.8/site-packages/distributed/comm/core.py", line 316, in connect
    await asyncio.sleep(backoff)
  File "/datasets/pentschev/miniconda3/envs/gdf/lib/python3.8/asyncio/tasks.py", line 659, in sleep
    return await future
asyncio.exceptions.CancelledError

During handling of the above exception, another exception occurred:

Traceback (most recent call last):
  File "/datasets/pentschev/miniconda3/envs/gdf/lib/python3.8/site-packages/distributed/worker.py", line 2066, in gather_dep
    response = await get_data_from_worker(
  File "/datasets/pentschev/miniconda3/envs/gdf/lib/python3.8/site-packages/distributed/worker.py", line 2889, in get_data_from_worker
    comm = await rpc.connect(worker)
  File "/datasets/pentschev/miniconda3/envs/gdf/lib/python3.8/site-packages/distributed/core.py", line 1506, in connect
    return await connect_attempt
  File "/datasets/pentschev/miniconda3/envs/gdf/lib/python3.8/site-packages/distributed/core.py", line 1450, in _connect
    raise CommClosedError(reason)
distributed.comm.core.CommClosedError: Address removed.
2023-03-27 22:47:59,302 - distributed.worker - ERROR - failed during get data with ucx://127.0.0.1:44163 -> ucx://127.0.0.1:58591
Traceback (most recent call last):
  File "/datasets/pentschev/miniconda3/envs/gdf/lib/python3.8/site-packages/distributed/comm/ucx.py", line 333, in write
    await self.ep.send(each_frame)
  File "/datasets/pentschev/miniconda3/envs/gdf/lib/python3.8/site-packages/ucp/core.py", line 650, in send
    return await comm.tag_send(self._ep, buffer, nbytes, tag, name=log)
ucp._libs.exceptions.UCXError: <[Send #007] ep: 0x7faf380bd140, tag: 0x51812abd4af54bf8, nbytes: 100000000, type: <class 'cudf.core.buffer.buffer.Buffer'>>: Endpoint timeout

During handling of the above exception, another exception occurred:

Traceback (most recent call last):
  File "/datasets/pentschev/miniconda3/envs/gdf/lib/python3.8/site-packages/distributed/worker.py", line 1792, in get_data
    compressed = await comm.write(msg, serializers=serializers)
  File "/datasets/pentschev/miniconda3/envs/gdf/lib/python3.8/site-packages/distributed/utils.py", line 752, in wrapper
    return await func(*args, **kwargs)
  File "/datasets/pentschev/miniconda3/envs/gdf/lib/python3.8/site-packages/distributed/comm/ucx.py", line 337, in write
    raise CommClosedError("While writing, the connection was closed")
distributed.comm.core.CommClosedError: While writing, the connection was closed
2023-03-27 22:47:59,311 - distributed.worker - ERROR - Worker stream died during communication: ucx://127.0.0.1:35803
Traceback (most recent call last):
  File "/datasets/pentschev/miniconda3/envs/gdf/lib/python3.8/site-packages/distributed/core.py", line 1427, in _connect
    comm = await connect(
  File "/datasets/pentschev/miniconda3/envs/gdf/lib/python3.8/site-packages/distributed/comm/core.py", line 316, in connect
    await asyncio.sleep(backoff)
  File "/datasets/pentschev/miniconda3/envs/gdf/lib/python3.8/asyncio/tasks.py", line 659, in sleep
    return await future
asyncio.exceptions.CancelledError

During handling of the above exception, another exception occurred:

Traceback (most recent call last):
  File "/datasets/pentschev/miniconda3/envs/gdf/lib/python3.8/site-packages/distributed/worker.py", line 2066, in gather_dep
    response = await get_data_from_worker(
  File "/datasets/pentschev/miniconda3/envs/gdf/lib/python3.8/site-packages/distributed/worker.py", line 2889, in get_data_from_worker
    comm = await rpc.connect(worker)
  File "/datasets/pentschev/miniconda3/envs/gdf/lib/python3.8/site-packages/distributed/core.py", line 1506, in connect
    return await connect_attempt
  File "/datasets/pentschev/miniconda3/envs/gdf/lib/python3.8/site-packages/distributed/core.py", line 1450, in _connect
    raise CommClosedError(reason)
distributed.comm.core.CommClosedError: Address removed.
2023-03-27 22:47:59,344 - distributed.worker - ERROR - Worker stream died during communication: ucx://127.0.0.1:38491
Traceback (most recent call last):
  File "/datasets/pentschev/miniconda3/envs/gdf/lib/python3.8/site-packages/distributed/comm/ucx.py", line 391, in read
    await self.ep.recv(each_frame)
  File "/datasets/pentschev/miniconda3/envs/gdf/lib/python3.8/site-packages/ucp/core.py", line 725, in recv
    ret = await comm.tag_recv(self._ep, buffer, nbytes, tag, name=log)
ucp._libs.exceptions.UCXCanceled: <[Recv #008] ep: 0x7f0730117200, tag: 0x7745fce630aeb1af, nbytes: 100000000, type: <class 'rmm._lib.device_buffer.DeviceBuffer'>>: 

During handling of the above exception, another exception occurred:

Traceback (most recent call last):
  File "/datasets/pentschev/miniconda3/envs/gdf/lib/python3.8/site-packages/distributed/worker.py", line 2066, in gather_dep
    response = await get_data_from_worker(
  File "/datasets/pentschev/miniconda3/envs/gdf/lib/python3.8/site-packages/distributed/worker.py", line 2892, in get_data_from_worker
    response = await send_recv(
  File "/datasets/pentschev/miniconda3/envs/gdf/lib/python3.8/site-packages/distributed/core.py", line 1024, in send_recv
    response = await comm.read(deserializers=deserializers)
  File "/datasets/pentschev/miniconda3/envs/gdf/lib/python3.8/site-packages/distributed/utils.py", line 752, in wrapper
    return await func(*args, **kwargs)
  File "/datasets/pentschev/miniconda3/envs/gdf/lib/python3.8/site-packages/distributed/comm/ucx.py", line 397, in read
    raise CommClosedError(
distributed.comm.core.CommClosedError: Connection closed by writer.
Inner exception: UCXCanceled("<[Recv #008] ep: 0x7f0730117200, tag: 0x7745fce630aeb1af, nbytes: 100000000, type: <class 'rmm._lib.device_buffer.DeviceBuffer'>>: ")
2023-03-27 22:47:59,412 - distributed.worker - ERROR - failed during get data with ucx://127.0.0.1:36153 -> ucx://127.0.0.1:35803
Traceback (most recent call last):
  File "/datasets/pentschev/miniconda3/envs/gdf/lib/python3.8/site-packages/distributed/comm/ucx.py", line 333, in write
    await self.ep.send(each_frame)
  File "/datasets/pentschev/miniconda3/envs/gdf/lib/python3.8/site-packages/ucp/core.py", line 650, in send
    return await comm.tag_send(self._ep, buffer, nbytes, tag, name=log)
ucp._libs.exceptions.UCXError: <[Send #007] ep: 0x7f7c7c1422c0, tag: 0xc93042b6c2c66e3b, nbytes: 100000000, type: <class 'cudf.core.buffer.buffer.Buffer'>>: Endpoint timeout

During handling of the above exception, another exception occurred:

Traceback (most recent call last):
  File "/datasets/pentschev/miniconda3/envs/gdf/lib/python3.8/site-packages/distributed/worker.py", line 1792, in get_data
    compressed = await comm.write(msg, serializers=serializers)
  File "/datasets/pentschev/miniconda3/envs/gdf/lib/python3.8/site-packages/distributed/utils.py", line 752, in wrapper
    return await func(*args, **kwargs)
  File "/datasets/pentschev/miniconda3/envs/gdf/lib/python3.8/site-packages/distributed/comm/ucx.py", line 337, in write
    raise CommClosedError("While writing, the connection was closed")
distributed.comm.core.CommClosedError: While writing, the connection was closed
2023-03-27 22:47:59,413 - distributed.worker - ERROR - Worker stream died during communication: ucx://127.0.0.1:35803
Traceback (most recent call last):
  File "/datasets/pentschev/miniconda3/envs/gdf/lib/python3.8/site-packages/distributed/comm/ucx.py", line 349, in read
    await self.ep.recv(msg)
  File "/datasets/pentschev/miniconda3/envs/gdf/lib/python3.8/site-packages/ucp/core.py", line 725, in recv
    ret = await comm.tag_recv(self._ep, buffer, nbytes, tag, name=log)
ucp._libs.exceptions.UCXCanceled: <[Recv #003] ep: 0x7f7c7c142200, tag: 0x91660af4bc0d2c70, nbytes: 16, type: <class 'numpy.ndarray'>>: 

During handling of the above exception, another exception occurred:

Traceback (most recent call last):
  File "/datasets/pentschev/miniconda3/envs/gdf/lib/python3.8/site-packages/distributed/worker.py", line 2066, in gather_dep
    response = await get_data_from_worker(
  File "/datasets/pentschev/miniconda3/envs/gdf/lib/python3.8/site-packages/distributed/worker.py", line 2892, in get_data_from_worker
    response = await send_recv(
  File "/datasets/pentschev/miniconda3/envs/gdf/lib/python3.8/site-packages/distributed/core.py", line 1024, in send_recv
    response = await comm.read(deserializers=deserializers)
  File "/datasets/pentschev/miniconda3/envs/gdf/lib/python3.8/site-packages/distributed/utils.py", line 752, in wrapper
    return await func(*args, **kwargs)
  File "/datasets/pentschev/miniconda3/envs/gdf/lib/python3.8/site-packages/distributed/comm/ucx.py", line 367, in read
    raise CommClosedError(
distributed.comm.core.CommClosedError: Connection closed by writer.
Inner exception: UCXCanceled("<[Recv #003] ep: 0x7f7c7c142200, tag: 0x91660af4bc0d2c70, nbytes: 16, type: <class 'numpy.ndarray'>>: ")
2023-03-27 22:47:59,414 - distributed.worker - ERROR - Worker stream died during communication: ucx://127.0.0.1:38491
Traceback (most recent call last):
  File "/datasets/pentschev/miniconda3/envs/gdf/lib/python3.8/site-packages/distributed/comm/ucx.py", line 349, in read
    await self.ep.recv(msg)
  File "/datasets/pentschev/miniconda3/envs/gdf/lib/python3.8/site-packages/ucp/core.py", line 725, in recv
    ret = await comm.tag_recv(self._ep, buffer, nbytes, tag, name=log)
ucp._libs.exceptions.UCXCanceled: <[Recv #011] ep: 0x7f7c7c142100, tag: 0xba2901bd0662920e, nbytes: 16, type: <class 'numpy.ndarray'>>: 

During handling of the above exception, another exception occurred:

Traceback (most recent call last):
  File "/datasets/pentschev/miniconda3/envs/gdf/lib/python3.8/site-packages/distributed/worker.py", line 2066, in gather_dep
    response = await get_data_from_worker(
  File "/datasets/pentschev/miniconda3/envs/gdf/lib/python3.8/site-packages/distributed/worker.py", line 2892, in get_data_from_worker
    response = await send_recv(
  File "/datasets/pentschev/miniconda3/envs/gdf/lib/python3.8/site-packages/distributed/core.py", line 1024, in send_recv
    response = await comm.read(deserializers=deserializers)
  File "/datasets/pentschev/miniconda3/envs/gdf/lib/python3.8/site-packages/distributed/utils.py", line 752, in wrapper
    return await func(*args, **kwargs)
  File "/datasets/pentschev/miniconda3/envs/gdf/lib/python3.8/site-packages/distributed/comm/ucx.py", line 367, in read
    raise CommClosedError(
distributed.comm.core.CommClosedError: Connection closed by writer.
Inner exception: UCXCanceled("<[Recv #011] ep: 0x7f7c7c142100, tag: 0xba2901bd0662920e, nbytes: 16, type: <class 'numpy.ndarray'>>: ")
2023-03-27 22:47:59,416 - distributed.nanny - WARNING - Restarting worker
2023-03-27 22:47:59,483 - distributed.nanny - WARNING - Restarting worker
2023-03-27 22:47:59,532 - distributed.nanny - WARNING - Restarting worker
2023-03-27 22:47:59,539 - distributed.worker - ERROR - failed during get data with ucx://127.0.0.1:44163 -> ucx://127.0.0.1:38491
Traceback (most recent call last):
  File "/datasets/pentschev/miniconda3/envs/gdf/lib/python3.8/site-packages/distributed/comm/ucx.py", line 333, in write
    await self.ep.send(each_frame)
  File "/datasets/pentschev/miniconda3/envs/gdf/lib/python3.8/site-packages/ucp/core.py", line 650, in send
    return await comm.tag_send(self._ep, buffer, nbytes, tag, name=log)
ucp._libs.exceptions.UCXError: <[Send #007] ep: 0x7faf380bd180, tag: 0x1d3fac7d4c926674, nbytes: 100000000, type: <class 'cudf.core.buffer.buffer.Buffer'>>: Endpoint timeout

During handling of the above exception, another exception occurred:

Traceback (most recent call last):
  File "/datasets/pentschev/miniconda3/envs/gdf/lib/python3.8/site-packages/distributed/worker.py", line 1792, in get_data
    compressed = await comm.write(msg, serializers=serializers)
  File "/datasets/pentschev/miniconda3/envs/gdf/lib/python3.8/site-packages/distributed/utils.py", line 752, in wrapper
    return await func(*args, **kwargs)
  File "/datasets/pentschev/miniconda3/envs/gdf/lib/python3.8/site-packages/distributed/comm/ucx.py", line 337, in write
    raise CommClosedError("While writing, the connection was closed")
distributed.comm.core.CommClosedError: While writing, the connection was closed
2023-03-27 22:47:59,544 - distributed.worker - ERROR - Worker stream died during communication: ucx://127.0.0.1:38491
Traceback (most recent call last):
  File "/datasets/pentschev/miniconda3/envs/gdf/lib/python3.8/asyncio/tasks.py", line 481, in wait_for
    await waiter
asyncio.exceptions.CancelledError

During handling of the above exception, another exception occurred:

Traceback (most recent call last):
  File "/datasets/pentschev/miniconda3/envs/gdf/lib/python3.8/site-packages/distributed/comm/core.py", line 329, in connect
    handshake = await wait_for(comm.read(), time_left())
  File "/datasets/pentschev/miniconda3/envs/gdf/lib/python3.8/site-packages/distributed/utils.py", line 1849, in wait_for
    return await asyncio.wait_for(fut, timeout)
  File "/datasets/pentschev/miniconda3/envs/gdf/lib/python3.8/asyncio/tasks.py", line 484, in wait_for
    return fut.result()
  File "/datasets/pentschev/miniconda3/envs/gdf/lib/python3.8/site-packages/distributed/utils.py", line 752, in wrapper
    return await func(*args, **kwargs)
  File "/datasets/pentschev/miniconda3/envs/gdf/lib/python3.8/site-packages/distributed/comm/ucx.py", line 367, in read
    raise CommClosedError(
distributed.comm.core.CommClosedError: Connection closed by writer.
Inner exception: UCXCanceled("<[Recv #000] ep: 0x7faf380bd200, tag: 0xc486443823a175f8, nbytes: 16, type: <class 'numpy.ndarray'>>: ")

The above exception was the direct cause of the following exception:

Traceback (most recent call last):
  File "/datasets/pentschev/miniconda3/envs/gdf/lib/python3.8/site-packages/distributed/worker.py", line 2066, in gather_dep
    response = await get_data_from_worker(
  File "/datasets/pentschev/miniconda3/envs/gdf/lib/python3.8/site-packages/distributed/worker.py", line 2889, in get_data_from_worker
    comm = await rpc.connect(worker)
  File "/datasets/pentschev/miniconda3/envs/gdf/lib/python3.8/site-packages/distributed/core.py", line 1506, in connect
    return await connect_attempt
  File "/datasets/pentschev/miniconda3/envs/gdf/lib/python3.8/site-packages/distributed/core.py", line 1427, in _connect
    comm = await connect(
  File "/datasets/pentschev/miniconda3/envs/gdf/lib/python3.8/site-packages/distributed/comm/core.py", line 334, in connect
    raise OSError(
OSError: Timed out during handshake while connecting to ucx://127.0.0.1:38491 after 30 s
2023-03-27 22:48:00,515 - distributed.preloading - INFO - Creating preload: dask_cuda.initialize
2023-03-27 22:48:00,515 - distributed.preloading - INFO - Import preload module: dask_cuda.initialize
terminate called after throwing an instance of 'rmm::out_of_memory'
  what():  std::bad_alloc: out_of_memory: RMM failure at:/datasets/pentschev/miniconda3/envs/gdf/include/rmm/mr/device/pool_memory_resource.hpp:195: Maximum pool size exceeded
2023-03-27 22:48:00,819 - distributed.diskutils - INFO - Found stale lock file and directory '/tmp/dask-worker-space/worker-4d2g1ibg', purging
2023-03-27 22:48:00,820 - distributed.preloading - INFO - Creating preload: dask_cuda.initialize
2023-03-27 22:48:00,820 - distributed.preloading - INFO - Import preload module: dask_cuda.initialize
2023-03-27 22:48:00,867 - distributed.nanny - WARNING - Restarting worker
2023-03-27 22:48:01,439 - distributed.preloading - INFO - Creating preload: dask_cuda.initialize
2023-03-27 22:48:01,439 - distributed.preloading - INFO - Import preload module: dask_cuda.initialize
2023-03-27 22:48:01,440 - distributed.preloading - INFO - Creating preload: dask_cuda.initialize
2023-03-27 22:48:01,440 - distributed.preloading - INFO - Import preload module: dask_cuda.initialize
2023-03-27 22:48:01,515 - distributed.preloading - INFO - Creating preload: dask_cuda.initialize
2023-03-27 22:48:01,515 - distributed.preloading - INFO - Import preload module: dask_cuda.initialize
2023-03-27 22:48:02,886 - distributed.preloading - INFO - Creating preload: dask_cuda.initialize
2023-03-27 22:48:02,886 - distributed.preloading - INFO - Import preload module: dask_cuda.initialize
Traceback (most recent call last):
  File "cupy/cuda/memory.pyx", line 742, in cupy.cuda.memory.alloc
  File "/datasets/pentschev/miniconda3/envs/gdf/lib/python3.8/site-packages/rmm/allocators/cupy.py", line 37, in rmm_cupy_allocator
    buf = librmm.device_buffer.DeviceBuffer(size=nbytes, stream=stream)
  File "device_buffer.pyx", line 85, in rmm._lib.device_buffer.DeviceBuffer.__cinit__
MemoryError: std::bad_alloc: out_of_memory: CUDA error at: /datasets/pentschev/miniconda3/envs/gdf/include/rmm/mr/device/cuda_memory_resource.hpp
Exception ignored in: 'cupy.cuda.thrust.cupy_malloc'
Traceback (most recent call last):
  File "cupy/cuda/memory.pyx", line 742, in cupy.cuda.memory.alloc
  File "/datasets/pentschev/miniconda3/envs/gdf/lib/python3.8/site-packages/rmm/allocators/cupy.py", line 37, in rmm_cupy_allocator
    buf = librmm.device_buffer.DeviceBuffer(size=nbytes, stream=stream)
  File "device_buffer.pyx", line 85, in rmm._lib.device_buffer.DeviceBuffer.__cinit__
MemoryError: std::bad_alloc: out_of_memory: CUDA error at: /datasets/pentschev/miniconda3/envs/gdf/include/rmm/mr/device/cuda_memory_resource.hpp
2023-03-27 22:48:06,296 - distributed.worker - WARNING - Compute Failed
Key:       ('generate-data-5366301a596b755bb8c33997d3ce7726', 3)
Function:  generate_chunk
args:      (3, 100000000, 8, 'build', 0.3, True)
kwargs:    {}
Exception: "RuntimeError('transform: failed to synchronize: cudaErrorIllegalAddress: an illegal memory access was encountered')"

2023-03-27 22:48:29,009 - distributed.worker - ERROR - Worker stream died during communication: ucx://127.0.0.1:58591
Traceback (most recent call last):
  File "/datasets/pentschev/miniconda3/envs/gdf/lib/python3.8/site-packages/distributed/comm/core.py", line 292, in connect
    comm = await wait_for(
  File "/datasets/pentschev/miniconda3/envs/gdf/lib/python3.8/site-packages/distributed/utils.py", line 1849, in wait_for
    return await asyncio.wait_for(fut, timeout)
  File "/datasets/pentschev/miniconda3/envs/gdf/lib/python3.8/asyncio/tasks.py", line 501, in wait_for
    raise exceptions.TimeoutError()
asyncio.exceptions.TimeoutError

The above exception was the direct cause of the following exception:

Traceback (most recent call last):
  File "/datasets/pentschev/miniconda3/envs/gdf/lib/python3.8/site-packages/distributed/worker.py", line 2066, in gather_dep
    response = await get_data_from_worker(
  File "/datasets/pentschev/miniconda3/envs/gdf/lib/python3.8/site-packages/distributed/worker.py", line 2889, in get_data_from_worker
    comm = await rpc.connect(worker)
  File "/datasets/pentschev/miniconda3/envs/gdf/lib/python3.8/site-packages/distributed/core.py", line 1506, in connect
    return await connect_attempt
  File "/datasets/pentschev/miniconda3/envs/gdf/lib/python3.8/site-packages/distributed/core.py", line 1427, in _connect
    comm = await connect(
  File "/datasets/pentschev/miniconda3/envs/gdf/lib/python3.8/site-packages/distributed/comm/core.py", line 318, in connect
    raise OSError(
OSError: Timed out trying to connect to ucx://127.0.0.1:58591 after 30 s
[dgx13:13717:0:13717] Caught signal 11 (Segmentation fault: address not mapped to object at address 0x448)
==== backtrace (tid:  13717) ====
 0  /datasets/pentschev/miniconda3/envs/gdf/lib/libucs.so.0(ucs_handle_error+0x2d4) [0x7fecb10a26b4]
 1  /datasets/pentschev/miniconda3/envs/gdf/lib/libucs.so.0(+0x2d88f) [0x7fecb10a288f]
 2  /datasets/pentschev/miniconda3/envs/gdf/lib/libucs.so.0(+0x2dbb4) [0x7fecb10a2bb4]
 3  /lib/x86_64-linux-gnu/libpthread.so.0(+0x12980) [0x7fed269df980]
 4  /datasets/pentschev/miniconda3/envs/gdf/lib/libucp.so.0(ucp_mem_type_unpack+0x17) [0x7fecb131e1b7]
 5  /datasets/pentschev/miniconda3/envs/gdf/lib/libucp.so.0(ucp_rndv_data_handler+0x508) [0x7fecb1347638]
 6  /datasets/pentschev/miniconda3/envs/gdf/lib/libuct.so.0(+0x1f0ff) [0x7fecb0e5a0ff]
 7  /datasets/pentschev/miniconda3/envs/gdf/lib/libuct.so.0(+0x1f674) [0x7fecb0e5a674]
 8  /datasets/pentschev/miniconda3/envs/gdf/lib/libuct.so.0(+0x21a78) [0x7fecb0e5ca78]
 9  /datasets/pentschev/miniconda3/envs/gdf/lib/libucs.so.0(ucs_event_set_wait+0xb9) [0x7fecb10ac8a9]
10  /datasets/pentschev/miniconda3/envs/gdf/lib/libuct.so.0(uct_tcp_iface_progress+0x7b) [0x7fecb0e5cb1b]
11  /datasets/pentschev/miniconda3/envs/gdf/lib/libucp.so.0(ucp_worker_progress+0x6a) [0x7fecb131af5a]
12  /datasets/pentschev/miniconda3/envs/gdf/lib/python3.8/site-packages/ucp/_libs/ucx_api.cpython-38-x86_64-linux-gnu.so(+0x272b9) [0x7fecb15c72b9]
13  /datasets/pentschev/miniconda3/envs/gdf/bin/python(+0x12e343) [0x562752c32343]
14  /datasets/pentschev/miniconda3/envs/gdf/bin/python(PyObject_Call+0x24a) [0x562752c3d1fa]
15  /datasets/pentschev/miniconda3/envs/gdf/bin/python(_PyEval_EvalFrameDefault+0x680b) [0x562752c23b8b]
16  /datasets/pentschev/miniconda3/envs/gdf/bin/python(_PyEval_EvalCodeWithName+0x2f1) [0x562752c1c2f1]
17  /datasets/pentschev/miniconda3/envs/gdf/bin/python(_PyFunction_Vectorcall+0x19c) [0x562752c2d93c]
18  /datasets/pentschev/miniconda3/envs/gdf/bin/python(_PyEval_EvalFrameDefault+0x6d5) [0x562752c1da55]
19  /datasets/pentschev/miniconda3/envs/gdf/bin/python(_PyFunction_Vectorcall+0x106) [0x562752c2d8a6]
20  /datasets/pentschev/miniconda3/envs/gdf/bin/python(+0x136c36) [0x562752c3ac36]
21  /datasets/pentschev/miniconda3/envs/gdf/bin/python(+0x23565a) [0x562752d3965a]
22  /datasets/pentschev/miniconda3/envs/gdf/bin/python(+0xe0b07) [0x562752be4b07]
23  /datasets/pentschev/miniconda3/envs/gdf/bin/python(+0x120f96) [0x562752c24f96]
24  /datasets/pentschev/miniconda3/envs/gdf/bin/python(PyVectorcall_Call+0x7a) [0x562752c3b1ea]
25  /datasets/pentschev/miniconda3/envs/gdf/bin/python(_PyEval_EvalFrameDefault+0x5df8) [0x562752c23178]
26  /datasets/pentschev/miniconda3/envs/gdf/bin/python(_PyFunction_Vectorcall+0x106) [0x562752c2d8a6]
27  /datasets/pentschev/miniconda3/envs/gdf/bin/python(_PyEval_EvalFrameDefault+0x6d5) [0x562752c1da55]
28  /datasets/pentschev/miniconda3/envs/gdf/bin/python(_PyFunction_Vectorcall+0x106) [0x562752c2d8a6]
29  /datasets/pentschev/miniconda3/envs/gdf/bin/python(_PyEval_EvalFrameDefault+0x6d5) [0x562752c1da55]
30  /datasets/pentschev/miniconda3/envs/gdf/bin/python(_PyFunction_Vectorcall+0x106) [0x562752c2d8a6]
31  /datasets/pentschev/miniconda3/envs/gdf/bin/python(_PyEval_EvalFrameDefault+0x6d5) [0x562752c1da55]
32  /datasets/pentschev/miniconda3/envs/gdf/bin/python(_PyFunction_Vectorcall+0x106) [0x562752c2d8a6]
33  /datasets/pentschev/miniconda3/envs/gdf/bin/python(_PyEval_EvalFrameDefault+0x6d5) [0x562752c1da55]
34  /datasets/pentschev/miniconda3/envs/gdf/bin/python(_PyEval_EvalCodeWithName+0x2f1) [0x562752c1c2f1]
35  /datasets/pentschev/miniconda3/envs/gdf/bin/python(_PyFunction_Vectorcall+0x19c) [0x562752c2d93c]
36  /datasets/pentschev/miniconda3/envs/gdf/bin/python(_PyEval_EvalFrameDefault+0x4b7b) [0x562752c21efb]
37  /datasets/pentschev/miniconda3/envs/gdf/bin/python(_PyEval_EvalCodeWithName+0x2f1) [0x562752c1c2f1]
38  /datasets/pentschev/miniconda3/envs/gdf/bin/python(_PyFunction_Vectorcall+0x19c) [0x562752c2d93c]
39  /datasets/pentschev/miniconda3/envs/gdf/bin/python(+0x136e8c) [0x562752c3ae8c]
40  /datasets/pentschev/miniconda3/envs/gdf/bin/python(_PyObject_FastCallDict+0x282) [0x562752c25a92]
41  /datasets/pentschev/miniconda3/envs/gdf/bin/python(+0x1ee049) [0x562752cf2049]
42  /datasets/pentschev/miniconda3/envs/gdf/bin/python(PyObject_Call+0x2d3) [0x562752c3d283]
43  /datasets/pentschev/miniconda3/envs/gdf/bin/python(_PyEval_EvalFrameDefault+0x205e) [0x562752c1f3de]
44  /datasets/pentschev/miniconda3/envs/gdf/bin/python(_PyFunction_Vectorcall+0x106) [0x562752c2d8a6]
45  /datasets/pentschev/miniconda3/envs/gdf/bin/python(+0x136e8c) [0x562752c3ae8c]
46  /datasets/pentschev/miniconda3/envs/gdf/bin/python(PyObject_Call+0x24a) [0x562752c3d1fa]
47  /datasets/pentschev/miniconda3/envs/gdf/bin/python(_PyEval_EvalFrameDefault+0x205e) [0x562752c1f3de]
48  /datasets/pentschev/miniconda3/envs/gdf/bin/python(_PyFunction_Vectorcall+0x106) [0x562752c2d8a6]
49  /datasets/pentschev/miniconda3/envs/gdf/bin/python(_PyEval_EvalFrameDefault+0x6d5) [0x562752c1da55]
50  /datasets/pentschev/miniconda3/envs/gdf/bin/python(_PyEval_EvalCodeWithName+0x2f1) [0x562752c1c2f1]
51  /datasets/pentschev/miniconda3/envs/gdf/bin/python(_PyFunction_Vectorcall+0x19c) [0x562752c2d93c]
52  /datasets/pentschev/miniconda3/envs/gdf/bin/python(_PyEval_EvalFrameDefault+0x6d5) [0x562752c1da55]
53  /datasets/pentschev/miniconda3/envs/gdf/bin/python(_PyFunction_Vectorcall+0x106) [0x562752c2d8a6]
54  /datasets/pentschev/miniconda3/envs/gdf/bin/python(_PyEval_EvalFrameDefault+0x3a9) [0x562752c1d729]
55  /datasets/pentschev/miniconda3/envs/gdf/bin/python(_PyEval_EvalCodeWithName+0x2f1) [0x562752c1c2f1]
56  /datasets/pentschev/miniconda3/envs/gdf/bin/python(_PyFunction_Vectorcall+0x19c) [0x562752c2d93c]
57  /datasets/pentschev/miniconda3/envs/gdf/bin/python(_PyEval_EvalFrameDefault+0x11bf) [0x562752c1e53f]
58  /datasets/pentschev/miniconda3/envs/gdf/bin/python(_PyEval_EvalCodeWithName+0x2f1) [0x562752c1c2f1]
59  /datasets/pentschev/miniconda3/envs/gdf/bin/python(PyEval_EvalCodeEx+0x39) [0x562752ccee99]
60  /datasets/pentschev/miniconda3/envs/gdf/bin/python(PyEval_EvalCode+0x1b) [0x562752ccee5b]
61  /datasets/pentschev/miniconda3/envs/gdf/bin/python(+0x1eb7f9) [0x562752cef7f9]
=================================
2023-03-27 22:48:29,074 - distributed.worker - ERROR - Worker stream died during communication: ucx://127.0.0.1:35803
Traceback (most recent call last):
  File "/datasets/pentschev/miniconda3/envs/gdf/lib/python3.8/site-packages/distributed/comm/core.py", line 292, in connect
    comm = await wait_for(
  File "/datasets/pentschev/miniconda3/envs/gdf/lib/python3.8/site-packages/distributed/utils.py", line 1849, in wait_for
    return await asyncio.wait_for(fut, timeout)
  File "/datasets/pentschev/miniconda3/envs/gdf/lib/python3.8/asyncio/tasks.py", line 501, in wait_for
    raise exceptions.TimeoutError()
asyncio.exceptions.TimeoutError

The above exception was the direct cause of the following exception:

Traceback (most recent call last):
  File "/datasets/pentschev/miniconda3/envs/gdf/lib/python3.8/site-packages/distributed/worker.py", line 2066, in gather_dep
    response = await get_data_from_worker(
  File "/datasets/pentschev/miniconda3/envs/gdf/lib/python3.8/site-packages/distributed/worker.py", line 2889, in get_data_from_worker
    comm = await rpc.connect(worker)
  File "/datasets/pentschev/miniconda3/envs/gdf/lib/python3.8/site-packages/distributed/core.py", line 1506, in connect
    return await connect_attempt
  File "/datasets/pentschev/miniconda3/envs/gdf/lib/python3.8/site-packages/distributed/core.py", line 1427, in _connect
    comm = await connect(
  File "/datasets/pentschev/miniconda3/envs/gdf/lib/python3.8/site-packages/distributed/comm/core.py", line 318, in connect
    raise OSError(
OSError: Timed out trying to connect to ucx://127.0.0.1:35803 after 30 s
2023-03-27 22:48:29,074 - distributed.worker - ERROR - Worker stream died during communication: ucx://127.0.0.1:58591
Traceback (most recent call last):
  File "/datasets/pentschev/miniconda3/envs/gdf/lib/python3.8/site-packages/distributed/comm/core.py", line 292, in connect
    comm = await wait_for(
  File "/datasets/pentschev/miniconda3/envs/gdf/lib/python3.8/site-packages/distributed/utils.py", line 1849, in wait_for
    return await asyncio.wait_for(fut, timeout)
  File "/datasets/pentschev/miniconda3/envs/gdf/lib/python3.8/asyncio/tasks.py", line 501, in wait_for
    raise exceptions.TimeoutError()
asyncio.exceptions.TimeoutError

The above exception was the direct cause of the following exception:

Traceback (most recent call last):
  File "/datasets/pentschev/miniconda3/envs/gdf/lib/python3.8/site-packages/distributed/worker.py", line 2066, in gather_dep
    response = await get_data_from_worker(
  File "/datasets/pentschev/miniconda3/envs/gdf/lib/python3.8/site-packages/distributed/worker.py", line 2889, in get_data_from_worker
    comm = await rpc.connect(worker)
  File "/datasets/pentschev/miniconda3/envs/gdf/lib/python3.8/site-packages/distributed/core.py", line 1506, in connect
    return await connect_attempt
  File "/datasets/pentschev/miniconda3/envs/gdf/lib/python3.8/site-packages/distributed/core.py", line 1427, in _connect
    comm = await connect(
  File "/datasets/pentschev/miniconda3/envs/gdf/lib/python3.8/site-packages/distributed/comm/core.py", line 318, in connect
    raise OSError(
OSError: Timed out trying to connect to ucx://127.0.0.1:58591 after 30 s
2023-03-27 22:48:29,248 - distributed.worker - ERROR - failed during get data with ucx://127.0.0.1:36153 -> ucx://127.0.0.1:50461
Traceback (most recent call last):
  File "/datasets/pentschev/miniconda3/envs/gdf/lib/python3.8/site-packages/distributed/comm/ucx.py", line 333, in write
    await self.ep.send(each_frame)
  File "/datasets/pentschev/miniconda3/envs/gdf/lib/python3.8/site-packages/ucp/core.py", line 650, in send
    return await comm.tag_send(self._ep, buffer, nbytes, tag, name=log)
ucp._libs.exceptions.UCXError: <[Send #007] ep: 0x7f7c7c142100, tag: 0x7b1a65b30ad1c0f8, nbytes: 100000000, type: <class 'cudf.core.buffer.buffer.Buffer'>>: Endpoint timeout

During handling of the above exception, another exception occurred:

Traceback (most recent call last):
  File "/datasets/pentschev/miniconda3/envs/gdf/lib/python3.8/site-packages/distributed/worker.py", line 1792, in get_data
    compressed = await comm.write(msg, serializers=serializers)
  File "/datasets/pentschev/miniconda3/envs/gdf/lib/python3.8/site-packages/distributed/utils.py", line 752, in wrapper
    return await func(*args, **kwargs)
  File "/datasets/pentschev/miniconda3/envs/gdf/lib/python3.8/site-packages/distributed/comm/ucx.py", line 337, in write
    raise CommClosedError("While writing, the connection was closed")
distributed.comm.core.CommClosedError: While writing, the connection was closed
2023-03-27 22:48:29,327 - distributed.nanny - WARNING - Restarting worker
2023-03-27 22:48:31,265 - distributed.preloading - INFO - Creating preload: dask_cuda.initialize
2023-03-27 22:48:31,265 - distributed.preloading - INFO - Import preload module: dask_cuda.initialize
/datasets/pentschev/miniconda3/envs/gdf/lib/python3.8/multiprocessing/resource_tracker.py:216: UserWarning: resource_tracker: There appear to be 48 leaked semaphore objects to clean up at shutdown
  warnings.warn('resource_tracker: There appear to be %d '
