2023-07-22 06:48:50,206 - distributed.preloading - INFO - Creating preload: dask_cuda.initialize
2023-07-22 06:48:50,206 - distributed.preloading - INFO - Import preload module: dask_cuda.initialize
2023-07-22 06:48:50,304 - distributed.preloading - INFO - Creating preload: dask_cuda.initialize
2023-07-22 06:48:50,304 - distributed.preloading - INFO - Import preload module: dask_cuda.initialize
2023-07-22 06:48:50,338 - distributed.preloading - INFO - Creating preload: dask_cuda.initialize
2023-07-22 06:48:50,338 - distributed.preloading - INFO - Import preload module: dask_cuda.initialize
2023-07-22 06:48:50,377 - distributed.preloading - INFO - Creating preload: dask_cuda.initialize
2023-07-22 06:48:50,377 - distributed.preloading - INFO - Import preload module: dask_cuda.initialize
2023-07-22 06:48:50,382 - distributed.preloading - INFO - Creating preload: dask_cuda.initialize
2023-07-22 06:48:50,382 - distributed.preloading - INFO - Import preload module: dask_cuda.initialize
2023-07-22 06:48:50,390 - distributed.preloading - INFO - Creating preload: dask_cuda.initialize
2023-07-22 06:48:50,390 - distributed.preloading - INFO - Import preload module: dask_cuda.initialize
2023-07-22 06:48:50,422 - distributed.preloading - INFO - Creating preload: dask_cuda.initialize
2023-07-22 06:48:50,422 - distributed.preloading - INFO - Import preload module: dask_cuda.initialize
2023-07-22 06:48:50,431 - distributed.preloading - INFO - Creating preload: dask_cuda.initialize
2023-07-22 06:48:50,432 - distributed.preloading - INFO - Import preload module: dask_cuda.initialize
[dgx13:62770:0:62770] Caught signal 11 (Segmentation fault: address not mapped to object at address 0x450)
==== backtrace (tid:  62770) ====
 0  /opt/conda/envs/gdf/lib/libucs.so.0(ucs_handle_error+0x2fd) [0x7ff0a5590ced]
 1  /opt/conda/envs/gdf/lib/libucs.so.0(+0x2aee4) [0x7ff0a5590ee4]
 2  /opt/conda/envs/gdf/lib/libucs.so.0(+0x2b0aa) [0x7ff0a55910aa]
 3  /usr/lib/x86_64-linux-gnu/libpthread.so.0(+0x14420) [0x7ff148d09420]
 4  /opt/conda/envs/gdf/lib/libucp.so.0(ucp_mem_type_unpack+0x14) [0x7ff0a56106d4]
 5  /opt/conda/envs/gdf/lib/libucp.so.0(ucp_rndv_data_handler+0x4e9) [0x7ff0a5638a29]
 6  /opt/conda/envs/gdf/lib/libuct.so.0(+0x2045f) [0x7ff0a554a45f]
 7  /opt/conda/envs/gdf/lib/libuct.so.0(+0x238c8) [0x7ff0a554d8c8]
 8  /opt/conda/envs/gdf/lib/libucs.so.0(ucs_event_set_wait+0xb9) [0x7ff0a559a399]
 9  /opt/conda/envs/gdf/lib/libuct.so.0(uct_tcp_iface_progress+0x7d) [0x7ff0a554c65d]
10  /opt/conda/envs/gdf/lib/libucp.so.0(ucp_worker_progress+0x5a) [0x7ff0a560d50a]
11  /opt/conda/envs/gdf/lib/python3.9/site-packages/ucp/_libs/ucx_api.cpython-39-x86_64-linux-gnu.so(+0x2b17a) [0x7ff0a56c217a]
12  /opt/conda/envs/gdf/bin/python(+0x13eb08) [0x55b9ed1b9b08]
13  /opt/conda/envs/gdf/bin/python(_PyEval_EvalFrameDefault+0x5f82) [0x55b9ed1aa112]
14  /opt/conda/envs/gdf/bin/python(+0x12827a) [0x55b9ed1a327a]
15  /opt/conda/envs/gdf/bin/python(_PyFunction_Vectorcall+0xd5) [0x55b9ed1b4c05]
16  /opt/conda/envs/gdf/bin/python(_PyEval_EvalFrameDefault+0x68b) [0x55b9ed1a481b]
17  /opt/conda/envs/gdf/bin/python(+0x139ef3) [0x55b9ed1b4ef3]
18  /opt/conda/envs/gdf/bin/python(+0x147a16) [0x55b9ed1c2a16]
19  /opt/conda/envs/gdf/bin/python(+0x2579b1) [0x55b9ed2d29b1]
20  /opt/conda/envs/gdf/bin/python(+0xe5817) [0x55b9ed160817]
21  /opt/conda/envs/gdf/bin/python(+0x130f83) [0x55b9ed1abf83]
22  /opt/conda/envs/gdf/bin/python(_PyEval_EvalFrameDefault+0x5ba6) [0x55b9ed1a9d36]
23  /opt/conda/envs/gdf/bin/python(+0x139ef3) [0x55b9ed1b4ef3]
24  /opt/conda/envs/gdf/bin/python(_PyEval_EvalFrameDefault+0x68b) [0x55b9ed1a481b]
25  /opt/conda/envs/gdf/bin/python(+0x139ef3) [0x55b9ed1b4ef3]
26  /opt/conda/envs/gdf/bin/python(_PyEval_EvalFrameDefault+0x68b) [0x55b9ed1a481b]
27  /opt/conda/envs/gdf/bin/python(+0x139ef3) [0x55b9ed1b4ef3]
28  /opt/conda/envs/gdf/bin/python(_PyEval_EvalFrameDefault+0x68b) [0x55b9ed1a481b]
29  /opt/conda/envs/gdf/bin/python(+0x139ef3) [0x55b9ed1b4ef3]
30  /opt/conda/envs/gdf/bin/python(_PyEval_EvalFrameDefault+0x68b) [0x55b9ed1a481b]
31  /opt/conda/envs/gdf/bin/python(+0x12827a) [0x55b9ed1a327a]
32  /opt/conda/envs/gdf/bin/python(_PyFunction_Vectorcall+0xd5) [0x55b9ed1b4c05]
33  /opt/conda/envs/gdf/bin/python(_PyEval_EvalFrameDefault+0x4e17) [0x55b9ed1a8fa7]
34  /opt/conda/envs/gdf/bin/python(+0x12827a) [0x55b9ed1a327a]
35  /opt/conda/envs/gdf/bin/python(+0x147935) [0x55b9ed1c2935]
36  /opt/conda/envs/gdf/bin/python(PyObject_Call+0xb4) [0x55b9ed1c3104]
37  /opt/conda/envs/gdf/bin/python(+0x20efc8) [0x55b9ed289fc8]
38  /opt/conda/envs/gdf/bin/python(_PyObject_MakeTpCall+0x2fc) [0x55b9ed1ad2bc]
39  /opt/conda/envs/gdf/bin/python(_PyEval_EvalFrameDefault+0x402b) [0x55b9ed1a81bb]
40  /opt/conda/envs/gdf/bin/python(+0x139ef3) [0x55b9ed1b4ef3]
41  /opt/conda/envs/gdf/bin/python(+0x147c72) [0x55b9ed1c2c72]
42  /opt/conda/envs/gdf/bin/python(_PyEval_EvalFrameDefault+0x402b) [0x55b9ed1a81bb]
43  /opt/conda/envs/gdf/bin/python(+0x139ef3) [0x55b9ed1b4ef3]
44  /opt/conda/envs/gdf/bin/python(_PyEval_EvalFrameDefault+0x68b) [0x55b9ed1a481b]
45  /opt/conda/envs/gdf/bin/python(+0x12827a) [0x55b9ed1a327a]
46  /opt/conda/envs/gdf/bin/python(_PyFunction_Vectorcall+0xd5) [0x55b9ed1b4c05]
47  /opt/conda/envs/gdf/bin/python(_PyEval_EvalFrameDefault+0x68b) [0x55b9ed1a481b]
48  /opt/conda/envs/gdf/bin/python(+0x139ef3) [0x55b9ed1b4ef3]
49  /opt/conda/envs/gdf/bin/python(_PyEval_EvalFrameDefault+0x3d8) [0x55b9ed1a4568]
50  /opt/conda/envs/gdf/bin/python(+0x12827a) [0x55b9ed1a327a]
51  /opt/conda/envs/gdf/bin/python(_PyFunction_Vectorcall+0xd5) [0x55b9ed1b4c05]
52  /opt/conda/envs/gdf/bin/python(_PyEval_EvalFrameDefault+0x123b) [0x55b9ed1a53cb]
53  /opt/conda/envs/gdf/bin/python(+0x12827a) [0x55b9ed1a327a]
54  /opt/conda/envs/gdf/bin/python(_PyEval_EvalCodeWithName+0x47) [0x55b9ed1a2f07]
55  /opt/conda/envs/gdf/bin/python(PyEval_EvalCodeEx+0x39) [0x55b9ed1a2eb9]
56  /opt/conda/envs/gdf/bin/python(PyEval_EvalCode+0x1b) [0x55b9ed2538bb]
57  /opt/conda/envs/gdf/bin/python(+0x206adc) [0x55b9ed281adc]
58  /opt/conda/envs/gdf/bin/python(+0x202c24) [0x55b9ed27dc24]
59  /opt/conda/envs/gdf/bin/python(PyRun_StringFlags+0x9d) [0x55b9ed2757ed]
60  /opt/conda/envs/gdf/bin/python(PyRun_SimpleStringFlags+0x3d) [0x55b9ed2756bd]
61  /opt/conda/envs/gdf/bin/python(Py_RunMain+0x262) [0x55b9ed2748a2]
=================================
[dgx13:62767:0:62767] Caught signal 11 (Segmentation fault: address not mapped to object at address 0x450)
==== backtrace (tid:  62767) ====
 0  /opt/conda/envs/gdf/lib/libucs.so.0(ucs_handle_error+0x2fd) [0x7f25e71c7ced]
 1  /opt/conda/envs/gdf/lib/libucs.so.0(+0x2aee4) [0x7f25e71c7ee4]
 2  /opt/conda/envs/gdf/lib/libucs.so.0(+0x2b0aa) [0x7f25e71c80aa]
 3  /usr/lib/x86_64-linux-gnu/libpthread.so.0(+0x14420) [0x7f268a91e420]
 4  /opt/conda/envs/gdf/lib/libucp.so.0(ucp_mem_type_unpack+0x14) [0x7f25e72476d4]
 5  /opt/conda/envs/gdf/lib/libucp.so.0(ucp_rndv_data_handler+0x4e9) [0x7f25e726fa29]
 6  /opt/conda/envs/gdf/lib/libuct.so.0(+0x2045f) [0x7f25e718145f]
 7  /opt/conda/envs/gdf/lib/libuct.so.0(+0x238c8) [0x7f25e71848c8]
 8  /opt/conda/envs/gdf/lib/libucs.so.0(ucs_event_set_wait+0xb9) [0x7f25e71d1399]
 9  /opt/conda/envs/gdf/lib/libuct.so.0(uct_tcp_iface_progress+0x7d) [0x7f25e718365d]
10  /opt/conda/envs/gdf/lib/libucp.so.0(ucp_worker_progress+0x5a) [0x7f25e724450a]
11  /opt/conda/envs/gdf/lib/python3.9/site-packages/ucp/_libs/ucx_api.cpython-39-x86_64-linux-gnu.so(+0x2b17a) [0x7f25e72f917a]
12  /opt/conda/envs/gdf/bin/python(+0x13eb08) [0x562ff6e29b08]
13  /opt/conda/envs/gdf/bin/python(_PyEval_EvalFrameDefault+0x5f82) [0x562ff6e1a112]
14  /opt/conda/envs/gdf/bin/python(+0x12827a) [0x562ff6e1327a]
15  /opt/conda/envs/gdf/bin/python(_PyFunction_Vectorcall+0xd5) [0x562ff6e24c05]
16  /opt/conda/envs/gdf/bin/python(_PyEval_EvalFrameDefault+0x68b) [0x562ff6e1481b]
17  /opt/conda/envs/gdf/bin/python(+0x139ef3) [0x562ff6e24ef3]
18  /opt/conda/envs/gdf/bin/python(+0x147a16) [0x562ff6e32a16]
19  /opt/conda/envs/gdf/bin/python(+0x2579b1) [0x562ff6f429b1]
20  /opt/conda/envs/gdf/bin/python(+0xe5817) [0x562ff6dd0817]
21  /opt/conda/envs/gdf/bin/python(+0x130f83) [0x562ff6e1bf83]
22  /opt/conda/envs/gdf/bin/python(_PyEval_EvalFrameDefault+0x5ba6) [0x562ff6e19d36]
23  /opt/conda/envs/gdf/bin/python(+0x139ef3) [0x562ff6e24ef3]
24  /opt/conda/envs/gdf/bin/python(_PyEval_EvalFrameDefault+0x68b) [0x562ff6e1481b]
25  /opt/conda/envs/gdf/bin/python(+0x139ef3) [0x562ff6e24ef3]
26  /opt/conda/envs/gdf/bin/python(_PyEval_EvalFrameDefault+0x68b) [0x562ff6e1481b]
27  /opt/conda/envs/gdf/bin/python(+0x139ef3) [0x562ff6e24ef3]
28  /opt/conda/envs/gdf/bin/python(_PyEval_EvalFrameDefault+0x68b) [0x562ff6e1481b]
29  /opt/conda/envs/gdf/bin/python(+0x139ef3) [0x562ff6e24ef3]
30  /opt/conda/envs/gdf/bin/python(_PyEval_EvalFrameDefault+0x68b) [0x562ff6e1481b]
31  /opt/conda/envs/gdf/bin/python(+0x12827a) [0x562ff6e1327a]
32  /opt/conda/envs/gdf/bin/python(_PyFunction_Vectorcall+0xd5) [0x562ff6e24c05]
33  /opt/conda/envs/gdf/bin/python(_PyEval_EvalFrameDefault+0x4e17) [0x562ff6e18fa7]
34  /opt/conda/envs/gdf/bin/python(+0x12827a) [0x562ff6e1327a]
35  /opt/conda/envs/gdf/bin/python(+0x147935) [0x562ff6e32935]
36  /opt/conda/envs/gdf/bin/python(PyObject_Call+0xb4) [0x562ff6e33104]
37  /opt/conda/envs/gdf/bin/python(+0x20efc8) [0x562ff6ef9fc8]
38  /opt/conda/envs/gdf/bin/python(_PyObject_MakeTpCall+0x2fc) [0x562ff6e1d2bc]
39  /opt/conda/envs/gdf/bin/python(_PyEval_EvalFrameDefault+0x402b) [0x562ff6e181bb]
40  /opt/conda/envs/gdf/bin/python(+0x139ef3) [0x562ff6e24ef3]
41  /opt/conda/envs/gdf/bin/python(+0x147c72) [0x562ff6e32c72]
42  /opt/conda/envs/gdf/bin/python(_PyEval_EvalFrameDefault+0x402b) [0x562ff6e181bb]
43  /opt/conda/envs/gdf/bin/python(+0x139ef3) [0x562ff6e24ef3]
44  /opt/conda/envs/gdf/bin/python(_PyEval_EvalFrameDefault+0x68b) [0x562ff6e1481b]
45  /opt/conda/envs/gdf/bin/python(+0x12827a) [0x562ff6e1327a]
46  /opt/conda/envs/gdf/bin/python(_PyFunction_Vectorcall+0xd5) [0x562ff6e24c05]
47  /opt/conda/envs/gdf/bin/python(_PyEval_EvalFrameDefault+0x68b) [0x562ff6e1481b]
48  /opt/conda/envs/gdf/bin/python(+0x139ef3) [0x562ff6e24ef3]
49  /opt/conda/envs/gdf/bin/python(_PyEval_EvalFrameDefault+0x3d8) [0x562ff6e14568]
50  /opt/conda/envs/gdf/bin/python(+0x12827a) [0x562ff6e1327a]
51  /opt/conda/envs/gdf/bin/python(_PyFunction_Vectorcall+0xd5) [0x562ff6e24c05]
52  /opt/conda/envs/gdf/bin/python(_PyEval_EvalFrameDefault+0x123b) [0x562ff6e153cb]
53  /opt/conda/envs/gdf/bin/python(+0x12827a) [0x562ff6e1327a]
54  /opt/conda/envs/gdf/bin/python(_PyEval_EvalCodeWithName+0x47) [0x562ff6e12f07]
55  /opt/conda/envs/gdf/bin/python(PyEval_EvalCodeEx+0x39) [0x562ff6e12eb9]
56  /opt/conda/envs/gdf/bin/python(PyEval_EvalCode+0x1b) [0x562ff6ec38bb]
57  /opt/conda/envs/gdf/bin/python(+0x206adc) [0x562ff6ef1adc]
58  /opt/conda/envs/gdf/bin/python(+0x202c24) [0x562ff6eedc24]
59  /opt/conda/envs/gdf/bin/python(PyRun_StringFlags+0x9d) [0x562ff6ee57ed]
60  /opt/conda/envs/gdf/bin/python(PyRun_SimpleStringFlags+0x3d) [0x562ff6ee56bd]
61  /opt/conda/envs/gdf/bin/python(Py_RunMain+0x262) [0x562ff6ee48a2]
=================================
[dgx13:62760:0:62760] Caught signal 11 (Segmentation fault: address not mapped to object at address 0x450)
==== backtrace (tid:  62760) ====
 0  /opt/conda/envs/gdf/lib/libucs.so.0(ucs_handle_error+0x2fd) [0x7fe4f0625ced]
 1  /opt/conda/envs/gdf/lib/libucs.so.0(+0x2aee4) [0x7fe4f0625ee4]
 2  /opt/conda/envs/gdf/lib/libucs.so.0(+0x2b0aa) [0x7fe4f06260aa]
 3  /usr/lib/x86_64-linux-gnu/libpthread.so.0(+0x14420) [0x7fe58fd6e420]
 4  /opt/conda/envs/gdf/lib/libucp.so.0(ucp_mem_type_unpack+0x14) [0x7fe4f06a56d4]
 5  /opt/conda/envs/gdf/lib/libucp.so.0(ucp_rndv_data_handler+0x4e9) [0x7fe4f06cda29]
 6  /opt/conda/envs/gdf/lib/libuct.so.0(+0x2045f) [0x7fe4f05df45f]
 7  /opt/conda/envs/gdf/lib/libuct.so.0(+0x238c8) [0x7fe4f05e28c8]
 8  /opt/conda/envs/gdf/lib/libucs.so.0(ucs_event_set_wait+0xb9) [0x7fe4f062f399]
 9  /opt/conda/envs/gdf/lib/libuct.so.0(uct_tcp_iface_progress+0x7d) [0x7fe4f05e165d]
10  /opt/conda/envs/gdf/lib/libucp.so.0(ucp_worker_progress+0x5a) [0x7fe4f06a250a]
11  /opt/conda/envs/gdf/lib/python3.9/site-packages/ucp/_libs/ucx_api.cpython-39-x86_64-linux-gnu.so(+0x2b17a) [0x7fe4f075717a]
12  /opt/conda/envs/gdf/bin/python(+0x13eb08) [0x564169e3db08]
13  /opt/conda/envs/gdf/bin/python(_PyEval_EvalFrameDefault+0x5f82) [0x564169e2e112]
14  /opt/conda/envs/gdf/bin/python(+0x12827a) [0x564169e2727a]
15  /opt/conda/envs/gdf/bin/python(_PyFunction_Vectorcall+0xd5) [0x564169e38c05]
16  /opt/conda/envs/gdf/bin/python(_PyEval_EvalFrameDefault+0x68b) [0x564169e2881b]
17  /opt/conda/envs/gdf/bin/python(+0x139ef3) [0x564169e38ef3]
18  /opt/conda/envs/gdf/bin/python(+0x147a16) [0x564169e46a16]
19  /opt/conda/envs/gdf/bin/python(+0x2579b1) [0x564169f569b1]
20  /opt/conda/envs/gdf/bin/python(+0xe5817) [0x564169de4817]
21  /opt/conda/envs/gdf/bin/python(+0x130f83) [0x564169e2ff83]
22  /opt/conda/envs/gdf/bin/python(_PyEval_EvalFrameDefault+0x5ba6) [0x564169e2dd36]
23  /opt/conda/envs/gdf/bin/python(+0x139ef3) [0x564169e38ef3]
24  /opt/conda/envs/gdf/bin/python(_PyEval_EvalFrameDefault+0x68b) [0x564169e2881b]
25  /opt/conda/envs/gdf/bin/python(+0x139ef3) [0x564169e38ef3]
26  /opt/conda/envs/gdf/bin/python(_PyEval_EvalFrameDefault+0x68b) [0x564169e2881b]
27  /opt/conda/envs/gdf/bin/python(+0x139ef3) [0x564169e38ef3]
28  /opt/conda/envs/gdf/bin/python(_PyEval_EvalFrameDefault+0x68b) [0x564169e2881b]
29  /opt/conda/envs/gdf/bin/python(+0x139ef3) [0x564169e38ef3]
30  /opt/conda/envs/gdf/bin/python(_PyEval_EvalFrameDefault+0x68b) [0x564169e2881b]
31  /opt/conda/envs/gdf/bin/python(+0x12827a) [0x564169e2727a]
32  /opt/conda/envs/gdf/bin/python(_PyFunction_Vectorcall+0xd5) [0x564169e38c05]
33  /opt/conda/envs/gdf/bin/python(_PyEval_EvalFrameDefault+0x4e17) [0x564169e2cfa7]
34  /opt/conda/envs/gdf/bin/python(+0x12827a) [0x564169e2727a]
35  /opt/conda/envs/gdf/bin/python(+0x147935) [0x564169e46935]
36  /opt/conda/envs/gdf/bin/python(PyObject_Call+0xb4) [0x564169e47104]
37  /opt/conda/envs/gdf/bin/python(+0x20efc8) [0x564169f0dfc8]
38  /opt/conda/envs/gdf/bin/python(_PyObject_MakeTpCall+0x2fc) [0x564169e312bc]
39  /opt/conda/envs/gdf/bin/python(_PyEval_EvalFrameDefault+0x402b) [0x564169e2c1bb]
40  /opt/conda/envs/gdf/bin/python(+0x139ef3) [0x564169e38ef3]
41  /opt/conda/envs/gdf/bin/python(+0x147c72) [0x564169e46c72]
42  /opt/conda/envs/gdf/bin/python(_PyEval_EvalFrameDefault+0x402b) [0x564169e2c1bb]
43  /opt/conda/envs/gdf/bin/python(+0x139ef3) [0x564169e38ef3]
44  /opt/conda/envs/gdf/bin/python(_PyEval_EvalFrameDefault+0x68b) [0x564169e2881b]
45  /opt/conda/envs/gdf/bin/python(+0x12827a) [0x564169e2727a]
46  /opt/conda/envs/gdf/bin/python(_PyFunction_Vectorcall+0xd5) [0x564169e38c05]
47  /opt/conda/envs/gdf/bin/python(_PyEval_EvalFrameDefault+0x68b) [0x564169e2881b]
48  /opt/conda/envs/gdf/bin/python(+0x139ef3) [0x564169e38ef3]
49  /opt/conda/envs/gdf/bin/python(_PyEval_EvalFrameDefault+0x3d8) [0x564169e28568]
50  /opt/conda/envs/gdf/bin/python(+0x12827a) [0x564169e2727a]
51  /opt/conda/envs/gdf/bin/python(_PyFunction_Vectorcall+0xd5) [0x564169e38c05]
52  /opt/conda/envs/gdf/bin/python(_PyEval_EvalFrameDefault+0x123b) [0x564169e293cb]
53  /opt/conda/envs/gdf/bin/python(+0x12827a) [0x564169e2727a]
54  /opt/conda/envs/gdf/bin/python(_PyEval_EvalCodeWithName+0x47) [0x564169e26f07]
55  /opt/conda/envs/gdf/bin/python(PyEval_EvalCodeEx+0x39) [0x564169e26eb9]
56  /opt/conda/envs/gdf/bin/python(PyEval_EvalCode+0x1b) [0x564169ed78bb]
57  /opt/conda/envs/gdf/bin/python(+0x206adc) [0x564169f05adc]
58  /opt/conda/envs/gdf/bin/python(+0x202c24) [0x564169f01c24]
59  /opt/conda/envs/gdf/bin/python(PyRun_StringFlags+0x9d) [0x564169ef97ed]
60  /opt/conda/envs/gdf/bin/python(PyRun_SimpleStringFlags+0x3d) [0x564169ef96bd]
61  /opt/conda/envs/gdf/bin/python(Py_RunMain+0x262) [0x564169ef88a2]
=================================
2023-07-22 06:48:54,170 - distributed.worker - ERROR - Worker stream died during communication: ucx://127.0.0.1:36987
Traceback (most recent call last):
  File "/opt/conda/envs/gdf/lib/python3.9/site-packages/distributed/comm/ucx.py", line 349, in read
    await self.ep.recv(msg)
  File "/opt/conda/envs/gdf/lib/python3.9/site-packages/ucp/core.py", line 725, in recv
    ret = await comm.tag_recv(self._ep, buffer, nbytes, tag, name=log)
ucp._libs.exceptions.UCXCanceled: <[Recv #003] ep: 0x7f7723c5c200, tag: 0x43356ef99aa320f, nbytes: 16, type: <class 'numpy.ndarray'>>: 

During handling of the above exception, another exception occurred:

Traceback (most recent call last):
  File "/opt/conda/envs/gdf/lib/python3.9/site-packages/distributed/worker.py", line 2066, in gather_dep
    response = await get_data_from_worker(
  File "/opt/conda/envs/gdf/lib/python3.9/site-packages/distributed/worker.py", line 2892, in get_data_from_worker
    response = await send_recv(
  File "/opt/conda/envs/gdf/lib/python3.9/site-packages/distributed/core.py", line 1024, in send_recv
    response = await comm.read(deserializers=deserializers)
  File "/opt/conda/envs/gdf/lib/python3.9/site-packages/distributed/utils.py", line 752, in wrapper
    return await func(*args, **kwargs)
  File "/opt/conda/envs/gdf/lib/python3.9/site-packages/distributed/comm/ucx.py", line 367, in read
    raise CommClosedError(
distributed.comm.core.CommClosedError: Connection closed by writer.
Inner exception: UCXCanceled("<[Recv #003] ep: 0x7f7723c5c200, tag: 0x43356ef99aa320f, nbytes: 16, type: <class 'numpy.ndarray'>>: ")
2023-07-22 06:48:54,170 - distributed.worker - ERROR - failed during get data with ucx://127.0.0.1:54803 -> ucx://127.0.0.1:36987
Traceback (most recent call last):
  File "/opt/conda/envs/gdf/lib/python3.9/site-packages/distributed/comm/ucx.py", line 333, in write
    await self.ep.send(each_frame)
  File "/opt/conda/envs/gdf/lib/python3.9/site-packages/ucp/core.py", line 650, in send
    return await comm.tag_send(self._ep, buffer, nbytes, tag, name=log)
ucp._libs.exceptions.UCXError: <[Send #007] ep: 0x7f9da1580240, tag: 0xe62b9048724197b7, nbytes: 50000000, type: <class 'cupy.ndarray'>>: Connection reset by remote peer

During handling of the above exception, another exception occurred:

Traceback (most recent call last):
  File "/opt/conda/envs/gdf/lib/python3.9/site-packages/distributed/worker.py", line 1792, in get_data
    compressed = await comm.write(msg, serializers=serializers)
  File "/opt/conda/envs/gdf/lib/python3.9/site-packages/distributed/utils.py", line 752, in wrapper
    return await func(*args, **kwargs)
  File "/opt/conda/envs/gdf/lib/python3.9/site-packages/distributed/comm/ucx.py", line 337, in write
    raise CommClosedError("While writing, the connection was closed")
distributed.comm.core.CommClosedError: While writing, the connection was closed
2023-07-22 06:48:54,170 - distributed.worker - ERROR - Worker stream died during communication: ucx://127.0.0.1:36987
Traceback (most recent call last):
  File "/opt/conda/envs/gdf/lib/python3.9/site-packages/distributed/comm/ucx.py", line 349, in read
    await self.ep.recv(msg)
  File "/opt/conda/envs/gdf/lib/python3.9/site-packages/ucp/core.py", line 725, in recv
    ret = await comm.tag_recv(self._ep, buffer, nbytes, tag, name=log)
ucp._libs.exceptions.UCXCanceled: <[Recv #003] ep: 0x7fcf413b0140, tag: 0x8abfa3d1bad144d1, nbytes: 16, type: <class 'numpy.ndarray'>>: 

During handling of the above exception, another exception occurred:

Traceback (most recent call last):
  File "/opt/conda/envs/gdf/lib/python3.9/site-packages/distributed/worker.py", line 2066, in gather_dep
    response = await get_data_from_worker(
  File "/opt/conda/envs/gdf/lib/python3.9/site-packages/distributed/worker.py", line 2892, in get_data_from_worker
    response = await send_recv(
  File "/opt/conda/envs/gdf/lib/python3.9/site-packages/distributed/core.py", line 1024, in send_recv
    response = await comm.read(deserializers=deserializers)
  File "/opt/conda/envs/gdf/lib/python3.9/site-packages/distributed/utils.py", line 752, in wrapper
    return await func(*args, **kwargs)
  File "/opt/conda/envs/gdf/lib/python3.9/site-packages/distributed/comm/ucx.py", line 367, in read
    raise CommClosedError(
distributed.comm.core.CommClosedError: Connection closed by writer.
Inner exception: UCXCanceled("<[Recv #003] ep: 0x7fcf413b0140, tag: 0x8abfa3d1bad144d1, nbytes: 16, type: <class 'numpy.ndarray'>>: ")
2023-07-22 06:48:54,171 - distributed.worker - ERROR - Worker stream died during communication: ucx://127.0.0.1:36987
Traceback (most recent call last):
  File "/opt/conda/envs/gdf/lib/python3.9/site-packages/distributed/comm/ucx.py", line 349, in read
    await self.ep.recv(msg)
  File "/opt/conda/envs/gdf/lib/python3.9/site-packages/ucp/core.py", line 725, in recv
    ret = await comm.tag_recv(self._ep, buffer, nbytes, tag, name=log)
ucp._libs.exceptions.UCXCanceled: <[Recv #003] ep: 0x7f7b858cb1c0, tag: 0xf48092ee3e40dc9, nbytes: 16, type: <class 'numpy.ndarray'>>: 

During handling of the above exception, another exception occurred:

Traceback (most recent call last):
  File "/opt/conda/envs/gdf/lib/python3.9/site-packages/distributed/worker.py", line 2066, in gather_dep
    response = await get_data_from_worker(
  File "/opt/conda/envs/gdf/lib/python3.9/site-packages/distributed/worker.py", line 2892, in get_data_from_worker
    response = await send_recv(
  File "/opt/conda/envs/gdf/lib/python3.9/site-packages/distributed/core.py", line 1024, in send_recv
    response = await comm.read(deserializers=deserializers)
  File "/opt/conda/envs/gdf/lib/python3.9/site-packages/distributed/utils.py", line 752, in wrapper
    return await func(*args, **kwargs)
  File "/opt/conda/envs/gdf/lib/python3.9/site-packages/distributed/comm/ucx.py", line 367, in read
    raise CommClosedError(
distributed.comm.core.CommClosedError: Connection closed by writer.
Inner exception: UCXCanceled("<[Recv #003] ep: 0x7f7b858cb1c0, tag: 0xf48092ee3e40dc9, nbytes: 16, type: <class 'numpy.ndarray'>>: ")
2023-07-22 06:48:54,171 - distributed.worker - ERROR - Worker stream died during communication: ucx://127.0.0.1:36987
Traceback (most recent call last):
  File "/opt/conda/envs/gdf/lib/python3.9/site-packages/distributed/comm/ucx.py", line 349, in read
    await self.ep.recv(msg)
  File "/opt/conda/envs/gdf/lib/python3.9/site-packages/ucp/core.py", line 725, in recv
    ret = await comm.tag_recv(self._ep, buffer, nbytes, tag, name=log)
ucp._libs.exceptions.UCXCanceled: <[Recv #003] ep: 0x7fc6d0aef1c0, tag: 0x6d4efd3354f1df9d, nbytes: 16, type: <class 'numpy.ndarray'>>: 

During handling of the above exception, another exception occurred:

Traceback (most recent call last):
  File "/opt/conda/envs/gdf/lib/python3.9/site-packages/distributed/worker.py", line 2066, in gather_dep
    response = await get_data_from_worker(
  File "/opt/conda/envs/gdf/lib/python3.9/site-packages/distributed/worker.py", line 2892, in get_data_from_worker
    response = await send_recv(
  File "/opt/conda/envs/gdf/lib/python3.9/site-packages/distributed/core.py", line 1024, in send_recv
    response = await comm.read(deserializers=deserializers)
  File "/opt/conda/envs/gdf/lib/python3.9/site-packages/distributed/utils.py", line 752, in wrapper
    return await func(*args, **kwargs)
  File "/opt/conda/envs/gdf/lib/python3.9/site-packages/distributed/comm/ucx.py", line 367, in read
    raise CommClosedError(
distributed.comm.core.CommClosedError: Connection closed by writer.
Inner exception: UCXCanceled("<[Recv #003] ep: 0x7fc6d0aef1c0, tag: 0x6d4efd3354f1df9d, nbytes: 16, type: <class 'numpy.ndarray'>>: ")
2023-07-22 06:48:54,172 - distributed.worker - ERROR - Worker stream died during communication: ucx://127.0.0.1:50171
Traceback (most recent call last):
  File "/opt/conda/envs/gdf/lib/python3.9/site-packages/distributed/comm/ucx.py", line 391, in read
    await self.ep.recv(each_frame)
  File "/opt/conda/envs/gdf/lib/python3.9/site-packages/ucp/core.py", line 725, in recv
    ret = await comm.tag_recv(self._ep, buffer, nbytes, tag, name=log)
ucp._libs.exceptions.UCXError: <[Recv #007] ep: 0x7f7723c5c100, tag: 0x1cbee6309a6bbcc9, nbytes: 50000000, type: <class 'rmm._lib.device_buffer.DeviceBuffer'>>: Connection reset by remote peer

During handling of the above exception, another exception occurred:

Traceback (most recent call last):
  File "/opt/conda/envs/gdf/lib/python3.9/site-packages/distributed/worker.py", line 2066, in gather_dep
    response = await get_data_from_worker(
  File "/opt/conda/envs/gdf/lib/python3.9/site-packages/distributed/worker.py", line 2892, in get_data_from_worker
    response = await send_recv(
  File "/opt/conda/envs/gdf/lib/python3.9/site-packages/distributed/core.py", line 1024, in send_recv
    response = await comm.read(deserializers=deserializers)
  File "/opt/conda/envs/gdf/lib/python3.9/site-packages/distributed/utils.py", line 752, in wrapper
    return await func(*args, **kwargs)
  File "/opt/conda/envs/gdf/lib/python3.9/site-packages/distributed/comm/ucx.py", line 397, in read
    raise CommClosedError(
distributed.comm.core.CommClosedError: Connection closed by writer.
Inner exception: UCXError("<[Recv #007] ep: 0x7f7723c5c100, tag: 0x1cbee6309a6bbcc9, nbytes: 50000000, type: <class 'rmm._lib.device_buffer.DeviceBuffer'>>: Connection reset by remote peer")
2023-07-22 06:48:54,172 - distributed.worker - ERROR - failed during get data with ucx://127.0.0.1:42989 -> ucx://127.0.0.1:36987
Traceback (most recent call last):
  File "/opt/conda/envs/gdf/lib/python3.9/site-packages/distributed/comm/ucx.py", line 333, in write
    await self.ep.send(each_frame)
  File "/opt/conda/envs/gdf/lib/python3.9/site-packages/ucp/core.py", line 650, in send
    return await comm.tag_send(self._ep, buffer, nbytes, tag, name=log)
ucp._libs.exceptions.UCXError: <[Send #007] ep: 0x7fcf413b0280, tag: 0xceb25c479d500707, nbytes: 50000000, type: <class 'cupy.ndarray'>>: Connection reset by remote peer

During handling of the above exception, another exception occurred:

Traceback (most recent call last):
  File "/opt/conda/envs/gdf/lib/python3.9/site-packages/distributed/worker.py", line 1792, in get_data
    compressed = await comm.write(msg, serializers=serializers)
  File "/opt/conda/envs/gdf/lib/python3.9/site-packages/distributed/utils.py", line 752, in wrapper
    return await func(*args, **kwargs)
  File "/opt/conda/envs/gdf/lib/python3.9/site-packages/distributed/comm/ucx.py", line 337, in write
    raise CommClosedError("While writing, the connection was closed")
distributed.comm.core.CommClosedError: While writing, the connection was closed
2023-07-22 06:48:54,172 - distributed.worker - ERROR - Worker stream died during communication: ucx://127.0.0.1:36987
Traceback (most recent call last):
  File "/opt/conda/envs/gdf/lib/python3.9/site-packages/distributed/comm/ucx.py", line 349, in read
    await self.ep.recv(msg)
  File "/opt/conda/envs/gdf/lib/python3.9/site-packages/ucp/core.py", line 725, in recv
    ret = await comm.tag_recv(self._ep, buffer, nbytes, tag, name=log)
ucp._libs.exceptions.UCXCanceled: <[Recv #003] ep: 0x7f9da1580140, tag: 0xcd307113848727c1, nbytes: 16, type: <class 'numpy.ndarray'>>: 

During handling of the above exception, another exception occurred:

Traceback (most recent call last):
  File "/opt/conda/envs/gdf/lib/python3.9/site-packages/distributed/worker.py", line 2066, in gather_dep
    response = await get_data_from_worker(
  File "/opt/conda/envs/gdf/lib/python3.9/site-packages/distributed/worker.py", line 2892, in get_data_from_worker
    response = await send_recv(
  File "/opt/conda/envs/gdf/lib/python3.9/site-packages/distributed/core.py", line 1024, in send_recv
    response = await comm.read(deserializers=deserializers)
  File "/opt/conda/envs/gdf/lib/python3.9/site-packages/distributed/utils.py", line 752, in wrapper
    return await func(*args, **kwargs)
  File "/opt/conda/envs/gdf/lib/python3.9/site-packages/distributed/comm/ucx.py", line 367, in read
    raise CommClosedError(
distributed.comm.core.CommClosedError: Connection closed by writer.
Inner exception: UCXCanceled("<[Recv #003] ep: 0x7f9da1580140, tag: 0xcd307113848727c1, nbytes: 16, type: <class 'numpy.ndarray'>>: ")
2023-07-22 06:48:54,173 - distributed.worker - ERROR - failed during get data with ucx://127.0.0.1:42683 -> ucx://127.0.0.1:50171
Traceback (most recent call last):
  File "/opt/conda/envs/gdf/lib/python3.9/site-packages/distributed/comm/ucx.py", line 333, in write
    await self.ep.send(each_frame)
  File "/opt/conda/envs/gdf/lib/python3.9/site-packages/ucp/core.py", line 650, in send
    return await comm.tag_send(self._ep, buffer, nbytes, tag, name=log)
ucp._libs.exceptions.UCXError: <[Send #007] ep: 0x7fc6d0aef2c0, tag: 0xbc6d667d1a2be6ae, nbytes: 50000000, type: <class 'cupy.ndarray'>>: Connection reset by remote peer

During handling of the above exception, another exception occurred:

Traceback (most recent call last):
  File "/opt/conda/envs/gdf/lib/python3.9/site-packages/distributed/worker.py", line 1792, in get_data
    compressed = await comm.write(msg, serializers=serializers)
  File "/opt/conda/envs/gdf/lib/python3.9/site-packages/distributed/utils.py", line 752, in wrapper
    return await func(*args, **kwargs)
  File "/opt/conda/envs/gdf/lib/python3.9/site-packages/distributed/comm/ucx.py", line 337, in write
    raise CommClosedError("While writing, the connection was closed")
distributed.comm.core.CommClosedError: While writing, the connection was closed
2023-07-22 06:48:54,173 - distributed.worker - ERROR - Worker stream died during communication: ucx://127.0.0.1:50171
Traceback (most recent call last):
  File "/opt/conda/envs/gdf/lib/python3.9/site-packages/distributed/comm/ucx.py", line 349, in read
    await self.ep.recv(msg)
  File "/opt/conda/envs/gdf/lib/python3.9/site-packages/ucp/core.py", line 725, in recv
    ret = await comm.tag_recv(self._ep, buffer, nbytes, tag, name=log)
ucp._libs.exceptions.UCXCanceled: <[Recv #003] ep: 0x7f7b858cb100, tag: 0xd0c15523303b02b5, nbytes: 16, type: <class 'numpy.ndarray'>>: 

During handling of the above exception, another exception occurred:

Traceback (most recent call last):
  File "/opt/conda/envs/gdf/lib/python3.9/site-packages/distributed/worker.py", line 2066, in gather_dep
    response = await get_data_from_worker(
  File "/opt/conda/envs/gdf/lib/python3.9/site-packages/distributed/worker.py", line 2892, in get_data_from_worker
    response = await send_recv(
  File "/opt/conda/envs/gdf/lib/python3.9/site-packages/distributed/core.py", line 1024, in send_recv
    response = await comm.read(deserializers=deserializers)
  File "/opt/conda/envs/gdf/lib/python3.9/site-packages/distributed/utils.py", line 752, in wrapper
    return await func(*args, **kwargs)
  File "/opt/conda/envs/gdf/lib/python3.9/site-packages/distributed/comm/ucx.py", line 367, in read
    raise CommClosedError(
distributed.comm.core.CommClosedError: Connection closed by writer.
Inner exception: UCXCanceled("<[Recv #003] ep: 0x7f7b858cb100, tag: 0xd0c15523303b02b5, nbytes: 16, type: <class 'numpy.ndarray'>>: ")
2023-07-22 06:48:54,173 - distributed.worker - ERROR - Worker stream died during communication: ucx://127.0.0.1:50171
Traceback (most recent call last):
  File "/opt/conda/envs/gdf/lib/python3.9/site-packages/distributed/comm/ucx.py", line 349, in read
    await self.ep.recv(msg)
  File "/opt/conda/envs/gdf/lib/python3.9/site-packages/ucp/core.py", line 725, in recv
    ret = await comm.tag_recv(self._ep, buffer, nbytes, tag, name=log)
ucp._libs.exceptions.UCXCanceled: <[Recv #000] ep: 0x7f9da1580200, tag: 0x6eced81d6048c8f4, nbytes: 16, type: <class 'numpy.ndarray'>>: 

During handling of the above exception, another exception occurred:

Traceback (most recent call last):
  File "/opt/conda/envs/gdf/lib/python3.9/site-packages/distributed/comm/core.py", line 329, in connect
    handshake = await wait_for(comm.read(), time_left())
  File "/opt/conda/envs/gdf/lib/python3.9/site-packages/distributed/utils.py", line 1849, in wait_for
    return await asyncio.wait_for(fut, timeout)
  File "/opt/conda/envs/gdf/lib/python3.9/asyncio/tasks.py", line 479, in wait_for
    return fut.result()
  File "/opt/conda/envs/gdf/lib/python3.9/site-packages/distributed/utils.py", line 752, in wrapper
    return await func(*args, **kwargs)
  File "/opt/conda/envs/gdf/lib/python3.9/site-packages/distributed/comm/ucx.py", line 367, in read
    raise CommClosedError(
distributed.comm.core.CommClosedError: Connection closed by writer.
Inner exception: UCXCanceled("<[Recv #000] ep: 0x7f9da1580200, tag: 0x6eced81d6048c8f4, nbytes: 16, type: <class 'numpy.ndarray'>>: ")

The above exception was the direct cause of the following exception:

Traceback (most recent call last):
  File "/opt/conda/envs/gdf/lib/python3.9/site-packages/distributed/worker.py", line 2066, in gather_dep
    response = await get_data_from_worker(
  File "/opt/conda/envs/gdf/lib/python3.9/site-packages/distributed/worker.py", line 2889, in get_data_from_worker
    comm = await rpc.connect(worker)
  File "/opt/conda/envs/gdf/lib/python3.9/site-packages/distributed/core.py", line 1506, in connect
    return await connect_attempt
  File "/opt/conda/envs/gdf/lib/python3.9/site-packages/distributed/core.py", line 1427, in _connect
    comm = await connect(
  File "/opt/conda/envs/gdf/lib/python3.9/site-packages/distributed/comm/core.py", line 334, in connect
    raise OSError(
OSError: Timed out during handshake while connecting to ucx://127.0.0.1:50171 after 30 s
2023-07-22 06:48:54,174 - distributed.worker - ERROR - Worker stream died during communication: ucx://127.0.0.1:50171
Traceback (most recent call last):
  File "/opt/conda/envs/gdf/lib/python3.9/site-packages/distributed/comm/ucx.py", line 349, in read
    await self.ep.recv(msg)
  File "/opt/conda/envs/gdf/lib/python3.9/site-packages/ucp/core.py", line 725, in recv
    ret = await comm.tag_recv(self._ep, buffer, nbytes, tag, name=log)
ucp._libs.exceptions.UCXCanceled: <[Recv #003] ep: 0x7fc6d0aef100, tag: 0xb37e5eb73bad1777, nbytes: 16, type: <class 'numpy.ndarray'>>: 

During handling of the above exception, another exception occurred:

Traceback (most recent call last):
  File "/opt/conda/envs/gdf/lib/python3.9/site-packages/distributed/worker.py", line 2066, in gather_dep
    response = await get_data_from_worker(
  File "/opt/conda/envs/gdf/lib/python3.9/site-packages/distributed/worker.py", line 2892, in get_data_from_worker
    response = await send_recv(
  File "/opt/conda/envs/gdf/lib/python3.9/site-packages/distributed/core.py", line 1024, in send_recv
    response = await comm.read(deserializers=deserializers)
  File "/opt/conda/envs/gdf/lib/python3.9/site-packages/distributed/utils.py", line 752, in wrapper
    return await func(*args, **kwargs)
  File "/opt/conda/envs/gdf/lib/python3.9/site-packages/distributed/comm/ucx.py", line 367, in read
    raise CommClosedError(
distributed.comm.core.CommClosedError: Connection closed by writer.
Inner exception: UCXCanceled("<[Recv #003] ep: 0x7fc6d0aef100, tag: 0xb37e5eb73bad1777, nbytes: 16, type: <class 'numpy.ndarray'>>: ")
2023-07-22 06:48:54,177 - distributed.worker - ERROR - failed during get data with ucx://127.0.0.1:46539 -> ucx://127.0.0.1:36987
Traceback (most recent call last):
  File "/opt/conda/envs/gdf/lib/python3.9/site-packages/distributed/comm/ucx.py", line 333, in write
    await self.ep.send(each_frame)
  File "/opt/conda/envs/gdf/lib/python3.9/site-packages/ucp/core.py", line 650, in send
    return await comm.tag_send(self._ep, buffer, nbytes, tag, name=log)
ucp._libs.exceptions.UCXError: <[Send #007] ep: 0x7f7b858cb300, tag: 0xb2a0239490f5b6b7, nbytes: 50000000, type: <class 'cupy.ndarray'>>: Connection reset by remote peer

During handling of the above exception, another exception occurred:

Traceback (most recent call last):
  File "/opt/conda/envs/gdf/lib/python3.9/site-packages/distributed/worker.py", line 1792, in get_data
    compressed = await comm.write(msg, serializers=serializers)
  File "/opt/conda/envs/gdf/lib/python3.9/site-packages/distributed/utils.py", line 752, in wrapper
    return await func(*args, **kwargs)
  File "/opt/conda/envs/gdf/lib/python3.9/site-packages/distributed/comm/ucx.py", line 337, in write
    raise CommClosedError("While writing, the connection was closed")
distributed.comm.core.CommClosedError: While writing, the connection was closed
2023-07-22 06:48:54,178 - distributed.worker - ERROR - failed during get data with ucx://127.0.0.1:46539 -> ucx://127.0.0.1:50171
Traceback (most recent call last):
  File "/opt/conda/envs/gdf/lib/python3.9/site-packages/distributed/comm/ucx.py", line 333, in write
    await self.ep.send(each_frame)
  File "/opt/conda/envs/gdf/lib/python3.9/site-packages/ucp/core.py", line 650, in send
    return await comm.tag_send(self._ep, buffer, nbytes, tag, name=log)
ucp._libs.exceptions.UCXError: <[Send #007] ep: 0x7f7b858cb240, tag: 0xf5ca931c4a6a6b1d, nbytes: 50000000, type: <class 'cupy.ndarray'>>: Connection reset by remote peer

During handling of the above exception, another exception occurred:

Traceback (most recent call last):
  File "/opt/conda/envs/gdf/lib/python3.9/site-packages/distributed/worker.py", line 1792, in get_data
    compressed = await comm.write(msg, serializers=serializers)
  File "/opt/conda/envs/gdf/lib/python3.9/site-packages/distributed/utils.py", line 752, in wrapper
    return await func(*args, **kwargs)
  File "/opt/conda/envs/gdf/lib/python3.9/site-packages/distributed/comm/ucx.py", line 337, in write
    raise CommClosedError("While writing, the connection was closed")
distributed.comm.core.CommClosedError: While writing, the connection was closed
2023-07-22 06:48:54,178 - distributed.worker - ERROR - failed during get data with ucx://127.0.0.1:46539 -> ucx://127.0.0.1:37899
Traceback (most recent call last):
  File "/opt/conda/envs/gdf/lib/python3.9/site-packages/distributed/comm/ucx.py", line 333, in write
    await self.ep.send(each_frame)
  File "/opt/conda/envs/gdf/lib/python3.9/site-packages/ucp/core.py", line 650, in send
    return await comm.tag_send(self._ep, buffer, nbytes, tag, name=log)
ucp._libs.exceptions.UCXError: <[Send #007] ep: 0x7f7b858cb2c0, tag: 0x2f1c4d1b3b68e2c5, nbytes: 50000000, type: <class 'cupy.ndarray'>>: Connection reset by remote peer

During handling of the above exception, another exception occurred:

Traceback (most recent call last):
  File "/opt/conda/envs/gdf/lib/python3.9/site-packages/distributed/worker.py", line 1792, in get_data
    compressed = await comm.write(msg, serializers=serializers)
  File "/opt/conda/envs/gdf/lib/python3.9/site-packages/distributed/utils.py", line 752, in wrapper
    return await func(*args, **kwargs)
  File "/opt/conda/envs/gdf/lib/python3.9/site-packages/distributed/comm/ucx.py", line 337, in write
    raise CommClosedError("While writing, the connection was closed")
distributed.comm.core.CommClosedError: While writing, the connection was closed
2023-07-22 06:48:54,179 - distributed.worker - ERROR - Worker stream died during communication: ucx://127.0.0.1:37899
Traceback (most recent call last):
  File "/opt/conda/envs/gdf/lib/python3.9/site-packages/distributed/comm/ucx.py", line 349, in read
    await self.ep.recv(msg)
  File "/opt/conda/envs/gdf/lib/python3.9/site-packages/ucp/core.py", line 725, in recv
    ret = await comm.tag_recv(self._ep, buffer, nbytes, tag, name=log)
ucp._libs.exceptions.UCXCanceled: <[Recv #008] ep: 0x7f7b858cb180, tag: 0x712689fb01ee705d, nbytes: 16, type: <class 'numpy.ndarray'>>: 

During handling of the above exception, another exception occurred:

Traceback (most recent call last):
  File "/opt/conda/envs/gdf/lib/python3.9/site-packages/distributed/worker.py", line 2066, in gather_dep
    response = await get_data_from_worker(
  File "/opt/conda/envs/gdf/lib/python3.9/site-packages/distributed/worker.py", line 2892, in get_data_from_worker
    response = await send_recv(
  File "/opt/conda/envs/gdf/lib/python3.9/site-packages/distributed/core.py", line 1024, in send_recv
    response = await comm.read(deserializers=deserializers)
  File "/opt/conda/envs/gdf/lib/python3.9/site-packages/distributed/utils.py", line 752, in wrapper
    return await func(*args, **kwargs)
  File "/opt/conda/envs/gdf/lib/python3.9/site-packages/distributed/comm/ucx.py", line 367, in read
    raise CommClosedError(
distributed.comm.core.CommClosedError: Connection closed by writer.
Inner exception: UCXCanceled("<[Recv #008] ep: 0x7f7b858cb180, tag: 0x712689fb01ee705d, nbytes: 16, type: <class 'numpy.ndarray'>>: ")
2023-07-22 06:48:54,178 - distributed.worker - ERROR - failed during get data with ucx://127.0.0.1:42989 -> ucx://127.0.0.1:37899
Traceback (most recent call last):
  File "/opt/conda/envs/gdf/lib/python3.9/site-packages/distributed/comm/ucx.py", line 333, in write
    await self.ep.send(each_frame)
  File "/opt/conda/envs/gdf/lib/python3.9/site-packages/ucp/core.py", line 650, in send
    return await comm.tag_send(self._ep, buffer, nbytes, tag, name=log)
ucp._libs.exceptions.UCXError: <[Send #007] ep: 0x7fcf413b0240, tag: 0x2d08e65f3884ac0a, nbytes: 50000000, type: <class 'cupy.ndarray'>>: Connection reset by remote peer

During handling of the above exception, another exception occurred:

Traceback (most recent call last):
  File "/opt/conda/envs/gdf/lib/python3.9/site-packages/distributed/worker.py", line 1792, in get_data
    compressed = await comm.write(msg, serializers=serializers)
  File "/opt/conda/envs/gdf/lib/python3.9/site-packages/distributed/utils.py", line 752, in wrapper
    return await func(*args, **kwargs)
  File "/opt/conda/envs/gdf/lib/python3.9/site-packages/distributed/comm/ucx.py", line 337, in write
    raise CommClosedError("While writing, the connection was closed")
distributed.comm.core.CommClosedError: While writing, the connection was closed
2023-07-22 06:48:54,185 - distributed.worker - ERROR - Worker stream died during communication: ucx://127.0.0.1:50171
Traceback (most recent call last):
  File "/opt/conda/envs/gdf/lib/python3.9/site-packages/distributed/core.py", line 1427, in _connect
    comm = await connect(
  File "/opt/conda/envs/gdf/lib/python3.9/site-packages/distributed/comm/core.py", line 292, in connect
    comm = await wait_for(
  File "/opt/conda/envs/gdf/lib/python3.9/site-packages/distributed/utils.py", line 1849, in wait_for
    return await asyncio.wait_for(fut, timeout)
  File "/opt/conda/envs/gdf/lib/python3.9/asyncio/tasks.py", line 466, in wait_for
    await waiter
asyncio.exceptions.CancelledError

During handling of the above exception, another exception occurred:

Traceback (most recent call last):
  File "/opt/conda/envs/gdf/lib/python3.9/site-packages/distributed/worker.py", line 2066, in gather_dep
    response = await get_data_from_worker(
  File "/opt/conda/envs/gdf/lib/python3.9/site-packages/distributed/worker.py", line 2889, in get_data_from_worker
    comm = await rpc.connect(worker)
  File "/opt/conda/envs/gdf/lib/python3.9/site-packages/distributed/core.py", line 1506, in connect
    return await connect_attempt
  File "/opt/conda/envs/gdf/lib/python3.9/site-packages/distributed/core.py", line 1450, in _connect
    raise CommClosedError(reason)
distributed.comm.core.CommClosedError: Address removed.
2023-07-22 06:48:54,250 - distributed.nanny - WARNING - Restarting worker
2023-07-22 06:48:54,283 - distributed.nanny - WARNING - Restarting worker
2023-07-22 06:48:54,325 - distributed.nanny - WARNING - Restarting worker
[dgx13:62773:0:62773] Caught signal 11 (Segmentation fault: address not mapped to object at address 0x450)
==== backtrace (tid:  62773) ====
 0  /opt/conda/envs/gdf/lib/libucs.so.0(ucs_handle_error+0x2fd) [0x7f7ba0036ced]
 1  /opt/conda/envs/gdf/lib/libucs.so.0(+0x2aee4) [0x7f7ba0036ee4]
 2  /opt/conda/envs/gdf/lib/libucs.so.0(+0x2b0aa) [0x7f7ba00370aa]
 3  /usr/lib/x86_64-linux-gnu/libpthread.so.0(+0x14420) [0x7f7c3f29a420]
 4  /opt/conda/envs/gdf/lib/libucp.so.0(ucp_mem_type_unpack+0x14) [0x7f7b85b726d4]
 5  /opt/conda/envs/gdf/lib/libucp.so.0(ucp_rndv_data_handler+0x4e9) [0x7f7b85b9aa29]
 6  /opt/conda/envs/gdf/lib/libuct.so.0(+0x2045f) [0x7f7b85b0c45f]
 7  /opt/conda/envs/gdf/lib/libuct.so.0(+0x238c8) [0x7f7b85b0f8c8]
 8  /opt/conda/envs/gdf/lib/libucs.so.0(ucs_event_set_wait+0xb9) [0x7f7ba0040399]
 9  /opt/conda/envs/gdf/lib/libuct.so.0(uct_tcp_iface_progress+0x7d) [0x7f7b85b0e65d]
10  /opt/conda/envs/gdf/lib/libucp.so.0(ucp_worker_progress+0x5a) [0x7f7b85b6f50a]
11  /opt/conda/envs/gdf/lib/python3.9/site-packages/ucp/_libs/ucx_api.cpython-39-x86_64-linux-gnu.so(+0x2b17a) [0x7f7b85c2417a]
12  /opt/conda/envs/gdf/bin/python(+0x13eb08) [0x55b945ea0b08]
13  /opt/conda/envs/gdf/bin/python(_PyEval_EvalFrameDefault+0x5f82) [0x55b945e91112]
14  /opt/conda/envs/gdf/bin/python(+0x12827a) [0x55b945e8a27a]
15  /opt/conda/envs/gdf/bin/python(_PyFunction_Vectorcall+0xd5) [0x55b945e9bc05]
16  /opt/conda/envs/gdf/bin/python(_PyEval_EvalFrameDefault+0x68b) [0x55b945e8b81b]
17  /opt/conda/envs/gdf/bin/python(+0x14e70e) [0x55b945eb070e]
18  /opt/conda/envs/gdf/lib/python3.9/lib-dynload/_asyncio.cpython-39-x86_64-linux-gnu.so(+0x82fe) [0x7f7bbff092fe]
19  /opt/conda/envs/gdf/bin/python(_PyObject_MakeTpCall+0x2fc) [0x55b945e942bc]
20  /opt/conda/envs/gdf/bin/python(+0xe5817) [0x55b945e47817]
21  /opt/conda/envs/gdf/bin/python(+0x130f83) [0x55b945e92f83]
22  /opt/conda/envs/gdf/bin/python(_PyEval_EvalFrameDefault+0x5ba6) [0x55b945e90d36]
23  /opt/conda/envs/gdf/bin/python(+0x139ef3) [0x55b945e9bef3]
24  /opt/conda/envs/gdf/bin/python(_PyEval_EvalFrameDefault+0x68b) [0x55b945e8b81b]
25  /opt/conda/envs/gdf/bin/python(+0x139ef3) [0x55b945e9bef3]
26  /opt/conda/envs/gdf/bin/python(_PyEval_EvalFrameDefault+0x68b) [0x55b945e8b81b]
27  /opt/conda/envs/gdf/bin/python(+0x139ef3) [0x55b945e9bef3]
28  /opt/conda/envs/gdf/bin/python(_PyEval_EvalFrameDefault+0x68b) [0x55b945e8b81b]
29  /opt/conda/envs/gdf/bin/python(+0x139ef3) [0x55b945e9bef3]
30  /opt/conda/envs/gdf/bin/python(_PyEval_EvalFrameDefault+0x68b) [0x55b945e8b81b]
31  /opt/conda/envs/gdf/bin/python(+0x12827a) [0x55b945e8a27a]
32  /opt/conda/envs/gdf/bin/python(_PyFunction_Vectorcall+0xd5) [0x55b945e9bc05]
33  /opt/conda/envs/gdf/bin/python(_PyEval_EvalFrameDefault+0x4e17) [0x55b945e8ffa7]
34  /opt/conda/envs/gdf/bin/python(+0x12827a) [0x55b945e8a27a]
35  /opt/conda/envs/gdf/bin/python(+0x147935) [0x55b945ea9935]
36  /opt/conda/envs/gdf/bin/python(PyObject_Call+0xb4) [0x55b945eaa104]
37  /opt/conda/envs/gdf/bin/python(+0x20efc8) [0x55b945f70fc8]
38  /opt/conda/envs/gdf/bin/python(_PyObject_MakeTpCall+0x2fc) [0x55b945e942bc]
39  /opt/conda/envs/gdf/bin/python(_PyEval_EvalFrameDefault+0x402b) [0x55b945e8f1bb]
40  /opt/conda/envs/gdf/bin/python(+0x139ef3) [0x55b945e9bef3]
41  /opt/conda/envs/gdf/bin/python(+0x147c72) [0x55b945ea9c72]
42  /opt/conda/envs/gdf/bin/python(_PyEval_EvalFrameDefault+0x402b) [0x55b945e8f1bb]
43  /opt/conda/envs/gdf/bin/python(+0x139ef3) [0x55b945e9bef3]
44  /opt/conda/envs/gdf/bin/python(_PyEval_EvalFrameDefault+0x68b) [0x55b945e8b81b]
45  /opt/conda/envs/gdf/bin/python(+0x12827a) [0x55b945e8a27a]
46  /opt/conda/envs/gdf/bin/python(_PyFunction_Vectorcall+0xd5) [0x55b945e9bc05]
47  /opt/conda/envs/gdf/bin/python(_PyEval_EvalFrameDefault+0x68b) [0x55b945e8b81b]
48  /opt/conda/envs/gdf/bin/python(+0x139ef3) [0x55b945e9bef3]
49  /opt/conda/envs/gdf/bin/python(_PyEval_EvalFrameDefault+0x3d8) [0x55b945e8b568]
50  /opt/conda/envs/gdf/bin/python(+0x12827a) [0x55b945e8a27a]
51  /opt/conda/envs/gdf/bin/python(_PyFunction_Vectorcall+0xd5) [0x55b945e9bc05]
52  /opt/conda/envs/gdf/bin/python(_PyEval_EvalFrameDefault+0x123b) [0x55b945e8c3cb]
53  /opt/conda/envs/gdf/bin/python(+0x12827a) [0x55b945e8a27a]
54  /opt/conda/envs/gdf/bin/python(_PyEval_EvalCodeWithName+0x47) [0x55b945e89f07]
55  /opt/conda/envs/gdf/bin/python(PyEval_EvalCodeEx+0x39) [0x55b945e89eb9]
56  /opt/conda/envs/gdf/bin/python(PyEval_EvalCode+0x1b) [0x55b945f3a8bb]
57  /opt/conda/envs/gdf/bin/python(+0x206adc) [0x55b945f68adc]
58  /opt/conda/envs/gdf/bin/python(+0x202c24) [0x55b945f64c24]
59  /opt/conda/envs/gdf/bin/python(PyRun_StringFlags+0x9d) [0x55b945f5c7ed]
60  /opt/conda/envs/gdf/bin/python(PyRun_SimpleStringFlags+0x3d) [0x55b945f5c6bd]
61  /opt/conda/envs/gdf/bin/python(Py_RunMain+0x262) [0x55b945f5b8a2]
=================================
2023-07-22 06:48:54,573 - distributed.worker - ERROR - Worker stream died during communication: ucx://127.0.0.1:46539
Traceback (most recent call last):
  File "/opt/conda/envs/gdf/lib/python3.9/site-packages/distributed/comm/ucx.py", line 349, in read
    await self.ep.recv(msg)
  File "/opt/conda/envs/gdf/lib/python3.9/site-packages/ucp/core.py", line 725, in recv
    ret = await comm.tag_recv(self._ep, buffer, nbytes, tag, name=log)
ucp._libs.exceptions.UCXCanceled: <[Recv #008] ep: 0x7f9da1580180, tag: 0xee80a4b91aef9f2f, nbytes: 16, type: <class 'numpy.ndarray'>>: 

During handling of the above exception, another exception occurred:

Traceback (most recent call last):
  File "/opt/conda/envs/gdf/lib/python3.9/site-packages/distributed/worker.py", line 2066, in gather_dep
    response = await get_data_from_worker(
  File "/opt/conda/envs/gdf/lib/python3.9/site-packages/distributed/worker.py", line 2892, in get_data_from_worker
    response = await send_recv(
  File "/opt/conda/envs/gdf/lib/python3.9/site-packages/distributed/core.py", line 1024, in send_recv
    response = await comm.read(deserializers=deserializers)
  File "/opt/conda/envs/gdf/lib/python3.9/site-packages/distributed/utils.py", line 752, in wrapper
    return await func(*args, **kwargs)
  File "/opt/conda/envs/gdf/lib/python3.9/site-packages/distributed/comm/ucx.py", line 367, in read
    raise CommClosedError(
distributed.comm.core.CommClosedError: Connection closed by writer.
Inner exception: UCXCanceled("<[Recv #008] ep: 0x7f9da1580180, tag: 0xee80a4b91aef9f2f, nbytes: 16, type: <class 'numpy.ndarray'>>: ")
2023-07-22 06:48:54,573 - distributed.worker - ERROR - Worker stream died during communication: ucx://127.0.0.1:46539
Traceback (most recent call last):
  File "/opt/conda/envs/gdf/lib/python3.9/site-packages/distributed/comm/ucx.py", line 349, in read
    await self.ep.recv(msg)
  File "/opt/conda/envs/gdf/lib/python3.9/site-packages/ucp/core.py", line 725, in recv
    ret = await comm.tag_recv(self._ep, buffer, nbytes, tag, name=log)
ucp._libs.exceptions.UCXCanceled: <[Recv #027] ep: 0x7fcf413b0100, tag: 0xc8bfc9b946231d95, nbytes: 16, type: <class 'numpy.ndarray'>>: 

During handling of the above exception, another exception occurred:

Traceback (most recent call last):
  File "/opt/conda/envs/gdf/lib/python3.9/site-packages/distributed/worker.py", line 2066, in gather_dep
    response = await get_data_from_worker(
  File "/opt/conda/envs/gdf/lib/python3.9/site-packages/distributed/worker.py", line 2892, in get_data_from_worker
    response = await send_recv(
  File "/opt/conda/envs/gdf/lib/python3.9/site-packages/distributed/core.py", line 1024, in send_recv
    response = await comm.read(deserializers=deserializers)
  File "/opt/conda/envs/gdf/lib/python3.9/site-packages/distributed/utils.py", line 752, in wrapper
    return await func(*args, **kwargs)
  File "/opt/conda/envs/gdf/lib/python3.9/site-packages/distributed/comm/ucx.py", line 367, in read
    raise CommClosedError(
distributed.comm.core.CommClosedError: Connection closed by writer.
Inner exception: UCXCanceled("<[Recv #027] ep: 0x7fcf413b0100, tag: 0xc8bfc9b946231d95, nbytes: 16, type: <class 'numpy.ndarray'>>: ")
2023-07-22 06:48:54,576 - distributed.worker - ERROR - failed during get data with ucx://127.0.0.1:54519 -> ucx://127.0.0.1:46539
Traceback (most recent call last):
  File "/opt/conda/envs/gdf/lib/python3.9/site-packages/distributed/comm/ucx.py", line 333, in write
    await self.ep.send(each_frame)
  File "/opt/conda/envs/gdf/lib/python3.9/site-packages/ucp/core.py", line 650, in send
    return await comm.tag_send(self._ep, buffer, nbytes, tag, name=log)
ucp._libs.exceptions.UCXError: <[Send #012] ep: 0x7f7723c5c100, tag: 0xd94612c729175d6f, nbytes: 50000000, type: <class 'cupy.ndarray'>>: Connection reset by remote peer

During handling of the above exception, another exception occurred:

Traceback (most recent call last):
  File "/opt/conda/envs/gdf/lib/python3.9/site-packages/distributed/worker.py", line 1792, in get_data
    compressed = await comm.write(msg, serializers=serializers)
  File "/opt/conda/envs/gdf/lib/python3.9/site-packages/distributed/utils.py", line 752, in wrapper
    return await func(*args, **kwargs)
  File "/opt/conda/envs/gdf/lib/python3.9/site-packages/distributed/comm/ucx.py", line 337, in write
    raise CommClosedError("While writing, the connection was closed")
distributed.comm.core.CommClosedError: While writing, the connection was closed
2023-07-22 06:48:54,580 - distributed.worker - ERROR - Worker stream died during communication: ucx://127.0.0.1:46539
Traceback (most recent call last):
  File "/opt/conda/envs/gdf/lib/python3.9/site-packages/distributed/comm/ucx.py", line 466, in connect
    ep = await ucp.create_endpoint(ip, port)
  File "/opt/conda/envs/gdf/lib/python3.9/site-packages/ucp/core.py", line 1004, in create_endpoint
    return await _get_ctx().create_endpoint(
  File "/opt/conda/envs/gdf/lib/python3.9/site-packages/ucp/core.py", line 316, in create_endpoint
    peer_info = await exchange_peer_info(
  File "/opt/conda/envs/gdf/lib/python3.9/site-packages/ucp/core.py", line 54, in exchange_peer_info
    await comm.stream_recv(endpoint, peer_info_arr, peer_info_arr.nbytes)
ucp._libs.exceptions.UCXError: <stream_recv>: Connection reset by remote peer

During handling of the above exception, another exception occurred:

Traceback (most recent call last):
  File "/opt/conda/envs/gdf/lib/python3.9/site-packages/distributed/comm/core.py", line 292, in connect
    comm = await wait_for(
  File "/opt/conda/envs/gdf/lib/python3.9/site-packages/distributed/utils.py", line 1849, in wait_for
    return await asyncio.wait_for(fut, timeout)
  File "/opt/conda/envs/gdf/lib/python3.9/asyncio/tasks.py", line 479, in wait_for
    return fut.result()
  File "/opt/conda/envs/gdf/lib/python3.9/site-packages/distributed/comm/ucx.py", line 468, in connect
    raise CommClosedError("Connection closed before handshake completed")
distributed.comm.core.CommClosedError: Connection closed before handshake completed

During handling of the above exception, another exception occurred:

Traceback (most recent call last):
  File "/opt/conda/envs/gdf/lib/python3.9/site-packages/distributed/core.py", line 1427, in _connect
    comm = await connect(
  File "/opt/conda/envs/gdf/lib/python3.9/site-packages/distributed/comm/core.py", line 316, in connect
    await asyncio.sleep(backoff)
  File "/opt/conda/envs/gdf/lib/python3.9/asyncio/tasks.py", line 652, in sleep
    return await future
asyncio.exceptions.CancelledError

During handling of the above exception, another exception occurred:

Traceback (most recent call last):
  File "/opt/conda/envs/gdf/lib/python3.9/site-packages/distributed/worker.py", line 2066, in gather_dep
    response = await get_data_from_worker(
  File "/opt/conda/envs/gdf/lib/python3.9/site-packages/distributed/worker.py", line 2889, in get_data_from_worker
    comm = await rpc.connect(worker)
  File "/opt/conda/envs/gdf/lib/python3.9/site-packages/distributed/core.py", line 1506, in connect
    return await connect_attempt
  File "/opt/conda/envs/gdf/lib/python3.9/site-packages/distributed/core.py", line 1450, in _connect
    raise CommClosedError(reason)
distributed.comm.core.CommClosedError: Address removed.
2023-07-22 06:48:54,605 - distributed.worker - ERROR - failed during get data with ucx://127.0.0.1:42683 -> ucx://127.0.0.1:46539
Traceback (most recent call last):
  File "/opt/conda/envs/gdf/lib/python3.9/site-packages/distributed/comm/ucx.py", line 333, in write
    await self.ep.send(each_frame)
  File "/opt/conda/envs/gdf/lib/python3.9/site-packages/ucp/core.py", line 650, in send
    return await comm.tag_send(self._ep, buffer, nbytes, tag, name=log)
ucp._libs.exceptions.UCXError: <[Send #012] ep: 0x7fc6d0aef100, tag: 0x198321efff2cc050, nbytes: 50000000, type: <class 'cupy.ndarray'>>: Connection reset by remote peer

During handling of the above exception, another exception occurred:

Traceback (most recent call last):
  File "/opt/conda/envs/gdf/lib/python3.9/site-packages/distributed/worker.py", line 1792, in get_data
    compressed = await comm.write(msg, serializers=serializers)
  File "/opt/conda/envs/gdf/lib/python3.9/site-packages/distributed/utils.py", line 752, in wrapper
    return await func(*args, **kwargs)
  File "/opt/conda/envs/gdf/lib/python3.9/site-packages/distributed/comm/ucx.py", line 337, in write
    raise CommClosedError("While writing, the connection was closed")
distributed.comm.core.CommClosedError: While writing, the connection was closed
2023-07-22 06:48:54,616 - distributed.nanny - WARNING - Restarting worker
2023-07-22 06:48:55,768 - distributed.preloading - INFO - Creating preload: dask_cuda.initialize
2023-07-22 06:48:55,768 - distributed.preloading - INFO - Import preload module: dask_cuda.initialize
2023-07-22 06:48:55,769 - distributed.preloading - INFO - Creating preload: dask_cuda.initialize
2023-07-22 06:48:55,769 - distributed.preloading - INFO - Import preload module: dask_cuda.initialize
2023-07-22 06:48:55,797 - distributed.preloading - INFO - Creating preload: dask_cuda.initialize
2023-07-22 06:48:55,797 - distributed.preloading - INFO - Import preload module: dask_cuda.initialize
2023-07-22 06:48:56,012 - distributed.preloading - INFO - Creating preload: dask_cuda.initialize
2023-07-22 06:48:56,012 - distributed.preloading - INFO - Import preload module: dask_cuda.initialize
[dgx13:62918:0:62918] Caught signal 11 (Segmentation fault: address not mapped to object at address 0x450)
==== backtrace (tid:  62918) ====
 0  /opt/conda/envs/gdf/lib/libucs.so.0(ucs_handle_error+0x2fd) [0x7eff9ceafced]
 1  /opt/conda/envs/gdf/lib/libucs.so.0(+0x2aee4) [0x7eff9ceafee4]
 2  /opt/conda/envs/gdf/lib/libucs.so.0(+0x2b0aa) [0x7eff9ceb00aa]
 3  /usr/lib/x86_64-linux-gnu/libpthread.so.0(+0x14420) [0x7f002e473420]
 4  /opt/conda/envs/gdf/lib/libucp.so.0(ucp_mem_type_unpack+0x14) [0x7eff9cf2f6d4]
 5  /opt/conda/envs/gdf/lib/libucp.so.0(ucp_rndv_data_handler+0x4e9) [0x7eff9cf57a29]
 6  /opt/conda/envs/gdf/lib/libuct.so.0(+0x2045f) [0x7eff9ce6945f]
 7  /opt/conda/envs/gdf/lib/libuct.so.0(+0x238c8) [0x7eff9ce6c8c8]
 8  /opt/conda/envs/gdf/lib/libucs.so.0(ucs_event_set_wait+0xb9) [0x7eff9ceb9399]
 9  /opt/conda/envs/gdf/lib/libuct.so.0(uct_tcp_iface_progress+0x7d) [0x7eff9ce6b65d]
10  /opt/conda/envs/gdf/lib/libucp.so.0(ucp_worker_progress+0x5a) [0x7eff9cf2c50a]
11  /opt/conda/envs/gdf/lib/python3.9/site-packages/ucp/_libs/ucx_api.cpython-39-x86_64-linux-gnu.so(+0x2b17a) [0x7eff9cfe117a]
12  /opt/conda/envs/gdf/bin/python(+0x13eb08) [0x5603941e6b08]
13  /opt/conda/envs/gdf/bin/python(_PyEval_EvalFrameDefault+0x5f82) [0x5603941d7112]
14  /opt/conda/envs/gdf/bin/python(+0x12827a) [0x5603941d027a]
15  /opt/conda/envs/gdf/bin/python(_PyFunction_Vectorcall+0xd5) [0x5603941e1c05]
16  /opt/conda/envs/gdf/bin/python(_PyEval_EvalFrameDefault+0x68b) [0x5603941d181b]
17  /opt/conda/envs/gdf/bin/python(+0x139ef3) [0x5603941e1ef3]
18  /opt/conda/envs/gdf/bin/python(+0x147a16) [0x5603941efa16]
19  /opt/conda/envs/gdf/bin/python(+0x2579b1) [0x5603942ff9b1]
20  /opt/conda/envs/gdf/bin/python(+0xe5817) [0x56039418d817]
21  /opt/conda/envs/gdf/bin/python(+0x130f83) [0x5603941d8f83]
22  /opt/conda/envs/gdf/bin/python(_PyEval_EvalFrameDefault+0x5ba6) [0x5603941d6d36]
23  /opt/conda/envs/gdf/bin/python(+0x139ef3) [0x5603941e1ef3]
24  /opt/conda/envs/gdf/bin/python(_PyEval_EvalFrameDefault+0x68b) [0x5603941d181b]
25  /opt/conda/envs/gdf/bin/python(+0x139ef3) [0x5603941e1ef3]
26  /opt/conda/envs/gdf/bin/python(_PyEval_EvalFrameDefault+0x68b) [0x5603941d181b]
27  /opt/conda/envs/gdf/bin/python(+0x139ef3) [0x5603941e1ef3]
28  /opt/conda/envs/gdf/bin/python(_PyEval_EvalFrameDefault+0x68b) [0x5603941d181b]
29  /opt/conda/envs/gdf/bin/python(+0x139ef3) [0x5603941e1ef3]
30  /opt/conda/envs/gdf/bin/python(_PyEval_EvalFrameDefault+0x68b) [0x5603941d181b]
31  /opt/conda/envs/gdf/bin/python(+0x12827a) [0x5603941d027a]
32  /opt/conda/envs/gdf/bin/python(_PyFunction_Vectorcall+0xd5) [0x5603941e1c05]
33  /opt/conda/envs/gdf/bin/python(_PyEval_EvalFrameDefault+0x4e17) [0x5603941d5fa7]
34  /opt/conda/envs/gdf/bin/python(+0x12827a) [0x5603941d027a]
35  /opt/conda/envs/gdf/bin/python(+0x147935) [0x5603941ef935]
36  /opt/conda/envs/gdf/bin/python(PyObject_Call+0xb4) [0x5603941f0104]
37  /opt/conda/envs/gdf/bin/python(+0x20efc8) [0x5603942b6fc8]
38  /opt/conda/envs/gdf/bin/python(_PyObject_MakeTpCall+0x2fc) [0x5603941da2bc]
39  /opt/conda/envs/gdf/bin/python(_PyEval_EvalFrameDefault+0x402b) [0x5603941d51bb]
40  /opt/conda/envs/gdf/bin/python(+0x139ef3) [0x5603941e1ef3]
41  /opt/conda/envs/gdf/bin/python(+0x147c72) [0x5603941efc72]
42  /opt/conda/envs/gdf/bin/python(_PyEval_EvalFrameDefault+0x402b) [0x5603941d51bb]
43  /opt/conda/envs/gdf/bin/python(+0x139ef3) [0x5603941e1ef3]
44  /opt/conda/envs/gdf/bin/python(_PyEval_EvalFrameDefault+0x68b) [0x5603941d181b]
45  /opt/conda/envs/gdf/bin/python(+0x12827a) [0x5603941d027a]
46  /opt/conda/envs/gdf/bin/python(_PyFunction_Vectorcall+0xd5) [0x5603941e1c05]
47  /opt/conda/envs/gdf/bin/python(_PyEval_EvalFrameDefault+0x68b) [0x5603941d181b]
48  /opt/conda/envs/gdf/bin/python(+0x139ef3) [0x5603941e1ef3]
49  /opt/conda/envs/gdf/bin/python(_PyEval_EvalFrameDefault+0x3d8) [0x5603941d1568]
50  /opt/conda/envs/gdf/bin/python(+0x12827a) [0x5603941d027a]
51  /opt/conda/envs/gdf/bin/python(_PyFunction_Vectorcall+0xd5) [0x5603941e1c05]
52  /opt/conda/envs/gdf/bin/python(_PyEval_EvalFrameDefault+0x123b) [0x5603941d23cb]
53  /opt/conda/envs/gdf/bin/python(+0x12827a) [0x5603941d027a]
54  /opt/conda/envs/gdf/bin/python(_PyEval_EvalCodeWithName+0x47) [0x5603941cff07]
55  /opt/conda/envs/gdf/bin/python(PyEval_EvalCodeEx+0x39) [0x5603941cfeb9]
56  /opt/conda/envs/gdf/bin/python(PyEval_EvalCode+0x1b) [0x5603942808bb]
57  /opt/conda/envs/gdf/bin/python(+0x206adc) [0x5603942aeadc]
58  /opt/conda/envs/gdf/bin/python(+0x202c24) [0x5603942aac24]
59  /opt/conda/envs/gdf/bin/python(PyRun_StringFlags+0x9d) [0x5603942a27ed]
60  /opt/conda/envs/gdf/bin/python(PyRun_SimpleStringFlags+0x3d) [0x5603942a26bd]
61  /opt/conda/envs/gdf/bin/python(Py_RunMain+0x262) [0x5603942a18a2]
=================================
[dgx13:62912:0:62912] Caught signal 11 (Segmentation fault: address not mapped to object at address 0x450)
==== backtrace (tid:  62912) ====
 0  /opt/conda/envs/gdf/lib/libucs.so.0(ucs_handle_error+0x2fd) [0x7f0b7413bced]
 1  /opt/conda/envs/gdf/lib/libucs.so.0(+0x2aee4) [0x7f0b7413bee4]
 2  /opt/conda/envs/gdf/lib/libucs.so.0(+0x2b0aa) [0x7f0b7413c0aa]
 3  /usr/lib/x86_64-linux-gnu/libpthread.so.0(+0x14420) [0x7f0c056fb420]
 4  /opt/conda/envs/gdf/lib/libucp.so.0(ucp_mem_type_unpack+0x14) [0x7f0b741bb6d4]
 5  /opt/conda/envs/gdf/lib/libucp.so.0(ucp_rndv_data_handler+0x4e9) [0x7f0b741e3a29]
 6  /opt/conda/envs/gdf/lib/libuct.so.0(+0x2045f) [0x7f0b740f545f]
 7  /opt/conda/envs/gdf/lib/libuct.so.0(+0x238c8) [0x7f0b740f88c8]
 8  /opt/conda/envs/gdf/lib/libucs.so.0(ucs_event_set_wait+0xb9) [0x7f0b74145399]
 9  /opt/conda/envs/gdf/lib/libuct.so.0(uct_tcp_iface_progress+0x7d) [0x7f0b740f765d]
10  /opt/conda/envs/gdf/lib/libucp.so.0(ucp_worker_progress+0x5a) [0x7f0b741b850a]
11  /opt/conda/envs/gdf/lib/python3.9/site-packages/ucp/_libs/ucx_api.cpython-39-x86_64-linux-gnu.so(+0x2b17a) [0x7f0b7426d17a]
12  /opt/conda/envs/gdf/bin/python(+0x13eb08) [0x5603584acb08]
13  /opt/conda/envs/gdf/bin/python(_PyEval_EvalFrameDefault+0x5f82) [0x56035849d112]
14  /opt/conda/envs/gdf/bin/python(+0x12827a) [0x56035849627a]
15  /opt/conda/envs/gdf/bin/python(_PyFunction_Vectorcall+0xd5) [0x5603584a7c05]
16  /opt/conda/envs/gdf/bin/python(_PyEval_EvalFrameDefault+0x68b) [0x56035849781b]
17  /opt/conda/envs/gdf/bin/python(+0x139ef3) [0x5603584a7ef3]
18  /opt/conda/envs/gdf/bin/python(+0x147a16) [0x5603584b5a16]
19  /opt/conda/envs/gdf/bin/python(+0x2579b1) [0x5603585c59b1]
20  /opt/conda/envs/gdf/bin/python(+0xe5817) [0x560358453817]
21  /opt/conda/envs/gdf/bin/python(+0x130f83) [0x56035849ef83]
22  /opt/conda/envs/gdf/bin/python(_PyEval_EvalFrameDefault+0x5ba6) [0x56035849cd36]
23  /opt/conda/envs/gdf/bin/python(+0x139ef3) [0x5603584a7ef3]
24  /opt/conda/envs/gdf/bin/python(_PyEval_EvalFrameDefault+0x68b) [0x56035849781b]
25  /opt/conda/envs/gdf/bin/python(+0x139ef3) [0x5603584a7ef3]
26  /opt/conda/envs/gdf/bin/python(_PyEval_EvalFrameDefault+0x68b) [0x56035849781b]
27  /opt/conda/envs/gdf/bin/python(+0x139ef3) [0x5603584a7ef3]
28  /opt/conda/envs/gdf/bin/python(_PyEval_EvalFrameDefault+0x68b) [0x56035849781b]
29  /opt/conda/envs/gdf/bin/python(+0x139ef3) [0x5603584a7ef3]
30  /opt/conda/envs/gdf/bin/python(_PyEval_EvalFrameDefault+0x68b) [0x56035849781b]
31  /opt/conda/envs/gdf/bin/python(+0x12827a) [0x56035849627a]
32  /opt/conda/envs/gdf/bin/python(_PyFunction_Vectorcall+0xd5) [0x5603584a7c05]
33  /opt/conda/envs/gdf/bin/python(_PyEval_EvalFrameDefault+0x4e17) [0x56035849bfa7]
34  /opt/conda/envs/gdf/bin/python(+0x12827a) [0x56035849627a]
35  /opt/conda/envs/gdf/bin/python(+0x147935) [0x5603584b5935]
36  /opt/conda/envs/gdf/bin/python(PyObject_Call+0xb4) [0x5603584b6104]
37  /opt/conda/envs/gdf/bin/python(+0x20efc8) [0x56035857cfc8]
38  /opt/conda/envs/gdf/bin/python(_PyObject_MakeTpCall+0x2fc) [0x5603584a02bc]
39  /opt/conda/envs/gdf/bin/python(_PyEval_EvalFrameDefault+0x402b) [0x56035849b1bb]
40  /opt/conda/envs/gdf/bin/python(+0x139ef3) [0x5603584a7ef3]
41  /opt/conda/envs/gdf/bin/python(+0x147c72) [0x5603584b5c72]
42  /opt/conda/envs/gdf/bin/python(_PyEval_EvalFrameDefault+0x402b) [0x56035849b1bb]
43  /opt/conda/envs/gdf/bin/python(+0x139ef3) [0x5603584a7ef3]
44  /opt/conda/envs/gdf/bin/python(_PyEval_EvalFrameDefault+0x68b) [0x56035849781b]
45  /opt/conda/envs/gdf/bin/python(+0x12827a) [0x56035849627a]
46  /opt/conda/envs/gdf/bin/python(_PyFunction_Vectorcall+0xd5) [0x5603584a7c05]
47  /opt/conda/envs/gdf/bin/python(_PyEval_EvalFrameDefault+0x68b) [0x56035849781b]
48  /opt/conda/envs/gdf/bin/python(+0x139ef3) [0x5603584a7ef3]
49  /opt/conda/envs/gdf/bin/python(_PyEval_EvalFrameDefault+0x3d8) [0x560358497568]
50  /opt/conda/envs/gdf/bin/python(+0x12827a) [0x56035849627a]
51  /opt/conda/envs/gdf/bin/python(_PyFunction_Vectorcall+0xd5) [0x5603584a7c05]
52  /opt/conda/envs/gdf/bin/python(_PyEval_EvalFrameDefault+0x123b) [0x5603584983cb]
53  /opt/conda/envs/gdf/bin/python(+0x12827a) [0x56035849627a]
54  /opt/conda/envs/gdf/bin/python(_PyEval_EvalCodeWithName+0x47) [0x560358495f07]
55  /opt/conda/envs/gdf/bin/python(PyEval_EvalCodeEx+0x39) [0x560358495eb9]
56  /opt/conda/envs/gdf/bin/python(PyEval_EvalCode+0x1b) [0x5603585468bb]
57  /opt/conda/envs/gdf/bin/python(+0x206adc) [0x560358574adc]
58  /opt/conda/envs/gdf/bin/python(+0x202c24) [0x560358570c24]
59  /opt/conda/envs/gdf/bin/python(PyRun_StringFlags+0x9d) [0x5603585687ed]
60  /opt/conda/envs/gdf/bin/python(PyRun_SimpleStringFlags+0x3d) [0x5603585686bd]
61  /opt/conda/envs/gdf/bin/python(Py_RunMain+0x262) [0x5603585678a2]
=================================
2023-07-22 06:48:57,623 - distributed.worker - ERROR - failed during get data with ucx://127.0.0.1:54519 -> ucx://127.0.0.1:53055
Traceback (most recent call last):
  File "/opt/conda/envs/gdf/lib/python3.9/site-packages/distributed/comm/ucx.py", line 333, in write
    await self.ep.send(each_frame)
  File "/opt/conda/envs/gdf/lib/python3.9/site-packages/ucp/core.py", line 650, in send
    return await comm.tag_send(self._ep, buffer, nbytes, tag, name=log)
ucp._libs.exceptions.UCXError: <[Send #007] ep: 0x7f7723c5c300, tag: 0x81b074eb1e4051fb, nbytes: 50000000, type: <class 'cupy.ndarray'>>: Connection reset by remote peer

During handling of the above exception, another exception occurred:

Traceback (most recent call last):
  File "/opt/conda/envs/gdf/lib/python3.9/site-packages/distributed/worker.py", line 1792, in get_data
    compressed = await comm.write(msg, serializers=serializers)
  File "/opt/conda/envs/gdf/lib/python3.9/site-packages/distributed/utils.py", line 752, in wrapper
    return await func(*args, **kwargs)
  File "/opt/conda/envs/gdf/lib/python3.9/site-packages/distributed/comm/ucx.py", line 337, in write
    raise CommClosedError("While writing, the connection was closed")
distributed.comm.core.CommClosedError: While writing, the connection was closed
2023-07-22 06:48:57,623 - distributed.worker - ERROR - failed during get data with ucx://127.0.0.1:42683 -> ucx://127.0.0.1:53055
Traceback (most recent call last):
  File "/opt/conda/envs/gdf/lib/python3.9/site-packages/distributed/comm/ucx.py", line 333, in write
    await self.ep.send(each_frame)
  File "/opt/conda/envs/gdf/lib/python3.9/site-packages/ucp/core.py", line 650, in send
    return await comm.tag_send(self._ep, buffer, nbytes, tag, name=log)
ucp._libs.exceptions.UCXError: <[Send #007] ep: 0x7fc6d0aef440, tag: 0xa8ece7ead3837646, nbytes: 50000000, type: <class 'cupy.ndarray'>>: Connection reset by remote peer

During handling of the above exception, another exception occurred:

Traceback (most recent call last):
  File "/opt/conda/envs/gdf/lib/python3.9/site-packages/distributed/worker.py", line 1792, in get_data
    compressed = await comm.write(msg, serializers=serializers)
  File "/opt/conda/envs/gdf/lib/python3.9/site-packages/distributed/utils.py", line 752, in wrapper
    return await func(*args, **kwargs)
  File "/opt/conda/envs/gdf/lib/python3.9/site-packages/distributed/comm/ucx.py", line 337, in write
    raise CommClosedError("While writing, the connection was closed")
distributed.comm.core.CommClosedError: While writing, the connection was closed
2023-07-22 06:48:57,624 - distributed.worker - ERROR - failed during get data with ucx://127.0.0.1:42683 -> ucx://127.0.0.1:48693
Traceback (most recent call last):
  File "/opt/conda/envs/gdf/lib/python3.9/site-packages/distributed/comm/ucx.py", line 333, in write
    await self.ep.send(each_frame)
  File "/opt/conda/envs/gdf/lib/python3.9/site-packages/ucp/core.py", line 650, in send
    return await comm.tag_send(self._ep, buffer, nbytes, tag, name=log)
ucp._libs.exceptions.UCXError: <[Send #007] ep: 0x7fc6d0aef480, tag: 0x6aa78f8a75850468, nbytes: 50000000, type: <class 'cupy.ndarray'>>: Connection reset by remote peer

During handling of the above exception, another exception occurred:

Traceback (most recent call last):
  File "/opt/conda/envs/gdf/lib/python3.9/site-packages/distributed/worker.py", line 1792, in get_data
    compressed = await comm.write(msg, serializers=serializers)
  File "/opt/conda/envs/gdf/lib/python3.9/site-packages/distributed/utils.py", line 752, in wrapper
    return await func(*args, **kwargs)
  File "/opt/conda/envs/gdf/lib/python3.9/site-packages/distributed/comm/ucx.py", line 337, in write
    raise CommClosedError("While writing, the connection was closed")
distributed.comm.core.CommClosedError: While writing, the connection was closed
Task exception was never retrieved
future: <Task finished name='Task-92' coro=<_listener_handler_coroutine() done, defined at /opt/conda/envs/gdf/lib/python3.9/site-packages/ucp/core.py:128> exception=UCXError('<stream_send>: Endpoint timeout')>
Traceback (most recent call last):
  File "/opt/conda/envs/gdf/lib/python3.9/site-packages/ucp/core.py", line 143, in _listener_handler_coroutine
    peer_info = await exchange_peer_info(
  File "/opt/conda/envs/gdf/lib/python3.9/site-packages/ucp/core.py", line 51, in exchange_peer_info
    await comm.stream_send(endpoint, my_info_arr, my_info_arr.nbytes)
ucp._libs.exceptions.UCXError: <stream_send>: Endpoint timeout
2023-07-22 06:48:57,669 - distributed.nanny - WARNING - Restarting worker
2023-07-22 06:48:57,695 - distributed.nanny - WARNING - Restarting worker
2023-07-22 06:48:59,129 - distributed.preloading - INFO - Creating preload: dask_cuda.initialize
2023-07-22 06:48:59,129 - distributed.preloading - INFO - Import preload module: dask_cuda.initialize
2023-07-22 06:48:59,134 - distributed.preloading - INFO - Creating preload: dask_cuda.initialize
2023-07-22 06:48:59,135 - distributed.preloading - INFO - Import preload module: dask_cuda.initialize
2023-07-22 06:49:23,989 - distributed.worker - ERROR - Worker stream died during communication: ucx://127.0.0.1:37899
Traceback (most recent call last):
  File "/opt/conda/envs/gdf/lib/python3.9/site-packages/distributed/comm/ucx.py", line 466, in connect
    ep = await ucp.create_endpoint(ip, port)
  File "/opt/conda/envs/gdf/lib/python3.9/site-packages/ucp/core.py", line 1004, in create_endpoint
    return await _get_ctx().create_endpoint(
  File "/opt/conda/envs/gdf/lib/python3.9/site-packages/ucp/core.py", line 316, in create_endpoint
    peer_info = await exchange_peer_info(
  File "/opt/conda/envs/gdf/lib/python3.9/site-packages/ucp/core.py", line 54, in exchange_peer_info
    await comm.stream_recv(endpoint, peer_info_arr, peer_info_arr.nbytes)
asyncio.exceptions.CancelledError

During handling of the above exception, another exception occurred:

Traceback (most recent call last):
  File "/opt/conda/envs/gdf/lib/python3.9/asyncio/tasks.py", line 490, in wait_for
    return fut.result()
asyncio.exceptions.CancelledError

The above exception was the direct cause of the following exception:

Traceback (most recent call last):
  File "/opt/conda/envs/gdf/lib/python3.9/site-packages/distributed/comm/core.py", line 292, in connect
    comm = await wait_for(
  File "/opt/conda/envs/gdf/lib/python3.9/site-packages/distributed/utils.py", line 1849, in wait_for
    return await asyncio.wait_for(fut, timeout)
  File "/opt/conda/envs/gdf/lib/python3.9/asyncio/tasks.py", line 492, in wait_for
    raise exceptions.TimeoutError() from exc
asyncio.exceptions.TimeoutError

The above exception was the direct cause of the following exception:

Traceback (most recent call last):
  File "/opt/conda/envs/gdf/lib/python3.9/site-packages/distributed/worker.py", line 2066, in gather_dep
    response = await get_data_from_worker(
  File "/opt/conda/envs/gdf/lib/python3.9/site-packages/distributed/worker.py", line 2889, in get_data_from_worker
    comm = await rpc.connect(worker)
  File "/opt/conda/envs/gdf/lib/python3.9/site-packages/distributed/core.py", line 1506, in connect
    return await connect_attempt
  File "/opt/conda/envs/gdf/lib/python3.9/site-packages/distributed/core.py", line 1427, in _connect
    comm = await connect(
  File "/opt/conda/envs/gdf/lib/python3.9/site-packages/distributed/comm/core.py", line 318, in connect
    raise OSError(
OSError: Timed out trying to connect to ucx://127.0.0.1:37899 after 30 s
2023-07-22 06:49:24,363 - distributed.worker - ERROR - Worker stream died during communication: ucx://127.0.0.1:46539
Traceback (most recent call last):
  File "/opt/conda/envs/gdf/lib/python3.9/site-packages/distributed/comm/ucx.py", line 466, in connect
    ep = await ucp.create_endpoint(ip, port)
  File "/opt/conda/envs/gdf/lib/python3.9/site-packages/ucp/core.py", line 1004, in create_endpoint
    return await _get_ctx().create_endpoint(
  File "/opt/conda/envs/gdf/lib/python3.9/site-packages/ucp/core.py", line 316, in create_endpoint
    peer_info = await exchange_peer_info(
  File "/opt/conda/envs/gdf/lib/python3.9/site-packages/ucp/core.py", line 54, in exchange_peer_info
    await comm.stream_recv(endpoint, peer_info_arr, peer_info_arr.nbytes)
asyncio.exceptions.CancelledError

During handling of the above exception, another exception occurred:

Traceback (most recent call last):
  File "/opt/conda/envs/gdf/lib/python3.9/asyncio/tasks.py", line 490, in wait_for
    return fut.result()
asyncio.exceptions.CancelledError

The above exception was the direct cause of the following exception:

Traceback (most recent call last):
  File "/opt/conda/envs/gdf/lib/python3.9/site-packages/distributed/comm/core.py", line 292, in connect
    comm = await wait_for(
  File "/opt/conda/envs/gdf/lib/python3.9/site-packages/distributed/utils.py", line 1849, in wait_for
    return await asyncio.wait_for(fut, timeout)
  File "/opt/conda/envs/gdf/lib/python3.9/asyncio/tasks.py", line 492, in wait_for
    raise exceptions.TimeoutError() from exc
asyncio.exceptions.TimeoutError

The above exception was the direct cause of the following exception:

Traceback (most recent call last):
  File "/opt/conda/envs/gdf/lib/python3.9/site-packages/distributed/worker.py", line 2066, in gather_dep
    response = await get_data_from_worker(
  File "/opt/conda/envs/gdf/lib/python3.9/site-packages/distributed/worker.py", line 2889, in get_data_from_worker
    comm = await rpc.connect(worker)
  File "/opt/conda/envs/gdf/lib/python3.9/site-packages/distributed/core.py", line 1506, in connect
    return await connect_attempt
  File "/opt/conda/envs/gdf/lib/python3.9/site-packages/distributed/core.py", line 1427, in _connect
    comm = await connect(
  File "/opt/conda/envs/gdf/lib/python3.9/site-packages/distributed/comm/core.py", line 318, in connect
    raise OSError(
OSError: Timed out trying to connect to ucx://127.0.0.1:46539 after 30 s
/opt/conda/envs/gdf/lib/python3.9/multiprocessing/resource_tracker.py:216: UserWarning: resource_tracker: There appear to be 48 leaked semaphore objects to clean up at shutdown
  warnings.warn('resource_tracker: There appear to be %d '
