[dgx13:86642:0:86642] Caught signal 11 (Segmentation fault: address not mapped to object at address 0x448)
==== backtrace (tid:  86642) ====
 0  /opt/conda/envs/gdf/lib/libucs.so.0(ucs_handle_error+0x2fd) [0x7fe42c04c07d]
 1  /opt/conda/envs/gdf/lib/libucs.so.0(+0x2a274) [0x7fe42c04c274]
 2  /opt/conda/envs/gdf/lib/libucs.so.0(+0x2a43a) [0x7fe42c04c43a]
 3  /usr/lib/x86_64-linux-gnu/libpthread.so.0(+0x14420) [0x7fe4bf10c420]
 4  /opt/conda/envs/gdf/lib/libucp.so.0(ucp_mem_type_unpack+0x14) [0x7fe419d636b4]
 5  /opt/conda/envs/gdf/lib/libucp.so.0(ucp_rndv_data_handler+0x4e9) [0x7fe419d8c839]
 6  /opt/conda/envs/gdf/lib/libuct.so.0(+0x203df) [0x7fe419cfd3df]
 7  /opt/conda/envs/gdf/lib/libuct.so.0(+0x23838) [0x7fe419d00838]
 8  /opt/conda/envs/gdf/lib/libucs.so.0(ucs_event_set_wait+0xb9) [0x7fe42c0554a9]
 9  /opt/conda/envs/gdf/lib/libuct.so.0(uct_tcp_iface_progress+0x7d) [0x7fe419cff5dd]
10  /opt/conda/envs/gdf/lib/libucp.so.0(ucp_worker_progress+0x5a) [0x7fe419d608da]
11  /opt/conda/envs/gdf/lib/python3.9/site-packages/ucp/_libs/ucx_api.cpython-39-x86_64-linux-gnu.so(+0x3206a) [0x7fe419e1906a]
12  /opt/conda/envs/gdf/bin/python(_PyEval_EvalFrameDefault+0x37cb) [0x559216cce6fb]
13  /opt/conda/envs/gdf/bin/python(+0x12f094) [0x559216cca094]
14  /opt/conda/envs/gdf/bin/python(_PyFunction_Vectorcall+0xd9) [0x559216cdb519]
15  /opt/conda/envs/gdf/bin/python(_PyEval_EvalFrameDefault+0x696) [0x559216ccb5c6]
16  /opt/conda/envs/gdf/bin/python(+0x1407c2) [0x559216cdb7c2]
17  /opt/conda/envs/gdf/bin/python(+0x14de83) [0x559216ce8e83]
18  /opt/conda/envs/gdf/bin/python(+0x258b2c) [0x559216df3b2c]
19  /opt/conda/envs/gdf/bin/python(+0xead05) [0x559216c85d05]
20  /opt/conda/envs/gdf/bin/python(+0x1377f3) [0x559216cd27f3]
21  /opt/conda/envs/gdf/bin/python(_PyEval_EvalFrameDefault+0x59f9) [0x559216cd0929]
22  /opt/conda/envs/gdf/bin/python(+0x1407c2) [0x559216cdb7c2]
23  /opt/conda/envs/gdf/bin/python(_PyEval_EvalFrameDefault+0x696) [0x559216ccb5c6]
24  /opt/conda/envs/gdf/bin/python(+0x1407c2) [0x559216cdb7c2]
25  /opt/conda/envs/gdf/bin/python(_PyEval_EvalFrameDefault+0x696) [0x559216ccb5c6]
26  /opt/conda/envs/gdf/bin/python(+0x1407c2) [0x559216cdb7c2]
27  /opt/conda/envs/gdf/bin/python(_PyEval_EvalFrameDefault+0x696) [0x559216ccb5c6]
28  /opt/conda/envs/gdf/bin/python(+0x1407c2) [0x559216cdb7c2]
29  /opt/conda/envs/gdf/bin/python(_PyEval_EvalFrameDefault+0x696) [0x559216ccb5c6]
30  /opt/conda/envs/gdf/bin/python(+0x12f094) [0x559216cca094]
31  /opt/conda/envs/gdf/bin/python(_PyFunction_Vectorcall+0xd9) [0x559216cdb519]
32  /opt/conda/envs/gdf/bin/python(_PyEval_EvalFrameDefault+0x11f8) [0x559216ccc128]
33  /opt/conda/envs/gdf/bin/python(+0x12f094) [0x559216cca094]
34  /opt/conda/envs/gdf/bin/python(+0x14dccb) [0x559216ce8ccb]
35  /opt/conda/envs/gdf/bin/python(PyObject_Call+0xbc) [0x559216ce944c]
36  /opt/conda/envs/gdf/bin/python(+0x21110e) [0x559216dac10e]
37  /opt/conda/envs/gdf/bin/python(_PyObject_MakeTpCall+0x2ec) [0x559216cd377c]
38  /opt/conda/envs/gdf/bin/python(_PyEval_EvalFrameDefault+0x37cb) [0x559216cce6fb]
39  /opt/conda/envs/gdf/bin/python(+0x1407c2) [0x559216cdb7c2]
40  /opt/conda/envs/gdf/bin/python(+0x14ddac) [0x559216ce8dac]
41  /opt/conda/envs/gdf/bin/python(_PyEval_EvalFrameDefault+0x37cb) [0x559216cce6fb]
42  /opt/conda/envs/gdf/bin/python(+0x1407c2) [0x559216cdb7c2]
43  /opt/conda/envs/gdf/bin/python(_PyEval_EvalFrameDefault+0x696) [0x559216ccb5c6]
44  /opt/conda/envs/gdf/bin/python(+0x12f094) [0x559216cca094]
45  /opt/conda/envs/gdf/bin/python(_PyFunction_Vectorcall+0xd9) [0x559216cdb519]
46  /opt/conda/envs/gdf/bin/python(_PyEval_EvalFrameDefault+0x696) [0x559216ccb5c6]
47  /opt/conda/envs/gdf/bin/python(+0x1407c2) [0x559216cdb7c2]
48  /opt/conda/envs/gdf/bin/python(_PyEval_EvalFrameDefault+0x3e2) [0x559216ccb312]
49  /opt/conda/envs/gdf/bin/python(+0x12f094) [0x559216cca094]
50  /opt/conda/envs/gdf/bin/python(_PyFunction_Vectorcall+0xd9) [0x559216cdb519]
51  /opt/conda/envs/gdf/bin/python(_PyEval_EvalFrameDefault+0x11f8) [0x559216ccc128]
52  /opt/conda/envs/gdf/bin/python(+0x12f094) [0x559216cca094]
53  /opt/conda/envs/gdf/bin/python(_PyEval_EvalCodeWithName+0x48) [0x559216cc9d68]
54  /opt/conda/envs/gdf/bin/python(PyEval_EvalCodeEx+0x39) [0x559216cc9d19]
55  /opt/conda/envs/gdf/bin/python(PyEval_EvalCode+0x1b) [0x559216d7707b]
56  /opt/conda/envs/gdf/bin/python(+0x208fca) [0x559216da3fca]
57  /opt/conda/envs/gdf/bin/python(+0x205353) [0x559216da0353]
58  /opt/conda/envs/gdf/bin/python(PyRun_StringFlags+0x9a) [0x559216d9816a]
59  /opt/conda/envs/gdf/bin/python(PyRun_SimpleStringFlags+0x3c) [0x559216d9805c]
60  /opt/conda/envs/gdf/bin/python(Py_RunMain+0x267) [0x559216d97297]
61  /opt/conda/envs/gdf/bin/python(Py_BytesMain+0x37) [0x559216d6af07]
=================================
[dgx13:86645:0:86645] Caught signal 11 (Segmentation fault: address not mapped to object at address 0x448)
==== backtrace (tid:  86645) ====
 0  /opt/conda/envs/gdf/lib/libucs.so.0(ucs_handle_error+0x2fd) [0x7f490cfb207d]
 1  /opt/conda/envs/gdf/lib/libucs.so.0(+0x2a274) [0x7f490cfb2274]
 2  /opt/conda/envs/gdf/lib/libucs.so.0(+0x2a43a) [0x7f490cfb243a]
 3  /usr/lib/x86_64-linux-gnu/libpthread.so.0(+0x14420) [0x7f49a035f420]
 4  /opt/conda/envs/gdf/lib/libucp.so.0(ucp_mem_type_unpack+0x14) [0x7f490d0316b4]
 5  /opt/conda/envs/gdf/lib/libucp.so.0(ucp_rndv_data_handler+0x4e9) [0x7f490d05a839]
 6  /opt/conda/envs/gdf/lib/libuct.so.0(+0x203df) [0x7f490cf6c3df]
 7  /opt/conda/envs/gdf/lib/libuct.so.0(+0x23838) [0x7f490cf6f838]
 8  /opt/conda/envs/gdf/lib/libucs.so.0(ucs_event_set_wait+0xb9) [0x7f490cfbb4a9]
 9  /opt/conda/envs/gdf/lib/libuct.so.0(uct_tcp_iface_progress+0x7d) [0x7f490cf6e5dd]
10  /opt/conda/envs/gdf/lib/libucp.so.0(ucp_worker_progress+0x5a) [0x7f490d02e8da]
11  /opt/conda/envs/gdf/lib/python3.9/site-packages/ucp/_libs/ucx_api.cpython-39-x86_64-linux-gnu.so(+0x3206a) [0x7f490d0e706a]
12  /opt/conda/envs/gdf/bin/python(_PyEval_EvalFrameDefault+0x37cb) [0x5568fb85e6fb]
13  /opt/conda/envs/gdf/bin/python(+0x12f094) [0x5568fb85a094]
14  /opt/conda/envs/gdf/bin/python(_PyFunction_Vectorcall+0xd9) [0x5568fb86b519]
15  /opt/conda/envs/gdf/bin/python(_PyEval_EvalFrameDefault+0x696) [0x5568fb85b5c6]
16  /opt/conda/envs/gdf/bin/python(+0x1407c2) [0x5568fb86b7c2]
17  /opt/conda/envs/gdf/bin/python(+0x14de83) [0x5568fb878e83]
18  /opt/conda/envs/gdf/bin/python(+0x258b2c) [0x5568fb983b2c]
19  /opt/conda/envs/gdf/bin/python(+0xead05) [0x5568fb815d05]
20  /opt/conda/envs/gdf/bin/python(+0x1377f3) [0x5568fb8627f3]
21  /opt/conda/envs/gdf/bin/python(_PyEval_EvalFrameDefault+0x59f9) [0x5568fb860929]
22  /opt/conda/envs/gdf/bin/python(+0x1407c2) [0x5568fb86b7c2]
23  /opt/conda/envs/gdf/bin/python(_PyEval_EvalFrameDefault+0x696) [0x5568fb85b5c6]
24  /opt/conda/envs/gdf/bin/python(+0x1407c2) [0x5568fb86b7c2]
25  /opt/conda/envs/gdf/bin/python(_PyEval_EvalFrameDefault+0x696) [0x5568fb85b5c6]
26  /opt/conda/envs/gdf/bin/python(+0x1407c2) [0x5568fb86b7c2]
27  /opt/conda/envs/gdf/bin/python(_PyEval_EvalFrameDefault+0x696) [0x5568fb85b5c6]
28  /opt/conda/envs/gdf/bin/python(+0x1407c2) [0x5568fb86b7c2]
29  /opt/conda/envs/gdf/bin/python(_PyEval_EvalFrameDefault+0x696) [0x5568fb85b5c6]
30  /opt/conda/envs/gdf/bin/python(+0x12f094) [0x5568fb85a094]
31  /opt/conda/envs/gdf/bin/python(_PyFunction_Vectorcall+0xd9) [0x5568fb86b519]
32  /opt/conda/envs/gdf/bin/python(_PyEval_EvalFrameDefault+0x11f8) [0x5568fb85c128]
33  /opt/conda/envs/gdf/bin/python(+0x12f094) [0x5568fb85a094]
34  /opt/conda/envs/gdf/bin/python(+0x14dccb) [0x5568fb878ccb]
35  /opt/conda/envs/gdf/bin/python(PyObject_Call+0xbc) [0x5568fb87944c]
36  /opt/conda/envs/gdf/bin/python(+0x21110e) [0x5568fb93c10e]
37  /opt/conda/envs/gdf/bin/python(_PyObject_MakeTpCall+0x2ec) [0x5568fb86377c]
38  /opt/conda/envs/gdf/bin/python(_PyEval_EvalFrameDefault+0x37cb) [0x5568fb85e6fb]
39  /opt/conda/envs/gdf/bin/python(+0x1407c2) [0x5568fb86b7c2]
40  /opt/conda/envs/gdf/bin/python(+0x14ddac) [0x5568fb878dac]
41  /opt/conda/envs/gdf/bin/python(_PyEval_EvalFrameDefault+0x37cb) [0x5568fb85e6fb]
42  /opt/conda/envs/gdf/bin/python(+0x1407c2) [0x5568fb86b7c2]
43  /opt/conda/envs/gdf/bin/python(_PyEval_EvalFrameDefault+0x696) [0x5568fb85b5c6]
44  /opt/conda/envs/gdf/bin/python(+0x12f094) [0x5568fb85a094]
45  /opt/conda/envs/gdf/bin/python(_PyFunction_Vectorcall+0xd9) [0x5568fb86b519]
46  /opt/conda/envs/gdf/bin/python(_PyEval_EvalFrameDefault+0x696) [0x5568fb85b5c6]
47  /opt/conda/envs/gdf/bin/python(+0x1407c2) [0x5568fb86b7c2]
48  /opt/conda/envs/gdf/bin/python(_PyEval_EvalFrameDefault+0x3e2) [0x5568fb85b312]
49  /opt/conda/envs/gdf/bin/python(+0x12f094) [0x5568fb85a094]
50  /opt/conda/envs/gdf/bin/python(_PyFunction_Vectorcall+0xd9) [0x5568fb86b519]
51  /opt/conda/envs/gdf/bin/python(_PyEval_EvalFrameDefault+0x11f8) [0x5568fb85c128]
52  /opt/conda/envs/gdf/bin/python(+0x12f094) [0x5568fb85a094]
53  /opt/conda/envs/gdf/bin/python(_PyEval_EvalCodeWithName+0x48) [0x5568fb859d68]
54  /opt/conda/envs/gdf/bin/python(PyEval_EvalCodeEx+0x39) [0x5568fb859d19]
55  /opt/conda/envs/gdf/bin/python(PyEval_EvalCode+0x1b) [0x5568fb90707b]
56  /opt/conda/envs/gdf/bin/python(+0x208fca) [0x5568fb933fca]
57  /opt/conda/envs/gdf/bin/python(+0x205353) [0x5568fb930353]
58  /opt/conda/envs/gdf/bin/python(PyRun_StringFlags+0x9a) [0x5568fb92816a]
59  /opt/conda/envs/gdf/bin/python(PyRun_SimpleStringFlags+0x3c) [0x5568fb92805c]
60  /opt/conda/envs/gdf/bin/python(Py_RunMain+0x267) [0x5568fb927297]
61  /opt/conda/envs/gdf/bin/python(Py_BytesMain+0x37) [0x5568fb8faf07]
=================================
[dgx13:86636:0:86636] Caught signal 11 (Segmentation fault: address not mapped to object at address 0x448)
==== backtrace (tid:  86636) ====
 0  /opt/conda/envs/gdf/lib/libucs.so.0(ucs_handle_error+0x2fd) [0x7fd59d9f407d]
 1  /opt/conda/envs/gdf/lib/libucs.so.0(+0x2a274) [0x7fd59d9f4274]
 2  /opt/conda/envs/gdf/lib/libucs.so.0(+0x2a43a) [0x7fd59d9f443a]
 3  /usr/lib/x86_64-linux-gnu/libpthread.so.0(+0x14420) [0x7fd642dd7420]
 4  /opt/conda/envs/gdf/lib/libucp.so.0(ucp_mem_type_unpack+0x14) [0x7fd59da736b4]
 5  /opt/conda/envs/gdf/lib/libucp.so.0(ucp_rndv_data_handler+0x4e9) [0x7fd59da9c839]
 6  /opt/conda/envs/gdf/lib/libuct.so.0(+0x203df) [0x7fd59d9ae3df]
 7  /opt/conda/envs/gdf/lib/libuct.so.0(+0x23838) [0x7fd59d9b1838]
 8  /opt/conda/envs/gdf/lib/libucs.so.0(ucs_event_set_wait+0xb9) [0x7fd59d9fd4a9]
 9  /opt/conda/envs/gdf/lib/libuct.so.0(uct_tcp_iface_progress+0x7d) [0x7fd59d9b05dd]
10  /opt/conda/envs/gdf/lib/libucp.so.0(ucp_worker_progress+0x5a) [0x7fd59da708da]
11  /opt/conda/envs/gdf/lib/python3.9/site-packages/ucp/_libs/ucx_api.cpython-39-x86_64-linux-gnu.so(+0x3206a) [0x7fd59db2906a]
12  /opt/conda/envs/gdf/bin/python(_PyEval_EvalFrameDefault+0x37cb) [0x55633d6dc6fb]
13  /opt/conda/envs/gdf/bin/python(+0x12f094) [0x55633d6d8094]
14  /opt/conda/envs/gdf/bin/python(_PyFunction_Vectorcall+0xd9) [0x55633d6e9519]
15  /opt/conda/envs/gdf/bin/python(_PyEval_EvalFrameDefault+0x696) [0x55633d6d95c6]
16  /opt/conda/envs/gdf/bin/python(+0x1407c2) [0x55633d6e97c2]
17  /opt/conda/envs/gdf/bin/python(+0x14de83) [0x55633d6f6e83]
18  /opt/conda/envs/gdf/bin/python(+0x258b2c) [0x55633d801b2c]
19  /opt/conda/envs/gdf/bin/python(+0xead05) [0x55633d693d05]
20  /opt/conda/envs/gdf/bin/python(+0x1377f3) [0x55633d6e07f3]
21  /opt/conda/envs/gdf/bin/python(_PyEval_EvalFrameDefault+0x59f9) [0x55633d6de929]
22  /opt/conda/envs/gdf/bin/python(+0x1407c2) [0x55633d6e97c2]
23  /opt/conda/envs/gdf/bin/python(_PyEval_EvalFrameDefault+0x696) [0x55633d6d95c6]
24  /opt/conda/envs/gdf/bin/python(+0x1407c2) [0x55633d6e97c2]
25  /opt/conda/envs/gdf/bin/python(_PyEval_EvalFrameDefault+0x696) [0x55633d6d95c6]
26  /opt/conda/envs/gdf/bin/python(+0x1407c2) [0x55633d6e97c2]
27  /opt/conda/envs/gdf/bin/python(_PyEval_EvalFrameDefault+0x696) [0x55633d6d95c6]
28  /opt/conda/envs/gdf/bin/python(+0x1407c2) [0x55633d6e97c2]
29  /opt/conda/envs/gdf/bin/python(_PyEval_EvalFrameDefault+0x696) [0x55633d6d95c6]
30  /opt/conda/envs/gdf/bin/python(+0x12f094) [0x55633d6d8094]
31  /opt/conda/envs/gdf/bin/python(_PyFunction_Vectorcall+0xd9) [0x55633d6e9519]
32  /opt/conda/envs/gdf/bin/python(_PyEval_EvalFrameDefault+0x11f8) [0x55633d6da128]
33  /opt/conda/envs/gdf/bin/python(+0x12f094) [0x55633d6d8094]
34  /opt/conda/envs/gdf/bin/python(+0x14dccb) [0x55633d6f6ccb]
35  /opt/conda/envs/gdf/bin/python(PyObject_Call+0xbc) [0x55633d6f744c]
36  /opt/conda/envs/gdf/bin/python(+0x21110e) [0x55633d7ba10e]
37  /opt/conda/envs/gdf/bin/python(_PyObject_MakeTpCall+0x2ec) [0x55633d6e177c]
38  /opt/conda/envs/gdf/bin/python(_PyEval_EvalFrameDefault+0x37cb) [0x55633d6dc6fb]
39  /opt/conda/envs/gdf/bin/python(+0x1407c2) [0x55633d6e97c2]
40  /opt/conda/envs/gdf/bin/python(+0x14ddac) [0x55633d6f6dac]
41  /opt/conda/envs/gdf/bin/python(_PyEval_EvalFrameDefault+0x37cb) [0x55633d6dc6fb]
42  /opt/conda/envs/gdf/bin/python(+0x1407c2) [0x55633d6e97c2]
43  /opt/conda/envs/gdf/bin/python(_PyEval_EvalFrameDefault+0x696) [0x55633d6d95c6]
44  /opt/conda/envs/gdf/bin/python(+0x12f094) [0x55633d6d8094]
45  /opt/conda/envs/gdf/bin/python(_PyFunction_Vectorcall+0xd9) [0x55633d6e9519]
46  /opt/conda/envs/gdf/bin/python(_PyEval_EvalFrameDefault+0x696) [0x55633d6d95c6]
47  /opt/conda/envs/gdf/bin/python(+0x1407c2) [0x55633d6e97c2]
48  /opt/conda/envs/gdf/bin/python(_PyEval_EvalFrameDefault+0x3e2) [0x55633d6d9312]
49  /opt/conda/envs/gdf/bin/python(+0x12f094) [0x55633d6d8094]
50  /opt/conda/envs/gdf/bin/python(_PyFunction_Vectorcall+0xd9) [0x55633d6e9519]
51  /opt/conda/envs/gdf/bin/python(_PyEval_EvalFrameDefault+0x11f8) [0x55633d6da128]
52  /opt/conda/envs/gdf/bin/python(+0x12f094) [0x55633d6d8094]
53  /opt/conda/envs/gdf/bin/python(_PyEval_EvalCodeWithName+0x48) [0x55633d6d7d68]
54  /opt/conda/envs/gdf/bin/python(PyEval_EvalCodeEx+0x39) [0x55633d6d7d19]
55  /opt/conda/envs/gdf/bin/python(PyEval_EvalCode+0x1b) [0x55633d78507b]
56  /opt/conda/envs/gdf/bin/python(+0x208fca) [0x55633d7b1fca]
57  /opt/conda/envs/gdf/bin/python(+0x205353) [0x55633d7ae353]
58  /opt/conda/envs/gdf/bin/python(PyRun_StringFlags+0x9a) [0x55633d7a616a]
59  /opt/conda/envs/gdf/bin/python(PyRun_SimpleStringFlags+0x3c) [0x55633d7a605c]
60  /opt/conda/envs/gdf/bin/python(Py_RunMain+0x267) [0x55633d7a5297]
61  /opt/conda/envs/gdf/bin/python(Py_BytesMain+0x37) [0x55633d778f07]
=================================
[dgx13:86624:0:86624] Caught signal 11 (Segmentation fault: address not mapped to object at address 0x448)
==== backtrace (tid:  86624) ====
 0  /opt/conda/envs/gdf/lib/libucs.so.0(ucs_handle_error+0x2fd) [0x7f48bc7b007d]
 1  /opt/conda/envs/gdf/lib/libucs.so.0(+0x2a274) [0x7f48bc7b0274]
 2  /opt/conda/envs/gdf/lib/libucs.so.0(+0x2a43a) [0x7f48bc7b043a]
 3  /usr/lib/x86_64-linux-gnu/libpthread.so.0(+0x14420) [0x7f495db70420]
 4  /opt/conda/envs/gdf/lib/libucp.so.0(ucp_mem_type_unpack+0x14) [0x7f48bc82f6b4]
 5  /opt/conda/envs/gdf/lib/libucp.so.0(ucp_rndv_data_handler+0x4e9) [0x7f48bc858839]
 6  /opt/conda/envs/gdf/lib/libuct.so.0(+0x203df) [0x7f48bc76a3df]
 7  /opt/conda/envs/gdf/lib/libuct.so.0(+0x23838) [0x7f48bc76d838]
 8  /opt/conda/envs/gdf/lib/libucs.so.0(ucs_event_set_wait+0xb9) [0x7f48bc7b94a9]
 9  /opt/conda/envs/gdf/lib/libuct.so.0(uct_tcp_iface_progress+0x7d) [0x7f48bc76c5dd]
10  /opt/conda/envs/gdf/lib/libucp.so.0(ucp_worker_progress+0x5a) [0x7f48bc82c8da]
11  /opt/conda/envs/gdf/lib/python3.9/site-packages/ucp/_libs/ucx_api.cpython-39-x86_64-linux-gnu.so(+0x3206a) [0x7f48bc8e506a]
12  /opt/conda/envs/gdf/bin/python(_PyEval_EvalFrameDefault+0x37cb) [0x555c8aaf66fb]
13  /opt/conda/envs/gdf/bin/python(+0x12f094) [0x555c8aaf2094]
14  /opt/conda/envs/gdf/bin/python(_PyFunction_Vectorcall+0xd9) [0x555c8ab03519]
15  /opt/conda/envs/gdf/bin/python(_PyEval_EvalFrameDefault+0x696) [0x555c8aaf35c6]
16  /opt/conda/envs/gdf/bin/python(+0x1407c2) [0x555c8ab037c2]
17  /opt/conda/envs/gdf/bin/python(+0x14de83) [0x555c8ab10e83]
18  /opt/conda/envs/gdf/bin/python(+0x258b2c) [0x555c8ac1bb2c]
19  /opt/conda/envs/gdf/bin/python(+0xead05) [0x555c8aaadd05]
20  /opt/conda/envs/gdf/bin/python(+0x1377f3) [0x555c8aafa7f3]
21  /opt/conda/envs/gdf/bin/python(_PyEval_EvalFrameDefault+0x59f9) [0x555c8aaf8929]
22  /opt/conda/envs/gdf/bin/python(+0x1407c2) [0x555c8ab037c2]
23  /opt/conda/envs/gdf/bin/python(_PyEval_EvalFrameDefault+0x696) [0x555c8aaf35c6]
24  /opt/conda/envs/gdf/bin/python(+0x1407c2) [0x555c8ab037c2]
25  /opt/conda/envs/gdf/bin/python(_PyEval_EvalFrameDefault+0x696) [0x555c8aaf35c6]
26  /opt/conda/envs/gdf/bin/python(+0x1407c2) [0x555c8ab037c2]
27  /opt/conda/envs/gdf/bin/python(_PyEval_EvalFrameDefault+0x696) [0x555c8aaf35c6]
28  /opt/conda/envs/gdf/bin/python(+0x1407c2) [0x555c8ab037c2]
29  /opt/conda/envs/gdf/bin/python(_PyEval_EvalFrameDefault+0x696) [0x555c8aaf35c6]
30  /opt/conda/envs/gdf/bin/python(+0x12f094) [0x555c8aaf2094]
31  /opt/conda/envs/gdf/bin/python(_PyFunction_Vectorcall+0xd9) [0x555c8ab03519]
32  /opt/conda/envs/gdf/bin/python(_PyEval_EvalFrameDefault+0x11f8) [0x555c8aaf4128]
33  /opt/conda/envs/gdf/bin/python(+0x12f094) [0x555c8aaf2094]
34  /opt/conda/envs/gdf/bin/python(+0x14dccb) [0x555c8ab10ccb]
35  /opt/conda/envs/gdf/bin/python(PyObject_Call+0xbc) [0x555c8ab1144c]
36  /opt/conda/envs/gdf/bin/python(+0x21110e) [0x555c8abd410e]
37  /opt/conda/envs/gdf/bin/python(_PyObject_MakeTpCall+0x2ec) [0x555c8aafb77c]
38  /opt/conda/envs/gdf/bin/python(_PyEval_EvalFrameDefault+0x37cb) [0x555c8aaf66fb]
39  /opt/conda/envs/gdf/bin/python(+0x1407c2) [0x555c8ab037c2]
40  /opt/conda/envs/gdf/bin/python(+0x14ddac) [0x555c8ab10dac]
41  /opt/conda/envs/gdf/bin/python(_PyEval_EvalFrameDefault+0x37cb) [0x555c8aaf66fb]
42  /opt/conda/envs/gdf/bin/python(+0x1407c2) [0x555c8ab037c2]
43  /opt/conda/envs/gdf/bin/python(_PyEval_EvalFrameDefault+0x696) [0x555c8aaf35c6]
44  /opt/conda/envs/gdf/bin/python(+0x12f094) [0x555c8aaf2094]
45  /opt/conda/envs/gdf/bin/python(_PyFunction_Vectorcall+0xd9) [0x555c8ab03519]
46  /opt/conda/envs/gdf/bin/python(_PyEval_EvalFrameDefault+0x696) [0x555c8aaf35c6]
47  /opt/conda/envs/gdf/bin/python(+0x1407c2) [0x555c8ab037c2]
48  /opt/conda/envs/gdf/bin/python(_PyEval_EvalFrameDefault+0x3e2) [0x555c8aaf3312]
49  /opt/conda/envs/gdf/bin/python(+0x12f094) [0x555c8aaf2094]
50  /opt/conda/envs/gdf/bin/python(_PyFunction_Vectorcall+0xd9) [0x555c8ab03519]
51  /opt/conda/envs/gdf/bin/python(_PyEval_EvalFrameDefault+0x11f8) [0x555c8aaf4128]
52  /opt/conda/envs/gdf/bin/python(+0x12f094) [0x555c8aaf2094]
53  /opt/conda/envs/gdf/bin/python(_PyEval_EvalCodeWithName+0x48) [0x555c8aaf1d68]
54  /opt/conda/envs/gdf/bin/python(PyEval_EvalCodeEx+0x39) [0x555c8aaf1d19]
55  /opt/conda/envs/gdf/bin/python(PyEval_EvalCode+0x1b) [0x555c8ab9f07b]
56  /opt/conda/envs/gdf/bin/python(+0x208fca) [0x555c8abcbfca]
57  /opt/conda/envs/gdf/bin/python(+0x205353) [0x555c8abc8353]
58  /opt/conda/envs/gdf/bin/python(PyRun_StringFlags+0x9a) [0x555c8abc016a]
59  /opt/conda/envs/gdf/bin/python(PyRun_SimpleStringFlags+0x3c) [0x555c8abc005c]
60  /opt/conda/envs/gdf/bin/python(Py_RunMain+0x267) [0x555c8abbf297]
61  /opt/conda/envs/gdf/bin/python(Py_BytesMain+0x37) [0x555c8ab92f07]
=================================
[dgx13:86632:0:86632] Caught signal 11 (Segmentation fault: address not mapped to object at address 0x448)
==== backtrace (tid:  86632) ====
 0  /opt/conda/envs/gdf/lib/libucs.so.0(ucs_handle_error+0x2fd) [0x7fb2c404a07d]
 1  /opt/conda/envs/gdf/lib/libucs.so.0(+0x2a274) [0x7fb2c404a274]
 2  /opt/conda/envs/gdf/lib/libucs.so.0(+0x2a43a) [0x7fb2c404a43a]
 3  /usr/lib/x86_64-linux-gnu/libpthread.so.0(+0x14420) [0x7fb357287420]
 4  /opt/conda/envs/gdf/lib/libucp.so.0(ucp_mem_type_unpack+0x14) [0x7fb2b1ed06b4]
 5  /opt/conda/envs/gdf/lib/libucp.so.0(ucp_rndv_data_handler+0x4e9) [0x7fb2b1ef9839]
 6  /opt/conda/envs/gdf/lib/libuct.so.0(+0x203df) [0x7fb2b1e6a3df]
 7  /opt/conda/envs/gdf/lib/libuct.so.0(+0x23838) [0x7fb2b1e6d838]
 8  /opt/conda/envs/gdf/lib/libucs.so.0(ucs_event_set_wait+0xb9) [0x7fb2c40534a9]
 9  /opt/conda/envs/gdf/lib/libuct.so.0(uct_tcp_iface_progress+0x7d) [0x7fb2b1e6c5dd]
10  /opt/conda/envs/gdf/lib/libucp.so.0(ucp_worker_progress+0x5a) [0x7fb2b1ecd8da]
11  /opt/conda/envs/gdf/lib/python3.9/site-packages/ucp/_libs/ucx_api.cpython-39-x86_64-linux-gnu.so(+0x3206a) [0x7fb2b1f8606a]
12  /opt/conda/envs/gdf/bin/python(_PyEval_EvalFrameDefault+0x37cb) [0x55fd54ef46fb]
13  /opt/conda/envs/gdf/bin/python(+0x12f094) [0x55fd54ef0094]
14  /opt/conda/envs/gdf/bin/python(_PyFunction_Vectorcall+0xd9) [0x55fd54f01519]
15  /opt/conda/envs/gdf/bin/python(_PyEval_EvalFrameDefault+0x696) [0x55fd54ef15c6]
16  /opt/conda/envs/gdf/bin/python(+0x1407c2) [0x55fd54f017c2]
17  /opt/conda/envs/gdf/bin/python(+0x14de83) [0x55fd54f0ee83]
18  /opt/conda/envs/gdf/bin/python(+0x258b2c) [0x55fd55019b2c]
19  /opt/conda/envs/gdf/bin/python(+0xead05) [0x55fd54eabd05]
20  /opt/conda/envs/gdf/bin/python(+0x1377f3) [0x55fd54ef87f3]
21  /opt/conda/envs/gdf/bin/python(_PyEval_EvalFrameDefault+0x59f9) [0x55fd54ef6929]
22  /opt/conda/envs/gdf/bin/python(+0x1407c2) [0x55fd54f017c2]
23  /opt/conda/envs/gdf/bin/python(_PyEval_EvalFrameDefault+0x696) [0x55fd54ef15c6]
24  /opt/conda/envs/gdf/bin/python(+0x1407c2) [0x55fd54f017c2]
25  /opt/conda/envs/gdf/bin/python(_PyEval_EvalFrameDefault+0x696) [0x55fd54ef15c6]
26  /opt/conda/envs/gdf/bin/python(+0x1407c2) [0x55fd54f017c2]
27  /opt/conda/envs/gdf/bin/python(_PyEval_EvalFrameDefault+0x696) [0x55fd54ef15c6]
28  /opt/conda/envs/gdf/bin/python(+0x1407c2) [0x55fd54f017c2]
29  /opt/conda/envs/gdf/bin/python(_PyEval_EvalFrameDefault+0x696) [0x55fd54ef15c6]
30  /opt/conda/envs/gdf/bin/python(+0x12f094) [0x55fd54ef0094]
31  /opt/conda/envs/gdf/bin/python(_PyFunction_Vectorcall+0xd9) [0x55fd54f01519]
32  /opt/conda/envs/gdf/bin/python(_PyEval_EvalFrameDefault+0x11f8) [0x55fd54ef2128]
33  /opt/conda/envs/gdf/bin/python(+0x12f094) [0x55fd54ef0094]
34  /opt/conda/envs/gdf/bin/python(+0x14dccb) [0x55fd54f0eccb]
35  /opt/conda/envs/gdf/bin/python(PyObject_Call+0xbc) [0x55fd54f0f44c]
36  /opt/conda/envs/gdf/bin/python(+0x21110e) [0x55fd54fd210e]
37  /opt/conda/envs/gdf/bin/python(_PyObject_MakeTpCall+0x2ec) [0x55fd54ef977c]
38  /opt/conda/envs/gdf/bin/python(_PyEval_EvalFrameDefault+0x37cb) [0x55fd54ef46fb]
39  /opt/conda/envs/gdf/bin/python(+0x1407c2) [0x55fd54f017c2]
40  /opt/conda/envs/gdf/bin/python(+0x14ddac) [0x55fd54f0edac]
41  /opt/conda/envs/gdf/bin/python(_PyEval_EvalFrameDefault+0x37cb) [0x55fd54ef46fb]
42  /opt/conda/envs/gdf/bin/python(+0x1407c2) [0x55fd54f017c2]
43  /opt/conda/envs/gdf/bin/python(_PyEval_EvalFrameDefault+0x696) [0x55fd54ef15c6]
44  /opt/conda/envs/gdf/bin/python(+0x12f094) [0x55fd54ef0094]
45  /opt/conda/envs/gdf/bin/python(_PyFunction_Vectorcall+0xd9) [0x55fd54f01519]
46  /opt/conda/envs/gdf/bin/python(_PyEval_EvalFrameDefault+0x696) [0x55fd54ef15c6]
47  /opt/conda/envs/gdf/bin/python(+0x1407c2) [0x55fd54f017c2]
48  /opt/conda/envs/gdf/bin/python(_PyEval_EvalFrameDefault+0x3e2) [0x55fd54ef1312]
49  /opt/conda/envs/gdf/bin/python(+0x12f094) [0x55fd54ef0094]
50  /opt/conda/envs/gdf/bin/python(_PyFunction_Vectorcall+0xd9) [0x55fd54f01519]
51  /opt/conda/envs/gdf/bin/python(_PyEval_EvalFrameDefault+0x11f8) [0x55fd54ef2128]
52  /opt/conda/envs/gdf/bin/python(+0x12f094) [0x55fd54ef0094]
53  /opt/conda/envs/gdf/bin/python(_PyEval_EvalCodeWithName+0x48) [0x55fd54eefd68]
54  /opt/conda/envs/gdf/bin/python(PyEval_EvalCodeEx+0x39) [0x55fd54eefd19]
55  /opt/conda/envs/gdf/bin/python(PyEval_EvalCode+0x1b) [0x55fd54f9d07b]
56  /opt/conda/envs/gdf/bin/python(+0x208fca) [0x55fd54fc9fca]
57  /opt/conda/envs/gdf/bin/python(+0x205353) [0x55fd54fc6353]
58  /opt/conda/envs/gdf/bin/python(PyRun_StringFlags+0x9a) [0x55fd54fbe16a]
59  /opt/conda/envs/gdf/bin/python(PyRun_SimpleStringFlags+0x3c) [0x55fd54fbe05c]
60  /opt/conda/envs/gdf/bin/python(Py_RunMain+0x267) [0x55fd54fbd297]
61  /opt/conda/envs/gdf/bin/python(Py_BytesMain+0x37) [0x55fd54f90f07]
=================================
Task exception was never retrieved
future: <Task finished name='Task-275' coro=<_listener_handler_coroutine() done, defined at /opt/conda/envs/gdf/lib/python3.9/site-packages/ucp/core.py:128> exception=UCXError('<stream_send>: Connection reset by remote peer')>
Traceback (most recent call last):
  File "/opt/conda/envs/gdf/lib/python3.9/site-packages/ucp/core.py", line 143, in _listener_handler_coroutine
    peer_info = await exchange_peer_info(
  File "/opt/conda/envs/gdf/lib/python3.9/site-packages/ucp/core.py", line 51, in exchange_peer_info
    await comm.stream_send(endpoint, my_info_arr, my_info_arr.nbytes)
ucp._libs.exceptions.UCXError: <stream_send>: Connection reset by remote peer
Task exception was never retrieved
future: <Task finished name='Task-266' coro=<_listener_handler_coroutine() done, defined at /opt/conda/envs/gdf/lib/python3.9/site-packages/ucp/core.py:128> exception=UCXError('<stream_send>: Connection reset by remote peer')>
Traceback (most recent call last):
  File "/opt/conda/envs/gdf/lib/python3.9/site-packages/ucp/core.py", line 143, in _listener_handler_coroutine
    peer_info = await exchange_peer_info(
  File "/opt/conda/envs/gdf/lib/python3.9/site-packages/ucp/core.py", line 51, in exchange_peer_info
    await comm.stream_send(endpoint, my_info_arr, my_info_arr.nbytes)
ucp._libs.exceptions.UCXError: <stream_send>: Connection reset by remote peer
Task exception was never retrieved
future: <Task finished name='Task-380' coro=<_listener_handler_coroutine() done, defined at /opt/conda/envs/gdf/lib/python3.9/site-packages/ucp/core.py:128> exception=UCXError('<stream_send>: Connection reset by remote peer')>
Traceback (most recent call last):
  File "/opt/conda/envs/gdf/lib/python3.9/site-packages/ucp/core.py", line 143, in _listener_handler_coroutine
    peer_info = await exchange_peer_info(
  File "/opt/conda/envs/gdf/lib/python3.9/site-packages/ucp/core.py", line 51, in exchange_peer_info
    await comm.stream_send(endpoint, my_info_arr, my_info_arr.nbytes)
ucp._libs.exceptions.UCXError: <stream_send>: Connection reset by remote peer
2023-11-30 07:33:41,854 - distributed.worker - ERROR - Worker stream died during communication: ucx://127.0.0.1:49223
Traceback (most recent call last):
  File "/opt/conda/envs/gdf/lib/python3.9/site-packages/distributed/comm/ucx.py", line 471, in connect
    ep = await ucp.create_endpoint(ip, port)
  File "/opt/conda/envs/gdf/lib/python3.9/site-packages/ucp/core.py", line 1004, in create_endpoint
    return await _get_ctx().create_endpoint(
  File "/opt/conda/envs/gdf/lib/python3.9/site-packages/ucp/core.py", line 316, in create_endpoint
    peer_info = await exchange_peer_info(
  File "/opt/conda/envs/gdf/lib/python3.9/site-packages/ucp/core.py", line 54, in exchange_peer_info
    await comm.stream_recv(endpoint, peer_info_arr, peer_info_arr.nbytes)
ucp._libs.exceptions.UCXError: <stream_recv>: Connection reset by remote peer

During handling of the above exception, another exception occurred:

Traceback (most recent call last):
  File "/opt/conda/envs/gdf/lib/python3.9/site-packages/distributed/comm/core.py", line 342, in connect
    comm = await wait_for(
  File "/opt/conda/envs/gdf/lib/python3.9/site-packages/distributed/utils.py", line 1920, in wait_for
    return await asyncio.wait_for(fut, timeout)
  File "/opt/conda/envs/gdf/lib/python3.9/asyncio/tasks.py", line 479, in wait_for
    return fut.result()
  File "/opt/conda/envs/gdf/lib/python3.9/site-packages/distributed/comm/ucx.py", line 473, in connect
    raise CommClosedError("Connection closed before handshake completed")
distributed.comm.core.CommClosedError: Connection closed before handshake completed

During handling of the above exception, another exception occurred:

Traceback (most recent call last):
  File "/opt/conda/envs/gdf/lib/python3.9/site-packages/distributed/core.py", line 1516, in _connect
    comm = await connect(
  File "/opt/conda/envs/gdf/lib/python3.9/site-packages/distributed/comm/core.py", line 366, in connect
    await asyncio.sleep(backoff)
  File "/opt/conda/envs/gdf/lib/python3.9/asyncio/tasks.py", line 652, in sleep
    return await future
asyncio.exceptions.CancelledError

During handling of the above exception, another exception occurred:

Traceback (most recent call last):
  File "/opt/conda/envs/gdf/lib/python3.9/site-packages/distributed/core.py", line 1626, in connect
    return connect_attempt.result()
asyncio.exceptions.CancelledError

During handling of the above exception, another exception occurred:

Traceback (most recent call last):
  File "/opt/conda/envs/gdf/lib/python3.9/site-packages/distributed/worker.py", line 2059, in gather_dep
    response = await get_data_from_worker(
  File "/opt/conda/envs/gdf/lib/python3.9/site-packages/distributed/worker.py", line 2849, in get_data_from_worker
    comm = await rpc.connect(worker)
  File "/opt/conda/envs/gdf/lib/python3.9/site-packages/distributed/core.py", line 1628, in connect
    raise CommClosedError(reason)
distributed.comm.core.CommClosedError: Address removed.
2023-11-30 07:33:41,855 - distributed.worker - ERROR - Worker stream died during communication: ucx://127.0.0.1:49223
Traceback (most recent call last):
  File "/opt/conda/envs/gdf/lib/python3.9/site-packages/distributed/comm/ucx.py", line 471, in connect
    ep = await ucp.create_endpoint(ip, port)
  File "/opt/conda/envs/gdf/lib/python3.9/site-packages/ucp/core.py", line 1004, in create_endpoint
    return await _get_ctx().create_endpoint(
  File "/opt/conda/envs/gdf/lib/python3.9/site-packages/ucp/core.py", line 316, in create_endpoint
    peer_info = await exchange_peer_info(
  File "/opt/conda/envs/gdf/lib/python3.9/site-packages/ucp/core.py", line 54, in exchange_peer_info
    await comm.stream_recv(endpoint, peer_info_arr, peer_info_arr.nbytes)
ucp._libs.exceptions.UCXError: <stream_recv>: Connection reset by remote peer

During handling of the above exception, another exception occurred:

Traceback (most recent call last):
  File "/opt/conda/envs/gdf/lib/python3.9/site-packages/distributed/comm/core.py", line 342, in connect
    comm = await wait_for(
  File "/opt/conda/envs/gdf/lib/python3.9/site-packages/distributed/utils.py", line 1920, in wait_for
    return await asyncio.wait_for(fut, timeout)
  File "/opt/conda/envs/gdf/lib/python3.9/asyncio/tasks.py", line 479, in wait_for
    return fut.result()
  File "/opt/conda/envs/gdf/lib/python3.9/site-packages/distributed/comm/ucx.py", line 473, in connect
    raise CommClosedError("Connection closed before handshake completed")
distributed.comm.core.CommClosedError: Connection closed before handshake completed

During handling of the above exception, another exception occurred:

Traceback (most recent call last):
  File "/opt/conda/envs/gdf/lib/python3.9/site-packages/distributed/core.py", line 1516, in _connect
    comm = await connect(
  File "/opt/conda/envs/gdf/lib/python3.9/site-packages/distributed/comm/core.py", line 366, in connect
    await asyncio.sleep(backoff)
  File "/opt/conda/envs/gdf/lib/python3.9/asyncio/tasks.py", line 652, in sleep
    return await future
asyncio.exceptions.CancelledError

During handling of the above exception, another exception occurred:

Traceback (most recent call last):
  File "/opt/conda/envs/gdf/lib/python3.9/site-packages/distributed/core.py", line 1626, in connect
    return connect_attempt.result()
asyncio.exceptions.CancelledError

During handling of the above exception, another exception occurred:

Traceback (most recent call last):
  File "/opt/conda/envs/gdf/lib/python3.9/site-packages/distributed/worker.py", line 2059, in gather_dep
    response = await get_data_from_worker(
  File "/opt/conda/envs/gdf/lib/python3.9/site-packages/distributed/worker.py", line 2849, in get_data_from_worker
    comm = await rpc.connect(worker)
  File "/opt/conda/envs/gdf/lib/python3.9/site-packages/distributed/core.py", line 1628, in connect
    raise CommClosedError(reason)
distributed.comm.core.CommClosedError: Address removed.
2023-11-30 07:33:41,854 - distributed.worker - ERROR - Worker stream died during communication: ucx://127.0.0.1:49223
Traceback (most recent call last):
  File "/opt/conda/envs/gdf/lib/python3.9/site-packages/distributed/comm/ucx.py", line 471, in connect
    ep = await ucp.create_endpoint(ip, port)
  File "/opt/conda/envs/gdf/lib/python3.9/site-packages/ucp/core.py", line 1004, in create_endpoint
    return await _get_ctx().create_endpoint(
  File "/opt/conda/envs/gdf/lib/python3.9/site-packages/ucp/core.py", line 316, in create_endpoint
    peer_info = await exchange_peer_info(
  File "/opt/conda/envs/gdf/lib/python3.9/site-packages/ucp/core.py", line 54, in exchange_peer_info
    await comm.stream_recv(endpoint, peer_info_arr, peer_info_arr.nbytes)
ucp._libs.exceptions.UCXError: <stream_recv>: Connection reset by remote peer

During handling of the above exception, another exception occurred:

Traceback (most recent call last):
  File "/opt/conda/envs/gdf/lib/python3.9/site-packages/distributed/comm/core.py", line 342, in connect
    comm = await wait_for(
  File "/opt/conda/envs/gdf/lib/python3.9/site-packages/distributed/utils.py", line 1920, in wait_for
    return await asyncio.wait_for(fut, timeout)
  File "/opt/conda/envs/gdf/lib/python3.9/asyncio/tasks.py", line 479, in wait_for
    return fut.result()
  File "/opt/conda/envs/gdf/lib/python3.9/site-packages/distributed/comm/ucx.py", line 473, in connect
    raise CommClosedError("Connection closed before handshake completed")
distributed.comm.core.CommClosedError: Connection closed before handshake completed

During handling of the above exception, another exception occurred:

Traceback (most recent call last):
  File "/opt/conda/envs/gdf/lib/python3.9/site-packages/distributed/core.py", line 1516, in _connect
    comm = await connect(
  File "/opt/conda/envs/gdf/lib/python3.9/site-packages/distributed/comm/core.py", line 366, in connect
    await asyncio.sleep(backoff)
  File "/opt/conda/envs/gdf/lib/python3.9/asyncio/tasks.py", line 652, in sleep
    return await future
asyncio.exceptions.CancelledError

During handling of the above exception, another exception occurred:

Traceback (most recent call last):
  File "/opt/conda/envs/gdf/lib/python3.9/site-packages/distributed/core.py", line 1626, in connect
    return connect_attempt.result()
asyncio.exceptions.CancelledError

During handling of the above exception, another exception occurred:

Traceback (most recent call last):
  File "/opt/conda/envs/gdf/lib/python3.9/site-packages/distributed/worker.py", line 2059, in gather_dep
    response = await get_data_from_worker(
  File "/opt/conda/envs/gdf/lib/python3.9/site-packages/distributed/worker.py", line 2849, in get_data_from_worker
    comm = await rpc.connect(worker)
  File "/opt/conda/envs/gdf/lib/python3.9/site-packages/distributed/core.py", line 1628, in connect
    raise CommClosedError(reason)
distributed.comm.core.CommClosedError: Address removed.
2023-11-30 07:33:41,905 - distributed.worker - ERROR - Worker stream died during communication: ucx://127.0.0.1:40913
Traceback (most recent call last):
  File "/opt/conda/envs/gdf/lib/python3.9/site-packages/distributed/comm/ucx.py", line 396, in read
    await self.ep.recv(each_frame)
  File "/opt/conda/envs/gdf/lib/python3.9/site-packages/ucp/core.py", line 725, in recv
    ret = await comm.tag_recv(self._ep, buffer, nbytes, tag, name=log)
ucp._libs.exceptions.UCXError: <[Recv #007] ep: 0x7fce42512100, tag: 0x9e8b62add89e4946, nbytes: 50000000, type: <class 'rmm._lib.device_buffer.DeviceBuffer'>>: Connection reset by remote peer

During handling of the above exception, another exception occurred:

Traceback (most recent call last):
  File "/opt/conda/envs/gdf/lib/python3.9/site-packages/distributed/worker.py", line 2059, in gather_dep
    response = await get_data_from_worker(
  File "/opt/conda/envs/gdf/lib/python3.9/site-packages/distributed/worker.py", line 2852, in get_data_from_worker
    response = await send_recv(
  File "/opt/conda/envs/gdf/lib/python3.9/site-packages/distributed/core.py", line 1106, in send_recv
    response = await comm.read(deserializers=deserializers)
  File "/opt/conda/envs/gdf/lib/python3.9/site-packages/distributed/utils.py", line 803, in wrapper
    return await func(*args, **kwargs)
  File "/opt/conda/envs/gdf/lib/python3.9/site-packages/distributed/comm/ucx.py", line 402, in read
    raise CommClosedError(
distributed.comm.core.CommClosedError: Connection closed by writer.
Inner exception: UCXError("<[Recv #007] ep: 0x7fce42512100, tag: 0x9e8b62add89e4946, nbytes: 50000000, type: <class 'rmm._lib.device_buffer.DeviceBuffer'>>: Connection reset by remote peer")
2023-11-30 07:33:41,905 - distributed.worker - ERROR - Worker stream died during communication: ucx://127.0.0.1:40913
Traceback (most recent call last):
  File "/opt/conda/envs/gdf/lib/python3.9/site-packages/distributed/comm/ucx.py", line 354, in read
    await self.ep.recv(msg)
  File "/opt/conda/envs/gdf/lib/python3.9/site-packages/ucp/core.py", line 725, in recv
    ret = await comm.tag_recv(self._ep, buffer, nbytes, tag, name=log)
ucp._libs.exceptions.UCXCanceled: <[Recv #003] ep: 0x7f84787aa140, tag: 0xb773c6bcba54423b, nbytes: 16, type: <class 'numpy.ndarray'>>: 

During handling of the above exception, another exception occurred:

Traceback (most recent call last):
  File "/opt/conda/envs/gdf/lib/python3.9/site-packages/distributed/worker.py", line 2059, in gather_dep
    response = await get_data_from_worker(
  File "/opt/conda/envs/gdf/lib/python3.9/site-packages/distributed/worker.py", line 2852, in get_data_from_worker
    response = await send_recv(
  File "/opt/conda/envs/gdf/lib/python3.9/site-packages/distributed/core.py", line 1106, in send_recv
    response = await comm.read(deserializers=deserializers)
  File "/opt/conda/envs/gdf/lib/python3.9/site-packages/distributed/utils.py", line 803, in wrapper
    return await func(*args, **kwargs)
  File "/opt/conda/envs/gdf/lib/python3.9/site-packages/distributed/comm/ucx.py", line 372, in read
    raise CommClosedError(
distributed.comm.core.CommClosedError: Connection closed by writer.
Inner exception: UCXCanceled("<[Recv #003] ep: 0x7f84787aa140, tag: 0xb773c6bcba54423b, nbytes: 16, type: <class 'numpy.ndarray'>>: ")
2023-11-30 07:33:41,906 - distributed.worker - ERROR - failed during get data with ucx://127.0.0.1:46241 -> ucx://127.0.0.1:40913
Traceback (most recent call last):
  File "/opt/conda/envs/gdf/lib/python3.9/site-packages/distributed/comm/ucx.py", line 338, in write
    await self.ep.send(each_frame)
  File "/opt/conda/envs/gdf/lib/python3.9/site-packages/ucp/core.py", line 650, in send
    return await comm.tag_send(self._ep, buffer, nbytes, tag, name=log)
ucp._libs.exceptions.UCXError: <[Send #007] ep: 0x7fce42512240, tag: 0x6e5b00532b07951f, nbytes: 50000000, type: <class 'cupy.ndarray'>>: Connection reset by remote peer

During handling of the above exception, another exception occurred:

Traceback (most recent call last):
  File "/opt/conda/envs/gdf/lib/python3.9/site-packages/distributed/worker.py", line 1782, in get_data
    compressed = await comm.write(msg, serializers=serializers)
  File "/opt/conda/envs/gdf/lib/python3.9/site-packages/distributed/utils.py", line 803, in wrapper
    return await func(*args, **kwargs)
  File "/opt/conda/envs/gdf/lib/python3.9/site-packages/distributed/comm/ucx.py", line 342, in write
    raise CommClosedError("While writing, the connection was closed")
distributed.comm.core.CommClosedError: While writing, the connection was closed
2023-11-30 07:33:41,918 - distributed.worker - ERROR - failed during get data with ucx://127.0.0.1:55455 -> ucx://127.0.0.1:41665
Traceback (most recent call last):
  File "/opt/conda/envs/gdf/lib/python3.9/site-packages/distributed/comm/ucx.py", line 338, in write
    await self.ep.send(each_frame)
  File "/opt/conda/envs/gdf/lib/python3.9/site-packages/ucp/core.py", line 650, in send
    return await comm.tag_send(self._ep, buffer, nbytes, tag, name=log)
ucp._libs.exceptions.UCXError: <[Send #007] ep: 0x7f84787aa2c0, tag: 0xa98932ea01add211, nbytes: 50000000, type: <class 'cupy.ndarray'>>: Connection reset by remote peer

During handling of the above exception, another exception occurred:

Traceback (most recent call last):
  File "/opt/conda/envs/gdf/lib/python3.9/site-packages/distributed/worker.py", line 1782, in get_data
    compressed = await comm.write(msg, serializers=serializers)
  File "/opt/conda/envs/gdf/lib/python3.9/site-packages/distributed/utils.py", line 803, in wrapper
    return await func(*args, **kwargs)
  File "/opt/conda/envs/gdf/lib/python3.9/site-packages/distributed/comm/ucx.py", line 342, in write
    raise CommClosedError("While writing, the connection was closed")
distributed.comm.core.CommClosedError: While writing, the connection was closed
Task exception was never retrieved
future: <Task finished name='Task-382' coro=<_listener_handler_coroutine() done, defined at /opt/conda/envs/gdf/lib/python3.9/site-packages/ucp/core.py:128> exception=UCXError('<stream_recv>: Connection reset by remote peer')>
Traceback (most recent call last):
  File "/opt/conda/envs/gdf/lib/python3.9/site-packages/ucp/core.py", line 143, in _listener_handler_coroutine
    peer_info = await exchange_peer_info(
  File "/opt/conda/envs/gdf/lib/python3.9/site-packages/ucp/core.py", line 52, in exchange_peer_info
    await comm.stream_recv(endpoint, peer_info_arr, peer_info_arr.nbytes)
ucp._libs.exceptions.UCXError: <stream_recv>: Connection reset by remote peer
2023-11-30 07:33:41,950 - distributed.worker - ERROR - Worker stream died during communication: ucx://127.0.0.1:45301
Traceback (most recent call last):
  File "/opt/conda/envs/gdf/lib/python3.9/site-packages/distributed/comm/ucx.py", line 471, in connect
    ep = await ucp.create_endpoint(ip, port)
  File "/opt/conda/envs/gdf/lib/python3.9/site-packages/ucp/core.py", line 1004, in create_endpoint
    return await _get_ctx().create_endpoint(
  File "/opt/conda/envs/gdf/lib/python3.9/site-packages/ucp/core.py", line 316, in create_endpoint
    peer_info = await exchange_peer_info(
  File "/opt/conda/envs/gdf/lib/python3.9/site-packages/ucp/core.py", line 54, in exchange_peer_info
    await comm.stream_recv(endpoint, peer_info_arr, peer_info_arr.nbytes)
ucp._libs.exceptions.UCXError: <stream_recv>: Connection reset by remote peer

During handling of the above exception, another exception occurred:

Traceback (most recent call last):
  File "/opt/conda/envs/gdf/lib/python3.9/site-packages/distributed/comm/core.py", line 342, in connect
    comm = await wait_for(
  File "/opt/conda/envs/gdf/lib/python3.9/site-packages/distributed/utils.py", line 1920, in wait_for
    return await asyncio.wait_for(fut, timeout)
  File "/opt/conda/envs/gdf/lib/python3.9/asyncio/tasks.py", line 479, in wait_for
    return fut.result()
  File "/opt/conda/envs/gdf/lib/python3.9/site-packages/distributed/comm/ucx.py", line 473, in connect
    raise CommClosedError("Connection closed before handshake completed")
distributed.comm.core.CommClosedError: Connection closed before handshake completed

During handling of the above exception, another exception occurred:

Traceback (most recent call last):
  File "/opt/conda/envs/gdf/lib/python3.9/site-packages/distributed/core.py", line 1516, in _connect
    comm = await connect(
  File "/opt/conda/envs/gdf/lib/python3.9/site-packages/distributed/comm/core.py", line 366, in connect
    await asyncio.sleep(backoff)
  File "/opt/conda/envs/gdf/lib/python3.9/asyncio/tasks.py", line 652, in sleep
    return await future
asyncio.exceptions.CancelledError

During handling of the above exception, another exception occurred:

Traceback (most recent call last):
  File "/opt/conda/envs/gdf/lib/python3.9/site-packages/distributed/core.py", line 1626, in connect
    return connect_attempt.result()
asyncio.exceptions.CancelledError

During handling of the above exception, another exception occurred:

Traceback (most recent call last):
  File "/opt/conda/envs/gdf/lib/python3.9/site-packages/distributed/worker.py", line 2059, in gather_dep
    response = await get_data_from_worker(
  File "/opt/conda/envs/gdf/lib/python3.9/site-packages/distributed/worker.py", line 2849, in get_data_from_worker
    comm = await rpc.connect(worker)
  File "/opt/conda/envs/gdf/lib/python3.9/site-packages/distributed/core.py", line 1628, in connect
    raise CommClosedError(reason)
distributed.comm.core.CommClosedError: Address removed.
2023-11-30 07:33:42,042 - distributed.worker - ERROR - failed during get data with ucx://127.0.0.1:55455 -> ucx://127.0.0.1:57771
Traceback (most recent call last):
  File "/opt/conda/envs/gdf/lib/python3.9/site-packages/distributed/comm/ucx.py", line 338, in write
    await self.ep.send(each_frame)
  File "/opt/conda/envs/gdf/lib/python3.9/site-packages/ucp/core.py", line 650, in send
    return await comm.tag_send(self._ep, buffer, nbytes, tag, name=log)
ucp._libs.exceptions.UCXError: <[Send #007] ep: 0x7f84787aa300, tag: 0x47c24061934ce5ec, nbytes: 50000000, type: <class 'cupy.ndarray'>>: Connection reset by remote peer

During handling of the above exception, another exception occurred:

Traceback (most recent call last):
  File "/opt/conda/envs/gdf/lib/python3.9/site-packages/distributed/worker.py", line 1782, in get_data
    compressed = await comm.write(msg, serializers=serializers)
  File "/opt/conda/envs/gdf/lib/python3.9/site-packages/distributed/utils.py", line 803, in wrapper
    return await func(*args, **kwargs)
  File "/opt/conda/envs/gdf/lib/python3.9/site-packages/distributed/comm/ucx.py", line 342, in write
    raise CommClosedError("While writing, the connection was closed")
distributed.comm.core.CommClosedError: While writing, the connection was closed
2023-11-30 07:33:42,043 - distributed.worker - ERROR - Worker stream died during communication: ucx://127.0.0.1:57771
Traceback (most recent call last):
  File "/opt/conda/envs/gdf/lib/python3.9/site-packages/distributed/comm/ucx.py", line 396, in read
    await self.ep.recv(each_frame)
  File "/opt/conda/envs/gdf/lib/python3.9/site-packages/ucp/core.py", line 725, in recv
    ret = await comm.tag_recv(self._ep, buffer, nbytes, tag, name=log)
ucp._libs.exceptions.UCXError: <[Recv #007] ep: 0x7f84787aa180, tag: 0xf40e3e2334f46895, nbytes: 50000000, type: <class 'rmm._lib.device_buffer.DeviceBuffer'>>: Connection reset by remote peer

During handling of the above exception, another exception occurred:

Traceback (most recent call last):
  File "/opt/conda/envs/gdf/lib/python3.9/site-packages/distributed/worker.py", line 2059, in gather_dep
    response = await get_data_from_worker(
  File "/opt/conda/envs/gdf/lib/python3.9/site-packages/distributed/worker.py", line 2852, in get_data_from_worker
    response = await send_recv(
  File "/opt/conda/envs/gdf/lib/python3.9/site-packages/distributed/core.py", line 1106, in send_recv
    response = await comm.read(deserializers=deserializers)
  File "/opt/conda/envs/gdf/lib/python3.9/site-packages/distributed/utils.py", line 803, in wrapper
    return await func(*args, **kwargs)
  File "/opt/conda/envs/gdf/lib/python3.9/site-packages/distributed/comm/ucx.py", line 402, in read
    raise CommClosedError(
distributed.comm.core.CommClosedError: Connection closed by writer.
Inner exception: UCXError("<[Recv #007] ep: 0x7f84787aa180, tag: 0xf40e3e2334f46895, nbytes: 50000000, type: <class 'rmm._lib.device_buffer.DeviceBuffer'>>: Connection reset by remote peer")
2023-11-30 07:33:42,177 - distributed.worker - ERROR - Worker stream died during communication: ucx://127.0.0.1:57771
Traceback (most recent call last):
  File "/opt/conda/envs/gdf/lib/python3.9/site-packages/distributed/comm/ucx.py", line 354, in read
    await self.ep.recv(msg)
  File "/opt/conda/envs/gdf/lib/python3.9/site-packages/ucp/core.py", line 725, in recv
    ret = await comm.tag_recv(self._ep, buffer, nbytes, tag, name=log)
ucp._libs.exceptions.UCXCanceled: <[Recv #008] ep: 0x7f0dd4cc1240, tag: 0x893514eca10f4816, nbytes: 16, type: <class 'numpy.ndarray'>>: 

During handling of the above exception, another exception occurred:

Traceback (most recent call last):
  File "/opt/conda/envs/gdf/lib/python3.9/site-packages/distributed/worker.py", line 2059, in gather_dep
    response = await get_data_from_worker(
  File "/opt/conda/envs/gdf/lib/python3.9/site-packages/distributed/worker.py", line 2852, in get_data_from_worker
    response = await send_recv(
  File "/opt/conda/envs/gdf/lib/python3.9/site-packages/distributed/core.py", line 1106, in send_recv
    response = await comm.read(deserializers=deserializers)
  File "/opt/conda/envs/gdf/lib/python3.9/site-packages/distributed/utils.py", line 803, in wrapper
    return await func(*args, **kwargs)
  File "/opt/conda/envs/gdf/lib/python3.9/site-packages/distributed/comm/ucx.py", line 372, in read
    raise CommClosedError(
distributed.comm.core.CommClosedError: Connection closed by writer.
Inner exception: UCXCanceled("<[Recv #008] ep: 0x7f0dd4cc1240, tag: 0x893514eca10f4816, nbytes: 16, type: <class 'numpy.ndarray'>>: ")
2023-11-30 07:33:47,848 - distributed.nanny - WARNING - Restarting worker
2023-11-30 07:33:48,251 - distributed.nanny - WARNING - Restarting worker
2023-11-30 07:33:48,438 - distributed.nanny - WARNING - Restarting worker
2023-11-30 07:33:48,481 - distributed.nanny - WARNING - Restarting worker
2023-11-30 07:33:48,528 - distributed.nanny - WARNING - Restarting worker
[dgx13:86782:0:86782] Caught signal 11 (Segmentation fault: address not mapped to object at address 0x448)
==== backtrace (tid:  86782) ====
 0  /opt/conda/envs/gdf/lib/libucs.so.0(ucs_handle_error+0x2fd) [0x7f9c1cf8707d]
 1  /opt/conda/envs/gdf/lib/libucs.so.0(+0x2a274) [0x7f9c1cf87274]
 2  /opt/conda/envs/gdf/lib/libucs.so.0(+0x2a43a) [0x7f9c1cf8743a]
 3  /usr/lib/x86_64-linux-gnu/libpthread.so.0(+0x14420) [0x7f9cb0235420]
 4  /opt/conda/envs/gdf/lib/libucp.so.0(ucp_mem_type_unpack+0x14) [0x7f9c1d0066b4]
 5  /opt/conda/envs/gdf/lib/libucp.so.0(ucp_rndv_data_handler+0x4e9) [0x7f9c1d02f839]
 6  /opt/conda/envs/gdf/lib/libuct.so.0(+0x203df) [0x7f9c1cf413df]
 7  /opt/conda/envs/gdf/lib/libuct.so.0(+0x23838) [0x7f9c1cf44838]
 8  /opt/conda/envs/gdf/lib/libucs.so.0(ucs_event_set_wait+0xb9) [0x7f9c1cf904a9]
 9  /opt/conda/envs/gdf/lib/libuct.so.0(uct_tcp_iface_progress+0x7d) [0x7f9c1cf435dd]
10  /opt/conda/envs/gdf/lib/libucp.so.0(ucp_worker_progress+0x5a) [0x7f9c1d0038da]
11  /opt/conda/envs/gdf/lib/python3.9/site-packages/ucp/_libs/ucx_api.cpython-39-x86_64-linux-gnu.so(+0x3206a) [0x7f9c1d0bc06a]
12  /opt/conda/envs/gdf/bin/python(_PyEval_EvalFrameDefault+0x37cb) [0x55c5929ad6fb]
13  /opt/conda/envs/gdf/bin/python(+0x12f094) [0x55c5929a9094]
14  /opt/conda/envs/gdf/bin/python(_PyFunction_Vectorcall+0xd9) [0x55c5929ba519]
15  /opt/conda/envs/gdf/bin/python(_PyEval_EvalFrameDefault+0x696) [0x55c5929aa5c6]
16  /opt/conda/envs/gdf/bin/python(+0x1e3162) [0x55c592a5d162]
17  /opt/conda/envs/gdf/lib/python3.9/lib-dynload/_asyncio.cpython-39-x86_64-linux-gnu.so(+0x81e9) [0x7f9ca61df1e9]
18  /opt/conda/envs/gdf/bin/python(_PyObject_MakeTpCall+0x2ec) [0x55c5929b277c]
19  /opt/conda/envs/gdf/bin/python(+0xead05) [0x55c592964d05]
20  /opt/conda/envs/gdf/bin/python(+0x1377f3) [0x55c5929b17f3]
21  /opt/conda/envs/gdf/bin/python(_PyEval_EvalFrameDefault+0x59f9) [0x55c5929af929]
22  /opt/conda/envs/gdf/bin/python(+0x1407c2) [0x55c5929ba7c2]
23  /opt/conda/envs/gdf/bin/python(_PyEval_EvalFrameDefault+0x696) [0x55c5929aa5c6]
24  /opt/conda/envs/gdf/bin/python(+0x1407c2) [0x55c5929ba7c2]
25  /opt/conda/envs/gdf/bin/python(_PyEval_EvalFrameDefault+0x696) [0x55c5929aa5c6]
26  /opt/conda/envs/gdf/bin/python(+0x1407c2) [0x55c5929ba7c2]
27  /opt/conda/envs/gdf/bin/python(_PyEval_EvalFrameDefault+0x696) [0x55c5929aa5c6]
28  /opt/conda/envs/gdf/bin/python(+0x1407c2) [0x55c5929ba7c2]
29  /opt/conda/envs/gdf/bin/python(_PyEval_EvalFrameDefault+0x696) [0x55c5929aa5c6]
30  /opt/conda/envs/gdf/bin/python(+0x12f094) [0x55c5929a9094]
31  /opt/conda/envs/gdf/bin/python(_PyFunction_Vectorcall+0xd9) [0x55c5929ba519]
32  /opt/conda/envs/gdf/bin/python(_PyEval_EvalFrameDefault+0x11f8) [0x55c5929ab128]
33  /opt/conda/envs/gdf/bin/python(+0x12f094) [0x55c5929a9094]
34  /opt/conda/envs/gdf/bin/python(+0x14dccb) [0x55c5929c7ccb]
35  /opt/conda/envs/gdf/bin/python(PyObject_Call+0xbc) [0x55c5929c844c]
36  /opt/conda/envs/gdf/bin/python(+0x21110e) [0x55c592a8b10e]
37  /opt/conda/envs/gdf/bin/python(_PyObject_MakeTpCall+0x2ec) [0x55c5929b277c]
38  /opt/conda/envs/gdf/bin/python(_PyEval_EvalFrameDefault+0x37cb) [0x55c5929ad6fb]
39  /opt/conda/envs/gdf/bin/python(+0x1407c2) [0x55c5929ba7c2]
40  /opt/conda/envs/gdf/bin/python(+0x14ddac) [0x55c5929c7dac]
41  /opt/conda/envs/gdf/bin/python(_PyEval_EvalFrameDefault+0x37cb) [0x55c5929ad6fb]
42  /opt/conda/envs/gdf/bin/python(+0x1407c2) [0x55c5929ba7c2]
43  /opt/conda/envs/gdf/bin/python(_PyEval_EvalFrameDefault+0x696) [0x55c5929aa5c6]
44  /opt/conda/envs/gdf/bin/python(+0x12f094) [0x55c5929a9094]
45  /opt/conda/envs/gdf/bin/python(_PyFunction_Vectorcall+0xd9) [0x55c5929ba519]
46  /opt/conda/envs/gdf/bin/python(_PyEval_EvalFrameDefault+0x696) [0x55c5929aa5c6]
47  /opt/conda/envs/gdf/bin/python(+0x1407c2) [0x55c5929ba7c2]
48  /opt/conda/envs/gdf/bin/python(_PyEval_EvalFrameDefault+0x3e2) [0x55c5929aa312]
49  /opt/conda/envs/gdf/bin/python(+0x12f094) [0x55c5929a9094]
50  /opt/conda/envs/gdf/bin/python(_PyFunction_Vectorcall+0xd9) [0x55c5929ba519]
51  /opt/conda/envs/gdf/bin/python(_PyEval_EvalFrameDefault+0x11f8) [0x55c5929ab128]
52  /opt/conda/envs/gdf/bin/python(+0x12f094) [0x55c5929a9094]
53  /opt/conda/envs/gdf/bin/python(_PyEval_EvalCodeWithName+0x48) [0x55c5929a8d68]
54  /opt/conda/envs/gdf/bin/python(PyEval_EvalCodeEx+0x39) [0x55c5929a8d19]
55  /opt/conda/envs/gdf/bin/python(PyEval_EvalCode+0x1b) [0x55c592a5607b]
56  /opt/conda/envs/gdf/bin/python(+0x208fca) [0x55c592a82fca]
57  /opt/conda/envs/gdf/bin/python(+0x205353) [0x55c592a7f353]
58  /opt/conda/envs/gdf/bin/python(PyRun_StringFlags+0x9a) [0x55c592a7716a]
59  /opt/conda/envs/gdf/bin/python(PyRun_SimpleStringFlags+0x3c) [0x55c592a7705c]
60  /opt/conda/envs/gdf/bin/python(Py_RunMain+0x267) [0x55c592a76297]
61  /opt/conda/envs/gdf/bin/python(Py_BytesMain+0x37) [0x55c592a49f07]
=================================
[dgx13:86792:0:86792] Caught signal 11 (Segmentation fault: address not mapped to object at address 0x448)
==== backtrace (tid:  86792) ====
 0  /opt/conda/envs/gdf/lib/libucs.so.0(ucs_handle_error+0x2fd) [0x7faa7784f07d]
 1  /opt/conda/envs/gdf/lib/libucs.so.0(+0x2a274) [0x7faa7784f274]
 2  /opt/conda/envs/gdf/lib/libucs.so.0(+0x2a43a) [0x7faa7784f43a]
 3  /usr/lib/x86_64-linux-gnu/libpthread.so.0(+0x14420) [0x7fab30ae2420]
 4  /opt/conda/envs/gdf/lib/libucp.so.0(ucp_mem_type_unpack+0x14) [0x7faa778ce6b4]
 5  /opt/conda/envs/gdf/lib/libucp.so.0(ucp_rndv_data_handler+0x4e9) [0x7faa778f7839]
 6  /opt/conda/envs/gdf/lib/libuct.so.0(+0x203df) [0x7faa778093df]
 7  /opt/conda/envs/gdf/lib/libuct.so.0(+0x23838) [0x7faa7780c838]
 8  /opt/conda/envs/gdf/lib/libucs.so.0(ucs_event_set_wait+0xb9) [0x7faa778584a9]
 9  /opt/conda/envs/gdf/lib/libuct.so.0(uct_tcp_iface_progress+0x7d) [0x7faa7780b5dd]
10  /opt/conda/envs/gdf/lib/libucp.so.0(ucp_worker_progress+0x5a) [0x7faa778cb8da]
11  /opt/conda/envs/gdf/lib/python3.9/site-packages/ucp/_libs/ucx_api.cpython-39-x86_64-linux-gnu.so(+0x3206a) [0x7faa7798406a]
12  /opt/conda/envs/gdf/bin/python(_PyEval_EvalFrameDefault+0x37cb) [0x564da85756fb]
13  /opt/conda/envs/gdf/bin/python(+0x12f094) [0x564da8571094]
14  /opt/conda/envs/gdf/bin/python(_PyFunction_Vectorcall+0xd9) [0x564da8582519]
15  /opt/conda/envs/gdf/bin/python(_PyEval_EvalFrameDefault+0x696) [0x564da85725c6]
16  /opt/conda/envs/gdf/bin/python(+0x1407c2) [0x564da85827c2]
17  /opt/conda/envs/gdf/bin/python(+0x14de83) [0x564da858fe83]
18  /opt/conda/envs/gdf/bin/python(+0x258b2c) [0x564da869ab2c]
19  /opt/conda/envs/gdf/bin/python(+0xead05) [0x564da852cd05]
20  /opt/conda/envs/gdf/bin/python(+0x1377f3) [0x564da85797f3]
21  /opt/conda/envs/gdf/bin/python(_PyEval_EvalFrameDefault+0x59f9) [0x564da8577929]
22  /opt/conda/envs/gdf/bin/python(+0x1407c2) [0x564da85827c2]
23  /opt/conda/envs/gdf/bin/python(_PyEval_EvalFrameDefault+0x696) [0x564da85725c6]
24  /opt/conda/envs/gdf/bin/python(+0x1407c2) [0x564da85827c2]
25  /opt/conda/envs/gdf/bin/python(_PyEval_EvalFrameDefault+0x696) [0x564da85725c6]
26  /opt/conda/envs/gdf/bin/python(+0x1407c2) [0x564da85827c2]
27  /opt/conda/envs/gdf/bin/python(_PyEval_EvalFrameDefault+0x696) [0x564da85725c6]
28  /opt/conda/envs/gdf/bin/python(+0x1407c2) [0x564da85827c2]
29  /opt/conda/envs/gdf/bin/python(_PyEval_EvalFrameDefault+0x696) [0x564da85725c6]
30  /opt/conda/envs/gdf/bin/python(+0x12f094) [0x564da8571094]
31  /opt/conda/envs/gdf/bin/python(_PyFunction_Vectorcall+0xd9) [0x564da8582519]
32  /opt/conda/envs/gdf/bin/python(_PyEval_EvalFrameDefault+0x11f8) [0x564da8573128]
33  /opt/conda/envs/gdf/bin/python(+0x12f094) [0x564da8571094]
34  /opt/conda/envs/gdf/bin/python(+0x14dccb) [0x564da858fccb]
35  /opt/conda/envs/gdf/bin/python(PyObject_Call+0xbc) [0x564da859044c]
36  /opt/conda/envs/gdf/bin/python(+0x21110e) [0x564da865310e]
37  /opt/conda/envs/gdf/bin/python(_PyObject_MakeTpCall+0x2ec) [0x564da857a77c]
38  /opt/conda/envs/gdf/bin/python(_PyEval_EvalFrameDefault+0x37cb) [0x564da85756fb]
39  /opt/conda/envs/gdf/bin/python(+0x1407c2) [0x564da85827c2]
40  /opt/conda/envs/gdf/bin/python(+0x14ddac) [0x564da858fdac]
41  /opt/conda/envs/gdf/bin/python(_PyEval_EvalFrameDefault+0x37cb) [0x564da85756fb]
42  /opt/conda/envs/gdf/bin/python(+0x1407c2) [0x564da85827c2]
43  /opt/conda/envs/gdf/bin/python(_PyEval_EvalFrameDefault+0x696) [0x564da85725c6]
44  /opt/conda/envs/gdf/bin/python(+0x12f094) [0x564da8571094]
45  /opt/conda/envs/gdf/bin/python(_PyFunction_Vectorcall+0xd9) [0x564da8582519]
46  /opt/conda/envs/gdf/bin/python(_PyEval_EvalFrameDefault+0x696) [0x564da85725c6]
47  /opt/conda/envs/gdf/bin/python(+0x1407c2) [0x564da85827c2]
48  /opt/conda/envs/gdf/bin/python(_PyEval_EvalFrameDefault+0x3e2) [0x564da8572312]
49  /opt/conda/envs/gdf/bin/python(+0x12f094) [0x564da8571094]
50  /opt/conda/envs/gdf/bin/python(_PyFunction_Vectorcall+0xd9) [0x564da8582519]
51  /opt/conda/envs/gdf/bin/python(_PyEval_EvalFrameDefault+0x11f8) [0x564da8573128]
52  /opt/conda/envs/gdf/bin/python(+0x12f094) [0x564da8571094]
53  /opt/conda/envs/gdf/bin/python(_PyEval_EvalCodeWithName+0x48) [0x564da8570d68]
54  /opt/conda/envs/gdf/bin/python(PyEval_EvalCodeEx+0x39) [0x564da8570d19]
55  /opt/conda/envs/gdf/bin/python(PyEval_EvalCode+0x1b) [0x564da861e07b]
56  /opt/conda/envs/gdf/bin/python(+0x208fca) [0x564da864afca]
57  /opt/conda/envs/gdf/bin/python(+0x205353) [0x564da8647353]
58  /opt/conda/envs/gdf/bin/python(PyRun_StringFlags+0x9a) [0x564da863f16a]
59  /opt/conda/envs/gdf/bin/python(PyRun_SimpleStringFlags+0x3c) [0x564da863f05c]
60  /opt/conda/envs/gdf/bin/python(Py_RunMain+0x267) [0x564da863e297]
61  /opt/conda/envs/gdf/bin/python(Py_BytesMain+0x37) [0x564da8611f07]
=================================
2023-11-30 07:33:52,300 - distributed.worker - ERROR - failed during get data with ucx://127.0.0.1:46241 -> ucx://127.0.0.1:56337
Traceback (most recent call last):
  File "/opt/conda/envs/gdf/lib/python3.9/site-packages/distributed/comm/ucx.py", line 338, in write
    await self.ep.send(each_frame)
  File "/opt/conda/envs/gdf/lib/python3.9/site-packages/ucp/core.py", line 650, in send
    return await comm.tag_send(self._ep, buffer, nbytes, tag, name=log)
ucp._libs.exceptions.UCXError: <[Send #007] ep: 0x7fce42512100, tag: 0x4e17f239a9068c6e, nbytes: 50000000, type: <class 'cupy.ndarray'>>: Connection reset by remote peer

During handling of the above exception, another exception occurred:

Traceback (most recent call last):
  File "/opt/conda/envs/gdf/lib/python3.9/site-packages/distributed/worker.py", line 1782, in get_data
    compressed = await comm.write(msg, serializers=serializers)
  File "/opt/conda/envs/gdf/lib/python3.9/site-packages/distributed/utils.py", line 803, in wrapper
    return await func(*args, **kwargs)
  File "/opt/conda/envs/gdf/lib/python3.9/site-packages/distributed/comm/ucx.py", line 342, in write
    raise CommClosedError("While writing, the connection was closed")
distributed.comm.core.CommClosedError: While writing, the connection was closed
2023-11-30 07:33:52,300 - distributed.worker - ERROR - Worker stream died during communication: ucx://127.0.0.1:56337
Traceback (most recent call last):
  File "/opt/conda/envs/gdf/lib/python3.9/site-packages/distributed/comm/ucx.py", line 396, in read
    await self.ep.recv(each_frame)
  File "/opt/conda/envs/gdf/lib/python3.9/site-packages/ucp/core.py", line 725, in recv
    ret = await comm.tag_recv(self._ep, buffer, nbytes, tag, name=log)
ucp._libs.exceptions.UCXError: <[Recv #007] ep: 0x7fce42512240, tag: 0xa3e273e272729d84, nbytes: 50000000, type: <class 'rmm._lib.device_buffer.DeviceBuffer'>>: Connection reset by remote peer

During handling of the above exception, another exception occurred:

Traceback (most recent call last):
  File "/opt/conda/envs/gdf/lib/python3.9/site-packages/distributed/worker.py", line 2059, in gather_dep
    response = await get_data_from_worker(
  File "/opt/conda/envs/gdf/lib/python3.9/site-packages/distributed/worker.py", line 2852, in get_data_from_worker
    response = await send_recv(
  File "/opt/conda/envs/gdf/lib/python3.9/site-packages/distributed/core.py", line 1106, in send_recv
    response = await comm.read(deserializers=deserializers)
  File "/opt/conda/envs/gdf/lib/python3.9/site-packages/distributed/utils.py", line 803, in wrapper
    return await func(*args, **kwargs)
  File "/opt/conda/envs/gdf/lib/python3.9/site-packages/distributed/comm/ucx.py", line 402, in read
    raise CommClosedError(
distributed.comm.core.CommClosedError: Connection closed by writer.
Inner exception: UCXError("<[Recv #007] ep: 0x7fce42512240, tag: 0xa3e273e272729d84, nbytes: 50000000, type: <class 'rmm._lib.device_buffer.DeviceBuffer'>>: Connection reset by remote peer")
Task exception was never retrieved
future: <Task finished name='Task-239' coro=<_listener_handler_coroutine() done, defined at /opt/conda/envs/gdf/lib/python3.9/site-packages/ucp/core.py:128> exception=UCXError('<stream_send>: Connection reset by remote peer')>
Traceback (most recent call last):
  File "/opt/conda/envs/gdf/lib/python3.9/site-packages/ucp/core.py", line 143, in _listener_handler_coroutine
    peer_info = await exchange_peer_info(
  File "/opt/conda/envs/gdf/lib/python3.9/site-packages/ucp/core.py", line 51, in exchange_peer_info
    await comm.stream_send(endpoint, my_info_arr, my_info_arr.nbytes)
ucp._libs.exceptions.UCXError: <stream_send>: Connection reset by remote peer
2023-11-30 07:33:52,307 - distributed.worker - ERROR - Worker stream died during communication: ucx://127.0.0.1:56337
Traceback (most recent call last):
  File "/opt/conda/envs/gdf/lib/python3.9/site-packages/distributed/comm/ucx.py", line 471, in connect
    ep = await ucp.create_endpoint(ip, port)
  File "/opt/conda/envs/gdf/lib/python3.9/site-packages/ucp/core.py", line 1004, in create_endpoint
    return await _get_ctx().create_endpoint(
  File "/opt/conda/envs/gdf/lib/python3.9/site-packages/ucp/core.py", line 316, in create_endpoint
    peer_info = await exchange_peer_info(
  File "/opt/conda/envs/gdf/lib/python3.9/site-packages/ucp/core.py", line 54, in exchange_peer_info
    await comm.stream_recv(endpoint, peer_info_arr, peer_info_arr.nbytes)
ucp._libs.exceptions.UCXError: <stream_recv>: Connection reset by remote peer

During handling of the above exception, another exception occurred:

Traceback (most recent call last):
  File "/opt/conda/envs/gdf/lib/python3.9/site-packages/distributed/comm/core.py", line 342, in connect
    comm = await wait_for(
  File "/opt/conda/envs/gdf/lib/python3.9/site-packages/distributed/utils.py", line 1920, in wait_for
    return await asyncio.wait_for(fut, timeout)
  File "/opt/conda/envs/gdf/lib/python3.9/asyncio/tasks.py", line 479, in wait_for
    return fut.result()
  File "/opt/conda/envs/gdf/lib/python3.9/site-packages/distributed/comm/ucx.py", line 473, in connect
    raise CommClosedError("Connection closed before handshake completed")
distributed.comm.core.CommClosedError: Connection closed before handshake completed

During handling of the above exception, another exception occurred:

Traceback (most recent call last):
  File "/opt/conda/envs/gdf/lib/python3.9/site-packages/distributed/core.py", line 1516, in _connect
    comm = await connect(
  File "/opt/conda/envs/gdf/lib/python3.9/site-packages/distributed/comm/core.py", line 366, in connect
    await asyncio.sleep(backoff)
  File "/opt/conda/envs/gdf/lib/python3.9/asyncio/tasks.py", line 652, in sleep
    return await future
asyncio.exceptions.CancelledError

During handling of the above exception, another exception occurred:

Traceback (most recent call last):
  File "/opt/conda/envs/gdf/lib/python3.9/site-packages/distributed/core.py", line 1626, in connect
    return connect_attempt.result()
asyncio.exceptions.CancelledError

During handling of the above exception, another exception occurred:

Traceback (most recent call last):
  File "/opt/conda/envs/gdf/lib/python3.9/site-packages/distributed/worker.py", line 2059, in gather_dep
    response = await get_data_from_worker(
  File "/opt/conda/envs/gdf/lib/python3.9/site-packages/distributed/worker.py", line 2849, in get_data_from_worker
    comm = await rpc.connect(worker)
  File "/opt/conda/envs/gdf/lib/python3.9/site-packages/distributed/core.py", line 1628, in connect
    raise CommClosedError(reason)
distributed.comm.core.CommClosedError: Address removed.
[dgx13:86785:0:86785] Caught signal 11 (Segmentation fault: address not mapped to object at address 0x448)
==== backtrace (tid:  86785) ====
 0  /opt/conda/envs/gdf/lib/libucs.so.0(ucs_handle_error+0x2fd) [0x7fd36561c07d]
 1  /opt/conda/envs/gdf/lib/libucs.so.0(+0x2a274) [0x7fd36561c274]
 2  /opt/conda/envs/gdf/lib/libucs.so.0(+0x2a43a) [0x7fd36561c43a]
 3  /usr/lib/x86_64-linux-gnu/libpthread.so.0(+0x14420) [0x7fd40a8b3420]
 4  /opt/conda/envs/gdf/lib/libucp.so.0(ucp_mem_type_unpack+0x14) [0x7fd36569b6b4]
 5  /opt/conda/envs/gdf/lib/libucp.so.0(ucp_rndv_data_handler+0x4e9) [0x7fd3656c4839]
 6  /opt/conda/envs/gdf/lib/libuct.so.0(+0x203df) [0x7fd3655d63df]
 7  /opt/conda/envs/gdf/lib/libuct.so.0(+0x23838) [0x7fd3655d9838]
 8  /opt/conda/envs/gdf/lib/libucs.so.0(ucs_event_set_wait+0xb9) [0x7fd3656254a9]
 9  /opt/conda/envs/gdf/lib/libuct.so.0(uct_tcp_iface_progress+0x7d) [0x7fd3655d85dd]
10  /opt/conda/envs/gdf/lib/libucp.so.0(ucp_worker_progress+0x5a) [0x7fd3656988da]
11  /opt/conda/envs/gdf/lib/python3.9/site-packages/ucp/_libs/ucx_api.cpython-39-x86_64-linux-gnu.so(+0x3206a) [0x7fd36575106a]
12  /opt/conda/envs/gdf/bin/python(_PyEval_EvalFrameDefault+0x37cb) [0x564bca6d66fb]
13  /opt/conda/envs/gdf/bin/python(+0x12f094) [0x564bca6d2094]
14  /opt/conda/envs/gdf/bin/python(_PyFunction_Vectorcall+0xd9) [0x564bca6e3519]
15  /opt/conda/envs/gdf/bin/python(_PyEval_EvalFrameDefault+0x696) [0x564bca6d35c6]
16  /opt/conda/envs/gdf/bin/python(+0x1e3162) [0x564bca786162]
17  /opt/conda/envs/gdf/lib/python3.9/lib-dynload/_asyncio.cpython-39-x86_64-linux-gnu.so(+0x81e9) [0x7fd40085f1e9]
18  /opt/conda/envs/gdf/bin/python(_PyObject_MakeTpCall+0x2ec) [0x564bca6db77c]
19  /opt/conda/envs/gdf/bin/python(+0xead05) [0x564bca68dd05]
20  /opt/conda/envs/gdf/bin/python(+0x1377f3) [0x564bca6da7f3]
21  /opt/conda/envs/gdf/bin/python(_PyEval_EvalFrameDefault+0x59f9) [0x564bca6d8929]
22  /opt/conda/envs/gdf/bin/python(+0x1407c2) [0x564bca6e37c2]
23  /opt/conda/envs/gdf/bin/python(_PyEval_EvalFrameDefault+0x696) [0x564bca6d35c6]
24  /opt/conda/envs/gdf/bin/python(+0x1407c2) [0x564bca6e37c2]
25  /opt/conda/envs/gdf/bin/python(_PyEval_EvalFrameDefault+0x696) [0x564bca6d35c6]
26  /opt/conda/envs/gdf/bin/python(+0x1407c2) [0x564bca6e37c2]
27  /opt/conda/envs/gdf/bin/python(_PyEval_EvalFrameDefault+0x696) [0x564bca6d35c6]
28  /opt/conda/envs/gdf/bin/python(+0x1407c2) [0x564bca6e37c2]
29  /opt/conda/envs/gdf/bin/python(_PyEval_EvalFrameDefault+0x696) [0x564bca6d35c6]
30  /opt/conda/envs/gdf/bin/python(+0x12f094) [0x564bca6d2094]
31  /opt/conda/envs/gdf/bin/python(_PyFunction_Vectorcall+0xd9) [0x564bca6e3519]
32  /opt/conda/envs/gdf/bin/python(_PyEval_EvalFrameDefault+0x11f8) [0x564bca6d4128]
33  /opt/conda/envs/gdf/bin/python(+0x12f094) [0x564bca6d2094]
34  /opt/conda/envs/gdf/bin/python(+0x14dccb) [0x564bca6f0ccb]
35  /opt/conda/envs/gdf/bin/python(PyObject_Call+0xbc) [0x564bca6f144c]
36  /opt/conda/envs/gdf/bin/python(+0x21110e) [0x564bca7b410e]
37  /opt/conda/envs/gdf/bin/python(_PyObject_MakeTpCall+0x2ec) [0x564bca6db77c]
38  /opt/conda/envs/gdf/bin/python(_PyEval_EvalFrameDefault+0x37cb) [0x564bca6d66fb]
39  /opt/conda/envs/gdf/bin/python(+0x1407c2) [0x564bca6e37c2]
40  /opt/conda/envs/gdf/bin/python(+0x14ddac) [0x564bca6f0dac]
41  /opt/conda/envs/gdf/bin/python(_PyEval_EvalFrameDefault+0x37cb) [0x564bca6d66fb]
42  /opt/conda/envs/gdf/bin/python(+0x1407c2) [0x564bca6e37c2]
43  /opt/conda/envs/gdf/bin/python(_PyEval_EvalFrameDefault+0x696) [0x564bca6d35c6]
44  /opt/conda/envs/gdf/bin/python(+0x12f094) [0x564bca6d2094]
45  /opt/conda/envs/gdf/bin/python(_PyFunction_Vectorcall+0xd9) [0x564bca6e3519]
46  /opt/conda/envs/gdf/bin/python(_PyEval_EvalFrameDefault+0x696) [0x564bca6d35c6]
47  /opt/conda/envs/gdf/bin/python(+0x1407c2) [0x564bca6e37c2]
48  /opt/conda/envs/gdf/bin/python(_PyEval_EvalFrameDefault+0x3e2) [0x564bca6d3312]
49  /opt/conda/envs/gdf/bin/python(+0x12f094) [0x564bca6d2094]
50  /opt/conda/envs/gdf/bin/python(_PyFunction_Vectorcall+0xd9) [0x564bca6e3519]
51  /opt/conda/envs/gdf/bin/python(_PyEval_EvalFrameDefault+0x11f8) [0x564bca6d4128]
52  /opt/conda/envs/gdf/bin/python(+0x12f094) [0x564bca6d2094]
53  /opt/conda/envs/gdf/bin/python(_PyEval_EvalCodeWithName+0x48) [0x564bca6d1d68]
54  /opt/conda/envs/gdf/bin/python(PyEval_EvalCodeEx+0x39) [0x564bca6d1d19]
55  /opt/conda/envs/gdf/bin/python(PyEval_EvalCode+0x1b) [0x564bca77f07b]
56  /opt/conda/envs/gdf/bin/python(+0x208fca) [0x564bca7abfca]
57  /opt/conda/envs/gdf/bin/python(+0x205353) [0x564bca7a8353]
58  /opt/conda/envs/gdf/bin/python(PyRun_StringFlags+0x9a) [0x564bca7a016a]
59  /opt/conda/envs/gdf/bin/python(PyRun_SimpleStringFlags+0x3c) [0x564bca7a005c]
60  /opt/conda/envs/gdf/bin/python(Py_RunMain+0x267) [0x564bca79f297]
61  /opt/conda/envs/gdf/bin/python(Py_BytesMain+0x37) [0x564bca772f07]
=================================
2023-11-30 07:33:52,426 - distributed.worker - ERROR - failed during get data with ucx://127.0.0.1:46241 -> ucx://127.0.0.1:59113
Traceback (most recent call last):
  File "/opt/conda/envs/gdf/lib/python3.9/site-packages/distributed/comm/ucx.py", line 338, in write
    await self.ep.send(each_frame)
  File "/opt/conda/envs/gdf/lib/python3.9/site-packages/ucp/core.py", line 650, in send
    return await comm.tag_send(self._ep, buffer, nbytes, tag, name=log)
ucp._libs.exceptions.UCXError: <[Send #007] ep: 0x7fce42512300, tag: 0x2f9465c0809a6a91, nbytes: 50000000, type: <class 'cupy.ndarray'>>: Connection reset by remote peer

During handling of the above exception, another exception occurred:

Traceback (most recent call last):
  File "/opt/conda/envs/gdf/lib/python3.9/site-packages/distributed/worker.py", line 1782, in get_data
    compressed = await comm.write(msg, serializers=serializers)
  File "/opt/conda/envs/gdf/lib/python3.9/site-packages/distributed/utils.py", line 803, in wrapper
    return await func(*args, **kwargs)
  File "/opt/conda/envs/gdf/lib/python3.9/site-packages/distributed/comm/ucx.py", line 342, in write
    raise CommClosedError("While writing, the connection was closed")
distributed.comm.core.CommClosedError: While writing, the connection was closed
2023-11-30 07:33:52,432 - distributed.worker - ERROR - Worker stream died during communication: ucx://127.0.0.1:59113
Traceback (most recent call last):
  File "/opt/conda/envs/gdf/lib/python3.9/site-packages/distributed/comm/ucx.py", line 471, in connect
    ep = await ucp.create_endpoint(ip, port)
  File "/opt/conda/envs/gdf/lib/python3.9/site-packages/ucp/core.py", line 1004, in create_endpoint
    return await _get_ctx().create_endpoint(
  File "/opt/conda/envs/gdf/lib/python3.9/site-packages/ucp/core.py", line 316, in create_endpoint
    peer_info = await exchange_peer_info(
  File "/opt/conda/envs/gdf/lib/python3.9/site-packages/ucp/core.py", line 54, in exchange_peer_info
    await comm.stream_recv(endpoint, peer_info_arr, peer_info_arr.nbytes)
ucp._libs.exceptions.UCXError: <stream_recv>: Connection reset by remote peer

During handling of the above exception, another exception occurred:

Traceback (most recent call last):
  File "/opt/conda/envs/gdf/lib/python3.9/site-packages/distributed/comm/core.py", line 342, in connect
    comm = await wait_for(
  File "/opt/conda/envs/gdf/lib/python3.9/site-packages/distributed/utils.py", line 1920, in wait_for
    return await asyncio.wait_for(fut, timeout)
  File "/opt/conda/envs/gdf/lib/python3.9/asyncio/tasks.py", line 479, in wait_for
    return fut.result()
  File "/opt/conda/envs/gdf/lib/python3.9/site-packages/distributed/comm/ucx.py", line 473, in connect
    raise CommClosedError("Connection closed before handshake completed")
distributed.comm.core.CommClosedError: Connection closed before handshake completed

During handling of the above exception, another exception occurred:

Traceback (most recent call last):
  File "/opt/conda/envs/gdf/lib/python3.9/site-packages/distributed/core.py", line 1516, in _connect
    comm = await connect(
  File "/opt/conda/envs/gdf/lib/python3.9/site-packages/distributed/comm/core.py", line 366, in connect
    await asyncio.sleep(backoff)
  File "/opt/conda/envs/gdf/lib/python3.9/asyncio/tasks.py", line 652, in sleep
    return await future
asyncio.exceptions.CancelledError

During handling of the above exception, another exception occurred:

Traceback (most recent call last):
  File "/opt/conda/envs/gdf/lib/python3.9/site-packages/distributed/core.py", line 1626, in connect
    return connect_attempt.result()
asyncio.exceptions.CancelledError

During handling of the above exception, another exception occurred:

Traceback (most recent call last):
  File "/opt/conda/envs/gdf/lib/python3.9/site-packages/distributed/worker.py", line 2059, in gather_dep
    response = await get_data_from_worker(
  File "/opt/conda/envs/gdf/lib/python3.9/site-packages/distributed/worker.py", line 2849, in get_data_from_worker
    comm = await rpc.connect(worker)
  File "/opt/conda/envs/gdf/lib/python3.9/site-packages/distributed/core.py", line 1628, in connect
    raise CommClosedError(reason)
distributed.comm.core.CommClosedError: Address removed.
2023-11-30 07:33:53,131 - distributed.worker - ERROR - failed during get data with ucx://127.0.0.1:55705 -> ucx://127.0.0.1:58181
Traceback (most recent call last):
  File "/opt/conda/envs/gdf/lib/python3.9/site-packages/distributed/comm/ucx.py", line 338, in write
    await self.ep.send(each_frame)
  File "/opt/conda/envs/gdf/lib/python3.9/site-packages/ucp/core.py", line 650, in send
    return await comm.tag_send(self._ep, buffer, nbytes, tag, name=log)
ucp._libs.exceptions.UCXError: <[Send #007] ep: 0x7f0dd4cc1240, tag: 0x8eeba950a377638a, nbytes: 50000000, type: <class 'cupy.ndarray'>>: Connection reset by remote peer

During handling of the above exception, another exception occurred:

Traceback (most recent call last):
  File "/opt/conda/envs/gdf/lib/python3.9/site-packages/distributed/worker.py", line 1782, in get_data
    compressed = await comm.write(msg, serializers=serializers)
  File "/opt/conda/envs/gdf/lib/python3.9/site-packages/distributed/utils.py", line 803, in wrapper
    return await func(*args, **kwargs)
  File "/opt/conda/envs/gdf/lib/python3.9/site-packages/distributed/comm/ucx.py", line 342, in write
    raise CommClosedError("While writing, the connection was closed")
distributed.comm.core.CommClosedError: While writing, the connection was closed
2023-11-30 07:33:53,133 - distributed.worker - ERROR - Worker stream died during communication: ucx://127.0.0.1:58181
Traceback (most recent call last):
  File "/opt/conda/envs/gdf/lib/python3.9/site-packages/distributed/comm/ucx.py", line 354, in read
    await self.ep.recv(msg)
  File "/opt/conda/envs/gdf/lib/python3.9/site-packages/ucp/core.py", line 725, in recv
    ret = await comm.tag_recv(self._ep, buffer, nbytes, tag, name=log)
ucp._libs.exceptions.UCXCanceled: <[Recv #003] ep: 0x7fce42512240, tag: 0xa7e18ee1511b5de0, nbytes: 16, type: <class 'numpy.ndarray'>>: 

During handling of the above exception, another exception occurred:

Traceback (most recent call last):
  File "/opt/conda/envs/gdf/lib/python3.9/site-packages/distributed/worker.py", line 2059, in gather_dep
    response = await get_data_from_worker(
  File "/opt/conda/envs/gdf/lib/python3.9/site-packages/distributed/worker.py", line 2852, in get_data_from_worker
    response = await send_recv(
  File "/opt/conda/envs/gdf/lib/python3.9/site-packages/distributed/core.py", line 1106, in send_recv
    response = await comm.read(deserializers=deserializers)
  File "/opt/conda/envs/gdf/lib/python3.9/site-packages/distributed/utils.py", line 803, in wrapper
    return await func(*args, **kwargs)
  File "/opt/conda/envs/gdf/lib/python3.9/site-packages/distributed/comm/ucx.py", line 372, in read
    raise CommClosedError(
distributed.comm.core.CommClosedError: Connection closed by writer.
Inner exception: UCXCanceled("<[Recv #003] ep: 0x7fce42512240, tag: 0xa7e18ee1511b5de0, nbytes: 16, type: <class 'numpy.ndarray'>>: ")
Task exception was never retrieved
future: <Task finished name='Task-5816' coro=<_listener_handler_coroutine() done, defined at /opt/conda/envs/gdf/lib/python3.9/site-packages/ucp/core.py:128> exception=UCXError('<stream_send>: Connection reset by remote peer')>
Traceback (most recent call last):
  File "/opt/conda/envs/gdf/lib/python3.9/site-packages/ucp/core.py", line 143, in _listener_handler_coroutine
    peer_info = await exchange_peer_info(
  File "/opt/conda/envs/gdf/lib/python3.9/site-packages/ucp/core.py", line 51, in exchange_peer_info
    await comm.stream_send(endpoint, my_info_arr, my_info_arr.nbytes)
ucp._libs.exceptions.UCXError: <stream_send>: Connection reset by remote peer
2023-11-30 07:33:53,135 - distributed.worker - ERROR - Worker stream died during communication: ucx://127.0.0.1:58181
Traceback (most recent call last):
  File "/opt/conda/envs/gdf/lib/python3.9/site-packages/distributed/comm/ucx.py", line 471, in connect
    ep = await ucp.create_endpoint(ip, port)
  File "/opt/conda/envs/gdf/lib/python3.9/site-packages/ucp/core.py", line 1004, in create_endpoint
    return await _get_ctx().create_endpoint(
  File "/opt/conda/envs/gdf/lib/python3.9/site-packages/ucp/core.py", line 316, in create_endpoint
    peer_info = await exchange_peer_info(
  File "/opt/conda/envs/gdf/lib/python3.9/site-packages/ucp/core.py", line 54, in exchange_peer_info
    await comm.stream_recv(endpoint, peer_info_arr, peer_info_arr.nbytes)
ucp._libs.exceptions.UCXError: <stream_recv>: Connection reset by remote peer

During handling of the above exception, another exception occurred:

Traceback (most recent call last):
  File "/opt/conda/envs/gdf/lib/python3.9/site-packages/distributed/comm/core.py", line 342, in connect
    comm = await wait_for(
  File "/opt/conda/envs/gdf/lib/python3.9/site-packages/distributed/utils.py", line 1920, in wait_for
    return await asyncio.wait_for(fut, timeout)
  File "/opt/conda/envs/gdf/lib/python3.9/asyncio/tasks.py", line 479, in wait_for
    return fut.result()
  File "/opt/conda/envs/gdf/lib/python3.9/site-packages/distributed/comm/ucx.py", line 473, in connect
    raise CommClosedError("Connection closed before handshake completed")
distributed.comm.core.CommClosedError: Connection closed before handshake completed

During handling of the above exception, another exception occurred:

Traceback (most recent call last):
  File "/opt/conda/envs/gdf/lib/python3.9/site-packages/distributed/core.py", line 1516, in _connect
    comm = await connect(
  File "/opt/conda/envs/gdf/lib/python3.9/site-packages/distributed/comm/core.py", line 366, in connect
    await asyncio.sleep(backoff)
  File "/opt/conda/envs/gdf/lib/python3.9/asyncio/tasks.py", line 652, in sleep
    return await future
asyncio.exceptions.CancelledError

During handling of the above exception, another exception occurred:

Traceback (most recent call last):
  File "/opt/conda/envs/gdf/lib/python3.9/site-packages/distributed/core.py", line 1626, in connect
    return connect_attempt.result()
asyncio.exceptions.CancelledError

During handling of the above exception, another exception occurred:

Traceback (most recent call last):
  File "/opt/conda/envs/gdf/lib/python3.9/site-packages/distributed/worker.py", line 2059, in gather_dep
    response = await get_data_from_worker(
  File "/opt/conda/envs/gdf/lib/python3.9/site-packages/distributed/worker.py", line 2849, in get_data_from_worker
    comm = await rpc.connect(worker)
  File "/opt/conda/envs/gdf/lib/python3.9/site-packages/distributed/core.py", line 1628, in connect
    raise CommClosedError(reason)
distributed.comm.core.CommClosedError: Address removed.
2023-11-30 07:33:55,312 - distributed.nanny - WARNING - Restarting worker
2023-11-30 07:33:55,709 - distributed.nanny - WARNING - Restarting worker
2023-11-30 07:33:56,396 - distributed.nanny - WARNING - Restarting worker
/opt/conda/envs/gdf/lib/python3.9/multiprocessing/resource_tracker.py:216: UserWarning: resource_tracker: There appear to be 30 leaked semaphore objects to clean up at shutdown
  warnings.warn('resource_tracker: There appear to be %d '
