2023-01-16 01:53:58,610 - distributed.preloading - INFO - Creating preload: dask_cuda.initialize
2023-01-16 01:53:58,610 - distributed.preloading - INFO - Import preload module: dask_cuda.initialize
2023-01-16 01:53:58,611 - distributed.preloading - INFO - Creating preload: dask_cuda.initialize
2023-01-16 01:53:58,611 - distributed.preloading - INFO - Import preload module: dask_cuda.initialize
2023-01-16 01:53:58,611 - distributed.preloading - INFO - Creating preload: dask_cuda.initialize
2023-01-16 01:53:58,611 - distributed.preloading - INFO - Creating preload: dask_cuda.initialize
2023-01-16 01:53:58,611 - distributed.preloading - INFO - Import preload module: dask_cuda.initialize
2023-01-16 01:53:58,611 - distributed.preloading - INFO - Import preload module: dask_cuda.initialize
2023-01-16 01:53:58,612 - distributed.preloading - INFO - Creating preload: dask_cuda.initialize
2023-01-16 01:53:58,612 - distributed.preloading - INFO - Import preload module: dask_cuda.initialize
2023-01-16 01:53:58,612 - distributed.preloading - INFO - Creating preload: dask_cuda.initialize
2023-01-16 01:53:58,612 - distributed.preloading - INFO - Import preload module: dask_cuda.initialize
2023-01-16 01:53:58,612 - distributed.preloading - INFO - Creating preload: dask_cuda.initialize
2023-01-16 01:53:58,612 - distributed.preloading - INFO - Import preload module: dask_cuda.initialize
2023-01-16 01:53:58,612 - distributed.preloading - INFO - Creating preload: dask_cuda.initialize
2023-01-16 01:53:58,612 - distributed.preloading - INFO - Import preload module: dask_cuda.initialize
[dgx13:36155:0:36155] Caught signal 11 (Segmentation fault: address not mapped to object at address 0x448)
==== backtrace (tid:  36155) ====
 0  /datasets/pentschev/miniconda3/envs/gdf/lib/libucs.so.0(ucs_handle_error+0x2d4) [0x7f2b61dca1a4]
 1  /datasets/pentschev/miniconda3/envs/gdf/lib/libucs.so.0(+0x2e37f) [0x7f2b61dca37f]
 2  /datasets/pentschev/miniconda3/envs/gdf/lib/libucs.so.0(+0x2e6a4) [0x7f2b61dca6a4]
 3  /lib/x86_64-linux-gnu/libpthread.so.0(+0x12980) [0x7f2bed69f980]
 4  /datasets/pentschev/miniconda3/envs/gdf/lib/libucp.so.0(ucp_mem_type_unpack+0x14) [0x7f2b782a2e64]
 5  /datasets/pentschev/miniconda3/envs/gdf/lib/libucp.so.0(ucp_rndv_data_handler+0x508) [0x7f2b782d5358]
 6  /datasets/pentschev/miniconda3/envs/gdf/lib/libuct.so.0(+0x20b1f) [0x7f2b78032b1f]
 7  /datasets/pentschev/miniconda3/envs/gdf/lib/libuct.so.0(+0x210f4) [0x7f2b780330f4]
 8  /datasets/pentschev/miniconda3/envs/gdf/lib/libuct.so.0(+0x23548) [0x7f2b78035548]
 9  /datasets/pentschev/miniconda3/envs/gdf/lib/libucs.so.0(ucs_event_set_wait+0xb9) [0x7f2b61dd4879]
10  /datasets/pentschev/miniconda3/envs/gdf/lib/libuct.so.0(uct_tcp_iface_progress+0x7b) [0x7f2b780355eb]
11  /datasets/pentschev/miniconda3/envs/gdf/lib/libucp.so.0(ucp_worker_progress+0x6a) [0x7f2b7829f42a]
12  /datasets/pentschev/miniconda3/envs/gdf/lib/python3.9/site-packages/ucp/_libs/ucx_api.cpython-39-x86_64-linux-gnu.so(+0x26c79) [0x7f2b7855bc79]
13  /datasets/pentschev/miniconda3/envs/gdf/bin/python(+0x141eca) [0x55598382eeca]
14  /datasets/pentschev/miniconda3/envs/gdf/bin/python(_PyEval_EvalFrameDefault+0x3d99) [0x55598381c549]
15  /datasets/pentschev/miniconda3/envs/gdf/bin/python(+0x12a7d7) [0x5559838177d7]
16  /datasets/pentschev/miniconda3/envs/gdf/bin/python(_PyFunction_Vectorcall+0xb9) [0x555983829bb9]
17  /datasets/pentschev/miniconda3/envs/gdf/bin/python(_PyEval_EvalFrameDefault+0x672) [0x555983818e22]
18  /datasets/pentschev/miniconda3/envs/gdf/bin/python(+0x153244) [0x555983840244]
19  /datasets/pentschev/miniconda3/envs/gdf/lib/python3.9/lib-dynload/_asyncio.cpython-39-x86_64-linux-gnu.so(+0x8301) [0x7f2b87cb6301]
20  /datasets/pentschev/miniconda3/envs/gdf/bin/python(_PyObject_MakeTpCall+0x347) [0x555983821a57]
21  /datasets/pentschev/miniconda3/envs/gdf/bin/python(+0xf7187) [0x5559837e4187]
22  /datasets/pentschev/miniconda3/envs/gdf/bin/python(+0x133747) [0x555983820747]
23  /datasets/pentschev/miniconda3/envs/gdf/bin/python(_PyEval_EvalFrameDefault+0x5f0a) [0x55598381e6ba]
24  /datasets/pentschev/miniconda3/envs/gdf/bin/python(+0x13cec3) [0x555983829ec3]
25  /datasets/pentschev/miniconda3/envs/gdf/bin/python(_PyEval_EvalFrameDefault+0x672) [0x555983818e22]
26  /datasets/pentschev/miniconda3/envs/gdf/bin/python(+0x13cec3) [0x555983829ec3]
27  /datasets/pentschev/miniconda3/envs/gdf/bin/python(_PyEval_EvalFrameDefault+0x672) [0x555983818e22]
28  /datasets/pentschev/miniconda3/envs/gdf/bin/python(+0x13cec3) [0x555983829ec3]
29  /datasets/pentschev/miniconda3/envs/gdf/bin/python(_PyEval_EvalFrameDefault+0x672) [0x555983818e22]
30  /datasets/pentschev/miniconda3/envs/gdf/bin/python(+0x13cec3) [0x555983829ec3]
31  /datasets/pentschev/miniconda3/envs/gdf/bin/python(_PyEval_EvalFrameDefault+0x672) [0x555983818e22]
32  /datasets/pentschev/miniconda3/envs/gdf/bin/python(+0x12a7d7) [0x5559838177d7]
33  /datasets/pentschev/miniconda3/envs/gdf/bin/python(_PyFunction_Vectorcall+0xb9) [0x555983829bb9]
34  /datasets/pentschev/miniconda3/envs/gdf/bin/python(_PyEval_EvalFrameDefault+0x4cbc) [0x55598381d46c]
35  /datasets/pentschev/miniconda3/envs/gdf/bin/python(+0x12a7d7) [0x5559838177d7]
36  /datasets/pentschev/miniconda3/envs/gdf/bin/python(+0x14baf8) [0x555983838af8]
37  /datasets/pentschev/miniconda3/envs/gdf/bin/python(PyObject_Call+0xb4) [0x555983839254]
38  /datasets/pentschev/miniconda3/envs/gdf/bin/python(+0x21b8b8) [0x5559839088b8]
39  /datasets/pentschev/miniconda3/envs/gdf/bin/python(_PyObject_MakeTpCall+0x347) [0x555983821a57]
40  /datasets/pentschev/miniconda3/envs/gdf/bin/python(_PyEval_EvalFrameDefault+0x3d99) [0x55598381c549]
41  /datasets/pentschev/miniconda3/envs/gdf/bin/python(+0x13cec3) [0x555983829ec3]
42  /datasets/pentschev/miniconda3/envs/gdf/bin/python(+0x14bb91) [0x555983838b91]
43  /datasets/pentschev/miniconda3/envs/gdf/bin/python(_PyEval_EvalFrameDefault+0x3d99) [0x55598381c549]
44  /datasets/pentschev/miniconda3/envs/gdf/bin/python(+0x13cec3) [0x555983829ec3]
45  /datasets/pentschev/miniconda3/envs/gdf/bin/python(_PyEval_EvalFrameDefault+0x672) [0x555983818e22]
46  /datasets/pentschev/miniconda3/envs/gdf/bin/python(+0x12a7d7) [0x5559838177d7]
47  /datasets/pentschev/miniconda3/envs/gdf/bin/python(_PyFunction_Vectorcall+0xb9) [0x555983829bb9]
48  /datasets/pentschev/miniconda3/envs/gdf/bin/python(_PyEval_EvalFrameDefault+0x672) [0x555983818e22]
49  /datasets/pentschev/miniconda3/envs/gdf/bin/python(+0x13cec3) [0x555983829ec3]
50  /datasets/pentschev/miniconda3/envs/gdf/bin/python(_PyEval_EvalFrameDefault+0x3c3) [0x555983818b73]
51  /datasets/pentschev/miniconda3/envs/gdf/bin/python(+0x12a7d7) [0x5559838177d7]
52  /datasets/pentschev/miniconda3/envs/gdf/bin/python(_PyFunction_Vectorcall+0xb9) [0x555983829bb9]
53  /datasets/pentschev/miniconda3/envs/gdf/bin/python(_PyEval_EvalFrameDefault+0x11df) [0x55598381998f]
54  /datasets/pentschev/miniconda3/envs/gdf/bin/python(+0x12a7d7) [0x5559838177d7]
55  /datasets/pentschev/miniconda3/envs/gdf/bin/python(_PyEval_EvalCodeWithName+0x47) [0x555983817497]
56  /datasets/pentschev/miniconda3/envs/gdf/bin/python(PyEval_EvalCodeEx+0x39) [0x555983817449]
57  /datasets/pentschev/miniconda3/envs/gdf/bin/python(PyEval_EvalCode+0x1b) [0x5559838d1ddb]
58  /datasets/pentschev/miniconda3/envs/gdf/bin/python(+0x213409) [0x555983900409]
59  /datasets/pentschev/miniconda3/envs/gdf/bin/python(+0x20f5a4) [0x5559838fc5a4]
60  /datasets/pentschev/miniconda3/envs/gdf/bin/python(PyRun_StringFlags+0x9d) [0x5559838f427d]
61  /datasets/pentschev/miniconda3/envs/gdf/bin/python(PyRun_SimpleStringFlags+0x3d) [0x5559838f414d]
=================================
[dgx13:36116:0:36116] Caught signal 11 (Segmentation fault: address not mapped to object at address 0x448)
==== backtrace (tid:  36116) ====
 0  /datasets/pentschev/miniconda3/envs/gdf/lib/libucs.so.0(ucs_handle_error+0x2d4) [0x7f07b48481a4]
 1  /datasets/pentschev/miniconda3/envs/gdf/lib/libucs.so.0(+0x2e37f) [0x7f07b484837f]
 2  /datasets/pentschev/miniconda3/envs/gdf/lib/libucs.so.0(+0x2e6a4) [0x7f07b48486a4]
 3  /lib/x86_64-linux-gnu/libpthread.so.0(+0x12980) [0x7f0829ed2980]
 4  /datasets/pentschev/miniconda3/envs/gdf/lib/libucp.so.0(ucp_mem_type_unpack+0x14) [0x7f07b4ad0e64]
 5  /datasets/pentschev/miniconda3/envs/gdf/lib/libucp.so.0(ucp_rndv_data_handler+0x508) [0x7f07b4b03358]
 6  /datasets/pentschev/miniconda3/envs/gdf/lib/libuct.so.0(+0x20b1f) [0x7f07b45fcb1f]
 7  /datasets/pentschev/miniconda3/envs/gdf/lib/libuct.so.0(+0x210f4) [0x7f07b45fd0f4]
 8  /datasets/pentschev/miniconda3/envs/gdf/lib/libuct.so.0(+0x23548) [0x7f07b45ff548]
 9  /datasets/pentschev/miniconda3/envs/gdf/lib/libucs.so.0(ucs_event_set_wait+0xb9) [0x7f07b4852879]
10  /datasets/pentschev/miniconda3/envs/gdf/lib/libuct.so.0(uct_tcp_iface_progress+0x7b) [0x7f07b45ff5eb]
11  /datasets/pentschev/miniconda3/envs/gdf/lib/libucp.so.0(ucp_worker_progress+0x6a) [0x7f07b4acd42a]
12  /datasets/pentschev/miniconda3/envs/gdf/lib/python3.9/site-packages/ucp/_libs/ucx_api.cpython-39-x86_64-linux-gnu.so(+0x26c79) [0x7f07b4d89c79]
13  /datasets/pentschev/miniconda3/envs/gdf/bin/python(+0x141eca) [0x5576b33dceca]
14  /datasets/pentschev/miniconda3/envs/gdf/bin/python(_PyEval_EvalFrameDefault+0x3d99) [0x5576b33ca549]
15  /datasets/pentschev/miniconda3/envs/gdf/bin/python(+0x12a7d7) [0x5576b33c57d7]
16  /datasets/pentschev/miniconda3/envs/gdf/bin/python(_PyFunction_Vectorcall+0xb9) [0x5576b33d7bb9]
17  /datasets/pentschev/miniconda3/envs/gdf/bin/python(_PyEval_EvalFrameDefault+0x672) [0x5576b33c6e22]
18  /datasets/pentschev/miniconda3/envs/gdf/bin/python(+0x153244) [0x5576b33ee244]
19  /datasets/pentschev/miniconda3/envs/gdf/lib/python3.9/lib-dynload/_asyncio.cpython-39-x86_64-linux-gnu.so(+0x8301) [0x7f081c210301]
20  /datasets/pentschev/miniconda3/envs/gdf/bin/python(_PyObject_MakeTpCall+0x347) [0x5576b33cfa57]
21  /datasets/pentschev/miniconda3/envs/gdf/bin/python(+0xf7187) [0x5576b3392187]
22  /datasets/pentschev/miniconda3/envs/gdf/bin/python(+0x133747) [0x5576b33ce747]
23  /datasets/pentschev/miniconda3/envs/gdf/bin/python(_PyEval_EvalFrameDefault+0x5f0a) [0x5576b33cc6ba]
24  /datasets/pentschev/miniconda3/envs/gdf/bin/python(+0x13cec3) [0x5576b33d7ec3]
25  /datasets/pentschev/miniconda3/envs/gdf/bin/python(_PyEval_EvalFrameDefault+0x672) [0x5576b33c6e22]
26  /datasets/pentschev/miniconda3/envs/gdf/bin/python(+0x13cec3) [0x5576b33d7ec3]
27  /datasets/pentschev/miniconda3/envs/gdf/bin/python(_PyEval_EvalFrameDefault+0x672) [0x5576b33c6e22]
28  /datasets/pentschev/miniconda3/envs/gdf/bin/python(+0x13cec3) [0x5576b33d7ec3]
29  /datasets/pentschev/miniconda3/envs/gdf/bin/python(_PyEval_EvalFrameDefault+0x672) [0x5576b33c6e22]
30  /datasets/pentschev/miniconda3/envs/gdf/bin/python(+0x13cec3) [0x5576b33d7ec3]
31  /datasets/pentschev/miniconda3/envs/gdf/bin/python(_PyEval_EvalFrameDefault+0x672) [0x5576b33c6e22]
32  /datasets/pentschev/miniconda3/envs/gdf/bin/python(+0x12a7d7) [0x5576b33c57d7]
33  /datasets/pentschev/miniconda3/envs/gdf/bin/python(_PyFunction_Vectorcall+0xb9) [0x5576b33d7bb9]
34  /datasets/pentschev/miniconda3/envs/gdf/bin/python(_PyEval_EvalFrameDefault+0x4cbc) [0x5576b33cb46c]
35  /datasets/pentschev/miniconda3/envs/gdf/bin/python(+0x12a7d7) [0x5576b33c57d7]
36  /datasets/pentschev/miniconda3/envs/gdf/bin/python(+0x14baf8) [0x5576b33e6af8]
37  /datasets/pentschev/miniconda3/envs/gdf/bin/python(PyObject_Call+0xb4) [0x5576b33e7254]
38  /datasets/pentschev/miniconda3/envs/gdf/bin/python(+0x21b8b8) [0x5576b34b68b8]
39  /datasets/pentschev/miniconda3/envs/gdf/bin/python(_PyObject_MakeTpCall+0x347) [0x5576b33cfa57]
40  /datasets/pentschev/miniconda3/envs/gdf/bin/python(_PyEval_EvalFrameDefault+0x3d99) [0x5576b33ca549]
41  /datasets/pentschev/miniconda3/envs/gdf/bin/python(+0x13cec3) [0x5576b33d7ec3]
42  /datasets/pentschev/miniconda3/envs/gdf/bin/python(+0x14bb91) [0x5576b33e6b91]
43  /datasets/pentschev/miniconda3/envs/gdf/bin/python(_PyEval_EvalFrameDefault+0x3d99) [0x5576b33ca549]
44  /datasets/pentschev/miniconda3/envs/gdf/bin/python(+0x13cec3) [0x5576b33d7ec3]
45  /datasets/pentschev/miniconda3/envs/gdf/bin/python(_PyEval_EvalFrameDefault+0x672) [0x5576b33c6e22]
46  /datasets/pentschev/miniconda3/envs/gdf/bin/python(+0x12a7d7) [0x5576b33c57d7]
47  /datasets/pentschev/miniconda3/envs/gdf/bin/python(_PyFunction_Vectorcall+0xb9) [0x5576b33d7bb9]
48  /datasets/pentschev/miniconda3/envs/gdf/bin/python(_PyEval_EvalFrameDefault+0x672) [0x5576b33c6e22]
49  /datasets/pentschev/miniconda3/envs/gdf/bin/python(+0x13cec3) [0x5576b33d7ec3]
50  /datasets/pentschev/miniconda3/envs/gdf/bin/python(_PyEval_EvalFrameDefault+0x3c3) [0x5576b33c6b73]
51  /datasets/pentschev/miniconda3/envs/gdf/bin/python(+0x12a7d7) [0x5576b33c57d7]
52  /datasets/pentschev/miniconda3/envs/gdf/bin/python(_PyFunction_Vectorcall+0xb9) [0x5576b33d7bb9]
53  /datasets/pentschev/miniconda3/envs/gdf/bin/python(_PyEval_EvalFrameDefault+0x11df) [0x5576b33c798f]
54  /datasets/pentschev/miniconda3/envs/gdf/bin/python(+0x12a7d7) [0x5576b33c57d7]
55  /datasets/pentschev/miniconda3/envs/gdf/bin/python(_PyEval_EvalCodeWithName+0x47) [0x5576b33c5497]
56  /datasets/pentschev/miniconda3/envs/gdf/bin/python(PyEval_EvalCodeEx+0x39) [0x5576b33c5449]
57  /datasets/pentschev/miniconda3/envs/gdf/bin/python(PyEval_EvalCode+0x1b) [0x5576b347fddb]
58  /datasets/pentschev/miniconda3/envs/gdf/bin/python(+0x213409) [0x5576b34ae409]
59  /datasets/pentschev/miniconda3/envs/gdf/bin/python(+0x20f5a4) [0x5576b34aa5a4]
60  /datasets/pentschev/miniconda3/envs/gdf/bin/python(PyRun_StringFlags+0x9d) [0x5576b34a227d]
61  /datasets/pentschev/miniconda3/envs/gdf/bin/python(PyRun_SimpleStringFlags+0x3d) [0x5576b34a214d]
=================================
[dgx13:36166:0:36166] Caught signal 11 (Segmentation fault: address not mapped to object at address 0x448)
[dgx13:36134:0:36134] Caught signal 11 (Segmentation fault: address not mapped to object at address 0x448)
==== backtrace (tid:  36166) ====
 0  /datasets/pentschev/miniconda3/envs/gdf/lib/libucs.so.0(ucs_handle_error+0x2d4) [0x7f47949571a4]
 1  /datasets/pentschev/miniconda3/envs/gdf/lib/libucs.so.0(+0x2e37f) [0x7f479495737f]
 2  /datasets/pentschev/miniconda3/envs/gdf/lib/libucs.so.0(+0x2e6a4) [0x7f47949576a4]
 3  /lib/x86_64-linux-gnu/libpthread.so.0(+0x12980) [0x7f4809fea980]
 4  /datasets/pentschev/miniconda3/envs/gdf/lib/libucp.so.0(ucp_mem_type_unpack+0x14) [0x7f4794bdfe64]
 5  /datasets/pentschev/miniconda3/envs/gdf/lib/libucp.so.0(ucp_rndv_data_handler+0x508) [0x7f4794c12358]
 6  /datasets/pentschev/miniconda3/envs/gdf/lib/libuct.so.0(+0x20b1f) [0x7f479470bb1f]
 7  /datasets/pentschev/miniconda3/envs/gdf/lib/libuct.so.0(+0x210f4) [0x7f479470c0f4]
 8  /datasets/pentschev/miniconda3/envs/gdf/lib/libuct.so.0(+0x23548) [0x7f479470e548]
 9  /datasets/pentschev/miniconda3/envs/gdf/lib/libucs.so.0(ucs_event_set_wait+0xb9) [0x7f4794961879]
10  /datasets/pentschev/miniconda3/envs/gdf/lib/libuct.so.0(uct_tcp_iface_progress+0x7b) [0x7f479470e5eb]
11  /datasets/pentschev/miniconda3/envs/gdf/lib/libucp.so.0(ucp_worker_progress+0x6a) [0x7f4794bdc42a]
12  /datasets/pentschev/miniconda3/envs/gdf/lib/python3.9/site-packages/ucp/_libs/ucx_api.cpython-39-x86_64-linux-gnu.so(+0x26c79) [0x7f4794e98c79]
13  /datasets/pentschev/miniconda3/envs/gdf/bin/python(+0x141eca) [0x561c6ea58eca]
14  /datasets/pentschev/miniconda3/envs/gdf/bin/python(_PyEval_EvalFrameDefault+0x3d99) [0x561c6ea46549]
15  /datasets/pentschev/miniconda3/envs/gdf/bin/python(+0x12a7d7) [0x561c6ea417d7]
16  /datasets/pentschev/miniconda3/envs/gdf/bin/python(_PyFunction_Vectorcall+0xb9) [0x561c6ea53bb9]
17  /datasets/pentschev/miniconda3/envs/gdf/bin/python(_PyEval_EvalFrameDefault+0x672) [0x561c6ea42e22]
18  /datasets/pentschev/miniconda3/envs/gdf/bin/python(+0x153244) [0x561c6ea6a244]
19  /datasets/pentschev/miniconda3/envs/gdf/lib/python3.9/lib-dynload/_asyncio.cpython-39-x86_64-linux-gnu.so(+0x8301) [0x7f47fc329301]
20  /datasets/pentschev/miniconda3/envs/gdf/bin/python(_PyObject_MakeTpCall+0x347) [0x561c6ea4ba57]
21  /datasets/pentschev/miniconda3/envs/gdf/bin/python(+0xf7187) [0x561c6ea0e187]
22  /datasets/pentschev/miniconda3/envs/gdf/bin/python(+0x133747) [0x561c6ea4a747]
23  /datasets/pentschev/miniconda3/envs/gdf/bin/python(_PyEval_EvalFrameDefault+0x5f0a) [0x561c6ea486ba]
24  /datasets/pentschev/miniconda3/envs/gdf/bin/python(+0x13cec3) [0x561c6ea53ec3]
25  /datasets/pentschev/miniconda3/envs/gdf/bin/python(_PyEval_EvalFrameDefault+0x672) [0x561c6ea42e22]
26  /datasets/pentschev/miniconda3/envs/gdf/bin/python(+0x13cec3) [0x561c6ea53ec3]
27  /datasets/pentschev/miniconda3/envs/gdf/bin/python(_PyEval_EvalFrameDefault+0x672) [0x561c6ea42e22]
28  /datasets/pentschev/miniconda3/envs/gdf/bin/python(+0x13cec3) [0x561c6ea53ec3]
29  /datasets/pentschev/miniconda3/envs/gdf/bin/python(_PyEval_EvalFrameDefault+0x672) [0x561c6ea42e22]
30  /datasets/pentschev/miniconda3/envs/gdf/bin/python(+0x13cec3) [0x561c6ea53ec3]
31  /datasets/pentschev/miniconda3/envs/gdf/bin/python(_PyEval_EvalFrameDefault+0x672) [0x561c6ea42e22]
32  /datasets/pentschev/miniconda3/envs/gdf/bin/python(+0x12a7d7) [0x561c6ea417d7]
33  /datasets/pentschev/miniconda3/envs/gdf/bin/python(_PyFunction_Vectorcall+0xb9) [0x561c6ea53bb9]
34  /datasets/pentschev/miniconda3/envs/gdf/bin/python(_PyEval_EvalFrameDefault+0x4cbc) [0x561c6ea4746c]
35  /datasets/pentschev/miniconda3/envs/gdf/bin/python(+0x12a7d7) [0x561c6ea417d7]
36  /datasets/pentschev/miniconda3/envs/gdf/bin/python(+0x14baf8) [0x561c6ea62af8]
37  /datasets/pentschev/miniconda3/envs/gdf/bin/python(PyObject_Call+0xb4) [0x561c6ea63254]
38  /datasets/pentschev/miniconda3/envs/gdf/bin/python(+0x21b8b8) [0x561c6eb328b8]
39  /datasets/pentschev/miniconda3/envs/gdf/bin/python(_PyObject_MakeTpCall+0x347) [0x561c6ea4ba57]
40  /datasets/pentschev/miniconda3/envs/gdf/bin/python(_PyEval_EvalFrameDefault+0x3d99) [0x561c6ea46549]
41  /datasets/pentschev/miniconda3/envs/gdf/bin/python(+0x13cec3) [0x561c6ea53ec3]
42  /datasets/pentschev/miniconda3/envs/gdf/bin/python(+0x14bb91) [0x561c6ea62b91]
43  /datasets/pentschev/miniconda3/envs/gdf/bin/python(_PyEval_EvalFrameDefault+0x3d99) [0x561c6ea46549]
44  /datasets/pentschev/miniconda3/envs/gdf/bin/python(+0x13cec3) [0x561c6ea53ec3]
45  /datasets/pentschev/miniconda3/envs/gdf/bin/python(_PyEval_EvalFrameDefault+0x672) [0x561c6ea42e22]
46  /datasets/pentschev/miniconda3/envs/gdf/bin/python(+0x12a7d7) [0x561c6ea417d7]
47  /datasets/pentschev/miniconda3/envs/gdf/bin/python(_PyFunction_Vectorcall+0xb9) [0x561c6ea53bb9]
48  /datasets/pentschev/miniconda3/envs/gdf/bin/python(_PyEval_EvalFrameDefault+0x672) [0x561c6ea42e22]
49  /datasets/pentschev/miniconda3/envs/gdf/bin/python(+0x13cec3) [0x561c6ea53ec3]
50  /datasets/pentschev/miniconda3/envs/gdf/bin/python(_PyEval_EvalFrameDefault+0x3c3) [0x561c6ea42b73]
51  /datasets/pentschev/miniconda3/envs/gdf/bin/python(+0x12a7d7) [0x561c6ea417d7]
52  /datasets/pentschev/miniconda3/envs/gdf/bin/python(_PyFunction_Vectorcall+0xb9) [0x561c6ea53bb9]
53  /datasets/pentschev/miniconda3/envs/gdf/bin/python(_PyEval_EvalFrameDefault+0x11df) [0x561c6ea4398f]
54  /datasets/pentschev/miniconda3/envs/gdf/bin/python(+0x12a7d7) [0x561c6ea417d7]
55  /datasets/pentschev/miniconda3/envs/gdf/bin/python(_PyEval_EvalCodeWithName+0x47) [0x561c6ea41497]
56  /datasets/pentschev/miniconda3/envs/gdf/bin/python(PyEval_EvalCodeEx+0x39) [0x561c6ea41449]
57  /datasets/pentschev/miniconda3/envs/gdf/bin/python(PyEval_EvalCode+0x1b) [0x561c6eafbddb]
58  /datasets/pentschev/miniconda3/envs/gdf/bin/python(+0x213409) [0x561c6eb2a409]
59  /datasets/pentschev/miniconda3/envs/gdf/bin/python(+0x20f5a4) [0x561c6eb265a4]
60  /datasets/pentschev/miniconda3/envs/gdf/bin/python(PyRun_StringFlags+0x9d) [0x561c6eb1e27d]
61  /datasets/pentschev/miniconda3/envs/gdf/bin/python(PyRun_SimpleStringFlags+0x3d) [0x561c6eb1e14d]
=================================
==== backtrace (tid:  36134) ====
 0  /datasets/pentschev/miniconda3/envs/gdf/lib/libucs.so.0(ucs_handle_error+0x2d4) [0x7fb1298391a4]
 1  /datasets/pentschev/miniconda3/envs/gdf/lib/libucs.so.0(+0x2e37f) [0x7fb12983937f]
 2  /datasets/pentschev/miniconda3/envs/gdf/lib/libucs.so.0(+0x2e6a4) [0x7fb1298396a4]
 3  /lib/x86_64-linux-gnu/libpthread.so.0(+0x12980) [0x7fb1acefe980]
 4  /datasets/pentschev/miniconda3/envs/gdf/lib/libucp.so.0(ucp_mem_type_unpack+0x14) [0x7fb129ac1e64]
 5  /datasets/pentschev/miniconda3/envs/gdf/lib/libucp.so.0(ucp_rndv_data_handler+0x508) [0x7fb129af4358]
 6  /datasets/pentschev/miniconda3/envs/gdf/lib/libuct.so.0(+0x20b1f) [0x7fb1295edb1f]
 7  /datasets/pentschev/miniconda3/envs/gdf/lib/libuct.so.0(+0x210f4) [0x7fb1295ee0f4]
 8  /datasets/pentschev/miniconda3/envs/gdf/lib/libuct.so.0(+0x23548) [0x7fb1295f0548]
 9  /datasets/pentschev/miniconda3/envs/gdf/lib/libucs.so.0(ucs_event_set_wait+0xb9) [0x7fb129843879]
10  /datasets/pentschev/miniconda3/envs/gdf/lib/libuct.so.0(uct_tcp_iface_progress+0x7b) [0x7fb1295f05eb]
11  /datasets/pentschev/miniconda3/envs/gdf/lib/libucp.so.0(ucp_worker_progress+0x6a) [0x7fb129abe42a]
12  /datasets/pentschev/miniconda3/envs/gdf/lib/python3.9/site-packages/ucp/_libs/ucx_api.cpython-39-x86_64-linux-gnu.so(+0x26c79) [0x7fb129d7ac79]
13  /datasets/pentschev/miniconda3/envs/gdf/bin/python(+0x141eca) [0x55ba35a1eeca]
14  /datasets/pentschev/miniconda3/envs/gdf/bin/python(_PyEval_EvalFrameDefault+0x3d99) [0x55ba35a0c549]
15  /datasets/pentschev/miniconda3/envs/gdf/bin/python(+0x12a7d7) [0x55ba35a077d7]
16  /datasets/pentschev/miniconda3/envs/gdf/bin/python(_PyFunction_Vectorcall+0xb9) [0x55ba35a19bb9]
17  /datasets/pentschev/miniconda3/envs/gdf/bin/python(_PyEval_EvalFrameDefault+0x672) [0x55ba35a08e22]
18  /datasets/pentschev/miniconda3/envs/gdf/bin/python(+0x13cec3) [0x55ba35a19ec3]
19  /datasets/pentschev/miniconda3/envs/gdf/bin/python(+0x14bc75) [0x55ba35a28c75]
20  /datasets/pentschev/miniconda3/envs/gdf/bin/python(+0x264071) [0x55ba35b41071]
21  /datasets/pentschev/miniconda3/envs/gdf/bin/python(+0xf7187) [0x55ba359d4187]
22  /datasets/pentschev/miniconda3/envs/gdf/bin/python(+0x133747) [0x55ba35a10747]
23  /datasets/pentschev/miniconda3/envs/gdf/bin/python(_PyEval_EvalFrameDefault+0x5f0a) [0x55ba35a0e6ba]
24  /datasets/pentschev/miniconda3/envs/gdf/bin/python(+0x13cec3) [0x55ba35a19ec3]
25  /datasets/pentschev/miniconda3/envs/gdf/bin/python(_PyEval_EvalFrameDefault+0x672) [0x55ba35a08e22]
26  /datasets/pentschev/miniconda3/envs/gdf/bin/python(+0x13cec3) [0x55ba35a19ec3]
27  /datasets/pentschev/miniconda3/envs/gdf/bin/python(_PyEval_EvalFrameDefault+0x672) [0x55ba35a08e22]
28  /datasets/pentschev/miniconda3/envs/gdf/bin/python(+0x13cec3) [0x55ba35a19ec3]
29  /datasets/pentschev/miniconda3/envs/gdf/bin/python(_PyEval_EvalFrameDefault+0x672) [0x55ba35a08e22]
30  /datasets/pentschev/miniconda3/envs/gdf/bin/python(+0x13cec3) [0x55ba35a19ec3]
31  /datasets/pentschev/miniconda3/envs/gdf/bin/python(_PyEval_EvalFrameDefault+0x672) [0x55ba35a08e22]
32  /datasets/pentschev/miniconda3/envs/gdf/bin/python(+0x12a7d7) [0x55ba35a077d7]
33  /datasets/pentschev/miniconda3/envs/gdf/bin/python(_PyFunction_Vectorcall+0xb9) [0x55ba35a19bb9]
34  /datasets/pentschev/miniconda3/envs/gdf/bin/python(_PyEval_EvalFrameDefault+0x4cbc) [0x55ba35a0d46c]
35  /datasets/pentschev/miniconda3/envs/gdf/bin/python(+0x12a7d7) [0x55ba35a077d7]
36  /datasets/pentschev/miniconda3/envs/gdf/bin/python(+0x14baf8) [0x55ba35a28af8]
37  /datasets/pentschev/miniconda3/envs/gdf/bin/python(PyObject_Call+0xb4) [0x55ba35a29254]
38  /datasets/pentschev/miniconda3/envs/gdf/bin/python(+0x21b8b8) [0x55ba35af88b8]
39  /datasets/pentschev/miniconda3/envs/gdf/bin/python(_PyObject_MakeTpCall+0x347) [0x55ba35a11a57]
40  /datasets/pentschev/miniconda3/envs/gdf/bin/python(_PyEval_EvalFrameDefault+0x3d99) [0x55ba35a0c549]
41  /datasets/pentschev/miniconda3/envs/gdf/bin/python(+0x13cec3) [0x55ba35a19ec3]
42  /datasets/pentschev/miniconda3/envs/gdf/bin/python(+0x14bb91) [0x55ba35a28b91]
43  /datasets/pentschev/miniconda3/envs/gdf/bin/python(_PyEval_EvalFrameDefault+0x3d99) [0x55ba35a0c549]
44  /datasets/pentschev/miniconda3/envs/gdf/bin/python(+0x13cec3) [0x55ba35a19ec3]
45  /datasets/pentschev/miniconda3/envs/gdf/bin/python(_PyEval_EvalFrameDefault+0x672) [0x55ba35a08e22]
46  /datasets/pentschev/miniconda3/envs/gdf/bin/python(+0x12a7d7) [0x55ba35a077d7]
47  /datasets/pentschev/miniconda3/envs/gdf/bin/python(_PyFunction_Vectorcall+0xb9) [0x55ba35a19bb9]
48  /datasets/pentschev/miniconda3/envs/gdf/bin/python(_PyEval_EvalFrameDefault+0x672) [0x55ba35a08e22]
49  /datasets/pentschev/miniconda3/envs/gdf/bin/python(+0x13cec3) [0x55ba35a19ec3]
50  /datasets/pentschev/miniconda3/envs/gdf/bin/python(_PyEval_EvalFrameDefault+0x3c3) [0x55ba35a08b73]
51  /datasets/pentschev/miniconda3/envs/gdf/bin/python(+0x12a7d7) [0x55ba35a077d7]
52  /datasets/pentschev/miniconda3/envs/gdf/bin/python(_PyFunction_Vectorcall+0xb9) [0x55ba35a19bb9]
53  /datasets/pentschev/miniconda3/envs/gdf/bin/python(_PyEval_EvalFrameDefault+0x11df) [0x55ba35a0998f]
54  /datasets/pentschev/miniconda3/envs/gdf/bin/python(+0x12a7d7) [0x55ba35a077d7]
55  /datasets/pentschev/miniconda3/envs/gdf/bin/python(_PyEval_EvalCodeWithName+0x47) [0x55ba35a07497]
56  /datasets/pentschev/miniconda3/envs/gdf/bin/python(PyEval_EvalCodeEx+0x39) [0x55ba35a07449]
57  /datasets/pentschev/miniconda3/envs/gdf/bin/python(PyEval_EvalCode+0x1b) [0x55ba35ac1ddb]
58  /datasets/pentschev/miniconda3/envs/gdf/bin/python(+0x213409) [0x55ba35af0409]
59  /datasets/pentschev/miniconda3/envs/gdf/bin/python(+0x20f5a4) [0x55ba35aec5a4]
60  /datasets/pentschev/miniconda3/envs/gdf/bin/python(PyRun_StringFlags+0x9d) [0x55ba35ae427d]
61  /datasets/pentschev/miniconda3/envs/gdf/bin/python(PyRun_SimpleStringFlags+0x3d) [0x55ba35ae414d]
=================================
[dgx13:36167:0:36167] Caught signal 11 (Segmentation fault: address not mapped to object at address 0x448)
==== backtrace (tid:  36167) ====
 0  /datasets/pentschev/miniconda3/envs/gdf/lib/libucs.so.0(ucs_handle_error+0x2d4) [0x7f4f006511a4]
 1  /datasets/pentschev/miniconda3/envs/gdf/lib/libucs.so.0(+0x2e37f) [0x7f4f0065137f]
 2  /datasets/pentschev/miniconda3/envs/gdf/lib/libucs.so.0(+0x2e6a4) [0x7f4f006516a4]
 3  /lib/x86_64-linux-gnu/libpthread.so.0(+0x12980) [0x7f4f75e73980]
 4  /datasets/pentschev/miniconda3/envs/gdf/lib/libucp.so.0(ucp_mem_type_unpack+0x14) [0x7f4f008d9e64]
 5  /datasets/pentschev/miniconda3/envs/gdf/lib/libucp.so.0(ucp_rndv_data_handler+0x508) [0x7f4f0090c358]
 6  /datasets/pentschev/miniconda3/envs/gdf/lib/libuct.so.0(+0x20b1f) [0x7f4f00405b1f]
 7  /datasets/pentschev/miniconda3/envs/gdf/lib/libuct.so.0(+0x210f4) [0x7f4f004060f4]
 8  /datasets/pentschev/miniconda3/envs/gdf/lib/libuct.so.0(+0x23548) [0x7f4f00408548]
 9  /datasets/pentschev/miniconda3/envs/gdf/lib/libucs.so.0(ucs_event_set_wait+0xb9) [0x7f4f0065b879]
10  /datasets/pentschev/miniconda3/envs/gdf/lib/libuct.so.0(uct_tcp_iface_progress+0x7b) [0x7f4f004085eb]
11  /datasets/pentschev/miniconda3/envs/gdf/lib/libucp.so.0(ucp_worker_progress+0x6a) [0x7f4f008d642a]
12  /datasets/pentschev/miniconda3/envs/gdf/lib/python3.9/site-packages/ucp/_libs/ucx_api.cpython-39-x86_64-linux-gnu.so(+0x26c79) [0x7f4f00b92c79]
13  /datasets/pentschev/miniconda3/envs/gdf/bin/python(+0x141eca) [0x5606181c9eca]
14  /datasets/pentschev/miniconda3/envs/gdf/bin/python(_PyEval_EvalFrameDefault+0x3d99) [0x5606181b7549]
15  /datasets/pentschev/miniconda3/envs/gdf/bin/python(+0x12a7d7) [0x5606181b27d7]
16  /datasets/pentschev/miniconda3/envs/gdf/bin/python(_PyFunction_Vectorcall+0xb9) [0x5606181c4bb9]
17  /datasets/pentschev/miniconda3/envs/gdf/bin/python(_PyEval_EvalFrameDefault+0x672) [0x5606181b3e22]
18  /datasets/pentschev/miniconda3/envs/gdf/bin/python(+0x13cec3) [0x5606181c4ec3]
19  /datasets/pentschev/miniconda3/envs/gdf/bin/python(+0x14bc75) [0x5606181d3c75]
20  /datasets/pentschev/miniconda3/envs/gdf/bin/python(+0x264071) [0x5606182ec071]
21  /datasets/pentschev/miniconda3/envs/gdf/bin/python(+0xf7187) [0x56061817f187]
22  /datasets/pentschev/miniconda3/envs/gdf/bin/python(+0x133747) [0x5606181bb747]
23  /datasets/pentschev/miniconda3/envs/gdf/bin/python(_PyEval_EvalFrameDefault+0x5f0a) [0x5606181b96ba]
24  /datasets/pentschev/miniconda3/envs/gdf/bin/python(+0x13cec3) [0x5606181c4ec3]
25  /datasets/pentschev/miniconda3/envs/gdf/bin/python(_PyEval_EvalFrameDefault+0x672) [0x5606181b3e22]
26  /datasets/pentschev/miniconda3/envs/gdf/bin/python(+0x13cec3) [0x5606181c4ec3]
27  /datasets/pentschev/miniconda3/envs/gdf/bin/python(_PyEval_EvalFrameDefault+0x672) [0x5606181b3e22]
28  /datasets/pentschev/miniconda3/envs/gdf/bin/python(+0x13cec3) [0x5606181c4ec3]
29  /datasets/pentschev/miniconda3/envs/gdf/bin/python(_PyEval_EvalFrameDefault+0x672) [0x5606181b3e22]
30  /datasets/pentschev/miniconda3/envs/gdf/bin/python(+0x13cec3) [0x5606181c4ec3]
31  /datasets/pentschev/miniconda3/envs/gdf/bin/python(_PyEval_EvalFrameDefault+0x672) [0x5606181b3e22]
32  /datasets/pentschev/miniconda3/envs/gdf/bin/python(+0x12a7d7) [0x5606181b27d7]
33  /datasets/pentschev/miniconda3/envs/gdf/bin/python(_PyFunction_Vectorcall+0xb9) [0x5606181c4bb9]
34  /datasets/pentschev/miniconda3/envs/gdf/bin/python(_PyEval_EvalFrameDefault+0x4cbc) [0x5606181b846c]
35  /datasets/pentschev/miniconda3/envs/gdf/bin/python(+0x12a7d7) [0x5606181b27d7]
36  /datasets/pentschev/miniconda3/envs/gdf/bin/python(+0x14baf8) [0x5606181d3af8]
37  /datasets/pentschev/miniconda3/envs/gdf/bin/python(PyObject_Call+0xb4) [0x5606181d4254]
38  /datasets/pentschev/miniconda3/envs/gdf/bin/python(+0x21b8b8) [0x5606182a38b8]
39  /datasets/pentschev/miniconda3/envs/gdf/bin/python(_PyObject_MakeTpCall+0x347) [0x5606181bca57]
40  /datasets/pentschev/miniconda3/envs/gdf/bin/python(_PyEval_EvalFrameDefault+0x3d99) [0x5606181b7549]
41  /datasets/pentschev/miniconda3/envs/gdf/bin/python(+0x13cec3) [0x5606181c4ec3]
42  /datasets/pentschev/miniconda3/envs/gdf/bin/python(+0x14bb91) [0x5606181d3b91]
43  /datasets/pentschev/miniconda3/envs/gdf/bin/python(_PyEval_EvalFrameDefault+0x3d99) [0x5606181b7549]
44  /datasets/pentschev/miniconda3/envs/gdf/bin/python(+0x13cec3) [0x5606181c4ec3]
45  /datasets/pentschev/miniconda3/envs/gdf/bin/python(_PyEval_EvalFrameDefault+0x672) [0x5606181b3e22]
46  /datasets/pentschev/miniconda3/envs/gdf/bin/python(+0x12a7d7) [0x5606181b27d7]
47  /datasets/pentschev/miniconda3/envs/gdf/bin/python(_PyFunction_Vectorcall+0xb9) [0x5606181c4bb9]
48  /datasets/pentschev/miniconda3/envs/gdf/bin/python(_PyEval_EvalFrameDefault+0x672) [0x5606181b3e22]
49  /datasets/pentschev/miniconda3/envs/gdf/bin/python(+0x13cec3) [0x5606181c4ec3]
50  /datasets/pentschev/miniconda3/envs/gdf/bin/python(_PyEval_EvalFrameDefault+0x3c3) [0x5606181b3b73]
51  /datasets/pentschev/miniconda3/envs/gdf/bin/python(+0x12a7d7) [0x5606181b27d7]
52  /datasets/pentschev/miniconda3/envs/gdf/bin/python(_PyFunction_Vectorcall+0xb9) [0x5606181c4bb9]
53  /datasets/pentschev/miniconda3/envs/gdf/bin/python(_PyEval_EvalFrameDefault+0x11df) [0x5606181b498f]
54  /datasets/pentschev/miniconda3/envs/gdf/bin/python(+0x12a7d7) [0x5606181b27d7]
55  /datasets/pentschev/miniconda3/envs/gdf/bin/python(_PyEval_EvalCodeWithName+0x47) [0x5606181b2497]
56  /datasets/pentschev/miniconda3/envs/gdf/bin/python(PyEval_EvalCodeEx+0x39) [0x5606181b2449]
57  /datasets/pentschev/miniconda3/envs/gdf/bin/python(PyEval_EvalCode+0x1b) [0x56061826cddb]
58  /datasets/pentschev/miniconda3/envs/gdf/bin/python(+0x213409) [0x56061829b409]
59  /datasets/pentschev/miniconda3/envs/gdf/bin/python(+0x20f5a4) [0x5606182975a4]
60  /datasets/pentschev/miniconda3/envs/gdf/bin/python(PyRun_StringFlags+0x9d) [0x56061828f27d]
61  /datasets/pentschev/miniconda3/envs/gdf/bin/python(PyRun_SimpleStringFlags+0x3d) [0x56061828f14d]
=================================
2023-01-16 01:54:02,358 - distributed.worker - ERROR - Worker stream died during communication: ucx://127.0.0.1:59047
Traceback (most recent call last):
  File "/datasets/pentschev/miniconda3/envs/gdf/lib/python3.9/site-packages/distributed/comm/ucx.py", line 349, in read
    await self.ep.recv(msg)
  File "/datasets/pentschev/miniconda3/envs/gdf/lib/python3.9/site-packages/ucp/core.py", line 725, in recv
    ret = await comm.tag_recv(self._ep, buffer, nbytes, tag, name=log)
ucp._libs.exceptions.UCXCanceled: <[Recv #003] ep: 0x7f3bd2687140, tag: 0xcd574727cef611c6, nbytes: 16, type: <class 'numpy.ndarray'>>: 

During handling of the above exception, another exception occurred:

Traceback (most recent call last):
  File "/datasets/pentschev/miniconda3/envs/gdf/lib/python3.9/site-packages/distributed/worker.py", line 2058, in gather_dep
    response = await get_data_from_worker(
  File "/datasets/pentschev/miniconda3/envs/gdf/lib/python3.9/site-packages/distributed/worker.py", line 2870, in get_data_from_worker
    return await retry_operation(_get_data, operation="get_data_from_worker")
  File "/datasets/pentschev/miniconda3/envs/gdf/lib/python3.9/site-packages/distributed/utils_comm.py", line 402, in retry_operation
    return await retry(
  File "/datasets/pentschev/miniconda3/envs/gdf/lib/python3.9/site-packages/distributed/utils_comm.py", line 387, in retry
    return await coro()
  File "/datasets/pentschev/miniconda3/envs/gdf/lib/python3.9/site-packages/distributed/worker.py", line 2850, in _get_data
    response = await send_recv(
  File "/datasets/pentschev/miniconda3/envs/gdf/lib/python3.9/site-packages/distributed/core.py", line 986, in send_recv
    response = await comm.read(deserializers=deserializers)
  File "/datasets/pentschev/miniconda3/envs/gdf/lib/python3.9/site-packages/distributed/utils.py", line 741, in wrapper
    return await func(*args, **kwargs)
  File "/datasets/pentschev/miniconda3/envs/gdf/lib/python3.9/site-packages/distributed/comm/ucx.py", line 367, in read
    raise CommClosedError(
distributed.comm.core.CommClosedError: Connection closed by writer.
Inner exception: UCXCanceled("<[Recv #003] ep: 0x7f3bd2687140, tag: 0xcd574727cef611c6, nbytes: 16, type: <class 'numpy.ndarray'>>: ")
Task exception was never retrieved
future: <Task finished name='Task-329' coro=<_listener_handler_coroutine() done, defined at /datasets/pentschev/miniconda3/envs/gdf/lib/python3.9/site-packages/ucp/core.py:128> exception=UCXError('<stream_recv>: Connection reset by remote peer')>
Traceback (most recent call last):
  File "/datasets/pentschev/miniconda3/envs/gdf/lib/python3.9/site-packages/ucp/core.py", line 143, in _listener_handler_coroutine
    peer_info = await exchange_peer_info(
  File "/datasets/pentschev/miniconda3/envs/gdf/lib/python3.9/site-packages/ucp/core.py", line 52, in exchange_peer_info
    await comm.stream_recv(endpoint, peer_info_arr, peer_info_arr.nbytes)
ucp._libs.exceptions.UCXError: <stream_recv>: Connection reset by remote peer
2023-01-16 01:54:02,379 - distributed.worker - ERROR - Worker stream died during communication: ucx://127.0.0.1:53089
Traceback (most recent call last):
  File "/datasets/pentschev/miniconda3/envs/gdf/lib/python3.9/site-packages/distributed/comm/ucx.py", line 391, in read
    await self.ep.recv(each_frame)
  File "/datasets/pentschev/miniconda3/envs/gdf/lib/python3.9/site-packages/ucp/core.py", line 725, in recv
    ret = await comm.tag_recv(self._ep, buffer, nbytes, tag, name=log)
ucp._libs.exceptions.UCXError: <[Recv #007] ep: 0x7f2da00ea140, tag: 0x98f410a6a24c5f44, nbytes: 50000000, type: <class 'rmm._lib.device_buffer.DeviceBuffer'>>: Connection reset by remote peer

During handling of the above exception, another exception occurred:

Traceback (most recent call last):
  File "/datasets/pentschev/miniconda3/envs/gdf/lib/python3.9/site-packages/distributed/worker.py", line 2058, in gather_dep
    response = await get_data_from_worker(
  File "/datasets/pentschev/miniconda3/envs/gdf/lib/python3.9/site-packages/distributed/worker.py", line 2870, in get_data_from_worker
    return await retry_operation(_get_data, operation="get_data_from_worker")
  File "/datasets/pentschev/miniconda3/envs/gdf/lib/python3.9/site-packages/distributed/utils_comm.py", line 402, in retry_operation
    return await retry(
  File "/datasets/pentschev/miniconda3/envs/gdf/lib/python3.9/site-packages/distributed/utils_comm.py", line 387, in retry
    return await coro()
  File "/datasets/pentschev/miniconda3/envs/gdf/lib/python3.9/site-packages/distributed/worker.py", line 2850, in _get_data
    response = await send_recv(
  File "/datasets/pentschev/miniconda3/envs/gdf/lib/python3.9/site-packages/distributed/core.py", line 986, in send_recv
    response = await comm.read(deserializers=deserializers)
  File "/datasets/pentschev/miniconda3/envs/gdf/lib/python3.9/site-packages/distributed/utils.py", line 741, in wrapper
    return await func(*args, **kwargs)
  File "/datasets/pentschev/miniconda3/envs/gdf/lib/python3.9/site-packages/distributed/comm/ucx.py", line 397, in read
    raise CommClosedError(
distributed.comm.core.CommClosedError: Connection closed by writer.
Inner exception: UCXError("<[Recv #007] ep: 0x7f2da00ea140, tag: 0x98f410a6a24c5f44, nbytes: 50000000, type: <class 'rmm._lib.device_buffer.DeviceBuffer'>>: Connection reset by remote peer")
2023-01-16 01:54:02,382 - distributed.worker - ERROR - failed during get data with ucx://127.0.0.1:42539 -> ucx://127.0.0.1:53089
Traceback (most recent call last):
  File "/datasets/pentschev/miniconda3/envs/gdf/lib/python3.9/site-packages/distributed/comm/ucx.py", line 333, in write
    await self.ep.send(each_frame)
  File "/datasets/pentschev/miniconda3/envs/gdf/lib/python3.9/site-packages/ucp/core.py", line 650, in send
    return await comm.tag_send(self._ep, buffer, nbytes, tag, name=log)
ucp._libs.exceptions.UCXError: <[Send #007] ep: 0x7f2da00ea1c0, tag: 0x8777c547cf8d3a1e, nbytes: 50000000, type: <class 'cupy.ndarray'>>: Connection reset by remote peer

During handling of the above exception, another exception occurred:

Traceback (most recent call last):
  File "/datasets/pentschev/miniconda3/envs/gdf/lib/python3.9/site-packages/distributed/worker.py", line 1766, in get_data
    compressed = await comm.write(msg, serializers=serializers)
  File "/datasets/pentschev/miniconda3/envs/gdf/lib/python3.9/site-packages/distributed/utils.py", line 741, in wrapper
    return await func(*args, **kwargs)
  File "/datasets/pentschev/miniconda3/envs/gdf/lib/python3.9/site-packages/distributed/comm/ucx.py", line 337, in write
    raise CommClosedError("While writing, the connection was closed")
distributed.comm.core.CommClosedError: While writing, the connection was closed
2023-01-16 01:54:02,390 - distributed.worker - ERROR - failed during get data with ucx://127.0.0.1:47717 -> ucx://127.0.0.1:46645
Traceback (most recent call last):
  File "/datasets/pentschev/miniconda3/envs/gdf/lib/python3.9/site-packages/distributed/comm/ucx.py", line 333, in write
    await self.ep.send(each_frame)
  File "/datasets/pentschev/miniconda3/envs/gdf/lib/python3.9/site-packages/ucp/core.py", line 650, in send
    return await comm.tag_send(self._ep, buffer, nbytes, tag, name=log)
ucp._libs.exceptions.UCXError: <[Send #007] ep: 0x7f3bd2687300, tag: 0x27d7b28f806ecb03, nbytes: 50000000, type: <class 'cupy.ndarray'>>: Connection reset by remote peer

During handling of the above exception, another exception occurred:

Traceback (most recent call last):
  File "/datasets/pentschev/miniconda3/envs/gdf/lib/python3.9/site-packages/distributed/worker.py", line 1766, in get_data
    compressed = await comm.write(msg, serializers=serializers)
  File "/datasets/pentschev/miniconda3/envs/gdf/lib/python3.9/site-packages/distributed/utils.py", line 741, in wrapper
    return await func(*args, **kwargs)
  File "/datasets/pentschev/miniconda3/envs/gdf/lib/python3.9/site-packages/distributed/comm/ucx.py", line 337, in write
    raise CommClosedError("While writing, the connection was closed")
distributed.comm.core.CommClosedError: While writing, the connection was closed
2023-01-16 01:54:02,391 - distributed.worker - ERROR - Worker stream died during communication: ucx://127.0.0.1:46645
Traceback (most recent call last):
  File "/datasets/pentschev/miniconda3/envs/gdf/lib/python3.9/site-packages/distributed/comm/ucx.py", line 391, in read
    await self.ep.recv(each_frame)
  File "/datasets/pentschev/miniconda3/envs/gdf/lib/python3.9/site-packages/ucp/core.py", line 725, in recv
    ret = await comm.tag_recv(self._ep, buffer, nbytes, tag, name=log)
ucp._libs.exceptions.UCXError: <[Recv #007] ep: 0x7f3bd2687100, tag: 0xc2a5926aac2e779c, nbytes: 50000000, type: <class 'rmm._lib.device_buffer.DeviceBuffer'>>: Connection reset by remote peer

During handling of the above exception, another exception occurred:

Traceback (most recent call last):
  File "/datasets/pentschev/miniconda3/envs/gdf/lib/python3.9/site-packages/distributed/worker.py", line 2058, in gather_dep
    response = await get_data_from_worker(
  File "/datasets/pentschev/miniconda3/envs/gdf/lib/python3.9/site-packages/distributed/worker.py", line 2870, in get_data_from_worker
    return await retry_operation(_get_data, operation="get_data_from_worker")
  File "/datasets/pentschev/miniconda3/envs/gdf/lib/python3.9/site-packages/distributed/utils_comm.py", line 402, in retry_operation
    return await retry(
  File "/datasets/pentschev/miniconda3/envs/gdf/lib/python3.9/site-packages/distributed/utils_comm.py", line 387, in retry
    return await coro()
  File "/datasets/pentschev/miniconda3/envs/gdf/lib/python3.9/site-packages/distributed/worker.py", line 2850, in _get_data
    response = await send_recv(
  File "/datasets/pentschev/miniconda3/envs/gdf/lib/python3.9/site-packages/distributed/core.py", line 986, in send_recv
    response = await comm.read(deserializers=deserializers)
  File "/datasets/pentschev/miniconda3/envs/gdf/lib/python3.9/site-packages/distributed/utils.py", line 741, in wrapper
    return await func(*args, **kwargs)
  File "/datasets/pentschev/miniconda3/envs/gdf/lib/python3.9/site-packages/distributed/comm/ucx.py", line 397, in read
    raise CommClosedError(
distributed.comm.core.CommClosedError: Connection closed by writer.
Inner exception: UCXError("<[Recv #007] ep: 0x7f3bd2687100, tag: 0xc2a5926aac2e779c, nbytes: 50000000, type: <class 'rmm._lib.device_buffer.DeviceBuffer'>>: Connection reset by remote peer")
2023-01-16 01:54:02,391 - distributed.worker - ERROR - Worker stream died during communication: ucx://127.0.0.1:46645
Traceback (most recent call last):
  File "/datasets/pentschev/miniconda3/envs/gdf/lib/python3.9/site-packages/distributed/comm/ucx.py", line 349, in read
    await self.ep.recv(msg)
  File "/datasets/pentschev/miniconda3/envs/gdf/lib/python3.9/site-packages/ucp/core.py", line 725, in recv
    ret = await comm.tag_recv(self._ep, buffer, nbytes, tag, name=log)
ucp._libs.exceptions.UCXCanceled: <[Recv #003] ep: 0x7f5830637240, tag: 0xcb1ec8fdd5947dee, nbytes: 16, type: <class 'numpy.ndarray'>>: 

During handling of the above exception, another exception occurred:

Traceback (most recent call last):
  File "/datasets/pentschev/miniconda3/envs/gdf/lib/python3.9/site-packages/distributed/worker.py", line 2058, in gather_dep
    response = await get_data_from_worker(
  File "/datasets/pentschev/miniconda3/envs/gdf/lib/python3.9/site-packages/distributed/worker.py", line 2870, in get_data_from_worker
    return await retry_operation(_get_data, operation="get_data_from_worker")
  File "/datasets/pentschev/miniconda3/envs/gdf/lib/python3.9/site-packages/distributed/utils_comm.py", line 402, in retry_operation
    return await retry(
  File "/datasets/pentschev/miniconda3/envs/gdf/lib/python3.9/site-packages/distributed/utils_comm.py", line 387, in retry
    return await coro()
  File "/datasets/pentschev/miniconda3/envs/gdf/lib/python3.9/site-packages/distributed/worker.py", line 2850, in _get_data
    response = await send_recv(
  File "/datasets/pentschev/miniconda3/envs/gdf/lib/python3.9/site-packages/distributed/core.py", line 986, in send_recv
    response = await comm.read(deserializers=deserializers)
  File "/datasets/pentschev/miniconda3/envs/gdf/lib/python3.9/site-packages/distributed/utils.py", line 741, in wrapper
    return await func(*args, **kwargs)
  File "/datasets/pentschev/miniconda3/envs/gdf/lib/python3.9/site-packages/distributed/comm/ucx.py", line 367, in read
    raise CommClosedError(
distributed.comm.core.CommClosedError: Connection closed by writer.
Inner exception: UCXCanceled("<[Recv #003] ep: 0x7f5830637240, tag: 0xcb1ec8fdd5947dee, nbytes: 16, type: <class 'numpy.ndarray'>>: ")
2023-01-16 01:54:02,405 - distributed.nanny - WARNING - Restarting worker
Task exception was never retrieved
future: <Task finished name='Task-356' coro=<_listener_handler_coroutine() done, defined at /datasets/pentschev/miniconda3/envs/gdf/lib/python3.9/site-packages/ucp/core.py:128> exception=UCXError('<stream_recv>: Connection reset by remote peer')>
Traceback (most recent call last):
  File "/datasets/pentschev/miniconda3/envs/gdf/lib/python3.9/site-packages/ucp/core.py", line 143, in _listener_handler_coroutine
    peer_info = await exchange_peer_info(
  File "/datasets/pentschev/miniconda3/envs/gdf/lib/python3.9/site-packages/ucp/core.py", line 52, in exchange_peer_info
    await comm.stream_recv(endpoint, peer_info_arr, peer_info_arr.nbytes)
ucp._libs.exceptions.UCXError: <stream_recv>: Connection reset by remote peer
Task exception was never retrieved
future: <Task finished name='Task-331' coro=<_listener_handler_coroutine() done, defined at /datasets/pentschev/miniconda3/envs/gdf/lib/python3.9/site-packages/ucp/core.py:128> exception=UCXError('<stream_send>: Connection reset by remote peer')>
Traceback (most recent call last):
  File "/datasets/pentschev/miniconda3/envs/gdf/lib/python3.9/site-packages/ucp/core.py", line 143, in _listener_handler_coroutine
    peer_info = await exchange_peer_info(
  File "/datasets/pentschev/miniconda3/envs/gdf/lib/python3.9/site-packages/ucp/core.py", line 51, in exchange_peer_info
    await comm.stream_send(endpoint, my_info_arr, my_info_arr.nbytes)
ucp._libs.exceptions.UCXError: <stream_send>: Connection reset by remote peer
2023-01-16 01:54:02,410 - distributed.worker - ERROR - Worker stream died during communication: ucx://127.0.0.1:50821
Traceback (most recent call last):
  File "/datasets/pentschev/miniconda3/envs/gdf/lib/python3.9/site-packages/distributed/comm/ucx.py", line 349, in read
    await self.ep.recv(msg)
  File "/datasets/pentschev/miniconda3/envs/gdf/lib/python3.9/site-packages/ucp/core.py", line 725, in recv
    ret = await comm.tag_recv(self._ep, buffer, nbytes, tag, name=log)
ucp._libs.exceptions.UCXCanceled: <[Recv #000] ep: 0x7f2da00ea100, tag: 0xbdf1a8a2b07557b8, nbytes: 16, type: <class 'numpy.ndarray'>>: 

During handling of the above exception, another exception occurred:

Traceback (most recent call last):
  File "/datasets/pentschev/miniconda3/envs/gdf/lib/python3.9/site-packages/distributed/comm/core.py", line 328, in connect
    handshake = await asyncio.wait_for(comm.read(), time_left())
  File "/datasets/pentschev/miniconda3/envs/gdf/lib/python3.9/asyncio/tasks.py", line 479, in wait_for
    return fut.result()
  File "/datasets/pentschev/miniconda3/envs/gdf/lib/python3.9/site-packages/distributed/utils.py", line 741, in wrapper
    return await func(*args, **kwargs)
  File "/datasets/pentschev/miniconda3/envs/gdf/lib/python3.9/site-packages/distributed/comm/ucx.py", line 367, in read
    raise CommClosedError(
distributed.comm.core.CommClosedError: Connection closed by writer.
Inner exception: UCXCanceled("<[Recv #000] ep: 0x7f2da00ea100, tag: 0xbdf1a8a2b07557b8, nbytes: 16, type: <class 'numpy.ndarray'>>: ")

The above exception was the direct cause of the following exception:

Traceback (most recent call last):
  File "/datasets/pentschev/miniconda3/envs/gdf/lib/python3.9/site-packages/distributed/worker.py", line 2058, in gather_dep
    response = await get_data_from_worker(
  File "/datasets/pentschev/miniconda3/envs/gdf/lib/python3.9/site-packages/distributed/worker.py", line 2870, in get_data_from_worker
    return await retry_operation(_get_data, operation="get_data_from_worker")
  File "/datasets/pentschev/miniconda3/envs/gdf/lib/python3.9/site-packages/distributed/utils_comm.py", line 402, in retry_operation
    return await retry(
  File "/datasets/pentschev/miniconda3/envs/gdf/lib/python3.9/site-packages/distributed/utils_comm.py", line 387, in retry
    return await coro()
  File "/datasets/pentschev/miniconda3/envs/gdf/lib/python3.9/site-packages/distributed/worker.py", line 2847, in _get_data
    comm = await rpc.connect(worker)
  File "/datasets/pentschev/miniconda3/envs/gdf/lib/python3.9/site-packages/distributed/core.py", line 1439, in connect
    return await connect_attempt
  File "/datasets/pentschev/miniconda3/envs/gdf/lib/python3.9/site-packages/distributed/core.py", line 1375, in _connect
    comm = await connect(
  File "/datasets/pentschev/miniconda3/envs/gdf/lib/python3.9/site-packages/distributed/comm/core.py", line 333, in connect
    raise OSError(
OSError: Timed out during handshake while connecting to ucx://127.0.0.1:50821 after 30 s
2023-01-16 01:54:02,410 - distributed.worker - ERROR - Worker stream died during communication: ucx://127.0.0.1:50821
Traceback (most recent call last):
  File "/datasets/pentschev/miniconda3/envs/gdf/lib/python3.9/site-packages/distributed/comm/ucx.py", line 349, in read
    await self.ep.recv(msg)
  File "/datasets/pentschev/miniconda3/envs/gdf/lib/python3.9/site-packages/ucp/core.py", line 725, in recv
    ret = await comm.tag_recv(self._ep, buffer, nbytes, tag, name=log)
ucp._libs.exceptions.UCXCanceled: <[Recv #000] ep: 0x7f3bd2687200, tag: 0x513170e5242e6501, nbytes: 16, type: <class 'numpy.ndarray'>>: 

During handling of the above exception, another exception occurred:

Traceback (most recent call last):
  File "/datasets/pentschev/miniconda3/envs/gdf/lib/python3.9/site-packages/distributed/comm/core.py", line 328, in connect
    handshake = await asyncio.wait_for(comm.read(), time_left())
  File "/datasets/pentschev/miniconda3/envs/gdf/lib/python3.9/asyncio/tasks.py", line 479, in wait_for
    return fut.result()
  File "/datasets/pentschev/miniconda3/envs/gdf/lib/python3.9/site-packages/distributed/utils.py", line 741, in wrapper
    return await func(*args, **kwargs)
  File "/datasets/pentschev/miniconda3/envs/gdf/lib/python3.9/site-packages/distributed/comm/ucx.py", line 367, in read
    raise CommClosedError(
distributed.comm.core.CommClosedError: Connection closed by writer.
Inner exception: UCXCanceled("<[Recv #000] ep: 0x7f3bd2687200, tag: 0x513170e5242e6501, nbytes: 16, type: <class 'numpy.ndarray'>>: ")

The above exception was the direct cause of the following exception:

Traceback (most recent call last):
  File "/datasets/pentschev/miniconda3/envs/gdf/lib/python3.9/site-packages/distributed/worker.py", line 2058, in gather_dep
    response = await get_data_from_worker(
  File "/datasets/pentschev/miniconda3/envs/gdf/lib/python3.9/site-packages/distributed/worker.py", line 2870, in get_data_from_worker
    return await retry_operation(_get_data, operation="get_data_from_worker")
  File "/datasets/pentschev/miniconda3/envs/gdf/lib/python3.9/site-packages/distributed/utils_comm.py", line 402, in retry_operation
    return await retry(
  File "/datasets/pentschev/miniconda3/envs/gdf/lib/python3.9/site-packages/distributed/utils_comm.py", line 387, in retry
    return await coro()
  File "/datasets/pentschev/miniconda3/envs/gdf/lib/python3.9/site-packages/distributed/worker.py", line 2847, in _get_data
    comm = await rpc.connect(worker)
  File "/datasets/pentschev/miniconda3/envs/gdf/lib/python3.9/site-packages/distributed/core.py", line 1439, in connect
    return await connect_attempt
  File "/datasets/pentschev/miniconda3/envs/gdf/lib/python3.9/site-packages/distributed/core.py", line 1375, in _connect
    comm = await connect(
  File "/datasets/pentschev/miniconda3/envs/gdf/lib/python3.9/site-packages/distributed/comm/core.py", line 333, in connect
    raise OSError(
OSError: Timed out during handshake while connecting to ucx://127.0.0.1:50821 after 30 s
2023-01-16 01:54:02,410 - distributed.worker - ERROR - Worker stream died during communication: ucx://127.0.0.1:50821
Traceback (most recent call last):
  File "/datasets/pentschev/miniconda3/envs/gdf/lib/python3.9/site-packages/distributed/comm/ucx.py", line 349, in read
    await self.ep.recv(msg)
  File "/datasets/pentschev/miniconda3/envs/gdf/lib/python3.9/site-packages/ucp/core.py", line 725, in recv
    ret = await comm.tag_recv(self._ep, buffer, nbytes, tag, name=log)
ucp._libs.exceptions.UCXCanceled: <[Recv #000] ep: 0x7f5830637200, tag: 0x3a6a0c7157a2d483, nbytes: 16, type: <class 'numpy.ndarray'>>: 

During handling of the above exception, another exception occurred:

Traceback (most recent call last):
  File "/datasets/pentschev/miniconda3/envs/gdf/lib/python3.9/site-packages/distributed/comm/core.py", line 328, in connect
    handshake = await asyncio.wait_for(comm.read(), time_left())
  File "/datasets/pentschev/miniconda3/envs/gdf/lib/python3.9/asyncio/tasks.py", line 479, in wait_for
    return fut.result()
  File "/datasets/pentschev/miniconda3/envs/gdf/lib/python3.9/site-packages/distributed/utils.py", line 741, in wrapper
    return await func(*args, **kwargs)
  File "/datasets/pentschev/miniconda3/envs/gdf/lib/python3.9/site-packages/distributed/comm/ucx.py", line 367, in read
    raise CommClosedError(
distributed.comm.core.CommClosedError: Connection closed by writer.
Inner exception: UCXCanceled("<[Recv #000] ep: 0x7f5830637200, tag: 0x3a6a0c7157a2d483, nbytes: 16, type: <class 'numpy.ndarray'>>: ")

The above exception was the direct cause of the following exception:

Traceback (most recent call last):
  File "/datasets/pentschev/miniconda3/envs/gdf/lib/python3.9/site-packages/distributed/worker.py", line 2058, in gather_dep
    response = await get_data_from_worker(
  File "/datasets/pentschev/miniconda3/envs/gdf/lib/python3.9/site-packages/distributed/worker.py", line 2870, in get_data_from_worker
    return await retry_operation(_get_data, operation="get_data_from_worker")
  File "/datasets/pentschev/miniconda3/envs/gdf/lib/python3.9/site-packages/distributed/utils_comm.py", line 402, in retry_operation
    return await retry(
  File "/datasets/pentschev/miniconda3/envs/gdf/lib/python3.9/site-packages/distributed/utils_comm.py", line 387, in retry
    return await coro()
  File "/datasets/pentschev/miniconda3/envs/gdf/lib/python3.9/site-packages/distributed/worker.py", line 2847, in _get_data
    comm = await rpc.connect(worker)
  File "/datasets/pentschev/miniconda3/envs/gdf/lib/python3.9/site-packages/distributed/core.py", line 1439, in connect
    return await connect_attempt
  File "/datasets/pentschev/miniconda3/envs/gdf/lib/python3.9/site-packages/distributed/core.py", line 1375, in _connect
    comm = await connect(
  File "/datasets/pentschev/miniconda3/envs/gdf/lib/python3.9/site-packages/distributed/comm/core.py", line 333, in connect
    raise OSError(
OSError: Timed out during handshake while connecting to ucx://127.0.0.1:50821 after 30 s
2023-01-16 01:54:02,506 - distributed.worker - ERROR - Worker stream died during communication: ucx://127.0.0.1:43547
Traceback (most recent call last):
  File "/datasets/pentschev/miniconda3/envs/gdf/lib/python3.9/site-packages/distributed/comm/ucx.py", line 349, in read
    await self.ep.recv(msg)
  File "/datasets/pentschev/miniconda3/envs/gdf/lib/python3.9/site-packages/ucp/core.py", line 725, in recv
    ret = await comm.tag_recv(self._ep, buffer, nbytes, tag, name=log)
ucp._libs.exceptions.UCXCanceled: <[Recv #003] ep: 0x7f2da00ea180, tag: 0x6d3d1b92575913ca, nbytes: 16, type: <class 'numpy.ndarray'>>: 

During handling of the above exception, another exception occurred:

Traceback (most recent call last):
  File "/datasets/pentschev/miniconda3/envs/gdf/lib/python3.9/site-packages/distributed/worker.py", line 2058, in gather_dep
    response = await get_data_from_worker(
  File "/datasets/pentschev/miniconda3/envs/gdf/lib/python3.9/site-packages/distributed/worker.py", line 2870, in get_data_from_worker
    return await retry_operation(_get_data, operation="get_data_from_worker")
  File "/datasets/pentschev/miniconda3/envs/gdf/lib/python3.9/site-packages/distributed/utils_comm.py", line 402, in retry_operation
    return await retry(
  File "/datasets/pentschev/miniconda3/envs/gdf/lib/python3.9/site-packages/distributed/utils_comm.py", line 387, in retry
    return await coro()
  File "/datasets/pentschev/miniconda3/envs/gdf/lib/python3.9/site-packages/distributed/worker.py", line 2850, in _get_data
    response = await send_recv(
  File "/datasets/pentschev/miniconda3/envs/gdf/lib/python3.9/site-packages/distributed/core.py", line 986, in send_recv
    response = await comm.read(deserializers=deserializers)
  File "/datasets/pentschev/miniconda3/envs/gdf/lib/python3.9/site-packages/distributed/utils.py", line 741, in wrapper
    return await func(*args, **kwargs)
  File "/datasets/pentschev/miniconda3/envs/gdf/lib/python3.9/site-packages/distributed/comm/ucx.py", line 367, in read
    raise CommClosedError(
distributed.comm.core.CommClosedError: Connection closed by writer.
Inner exception: UCXCanceled("<[Recv #003] ep: 0x7f2da00ea180, tag: 0x6d3d1b92575913ca, nbytes: 16, type: <class 'numpy.ndarray'>>: ")
2023-01-16 01:54:02,507 - distributed.worker - ERROR - Worker stream died during communication: ucx://127.0.0.1:43547
Traceback (most recent call last):
  File "/datasets/pentschev/miniconda3/envs/gdf/lib/python3.9/site-packages/distributed/comm/ucx.py", line 391, in read
    await self.ep.recv(each_frame)
  File "/datasets/pentschev/miniconda3/envs/gdf/lib/python3.9/site-packages/ucp/core.py", line 725, in recv
    ret = await comm.tag_recv(self._ep, buffer, nbytes, tag, name=log)
ucp._libs.exceptions.UCXError: <[Recv #007] ep: 0x7f58306371c0, tag: 0xfc013f0139a37a32, nbytes: 50000000, type: <class 'rmm._lib.device_buffer.DeviceBuffer'>>: Connection reset by remote peer

During handling of the above exception, another exception occurred:

Traceback (most recent call last):
  File "/datasets/pentschev/miniconda3/envs/gdf/lib/python3.9/site-packages/distributed/worker.py", line 2058, in gather_dep
    response = await get_data_from_worker(
  File "/datasets/pentschev/miniconda3/envs/gdf/lib/python3.9/site-packages/distributed/worker.py", line 2870, in get_data_from_worker
    return await retry_operation(_get_data, operation="get_data_from_worker")
  File "/datasets/pentschev/miniconda3/envs/gdf/lib/python3.9/site-packages/distributed/utils_comm.py", line 402, in retry_operation
    return await retry(
  File "/datasets/pentschev/miniconda3/envs/gdf/lib/python3.9/site-packages/distributed/utils_comm.py", line 387, in retry
    return await coro()
  File "/datasets/pentschev/miniconda3/envs/gdf/lib/python3.9/site-packages/distributed/worker.py", line 2850, in _get_data
    response = await send_recv(
  File "/datasets/pentschev/miniconda3/envs/gdf/lib/python3.9/site-packages/distributed/core.py", line 986, in send_recv
    response = await comm.read(deserializers=deserializers)
  File "/datasets/pentschev/miniconda3/envs/gdf/lib/python3.9/site-packages/distributed/utils.py", line 741, in wrapper
    return await func(*args, **kwargs)
  File "/datasets/pentschev/miniconda3/envs/gdf/lib/python3.9/site-packages/distributed/comm/ucx.py", line 397, in read
    raise CommClosedError(
distributed.comm.core.CommClosedError: Connection closed by writer.
Inner exception: UCXError("<[Recv #007] ep: 0x7f58306371c0, tag: 0xfc013f0139a37a32, nbytes: 50000000, type: <class 'rmm._lib.device_buffer.DeviceBuffer'>>: Connection reset by remote peer")
2023-01-16 01:54:02,507 - distributed.worker - ERROR - failed during get data with ucx://127.0.0.1:36583 -> ucx://127.0.0.1:43547
Traceback (most recent call last):
  File "/datasets/pentschev/miniconda3/envs/gdf/lib/python3.9/site-packages/distributed/comm/ucx.py", line 333, in write
    await self.ep.send(each_frame)
  File "/datasets/pentschev/miniconda3/envs/gdf/lib/python3.9/site-packages/ucp/core.py", line 650, in send
    return await comm.tag_send(self._ep, buffer, nbytes, tag, name=log)
ucp._libs.exceptions.UCXError: <[Send #007] ep: 0x7f58306372c0, tag: 0xd5b793e603a302df, nbytes: 50000000, type: <class 'cupy.ndarray'>>: Connection reset by remote peer

During handling of the above exception, another exception occurred:

Traceback (most recent call last):
  File "/datasets/pentschev/miniconda3/envs/gdf/lib/python3.9/site-packages/distributed/worker.py", line 1766, in get_data
    compressed = await comm.write(msg, serializers=serializers)
  File "/datasets/pentschev/miniconda3/envs/gdf/lib/python3.9/site-packages/distributed/utils.py", line 741, in wrapper
    return await func(*args, **kwargs)
  File "/datasets/pentschev/miniconda3/envs/gdf/lib/python3.9/site-packages/distributed/comm/ucx.py", line 337, in write
    raise CommClosedError("While writing, the connection was closed")
distributed.comm.core.CommClosedError: While writing, the connection was closed
Task exception was never retrieved
future: <Task finished name='Task-330' coro=<_listener_handler_coroutine() done, defined at /datasets/pentschev/miniconda3/envs/gdf/lib/python3.9/site-packages/ucp/core.py:128> exception=UCXError('<stream_recv>: Connection reset by remote peer')>
Traceback (most recent call last):
  File "/datasets/pentschev/miniconda3/envs/gdf/lib/python3.9/site-packages/ucp/core.py", line 143, in _listener_handler_coroutine
    peer_info = await exchange_peer_info(
  File "/datasets/pentschev/miniconda3/envs/gdf/lib/python3.9/site-packages/ucp/core.py", line 52, in exchange_peer_info
    await comm.stream_recv(endpoint, peer_info_arr, peer_info_arr.nbytes)
ucp._libs.exceptions.UCXError: <stream_recv>: Connection reset by remote peer
2023-01-16 01:54:02,588 - distributed.nanny - WARNING - Restarting worker
2023-01-16 01:54:02,591 - distributed.nanny - WARNING - Restarting worker
2023-01-16 01:54:02,609 - distributed.nanny - WARNING - Restarting worker
2023-01-16 01:54:02,647 - distributed.nanny - WARNING - Restarting worker
[dgx13:36150:0:36150] Caught signal 11 (Segmentation fault: address not mapped to object at address 0x448)
==== backtrace (tid:  36150) ====
 0  /datasets/pentschev/miniconda3/envs/gdf/lib/libucs.so.0(ucs_handle_error+0x2d4) [0x7f5844b7b1a4]
 1  /datasets/pentschev/miniconda3/envs/gdf/lib/libucs.so.0(+0x2e37f) [0x7f5844b7b37f]
 2  /datasets/pentschev/miniconda3/envs/gdf/lib/libucs.so.0(+0x2e6a4) [0x7f5844b7b6a4]
 3  /lib/x86_64-linux-gnu/libpthread.so.0(+0x12980) [0x7f58ba205980]
 4  /datasets/pentschev/miniconda3/envs/gdf/lib/libucp.so.0(ucp_mem_type_unpack+0x14) [0x7f5844e03e64]
 5  /datasets/pentschev/miniconda3/envs/gdf/lib/libucp.so.0(ucp_rndv_data_handler+0x508) [0x7f5844e36358]
 6  /datasets/pentschev/miniconda3/envs/gdf/lib/libuct.so.0(+0x20b1f) [0x7f584492fb1f]
 7  /datasets/pentschev/miniconda3/envs/gdf/lib/libuct.so.0(+0x210f4) [0x7f58449300f4]
 8  /datasets/pentschev/miniconda3/envs/gdf/lib/libuct.so.0(+0x23548) [0x7f5844932548]
 9  /datasets/pentschev/miniconda3/envs/gdf/lib/libucs.so.0(ucs_event_set_wait+0xb9) [0x7f5844b85879]
10  /datasets/pentschev/miniconda3/envs/gdf/lib/libuct.so.0(uct_tcp_iface_progress+0x7b) [0x7f58449325eb]
11  /datasets/pentschev/miniconda3/envs/gdf/lib/libucp.so.0(ucp_worker_progress+0x6a) [0x7f5844e0042a]
12  /datasets/pentschev/miniconda3/envs/gdf/lib/python3.9/site-packages/ucp/_libs/ucx_api.cpython-39-x86_64-linux-gnu.so(+0x26c79) [0x7f58450bcc79]
13  /datasets/pentschev/miniconda3/envs/gdf/bin/python(+0x141eca) [0x56184d5bbeca]
14  /datasets/pentschev/miniconda3/envs/gdf/bin/python(_PyEval_EvalFrameDefault+0x3d99) [0x56184d5a9549]
15  /datasets/pentschev/miniconda3/envs/gdf/bin/python(+0x12a7d7) [0x56184d5a47d7]
16  /datasets/pentschev/miniconda3/envs/gdf/bin/python(_PyFunction_Vectorcall+0xb9) [0x56184d5b6bb9]
17  /datasets/pentschev/miniconda3/envs/gdf/bin/python(_PyEval_EvalFrameDefault+0x672) [0x56184d5a5e22]
18  /datasets/pentschev/miniconda3/envs/gdf/bin/python(+0x13cec3) [0x56184d5b6ec3]
19  /datasets/pentschev/miniconda3/envs/gdf/bin/python(+0x14bc75) [0x56184d5c5c75]
20  /datasets/pentschev/miniconda3/envs/gdf/bin/python(+0x264071) [0x56184d6de071]
21  /datasets/pentschev/miniconda3/envs/gdf/bin/python(+0xf7187) [0x56184d571187]
22  /datasets/pentschev/miniconda3/envs/gdf/bin/python(+0x133747) [0x56184d5ad747]
23  /datasets/pentschev/miniconda3/envs/gdf/bin/python(_PyEval_EvalFrameDefault+0x5f0a) [0x56184d5ab6ba]
24  /datasets/pentschev/miniconda3/envs/gdf/bin/python(+0x13cec3) [0x56184d5b6ec3]
25  /datasets/pentschev/miniconda3/envs/gdf/bin/python(_PyEval_EvalFrameDefault+0x672) [0x56184d5a5e22]
26  /datasets/pentschev/miniconda3/envs/gdf/bin/python(+0x13cec3) [0x56184d5b6ec3]
27  /datasets/pentschev/miniconda3/envs/gdf/bin/python(_PyEval_EvalFrameDefault+0x672) [0x56184d5a5e22]
28  /datasets/pentschev/miniconda3/envs/gdf/bin/python(+0x13cec3) [0x56184d5b6ec3]
29  /datasets/pentschev/miniconda3/envs/gdf/bin/python(_PyEval_EvalFrameDefault+0x672) [0x56184d5a5e22]
30  /datasets/pentschev/miniconda3/envs/gdf/bin/python(+0x13cec3) [0x56184d5b6ec3]
31  /datasets/pentschev/miniconda3/envs/gdf/bin/python(_PyEval_EvalFrameDefault+0x672) [0x56184d5a5e22]
32  /datasets/pentschev/miniconda3/envs/gdf/bin/python(+0x12a7d7) [0x56184d5a47d7]
33  /datasets/pentschev/miniconda3/envs/gdf/bin/python(_PyFunction_Vectorcall+0xb9) [0x56184d5b6bb9]
34  /datasets/pentschev/miniconda3/envs/gdf/bin/python(_PyEval_EvalFrameDefault+0x4cbc) [0x56184d5aa46c]
35  /datasets/pentschev/miniconda3/envs/gdf/bin/python(+0x12a7d7) [0x56184d5a47d7]
36  /datasets/pentschev/miniconda3/envs/gdf/bin/python(+0x14baf8) [0x56184d5c5af8]
37  /datasets/pentschev/miniconda3/envs/gdf/bin/python(PyObject_Call+0xb4) [0x56184d5c6254]
38  /datasets/pentschev/miniconda3/envs/gdf/bin/python(+0x21b8b8) [0x56184d6958b8]
39  /datasets/pentschev/miniconda3/envs/gdf/bin/python(_PyObject_MakeTpCall+0x347) [0x56184d5aea57]
40  /datasets/pentschev/miniconda3/envs/gdf/bin/python(_PyEval_EvalFrameDefault+0x3d99) [0x56184d5a9549]
41  /datasets/pentschev/miniconda3/envs/gdf/bin/python(+0x13cec3) [0x56184d5b6ec3]
42  /datasets/pentschev/miniconda3/envs/gdf/bin/python(+0x14bb91) [0x56184d5c5b91]
43  /datasets/pentschev/miniconda3/envs/gdf/bin/python(_PyEval_EvalFrameDefault+0x3d99) [0x56184d5a9549]
44  /datasets/pentschev/miniconda3/envs/gdf/bin/python(+0x13cec3) [0x56184d5b6ec3]
45  /datasets/pentschev/miniconda3/envs/gdf/bin/python(_PyEval_EvalFrameDefault+0x672) [0x56184d5a5e22]
46  /datasets/pentschev/miniconda3/envs/gdf/bin/python(+0x12a7d7) [0x56184d5a47d7]
47  /datasets/pentschev/miniconda3/envs/gdf/bin/python(_PyFunction_Vectorcall+0xb9) [0x56184d5b6bb9]
48  /datasets/pentschev/miniconda3/envs/gdf/bin/python(_PyEval_EvalFrameDefault+0x672) [0x56184d5a5e22]
49  /datasets/pentschev/miniconda3/envs/gdf/bin/python(+0x13cec3) [0x56184d5b6ec3]
50  /datasets/pentschev/miniconda3/envs/gdf/bin/python(_PyEval_EvalFrameDefault+0x3c3) [0x56184d5a5b73]
51  /datasets/pentschev/miniconda3/envs/gdf/bin/python(+0x12a7d7) [0x56184d5a47d7]
52  /datasets/pentschev/miniconda3/envs/gdf/bin/python(_PyFunction_Vectorcall+0xb9) [0x56184d5b6bb9]
53  /datasets/pentschev/miniconda3/envs/gdf/bin/python(_PyEval_EvalFrameDefault+0x11df) [0x56184d5a698f]
54  /datasets/pentschev/miniconda3/envs/gdf/bin/python(+0x12a7d7) [0x56184d5a47d7]
55  /datasets/pentschev/miniconda3/envs/gdf/bin/python(_PyEval_EvalCodeWithName+0x47) [0x56184d5a4497]
56  /datasets/pentschev/miniconda3/envs/gdf/bin/python(PyEval_EvalCodeEx+0x39) [0x56184d5a4449]
57  /datasets/pentschev/miniconda3/envs/gdf/bin/python(PyEval_EvalCode+0x1b) [0x56184d65eddb]
58  /datasets/pentschev/miniconda3/envs/gdf/bin/python(+0x213409) [0x56184d68d409]
59  /datasets/pentschev/miniconda3/envs/gdf/bin/python(+0x20f5a4) [0x56184d6895a4]
60  /datasets/pentschev/miniconda3/envs/gdf/bin/python(PyRun_StringFlags+0x9d) [0x56184d68127d]
61  /datasets/pentschev/miniconda3/envs/gdf/bin/python(PyRun_SimpleStringFlags+0x3d) [0x56184d68114d]
=================================
2023-01-16 01:54:02,860 - distributed.worker - ERROR - failed during get data with ucx://127.0.0.1:42539 -> ucx://127.0.0.1:36583
Traceback (most recent call last):
  File "/datasets/pentschev/miniconda3/envs/gdf/lib/python3.9/site-packages/distributed/comm/ucx.py", line 333, in write
    await self.ep.send(each_frame)
  File "/datasets/pentschev/miniconda3/envs/gdf/lib/python3.9/site-packages/ucp/core.py", line 650, in send
    return await comm.tag_send(self._ep, buffer, nbytes, tag, name=log)
ucp._libs.exceptions.UCXError: <[Send #007] ep: 0x7f2da00ea200, tag: 0x76b82c6624510a94, nbytes: 50000000, type: <class 'cupy.ndarray'>>: Connection reset by remote peer

During handling of the above exception, another exception occurred:

Traceback (most recent call last):
  File "/datasets/pentschev/miniconda3/envs/gdf/lib/python3.9/site-packages/distributed/worker.py", line 1766, in get_data
    compressed = await comm.write(msg, serializers=serializers)
  File "/datasets/pentschev/miniconda3/envs/gdf/lib/python3.9/site-packages/distributed/utils.py", line 741, in wrapper
    return await func(*args, **kwargs)
  File "/datasets/pentschev/miniconda3/envs/gdf/lib/python3.9/site-packages/distributed/comm/ucx.py", line 337, in write
    raise CommClosedError("While writing, the connection was closed")
distributed.comm.core.CommClosedError: While writing, the connection was closed
2023-01-16 01:54:02,861 - distributed.worker - ERROR - Worker stream died during communication: ucx://127.0.0.1:36583
Traceback (most recent call last):
  File "/datasets/pentschev/miniconda3/envs/gdf/lib/python3.9/site-packages/distributed/comm/ucx.py", line 349, in read
    await self.ep.recv(msg)
  File "/datasets/pentschev/miniconda3/envs/gdf/lib/python3.9/site-packages/ucp/core.py", line 725, in recv
    ret = await comm.tag_recv(self._ep, buffer, nbytes, tag, name=log)
ucp._libs.exceptions.UCXCanceled: <[Recv #008] ep: 0x7f2da00ea240, tag: 0x610fb2dac0eeb22c, nbytes: 16, type: <class 'numpy.ndarray'>>: 

During handling of the above exception, another exception occurred:

Traceback (most recent call last):
  File "/datasets/pentschev/miniconda3/envs/gdf/lib/python3.9/site-packages/distributed/worker.py", line 2058, in gather_dep
    response = await get_data_from_worker(
  File "/datasets/pentschev/miniconda3/envs/gdf/lib/python3.9/site-packages/distributed/worker.py", line 2870, in get_data_from_worker
    return await retry_operation(_get_data, operation="get_data_from_worker")
  File "/datasets/pentschev/miniconda3/envs/gdf/lib/python3.9/site-packages/distributed/utils_comm.py", line 402, in retry_operation
    return await retry(
  File "/datasets/pentschev/miniconda3/envs/gdf/lib/python3.9/site-packages/distributed/utils_comm.py", line 387, in retry
    return await coro()
  File "/datasets/pentschev/miniconda3/envs/gdf/lib/python3.9/site-packages/distributed/worker.py", line 2850, in _get_data
    response = await send_recv(
  File "/datasets/pentschev/miniconda3/envs/gdf/lib/python3.9/site-packages/distributed/core.py", line 986, in send_recv
    response = await comm.read(deserializers=deserializers)
  File "/datasets/pentschev/miniconda3/envs/gdf/lib/python3.9/site-packages/distributed/utils.py", line 741, in wrapper
    return await func(*args, **kwargs)
  File "/datasets/pentschev/miniconda3/envs/gdf/lib/python3.9/site-packages/distributed/comm/ucx.py", line 367, in read
    raise CommClosedError(
distributed.comm.core.CommClosedError: Connection closed by writer.
Inner exception: UCXCanceled("<[Recv #008] ep: 0x7f2da00ea240, tag: 0x610fb2dac0eeb22c, nbytes: 16, type: <class 'numpy.ndarray'>>: ")
2023-01-16 01:54:02,941 - distributed.nanny - WARNING - Restarting worker
2023-01-16 01:54:04,359 - distributed.preloading - INFO - Creating preload: dask_cuda.initialize
2023-01-16 01:54:04,359 - distributed.preloading - INFO - Import preload module: dask_cuda.initialize
2023-01-16 01:54:04,622 - distributed.preloading - INFO - Creating preload: dask_cuda.initialize
2023-01-16 01:54:04,622 - distributed.preloading - INFO - Import preload module: dask_cuda.initialize
2023-01-16 01:54:04,622 - distributed.preloading - INFO - Creating preload: dask_cuda.initialize
2023-01-16 01:54:04,622 - distributed.preloading - INFO - Import preload module: dask_cuda.initialize
2023-01-16 01:54:04,624 - distributed.preloading - INFO - Creating preload: dask_cuda.initialize
2023-01-16 01:54:04,624 - distributed.preloading - INFO - Import preload module: dask_cuda.initialize
2023-01-16 01:54:04,627 - distributed.preloading - INFO - Creating preload: dask_cuda.initialize
2023-01-16 01:54:04,627 - distributed.preloading - INFO - Import preload module: dask_cuda.initialize
2023-01-16 01:54:04,833 - distributed.preloading - INFO - Creating preload: dask_cuda.initialize
2023-01-16 01:54:04,833 - distributed.preloading - INFO - Import preload module: dask_cuda.initialize
2023-01-16 01:54:32,054 - distributed.worker - ERROR - Worker stream died during communication: ucx://127.0.0.1:53089
Traceback (most recent call last):
  File "/datasets/pentschev/miniconda3/envs/gdf/lib/python3.9/site-packages/distributed/comm/ucx.py", line 466, in connect
    ep = await ucp.create_endpoint(ip, port)
  File "/datasets/pentschev/miniconda3/envs/gdf/lib/python3.9/site-packages/ucp/core.py", line 1004, in create_endpoint
    return await _get_ctx().create_endpoint(
  File "/datasets/pentschev/miniconda3/envs/gdf/lib/python3.9/site-packages/ucp/core.py", line 316, in create_endpoint
    peer_info = await exchange_peer_info(
  File "/datasets/pentschev/miniconda3/envs/gdf/lib/python3.9/site-packages/ucp/core.py", line 54, in exchange_peer_info
    await comm.stream_recv(endpoint, peer_info_arr, peer_info_arr.nbytes)
asyncio.exceptions.CancelledError

During handling of the above exception, another exception occurred:

Traceback (most recent call last):
  File "/datasets/pentschev/miniconda3/envs/gdf/lib/python3.9/asyncio/tasks.py", line 490, in wait_for
    return fut.result()
asyncio.exceptions.CancelledError

The above exception was the direct cause of the following exception:

Traceback (most recent call last):
  File "/datasets/pentschev/miniconda3/envs/gdf/lib/python3.9/site-packages/distributed/comm/core.py", line 291, in connect
    comm = await asyncio.wait_for(
  File "/datasets/pentschev/miniconda3/envs/gdf/lib/python3.9/asyncio/tasks.py", line 492, in wait_for
    raise exceptions.TimeoutError() from exc
asyncio.exceptions.TimeoutError

The above exception was the direct cause of the following exception:

Traceback (most recent call last):
  File "/datasets/pentschev/miniconda3/envs/gdf/lib/python3.9/site-packages/distributed/worker.py", line 2058, in gather_dep
    response = await get_data_from_worker(
  File "/datasets/pentschev/miniconda3/envs/gdf/lib/python3.9/site-packages/distributed/worker.py", line 2870, in get_data_from_worker
    return await retry_operation(_get_data, operation="get_data_from_worker")
  File "/datasets/pentschev/miniconda3/envs/gdf/lib/python3.9/site-packages/distributed/utils_comm.py", line 402, in retry_operation
    return await retry(
  File "/datasets/pentschev/miniconda3/envs/gdf/lib/python3.9/site-packages/distributed/utils_comm.py", line 387, in retry
    return await coro()
  File "/datasets/pentschev/miniconda3/envs/gdf/lib/python3.9/site-packages/distributed/worker.py", line 2847, in _get_data
    comm = await rpc.connect(worker)
  File "/datasets/pentschev/miniconda3/envs/gdf/lib/python3.9/site-packages/distributed/core.py", line 1439, in connect
    return await connect_attempt
  File "/datasets/pentschev/miniconda3/envs/gdf/lib/python3.9/site-packages/distributed/core.py", line 1375, in _connect
    comm = await connect(
  File "/datasets/pentschev/miniconda3/envs/gdf/lib/python3.9/site-packages/distributed/comm/core.py", line 317, in connect
    raise OSError(
OSError: Timed out trying to connect to ucx://127.0.0.1:53089 after 30 s
2023-01-16 01:54:32,057 - distributed.worker - ERROR - Worker stream died during communication: ucx://127.0.0.1:43547
Traceback (most recent call last):
  File "/datasets/pentschev/miniconda3/envs/gdf/lib/python3.9/site-packages/distributed/comm/ucx.py", line 466, in connect
    ep = await ucp.create_endpoint(ip, port)
  File "/datasets/pentschev/miniconda3/envs/gdf/lib/python3.9/site-packages/ucp/core.py", line 1004, in create_endpoint
    return await _get_ctx().create_endpoint(
  File "/datasets/pentschev/miniconda3/envs/gdf/lib/python3.9/site-packages/ucp/core.py", line 316, in create_endpoint
    peer_info = await exchange_peer_info(
  File "/datasets/pentschev/miniconda3/envs/gdf/lib/python3.9/site-packages/ucp/core.py", line 54, in exchange_peer_info
    await comm.stream_recv(endpoint, peer_info_arr, peer_info_arr.nbytes)
asyncio.exceptions.CancelledError

During handling of the above exception, another exception occurred:

Traceback (most recent call last):
  File "/datasets/pentschev/miniconda3/envs/gdf/lib/python3.9/asyncio/tasks.py", line 490, in wait_for
    return fut.result()
asyncio.exceptions.CancelledError

The above exception was the direct cause of the following exception:

Traceback (most recent call last):
  File "/datasets/pentschev/miniconda3/envs/gdf/lib/python3.9/site-packages/distributed/comm/core.py", line 291, in connect
    comm = await asyncio.wait_for(
  File "/datasets/pentschev/miniconda3/envs/gdf/lib/python3.9/asyncio/tasks.py", line 492, in wait_for
    raise exceptions.TimeoutError() from exc
asyncio.exceptions.TimeoutError

The above exception was the direct cause of the following exception:

Traceback (most recent call last):
  File "/datasets/pentschev/miniconda3/envs/gdf/lib/python3.9/site-packages/distributed/worker.py", line 2058, in gather_dep
    response = await get_data_from_worker(
  File "/datasets/pentschev/miniconda3/envs/gdf/lib/python3.9/site-packages/distributed/worker.py", line 2870, in get_data_from_worker
    return await retry_operation(_get_data, operation="get_data_from_worker")
  File "/datasets/pentschev/miniconda3/envs/gdf/lib/python3.9/site-packages/distributed/utils_comm.py", line 402, in retry_operation
    return await retry(
  File "/datasets/pentschev/miniconda3/envs/gdf/lib/python3.9/site-packages/distributed/utils_comm.py", line 387, in retry
    return await coro()
  File "/datasets/pentschev/miniconda3/envs/gdf/lib/python3.9/site-packages/distributed/worker.py", line 2847, in _get_data
    comm = await rpc.connect(worker)
  File "/datasets/pentschev/miniconda3/envs/gdf/lib/python3.9/site-packages/distributed/core.py", line 1439, in connect
    return await connect_attempt
  File "/datasets/pentschev/miniconda3/envs/gdf/lib/python3.9/site-packages/distributed/core.py", line 1375, in _connect
    comm = await connect(
  File "/datasets/pentschev/miniconda3/envs/gdf/lib/python3.9/site-packages/distributed/comm/core.py", line 317, in connect
    raise OSError(
OSError: Timed out trying to connect to ucx://127.0.0.1:43547 after 30 s
[dgx13:36331:0:36331] Caught signal 11 (Segmentation fault: address not mapped to object at address 0x448)
==== backtrace (tid:  36331) ====
 0  /datasets/pentschev/miniconda3/envs/gdf/lib/libucs.so.0(ucs_handle_error+0x2d4) [0x7fdaa1dca1a4]
 1  /datasets/pentschev/miniconda3/envs/gdf/lib/libucs.so.0(+0x2e37f) [0x7fdaa1dca37f]
 2  /datasets/pentschev/miniconda3/envs/gdf/lib/libucs.so.0(+0x2e6a4) [0x7fdaa1dca6a4]
 3  /lib/x86_64-linux-gnu/libpthread.so.0(+0x12980) [0x7fdb25519980]
 4  /datasets/pentschev/miniconda3/envs/gdf/lib/libucp.so.0(ucp_mem_type_unpack+0x14) [0x7fdab427ee64]
 5  /datasets/pentschev/miniconda3/envs/gdf/lib/libucp.so.0(ucp_rndv_data_handler+0x508) [0x7fdab42b1358]
 6  /datasets/pentschev/miniconda3/envs/gdf/lib/libuct.so.0(+0x20b1f) [0x7fdaa1b7eb1f]
 7  /datasets/pentschev/miniconda3/envs/gdf/lib/libuct.so.0(+0x210f4) [0x7fdaa1b7f0f4]
 8  /datasets/pentschev/miniconda3/envs/gdf/lib/libuct.so.0(+0x23548) [0x7fdaa1b81548]
 9  /datasets/pentschev/miniconda3/envs/gdf/lib/libucs.so.0(ucs_event_set_wait+0xb9) [0x7fdaa1dd4879]
10  /datasets/pentschev/miniconda3/envs/gdf/lib/libuct.so.0(uct_tcp_iface_progress+0x7b) [0x7fdaa1b815eb]
11  /datasets/pentschev/miniconda3/envs/gdf/lib/libucp.so.0(ucp_worker_progress+0x6a) [0x7fdab427b42a]
12  /datasets/pentschev/miniconda3/envs/gdf/lib/python3.9/site-packages/ucp/_libs/ucx_api.cpython-39-x86_64-linux-gnu.so(+0x26c79) [0x7fdab4537c79]
13  /datasets/pentschev/miniconda3/envs/gdf/bin/python(+0x141eca) [0x55be5150feca]
14  /datasets/pentschev/miniconda3/envs/gdf/bin/python(_PyEval_EvalFrameDefault+0x3d99) [0x55be514fd549]
15  /datasets/pentschev/miniconda3/envs/gdf/bin/python(+0x12a7d7) [0x55be514f87d7]
16  /datasets/pentschev/miniconda3/envs/gdf/bin/python(_PyFunction_Vectorcall+0xb9) [0x55be5150abb9]
17  /datasets/pentschev/miniconda3/envs/gdf/bin/python(_PyEval_EvalFrameDefault+0x672) [0x55be514f9e22]
18  /datasets/pentschev/miniconda3/envs/gdf/bin/python(+0x13cec3) [0x55be5150aec3]
19  /datasets/pentschev/miniconda3/envs/gdf/bin/python(+0x14bc75) [0x55be51519c75]
20  /datasets/pentschev/miniconda3/envs/gdf/bin/python(+0x264071) [0x55be51632071]
21  /datasets/pentschev/miniconda3/envs/gdf/bin/python(+0xf7187) [0x55be514c5187]
22  /datasets/pentschev/miniconda3/envs/gdf/bin/python(+0x133747) [0x55be51501747]
23  /datasets/pentschev/miniconda3/envs/gdf/bin/python(_PyEval_EvalFrameDefault+0x5f0a) [0x55be514ff6ba]
24  /datasets/pentschev/miniconda3/envs/gdf/bin/python(+0x13cec3) [0x55be5150aec3]
25  /datasets/pentschev/miniconda3/envs/gdf/bin/python(_PyEval_EvalFrameDefault+0x672) [0x55be514f9e22]
26  /datasets/pentschev/miniconda3/envs/gdf/bin/python(+0x13cec3) [0x55be5150aec3]
27  /datasets/pentschev/miniconda3/envs/gdf/bin/python(_PyEval_EvalFrameDefault+0x672) [0x55be514f9e22]
28  /datasets/pentschev/miniconda3/envs/gdf/bin/python(+0x13cec3) [0x55be5150aec3]
29  /datasets/pentschev/miniconda3/envs/gdf/bin/python(_PyEval_EvalFrameDefault+0x672) [0x55be514f9e22]
30  /datasets/pentschev/miniconda3/envs/gdf/bin/python(+0x13cec3) [0x55be5150aec3]
31  /datasets/pentschev/miniconda3/envs/gdf/bin/python(_PyEval_EvalFrameDefault+0x672) [0x55be514f9e22]
32  /datasets/pentschev/miniconda3/envs/gdf/bin/python(+0x12a7d7) [0x55be514f87d7]
33  /datasets/pentschev/miniconda3/envs/gdf/bin/python(_PyFunction_Vectorcall+0xb9) [0x55be5150abb9]
34  /datasets/pentschev/miniconda3/envs/gdf/bin/python(_PyEval_EvalFrameDefault+0x4cbc) [0x55be514fe46c]
35  /datasets/pentschev/miniconda3/envs/gdf/bin/python(+0x12a7d7) [0x55be514f87d7]
36  /datasets/pentschev/miniconda3/envs/gdf/bin/python(+0x14baf8) [0x55be51519af8]
37  /datasets/pentschev/miniconda3/envs/gdf/bin/python(PyObject_Call+0xb4) [0x55be5151a254]
38  /datasets/pentschev/miniconda3/envs/gdf/bin/python(+0x21b8b8) [0x55be515e98b8]
39  /datasets/pentschev/miniconda3/envs/gdf/bin/python(_PyObject_MakeTpCall+0x347) [0x55be51502a57]
40  /datasets/pentschev/miniconda3/envs/gdf/bin/python(_PyEval_EvalFrameDefault+0x3d99) [0x55be514fd549]
41  /datasets/pentschev/miniconda3/envs/gdf/bin/python(+0x13cec3) [0x55be5150aec3]
42  /datasets/pentschev/miniconda3/envs/gdf/bin/python(+0x14bb91) [0x55be51519b91]
43  /datasets/pentschev/miniconda3/envs/gdf/bin/python(_PyEval_EvalFrameDefault+0x3d99) [0x55be514fd549]
44  /datasets/pentschev/miniconda3/envs/gdf/bin/python(+0x13cec3) [0x55be5150aec3]
45  /datasets/pentschev/miniconda3/envs/gdf/bin/python(_PyEval_EvalFrameDefault+0x672) [0x55be514f9e22]
46  /datasets/pentschev/miniconda3/envs/gdf/bin/python(+0x12a7d7) [0x55be514f87d7]
47  /datasets/pentschev/miniconda3/envs/gdf/bin/python(_PyFunction_Vectorcall+0xb9) [0x55be5150abb9]
48  /datasets/pentschev/miniconda3/envs/gdf/bin/python(_PyEval_EvalFrameDefault+0x672) [0x55be514f9e22]
49  /datasets/pentschev/miniconda3/envs/gdf/bin/python(+0x13cec3) [0x55be5150aec3]
50  /datasets/pentschev/miniconda3/envs/gdf/bin/python(_PyEval_EvalFrameDefault+0x3c3) [0x55be514f9b73]
51  /datasets/pentschev/miniconda3/envs/gdf/bin/python(+0x12a7d7) [0x55be514f87d7]
52  /datasets/pentschev/miniconda3/envs/gdf/bin/python(_PyFunction_Vectorcall+0xb9) [0x55be5150abb9]
53  /datasets/pentschev/miniconda3/envs/gdf/bin/python(_PyEval_EvalFrameDefault+0x11df) [0x55be514fa98f]
54  /datasets/pentschev/miniconda3/envs/gdf/bin/python(+0x12a7d7) [0x55be514f87d7]
55  /datasets/pentschev/miniconda3/envs/gdf/bin/python(_PyEval_EvalCodeWithName+0x47) [0x55be514f8497]
56  /datasets/pentschev/miniconda3/envs/gdf/bin/python(PyEval_EvalCodeEx+0x39) [0x55be514f8449]
57  /datasets/pentschev/miniconda3/envs/gdf/bin/python(PyEval_EvalCode+0x1b) [0x55be515b2ddb]
58  /datasets/pentschev/miniconda3/envs/gdf/bin/python(+0x213409) [0x55be515e1409]
59  /datasets/pentschev/miniconda3/envs/gdf/bin/python(+0x20f5a4) [0x55be515dd5a4]
60  /datasets/pentschev/miniconda3/envs/gdf/bin/python(PyRun_StringFlags+0x9d) [0x55be515d527d]
61  /datasets/pentschev/miniconda3/envs/gdf/bin/python(PyRun_SimpleStringFlags+0x3d) [0x55be515d514d]
=================================
[dgx13:36334:0:36334] Caught signal 11 (Segmentation fault: address not mapped to object at address 0x448)
==== backtrace (tid:  36334) ====
 0  /datasets/pentschev/miniconda3/envs/gdf/lib/libucs.so.0(ucs_handle_error+0x2d4) [0x7fc1b827a1a4]
 1  /datasets/pentschev/miniconda3/envs/gdf/lib/libucs.so.0(+0x2e37f) [0x7fc1b827a37f]
 2  /datasets/pentschev/miniconda3/envs/gdf/lib/libucs.so.0(+0x2e6a4) [0x7fc1b827a6a4]
 3  /lib/x86_64-linux-gnu/libpthread.so.0(+0x12980) [0x7fc22d79d980]
 4  /datasets/pentschev/miniconda3/envs/gdf/lib/libucp.so.0(ucp_mem_type_unpack+0x14) [0x7fc1b8502e64]
 5  /datasets/pentschev/miniconda3/envs/gdf/lib/libucp.so.0(ucp_rndv_data_handler+0x508) [0x7fc1b8535358]
 6  /datasets/pentschev/miniconda3/envs/gdf/lib/libuct.so.0(+0x20b1f) [0x7fc1b802eb1f]
 7  /datasets/pentschev/miniconda3/envs/gdf/lib/libuct.so.0(+0x210f4) [0x7fc1b802f0f4]
 8  /datasets/pentschev/miniconda3/envs/gdf/lib/libuct.so.0(+0x23548) [0x7fc1b8031548]
 9  /datasets/pentschev/miniconda3/envs/gdf/lib/libucs.so.0(ucs_event_set_wait+0xb9) [0x7fc1b8284879]
10  /datasets/pentschev/miniconda3/envs/gdf/lib/libuct.so.0(uct_tcp_iface_progress+0x7b) [0x7fc1b80315eb]
11  /datasets/pentschev/miniconda3/envs/gdf/lib/libucp.so.0(ucp_worker_progress+0x6a) [0x7fc1b84ff42a]
12  /datasets/pentschev/miniconda3/envs/gdf/lib/python3.9/site-packages/ucp/_libs/ucx_api.cpython-39-x86_64-linux-gnu.so(+0x26c79) [0x7fc1b87bbc79]
13  /datasets/pentschev/miniconda3/envs/gdf/bin/python(+0x141eca) [0x560253247eca]
14  /datasets/pentschev/miniconda3/envs/gdf/bin/python(_PyEval_EvalFrameDefault+0x3d99) [0x560253235549]
15  /datasets/pentschev/miniconda3/envs/gdf/bin/python(+0x12a7d7) [0x5602532307d7]
16  /datasets/pentschev/miniconda3/envs/gdf/bin/python(_PyFunction_Vectorcall+0xb9) [0x560253242bb9]
17  /datasets/pentschev/miniconda3/envs/gdf/bin/python(_PyEval_EvalFrameDefault+0x672) [0x560253231e22]
18  /datasets/pentschev/miniconda3/envs/gdf/bin/python(+0x13cec3) [0x560253242ec3]
19  /datasets/pentschev/miniconda3/envs/gdf/bin/python(+0x14bc75) [0x560253251c75]
20  /datasets/pentschev/miniconda3/envs/gdf/bin/python(+0x264071) [0x56025336a071]
21  /datasets/pentschev/miniconda3/envs/gdf/bin/python(+0xf7187) [0x5602531fd187]
22  /datasets/pentschev/miniconda3/envs/gdf/bin/python(+0x133747) [0x560253239747]
23  /datasets/pentschev/miniconda3/envs/gdf/bin/python(_PyEval_EvalFrameDefault+0x5f0a) [0x5602532376ba]
24  /datasets/pentschev/miniconda3/envs/gdf/bin/python(+0x13cec3) [0x560253242ec3]
25  /datasets/pentschev/miniconda3/envs/gdf/bin/python(_PyEval_EvalFrameDefault+0x672) [0x560253231e22]
26  /datasets/pentschev/miniconda3/envs/gdf/bin/python(+0x13cec3) [0x560253242ec3]
27  /datasets/pentschev/miniconda3/envs/gdf/bin/python(_PyEval_EvalFrameDefault+0x672) [0x560253231e22]
28  /datasets/pentschev/miniconda3/envs/gdf/bin/python(+0x13cec3) [0x560253242ec3]
29  /datasets/pentschev/miniconda3/envs/gdf/bin/python(_PyEval_EvalFrameDefault+0x672) [0x560253231e22]
30  /datasets/pentschev/miniconda3/envs/gdf/bin/python(+0x13cec3) [0x560253242ec3]
31  /datasets/pentschev/miniconda3/envs/gdf/bin/python(_PyEval_EvalFrameDefault+0x672) [0x560253231e22]
32  /datasets/pentschev/miniconda3/envs/gdf/bin/python(+0x12a7d7) [0x5602532307d7]
33  /datasets/pentschev/miniconda3/envs/gdf/bin/python(_PyFunction_Vectorcall+0xb9) [0x560253242bb9]
34  /datasets/pentschev/miniconda3/envs/gdf/bin/python(_PyEval_EvalFrameDefault+0x4cbc) [0x56025323646c]
35  /datasets/pentschev/miniconda3/envs/gdf/bin/python(+0x12a7d7) [0x5602532307d7]
36  /datasets/pentschev/miniconda3/envs/gdf/bin/python(+0x14baf8) [0x560253251af8]
37  /datasets/pentschev/miniconda3/envs/gdf/bin/python(PyObject_Call+0xb4) [0x560253252254]
38  /datasets/pentschev/miniconda3/envs/gdf/bin/python(+0x21b8b8) [0x5602533218b8]
39  /datasets/pentschev/miniconda3/envs/gdf/bin/python(_PyObject_MakeTpCall+0x347) [0x56025323aa57]
40  /datasets/pentschev/miniconda3/envs/gdf/bin/python(_PyEval_EvalFrameDefault+0x3d99) [0x560253235549]
41  /datasets/pentschev/miniconda3/envs/gdf/bin/python(+0x13cec3) [0x560253242ec3]
42  /datasets/pentschev/miniconda3/envs/gdf/bin/python(+0x14bb91) [0x560253251b91]
43  /datasets/pentschev/miniconda3/envs/gdf/bin/python(_PyEval_EvalFrameDefault+0x3d99) [0x560253235549]
44  /datasets/pentschev/miniconda3/envs/gdf/bin/python(+0x13cec3) [0x560253242ec3]
45  /datasets/pentschev/miniconda3/envs/gdf/bin/python(_PyEval_EvalFrameDefault+0x672) [0x560253231e22]
46  /datasets/pentschev/miniconda3/envs/gdf/bin/python(+0x12a7d7) [0x5602532307d7]
47  /datasets/pentschev/miniconda3/envs/gdf/bin/python(_PyFunction_Vectorcall+0xb9) [0x560253242bb9]
48  /datasets/pentschev/miniconda3/envs/gdf/bin/python(_PyEval_EvalFrameDefault+0x672) [0x560253231e22]
49  /datasets/pentschev/miniconda3/envs/gdf/bin/python(+0x13cec3) [0x560253242ec3]
50  /datasets/pentschev/miniconda3/envs/gdf/bin/python(_PyEval_EvalFrameDefault+0x3c3) [0x560253231b73]
51  /datasets/pentschev/miniconda3/envs/gdf/bin/python(+0x12a7d7) [0x5602532307d7]
52  /datasets/pentschev/miniconda3/envs/gdf/bin/python(_PyFunction_Vectorcall+0xb9) [0x560253242bb9]
53  /datasets/pentschev/miniconda3/envs/gdf/bin/python(_PyEval_EvalFrameDefault+0x11df) [0x56025323298f]
54  /datasets/pentschev/miniconda3/envs/gdf/bin/python(+0x12a7d7) [0x5602532307d7]
55  /datasets/pentschev/miniconda3/envs/gdf/bin/python(_PyEval_EvalCodeWithName+0x47) [0x560253230497]
56  /datasets/pentschev/miniconda3/envs/gdf/bin/python(PyEval_EvalCodeEx+0x39) [0x560253230449]
57  /datasets/pentschev/miniconda3/envs/gdf/bin/python(PyEval_EvalCode+0x1b) [0x5602532eaddb]
58  /datasets/pentschev/miniconda3/envs/gdf/bin/python(+0x213409) [0x560253319409]
59  /datasets/pentschev/miniconda3/envs/gdf/bin/python(+0x20f5a4) [0x5602533155a4]
60  /datasets/pentschev/miniconda3/envs/gdf/bin/python(PyRun_StringFlags+0x9d) [0x56025330d27d]
61  /datasets/pentschev/miniconda3/envs/gdf/bin/python(PyRun_SimpleStringFlags+0x3d) [0x56025330d14d]
=================================
2023-01-16 01:54:32,883 - distributed.worker - ERROR - Worker stream died during communication: ucx://127.0.0.1:36337
Traceback (most recent call last):
  File "/datasets/pentschev/miniconda3/envs/gdf/lib/python3.9/site-packages/distributed/comm/ucx.py", line 349, in read
    await self.ep.recv(msg)
  File "/datasets/pentschev/miniconda3/envs/gdf/lib/python3.9/site-packages/ucp/core.py", line 725, in recv
    ret = await comm.tag_recv(self._ep, buffer, nbytes, tag, name=log)
ucp._libs.exceptions.UCXCanceled: <[Recv #008] ep: 0x7f462014f100, tag: 0x5bba762de8519e4d, nbytes: 16, type: <class 'numpy.ndarray'>>: 

During handling of the above exception, another exception occurred:

Traceback (most recent call last):
  File "/datasets/pentschev/miniconda3/envs/gdf/lib/python3.9/site-packages/distributed/worker.py", line 2058, in gather_dep
    response = await get_data_from_worker(
  File "/datasets/pentschev/miniconda3/envs/gdf/lib/python3.9/site-packages/distributed/worker.py", line 2870, in get_data_from_worker
    return await retry_operation(_get_data, operation="get_data_from_worker")
  File "/datasets/pentschev/miniconda3/envs/gdf/lib/python3.9/site-packages/distributed/utils_comm.py", line 402, in retry_operation
    return await retry(
  File "/datasets/pentschev/miniconda3/envs/gdf/lib/python3.9/site-packages/distributed/utils_comm.py", line 387, in retry
    return await coro()
  File "/datasets/pentschev/miniconda3/envs/gdf/lib/python3.9/site-packages/distributed/worker.py", line 2850, in _get_data
    response = await send_recv(
  File "/datasets/pentschev/miniconda3/envs/gdf/lib/python3.9/site-packages/distributed/core.py", line 986, in send_recv
    response = await comm.read(deserializers=deserializers)
  File "/datasets/pentschev/miniconda3/envs/gdf/lib/python3.9/site-packages/distributed/utils.py", line 741, in wrapper
    return await func(*args, **kwargs)
  File "/datasets/pentschev/miniconda3/envs/gdf/lib/python3.9/site-packages/distributed/comm/ucx.py", line 367, in read
    raise CommClosedError(
distributed.comm.core.CommClosedError: Connection closed by writer.
Inner exception: UCXCanceled("<[Recv #008] ep: 0x7f462014f100, tag: 0x5bba762de8519e4d, nbytes: 16, type: <class 'numpy.ndarray'>>: ")
2023-01-16 01:54:32,892 - distributed.worker - ERROR - failed during get data with ucx://127.0.0.1:42539 -> ucx://127.0.0.1:46577
Traceback (most recent call last):
  File "/datasets/pentschev/miniconda3/envs/gdf/lib/python3.9/site-packages/distributed/comm/ucx.py", line 333, in write
    await self.ep.send(each_frame)
  File "/datasets/pentschev/miniconda3/envs/gdf/lib/python3.9/site-packages/ucp/core.py", line 650, in send
    return await comm.tag_send(self._ep, buffer, nbytes, tag, name=log)
ucp._libs.exceptions.UCXError: <[Send #007] ep: 0x7f2da00ea200, tag: 0xfa30b21d651cf15f, nbytes: 50000000, type: <class 'cupy.ndarray'>>: Connection reset by remote peer

During handling of the above exception, another exception occurred:

Traceback (most recent call last):
  File "/datasets/pentschev/miniconda3/envs/gdf/lib/python3.9/site-packages/distributed/worker.py", line 1766, in get_data
    compressed = await comm.write(msg, serializers=serializers)
  File "/datasets/pentschev/miniconda3/envs/gdf/lib/python3.9/site-packages/distributed/utils.py", line 741, in wrapper
    return await func(*args, **kwargs)
  File "/datasets/pentschev/miniconda3/envs/gdf/lib/python3.9/site-packages/distributed/comm/ucx.py", line 337, in write
    raise CommClosedError("While writing, the connection was closed")
distributed.comm.core.CommClosedError: While writing, the connection was closed
2023-01-16 01:54:32,895 - distributed.worker - ERROR - failed during get data with ucx://127.0.0.1:47717 -> ucx://127.0.0.1:46577
Traceback (most recent call last):
  File "/datasets/pentschev/miniconda3/envs/gdf/lib/python3.9/site-packages/distributed/comm/ucx.py", line 333, in write
    await self.ep.send(each_frame)
  File "/datasets/pentschev/miniconda3/envs/gdf/lib/python3.9/site-packages/ucp/core.py", line 650, in send
    return await comm.tag_send(self._ep, buffer, nbytes, tag, name=log)
ucp._libs.exceptions.UCXError: <[Send #007] ep: 0x7f3bd26871c0, tag: 0x9b01f79944bf8b57, nbytes: 50000000, type: <class 'cupy.ndarray'>>: Endpoint timeout

During handling of the above exception, another exception occurred:

Traceback (most recent call last):
  File "/datasets/pentschev/miniconda3/envs/gdf/lib/python3.9/site-packages/distributed/worker.py", line 1766, in get_data
    compressed = await comm.write(msg, serializers=serializers)
  File "/datasets/pentschev/miniconda3/envs/gdf/lib/python3.9/site-packages/distributed/utils.py", line 741, in wrapper
    return await func(*args, **kwargs)
  File "/datasets/pentschev/miniconda3/envs/gdf/lib/python3.9/site-packages/distributed/comm/ucx.py", line 337, in write
    raise CommClosedError("While writing, the connection was closed")
distributed.comm.core.CommClosedError: While writing, the connection was closed
2023-01-16 01:54:32,897 - distributed.worker - ERROR - failed during get data with ucx://127.0.0.1:47717 -> ucx://127.0.0.1:36337
Traceback (most recent call last):
  File "/datasets/pentschev/miniconda3/envs/gdf/lib/python3.9/site-packages/distributed/comm/ucx.py", line 333, in write
    await self.ep.send(each_frame)
  File "/datasets/pentschev/miniconda3/envs/gdf/lib/python3.9/site-packages/ucp/core.py", line 650, in send
    return await comm.tag_send(self._ep, buffer, nbytes, tag, name=log)
ucp._libs.exceptions.UCXError: <[Send #007] ep: 0x7f3bd2687300, tag: 0xfce279fbfd455e2c, nbytes: 50000000, type: <class 'cupy.ndarray'>>: Connection reset by remote peer

During handling of the above exception, another exception occurred:

Traceback (most recent call last):
  File "/datasets/pentschev/miniconda3/envs/gdf/lib/python3.9/site-packages/distributed/worker.py", line 1766, in get_data
    compressed = await comm.write(msg, serializers=serializers)
  File "/datasets/pentschev/miniconda3/envs/gdf/lib/python3.9/site-packages/distributed/utils.py", line 741, in wrapper
    return await func(*args, **kwargs)
  File "/datasets/pentschev/miniconda3/envs/gdf/lib/python3.9/site-packages/distributed/comm/ucx.py", line 337, in write
    raise CommClosedError("While writing, the connection was closed")
distributed.comm.core.CommClosedError: While writing, the connection was closed
2023-01-16 01:54:32,963 - distributed.nanny - WARNING - Restarting worker
2023-01-16 01:54:33,005 - distributed.nanny - WARNING - Restarting worker
[dgx13:36352:0:36352] Caught signal 11 (Segmentation fault: address not mapped to object at address 0x448)
==== backtrace (tid:  36352) ====
 0  /datasets/pentschev/miniconda3/envs/gdf/lib/libucs.so.0(ucs_handle_error+0x2d4) [0x7f04296071a4]
 1  /datasets/pentschev/miniconda3/envs/gdf/lib/libucs.so.0(+0x2e37f) [0x7f042960737f]
 2  /datasets/pentschev/miniconda3/envs/gdf/lib/libucs.so.0(+0x2e6a4) [0x7f04296076a4]
 3  /lib/x86_64-linux-gnu/libpthread.so.0(+0x12980) [0x7f04acb35980]
 4  /datasets/pentschev/miniconda3/envs/gdf/lib/libucp.so.0(ucp_mem_type_unpack+0x14) [0x7f042988fe64]
 5  /datasets/pentschev/miniconda3/envs/gdf/lib/libucp.so.0(ucp_rndv_data_handler+0x508) [0x7f04298c2358]
 6  /datasets/pentschev/miniconda3/envs/gdf/lib/libuct.so.0(+0x20b1f) [0x7f04293bbb1f]
 7  /datasets/pentschev/miniconda3/envs/gdf/lib/libuct.so.0(+0x210f4) [0x7f04293bc0f4]
 8  /datasets/pentschev/miniconda3/envs/gdf/lib/libuct.so.0(+0x23548) [0x7f04293be548]
 9  /datasets/pentschev/miniconda3/envs/gdf/lib/libucs.so.0(ucs_event_set_wait+0xb9) [0x7f0429611879]
10  /datasets/pentschev/miniconda3/envs/gdf/lib/libuct.so.0(uct_tcp_iface_progress+0x7b) [0x7f04293be5eb]
11  /datasets/pentschev/miniconda3/envs/gdf/lib/libucp.so.0(ucp_worker_progress+0x6a) [0x7f042988c42a]
12  /datasets/pentschev/miniconda3/envs/gdf/lib/python3.9/site-packages/ucp/_libs/ucx_api.cpython-39-x86_64-linux-gnu.so(+0x26c79) [0x7f0429b48c79]
13  /datasets/pentschev/miniconda3/envs/gdf/bin/python(+0x141eca) [0x55fd2925eeca]
14  /datasets/pentschev/miniconda3/envs/gdf/bin/python(_PyEval_EvalFrameDefault+0x3d99) [0x55fd2924c549]
15  /datasets/pentschev/miniconda3/envs/gdf/bin/python(+0x12a7d7) [0x55fd292477d7]
16  /datasets/pentschev/miniconda3/envs/gdf/bin/python(_PyFunction_Vectorcall+0xb9) [0x55fd29259bb9]
17  /datasets/pentschev/miniconda3/envs/gdf/bin/python(_PyEval_EvalFrameDefault+0x672) [0x55fd29248e22]
18  /datasets/pentschev/miniconda3/envs/gdf/bin/python(+0x13cec3) [0x55fd29259ec3]
19  /datasets/pentschev/miniconda3/envs/gdf/bin/python(+0x14bc75) [0x55fd29268c75]
20  /datasets/pentschev/miniconda3/envs/gdf/bin/python(+0x264071) [0x55fd29381071]
21  /datasets/pentschev/miniconda3/envs/gdf/bin/python(+0xf7187) [0x55fd29214187]
22  /datasets/pentschev/miniconda3/envs/gdf/bin/python(+0x133747) [0x55fd29250747]
23  /datasets/pentschev/miniconda3/envs/gdf/bin/python(_PyEval_EvalFrameDefault+0x5f0a) [0x55fd2924e6ba]
24  /datasets/pentschev/miniconda3/envs/gdf/bin/python(+0x13cec3) [0x55fd29259ec3]
25  /datasets/pentschev/miniconda3/envs/gdf/bin/python(_PyEval_EvalFrameDefault+0x672) [0x55fd29248e22]
26  /datasets/pentschev/miniconda3/envs/gdf/bin/python(+0x13cec3) [0x55fd29259ec3]
27  /datasets/pentschev/miniconda3/envs/gdf/bin/python(_PyEval_EvalFrameDefault+0x672) [0x55fd29248e22]
28  /datasets/pentschev/miniconda3/envs/gdf/bin/python(+0x13cec3) [0x55fd29259ec3]
29  /datasets/pentschev/miniconda3/envs/gdf/bin/python(_PyEval_EvalFrameDefault+0x672) [0x55fd29248e22]
30  /datasets/pentschev/miniconda3/envs/gdf/bin/python(+0x13cec3) [0x55fd29259ec3]
31  /datasets/pentschev/miniconda3/envs/gdf/bin/python(_PyEval_EvalFrameDefault+0x672) [0x55fd29248e22]
32  /datasets/pentschev/miniconda3/envs/gdf/bin/python(+0x12a7d7) [0x55fd292477d7]
33  /datasets/pentschev/miniconda3/envs/gdf/bin/python(_PyFunction_Vectorcall+0xb9) [0x55fd29259bb9]
34  /datasets/pentschev/miniconda3/envs/gdf/bin/python(_PyEval_EvalFrameDefault+0x4cbc) [0x55fd2924d46c]
35  /datasets/pentschev/miniconda3/envs/gdf/bin/python(+0x12a7d7) [0x55fd292477d7]
36  /datasets/pentschev/miniconda3/envs/gdf/bin/python(+0x14baf8) [0x55fd29268af8]
37  /datasets/pentschev/miniconda3/envs/gdf/bin/python(PyObject_Call+0xb4) [0x55fd29269254]
38  /datasets/pentschev/miniconda3/envs/gdf/bin/python(+0x21b8b8) [0x55fd293388b8]
39  /datasets/pentschev/miniconda3/envs/gdf/bin/python(_PyObject_MakeTpCall+0x347) [0x55fd29251a57]
40  /datasets/pentschev/miniconda3/envs/gdf/bin/python(_PyEval_EvalFrameDefault+0x3d99) [0x55fd2924c549]
41  /datasets/pentschev/miniconda3/envs/gdf/bin/python(+0x13cec3) [0x55fd29259ec3]
42  /datasets/pentschev/miniconda3/envs/gdf/bin/python(+0x14bb91) [0x55fd29268b91]
43  /datasets/pentschev/miniconda3/envs/gdf/bin/python(_PyEval_EvalFrameDefault+0x3d99) [0x55fd2924c549]
44  /datasets/pentschev/miniconda3/envs/gdf/bin/python(+0x13cec3) [0x55fd29259ec3]
45  /datasets/pentschev/miniconda3/envs/gdf/bin/python(_PyEval_EvalFrameDefault+0x672) [0x55fd29248e22]
46  /datasets/pentschev/miniconda3/envs/gdf/bin/python(+0x12a7d7) [0x55fd292477d7]
47  /datasets/pentschev/miniconda3/envs/gdf/bin/python(_PyFunction_Vectorcall+0xb9) [0x55fd29259bb9]
48  /datasets/pentschev/miniconda3/envs/gdf/bin/python(_PyEval_EvalFrameDefault+0x672) [0x55fd29248e22]
49  /datasets/pentschev/miniconda3/envs/gdf/bin/python(+0x13cec3) [0x55fd29259ec3]
50  /datasets/pentschev/miniconda3/envs/gdf/bin/python(_PyEval_EvalFrameDefault+0x3c3) [0x55fd29248b73]
51  /datasets/pentschev/miniconda3/envs/gdf/bin/python(+0x12a7d7) [0x55fd292477d7]
52  /datasets/pentschev/miniconda3/envs/gdf/bin/python(_PyFunction_Vectorcall+0xb9) [0x55fd29259bb9]
53  /datasets/pentschev/miniconda3/envs/gdf/bin/python(_PyEval_EvalFrameDefault+0x11df) [0x55fd2924998f]
54  /datasets/pentschev/miniconda3/envs/gdf/bin/python(+0x12a7d7) [0x55fd292477d7]
55  /datasets/pentschev/miniconda3/envs/gdf/bin/python(_PyEval_EvalCodeWithName+0x47) [0x55fd29247497]
56  /datasets/pentschev/miniconda3/envs/gdf/bin/python(PyEval_EvalCodeEx+0x39) [0x55fd29247449]
57  /datasets/pentschev/miniconda3/envs/gdf/bin/python(PyEval_EvalCode+0x1b) [0x55fd29301ddb]
58  /datasets/pentschev/miniconda3/envs/gdf/bin/python(+0x213409) [0x55fd29330409]
59  /datasets/pentschev/miniconda3/envs/gdf/bin/python(+0x20f5a4) [0x55fd2932c5a4]
60  /datasets/pentschev/miniconda3/envs/gdf/bin/python(PyRun_StringFlags+0x9d) [0x55fd2932427d]
61  /datasets/pentschev/miniconda3/envs/gdf/bin/python(PyRun_SimpleStringFlags+0x3d) [0x55fd2932414d]
=================================
2023-01-16 01:54:33,186 - distributed.worker - ERROR - failed during get data with ucx://127.0.0.1:42539 -> ucx://127.0.0.1:37597
Traceback (most recent call last):
  File "/datasets/pentschev/miniconda3/envs/gdf/lib/python3.9/site-packages/distributed/comm/ucx.py", line 333, in write
    await self.ep.send(each_frame)
  File "/datasets/pentschev/miniconda3/envs/gdf/lib/python3.9/site-packages/ucp/core.py", line 650, in send
    return await comm.tag_send(self._ep, buffer, nbytes, tag, name=log)
ucp._libs.exceptions.UCXError: <[Send #007] ep: 0x7f2da00ea200, tag: 0xeef6d1fc5deeb018, nbytes: 50000000, type: <class 'cupy.ndarray'>>: Connection reset by remote peer

During handling of the above exception, another exception occurred:

Traceback (most recent call last):
  File "/datasets/pentschev/miniconda3/envs/gdf/lib/python3.9/site-packages/distributed/worker.py", line 1766, in get_data
    compressed = await comm.write(msg, serializers=serializers)
  File "/datasets/pentschev/miniconda3/envs/gdf/lib/python3.9/site-packages/distributed/utils.py", line 741, in wrapper
    return await func(*args, **kwargs)
  File "/datasets/pentschev/miniconda3/envs/gdf/lib/python3.9/site-packages/distributed/comm/ucx.py", line 337, in write
    raise CommClosedError("While writing, the connection was closed")
distributed.comm.core.CommClosedError: While writing, the connection was closed
2023-01-16 01:54:33,187 - distributed.worker - ERROR - Worker stream died during communication: ucx://127.0.0.1:37597
Traceback (most recent call last):
  File "/datasets/pentschev/miniconda3/envs/gdf/lib/python3.9/site-packages/distributed/comm/ucx.py", line 349, in read
    await self.ep.recv(msg)
  File "/datasets/pentschev/miniconda3/envs/gdf/lib/python3.9/site-packages/ucp/core.py", line 725, in recv
    ret = await comm.tag_recv(self._ep, buffer, nbytes, tag, name=log)
ucp._libs.exceptions.UCXCanceled: <[Recv #003] ep: 0x7f2da00ea280, tag: 0x9986b156a5ea8669, nbytes: 16, type: <class 'numpy.ndarray'>>: 

During handling of the above exception, another exception occurred:

Traceback (most recent call last):
  File "/datasets/pentschev/miniconda3/envs/gdf/lib/python3.9/site-packages/distributed/worker.py", line 2058, in gather_dep
    response = await get_data_from_worker(
  File "/datasets/pentschev/miniconda3/envs/gdf/lib/python3.9/site-packages/distributed/worker.py", line 2870, in get_data_from_worker
    return await retry_operation(_get_data, operation="get_data_from_worker")
  File "/datasets/pentschev/miniconda3/envs/gdf/lib/python3.9/site-packages/distributed/utils_comm.py", line 402, in retry_operation
    return await retry(
  File "/datasets/pentschev/miniconda3/envs/gdf/lib/python3.9/site-packages/distributed/utils_comm.py", line 387, in retry
    return await coro()
  File "/datasets/pentschev/miniconda3/envs/gdf/lib/python3.9/site-packages/distributed/worker.py", line 2850, in _get_data
    response = await send_recv(
  File "/datasets/pentschev/miniconda3/envs/gdf/lib/python3.9/site-packages/distributed/core.py", line 986, in send_recv
    response = await comm.read(deserializers=deserializers)
  File "/datasets/pentschev/miniconda3/envs/gdf/lib/python3.9/site-packages/distributed/utils.py", line 741, in wrapper
    return await func(*args, **kwargs)
  File "/datasets/pentschev/miniconda3/envs/gdf/lib/python3.9/site-packages/distributed/comm/ucx.py", line 367, in read
    raise CommClosedError(
distributed.comm.core.CommClosedError: Connection closed by writer.
Inner exception: UCXCanceled("<[Recv #003] ep: 0x7f2da00ea280, tag: 0x9986b156a5ea8669, nbytes: 16, type: <class 'numpy.ndarray'>>: ")
2023-01-16 01:54:33,205 - distributed.nanny - WARNING - Restarting worker
2023-01-16 01:54:35,566 - distributed.preloading - INFO - Creating preload: dask_cuda.initialize
2023-01-16 01:54:35,566 - distributed.preloading - INFO - Creating preload: dask_cuda.initialize
2023-01-16 01:54:35,566 - distributed.preloading - INFO - Import preload module: dask_cuda.initialize
2023-01-16 01:54:35,566 - distributed.preloading - INFO - Import preload module: dask_cuda.initialize
2023-01-16 01:54:35,567 - distributed.preloading - INFO - Creating preload: dask_cuda.initialize
2023-01-16 01:54:35,567 - distributed.preloading - INFO - Import preload module: dask_cuda.initialize
2023-01-16 01:55:03,010 - distributed.worker - ERROR - Worker stream died during communication: ucx://127.0.0.1:37597
Traceback (most recent call last):
  File "/datasets/pentschev/miniconda3/envs/gdf/lib/python3.9/site-packages/distributed/comm/ucx.py", line 466, in connect
    ep = await ucp.create_endpoint(ip, port)
  File "/datasets/pentschev/miniconda3/envs/gdf/lib/python3.9/site-packages/ucp/core.py", line 1004, in create_endpoint
    return await _get_ctx().create_endpoint(
  File "/datasets/pentschev/miniconda3/envs/gdf/lib/python3.9/site-packages/ucp/core.py", line 316, in create_endpoint
    peer_info = await exchange_peer_info(
  File "/datasets/pentschev/miniconda3/envs/gdf/lib/python3.9/site-packages/ucp/core.py", line 54, in exchange_peer_info
    await comm.stream_recv(endpoint, peer_info_arr, peer_info_arr.nbytes)
asyncio.exceptions.CancelledError

During handling of the above exception, another exception occurred:

Traceback (most recent call last):
  File "/datasets/pentschev/miniconda3/envs/gdf/lib/python3.9/asyncio/tasks.py", line 490, in wait_for
    return fut.result()
asyncio.exceptions.CancelledError

The above exception was the direct cause of the following exception:

Traceback (most recent call last):
  File "/datasets/pentschev/miniconda3/envs/gdf/lib/python3.9/site-packages/distributed/comm/core.py", line 291, in connect
    comm = await asyncio.wait_for(
  File "/datasets/pentschev/miniconda3/envs/gdf/lib/python3.9/asyncio/tasks.py", line 492, in wait_for
    raise exceptions.TimeoutError() from exc
asyncio.exceptions.TimeoutError

The above exception was the direct cause of the following exception:

Traceback (most recent call last):
  File "/datasets/pentschev/miniconda3/envs/gdf/lib/python3.9/site-packages/distributed/worker.py", line 2058, in gather_dep
    response = await get_data_from_worker(
  File "/datasets/pentschev/miniconda3/envs/gdf/lib/python3.9/site-packages/distributed/worker.py", line 2870, in get_data_from_worker
    return await retry_operation(_get_data, operation="get_data_from_worker")
  File "/datasets/pentschev/miniconda3/envs/gdf/lib/python3.9/site-packages/distributed/utils_comm.py", line 402, in retry_operation
    return await retry(
  File "/datasets/pentschev/miniconda3/envs/gdf/lib/python3.9/site-packages/distributed/utils_comm.py", line 387, in retry
    return await coro()
  File "/datasets/pentschev/miniconda3/envs/gdf/lib/python3.9/site-packages/distributed/worker.py", line 2847, in _get_data
    comm = await rpc.connect(worker)
  File "/datasets/pentschev/miniconda3/envs/gdf/lib/python3.9/site-packages/distributed/core.py", line 1439, in connect
    return await connect_attempt
  File "/datasets/pentschev/miniconda3/envs/gdf/lib/python3.9/site-packages/distributed/core.py", line 1375, in _connect
    comm = await connect(
  File "/datasets/pentschev/miniconda3/envs/gdf/lib/python3.9/site-packages/distributed/comm/core.py", line 317, in connect
    raise OSError(
OSError: Timed out trying to connect to ucx://127.0.0.1:37597 after 30 s
/datasets/pentschev/miniconda3/envs/gdf/lib/python3.9/multiprocessing/resource_tracker.py:216: UserWarning: resource_tracker: There appear to be 48 leaked semaphore objects to clean up at shutdown
  warnings.warn('resource_tracker: There appear to be %d '
