[dgx13:83477:0:83477] Caught signal 11 (Segmentation fault: address not mapped to object at address 0x448)
==== backtrace (tid:  83477) ====
 0  /opt/conda/envs/gdf/lib/libucs.so.0(ucs_handle_error+0x2fd) [0x7f6950c9bf1d]
 1  /opt/conda/envs/gdf/lib/libucs.so.0(+0x29114) [0x7f6950c9c114]
 2  /opt/conda/envs/gdf/lib/libucs.so.0(+0x292da) [0x7f6950c9c2da]
 3  /usr/lib/x86_64-linux-gnu/libpthread.so.0(+0x14420) [0x7f69f22ba420]
 4  /opt/conda/envs/gdf/lib/libucp.so.0(ucp_mem_type_unpack+0x14) [0x7f6950d155d4]
 5  /opt/conda/envs/gdf/lib/libucp.so.0(ucp_rndv_data_handler+0x4e9) [0x7f6950d3a859]
 6  /opt/conda/envs/gdf/lib/libuct.so.0(+0x2042f) [0x7f6950c5742f]
 7  /opt/conda/envs/gdf/lib/libuct.so.0(+0x23798) [0x7f6950c5a798]
 8  /opt/conda/envs/gdf/lib/libucs.so.0(ucs_event_set_wait+0xb9) [0x7f6950ca4989]
 9  /opt/conda/envs/gdf/lib/libuct.so.0(uct_tcp_iface_progress+0x7d) [0x7f6950c5962d]
10  /opt/conda/envs/gdf/lib/libucp.so.0(ucp_worker_progress+0x5a) [0x7f6950d12c4a]
11  /opt/conda/envs/gdf/lib/python3.9/site-packages/ucp/_libs/ucx_api.cpython-39-x86_64-linux-gnu.so(+0x3206a) [0x7f6950dc406a]
12  /opt/conda/envs/gdf/bin/python(_PyEval_EvalFrameDefault+0x45a6) [0x557aa72a93f6]
13  /opt/conda/envs/gdf/bin/python(+0x12dfb4) [0x557aa72a3fb4]
14  /opt/conda/envs/gdf/bin/python(_PyFunction_Vectorcall+0xd9) [0x557aa72b5469]
15  /opt/conda/envs/gdf/bin/python(_PyEval_EvalFrameDefault+0x696) [0x557aa72a54e6]
16  /opt/conda/envs/gdf/bin/python(+0x13f712) [0x557aa72b5712]
17  /opt/conda/envs/gdf/bin/python(+0x14ca83) [0x557aa72c2a83]
18  /opt/conda/envs/gdf/bin/python(+0x25819c) [0x557aa73ce19c]
19  /opt/conda/envs/gdf/bin/python(+0xf23ff) [0x557aa72683ff]
20  /opt/conda/envs/gdf/bin/python(+0x136723) [0x557aa72ac723]
21  /opt/conda/envs/gdf/bin/python(_PyEval_EvalFrameDefault+0x5ad9) [0x557aa72aa929]
22  /opt/conda/envs/gdf/bin/python(+0x13f712) [0x557aa72b5712]
23  /opt/conda/envs/gdf/bin/python(_PyEval_EvalFrameDefault+0x696) [0x557aa72a54e6]
24  /opt/conda/envs/gdf/bin/python(+0x13f712) [0x557aa72b5712]
25  /opt/conda/envs/gdf/bin/python(_PyEval_EvalFrameDefault+0x696) [0x557aa72a54e6]
26  /opt/conda/envs/gdf/bin/python(+0x13f712) [0x557aa72b5712]
27  /opt/conda/envs/gdf/bin/python(_PyEval_EvalFrameDefault+0x696) [0x557aa72a54e6]
28  /opt/conda/envs/gdf/bin/python(+0x13f712) [0x557aa72b5712]
29  /opt/conda/envs/gdf/bin/python(_PyEval_EvalFrameDefault+0x696) [0x557aa72a54e6]
30  /opt/conda/envs/gdf/bin/python(+0x12dfb4) [0x557aa72a3fb4]
31  /opt/conda/envs/gdf/bin/python(_PyFunction_Vectorcall+0xd9) [0x557aa72b5469]
32  /opt/conda/envs/gdf/bin/python(_PyEval_EvalFrameDefault+0x11f2) [0x557aa72a6042]
33  /opt/conda/envs/gdf/bin/python(+0x12dfb4) [0x557aa72a3fb4]
34  /opt/conda/envs/gdf/bin/python(+0x14c8cb) [0x557aa72c28cb]
35  /opt/conda/envs/gdf/bin/python(PyObject_Call+0xbc) [0x557aa72c304c]
36  /opt/conda/envs/gdf/bin/python(+0x21080e) [0x557aa738680e]
37  /opt/conda/envs/gdf/bin/python(_PyObject_MakeTpCall+0x2ec) [0x557aa72ad6ac]
38  /opt/conda/envs/gdf/bin/python(_PyEval_EvalFrameDefault+0x45a6) [0x557aa72a93f6]
39  /opt/conda/envs/gdf/bin/python(+0x13f712) [0x557aa72b5712]
40  /opt/conda/envs/gdf/bin/python(+0x14c9ac) [0x557aa72c29ac]
41  /opt/conda/envs/gdf/bin/python(_PyEval_EvalFrameDefault+0x45a6) [0x557aa72a93f6]
42  /opt/conda/envs/gdf/bin/python(+0x13f712) [0x557aa72b5712]
43  /opt/conda/envs/gdf/bin/python(_PyEval_EvalFrameDefault+0x696) [0x557aa72a54e6]
44  /opt/conda/envs/gdf/bin/python(+0x12dfb4) [0x557aa72a3fb4]
45  /opt/conda/envs/gdf/bin/python(_PyFunction_Vectorcall+0xd9) [0x557aa72b5469]
46  /opt/conda/envs/gdf/bin/python(_PyEval_EvalFrameDefault+0x696) [0x557aa72a54e6]
47  /opt/conda/envs/gdf/bin/python(+0x13f712) [0x557aa72b5712]
48  /opt/conda/envs/gdf/bin/python(_PyEval_EvalFrameDefault+0x3e2) [0x557aa72a5232]
49  /opt/conda/envs/gdf/bin/python(+0x12dfb4) [0x557aa72a3fb4]
50  /opt/conda/envs/gdf/bin/python(_PyFunction_Vectorcall+0xd9) [0x557aa72b5469]
51  /opt/conda/envs/gdf/bin/python(_PyEval_EvalFrameDefault+0x11f2) [0x557aa72a6042]
52  /opt/conda/envs/gdf/bin/python(+0x12dfb4) [0x557aa72a3fb4]
53  /opt/conda/envs/gdf/bin/python(_PyEval_EvalCodeWithName+0x48) [0x557aa72a3c88]
54  /opt/conda/envs/gdf/bin/python(PyEval_EvalCodeEx+0x39) [0x557aa72a3c39]
55  /opt/conda/envs/gdf/bin/python(PyEval_EvalCode+0x1b) [0x557aa73512cb]
56  /opt/conda/envs/gdf/bin/python(+0x2086ca) [0x557aa737e6ca]
57  /opt/conda/envs/gdf/bin/python(+0x204a63) [0x557aa737aa63]
58  /opt/conda/envs/gdf/bin/python(PyRun_StringFlags+0x9a) [0x557aa737287a]
59  /opt/conda/envs/gdf/bin/python(PyRun_SimpleStringFlags+0x3c) [0x557aa737276c]
60  /opt/conda/envs/gdf/bin/python(Py_RunMain+0x267) [0x557aa73719a7]
61  /opt/conda/envs/gdf/bin/python(Py_BytesMain+0x37) [0x557aa7345107]
=================================
[dgx13:83488:0:83488] Caught signal 11 (Segmentation fault: address not mapped to object at address 0x448)
==== backtrace (tid:  83488) ====
 0  /opt/conda/envs/gdf/lib/libucs.so.0(ucs_handle_error+0x2fd) [0x7fef6f708f1d]
 1  /opt/conda/envs/gdf/lib/libucs.so.0(+0x29114) [0x7fef6f709114]
 2  /opt/conda/envs/gdf/lib/libucs.so.0(+0x292da) [0x7fef6f7092da]
 3  /usr/lib/x86_64-linux-gnu/libpthread.so.0(+0x14420) [0x7ff020d95420]
 4  /opt/conda/envs/gdf/lib/libucp.so.0(ucp_mem_type_unpack+0x14) [0x7fef6f7825d4]
 5  /opt/conda/envs/gdf/lib/libucp.so.0(ucp_rndv_data_handler+0x4e9) [0x7fef6f7a7859]
 6  /opt/conda/envs/gdf/lib/libuct.so.0(+0x2042f) [0x7fef8002e42f]
 7  /opt/conda/envs/gdf/lib/libuct.so.0(+0x23798) [0x7fef80031798]
 8  /opt/conda/envs/gdf/lib/libucs.so.0(ucs_event_set_wait+0xb9) [0x7fef6f711989]
 9  /opt/conda/envs/gdf/lib/libuct.so.0(uct_tcp_iface_progress+0x7d) [0x7fef8003062d]
10  /opt/conda/envs/gdf/lib/libucp.so.0(ucp_worker_progress+0x5a) [0x7fef6f77fc4a]
11  /opt/conda/envs/gdf/lib/python3.9/site-packages/ucp/_libs/ucx_api.cpython-39-x86_64-linux-gnu.so(+0x3206a) [0x7fef8007c06a]
12  /opt/conda/envs/gdf/bin/python(_PyEval_EvalFrameDefault+0x45a6) [0x5613eaa4c3f6]
13  /opt/conda/envs/gdf/bin/python(+0x12dfb4) [0x5613eaa46fb4]
14  /opt/conda/envs/gdf/bin/python(_PyFunction_Vectorcall+0xd9) [0x5613eaa58469]
15  /opt/conda/envs/gdf/bin/python(_PyEval_EvalFrameDefault+0x696) [0x5613eaa484e6]
16  /opt/conda/envs/gdf/bin/python(+0x1e26d2) [0x5613eaafb6d2]
17  /opt/conda/envs/gdf/lib/python3.9/lib-dynload/_asyncio.cpython-39-x86_64-linux-gnu.so(+0x81e9) [0x7ff016d851e9]
18  /opt/conda/envs/gdf/bin/python(_PyObject_MakeTpCall+0x2ec) [0x5613eaa506ac]
19  /opt/conda/envs/gdf/bin/python(+0xf23ff) [0x5613eaa0b3ff]
20  /opt/conda/envs/gdf/bin/python(+0x136723) [0x5613eaa4f723]
21  /opt/conda/envs/gdf/bin/python(_PyEval_EvalFrameDefault+0x5ad9) [0x5613eaa4d929]
22  /opt/conda/envs/gdf/bin/python(+0x13f712) [0x5613eaa58712]
23  /opt/conda/envs/gdf/bin/python(_PyEval_EvalFrameDefault+0x696) [0x5613eaa484e6]
24  /opt/conda/envs/gdf/bin/python(+0x13f712) [0x5613eaa58712]
25  /opt/conda/envs/gdf/bin/python(_PyEval_EvalFrameDefault+0x696) [0x5613eaa484e6]
26  /opt/conda/envs/gdf/bin/python(+0x13f712) [0x5613eaa58712]
27  /opt/conda/envs/gdf/bin/python(_PyEval_EvalFrameDefault+0x696) [0x5613eaa484e6]
28  /opt/conda/envs/gdf/bin/python(+0x13f712) [0x5613eaa58712]
29  /opt/conda/envs/gdf/bin/python(_PyEval_EvalFrameDefault+0x696) [0x5613eaa484e6]
30  /opt/conda/envs/gdf/bin/python(+0x12dfb4) [0x5613eaa46fb4]
31  /opt/conda/envs/gdf/bin/python(_PyFunction_Vectorcall+0xd9) [0x5613eaa58469]
32  /opt/conda/envs/gdf/bin/python(_PyEval_EvalFrameDefault+0x11f2) [0x5613eaa49042]
33  /opt/conda/envs/gdf/bin/python(+0x12dfb4) [0x5613eaa46fb4]
34  /opt/conda/envs/gdf/bin/python(+0x14c8cb) [0x5613eaa658cb]
35  /opt/conda/envs/gdf/bin/python(PyObject_Call+0xbc) [0x5613eaa6604c]
36  /opt/conda/envs/gdf/bin/python(+0x21080e) [0x5613eab2980e]
37  /opt/conda/envs/gdf/bin/python(_PyObject_MakeTpCall+0x2ec) [0x5613eaa506ac]
38  /opt/conda/envs/gdf/bin/python(_PyEval_EvalFrameDefault+0x45a6) [0x5613eaa4c3f6]
39  /opt/conda/envs/gdf/bin/python(+0x13f712) [0x5613eaa58712]
40  /opt/conda/envs/gdf/bin/python(+0x14c9ac) [0x5613eaa659ac]
41  /opt/conda/envs/gdf/bin/python(_PyEval_EvalFrameDefault+0x45a6) [0x5613eaa4c3f6]
42  /opt/conda/envs/gdf/bin/python(+0x13f712) [0x5613eaa58712]
43  /opt/conda/envs/gdf/bin/python(_PyEval_EvalFrameDefault+0x696) [0x5613eaa484e6]
44  /opt/conda/envs/gdf/bin/python(+0x12dfb4) [0x5613eaa46fb4]
45  /opt/conda/envs/gdf/bin/python(_PyFunction_Vectorcall+0xd9) [0x5613eaa58469]
46  /opt/conda/envs/gdf/bin/python(_PyEval_EvalFrameDefault+0x696) [0x5613eaa484e6]
47  /opt/conda/envs/gdf/bin/python(+0x13f712) [0x5613eaa58712]
48  /opt/conda/envs/gdf/bin/python(_PyEval_EvalFrameDefault+0x3e2) [0x5613eaa48232]
49  /opt/conda/envs/gdf/bin/python(+0x12dfb4) [0x5613eaa46fb4]
50  /opt/conda/envs/gdf/bin/python(_PyFunction_Vectorcall+0xd9) [0x5613eaa58469]
51  /opt/conda/envs/gdf/bin/python(_PyEval_EvalFrameDefault+0x11f2) [0x5613eaa49042]
52  /opt/conda/envs/gdf/bin/python(+0x12dfb4) [0x5613eaa46fb4]
53  /opt/conda/envs/gdf/bin/python(_PyEval_EvalCodeWithName+0x48) [0x5613eaa46c88]
54  /opt/conda/envs/gdf/bin/python(PyEval_EvalCodeEx+0x39) [0x5613eaa46c39]
55  /opt/conda/envs/gdf/bin/python(PyEval_EvalCode+0x1b) [0x5613eaaf42cb]
56  /opt/conda/envs/gdf/bin/python(+0x2086ca) [0x5613eab216ca]
57  /opt/conda/envs/gdf/bin/python(+0x204a63) [0x5613eab1da63]
58  /opt/conda/envs/gdf/bin/python(PyRun_StringFlags+0x9a) [0x5613eab1587a]
59  /opt/conda/envs/gdf/bin/python(PyRun_SimpleStringFlags+0x3c) [0x5613eab1576c]
60  /opt/conda/envs/gdf/bin/python(Py_RunMain+0x267) [0x5613eab149a7]
61  /opt/conda/envs/gdf/bin/python(Py_BytesMain+0x37) [0x5613eaae8107]
=================================
[dgx13:83486:0:83486] Caught signal 11 (Segmentation fault: address not mapped to object at address 0x448)
==== backtrace (tid:  83486) ====
 0  /opt/conda/envs/gdf/lib/libucs.so.0(ucs_handle_error+0x2fd) [0x7fa2ff212f1d]
 1  /opt/conda/envs/gdf/lib/libucs.so.0(+0x29114) [0x7fa2ff213114]
 2  /opt/conda/envs/gdf/lib/libucs.so.0(+0x292da) [0x7fa2ff2132da]
 3  /usr/lib/x86_64-linux-gnu/libpthread.so.0(+0x14420) [0x7fa3b08c9420]
 4  /opt/conda/envs/gdf/lib/libucp.so.0(ucp_mem_type_unpack+0x14) [0x7fa2ff28c5d4]
 5  /opt/conda/envs/gdf/lib/libucp.so.0(ucp_rndv_data_handler+0x4e9) [0x7fa2ff2b1859]
 6  /opt/conda/envs/gdf/lib/libuct.so.0(+0x2042f) [0x7fa2ff1ce42f]
 7  /opt/conda/envs/gdf/lib/libuct.so.0(+0x23798) [0x7fa2ff1d1798]
 8  /opt/conda/envs/gdf/lib/libucs.so.0(ucs_event_set_wait+0xb9) [0x7fa2ff21b989]
 9  /opt/conda/envs/gdf/lib/libuct.so.0(uct_tcp_iface_progress+0x7d) [0x7fa2ff1d062d]
10  /opt/conda/envs/gdf/lib/libucp.so.0(ucp_worker_progress+0x5a) [0x7fa2ff289c4a]
11  /opt/conda/envs/gdf/lib/python3.9/site-packages/ucp/_libs/ucx_api.cpython-39-x86_64-linux-gnu.so(+0x3206a) [0x7fa2ff33b06a]
12  /opt/conda/envs/gdf/bin/python(_PyEval_EvalFrameDefault+0x45a6) [0x564633b8a3f6]
13  /opt/conda/envs/gdf/bin/python(+0x12dfb4) [0x564633b84fb4]
14  /opt/conda/envs/gdf/bin/python(_PyFunction_Vectorcall+0xd9) [0x564633b96469]
15  /opt/conda/envs/gdf/bin/python(_PyEval_EvalFrameDefault+0x696) [0x564633b864e6]
16  /opt/conda/envs/gdf/bin/python(+0x1e26d2) [0x564633c396d2]
17  /opt/conda/envs/gdf/lib/python3.9/lib-dynload/_asyncio.cpython-39-x86_64-linux-gnu.so(+0x81e9) [0x7fa3a689f1e9]
18  /opt/conda/envs/gdf/bin/python(_PyObject_MakeTpCall+0x2ec) [0x564633b8e6ac]
19  /opt/conda/envs/gdf/bin/python(+0xf23ff) [0x564633b493ff]
20  /opt/conda/envs/gdf/bin/python(+0x136723) [0x564633b8d723]
21  /opt/conda/envs/gdf/bin/python(_PyEval_EvalFrameDefault+0x5ad9) [0x564633b8b929]
22  /opt/conda/envs/gdf/bin/python(+0x13f712) [0x564633b96712]
23  /opt/conda/envs/gdf/bin/python(_PyEval_EvalFrameDefault+0x696) [0x564633b864e6]
24  /opt/conda/envs/gdf/bin/python(+0x13f712) [0x564633b96712]
25  /opt/conda/envs/gdf/bin/python(_PyEval_EvalFrameDefault+0x696) [0x564633b864e6]
26  /opt/conda/envs/gdf/bin/python(+0x13f712) [0x564633b96712]
27  /opt/conda/envs/gdf/bin/python(_PyEval_EvalFrameDefault+0x696) [0x564633b864e6]
28  /opt/conda/envs/gdf/bin/python(+0x13f712) [0x564633b96712]
29  /opt/conda/envs/gdf/bin/python(_PyEval_EvalFrameDefault+0x696) [0x564633b864e6]
30  /opt/conda/envs/gdf/bin/python(+0x12dfb4) [0x564633b84fb4]
31  /opt/conda/envs/gdf/bin/python(_PyFunction_Vectorcall+0xd9) [0x564633b96469]
32  /opt/conda/envs/gdf/bin/python(_PyEval_EvalFrameDefault+0x11f2) [0x564633b87042]
33  /opt/conda/envs/gdf/bin/python(+0x12dfb4) [0x564633b84fb4]
34  /opt/conda/envs/gdf/bin/python(+0x14c8cb) [0x564633ba38cb]
35  /opt/conda/envs/gdf/bin/python(PyObject_Call+0xbc) [0x564633ba404c]
36  /opt/conda/envs/gdf/bin/python(+0x21080e) [0x564633c6780e]
37  /opt/conda/envs/gdf/bin/python(_PyObject_MakeTpCall+0x2ec) [0x564633b8e6ac]
38  /opt/conda/envs/gdf/bin/python(_PyEval_EvalFrameDefault+0x45a6) [0x564633b8a3f6]
39  /opt/conda/envs/gdf/bin/python(+0x13f712) [0x564633b96712]
40  /opt/conda/envs/gdf/bin/python(+0x14c9ac) [0x564633ba39ac]
41  /opt/conda/envs/gdf/bin/python(_PyEval_EvalFrameDefault+0x45a6) [0x564633b8a3f6]
42  /opt/conda/envs/gdf/bin/python(+0x13f712) [0x564633b96712]
43  /opt/conda/envs/gdf/bin/python(_PyEval_EvalFrameDefault+0x696) [0x564633b864e6]
44  /opt/conda/envs/gdf/bin/python(+0x12dfb4) [0x564633b84fb4]
45  /opt/conda/envs/gdf/bin/python(_PyFunction_Vectorcall+0xd9) [0x564633b96469]
46  /opt/conda/envs/gdf/bin/python(_PyEval_EvalFrameDefault+0x696) [0x564633b864e6]
47  /opt/conda/envs/gdf/bin/python(+0x13f712) [0x564633b96712]
48  /opt/conda/envs/gdf/bin/python(_PyEval_EvalFrameDefault+0x3e2) [0x564633b86232]
49  /opt/conda/envs/gdf/bin/python(+0x12dfb4) [0x564633b84fb4]
50  /opt/conda/envs/gdf/bin/python(_PyFunction_Vectorcall+0xd9) [0x564633b96469]
51  /opt/conda/envs/gdf/bin/python(_PyEval_EvalFrameDefault+0x11f2) [0x564633b87042]
52  /opt/conda/envs/gdf/bin/python(+0x12dfb4) [0x564633b84fb4]
53  /opt/conda/envs/gdf/bin/python(_PyEval_EvalCodeWithName+0x48) [0x564633b84c88]
54  /opt/conda/envs/gdf/bin/python(PyEval_EvalCodeEx+0x39) [0x564633b84c39]
55  /opt/conda/envs/gdf/bin/python(PyEval_EvalCode+0x1b) [0x564633c322cb]
56  /opt/conda/envs/gdf/bin/python(+0x2086ca) [0x564633c5f6ca]
57  /opt/conda/envs/gdf/bin/python(+0x204a63) [0x564633c5ba63]
58  /opt/conda/envs/gdf/bin/python(PyRun_StringFlags+0x9a) [0x564633c5387a]
59  /opt/conda/envs/gdf/bin/python(PyRun_SimpleStringFlags+0x3c) [0x564633c5376c]
60  /opt/conda/envs/gdf/bin/python(Py_RunMain+0x267) [0x564633c529a7]
61  /opt/conda/envs/gdf/bin/python(Py_BytesMain+0x37) [0x564633c26107]
=================================
[dgx13:83483:0:83483] Caught signal 11 (Segmentation fault: address not mapped to object at address 0x448)
==== backtrace (tid:  83483) ====
 0  /opt/conda/envs/gdf/lib/libucs.so.0(ucs_handle_error+0x2fd) [0x7f588d6fbf1d]
 1  /opt/conda/envs/gdf/lib/libucs.so.0(+0x29114) [0x7f588d6fc114]
 2  /opt/conda/envs/gdf/lib/libucs.so.0(+0x292da) [0x7f588d6fc2da]
 3  /usr/lib/x86_64-linux-gnu/libpthread.so.0(+0x14420) [0x7f5932d23420]
 4  /opt/conda/envs/gdf/lib/libucp.so.0(ucp_mem_type_unpack+0x14) [0x7f588d7755d4]
 5  /opt/conda/envs/gdf/lib/libucp.so.0(ucp_rndv_data_handler+0x4e9) [0x7f588d79a859]
 6  /opt/conda/envs/gdf/lib/libuct.so.0(+0x2042f) [0x7f588d6b742f]
 7  /opt/conda/envs/gdf/lib/libuct.so.0(+0x23798) [0x7f588d6ba798]
 8  /opt/conda/envs/gdf/lib/libucs.so.0(ucs_event_set_wait+0xb9) [0x7f588d704989]
 9  /opt/conda/envs/gdf/lib/libuct.so.0(uct_tcp_iface_progress+0x7d) [0x7f588d6b962d]
10  /opt/conda/envs/gdf/lib/libucp.so.0(ucp_worker_progress+0x5a) [0x7f588d772c4a]
11  /opt/conda/envs/gdf/lib/python3.9/site-packages/ucp/_libs/ucx_api.cpython-39-x86_64-linux-gnu.so(+0x3206a) [0x7f588d82406a]
12  /opt/conda/envs/gdf/bin/python(_PyEval_EvalFrameDefault+0x45a6) [0x55790a5ce3f6]
13  /opt/conda/envs/gdf/bin/python(+0x12dfb4) [0x55790a5c8fb4]
14  /opt/conda/envs/gdf/bin/python(_PyFunction_Vectorcall+0xd9) [0x55790a5da469]
15  /opt/conda/envs/gdf/bin/python(_PyEval_EvalFrameDefault+0x696) [0x55790a5ca4e6]
16  /opt/conda/envs/gdf/bin/python(+0x13f712) [0x55790a5da712]
17  /opt/conda/envs/gdf/bin/python(+0x14ca83) [0x55790a5e7a83]
18  /opt/conda/envs/gdf/bin/python(+0x25819c) [0x55790a6f319c]
19  /opt/conda/envs/gdf/bin/python(+0xf23ff) [0x55790a58d3ff]
20  /opt/conda/envs/gdf/bin/python(+0x136723) [0x55790a5d1723]
21  /opt/conda/envs/gdf/bin/python(_PyEval_EvalFrameDefault+0x5ad9) [0x55790a5cf929]
22  /opt/conda/envs/gdf/bin/python(+0x13f712) [0x55790a5da712]
23  /opt/conda/envs/gdf/bin/python(_PyEval_EvalFrameDefault+0x696) [0x55790a5ca4e6]
24  /opt/conda/envs/gdf/bin/python(+0x13f712) [0x55790a5da712]
25  /opt/conda/envs/gdf/bin/python(_PyEval_EvalFrameDefault+0x696) [0x55790a5ca4e6]
26  /opt/conda/envs/gdf/bin/python(+0x13f712) [0x55790a5da712]
27  /opt/conda/envs/gdf/bin/python(_PyEval_EvalFrameDefault+0x696) [0x55790a5ca4e6]
28  /opt/conda/envs/gdf/bin/python(+0x13f712) [0x55790a5da712]
29  /opt/conda/envs/gdf/bin/python(_PyEval_EvalFrameDefault+0x696) [0x55790a5ca4e6]
30  /opt/conda/envs/gdf/bin/python(+0x12dfb4) [0x55790a5c8fb4]
31  /opt/conda/envs/gdf/bin/python(_PyFunction_Vectorcall+0xd9) [0x55790a5da469]
32  /opt/conda/envs/gdf/bin/python(_PyEval_EvalFrameDefault+0x11f2) [0x55790a5cb042]
33  /opt/conda/envs/gdf/bin/python(+0x12dfb4) [0x55790a5c8fb4]
34  /opt/conda/envs/gdf/bin/python(+0x14c8cb) [0x55790a5e78cb]
35  /opt/conda/envs/gdf/bin/python(PyObject_Call+0xbc) [0x55790a5e804c]
36  /opt/conda/envs/gdf/bin/python(+0x21080e) [0x55790a6ab80e]
37  /opt/conda/envs/gdf/bin/python(_PyObject_MakeTpCall+0x2ec) [0x55790a5d26ac]
38  /opt/conda/envs/gdf/bin/python(_PyEval_EvalFrameDefault+0x45a6) [0x55790a5ce3f6]
39  /opt/conda/envs/gdf/bin/python(+0x13f712) [0x55790a5da712]
40  /opt/conda/envs/gdf/bin/python(+0x14c9ac) [0x55790a5e79ac]
41  /opt/conda/envs/gdf/bin/python(_PyEval_EvalFrameDefault+0x45a6) [0x55790a5ce3f6]
42  /opt/conda/envs/gdf/bin/python(+0x13f712) [0x55790a5da712]
43  /opt/conda/envs/gdf/bin/python(_PyEval_EvalFrameDefault+0x696) [0x55790a5ca4e6]
44  /opt/conda/envs/gdf/bin/python(+0x12dfb4) [0x55790a5c8fb4]
45  /opt/conda/envs/gdf/bin/python(_PyFunction_Vectorcall+0xd9) [0x55790a5da469]
46  /opt/conda/envs/gdf/bin/python(_PyEval_EvalFrameDefault+0x696) [0x55790a5ca4e6]
47  /opt/conda/envs/gdf/bin/python(+0x13f712) [0x55790a5da712]
48  /opt/conda/envs/gdf/bin/python(_PyEval_EvalFrameDefault+0x3e2) [0x55790a5ca232]
49  /opt/conda/envs/gdf/bin/python(+0x12dfb4) [0x55790a5c8fb4]
50  /opt/conda/envs/gdf/bin/python(_PyFunction_Vectorcall+0xd9) [0x55790a5da469]
51  /opt/conda/envs/gdf/bin/python(_PyEval_EvalFrameDefault+0x11f2) [0x55790a5cb042]
52  /opt/conda/envs/gdf/bin/python(+0x12dfb4) [0x55790a5c8fb4]
53  /opt/conda/envs/gdf/bin/python(_PyEval_EvalCodeWithName+0x48) [0x55790a5c8c88]
54  /opt/conda/envs/gdf/bin/python(PyEval_EvalCodeEx+0x39) [0x55790a5c8c39]
55  /opt/conda/envs/gdf/bin/python(PyEval_EvalCode+0x1b) [0x55790a6762cb]
56  /opt/conda/envs/gdf/bin/python(+0x2086ca) [0x55790a6a36ca]
57  /opt/conda/envs/gdf/bin/python(+0x204a63) [0x55790a69fa63]
58  /opt/conda/envs/gdf/bin/python(PyRun_StringFlags+0x9a) [0x55790a69787a]
59  /opt/conda/envs/gdf/bin/python(PyRun_SimpleStringFlags+0x3c) [0x55790a69776c]
60  /opt/conda/envs/gdf/bin/python(Py_RunMain+0x267) [0x55790a6969a7]
61  /opt/conda/envs/gdf/bin/python(Py_BytesMain+0x37) [0x55790a66a107]
=================================
2024-01-03 07:09:31,585 - distributed.worker - ERROR - Worker stream died during communication: ucx://127.0.0.1:49443
Traceback (most recent call last):
  File "/opt/conda/envs/gdf/lib/python3.9/site-packages/distributed/comm/ucx.py", line 354, in read
    await self.ep.recv(msg)
  File "/opt/conda/envs/gdf/lib/python3.9/site-packages/ucp/core.py", line 725, in recv
    ret = await comm.tag_recv(self._ep, buffer, nbytes, tag, name=log)
ucp._libs.exceptions.UCXCanceled: <[Recv #000] ep: 0x7f8fb0252140, tag: 0x9d732eb6e67eaf79, nbytes: 16, type: <class 'numpy.ndarray'>>: 

During handling of the above exception, another exception occurred:

Traceback (most recent call last):
  File "/opt/conda/envs/gdf/lib/python3.9/site-packages/distributed/worker.py", line 2059, in gather_dep
    response = await get_data_from_worker(
  File "/opt/conda/envs/gdf/lib/python3.9/site-packages/distributed/worker.py", line 2849, in get_data_from_worker
    comm = await rpc.connect(worker)
  File "/opt/conda/envs/gdf/lib/python3.9/site-packages/distributed/core.py", line 1626, in connect
    return connect_attempt.result()
  File "/opt/conda/envs/gdf/lib/python3.9/site-packages/distributed/core.py", line 1516, in _connect
    comm = await connect(
  File "/opt/conda/envs/gdf/lib/python3.9/site-packages/distributed/comm/core.py", line 377, in connect
    handshake = await comm.read()
  File "/opt/conda/envs/gdf/lib/python3.9/site-packages/distributed/utils.py", line 803, in wrapper
    return await func(*args, **kwargs)
  File "/opt/conda/envs/gdf/lib/python3.9/site-packages/distributed/comm/ucx.py", line 372, in read
    raise CommClosedError(
distributed.comm.core.CommClosedError: Connection closed by writer.
Inner exception: UCXCanceled("<[Recv #000] ep: 0x7f8fb0252140, tag: 0x9d732eb6e67eaf79, nbytes: 16, type: <class 'numpy.ndarray'>>: ")
2024-01-03 07:09:31,585 - distributed.worker - ERROR - Worker stream died during communication: ucx://127.0.0.1:49443
Traceback (most recent call last):
  File "/opt/conda/envs/gdf/lib/python3.9/site-packages/distributed/comm/ucx.py", line 354, in read
    await self.ep.recv(msg)
  File "/opt/conda/envs/gdf/lib/python3.9/site-packages/ucp/core.py", line 725, in recv
    ret = await comm.tag_recv(self._ep, buffer, nbytes, tag, name=log)
ucp._libs.exceptions.UCXCanceled: <[Recv #003] ep: 0x7f8c71b77100, tag: 0xb761476363052da0, nbytes: 16, type: <class 'numpy.ndarray'>>: 

During handling of the above exception, another exception occurred:

Traceback (most recent call last):
  File "/opt/conda/envs/gdf/lib/python3.9/site-packages/distributed/worker.py", line 2059, in gather_dep
    response = await get_data_from_worker(
  File "/opt/conda/envs/gdf/lib/python3.9/site-packages/distributed/worker.py", line 2852, in get_data_from_worker
    response = await send_recv(
  File "/opt/conda/envs/gdf/lib/python3.9/site-packages/distributed/core.py", line 1106, in send_recv
    response = await comm.read(deserializers=deserializers)
  File "/opt/conda/envs/gdf/lib/python3.9/site-packages/distributed/utils.py", line 803, in wrapper
    return await func(*args, **kwargs)
  File "/opt/conda/envs/gdf/lib/python3.9/site-packages/distributed/comm/ucx.py", line 372, in read
    raise CommClosedError(
distributed.comm.core.CommClosedError: Connection closed by writer.
Inner exception: UCXCanceled("<[Recv #003] ep: 0x7f8c71b77100, tag: 0xb761476363052da0, nbytes: 16, type: <class 'numpy.ndarray'>>: ")
2024-01-03 07:09:31,585 - distributed.worker - ERROR - Worker stream died during communication: ucx://127.0.0.1:49443
Traceback (most recent call last):
  File "/opt/conda/envs/gdf/lib/python3.9/site-packages/distributed/comm/ucx.py", line 354, in read
    await self.ep.recv(msg)
  File "/opt/conda/envs/gdf/lib/python3.9/site-packages/ucp/core.py", line 725, in recv
    ret = await comm.tag_recv(self._ep, buffer, nbytes, tag, name=log)
ucp._libs.exceptions.UCXCanceled: <[Recv #003] ep: 0x7fd412f521c0, tag: 0x729e53f98b67e27d, nbytes: 16, type: <class 'numpy.ndarray'>>: 

During handling of the above exception, another exception occurred:

Traceback (most recent call last):
  File "/opt/conda/envs/gdf/lib/python3.9/site-packages/distributed/worker.py", line 2059, in gather_dep
    response = await get_data_from_worker(
  File "/opt/conda/envs/gdf/lib/python3.9/site-packages/distributed/worker.py", line 2852, in get_data_from_worker
    response = await send_recv(
  File "/opt/conda/envs/gdf/lib/python3.9/site-packages/distributed/core.py", line 1106, in send_recv
    response = await comm.read(deserializers=deserializers)
  File "/opt/conda/envs/gdf/lib/python3.9/site-packages/distributed/utils.py", line 803, in wrapper
    return await func(*args, **kwargs)
  File "/opt/conda/envs/gdf/lib/python3.9/site-packages/distributed/comm/ucx.py", line 372, in read
    raise CommClosedError(
distributed.comm.core.CommClosedError: Connection closed by writer.
Inner exception: UCXCanceled("<[Recv #003] ep: 0x7fd412f521c0, tag: 0x729e53f98b67e27d, nbytes: 16, type: <class 'numpy.ndarray'>>: ")
2024-01-03 07:09:31,588 - distributed.worker - ERROR - failed during get data with ucx://127.0.0.1:53883 -> ucx://127.0.0.1:49443
Traceback (most recent call last):
  File "/opt/conda/envs/gdf/lib/python3.9/site-packages/distributed/comm/ucx.py", line 354, in read
    await self.ep.recv(msg)
  File "/opt/conda/envs/gdf/lib/python3.9/site-packages/ucp/core.py", line 725, in recv
    ret = await comm.tag_recv(self._ep, buffer, nbytes, tag, name=log)
ucp._libs.exceptions.UCXCanceled: <[Recv #006] ep: 0x7fd412f52100, tag: 0x9a910f4e4dce4279, nbytes: 16, type: <class 'numpy.ndarray'>>: 

During handling of the above exception, another exception occurred:

Traceback (most recent call last):
  File "/opt/conda/envs/gdf/lib/python3.9/site-packages/distributed/worker.py", line 1783, in get_data
    response = await comm.read(deserializers=serializers)
  File "/opt/conda/envs/gdf/lib/python3.9/site-packages/distributed/utils.py", line 803, in wrapper
    return await func(*args, **kwargs)
  File "/opt/conda/envs/gdf/lib/python3.9/site-packages/distributed/comm/ucx.py", line 372, in read
    raise CommClosedError(
distributed.comm.core.CommClosedError: Connection closed by writer.
Inner exception: UCXCanceled("<[Recv #006] ep: 0x7fd412f52100, tag: 0x9a910f4e4dce4279, nbytes: 16, type: <class 'numpy.ndarray'>>: ")
Task exception was never retrieved
future: <Task finished name='Task-304' coro=<_listener_handler_coroutine() done, defined at /opt/conda/envs/gdf/lib/python3.9/site-packages/ucp/core.py:128> exception=UCXError('<stream_recv>: Connection reset by remote peer')>
Traceback (most recent call last):
  File "/opt/conda/envs/gdf/lib/python3.9/site-packages/ucp/core.py", line 143, in _listener_handler_coroutine
    peer_info = await exchange_peer_info(
  File "/opt/conda/envs/gdf/lib/python3.9/site-packages/ucp/core.py", line 52, in exchange_peer_info
    await comm.stream_recv(endpoint, peer_info_arr, peer_info_arr.nbytes)
ucp._libs.exceptions.UCXError: <stream_recv>: Connection reset by remote peer
2024-01-03 07:09:31,589 - distributed.worker - ERROR - Worker stream died during communication: ucx://127.0.0.1:42405
Traceback (most recent call last):
  File "/opt/conda/envs/gdf/lib/python3.9/site-packages/distributed/comm/ucx.py", line 354, in read
    await self.ep.recv(msg)
  File "/opt/conda/envs/gdf/lib/python3.9/site-packages/ucp/core.py", line 725, in recv
    ret = await comm.tag_recv(self._ep, buffer, nbytes, tag, name=log)
ucp._libs.exceptions.UCXCanceled: <[Recv #003] ep: 0x7f8fb0252100, tag: 0x74e63e6a56f08f9, nbytes: 16, type: <class 'numpy.ndarray'>>: 

During handling of the above exception, another exception occurred:

Traceback (most recent call last):
  File "/opt/conda/envs/gdf/lib/python3.9/site-packages/distributed/worker.py", line 2059, in gather_dep
    response = await get_data_from_worker(
  File "/opt/conda/envs/gdf/lib/python3.9/site-packages/distributed/worker.py", line 2852, in get_data_from_worker
    response = await send_recv(
  File "/opt/conda/envs/gdf/lib/python3.9/site-packages/distributed/core.py", line 1106, in send_recv
    response = await comm.read(deserializers=deserializers)
  File "/opt/conda/envs/gdf/lib/python3.9/site-packages/distributed/utils.py", line 803, in wrapper
    return await func(*args, **kwargs)
  File "/opt/conda/envs/gdf/lib/python3.9/site-packages/distributed/comm/ucx.py", line 372, in read
    raise CommClosedError(
distributed.comm.core.CommClosedError: Connection closed by writer.
Inner exception: UCXCanceled("<[Recv #003] ep: 0x7f8fb0252100, tag: 0x74e63e6a56f08f9, nbytes: 16, type: <class 'numpy.ndarray'>>: ")
2024-01-03 07:09:31,589 - distributed.worker - ERROR - Worker stream died during communication: ucx://127.0.0.1:42405
Traceback (most recent call last):
  File "/opt/conda/envs/gdf/lib/python3.9/site-packages/distributed/comm/ucx.py", line 396, in read
    await self.ep.recv(each_frame)
  File "/opt/conda/envs/gdf/lib/python3.9/site-packages/ucp/core.py", line 725, in recv
    ret = await comm.tag_recv(self._ep, buffer, nbytes, tag, name=log)
ucp._libs.exceptions.UCXError: <[Recv #007] ep: 0x7f8590c25140, tag: 0x30c82de55e8723b8, nbytes: 50000000, type: <class 'rmm._lib.device_buffer.DeviceBuffer'>>: Connection reset by remote peer

During handling of the above exception, another exception occurred:

Traceback (most recent call last):
  File "/opt/conda/envs/gdf/lib/python3.9/site-packages/distributed/worker.py", line 2059, in gather_dep
    response = await get_data_from_worker(
  File "/opt/conda/envs/gdf/lib/python3.9/site-packages/distributed/worker.py", line 2852, in get_data_from_worker
    response = await send_recv(
  File "/opt/conda/envs/gdf/lib/python3.9/site-packages/distributed/core.py", line 1106, in send_recv
    response = await comm.read(deserializers=deserializers)
  File "/opt/conda/envs/gdf/lib/python3.9/site-packages/distributed/utils.py", line 803, in wrapper
    return await func(*args, **kwargs)
  File "/opt/conda/envs/gdf/lib/python3.9/site-packages/distributed/comm/ucx.py", line 402, in read
    raise CommClosedError(
distributed.comm.core.CommClosedError: Connection closed by writer.
Inner exception: UCXError("<[Recv #007] ep: 0x7f8590c25140, tag: 0x30c82de55e8723b8, nbytes: 50000000, type: <class 'rmm._lib.device_buffer.DeviceBuffer'>>: Connection reset by remote peer")
2024-01-03 07:09:31,591 - distributed.worker - ERROR - failed during get data with ucx://127.0.0.1:37529 -> ucx://127.0.0.1:42405
Traceback (most recent call last):
  File "/opt/conda/envs/gdf/lib/python3.9/site-packages/distributed/comm/ucx.py", line 338, in write
    await self.ep.send(each_frame)
  File "/opt/conda/envs/gdf/lib/python3.9/site-packages/ucp/core.py", line 650, in send
    return await comm.tag_send(self._ep, buffer, nbytes, tag, name=log)
ucp._libs.exceptions.UCXError: <[Send #007] ep: 0x7f8590c25240, tag: 0xb927e7c729d2ed59, nbytes: 50000000, type: <class 'cupy.ndarray'>>: Connection reset by remote peer

During handling of the above exception, another exception occurred:

Traceback (most recent call last):
  File "/opt/conda/envs/gdf/lib/python3.9/site-packages/distributed/worker.py", line 1782, in get_data
    compressed = await comm.write(msg, serializers=serializers)
  File "/opt/conda/envs/gdf/lib/python3.9/site-packages/distributed/utils.py", line 803, in wrapper
    return await func(*args, **kwargs)
  File "/opt/conda/envs/gdf/lib/python3.9/site-packages/distributed/comm/ucx.py", line 342, in write
    raise CommClosedError("While writing, the connection was closed")
distributed.comm.core.CommClosedError: While writing, the connection was closed
Task exception was never retrieved
future: <Task finished name='Task-292' coro=<_listener_handler_coroutine() done, defined at /opt/conda/envs/gdf/lib/python3.9/site-packages/ucp/core.py:128> exception=UCXError('<stream_send>: Connection reset by remote peer')>
Traceback (most recent call last):
  File "/opt/conda/envs/gdf/lib/python3.9/site-packages/ucp/core.py", line 143, in _listener_handler_coroutine
    peer_info = await exchange_peer_info(
  File "/opt/conda/envs/gdf/lib/python3.9/site-packages/ucp/core.py", line 51, in exchange_peer_info
    await comm.stream_send(endpoint, my_info_arr, my_info_arr.nbytes)
ucp._libs.exceptions.UCXError: <stream_send>: Connection reset by remote peer
2024-01-03 07:09:31,599 - distributed.worker - ERROR - Worker stream died during communication: ucx://127.0.0.1:42405
Traceback (most recent call last):
  File "/opt/conda/envs/gdf/lib/python3.9/site-packages/distributed/core.py", line 1516, in _connect
    comm = await connect(
  File "/opt/conda/envs/gdf/lib/python3.9/site-packages/distributed/comm/core.py", line 342, in connect
    comm = await wait_for(
  File "/opt/conda/envs/gdf/lib/python3.9/site-packages/distributed/utils.py", line 1920, in wait_for
    return await asyncio.wait_for(fut, timeout)
  File "/opt/conda/envs/gdf/lib/python3.9/asyncio/tasks.py", line 466, in wait_for
    await waiter
asyncio.exceptions.CancelledError

During handling of the above exception, another exception occurred:

Traceback (most recent call last):
  File "/opt/conda/envs/gdf/lib/python3.9/site-packages/distributed/core.py", line 1626, in connect
    return connect_attempt.result()
asyncio.exceptions.CancelledError

During handling of the above exception, another exception occurred:

Traceback (most recent call last):
  File "/opt/conda/envs/gdf/lib/python3.9/site-packages/distributed/worker.py", line 2059, in gather_dep
    response = await get_data_from_worker(
  File "/opt/conda/envs/gdf/lib/python3.9/site-packages/distributed/worker.py", line 2849, in get_data_from_worker
    comm = await rpc.connect(worker)
  File "/opt/conda/envs/gdf/lib/python3.9/site-packages/distributed/core.py", line 1628, in connect
    raise CommClosedError(reason)
distributed.comm.core.CommClosedError: Address removed.
2024-01-03 07:09:31,652 - distributed.worker - ERROR - Worker stream died during communication: ucx://127.0.0.1:58661
Traceback (most recent call last):
  File "/opt/conda/envs/gdf/lib/python3.9/site-packages/distributed/comm/ucx.py", line 396, in read
    await self.ep.recv(each_frame)
  File "/opt/conda/envs/gdf/lib/python3.9/site-packages/ucp/core.py", line 725, in recv
    ret = await comm.tag_recv(self._ep, buffer, nbytes, tag, name=log)
ucp._libs.exceptions.UCXError: <[Recv #007] ep: 0x7f8fb02521c0, tag: 0x7289ee8d9cb44a88, nbytes: 50000000, type: <class 'rmm._lib.device_buffer.DeviceBuffer'>>: Connection reset by remote peer

During handling of the above exception, another exception occurred:

Traceback (most recent call last):
  File "/opt/conda/envs/gdf/lib/python3.9/site-packages/distributed/worker.py", line 2059, in gather_dep
    response = await get_data_from_worker(
  File "/opt/conda/envs/gdf/lib/python3.9/site-packages/distributed/worker.py", line 2852, in get_data_from_worker
    response = await send_recv(
  File "/opt/conda/envs/gdf/lib/python3.9/site-packages/distributed/core.py", line 1106, in send_recv
    response = await comm.read(deserializers=deserializers)
  File "/opt/conda/envs/gdf/lib/python3.9/site-packages/distributed/utils.py", line 803, in wrapper
    return await func(*args, **kwargs)
  File "/opt/conda/envs/gdf/lib/python3.9/site-packages/distributed/comm/ucx.py", line 402, in read
    raise CommClosedError(
distributed.comm.core.CommClosedError: Connection closed by writer.
Inner exception: UCXError("<[Recv #007] ep: 0x7f8fb02521c0, tag: 0x7289ee8d9cb44a88, nbytes: 50000000, type: <class 'rmm._lib.device_buffer.DeviceBuffer'>>: Connection reset by remote peer")
2024-01-03 07:09:31,652 - distributed.worker - ERROR - failed during get data with ucx://127.0.0.1:45997 -> ucx://127.0.0.1:58661
Traceback (most recent call last):
  File "/opt/conda/envs/gdf/lib/python3.9/site-packages/distributed/comm/ucx.py", line 354, in read
    await self.ep.recv(msg)
  File "/opt/conda/envs/gdf/lib/python3.9/site-packages/ucp/core.py", line 725, in recv
    ret = await comm.tag_recv(self._ep, buffer, nbytes, tag, name=log)
ucp._libs.exceptions.UCXCanceled: <[Recv #006] ep: 0x7f8c71b77280, tag: 0x47e0699bc8428a7e, nbytes: 16, type: <class 'numpy.ndarray'>>: 

During handling of the above exception, another exception occurred:

Traceback (most recent call last):
  File "/opt/conda/envs/gdf/lib/python3.9/site-packages/distributed/worker.py", line 1783, in get_data
    response = await comm.read(deserializers=serializers)
  File "/opt/conda/envs/gdf/lib/python3.9/site-packages/distributed/utils.py", line 803, in wrapper
    return await func(*args, **kwargs)
  File "/opt/conda/envs/gdf/lib/python3.9/site-packages/distributed/comm/ucx.py", line 372, in read
    raise CommClosedError(
distributed.comm.core.CommClosedError: Connection closed by writer.
Inner exception: UCXCanceled("<[Recv #006] ep: 0x7f8c71b77280, tag: 0x47e0699bc8428a7e, nbytes: 16, type: <class 'numpy.ndarray'>>: ")
2024-01-03 07:09:31,652 - distributed.worker - ERROR - Worker stream died during communication: ucx://127.0.0.1:58661
Traceback (most recent call last):
  File "/opt/conda/envs/gdf/lib/python3.9/site-packages/distributed/comm/ucx.py", line 396, in read
    await self.ep.recv(each_frame)
  File "/opt/conda/envs/gdf/lib/python3.9/site-packages/ucp/core.py", line 725, in recv
    ret = await comm.tag_recv(self._ep, buffer, nbytes, tag, name=log)
ucp._libs.exceptions.UCXError: <[Recv #007] ep: 0x7f8590c25180, tag: 0x87eea35b667d8a5, nbytes: 50000000, type: <class 'rmm._lib.device_buffer.DeviceBuffer'>>: Connection reset by remote peer

During handling of the above exception, another exception occurred:

Traceback (most recent call last):
  File "/opt/conda/envs/gdf/lib/python3.9/site-packages/distributed/worker.py", line 2059, in gather_dep
    response = await get_data_from_worker(
  File "/opt/conda/envs/gdf/lib/python3.9/site-packages/distributed/worker.py", line 2852, in get_data_from_worker
    response = await send_recv(
  File "/opt/conda/envs/gdf/lib/python3.9/site-packages/distributed/core.py", line 1106, in send_recv
    response = await comm.read(deserializers=deserializers)
  File "/opt/conda/envs/gdf/lib/python3.9/site-packages/distributed/utils.py", line 803, in wrapper
    return await func(*args, **kwargs)
  File "/opt/conda/envs/gdf/lib/python3.9/site-packages/distributed/comm/ucx.py", line 402, in read
    raise CommClosedError(
distributed.comm.core.CommClosedError: Connection closed by writer.
Inner exception: UCXError("<[Recv #007] ep: 0x7f8590c25180, tag: 0x87eea35b667d8a5, nbytes: 50000000, type: <class 'rmm._lib.device_buffer.DeviceBuffer'>>: Connection reset by remote peer")
2024-01-03 07:09:31,653 - distributed.worker - ERROR - failed during get data with ucx://127.0.0.1:43953 -> ucx://127.0.0.1:58661
Traceback (most recent call last):
  File "/opt/conda/envs/gdf/lib/python3.9/site-packages/distributed/comm/ucx.py", line 338, in write
    await self.ep.send(each_frame)
  File "/opt/conda/envs/gdf/lib/python3.9/site-packages/ucp/core.py", line 650, in send
    return await comm.tag_send(self._ep, buffer, nbytes, tag, name=log)
ucp._libs.exceptions.UCXError: <[Send #007] ep: 0x7f8fb0252280, tag: 0x688a4c154f9e096d, nbytes: 50000000, type: <class 'cupy.ndarray'>>: Connection reset by remote peer

During handling of the above exception, another exception occurred:

Traceback (most recent call last):
  File "/opt/conda/envs/gdf/lib/python3.9/site-packages/distributed/worker.py", line 1782, in get_data
    compressed = await comm.write(msg, serializers=serializers)
  File "/opt/conda/envs/gdf/lib/python3.9/site-packages/distributed/utils.py", line 803, in wrapper
    return await func(*args, **kwargs)
  File "/opt/conda/envs/gdf/lib/python3.9/site-packages/distributed/comm/ucx.py", line 342, in write
    raise CommClosedError("While writing, the connection was closed")
distributed.comm.core.CommClosedError: While writing, the connection was closed
2024-01-03 07:09:31,653 - distributed.worker - ERROR - failed during get data with ucx://127.0.0.1:37529 -> ucx://127.0.0.1:58661
Traceback (most recent call last):
  File "/opt/conda/envs/gdf/lib/python3.9/site-packages/distributed/comm/ucx.py", line 338, in write
    await self.ep.send(each_frame)
  File "/opt/conda/envs/gdf/lib/python3.9/site-packages/ucp/core.py", line 650, in send
    return await comm.tag_send(self._ep, buffer, nbytes, tag, name=log)
ucp._libs.exceptions.UCXError: <[Send #007] ep: 0x7f8590c25100, tag: 0x2f0c9731d71310c9, nbytes: 50000000, type: <class 'cupy.ndarray'>>: Connection reset by remote peer

During handling of the above exception, another exception occurred:

Traceback (most recent call last):
  File "/opt/conda/envs/gdf/lib/python3.9/site-packages/distributed/worker.py", line 1782, in get_data
    compressed = await comm.write(msg, serializers=serializers)
  File "/opt/conda/envs/gdf/lib/python3.9/site-packages/distributed/utils.py", line 803, in wrapper
    return await func(*args, **kwargs)
  File "/opt/conda/envs/gdf/lib/python3.9/site-packages/distributed/comm/ucx.py", line 342, in write
    raise CommClosedError("While writing, the connection was closed")
distributed.comm.core.CommClosedError: While writing, the connection was closed
2024-01-03 07:09:31,769 - distributed.worker - ERROR - Worker stream died during communication: ucx://127.0.0.1:48127
Traceback (most recent call last):
  File "/opt/conda/envs/gdf/lib/python3.9/site-packages/distributed/comm/ucx.py", line 354, in read
    await self.ep.recv(msg)
  File "/opt/conda/envs/gdf/lib/python3.9/site-packages/ucp/core.py", line 725, in recv
    ret = await comm.tag_recv(self._ep, buffer, nbytes, tag, name=log)
ucp._libs.exceptions.UCXCanceled: <[Recv #008] ep: 0x7f8c71b77140, tag: 0xf6fca929fe57f887, nbytes: 16, type: <class 'numpy.ndarray'>>: 

During handling of the above exception, another exception occurred:

Traceback (most recent call last):
  File "/opt/conda/envs/gdf/lib/python3.9/site-packages/distributed/worker.py", line 2059, in gather_dep
    response = await get_data_from_worker(
  File "/opt/conda/envs/gdf/lib/python3.9/site-packages/distributed/worker.py", line 2852, in get_data_from_worker
    response = await send_recv(
  File "/opt/conda/envs/gdf/lib/python3.9/site-packages/distributed/core.py", line 1106, in send_recv
    response = await comm.read(deserializers=deserializers)
  File "/opt/conda/envs/gdf/lib/python3.9/site-packages/distributed/utils.py", line 803, in wrapper
    return await func(*args, **kwargs)
  File "/opt/conda/envs/gdf/lib/python3.9/site-packages/distributed/comm/ucx.py", line 372, in read
    raise CommClosedError(
distributed.comm.core.CommClosedError: Connection closed by writer.
Inner exception: UCXCanceled("<[Recv #008] ep: 0x7f8c71b77140, tag: 0xf6fca929fe57f887, nbytes: 16, type: <class 'numpy.ndarray'>>: ")
2024-01-03 07:09:31,769 - distributed.worker - ERROR - failed during get data with ucx://127.0.0.1:53883 -> ucx://127.0.0.1:48127
Traceback (most recent call last):
  File "/opt/conda/envs/gdf/lib/python3.9/site-packages/distributed/comm/ucx.py", line 338, in write
    await self.ep.send(each_frame)
  File "/opt/conda/envs/gdf/lib/python3.9/site-packages/ucp/core.py", line 650, in send
    return await comm.tag_send(self._ep, buffer, nbytes, tag, name=log)
ucp._libs.exceptions.UCXError: <[Send #007] ep: 0x7fd412f52240, tag: 0xd3a1ce98718ded6f, nbytes: 50000000, type: <class 'cupy.ndarray'>>: Connection reset by remote peer

During handling of the above exception, another exception occurred:

Traceback (most recent call last):
  File "/opt/conda/envs/gdf/lib/python3.9/site-packages/distributed/worker.py", line 1782, in get_data
    compressed = await comm.write(msg, serializers=serializers)
  File "/opt/conda/envs/gdf/lib/python3.9/site-packages/distributed/utils.py", line 803, in wrapper
    return await func(*args, **kwargs)
  File "/opt/conda/envs/gdf/lib/python3.9/site-packages/distributed/comm/ucx.py", line 342, in write
    raise CommClosedError("While writing, the connection was closed")
distributed.comm.core.CommClosedError: While writing, the connection was closed
2024-01-03 07:09:31,770 - distributed.worker - ERROR - Worker stream died during communication: ucx://127.0.0.1:48127
Traceback (most recent call last):
  File "/opt/conda/envs/gdf/lib/python3.9/site-packages/distributed/comm/ucx.py", line 396, in read
    await self.ep.recv(each_frame)
  File "/opt/conda/envs/gdf/lib/python3.9/site-packages/ucp/core.py", line 725, in recv
    ret = await comm.tag_recv(self._ep, buffer, nbytes, tag, name=log)
ucp._libs.exceptions.UCXError: <[Recv #007] ep: 0x7fd412f52140, tag: 0x598afcbc8dcf5f42, nbytes: 50000000, type: <class 'rmm._lib.device_buffer.DeviceBuffer'>>: Connection reset by remote peer

During handling of the above exception, another exception occurred:

Traceback (most recent call last):
  File "/opt/conda/envs/gdf/lib/python3.9/site-packages/distributed/worker.py", line 2059, in gather_dep
    response = await get_data_from_worker(
  File "/opt/conda/envs/gdf/lib/python3.9/site-packages/distributed/worker.py", line 2852, in get_data_from_worker
    response = await send_recv(
  File "/opt/conda/envs/gdf/lib/python3.9/site-packages/distributed/core.py", line 1106, in send_recv
    response = await comm.read(deserializers=deserializers)
  File "/opt/conda/envs/gdf/lib/python3.9/site-packages/distributed/utils.py", line 803, in wrapper
    return await func(*args, **kwargs)
  File "/opt/conda/envs/gdf/lib/python3.9/site-packages/distributed/comm/ucx.py", line 402, in read
    raise CommClosedError(
distributed.comm.core.CommClosedError: Connection closed by writer.
Inner exception: UCXError("<[Recv #007] ep: 0x7fd412f52140, tag: 0x598afcbc8dcf5f42, nbytes: 50000000, type: <class 'rmm._lib.device_buffer.DeviceBuffer'>>: Connection reset by remote peer")
2024-01-03 07:09:31,776 - distributed.worker - ERROR - Worker stream died during communication: ucx://127.0.0.1:48127
Traceback (most recent call last):
  File "/opt/conda/envs/gdf/lib/python3.9/site-packages/distributed/comm/ucx.py", line 471, in connect
    ep = await ucp.create_endpoint(ip, port)
  File "/opt/conda/envs/gdf/lib/python3.9/site-packages/ucp/core.py", line 1004, in create_endpoint
    return await _get_ctx().create_endpoint(
  File "/opt/conda/envs/gdf/lib/python3.9/site-packages/ucp/core.py", line 316, in create_endpoint
    peer_info = await exchange_peer_info(
  File "/opt/conda/envs/gdf/lib/python3.9/site-packages/ucp/core.py", line 54, in exchange_peer_info
    await comm.stream_recv(endpoint, peer_info_arr, peer_info_arr.nbytes)
ucp._libs.exceptions.UCXError: <stream_recv>: Connection reset by remote peer

During handling of the above exception, another exception occurred:

Traceback (most recent call last):
  File "/opt/conda/envs/gdf/lib/python3.9/site-packages/distributed/comm/core.py", line 342, in connect
    comm = await wait_for(
  File "/opt/conda/envs/gdf/lib/python3.9/site-packages/distributed/utils.py", line 1920, in wait_for
    return await asyncio.wait_for(fut, timeout)
  File "/opt/conda/envs/gdf/lib/python3.9/asyncio/tasks.py", line 479, in wait_for
    return fut.result()
  File "/opt/conda/envs/gdf/lib/python3.9/site-packages/distributed/comm/ucx.py", line 473, in connect
    raise CommClosedError("Connection closed before handshake completed")
distributed.comm.core.CommClosedError: Connection closed before handshake completed

During handling of the above exception, another exception occurred:

Traceback (most recent call last):
  File "/opt/conda/envs/gdf/lib/python3.9/site-packages/distributed/core.py", line 1516, in _connect
    comm = await connect(
  File "/opt/conda/envs/gdf/lib/python3.9/site-packages/distributed/comm/core.py", line 366, in connect
    await asyncio.sleep(backoff)
  File "/opt/conda/envs/gdf/lib/python3.9/asyncio/tasks.py", line 652, in sleep
    return await future
asyncio.exceptions.CancelledError

During handling of the above exception, another exception occurred:

Traceback (most recent call last):
  File "/opt/conda/envs/gdf/lib/python3.9/site-packages/distributed/core.py", line 1626, in connect
    return connect_attempt.result()
asyncio.exceptions.CancelledError

During handling of the above exception, another exception occurred:

Traceback (most recent call last):
  File "/opt/conda/envs/gdf/lib/python3.9/site-packages/distributed/worker.py", line 2059, in gather_dep
    response = await get_data_from_worker(
  File "/opt/conda/envs/gdf/lib/python3.9/site-packages/distributed/worker.py", line 2849, in get_data_from_worker
    comm = await rpc.connect(worker)
  File "/opt/conda/envs/gdf/lib/python3.9/site-packages/distributed/core.py", line 1628, in connect
    raise CommClosedError(reason)
distributed.comm.core.CommClosedError: Address removed.
2024-01-03 07:09:31,778 - distributed.worker - ERROR - Worker stream died during communication: ucx://127.0.0.1:48127
Traceback (most recent call last):
  File "/opt/conda/envs/gdf/lib/python3.9/site-packages/distributed/core.py", line 1516, in _connect
    comm = await connect(
  File "/opt/conda/envs/gdf/lib/python3.9/site-packages/distributed/comm/core.py", line 342, in connect
    comm = await wait_for(
  File "/opt/conda/envs/gdf/lib/python3.9/site-packages/distributed/utils.py", line 1920, in wait_for
    return await asyncio.wait_for(fut, timeout)
  File "/opt/conda/envs/gdf/lib/python3.9/asyncio/tasks.py", line 466, in wait_for
    await waiter
asyncio.exceptions.CancelledError

During handling of the above exception, another exception occurred:

Traceback (most recent call last):
  File "/opt/conda/envs/gdf/lib/python3.9/site-packages/distributed/core.py", line 1626, in connect
    return connect_attempt.result()
asyncio.exceptions.CancelledError

During handling of the above exception, another exception occurred:

Traceback (most recent call last):
  File "/opt/conda/envs/gdf/lib/python3.9/site-packages/distributed/worker.py", line 2059, in gather_dep
    response = await get_data_from_worker(
  File "/opt/conda/envs/gdf/lib/python3.9/site-packages/distributed/worker.py", line 2849, in get_data_from_worker
    comm = await rpc.connect(worker)
  File "/opt/conda/envs/gdf/lib/python3.9/site-packages/distributed/core.py", line 1628, in connect
    raise CommClosedError(reason)
distributed.comm.core.CommClosedError: Address removed.
2024-01-03 07:09:36,486 - distributed.nanny - WARNING - Restarting worker
2024-01-03 07:09:36,763 - distributed.nanny - WARNING - Restarting worker
2024-01-03 07:09:36,764 - distributed.nanny - WARNING - Restarting worker
2024-01-03 07:09:36,791 - distributed.nanny - WARNING - Restarting worker
/opt/conda/envs/gdf/lib/python3.9/multiprocessing/resource_tracker.py:216: UserWarning: resource_tracker: There appear to be 48 leaked semaphore objects to clean up at shutdown
  warnings.warn('resource_tracker: There appear to be %d '
