2023-01-15 22:59:59,836 - distributed.preloading - INFO - Creating preload: dask_cuda.initialize
2023-01-15 22:59:59,836 - distributed.preloading - INFO - Import preload module: dask_cuda.initialize
2023-01-15 22:59:59,932 - distributed.preloading - INFO - Creating preload: dask_cuda.initialize
2023-01-15 22:59:59,932 - distributed.preloading - INFO - Import preload module: dask_cuda.initialize
2023-01-15 22:59:59,957 - distributed.preloading - INFO - Creating preload: dask_cuda.initialize
2023-01-15 22:59:59,957 - distributed.preloading - INFO - Import preload module: dask_cuda.initialize
2023-01-15 22:59:59,957 - distributed.preloading - INFO - Creating preload: dask_cuda.initialize
2023-01-15 22:59:59,958 - distributed.preloading - INFO - Import preload module: dask_cuda.initialize
2023-01-15 22:59:59,961 - distributed.preloading - INFO - Creating preload: dask_cuda.initialize
2023-01-15 22:59:59,961 - distributed.preloading - INFO - Import preload module: dask_cuda.initialize
2023-01-15 22:59:59,963 - distributed.preloading - INFO - Creating preload: dask_cuda.initialize
2023-01-15 22:59:59,963 - distributed.preloading - INFO - Import preload module: dask_cuda.initialize
2023-01-15 22:59:59,966 - distributed.preloading - INFO - Creating preload: dask_cuda.initialize
2023-01-15 22:59:59,966 - distributed.preloading - INFO - Import preload module: dask_cuda.initialize
2023-01-15 22:59:59,974 - distributed.preloading - INFO - Creating preload: dask_cuda.initialize
2023-01-15 22:59:59,974 - distributed.preloading - INFO - Import preload module: dask_cuda.initialize
terminate called after throwing an instance of 'rmm::out_of_memory'
  what():  std::bad_alloc: out_of_memory: RMM failure at:/datasets/pentschev/miniconda3/envs/gdf/include/rmm/mr/device/pool_memory_resource.hpp:193: Maximum pool size exceeded
2023-01-15 23:00:20,076 - distributed.worker - ERROR - failed during get data with ucx://127.0.0.1:48851 -> ucx://127.0.0.1:57777
Traceback (most recent call last):
  File "/datasets/pentschev/miniconda3/envs/gdf/lib/python3.9/site-packages/distributed/comm/ucx.py", line 333, in write
    await self.ep.send(each_frame)
  File "/datasets/pentschev/miniconda3/envs/gdf/lib/python3.9/site-packages/ucp/core.py", line 650, in send
    return await comm.tag_send(self._ep, buffer, nbytes, tag, name=log)
ucp._libs.exceptions.UCXError: <[Send #041] ep: 0x7f620018f1c0, tag: 0x82cacc38e7952c21, nbytes: 100000000, type: <class 'cudf.core.buffer.buffer.Buffer'>>: Connection reset by remote peer

During handling of the above exception, another exception occurred:

Traceback (most recent call last):
  File "/datasets/pentschev/miniconda3/envs/gdf/lib/python3.9/site-packages/distributed/worker.py", line 1766, in get_data
    compressed = await comm.write(msg, serializers=serializers)
  File "/datasets/pentschev/miniconda3/envs/gdf/lib/python3.9/site-packages/distributed/utils.py", line 741, in wrapper
    return await func(*args, **kwargs)
  File "/datasets/pentschev/miniconda3/envs/gdf/lib/python3.9/site-packages/distributed/comm/ucx.py", line 337, in write
    raise CommClosedError("While writing, the connection was closed")
distributed.comm.core.CommClosedError: While writing, the connection was closed
2023-01-15 23:00:20,076 - distributed.worker - ERROR - failed during get data with ucx://127.0.0.1:43699 -> ucx://127.0.0.1:57777
Traceback (most recent call last):
  File "/datasets/pentschev/miniconda3/envs/gdf/lib/python3.9/site-packages/distributed/comm/ucx.py", line 333, in write
    await self.ep.send(each_frame)
  File "/datasets/pentschev/miniconda3/envs/gdf/lib/python3.9/site-packages/ucp/core.py", line 650, in send
    return await comm.tag_send(self._ep, buffer, nbytes, tag, name=log)
ucp._libs.exceptions.UCXError: <[Send #041] ep: 0x7efc7017a180, tag: 0x2891592b07dea276, nbytes: 100000000, type: <class 'cudf.core.buffer.buffer.Buffer'>>: Endpoint timeout

During handling of the above exception, another exception occurred:

Traceback (most recent call last):
  File "/datasets/pentschev/miniconda3/envs/gdf/lib/python3.9/site-packages/distributed/worker.py", line 1766, in get_data
    compressed = await comm.write(msg, serializers=serializers)
  File "/datasets/pentschev/miniconda3/envs/gdf/lib/python3.9/site-packages/distributed/utils.py", line 741, in wrapper
    return await func(*args, **kwargs)
  File "/datasets/pentschev/miniconda3/envs/gdf/lib/python3.9/site-packages/distributed/comm/ucx.py", line 337, in write
    raise CommClosedError("While writing, the connection was closed")
distributed.comm.core.CommClosedError: While writing, the connection was closed
2023-01-15 23:00:20,288 - distributed.nanny - WARNING - Restarting worker
2023-01-15 23:00:22,324 - distributed.preloading - INFO - Creating preload: dask_cuda.initialize
2023-01-15 23:00:22,324 - distributed.preloading - INFO - Import preload module: dask_cuda.initialize
/datasets/pentschev/miniconda3/envs/gdf/lib/python3.9/multiprocessing/resource_tracker.py:216: UserWarning: resource_tracker: There appear to be 48 leaked semaphore objects to clean up at shutdown
  warnings.warn('resource_tracker: There appear to be %d '
