/opt/conda/envs/gdf/lib/python3.9/site-packages/distributed/node.py:182: UserWarning: Port 8787 is already in use.
Perhaps you already have a cluster running?
Hosting the HTTP server on port 33009 instead
  warnings.warn(
[dgx13:72784:0:72784] Caught signal 11 (Segmentation fault: address not mapped to object at address 0x448)
==== backtrace (tid:  72784) ====
 0  /opt/conda/envs/gdf/lib/libucs.so.0(ucs_handle_error+0x2fd) [0x7f4fd905c06d]
 1  /opt/conda/envs/gdf/lib/libucs.so.0(+0x2a264) [0x7f4fd905c264]
 2  /opt/conda/envs/gdf/lib/libucs.so.0(+0x2a42a) [0x7f4fd905c42a]
 3  /usr/lib/x86_64-linux-gnu/libpthread.so.0(+0x14420) [0x7f507e1a6420]
 4  /opt/conda/envs/gdf/lib/libucp.so.0(ucp_mem_type_unpack+0x14) [0x7f4fd90da6a4]
 5  /opt/conda/envs/gdf/lib/libucp.so.0(ucp_rndv_data_handler+0x4e9) [0x7f4fd9103829]
 6  /opt/conda/envs/gdf/lib/./libuct.so.0(+0x2146f) [0x7f4fd901646f]
 7  /opt/conda/envs/gdf/lib/./libuct.so.0(+0x248c8) [0x7f4fd90198c8]
 8  /opt/conda/envs/gdf/lib/libucs.so.0(ucs_event_set_wait+0xb9) [0x7f4fd9065499]
 9  /opt/conda/envs/gdf/lib/./libuct.so.0(uct_tcp_iface_progress+0x7d) [0x7f4fd901866d]
10  /opt/conda/envs/gdf/lib/libucp.so.0(ucp_worker_progress+0x5a) [0x7f4fd90d78ca]
11  /opt/conda/envs/gdf/lib/python3.9/site-packages/ucp/_libs/ucx_api.cpython-39-x86_64-linux-gnu.so(+0x3206a) [0x7f4fd919006a]
12  /opt/conda/envs/gdf/bin/python(_PyEval_EvalFrameDefault+0x37cb) [0x559ea625f6fb]
13  /opt/conda/envs/gdf/bin/python(+0x12f094) [0x559ea625b094]
14  /opt/conda/envs/gdf/bin/python(_PyFunction_Vectorcall+0xd9) [0x559ea626c519]
15  /opt/conda/envs/gdf/bin/python(_PyEval_EvalFrameDefault+0x696) [0x559ea625c5c6]
16  /opt/conda/envs/gdf/bin/python(+0x1407c2) [0x559ea626c7c2]
17  /opt/conda/envs/gdf/bin/python(+0x14de83) [0x559ea6279e83]
18  /opt/conda/envs/gdf/bin/python(+0x258b2c) [0x559ea6384b2c]
19  /opt/conda/envs/gdf/bin/python(+0xead05) [0x559ea6216d05]
20  /opt/conda/envs/gdf/bin/python(+0x1377f3) [0x559ea62637f3]
21  /opt/conda/envs/gdf/bin/python(_PyEval_EvalFrameDefault+0x59f9) [0x559ea6261929]
22  /opt/conda/envs/gdf/bin/python(+0x1407c2) [0x559ea626c7c2]
23  /opt/conda/envs/gdf/bin/python(_PyEval_EvalFrameDefault+0x696) [0x559ea625c5c6]
24  /opt/conda/envs/gdf/bin/python(+0x1407c2) [0x559ea626c7c2]
25  /opt/conda/envs/gdf/bin/python(_PyEval_EvalFrameDefault+0x696) [0x559ea625c5c6]
26  /opt/conda/envs/gdf/bin/python(+0x1407c2) [0x559ea626c7c2]
27  /opt/conda/envs/gdf/bin/python(_PyEval_EvalFrameDefault+0x696) [0x559ea625c5c6]
28  /opt/conda/envs/gdf/bin/python(+0x1407c2) [0x559ea626c7c2]
29  /opt/conda/envs/gdf/bin/python(_PyEval_EvalFrameDefault+0x696) [0x559ea625c5c6]
30  /opt/conda/envs/gdf/bin/python(+0x12f094) [0x559ea625b094]
31  /opt/conda/envs/gdf/bin/python(_PyFunction_Vectorcall+0xd9) [0x559ea626c519]
32  /opt/conda/envs/gdf/bin/python(_PyEval_EvalFrameDefault+0x11f8) [0x559ea625d128]
33  /opt/conda/envs/gdf/bin/python(+0x12f094) [0x559ea625b094]
34  /opt/conda/envs/gdf/bin/python(+0x14dccb) [0x559ea6279ccb]
35  /opt/conda/envs/gdf/bin/python(PyObject_Call+0xbc) [0x559ea627a44c]
36  /opt/conda/envs/gdf/bin/python(+0x21110e) [0x559ea633d10e]
37  /opt/conda/envs/gdf/bin/python(_PyObject_MakeTpCall+0x2ec) [0x559ea626477c]
38  /opt/conda/envs/gdf/bin/python(_PyEval_EvalFrameDefault+0x37cb) [0x559ea625f6fb]
39  /opt/conda/envs/gdf/bin/python(+0x1407c2) [0x559ea626c7c2]
40  /opt/conda/envs/gdf/bin/python(+0x14ddac) [0x559ea6279dac]
41  /opt/conda/envs/gdf/bin/python(_PyEval_EvalFrameDefault+0x37cb) [0x559ea625f6fb]
42  /opt/conda/envs/gdf/bin/python(+0x1407c2) [0x559ea626c7c2]
43  /opt/conda/envs/gdf/bin/python(_PyEval_EvalFrameDefault+0x696) [0x559ea625c5c6]
44  /opt/conda/envs/gdf/bin/python(+0x12f094) [0x559ea625b094]
45  /opt/conda/envs/gdf/bin/python(_PyFunction_Vectorcall+0xd9) [0x559ea626c519]
46  /opt/conda/envs/gdf/bin/python(_PyEval_EvalFrameDefault+0x696) [0x559ea625c5c6]
47  /opt/conda/envs/gdf/bin/python(+0x1407c2) [0x559ea626c7c2]
48  /opt/conda/envs/gdf/bin/python(_PyEval_EvalFrameDefault+0x3e2) [0x559ea625c312]
49  /opt/conda/envs/gdf/bin/python(+0x12f094) [0x559ea625b094]
50  /opt/conda/envs/gdf/bin/python(_PyFunction_Vectorcall+0xd9) [0x559ea626c519]
51  /opt/conda/envs/gdf/bin/python(_PyEval_EvalFrameDefault+0x11f8) [0x559ea625d128]
52  /opt/conda/envs/gdf/bin/python(+0x12f094) [0x559ea625b094]
53  /opt/conda/envs/gdf/bin/python(_PyEval_EvalCodeWithName+0x48) [0x559ea625ad68]
54  /opt/conda/envs/gdf/bin/python(PyEval_EvalCodeEx+0x39) [0x559ea625ad19]
55  /opt/conda/envs/gdf/bin/python(PyEval_EvalCode+0x1b) [0x559ea630807b]
56  /opt/conda/envs/gdf/bin/python(+0x208fca) [0x559ea6334fca]
57  /opt/conda/envs/gdf/bin/python(+0x205353) [0x559ea6331353]
58  /opt/conda/envs/gdf/bin/python(PyRun_StringFlags+0x9a) [0x559ea632916a]
59  /opt/conda/envs/gdf/bin/python(PyRun_SimpleStringFlags+0x3c) [0x559ea632905c]
60  /opt/conda/envs/gdf/bin/python(Py_RunMain+0x267) [0x559ea6328297]
61  /opt/conda/envs/gdf/bin/python(Py_BytesMain+0x37) [0x559ea62fbf07]
=================================
2023-11-05 05:51:41,758 - distributed.worker - ERROR - failed during get data with ucx://127.0.0.1:34083 -> ucx://127.0.0.1:49999
Traceback (most recent call last):
  File "/opt/conda/envs/gdf/lib/python3.9/site-packages/distributed/comm/ucx.py", line 338, in write
    await self.ep.send(each_frame)
  File "/opt/conda/envs/gdf/lib/python3.9/site-packages/ucp/core.py", line 650, in send
    return await comm.tag_send(self._ep, buffer, nbytes, tag, name=log)
ucp._libs.exceptions.UCXError: <[Send #007] ep: 0x7f9b091a0140, tag: 0xfcde0a075c8219f1, nbytes: 800000000, type: <class 'cudf.core.buffer.buffer.Buffer'>>: Connection reset by remote peer

During handling of the above exception, another exception occurred:

Traceback (most recent call last):
  File "/opt/conda/envs/gdf/lib/python3.9/site-packages/distributed/worker.py", line 1782, in get_data
    compressed = await comm.write(msg, serializers=serializers)
  File "/opt/conda/envs/gdf/lib/python3.9/site-packages/distributed/utils.py", line 803, in wrapper
    return await func(*args, **kwargs)
  File "/opt/conda/envs/gdf/lib/python3.9/site-packages/distributed/comm/ucx.py", line 342, in write
    raise CommClosedError("While writing, the connection was closed")
distributed.comm.core.CommClosedError: While writing, the connection was closed
[dgx13:72777:0:72777] Caught signal 11 (Segmentation fault: address not mapped to object at address 0x448)
==== backtrace (tid:  72777) ====
 0  /opt/conda/envs/gdf/lib/libucs.so.0(ucs_handle_error+0x2fd) [0x7f64a405a06d]
 1  /opt/conda/envs/gdf/lib/libucs.so.0(+0x2a264) [0x7f64a405a264]
 2  /opt/conda/envs/gdf/lib/libucs.so.0(+0x2a42a) [0x7f64a405a42a]
 3  /usr/lib/x86_64-linux-gnu/libpthread.so.0(+0x14420) [0x7f654510a420]
 4  /opt/conda/envs/gdf/lib/libucp.so.0(ucp_mem_type_unpack+0x14) [0x7f64a1f7c6a4]
 5  /opt/conda/envs/gdf/lib/libucp.so.0(ucp_rndv_data_handler+0x4e9) [0x7f64a1fa5829]
 6  /opt/conda/envs/gdf/lib/./libuct.so.0(+0x2146f) [0x7f64a1f1646f]
 7  /opt/conda/envs/gdf/lib/./libuct.so.0(+0x248c8) [0x7f64a1f198c8]
 8  /opt/conda/envs/gdf/lib/libucs.so.0(ucs_event_set_wait+0xb9) [0x7f64a4063499]
 9  /opt/conda/envs/gdf/lib/./libuct.so.0(uct_tcp_iface_progress+0x7d) [0x7f64a1f1866d]
10  /opt/conda/envs/gdf/lib/libucp.so.0(ucp_worker_progress+0x5a) [0x7f64a1f798ca]
11  /opt/conda/envs/gdf/lib/python3.9/site-packages/ucp/_libs/ucx_api.cpython-39-x86_64-linux-gnu.so(+0x3206a) [0x7f64a40c006a]
12  /opt/conda/envs/gdf/bin/python(_PyEval_EvalFrameDefault+0x37cb) [0x556be2f546fb]
13  /opt/conda/envs/gdf/bin/python(+0x12f094) [0x556be2f50094]
14  /opt/conda/envs/gdf/bin/python(_PyFunction_Vectorcall+0xd9) [0x556be2f61519]
15  /opt/conda/envs/gdf/bin/python(_PyEval_EvalFrameDefault+0x696) [0x556be2f515c6]
16  /opt/conda/envs/gdf/bin/python(+0x1e3162) [0x556be3004162]
17  /opt/conda/envs/gdf/lib/python3.9/lib-dynload/_asyncio.cpython-39-x86_64-linux-gnu.so(+0x81e9) [0x7f64c52851e9]
18  /opt/conda/envs/gdf/bin/python(_PyObject_MakeTpCall+0x2ec) [0x556be2f5977c]
19  /opt/conda/envs/gdf/bin/python(+0xead05) [0x556be2f0bd05]
20  /opt/conda/envs/gdf/bin/python(+0x1377f3) [0x556be2f587f3]
21  /opt/conda/envs/gdf/bin/python(_PyEval_EvalFrameDefault+0x59f9) [0x556be2f56929]
22  /opt/conda/envs/gdf/bin/python(+0x1407c2) [0x556be2f617c2]
23  /opt/conda/envs/gdf/bin/python(_PyEval_EvalFrameDefault+0x696) [0x556be2f515c6]
24  /opt/conda/envs/gdf/bin/python(+0x1407c2) [0x556be2f617c2]
25  /opt/conda/envs/gdf/bin/python(_PyEval_EvalFrameDefault+0x696) [0x556be2f515c6]
26  /opt/conda/envs/gdf/bin/python(+0x1407c2) [0x556be2f617c2]
27  /opt/conda/envs/gdf/bin/python(_PyEval_EvalFrameDefault+0x696) [0x556be2f515c6]
28  /opt/conda/envs/gdf/bin/python(+0x1407c2) [0x556be2f617c2]
29  /opt/conda/envs/gdf/bin/python(_PyEval_EvalFrameDefault+0x696) [0x556be2f515c6]
30  /opt/conda/envs/gdf/bin/python(+0x12f094) [0x556be2f50094]
31  /opt/conda/envs/gdf/bin/python(_PyFunction_Vectorcall+0xd9) [0x556be2f61519]
32  /opt/conda/envs/gdf/bin/python(_PyEval_EvalFrameDefault+0x11f8) [0x556be2f52128]
33  /opt/conda/envs/gdf/bin/python(+0x12f094) [0x556be2f50094]
34  /opt/conda/envs/gdf/bin/python(+0x14dccb) [0x556be2f6eccb]
35  /opt/conda/envs/gdf/bin/python(PyObject_Call+0xbc) [0x556be2f6f44c]
36  /opt/conda/envs/gdf/bin/python(+0x21110e) [0x556be303210e]
37  /opt/conda/envs/gdf/bin/python(_PyObject_MakeTpCall+0x2ec) [0x556be2f5977c]
38  /opt/conda/envs/gdf/bin/python(_PyEval_EvalFrameDefault+0x37cb) [0x556be2f546fb]
39  /opt/conda/envs/gdf/bin/python(+0x1407c2) [0x556be2f617c2]
40  /opt/conda/envs/gdf/bin/python(+0x14ddac) [0x556be2f6edac]
41  /opt/conda/envs/gdf/bin/python(_PyEval_EvalFrameDefault+0x37cb) [0x556be2f546fb]
42  /opt/conda/envs/gdf/bin/python(+0x1407c2) [0x556be2f617c2]
43  /opt/conda/envs/gdf/bin/python(_PyEval_EvalFrameDefault+0x696) [0x556be2f515c6]
44  /opt/conda/envs/gdf/bin/python(+0x12f094) [0x556be2f50094]
45  /opt/conda/envs/gdf/bin/python(_PyFunction_Vectorcall+0xd9) [0x556be2f61519]
46  /opt/conda/envs/gdf/bin/python(_PyEval_EvalFrameDefault+0x696) [0x556be2f515c6]
47  /opt/conda/envs/gdf/bin/python(+0x1407c2) [0x556be2f617c2]
48  /opt/conda/envs/gdf/bin/python(_PyEval_EvalFrameDefault+0x3e2) [0x556be2f51312]
49  /opt/conda/envs/gdf/bin/python(+0x12f094) [0x556be2f50094]
50  /opt/conda/envs/gdf/bin/python(_PyFunction_Vectorcall+0xd9) [0x556be2f61519]
51  /opt/conda/envs/gdf/bin/python(_PyEval_EvalFrameDefault+0x11f8) [0x556be2f52128]
52  /opt/conda/envs/gdf/bin/python(+0x12f094) [0x556be2f50094]
53  /opt/conda/envs/gdf/bin/python(_PyEval_EvalCodeWithName+0x48) [0x556be2f4fd68]
54  /opt/conda/envs/gdf/bin/python(PyEval_EvalCodeEx+0x39) [0x556be2f4fd19]
55  /opt/conda/envs/gdf/bin/python(PyEval_EvalCode+0x1b) [0x556be2ffd07b]
56  /opt/conda/envs/gdf/bin/python(+0x208fca) [0x556be3029fca]
57  /opt/conda/envs/gdf/bin/python(+0x205353) [0x556be3026353]
58  /opt/conda/envs/gdf/bin/python(PyRun_StringFlags+0x9a) [0x556be301e16a]
59  /opt/conda/envs/gdf/bin/python(PyRun_SimpleStringFlags+0x3c) [0x556be301e05c]
60  /opt/conda/envs/gdf/bin/python(Py_RunMain+0x267) [0x556be301d297]
61  /opt/conda/envs/gdf/bin/python(Py_BytesMain+0x37) [0x556be2ff0f07]
=================================
[dgx13:72782:0:72782] Caught signal 11 (Segmentation fault: address not mapped to object at address 0x448)
==== backtrace (tid:  72782) ====
 0  /opt/conda/envs/gdf/lib/libucs.so.0(ucs_handle_error+0x2fd) [0x7f5fa0e0706d]
 1  /opt/conda/envs/gdf/lib/libucs.so.0(+0x2a264) [0x7f5fa0e07264]
 2  /opt/conda/envs/gdf/lib/libucs.so.0(+0x2a42a) [0x7f5fa0e0742a]
 3  /usr/lib/x86_64-linux-gnu/libpthread.so.0(+0x14420) [0x7f6033f86420]
 4  /opt/conda/envs/gdf/lib/libucp.so.0(ucp_mem_type_unpack+0x14) [0x7f5fa0e856a4]
 5  /opt/conda/envs/gdf/lib/libucp.so.0(ucp_rndv_data_handler+0x4e9) [0x7f5fa0eae829]
 6  /opt/conda/envs/gdf/lib/./libuct.so.0(+0x2146f) [0x7f5fa0dc146f]
 7  /opt/conda/envs/gdf/lib/./libuct.so.0(+0x248c8) [0x7f5fa0dc48c8]
 8  /opt/conda/envs/gdf/lib/libucs.so.0(ucs_event_set_wait+0xb9) [0x7f5fa0e10499]
 9  /opt/conda/envs/gdf/lib/./libuct.so.0(uct_tcp_iface_progress+0x7d) [0x7f5fa0dc366d]
10  /opt/conda/envs/gdf/lib/libucp.so.0(ucp_worker_progress+0x5a) [0x7f5fa0e828ca]
11  /opt/conda/envs/gdf/lib/python3.9/site-packages/ucp/_libs/ucx_api.cpython-39-x86_64-linux-gnu.so(+0x3206a) [0x7f5fa0f3b06a]
12  /opt/conda/envs/gdf/bin/python(_PyEval_EvalFrameDefault+0x37cb) [0x5613734636fb]
13  /opt/conda/envs/gdf/bin/python(+0x12f094) [0x56137345f094]
14  /opt/conda/envs/gdf/bin/python(_PyFunction_Vectorcall+0xd9) [0x561373470519]
15  /opt/conda/envs/gdf/bin/python(_PyEval_EvalFrameDefault+0x696) [0x5613734605c6]
16  /opt/conda/envs/gdf/bin/python(+0x1e3162) [0x561373513162]
17  /opt/conda/envs/gdf/lib/python3.9/lib-dynload/_asyncio.cpython-39-x86_64-linux-gnu.so(+0x81e9) [0x7f5fb41071e9]
18  /opt/conda/envs/gdf/bin/python(_PyObject_MakeTpCall+0x2ec) [0x56137346877c]
19  /opt/conda/envs/gdf/bin/python(+0xead05) [0x56137341ad05]
20  /opt/conda/envs/gdf/bin/python(+0x1377f3) [0x5613734677f3]
21  /opt/conda/envs/gdf/bin/python(_PyEval_EvalFrameDefault+0x59f9) [0x561373465929]
22  /opt/conda/envs/gdf/bin/python(+0x1407c2) [0x5613734707c2]
23  /opt/conda/envs/gdf/bin/python(_PyEval_EvalFrameDefault+0x696) [0x5613734605c6]
24  /opt/conda/envs/gdf/bin/python(+0x1407c2) [0x5613734707c2]
25  /opt/conda/envs/gdf/bin/python(_PyEval_EvalFrameDefault+0x696) [0x5613734605c6]
26  /opt/conda/envs/gdf/bin/python(+0x1407c2) [0x5613734707c2]
27  /opt/conda/envs/gdf/bin/python(_PyEval_EvalFrameDefault+0x696) [0x5613734605c6]
28  /opt/conda/envs/gdf/bin/python(+0x1407c2) [0x5613734707c2]
29  /opt/conda/envs/gdf/bin/python(_PyEval_EvalFrameDefault+0x696) [0x5613734605c6]
30  /opt/conda/envs/gdf/bin/python(+0x12f094) [0x56137345f094]
31  /opt/conda/envs/gdf/bin/python(_PyFunction_Vectorcall+0xd9) [0x561373470519]
32  /opt/conda/envs/gdf/bin/python(_PyEval_EvalFrameDefault+0x11f8) [0x561373461128]
33  /opt/conda/envs/gdf/bin/python(+0x12f094) [0x56137345f094]
34  /opt/conda/envs/gdf/bin/python(+0x14dccb) [0x56137347dccb]
35  /opt/conda/envs/gdf/bin/python(PyObject_Call+0xbc) [0x56137347e44c]
36  /opt/conda/envs/gdf/bin/python(+0x21110e) [0x56137354110e]
37  /opt/conda/envs/gdf/bin/python(_PyObject_MakeTpCall+0x2ec) [0x56137346877c]
38  /opt/conda/envs/gdf/bin/python(_PyEval_EvalFrameDefault+0x37cb) [0x5613734636fb]
39  /opt/conda/envs/gdf/bin/python(+0x1407c2) [0x5613734707c2]
40  /opt/conda/envs/gdf/bin/python(+0x14ddac) [0x56137347ddac]
41  /opt/conda/envs/gdf/bin/python(_PyEval_EvalFrameDefault+0x37cb) [0x5613734636fb]
42  /opt/conda/envs/gdf/bin/python(+0x1407c2) [0x5613734707c2]
43  /opt/conda/envs/gdf/bin/python(_PyEval_EvalFrameDefault+0x696) [0x5613734605c6]
44  /opt/conda/envs/gdf/bin/python(+0x12f094) [0x56137345f094]
45  /opt/conda/envs/gdf/bin/python(_PyFunction_Vectorcall+0xd9) [0x561373470519]
46  /opt/conda/envs/gdf/bin/python(_PyEval_EvalFrameDefault+0x696) [0x5613734605c6]
47  /opt/conda/envs/gdf/bin/python(+0x1407c2) [0x5613734707c2]
48  /opt/conda/envs/gdf/bin/python(_PyEval_EvalFrameDefault+0x3e2) [0x561373460312]
49  /opt/conda/envs/gdf/bin/python(+0x12f094) [0x56137345f094]
50  /opt/conda/envs/gdf/bin/python(_PyFunction_Vectorcall+0xd9) [0x561373470519]
51  /opt/conda/envs/gdf/bin/python(_PyEval_EvalFrameDefault+0x11f8) [0x561373461128]
52  /opt/conda/envs/gdf/bin/python(+0x12f094) [0x56137345f094]
53  /opt/conda/envs/gdf/bin/python(_PyEval_EvalCodeWithName+0x48) [0x56137345ed68]
54  /opt/conda/envs/gdf/bin/python(PyEval_EvalCodeEx+0x39) [0x56137345ed19]
55  /opt/conda/envs/gdf/bin/python(PyEval_EvalCode+0x1b) [0x56137350c07b]
56  /opt/conda/envs/gdf/bin/python(+0x208fca) [0x561373538fca]
57  /opt/conda/envs/gdf/bin/python(+0x205353) [0x561373535353]
58  /opt/conda/envs/gdf/bin/python(PyRun_StringFlags+0x9a) [0x56137352d16a]
59  /opt/conda/envs/gdf/bin/python(PyRun_SimpleStringFlags+0x3c) [0x56137352d05c]
60  /opt/conda/envs/gdf/bin/python(Py_RunMain+0x267) [0x56137352c297]
61  /opt/conda/envs/gdf/bin/python(Py_BytesMain+0x37) [0x5613734fff07]
=================================
[dgx13:72797:0:72797] Caught signal 11 (Segmentation fault: address not mapped to object at address 0x448)
==== backtrace (tid:  72797) ====
 0  /opt/conda/envs/gdf/lib/libucs.so.0(ucs_handle_error+0x2fd) [0x7f66883e106d]
 1  /opt/conda/envs/gdf/lib/libucs.so.0(+0x2a264) [0x7f66883e1264]
 2  /opt/conda/envs/gdf/lib/libucs.so.0(+0x2a42a) [0x7f66883e142a]
 3  /usr/lib/x86_64-linux-gnu/libpthread.so.0(+0x14420) [0x7f6729539420]
 4  /opt/conda/envs/gdf/lib/libucp.so.0(ucp_mem_type_unpack+0x14) [0x7f668845f6a4]
 5  /opt/conda/envs/gdf/lib/libucp.so.0(ucp_rndv_data_handler+0x4e9) [0x7f6688488829]
 6  /opt/conda/envs/gdf/lib/./libuct.so.0(+0x2146f) [0x7f668839b46f]
 7  /opt/conda/envs/gdf/lib/./libuct.so.0(+0x248c8) [0x7f668839e8c8]
 8  /opt/conda/envs/gdf/lib/libucs.so.0(ucs_event_set_wait+0xb9) [0x7f66883ea499]
 9  /opt/conda/envs/gdf/lib/./libuct.so.0(uct_tcp_iface_progress+0x7d) [0x7f668839d66d]
10  /opt/conda/envs/gdf/lib/libucp.so.0(ucp_worker_progress+0x5a) [0x7f668845c8ca]
11  /opt/conda/envs/gdf/lib/python3.9/site-packages/ucp/_libs/ucx_api.cpython-39-x86_64-linux-gnu.so(+0x3206a) [0x7f668851506a]
12  /opt/conda/envs/gdf/bin/python(_PyEval_EvalFrameDefault+0x37cb) [0x55a672ca36fb]
13  /opt/conda/envs/gdf/bin/python(+0x12f094) [0x55a672c9f094]
14  /opt/conda/envs/gdf/bin/python(_PyFunction_Vectorcall+0xd9) [0x55a672cb0519]
15  /opt/conda/envs/gdf/bin/python(_PyEval_EvalFrameDefault+0x696) [0x55a672ca05c6]
16  /opt/conda/envs/gdf/bin/python(+0x1407c2) [0x55a672cb07c2]
17  /opt/conda/envs/gdf/bin/python(+0x14de83) [0x55a672cbde83]
18  /opt/conda/envs/gdf/bin/python(+0x258b2c) [0x55a672dc8b2c]
19  /opt/conda/envs/gdf/bin/python(+0xead05) [0x55a672c5ad05]
20  /opt/conda/envs/gdf/bin/python(+0x1377f3) [0x55a672ca77f3]
21  /opt/conda/envs/gdf/bin/python(_PyEval_EvalFrameDefault+0x59f9) [0x55a672ca5929]
22  /opt/conda/envs/gdf/bin/python(+0x1407c2) [0x55a672cb07c2]
23  /opt/conda/envs/gdf/bin/python(_PyEval_EvalFrameDefault+0x696) [0x55a672ca05c6]
24  /opt/conda/envs/gdf/bin/python(+0x1407c2) [0x55a672cb07c2]
25  /opt/conda/envs/gdf/bin/python(_PyEval_EvalFrameDefault+0x696) [0x55a672ca05c6]
26  /opt/conda/envs/gdf/bin/python(+0x1407c2) [0x55a672cb07c2]
27  /opt/conda/envs/gdf/bin/python(_PyEval_EvalFrameDefault+0x696) [0x55a672ca05c6]
28  /opt/conda/envs/gdf/bin/python(+0x1407c2) [0x55a672cb07c2]
29  /opt/conda/envs/gdf/bin/python(_PyEval_EvalFrameDefault+0x696) [0x55a672ca05c6]
30  /opt/conda/envs/gdf/bin/python(+0x12f094) [0x55a672c9f094]
31  /opt/conda/envs/gdf/bin/python(_PyFunction_Vectorcall+0xd9) [0x55a672cb0519]
32  /opt/conda/envs/gdf/bin/python(_PyEval_EvalFrameDefault+0x11f8) [0x55a672ca1128]
33  /opt/conda/envs/gdf/bin/python(+0x12f094) [0x55a672c9f094]
34  /opt/conda/envs/gdf/bin/python(+0x14dccb) [0x55a672cbdccb]
35  /opt/conda/envs/gdf/bin/python(PyObject_Call+0xbc) [0x55a672cbe44c]
36  /opt/conda/envs/gdf/bin/python(+0x21110e) [0x55a672d8110e]
37  /opt/conda/envs/gdf/bin/python(_PyObject_MakeTpCall+0x2ec) [0x55a672ca877c]
38  /opt/conda/envs/gdf/bin/python(_PyEval_EvalFrameDefault+0x37cb) [0x55a672ca36fb]
39  /opt/conda/envs/gdf/bin/python(+0x1407c2) [0x55a672cb07c2]
40  /opt/conda/envs/gdf/bin/python(+0x14ddac) [0x55a672cbddac]
41  /opt/conda/envs/gdf/bin/python(_PyEval_EvalFrameDefault+0x37cb) [0x55a672ca36fb]
42  /opt/conda/envs/gdf/bin/python(+0x1407c2) [0x55a672cb07c2]
43  /opt/conda/envs/gdf/bin/python(_PyEval_EvalFrameDefault+0x696) [0x55a672ca05c6]
44  /opt/conda/envs/gdf/bin/python(+0x12f094) [0x55a672c9f094]
45  /opt/conda/envs/gdf/bin/python(_PyFunction_Vectorcall+0xd9) [0x55a672cb0519]
46  /opt/conda/envs/gdf/bin/python(_PyEval_EvalFrameDefault+0x696) [0x55a672ca05c6]
47  /opt/conda/envs/gdf/bin/python(+0x1407c2) [0x55a672cb07c2]
48  /opt/conda/envs/gdf/bin/python(_PyEval_EvalFrameDefault+0x3e2) [0x55a672ca0312]
49  /opt/conda/envs/gdf/bin/python(+0x12f094) [0x55a672c9f094]
50  /opt/conda/envs/gdf/bin/python(_PyFunction_Vectorcall+0xd9) [0x55a672cb0519]
51  /opt/conda/envs/gdf/bin/python(_PyEval_EvalFrameDefault+0x11f8) [0x55a672ca1128]
52  /opt/conda/envs/gdf/bin/python(+0x12f094) [0x55a672c9f094]
53  /opt/conda/envs/gdf/bin/python(_PyEval_EvalCodeWithName+0x48) [0x55a672c9ed68]
54  /opt/conda/envs/gdf/bin/python(PyEval_EvalCodeEx+0x39) [0x55a672c9ed19]
55  /opt/conda/envs/gdf/bin/python(PyEval_EvalCode+0x1b) [0x55a672d4c07b]
56  /opt/conda/envs/gdf/bin/python(+0x208fca) [0x55a672d78fca]
57  /opt/conda/envs/gdf/bin/python(+0x205353) [0x55a672d75353]
58  /opt/conda/envs/gdf/bin/python(PyRun_StringFlags+0x9a) [0x55a672d6d16a]
59  /opt/conda/envs/gdf/bin/python(PyRun_SimpleStringFlags+0x3c) [0x55a672d6d05c]
60  /opt/conda/envs/gdf/bin/python(Py_RunMain+0x267) [0x55a672d6c297]
61  /opt/conda/envs/gdf/bin/python(Py_BytesMain+0x37) [0x55a672d3ff07]
=================================
[dgx13:72791:0:72791] Caught signal 11 (Segmentation fault: address not mapped to object at address 0x448)
==== backtrace (tid:  72791) ====
 0  /opt/conda/envs/gdf/lib/libucs.so.0(ucs_handle_error+0x2fd) [0x7f6b119d006d]
 1  /opt/conda/envs/gdf/lib/libucs.so.0(+0x2a264) [0x7f6b119d0264]
 2  /opt/conda/envs/gdf/lib/libucs.so.0(+0x2a42a) [0x7f6b119d042a]
 3  /usr/lib/x86_64-linux-gnu/libpthread.so.0(+0x14420) [0x7f6bb6b4b420]
 4  /opt/conda/envs/gdf/lib/libucp.so.0(ucp_mem_type_unpack+0x14) [0x7f6b11a4e6a4]
 5  /opt/conda/envs/gdf/lib/libucp.so.0(ucp_rndv_data_handler+0x4e9) [0x7f6b11a77829]
 6  /opt/conda/envs/gdf/lib/./libuct.so.0(+0x2146f) [0x7f6b1198a46f]
 7  /opt/conda/envs/gdf/lib/./libuct.so.0(+0x248c8) [0x7f6b1198d8c8]
 8  /opt/conda/envs/gdf/lib/libucs.so.0(ucs_event_set_wait+0xb9) [0x7f6b119d9499]
 9  /opt/conda/envs/gdf/lib/./libuct.so.0(uct_tcp_iface_progress+0x7d) [0x7f6b1198c66d]
10  /opt/conda/envs/gdf/lib/libucp.so.0(ucp_worker_progress+0x5a) [0x7f6b11a4b8ca]
11  /opt/conda/envs/gdf/lib/python3.9/site-packages/ucp/_libs/ucx_api.cpython-39-x86_64-linux-gnu.so(+0x3206a) [0x7f6b11b0406a]
12  /opt/conda/envs/gdf/bin/python(_PyEval_EvalFrameDefault+0x37cb) [0x55fedca366fb]
13  /opt/conda/envs/gdf/bin/python(+0x12f094) [0x55fedca32094]
14  /opt/conda/envs/gdf/bin/python(_PyFunction_Vectorcall+0xd9) [0x55fedca43519]
15  /opt/conda/envs/gdf/bin/python(_PyEval_EvalFrameDefault+0x696) [0x55fedca335c6]
16  /opt/conda/envs/gdf/bin/python(+0x1407c2) [0x55fedca437c2]
17  /opt/conda/envs/gdf/bin/python(+0x14de83) [0x55fedca50e83]
18  /opt/conda/envs/gdf/bin/python(+0x258b2c) [0x55fedcb5bb2c]
19  /opt/conda/envs/gdf/bin/python(+0xead05) [0x55fedc9edd05]
20  /opt/conda/envs/gdf/bin/python(+0x1377f3) [0x55fedca3a7f3]
21  /opt/conda/envs/gdf/bin/python(_PyEval_EvalFrameDefault+0x59f9) [0x55fedca38929]
22  /opt/conda/envs/gdf/bin/python(+0x1407c2) [0x55fedca437c2]
23  /opt/conda/envs/gdf/bin/python(_PyEval_EvalFrameDefault+0x696) [0x55fedca335c6]
24  /opt/conda/envs/gdf/bin/python(+0x1407c2) [0x55fedca437c2]
25  /opt/conda/envs/gdf/bin/python(_PyEval_EvalFrameDefault+0x696) [0x55fedca335c6]
26  /opt/conda/envs/gdf/bin/python(+0x1407c2) [0x55fedca437c2]
27  /opt/conda/envs/gdf/bin/python(_PyEval_EvalFrameDefault+0x696) [0x55fedca335c6]
28  /opt/conda/envs/gdf/bin/python(+0x1407c2) [0x55fedca437c2]
29  /opt/conda/envs/gdf/bin/python(_PyEval_EvalFrameDefault+0x696) [0x55fedca335c6]
30  /opt/conda/envs/gdf/bin/python(+0x12f094) [0x55fedca32094]
31  /opt/conda/envs/gdf/bin/python(_PyFunction_Vectorcall+0xd9) [0x55fedca43519]
32  /opt/conda/envs/gdf/bin/python(_PyEval_EvalFrameDefault+0x11f8) [0x55fedca34128]
33  /opt/conda/envs/gdf/bin/python(+0x12f094) [0x55fedca32094]
34  /opt/conda/envs/gdf/bin/python(+0x14dccb) [0x55fedca50ccb]
35  /opt/conda/envs/gdf/bin/python(PyObject_Call+0xbc) [0x55fedca5144c]
36  /opt/conda/envs/gdf/bin/python(+0x21110e) [0x55fedcb1410e]
37  /opt/conda/envs/gdf/bin/python(_PyObject_MakeTpCall+0x2ec) [0x55fedca3b77c]
38  /opt/conda/envs/gdf/bin/python(_PyEval_EvalFrameDefault+0x37cb) [0x55fedca366fb]
39  /opt/conda/envs/gdf/bin/python(+0x1407c2) [0x55fedca437c2]
40  /opt/conda/envs/gdf/bin/python(+0x14ddac) [0x55fedca50dac]
41  /opt/conda/envs/gdf/bin/python(_PyEval_EvalFrameDefault+0x37cb) [0x55fedca366fb]
42  /opt/conda/envs/gdf/bin/python(+0x1407c2) [0x55fedca437c2]
43  /opt/conda/envs/gdf/bin/python(_PyEval_EvalFrameDefault+0x696) [0x55fedca335c6]
44  /opt/conda/envs/gdf/bin/python(+0x12f094) [0x55fedca32094]
45  /opt/conda/envs/gdf/bin/python(_PyFunction_Vectorcall+0xd9) [0x55fedca43519]
46  /opt/conda/envs/gdf/bin/python(_PyEval_EvalFrameDefault+0x696) [0x55fedca335c6]
47  /opt/conda/envs/gdf/bin/python(+0x1407c2) [0x55fedca437c2]
48  /opt/conda/envs/gdf/bin/python(_PyEval_EvalFrameDefault+0x3e2) [0x55fedca33312]
49  /opt/conda/envs/gdf/bin/python(+0x12f094) [0x55fedca32094]
50  /opt/conda/envs/gdf/bin/python(_PyFunction_Vectorcall+0xd9) [0x55fedca43519]
51  /opt/conda/envs/gdf/bin/python(_PyEval_EvalFrameDefault+0x11f8) [0x55fedca34128]
52  /opt/conda/envs/gdf/bin/python(+0x12f094) [0x55fedca32094]
53  /opt/conda/envs/gdf/bin/python(_PyEval_EvalCodeWithName+0x48) [0x55fedca31d68]
54  /opt/conda/envs/gdf/bin/python(PyEval_EvalCodeEx+0x39) [0x55fedca31d19]
55  /opt/conda/envs/gdf/bin/python(PyEval_EvalCode+0x1b) [0x55fedcadf07b]
56  /opt/conda/envs/gdf/bin/python(+0x208fca) [0x55fedcb0bfca]
57  /opt/conda/envs/gdf/bin/python(+0x205353) [0x55fedcb08353]
58  /opt/conda/envs/gdf/bin/python(PyRun_StringFlags+0x9a) [0x55fedcb0016a]
59  /opt/conda/envs/gdf/bin/python(PyRun_SimpleStringFlags+0x3c) [0x55fedcb0005c]
60  /opt/conda/envs/gdf/bin/python(Py_RunMain+0x267) [0x55fedcaff297]
61  /opt/conda/envs/gdf/bin/python(Py_BytesMain+0x37) [0x55fedcad2f07]
=================================
2023-11-05 05:51:44,871 - distributed.worker - ERROR - Worker stream died during communication: ucx://127.0.0.1:41461
Traceback (most recent call last):
  File "/opt/conda/envs/gdf/lib/python3.9/site-packages/distributed/comm/ucx.py", line 396, in read
    await self.ep.recv(each_frame)
  File "/opt/conda/envs/gdf/lib/python3.9/site-packages/ucp/core.py", line 725, in recv
    ret = await comm.tag_recv(self._ep, buffer, nbytes, tag, name=log)
ucp._libs.exceptions.UCXCanceled: <[Recv #008] ep: 0x7f9b091a01c0, tag: 0x5b69ca047791e564, nbytes: 100000000, type: <class 'rmm._lib.device_buffer.DeviceBuffer'>>: 

During handling of the above exception, another exception occurred:

Traceback (most recent call last):
  File "/opt/conda/envs/gdf/lib/python3.9/site-packages/distributed/worker.py", line 2059, in gather_dep
    response = await get_data_from_worker(
  File "/opt/conda/envs/gdf/lib/python3.9/site-packages/distributed/worker.py", line 2852, in get_data_from_worker
    response = await send_recv(
  File "/opt/conda/envs/gdf/lib/python3.9/site-packages/distributed/core.py", line 1106, in send_recv
    response = await comm.read(deserializers=deserializers)
  File "/opt/conda/envs/gdf/lib/python3.9/site-packages/distributed/utils.py", line 803, in wrapper
    return await func(*args, **kwargs)
  File "/opt/conda/envs/gdf/lib/python3.9/site-packages/distributed/comm/ucx.py", line 402, in read
    raise CommClosedError(
distributed.comm.core.CommClosedError: Connection closed by writer.
Inner exception: UCXCanceled("<[Recv #008] ep: 0x7f9b091a01c0, tag: 0x5b69ca047791e564, nbytes: 100000000, type: <class 'rmm._lib.device_buffer.DeviceBuffer'>>: ")
2023-11-05 05:51:44,871 - distributed.worker - ERROR - Worker stream died during communication: ucx://127.0.0.1:41461
Traceback (most recent call last):
  File "/opt/conda/envs/gdf/lib/python3.9/site-packages/distributed/comm/ucx.py", line 396, in read
    await self.ep.recv(each_frame)
  File "/opt/conda/envs/gdf/lib/python3.9/site-packages/ucp/core.py", line 725, in recv
    ret = await comm.tag_recv(self._ep, buffer, nbytes, tag, name=log)
ucp._libs.exceptions.UCXError: <[Recv #007] ep: 0x7f8bad025200, tag: 0x208935959fa74579, nbytes: 100000000, type: <class 'rmm._lib.device_buffer.DeviceBuffer'>>: Connection reset by remote peer

During handling of the above exception, another exception occurred:

Traceback (most recent call last):
  File "/opt/conda/envs/gdf/lib/python3.9/site-packages/distributed/worker.py", line 2059, in gather_dep
    response = await get_data_from_worker(
  File "/opt/conda/envs/gdf/lib/python3.9/site-packages/distributed/worker.py", line 2852, in get_data_from_worker
    response = await send_recv(
  File "/opt/conda/envs/gdf/lib/python3.9/site-packages/distributed/core.py", line 1106, in send_recv
    response = await comm.read(deserializers=deserializers)
  File "/opt/conda/envs/gdf/lib/python3.9/site-packages/distributed/utils.py", line 803, in wrapper
    return await func(*args, **kwargs)
  File "/opt/conda/envs/gdf/lib/python3.9/site-packages/distributed/comm/ucx.py", line 402, in read
    raise CommClosedError(
distributed.comm.core.CommClosedError: Connection closed by writer.
Inner exception: UCXError("<[Recv #007] ep: 0x7f8bad025200, tag: 0x208935959fa74579, nbytes: 100000000, type: <class 'rmm._lib.device_buffer.DeviceBuffer'>>: Connection reset by remote peer")
2023-11-05 05:51:44,873 - distributed.worker - ERROR - failed during get data with ucx://127.0.0.1:51881 -> ucx://127.0.0.1:41461
Traceback (most recent call last):
  File "/opt/conda/envs/gdf/lib/python3.9/site-packages/distributed/comm/ucx.py", line 338, in write
    await self.ep.send(each_frame)
  File "/opt/conda/envs/gdf/lib/python3.9/site-packages/ucp/core.py", line 650, in send
    return await comm.tag_send(self._ep, buffer, nbytes, tag, name=log)
ucp._libs.exceptions.UCXError: <[Send #007] ep: 0x7f8bad025340, tag: 0x79388ef62b8a3f5, nbytes: 100000000, type: <class 'cudf.core.buffer.buffer.Buffer'>>: Connection reset by remote peer

During handling of the above exception, another exception occurred:

Traceback (most recent call last):
  File "/opt/conda/envs/gdf/lib/python3.9/site-packages/distributed/worker.py", line 1782, in get_data
    compressed = await comm.write(msg, serializers=serializers)
  File "/opt/conda/envs/gdf/lib/python3.9/site-packages/distributed/utils.py", line 803, in wrapper
    return await func(*args, **kwargs)
  File "/opt/conda/envs/gdf/lib/python3.9/site-packages/distributed/comm/ucx.py", line 342, in write
    raise CommClosedError("While writing, the connection was closed")
distributed.comm.core.CommClosedError: While writing, the connection was closed
2023-11-05 05:51:44,919 - distributed.worker - ERROR - Worker stream died during communication: ucx://127.0.0.1:52765
Traceback (most recent call last):
  File "/opt/conda/envs/gdf/lib/python3.9/site-packages/distributed/comm/ucx.py", line 354, in read
    await self.ep.recv(msg)
  File "/opt/conda/envs/gdf/lib/python3.9/site-packages/ucp/core.py", line 725, in recv
    ret = await comm.tag_recv(self._ep, buffer, nbytes, tag, name=log)
ucp._libs.exceptions.UCXCanceled: <[Recv #003] ep: 0x7f8bad025140, tag: 0x2c4737d510e58e53, nbytes: 16, type: <class 'numpy.ndarray'>>: 

During handling of the above exception, another exception occurred:

Traceback (most recent call last):
  File "/opt/conda/envs/gdf/lib/python3.9/site-packages/distributed/worker.py", line 2059, in gather_dep
    response = await get_data_from_worker(
  File "/opt/conda/envs/gdf/lib/python3.9/site-packages/distributed/worker.py", line 2852, in get_data_from_worker
    response = await send_recv(
  File "/opt/conda/envs/gdf/lib/python3.9/site-packages/distributed/core.py", line 1106, in send_recv
    response = await comm.read(deserializers=deserializers)
  File "/opt/conda/envs/gdf/lib/python3.9/site-packages/distributed/utils.py", line 803, in wrapper
    return await func(*args, **kwargs)
  File "/opt/conda/envs/gdf/lib/python3.9/site-packages/distributed/comm/ucx.py", line 372, in read
    raise CommClosedError(
distributed.comm.core.CommClosedError: Connection closed by writer.
Inner exception: UCXCanceled("<[Recv #003] ep: 0x7f8bad025140, tag: 0x2c4737d510e58e53, nbytes: 16, type: <class 'numpy.ndarray'>>: ")
2023-11-05 05:51:44,919 - distributed.worker - ERROR - Worker stream died during communication: ucx://127.0.0.1:52765
Traceback (most recent call last):
  File "/opt/conda/envs/gdf/lib/python3.9/site-packages/distributed/comm/ucx.py", line 354, in read
    await self.ep.recv(msg)
  File "/opt/conda/envs/gdf/lib/python3.9/site-packages/ucp/core.py", line 725, in recv
    ret = await comm.tag_recv(self._ep, buffer, nbytes, tag, name=log)
ucp._libs.exceptions.UCXCanceled: <[Recv #003] ep: 0x7f9b091a0140, tag: 0xd29beecb64a4237, nbytes: 16, type: <class 'numpy.ndarray'>>: 

During handling of the above exception, another exception occurred:

Traceback (most recent call last):
  File "/opt/conda/envs/gdf/lib/python3.9/site-packages/distributed/worker.py", line 2059, in gather_dep
    response = await get_data_from_worker(
  File "/opt/conda/envs/gdf/lib/python3.9/site-packages/distributed/worker.py", line 2852, in get_data_from_worker
    response = await send_recv(
  File "/opt/conda/envs/gdf/lib/python3.9/site-packages/distributed/core.py", line 1106, in send_recv
    response = await comm.read(deserializers=deserializers)
  File "/opt/conda/envs/gdf/lib/python3.9/site-packages/distributed/utils.py", line 803, in wrapper
    return await func(*args, **kwargs)
  File "/opt/conda/envs/gdf/lib/python3.9/site-packages/distributed/comm/ucx.py", line 372, in read
    raise CommClosedError(
distributed.comm.core.CommClosedError: Connection closed by writer.
Inner exception: UCXCanceled("<[Recv #003] ep: 0x7f9b091a0140, tag: 0xd29beecb64a4237, nbytes: 16, type: <class 'numpy.ndarray'>>: ")
2023-11-05 05:51:44,920 - distributed.worker - ERROR - failed during get data with ucx://127.0.0.1:34083 -> ucx://127.0.0.1:52765
Traceback (most recent call last):
  File "/opt/conda/envs/gdf/lib/python3.9/site-packages/distributed/comm/ucx.py", line 338, in write
    await self.ep.send(each_frame)
  File "/opt/conda/envs/gdf/lib/python3.9/site-packages/ucp/core.py", line 650, in send
    return await comm.tag_send(self._ep, buffer, nbytes, tag, name=log)
ucp._libs.exceptions.UCXError: <[Send #007] ep: 0x7f9b091a0280, tag: 0x36b612088d3af97a, nbytes: 100000000, type: <class 'cudf.core.buffer.buffer.Buffer'>>: Connection reset by remote peer

During handling of the above exception, another exception occurred:

Traceback (most recent call last):
  File "/opt/conda/envs/gdf/lib/python3.9/site-packages/distributed/worker.py", line 1782, in get_data
    compressed = await comm.write(msg, serializers=serializers)
  File "/opt/conda/envs/gdf/lib/python3.9/site-packages/distributed/utils.py", line 803, in wrapper
    return await func(*args, **kwargs)
  File "/opt/conda/envs/gdf/lib/python3.9/site-packages/distributed/comm/ucx.py", line 342, in write
    raise CommClosedError("While writing, the connection was closed")
distributed.comm.core.CommClosedError: While writing, the connection was closed
2023-11-05 05:51:44,919 - distributed.worker - ERROR - Worker stream died during communication: ucx://127.0.0.1:52765
Traceback (most recent call last):
  File "/opt/conda/envs/gdf/lib/python3.9/site-packages/distributed/comm/ucx.py", line 354, in read
    await self.ep.recv(msg)
  File "/opt/conda/envs/gdf/lib/python3.9/site-packages/ucp/core.py", line 725, in recv
    ret = await comm.tag_recv(self._ep, buffer, nbytes, tag, name=log)
ucp._libs.exceptions.UCXCanceled: <[Recv #003] ep: 0x7f8898de91c0, tag: 0x2c50e89862da4b97, nbytes: 16, type: <class 'numpy.ndarray'>>: 

During handling of the above exception, another exception occurred:

Traceback (most recent call last):
  File "/opt/conda/envs/gdf/lib/python3.9/site-packages/distributed/worker.py", line 2059, in gather_dep
    response = await get_data_from_worker(
  File "/opt/conda/envs/gdf/lib/python3.9/site-packages/distributed/worker.py", line 2852, in get_data_from_worker
    response = await send_recv(
  File "/opt/conda/envs/gdf/lib/python3.9/site-packages/distributed/core.py", line 1106, in send_recv
    response = await comm.read(deserializers=deserializers)
  File "/opt/conda/envs/gdf/lib/python3.9/site-packages/distributed/utils.py", line 803, in wrapper
    return await func(*args, **kwargs)
  File "/opt/conda/envs/gdf/lib/python3.9/site-packages/distributed/comm/ucx.py", line 372, in read
    raise CommClosedError(
distributed.comm.core.CommClosedError: Connection closed by writer.
Inner exception: UCXCanceled("<[Recv #003] ep: 0x7f8898de91c0, tag: 0x2c50e89862da4b97, nbytes: 16, type: <class 'numpy.ndarray'>>: ")
2023-11-05 05:51:44,921 - distributed.worker - ERROR - failed during get data with ucx://127.0.0.1:42981 -> ucx://127.0.0.1:52765
Traceback (most recent call last):
  File "/opt/conda/envs/gdf/lib/python3.9/site-packages/distributed/comm/ucx.py", line 338, in write
    await self.ep.send(each_frame)
  File "/opt/conda/envs/gdf/lib/python3.9/site-packages/ucp/core.py", line 650, in send
    return await comm.tag_send(self._ep, buffer, nbytes, tag, name=log)
ucp._libs.exceptions.UCXError: <[Send #007] ep: 0x7f8898de9280, tag: 0x3bdbf211931183d2, nbytes: 100000000, type: <class 'cudf.core.buffer.buffer.Buffer'>>: Connection reset by remote peer

During handling of the above exception, another exception occurred:

Traceback (most recent call last):
  File "/opt/conda/envs/gdf/lib/python3.9/site-packages/distributed/worker.py", line 1782, in get_data
    compressed = await comm.write(msg, serializers=serializers)
  File "/opt/conda/envs/gdf/lib/python3.9/site-packages/distributed/utils.py", line 803, in wrapper
    return await func(*args, **kwargs)
  File "/opt/conda/envs/gdf/lib/python3.9/site-packages/distributed/comm/ucx.py", line 342, in write
    raise CommClosedError("While writing, the connection was closed")
distributed.comm.core.CommClosedError: While writing, the connection was closed
2023-11-05 05:51:44,958 - distributed.worker - ERROR - Worker stream died during communication: ucx://127.0.0.1:49541
Traceback (most recent call last):
  File "/opt/conda/envs/gdf/lib/python3.9/site-packages/distributed/comm/ucx.py", line 396, in read
    await self.ep.recv(each_frame)
  File "/opt/conda/envs/gdf/lib/python3.9/site-packages/ucp/core.py", line 725, in recv
    ret = await comm.tag_recv(self._ep, buffer, nbytes, tag, name=log)
ucp._libs.exceptions.UCXError: <[Recv #007] ep: 0x7f8898de9200, tag: 0x79138402971f6604, nbytes: 100000000, type: <class 'rmm._lib.device_buffer.DeviceBuffer'>>: Connection reset by remote peer

During handling of the above exception, another exception occurred:

Traceback (most recent call last):
  File "/opt/conda/envs/gdf/lib/python3.9/site-packages/distributed/worker.py", line 2059, in gather_dep
    response = await get_data_from_worker(
  File "/opt/conda/envs/gdf/lib/python3.9/site-packages/distributed/worker.py", line 2852, in get_data_from_worker
    response = await send_recv(
  File "/opt/conda/envs/gdf/lib/python3.9/site-packages/distributed/core.py", line 1106, in send_recv
    response = await comm.read(deserializers=deserializers)
  File "/opt/conda/envs/gdf/lib/python3.9/site-packages/distributed/utils.py", line 803, in wrapper
    return await func(*args, **kwargs)
  File "/opt/conda/envs/gdf/lib/python3.9/site-packages/distributed/comm/ucx.py", line 402, in read
    raise CommClosedError(
distributed.comm.core.CommClosedError: Connection closed by writer.
Inner exception: UCXError("<[Recv #007] ep: 0x7f8898de9200, tag: 0x79138402971f6604, nbytes: 100000000, type: <class 'rmm._lib.device_buffer.DeviceBuffer'>>: Connection reset by remote peer")
2023-11-05 05:51:45,001 - distributed.worker - ERROR - Worker stream died during communication: ucx://127.0.0.1:49541
Traceback (most recent call last):
  File "/opt/conda/envs/gdf/lib/python3.9/site-packages/distributed/comm/ucx.py", line 354, in read
    await self.ep.recv(msg)
  File "/opt/conda/envs/gdf/lib/python3.9/site-packages/ucp/core.py", line 725, in recv
    ret = await comm.tag_recv(self._ep, buffer, nbytes, tag, name=log)
ucp._libs.exceptions.UCXCanceled: <[Recv #003] ep: 0x7f9b091a0240, tag: 0x5796c3991b3d17e5, nbytes: 16, type: <class 'numpy.ndarray'>>: 

During handling of the above exception, another exception occurred:

Traceback (most recent call last):
  File "/opt/conda/envs/gdf/lib/python3.9/site-packages/distributed/worker.py", line 2059, in gather_dep
    response = await get_data_from_worker(
  File "/opt/conda/envs/gdf/lib/python3.9/site-packages/distributed/worker.py", line 2852, in get_data_from_worker
    response = await send_recv(
  File "/opt/conda/envs/gdf/lib/python3.9/site-packages/distributed/core.py", line 1106, in send_recv
    response = await comm.read(deserializers=deserializers)
  File "/opt/conda/envs/gdf/lib/python3.9/site-packages/distributed/utils.py", line 803, in wrapper
    return await func(*args, **kwargs)
  File "/opt/conda/envs/gdf/lib/python3.9/site-packages/distributed/comm/ucx.py", line 372, in read
    raise CommClosedError(
distributed.comm.core.CommClosedError: Connection closed by writer.
Inner exception: UCXCanceled("<[Recv #003] ep: 0x7f9b091a0240, tag: 0x5796c3991b3d17e5, nbytes: 16, type: <class 'numpy.ndarray'>>: ")
2023-11-05 05:51:45,001 - distributed.worker - ERROR - Worker stream died during communication: ucx://127.0.0.1:49541
Traceback (most recent call last):
  File "/opt/conda/envs/gdf/lib/python3.9/site-packages/distributed/comm/ucx.py", line 396, in read
    await self.ep.recv(each_frame)
  File "/opt/conda/envs/gdf/lib/python3.9/site-packages/ucp/core.py", line 725, in recv
    ret = await comm.tag_recv(self._ep, buffer, nbytes, tag, name=log)
ucp._libs.exceptions.UCXCanceled: <[Recv #008] ep: 0x7f8bad025180, tag: 0x6e226ca8cbd804f7, nbytes: 100000000, type: <class 'rmm._lib.device_buffer.DeviceBuffer'>>: 

During handling of the above exception, another exception occurred:

Traceback (most recent call last):
  File "/opt/conda/envs/gdf/lib/python3.9/site-packages/distributed/worker.py", line 2059, in gather_dep
    response = await get_data_from_worker(
  File "/opt/conda/envs/gdf/lib/python3.9/site-packages/distributed/worker.py", line 2852, in get_data_from_worker
    response = await send_recv(
  File "/opt/conda/envs/gdf/lib/python3.9/site-packages/distributed/core.py", line 1106, in send_recv
    response = await comm.read(deserializers=deserializers)
  File "/opt/conda/envs/gdf/lib/python3.9/site-packages/distributed/utils.py", line 803, in wrapper
    return await func(*args, **kwargs)
  File "/opt/conda/envs/gdf/lib/python3.9/site-packages/distributed/comm/ucx.py", line 402, in read
    raise CommClosedError(
distributed.comm.core.CommClosedError: Connection closed by writer.
Inner exception: UCXCanceled("<[Recv #008] ep: 0x7f8bad025180, tag: 0x6e226ca8cbd804f7, nbytes: 100000000, type: <class 'rmm._lib.device_buffer.DeviceBuffer'>>: ")
2023-11-05 05:51:45,051 - distributed.worker - ERROR - failed during get data with ucx://127.0.0.1:51881 -> ucx://127.0.0.1:49129
Traceback (most recent call last):
  File "/opt/conda/envs/gdf/lib/python3.9/site-packages/distributed/comm/ucx.py", line 338, in write
    await self.ep.send(each_frame)
  File "/opt/conda/envs/gdf/lib/python3.9/site-packages/ucp/core.py", line 650, in send
    return await comm.tag_send(self._ep, buffer, nbytes, tag, name=log)
ucp._libs.exceptions.UCXError: <[Send #007] ep: 0x7f8bad025380, tag: 0xca36c645243f5242, nbytes: 100000000, type: <class 'cudf.core.buffer.buffer.Buffer'>>: Connection reset by remote peer

During handling of the above exception, another exception occurred:

Traceback (most recent call last):
  File "/opt/conda/envs/gdf/lib/python3.9/site-packages/distributed/worker.py", line 1782, in get_data
    compressed = await comm.write(msg, serializers=serializers)
  File "/opt/conda/envs/gdf/lib/python3.9/site-packages/distributed/utils.py", line 803, in wrapper
    return await func(*args, **kwargs)
  File "/opt/conda/envs/gdf/lib/python3.9/site-packages/distributed/comm/ucx.py", line 342, in write
    raise CommClosedError("While writing, the connection was closed")
distributed.comm.core.CommClosedError: While writing, the connection was closed
2023-11-05 05:51:51,351 - distributed.nanny - WARNING - Restarting worker
/opt/conda/envs/gdf/lib/python3.9/multiprocessing/resource_tracker.py:216: UserWarning: resource_tracker: There appear to be 24 leaked semaphore objects to clean up at shutdown
  warnings.warn('resource_tracker: There appear to be %d '
