2023-03-08 00:00:26,478 - distributed.preloading - INFO - Creating preload: dask_cuda.initialize
2023-03-08 00:00:26,478 - distributed.preloading - INFO - Creating preload: dask_cuda.initialize
2023-03-08 00:00:26,478 - distributed.preloading - INFO - Import preload module: dask_cuda.initialize
2023-03-08 00:00:26,478 - distributed.preloading - INFO - Import preload module: dask_cuda.initialize
2023-03-08 00:00:26,478 - distributed.preloading - INFO - Creating preload: dask_cuda.initialize
2023-03-08 00:00:26,479 - distributed.preloading - INFO - Import preload module: dask_cuda.initialize
2023-03-08 00:00:26,479 - distributed.preloading - INFO - Creating preload: dask_cuda.initialize
2023-03-08 00:00:26,479 - distributed.preloading - INFO - Import preload module: dask_cuda.initialize
2023-03-08 00:00:26,485 - distributed.preloading - INFO - Creating preload: dask_cuda.initialize
2023-03-08 00:00:26,485 - distributed.preloading - INFO - Import preload module: dask_cuda.initialize
2023-03-08 00:00:26,485 - distributed.preloading - INFO - Creating preload: dask_cuda.initialize
2023-03-08 00:00:26,485 - distributed.preloading - INFO - Import preload module: dask_cuda.initialize
2023-03-08 00:00:26,530 - distributed.preloading - INFO - Creating preload: dask_cuda.initialize
2023-03-08 00:00:26,530 - distributed.preloading - INFO - Import preload module: dask_cuda.initialize
2023-03-08 00:00:26,531 - distributed.preloading - INFO - Creating preload: dask_cuda.initialize
2023-03-08 00:00:26,531 - distributed.preloading - INFO - Import preload module: dask_cuda.initialize
[dgx13:45792:0:45792] Caught signal 11 (Segmentation fault: address not mapped to object at address 0x448)
==== backtrace (tid:  45792) ====
 0  /datasets/pentschev/miniconda3/envs/gdf/lib/libucs.so.0(ucs_handle_error+0x2d4) [0x7f3cdcdce614]
 1  /datasets/pentschev/miniconda3/envs/gdf/lib/libucs.so.0(+0x2e7ef) [0x7f3cdcdce7ef]
 2  /datasets/pentschev/miniconda3/envs/gdf/lib/libucs.so.0(+0x2eb14) [0x7f3cdcdceb14]
 3  /lib/x86_64-linux-gnu/libpthread.so.0(+0x12980) [0x7f3d60790980]
 4  /datasets/pentschev/miniconda3/envs/gdf/lib/libucp.so.0(ucp_mem_type_unpack+0x14) [0x7f3cdd0533b4]
 5  /datasets/pentschev/miniconda3/envs/gdf/lib/libucp.so.0(ucp_rndv_data_handler+0x508) [0x7f3cdd083a08]
 6  /datasets/pentschev/miniconda3/envs/gdf/lib/libuct.so.0(+0x20b5f) [0x7f3cdcb82b5f]
 7  /datasets/pentschev/miniconda3/envs/gdf/lib/libuct.so.0(+0x21134) [0x7f3cdcb83134]
 8  /datasets/pentschev/miniconda3/envs/gdf/lib/libuct.so.0(+0x23578) [0x7f3cdcb85578]
 9  /datasets/pentschev/miniconda3/envs/gdf/lib/libucs.so.0(ucs_event_set_wait+0xb9) [0x7f3cdcdd8c99]
10  /datasets/pentschev/miniconda3/envs/gdf/lib/libuct.so.0(uct_tcp_iface_progress+0x7b) [0x7f3cdcb8561b]
11  /datasets/pentschev/miniconda3/envs/gdf/lib/libucp.so.0(ucp_worker_progress+0x6a) [0x7f3cdd04fcaa]
12  /datasets/pentschev/miniconda3/envs/gdf/lib/python3.8/site-packages/ucp/_libs/ucx_api.cpython-38-x86_64-linux-gnu.so(+0x272b9) [0x7f3cdd30a2b9]
13  /datasets/pentschev/miniconda3/envs/gdf/bin/python(+0x12e343) [0x562c04c6a343]
14  /datasets/pentschev/miniconda3/envs/gdf/bin/python(PyObject_Call+0x24a) [0x562c04c751fa]
15  /datasets/pentschev/miniconda3/envs/gdf/bin/python(_PyEval_EvalFrameDefault+0x680b) [0x562c04c5bb8b]
16  /datasets/pentschev/miniconda3/envs/gdf/bin/python(_PyEval_EvalCodeWithName+0x2f1) [0x562c04c542f1]
17  /datasets/pentschev/miniconda3/envs/gdf/bin/python(_PyFunction_Vectorcall+0x19c) [0x562c04c6593c]
18  /datasets/pentschev/miniconda3/envs/gdf/bin/python(_PyEval_EvalFrameDefault+0x6d5) [0x562c04c55a55]
19  /datasets/pentschev/miniconda3/envs/gdf/bin/python(+0x13e1e8) [0x562c04c7a1e8]
20  /datasets/pentschev/miniconda3/envs/gdf/lib/python3.8/lib-dynload/_asyncio.cpython-38-x86_64-linux-gnu.so(+0x7003) [0x7f3cfafea003]
21  /datasets/pentschev/miniconda3/envs/gdf/bin/python(_PyObject_MakeTpCall+0x3db) [0x562c04c5e30b]
22  /datasets/pentschev/miniconda3/envs/gdf/bin/python(+0xe0b07) [0x562c04c1cb07]
23  /datasets/pentschev/miniconda3/envs/gdf/bin/python(+0x120f96) [0x562c04c5cf96]
24  /datasets/pentschev/miniconda3/envs/gdf/bin/python(PyVectorcall_Call+0x7a) [0x562c04c731ea]
25  /datasets/pentschev/miniconda3/envs/gdf/bin/python(_PyEval_EvalFrameDefault+0x5df8) [0x562c04c5b178]
26  /datasets/pentschev/miniconda3/envs/gdf/bin/python(_PyFunction_Vectorcall+0x106) [0x562c04c658a6]
27  /datasets/pentschev/miniconda3/envs/gdf/bin/python(_PyEval_EvalFrameDefault+0x6d5) [0x562c04c55a55]
28  /datasets/pentschev/miniconda3/envs/gdf/bin/python(_PyFunction_Vectorcall+0x106) [0x562c04c658a6]
29  /datasets/pentschev/miniconda3/envs/gdf/bin/python(_PyEval_EvalFrameDefault+0x6d5) [0x562c04c55a55]
30  /datasets/pentschev/miniconda3/envs/gdf/bin/python(_PyFunction_Vectorcall+0x106) [0x562c04c658a6]
31  /datasets/pentschev/miniconda3/envs/gdf/bin/python(_PyEval_EvalFrameDefault+0x6d5) [0x562c04c55a55]
32  /datasets/pentschev/miniconda3/envs/gdf/bin/python(_PyFunction_Vectorcall+0x106) [0x562c04c658a6]
33  /datasets/pentschev/miniconda3/envs/gdf/bin/python(_PyEval_EvalFrameDefault+0x6d5) [0x562c04c55a55]
34  /datasets/pentschev/miniconda3/envs/gdf/bin/python(_PyEval_EvalCodeWithName+0x2f1) [0x562c04c542f1]
35  /datasets/pentschev/miniconda3/envs/gdf/bin/python(_PyFunction_Vectorcall+0x19c) [0x562c04c6593c]
36  /datasets/pentschev/miniconda3/envs/gdf/bin/python(_PyEval_EvalFrameDefault+0x4b7b) [0x562c04c59efb]
37  /datasets/pentschev/miniconda3/envs/gdf/bin/python(_PyEval_EvalCodeWithName+0x2f1) [0x562c04c542f1]
38  /datasets/pentschev/miniconda3/envs/gdf/bin/python(_PyFunction_Vectorcall+0x19c) [0x562c04c6593c]
39  /datasets/pentschev/miniconda3/envs/gdf/bin/python(+0x136e8c) [0x562c04c72e8c]
40  /datasets/pentschev/miniconda3/envs/gdf/bin/python(_PyObject_FastCallDict+0x282) [0x562c04c5da92]
41  /datasets/pentschev/miniconda3/envs/gdf/bin/python(+0x1ee049) [0x562c04d2a049]
42  /datasets/pentschev/miniconda3/envs/gdf/bin/python(PyObject_Call+0x2d3) [0x562c04c75283]
43  /datasets/pentschev/miniconda3/envs/gdf/bin/python(_PyEval_EvalFrameDefault+0x205e) [0x562c04c573de]
44  /datasets/pentschev/miniconda3/envs/gdf/bin/python(_PyFunction_Vectorcall+0x106) [0x562c04c658a6]
45  /datasets/pentschev/miniconda3/envs/gdf/bin/python(+0x136e8c) [0x562c04c72e8c]
46  /datasets/pentschev/miniconda3/envs/gdf/bin/python(PyObject_Call+0x24a) [0x562c04c751fa]
47  /datasets/pentschev/miniconda3/envs/gdf/bin/python(_PyEval_EvalFrameDefault+0x205e) [0x562c04c573de]
48  /datasets/pentschev/miniconda3/envs/gdf/bin/python(_PyFunction_Vectorcall+0x106) [0x562c04c658a6]
49  /datasets/pentschev/miniconda3/envs/gdf/bin/python(_PyEval_EvalFrameDefault+0x6d5) [0x562c04c55a55]
50  /datasets/pentschev/miniconda3/envs/gdf/bin/python(_PyEval_EvalCodeWithName+0x2f1) [0x562c04c542f1]
51  /datasets/pentschev/miniconda3/envs/gdf/bin/python(_PyFunction_Vectorcall+0x19c) [0x562c04c6593c]
52  /datasets/pentschev/miniconda3/envs/gdf/bin/python(_PyEval_EvalFrameDefault+0x6d5) [0x562c04c55a55]
53  /datasets/pentschev/miniconda3/envs/gdf/bin/python(_PyFunction_Vectorcall+0x106) [0x562c04c658a6]
54  /datasets/pentschev/miniconda3/envs/gdf/bin/python(_PyEval_EvalFrameDefault+0x3a9) [0x562c04c55729]
55  /datasets/pentschev/miniconda3/envs/gdf/bin/python(_PyEval_EvalCodeWithName+0x2f1) [0x562c04c542f1]
56  /datasets/pentschev/miniconda3/envs/gdf/bin/python(_PyFunction_Vectorcall+0x19c) [0x562c04c6593c]
57  /datasets/pentschev/miniconda3/envs/gdf/bin/python(_PyEval_EvalFrameDefault+0x11bf) [0x562c04c5653f]
58  /datasets/pentschev/miniconda3/envs/gdf/bin/python(_PyEval_EvalCodeWithName+0x2f1) [0x562c04c542f1]
59  /datasets/pentschev/miniconda3/envs/gdf/bin/python(PyEval_EvalCodeEx+0x39) [0x562c04d06e99]
60  /datasets/pentschev/miniconda3/envs/gdf/bin/python(PyEval_EvalCode+0x1b) [0x562c04d06e5b]
61  /datasets/pentschev/miniconda3/envs/gdf/bin/python(+0x1eb7f9) [0x562c04d277f9]
=================================
[dgx13:45768:0:45768] Caught signal 11 (Segmentation fault: address not mapped to object at address 0x448)
==== backtrace (tid:  45768) ====
 0  /datasets/pentschev/miniconda3/envs/gdf/lib/libucs.so.0(ucs_handle_error+0x2d4) [0x7fc2394f5614]
 1  /datasets/pentschev/miniconda3/envs/gdf/lib/libucs.so.0(+0x2e7ef) [0x7fc2394f57ef]
 2  /datasets/pentschev/miniconda3/envs/gdf/lib/libucs.so.0(+0x2eb14) [0x7fc2394f5b14]
 3  /lib/x86_64-linux-gnu/libpthread.so.0(+0x12980) [0x7fc2aef0e980]
 4  /datasets/pentschev/miniconda3/envs/gdf/lib/libucp.so.0(ucp_mem_type_unpack+0x14) [0x7fc23977a3b4]
 5  /datasets/pentschev/miniconda3/envs/gdf/lib/libucp.so.0(ucp_rndv_data_handler+0x508) [0x7fc2397aaa08]
 6  /datasets/pentschev/miniconda3/envs/gdf/lib/libuct.so.0(+0x20b5f) [0x7fc2392a9b5f]
 7  /datasets/pentschev/miniconda3/envs/gdf/lib/libuct.so.0(+0x21134) [0x7fc2392aa134]
 8  /datasets/pentschev/miniconda3/envs/gdf/lib/libuct.so.0(+0x23578) [0x7fc2392ac578]
 9  /datasets/pentschev/miniconda3/envs/gdf/lib/libucs.so.0(ucs_event_set_wait+0xb9) [0x7fc2394ffc99]
10  /datasets/pentschev/miniconda3/envs/gdf/lib/libuct.so.0(uct_tcp_iface_progress+0x7b) [0x7fc2392ac61b]
11  /datasets/pentschev/miniconda3/envs/gdf/lib/libucp.so.0(ucp_worker_progress+0x6a) [0x7fc239776caa]
12  /datasets/pentschev/miniconda3/envs/gdf/lib/python3.8/site-packages/ucp/_libs/ucx_api.cpython-38-x86_64-linux-gnu.so(+0x272b9) [0x7fc239a312b9]
13  /datasets/pentschev/miniconda3/envs/gdf/bin/python(+0x12e343) [0x561dd9916343]
14  /datasets/pentschev/miniconda3/envs/gdf/bin/python(PyObject_Call+0x24a) [0x561dd99211fa]
15  /datasets/pentschev/miniconda3/envs/gdf/bin/python(_PyEval_EvalFrameDefault+0x680b) [0x561dd9907b8b]
16  /datasets/pentschev/miniconda3/envs/gdf/bin/python(_PyEval_EvalCodeWithName+0x2f1) [0x561dd99002f1]
17  /datasets/pentschev/miniconda3/envs/gdf/bin/python(_PyFunction_Vectorcall+0x19c) [0x561dd991193c]
18  /datasets/pentschev/miniconda3/envs/gdf/bin/python(_PyEval_EvalFrameDefault+0x6d5) [0x561dd9901a55]
19  /datasets/pentschev/miniconda3/envs/gdf/bin/python(_PyFunction_Vectorcall+0x106) [0x561dd99118a6]
20  /datasets/pentschev/miniconda3/envs/gdf/bin/python(+0x136c36) [0x561dd991ec36]
21  /datasets/pentschev/miniconda3/envs/gdf/bin/python(+0x23565a) [0x561dd9a1d65a]
22  /datasets/pentschev/miniconda3/envs/gdf/bin/python(+0xe0b07) [0x561dd98c8b07]
23  /datasets/pentschev/miniconda3/envs/gdf/bin/python(+0x120f96) [0x561dd9908f96]
24  /datasets/pentschev/miniconda3/envs/gdf/bin/python(PyVectorcall_Call+0x7a) [0x561dd991f1ea]
25  /datasets/pentschev/miniconda3/envs/gdf/bin/python(_PyEval_EvalFrameDefault+0x5df8) [0x561dd9907178]
26  /datasets/pentschev/miniconda3/envs/gdf/bin/python(_PyFunction_Vectorcall+0x106) [0x561dd99118a6]
27  /datasets/pentschev/miniconda3/envs/gdf/bin/python(_PyEval_EvalFrameDefault+0x6d5) [0x561dd9901a55]
28  /datasets/pentschev/miniconda3/envs/gdf/bin/python(_PyFunction_Vectorcall+0x106) [0x561dd99118a6]
29  /datasets/pentschev/miniconda3/envs/gdf/bin/python(_PyEval_EvalFrameDefault+0x6d5) [0x561dd9901a55]
30  /datasets/pentschev/miniconda3/envs/gdf/bin/python(_PyFunction_Vectorcall+0x106) [0x561dd99118a6]
31  /datasets/pentschev/miniconda3/envs/gdf/bin/python(_PyEval_EvalFrameDefault+0x6d5) [0x561dd9901a55]
32  /datasets/pentschev/miniconda3/envs/gdf/bin/python(_PyFunction_Vectorcall+0x106) [0x561dd99118a6]
33  /datasets/pentschev/miniconda3/envs/gdf/bin/python(_PyEval_EvalFrameDefault+0x6d5) [0x561dd9901a55]
34  /datasets/pentschev/miniconda3/envs/gdf/bin/python(_PyEval_EvalCodeWithName+0x2f1) [0x561dd99002f1]
35  /datasets/pentschev/miniconda3/envs/gdf/bin/python(_PyFunction_Vectorcall+0x19c) [0x561dd991193c]
36  /datasets/pentschev/miniconda3/envs/gdf/bin/python(_PyEval_EvalFrameDefault+0x4b7b) [0x561dd9905efb]
37  /datasets/pentschev/miniconda3/envs/gdf/bin/python(_PyEval_EvalCodeWithName+0x2f1) [0x561dd99002f1]
38  /datasets/pentschev/miniconda3/envs/gdf/bin/python(_PyFunction_Vectorcall+0x19c) [0x561dd991193c]
39  /datasets/pentschev/miniconda3/envs/gdf/bin/python(+0x136e8c) [0x561dd991ee8c]
40  /datasets/pentschev/miniconda3/envs/gdf/bin/python(_PyObject_FastCallDict+0x282) [0x561dd9909a92]
41  /datasets/pentschev/miniconda3/envs/gdf/bin/python(+0x1ee049) [0x561dd99d6049]
42  /datasets/pentschev/miniconda3/envs/gdf/bin/python(PyObject_Call+0x2d3) [0x561dd9921283]
43  /datasets/pentschev/miniconda3/envs/gdf/bin/python(_PyEval_EvalFrameDefault+0x205e) [0x561dd99033de]
44  /datasets/pentschev/miniconda3/envs/gdf/bin/python(_PyFunction_Vectorcall+0x106) [0x561dd99118a6]
45  /datasets/pentschev/miniconda3/envs/gdf/bin/python(+0x136e8c) [0x561dd991ee8c]
46  /datasets/pentschev/miniconda3/envs/gdf/bin/python(PyObject_Call+0x24a) [0x561dd99211fa]
47  /datasets/pentschev/miniconda3/envs/gdf/bin/python(_PyEval_EvalFrameDefault+0x205e) [0x561dd99033de]
48  /datasets/pentschev/miniconda3/envs/gdf/bin/python(_PyFunction_Vectorcall+0x106) [0x561dd99118a6]
49  /datasets/pentschev/miniconda3/envs/gdf/bin/python(_PyEval_EvalFrameDefault+0x6d5) [0x561dd9901a55]
50  /datasets/pentschev/miniconda3/envs/gdf/bin/python(_PyEval_EvalCodeWithName+0x2f1) [0x561dd99002f1]
51  /datasets/pentschev/miniconda3/envs/gdf/bin/python(_PyFunction_Vectorcall+0x19c) [0x561dd991193c]
52  /datasets/pentschev/miniconda3/envs/gdf/bin/python(_PyEval_EvalFrameDefault+0x6d5) [0x561dd9901a55]
53  /datasets/pentschev/miniconda3/envs/gdf/bin/python(_PyFunction_Vectorcall+0x106) [0x561dd99118a6]
54  /datasets/pentschev/miniconda3/envs/gdf/bin/python(_PyEval_EvalFrameDefault+0x3a9) [0x561dd9901729]
55  /datasets/pentschev/miniconda3/envs/gdf/bin/python(_PyEval_EvalCodeWithName+0x2f1) [0x561dd99002f1]
56  /datasets/pentschev/miniconda3/envs/gdf/bin/python(_PyFunction_Vectorcall+0x19c) [0x561dd991193c]
57  /datasets/pentschev/miniconda3/envs/gdf/bin/python(_PyEval_EvalFrameDefault+0x11bf) [0x561dd990253f]
58  /datasets/pentschev/miniconda3/envs/gdf/bin/python(_PyEval_EvalCodeWithName+0x2f1) [0x561dd99002f1]
59  /datasets/pentschev/miniconda3/envs/gdf/bin/python(PyEval_EvalCodeEx+0x39) [0x561dd99b2e99]
60  /datasets/pentschev/miniconda3/envs/gdf/bin/python(PyEval_EvalCode+0x1b) [0x561dd99b2e5b]
61  /datasets/pentschev/miniconda3/envs/gdf/bin/python(+0x1eb7f9) [0x561dd99d37f9]
=================================
[dgx13:45781:0:45781] Caught signal 11 (Segmentation fault: address not mapped to object at address 0x448)
==== backtrace (tid:  45781) ====
 0  /datasets/pentschev/miniconda3/envs/gdf/lib/libucs.so.0(ucs_handle_error+0x2d4) [0x7f5f74231614]
 1  /datasets/pentschev/miniconda3/envs/gdf/lib/libucs.so.0(+0x2e7ef) [0x7f5f742317ef]
 2  /datasets/pentschev/miniconda3/envs/gdf/lib/libucs.so.0(+0x2eb14) [0x7f5f74231b14]
 3  /lib/x86_64-linux-gnu/libpthread.so.0(+0x12980) [0x7f5fe9bc0980]
 4  /datasets/pentschev/miniconda3/envs/gdf/lib/libucp.so.0(ucp_mem_type_unpack+0x14) [0x7f5f744b63b4]
 5  /datasets/pentschev/miniconda3/envs/gdf/lib/libucp.so.0(ucp_rndv_data_handler+0x508) [0x7f5f744e6a08]
 6  /datasets/pentschev/miniconda3/envs/gdf/lib/libuct.so.0(+0x20b5f) [0x7f5f61de2b5f]
 7  /datasets/pentschev/miniconda3/envs/gdf/lib/libuct.so.0(+0x21134) [0x7f5f61de3134]
 8  /datasets/pentschev/miniconda3/envs/gdf/lib/libuct.so.0(+0x23578) [0x7f5f61de5578]
 9  /datasets/pentschev/miniconda3/envs/gdf/lib/libucs.so.0(ucs_event_set_wait+0xb9) [0x7f5f7423bc99]
10  /datasets/pentschev/miniconda3/envs/gdf/lib/libuct.so.0(uct_tcp_iface_progress+0x7b) [0x7f5f61de561b]
11  /datasets/pentschev/miniconda3/envs/gdf/lib/libucp.so.0(ucp_worker_progress+0x6a) [0x7f5f744b2caa]
12  /datasets/pentschev/miniconda3/envs/gdf/lib/python3.8/site-packages/ucp/_libs/ucx_api.cpython-38-x86_64-linux-gnu.so(+0x272b9) [0x7f5f7476d2b9]
13  /datasets/pentschev/miniconda3/envs/gdf/bin/python(+0x12e343) [0x561f03801343]
14  /datasets/pentschev/miniconda3/envs/gdf/bin/python(PyObject_Call+0x24a) [0x561f0380c1fa]
15  /datasets/pentschev/miniconda3/envs/gdf/bin/python(_PyEval_EvalFrameDefault+0x680b) [0x561f037f2b8b]
16  /datasets/pentschev/miniconda3/envs/gdf/bin/python(_PyEval_EvalCodeWithName+0x2f1) [0x561f037eb2f1]
17  /datasets/pentschev/miniconda3/envs/gdf/bin/python(_PyFunction_Vectorcall+0x19c) [0x561f037fc93c]
18  /datasets/pentschev/miniconda3/envs/gdf/bin/python(_PyEval_EvalFrameDefault+0x6d5) [0x561f037eca55]
19  /datasets/pentschev/miniconda3/envs/gdf/bin/python(+0x13e1e8) [0x561f038111e8]
20  /datasets/pentschev/miniconda3/envs/gdf/lib/python3.8/lib-dynload/_asyncio.cpython-38-x86_64-linux-gnu.so(+0x7003) [0x7f5fdc14e003]
21  /datasets/pentschev/miniconda3/envs/gdf/bin/python(_PyObject_MakeTpCall+0x3db) [0x561f037f530b]
22  /datasets/pentschev/miniconda3/envs/gdf/bin/python(+0xe0b07) [0x561f037b3b07]
23  /datasets/pentschev/miniconda3/envs/gdf/bin/python(+0x120f96) [0x561f037f3f96]
24  /datasets/pentschev/miniconda3/envs/gdf/bin/python(PyVectorcall_Call+0x7a) [0x561f0380a1ea]
25  /datasets/pentschev/miniconda3/envs/gdf/bin/python(_PyEval_EvalFrameDefault+0x5df8) [0x561f037f2178]
26  /datasets/pentschev/miniconda3/envs/gdf/bin/python(_PyFunction_Vectorcall+0x106) [0x561f037fc8a6]
27  /datasets/pentschev/miniconda3/envs/gdf/bin/python(_PyEval_EvalFrameDefault+0x6d5) [0x561f037eca55]
28  /datasets/pentschev/miniconda3/envs/gdf/bin/python(_PyFunction_Vectorcall+0x106) [0x561f037fc8a6]
29  /datasets/pentschev/miniconda3/envs/gdf/bin/python(_PyEval_EvalFrameDefault+0x6d5) [0x561f037eca55]
30  /datasets/pentschev/miniconda3/envs/gdf/bin/python(_PyFunction_Vectorcall+0x106) [0x561f037fc8a6]
31  /datasets/pentschev/miniconda3/envs/gdf/bin/python(_PyEval_EvalFrameDefault+0x6d5) [0x561f037eca55]
32  /datasets/pentschev/miniconda3/envs/gdf/bin/python(_PyFunction_Vectorcall+0x106) [0x561f037fc8a6]
33  /datasets/pentschev/miniconda3/envs/gdf/bin/python(_PyEval_EvalFrameDefault+0x6d5) [0x561f037eca55]
34  /datasets/pentschev/miniconda3/envs/gdf/bin/python(_PyEval_EvalCodeWithName+0x2f1) [0x561f037eb2f1]
35  /datasets/pentschev/miniconda3/envs/gdf/bin/python(_PyFunction_Vectorcall+0x19c) [0x561f037fc93c]
36  /datasets/pentschev/miniconda3/envs/gdf/bin/python(_PyEval_EvalFrameDefault+0x4b7b) [0x561f037f0efb]
37  /datasets/pentschev/miniconda3/envs/gdf/bin/python(_PyEval_EvalCodeWithName+0x2f1) [0x561f037eb2f1]
38  /datasets/pentschev/miniconda3/envs/gdf/bin/python(_PyFunction_Vectorcall+0x19c) [0x561f037fc93c]
39  /datasets/pentschev/miniconda3/envs/gdf/bin/python(+0x136e8c) [0x561f03809e8c]
40  /datasets/pentschev/miniconda3/envs/gdf/bin/python(_PyObject_FastCallDict+0x282) [0x561f037f4a92]
41  /datasets/pentschev/miniconda3/envs/gdf/bin/python(+0x1ee049) [0x561f038c1049]
42  /datasets/pentschev/miniconda3/envs/gdf/bin/python(PyObject_Call+0x2d3) [0x561f0380c283]
43  /datasets/pentschev/miniconda3/envs/gdf/bin/python(_PyEval_EvalFrameDefault+0x205e) [0x561f037ee3de]
44  /datasets/pentschev/miniconda3/envs/gdf/bin/python(_PyFunction_Vectorcall+0x106) [0x561f037fc8a6]
45  /datasets/pentschev/miniconda3/envs/gdf/bin/python(+0x136e8c) [0x561f03809e8c]
46  /datasets/pentschev/miniconda3/envs/gdf/bin/python(PyObject_Call+0x24a) [0x561f0380c1fa]
47  /datasets/pentschev/miniconda3/envs/gdf/bin/python(_PyEval_EvalFrameDefault+0x205e) [0x561f037ee3de]
48  /datasets/pentschev/miniconda3/envs/gdf/bin/python(_PyFunction_Vectorcall+0x106) [0x561f037fc8a6]
49  /datasets/pentschev/miniconda3/envs/gdf/bin/python(_PyEval_EvalFrameDefault+0x6d5) [0x561f037eca55]
50  /datasets/pentschev/miniconda3/envs/gdf/bin/python(_PyEval_EvalCodeWithName+0x2f1) [0x561f037eb2f1]
51  /datasets/pentschev/miniconda3/envs/gdf/bin/python(_PyFunction_Vectorcall+0x19c) [0x561f037fc93c]
52  /datasets/pentschev/miniconda3/envs/gdf/bin/python(_PyEval_EvalFrameDefault+0x6d5) [0x561f037eca55]
53  /datasets/pentschev/miniconda3/envs/gdf/bin/python(_PyFunction_Vectorcall+0x106) [0x561f037fc8a6]
54  /datasets/pentschev/miniconda3/envs/gdf/bin/python(_PyEval_EvalFrameDefault+0x3a9) [0x561f037ec729]
55  /datasets/pentschev/miniconda3/envs/gdf/bin/python(_PyEval_EvalCodeWithName+0x2f1) [0x561f037eb2f1]
56  /datasets/pentschev/miniconda3/envs/gdf/bin/python(_PyFunction_Vectorcall+0x19c) [0x561f037fc93c]
57  /datasets/pentschev/miniconda3/envs/gdf/bin/python(_PyEval_EvalFrameDefault+0x11bf) [0x561f037ed53f]
58  /datasets/pentschev/miniconda3/envs/gdf/bin/python(_PyEval_EvalCodeWithName+0x2f1) [0x561f037eb2f1]
59  /datasets/pentschev/miniconda3/envs/gdf/bin/python(PyEval_EvalCodeEx+0x39) [0x561f0389de99]
60  /datasets/pentschev/miniconda3/envs/gdf/bin/python(PyEval_EvalCode+0x1b) [0x561f0389de5b]
61  /datasets/pentschev/miniconda3/envs/gdf/bin/python(+0x1eb7f9) [0x561f038be7f9]
=================================
[dgx13:45776:0:45776] Caught signal 11 (Segmentation fault: address not mapped to object at address 0x448)
==== backtrace (tid:  45776) ====
 0  /datasets/pentschev/miniconda3/envs/gdf/lib/libucs.so.0(ucs_handle_error+0x2d4) [0x7f9dc9378614]
 1  /datasets/pentschev/miniconda3/envs/gdf/lib/libucs.so.0(+0x2e7ef) [0x7f9dc93787ef]
 2  /datasets/pentschev/miniconda3/envs/gdf/lib/libucs.so.0(+0x2eb14) [0x7f9dc9378b14]
 3  /lib/x86_64-linux-gnu/libpthread.so.0(+0x12980) [0x7f9e4cd02980]
 4  /datasets/pentschev/miniconda3/envs/gdf/lib/libucp.so.0(ucp_mem_type_unpack+0x14) [0x7f9dc95fd3b4]
 5  /datasets/pentschev/miniconda3/envs/gdf/lib/libucp.so.0(ucp_rndv_data_handler+0x508) [0x7f9dc962da08]
 6  /datasets/pentschev/miniconda3/envs/gdf/lib/libuct.so.0(+0x20b5f) [0x7f9dc912cb5f]
 7  /datasets/pentschev/miniconda3/envs/gdf/lib/libuct.so.0(+0x21134) [0x7f9dc912d134]
 8  /datasets/pentschev/miniconda3/envs/gdf/lib/libuct.so.0(+0x23578) [0x7f9dc912f578]
 9  /datasets/pentschev/miniconda3/envs/gdf/lib/libucs.so.0(ucs_event_set_wait+0xb9) [0x7f9dc9382c99]
10  /datasets/pentschev/miniconda3/envs/gdf/lib/libuct.so.0(uct_tcp_iface_progress+0x7b) [0x7f9dc912f61b]
11  /datasets/pentschev/miniconda3/envs/gdf/lib/libucp.so.0(ucp_worker_progress+0x6a) [0x7f9dc95f9caa]
12  /datasets/pentschev/miniconda3/envs/gdf/lib/python3.8/site-packages/ucp/_libs/ucx_api.cpython-38-x86_64-linux-gnu.so(+0x272b9) [0x7f9dc98b42b9]
13  /datasets/pentschev/miniconda3/envs/gdf/bin/python(+0x12e343) [0x55b430a87343]
14  /datasets/pentschev/miniconda3/envs/gdf/bin/python(PyObject_Call+0x24a) [0x55b430a921fa]
15  /datasets/pentschev/miniconda3/envs/gdf/bin/python(_PyEval_EvalFrameDefault+0x680b) [0x55b430a78b8b]
16  /datasets/pentschev/miniconda3/envs/gdf/bin/python(_PyEval_EvalCodeWithName+0x2f1) [0x55b430a712f1]
17  /datasets/pentschev/miniconda3/envs/gdf/bin/python(_PyFunction_Vectorcall+0x19c) [0x55b430a8293c]
18  /datasets/pentschev/miniconda3/envs/gdf/bin/python(_PyEval_EvalFrameDefault+0x6d5) [0x55b430a72a55]
19  /datasets/pentschev/miniconda3/envs/gdf/bin/python(+0x13e1e8) [0x55b430a971e8]
20  /datasets/pentschev/miniconda3/envs/gdf/lib/python3.8/lib-dynload/_asyncio.cpython-38-x86_64-linux-gnu.so(+0x7003) [0x7f9de7562003]
21  /datasets/pentschev/miniconda3/envs/gdf/bin/python(_PyObject_MakeTpCall+0x3db) [0x55b430a7b30b]
22  /datasets/pentschev/miniconda3/envs/gdf/bin/python(+0xe0b07) [0x55b430a39b07]
23  /datasets/pentschev/miniconda3/envs/gdf/bin/python(+0x120f96) [0x55b430a79f96]
24  /datasets/pentschev/miniconda3/envs/gdf/bin/python(PyVectorcall_Call+0x7a) [0x55b430a901ea]
25  /datasets/pentschev/miniconda3/envs/gdf/bin/python(_PyEval_EvalFrameDefault+0x5df8) [0x55b430a78178]
26  /datasets/pentschev/miniconda3/envs/gdf/bin/python(_PyFunction_Vectorcall+0x106) [0x55b430a828a6]
27  /datasets/pentschev/miniconda3/envs/gdf/bin/python(_PyEval_EvalFrameDefault+0x6d5) [0x55b430a72a55]
28  /datasets/pentschev/miniconda3/envs/gdf/bin/python(_PyFunction_Vectorcall+0x106) [0x55b430a828a6]
29  /datasets/pentschev/miniconda3/envs/gdf/bin/python(_PyEval_EvalFrameDefault+0x6d5) [0x55b430a72a55]
30  /datasets/pentschev/miniconda3/envs/gdf/bin/python(_PyFunction_Vectorcall+0x106) [0x55b430a828a6]
31  /datasets/pentschev/miniconda3/envs/gdf/bin/python(_PyEval_EvalFrameDefault+0x6d5) [0x55b430a72a55]
32  /datasets/pentschev/miniconda3/envs/gdf/bin/python(_PyFunction_Vectorcall+0x106) [0x55b430a828a6]
33  /datasets/pentschev/miniconda3/envs/gdf/bin/python(_PyEval_EvalFrameDefault+0x6d5) [0x55b430a72a55]
34  /datasets/pentschev/miniconda3/envs/gdf/bin/python(_PyEval_EvalCodeWithName+0x2f1) [0x55b430a712f1]
35  /datasets/pentschev/miniconda3/envs/gdf/bin/python(_PyFunction_Vectorcall+0x19c) [0x55b430a8293c]
36  /datasets/pentschev/miniconda3/envs/gdf/bin/python(_PyEval_EvalFrameDefault+0x4b7b) [0x55b430a76efb]
37  /datasets/pentschev/miniconda3/envs/gdf/bin/python(_PyEval_EvalCodeWithName+0x2f1) [0x55b430a712f1]
38  /datasets/pentschev/miniconda3/envs/gdf/bin/python(_PyFunction_Vectorcall+0x19c) [0x55b430a8293c]
39  /datasets/pentschev/miniconda3/envs/gdf/bin/python(+0x136e8c) [0x55b430a8fe8c]
40  /datasets/pentschev/miniconda3/envs/gdf/bin/python(_PyObject_FastCallDict+0x282) [0x55b430a7aa92]
41  /datasets/pentschev/miniconda3/envs/gdf/bin/python(+0x1ee049) [0x55b430b47049]
42  /datasets/pentschev/miniconda3/envs/gdf/bin/python(PyObject_Call+0x2d3) [0x55b430a92283]
43  /datasets/pentschev/miniconda3/envs/gdf/bin/python(_PyEval_EvalFrameDefault+0x205e) [0x55b430a743de]
44  /datasets/pentschev/miniconda3/envs/gdf/bin/python(_PyFunction_Vectorcall+0x106) [0x55b430a828a6]
45  /datasets/pentschev/miniconda3/envs/gdf/bin/python(+0x136e8c) [0x55b430a8fe8c]
46  /datasets/pentschev/miniconda3/envs/gdf/bin/python(PyObject_Call+0x24a) [0x55b430a921fa]
47  /datasets/pentschev/miniconda3/envs/gdf/bin/python(_PyEval_EvalFrameDefault+0x205e) [0x55b430a743de]
48  /datasets/pentschev/miniconda3/envs/gdf/bin/python(_PyFunction_Vectorcall+0x106) [0x55b430a828a6]
49  /datasets/pentschev/miniconda3/envs/gdf/bin/python(_PyEval_EvalFrameDefault+0x6d5) [0x55b430a72a55]
50  /datasets/pentschev/miniconda3/envs/gdf/bin/python(_PyEval_EvalCodeWithName+0x2f1) [0x55b430a712f1]
51  /datasets/pentschev/miniconda3/envs/gdf/bin/python(_PyFunction_Vectorcall+0x19c) [0x55b430a8293c]
52  /datasets/pentschev/miniconda3/envs/gdf/bin/python(_PyEval_EvalFrameDefault+0x6d5) [0x55b430a72a55]
53  /datasets/pentschev/miniconda3/envs/gdf/bin/python(_PyFunction_Vectorcall+0x106) [0x55b430a828a6]
54  /datasets/pentschev/miniconda3/envs/gdf/bin/python(_PyEval_EvalFrameDefault+0x3a9) [0x55b430a72729]
55  /datasets/pentschev/miniconda3/envs/gdf/bin/python(_PyEval_EvalCodeWithName+0x2f1) [0x55b430a712f1]
56  /datasets/pentschev/miniconda3/envs/gdf/bin/python(_PyFunction_Vectorcall+0x19c) [0x55b430a8293c]
57  /datasets/pentschev/miniconda3/envs/gdf/bin/python(_PyEval_EvalFrameDefault+0x11bf) [0x55b430a7353f]
58  /datasets/pentschev/miniconda3/envs/gdf/bin/python(_PyEval_EvalCodeWithName+0x2f1) [0x55b430a712f1]
59  /datasets/pentschev/miniconda3/envs/gdf/bin/python(PyEval_EvalCodeEx+0x39) [0x55b430b23e99]
60  /datasets/pentschev/miniconda3/envs/gdf/bin/python(PyEval_EvalCode+0x1b) [0x55b430b23e5b]
61  /datasets/pentschev/miniconda3/envs/gdf/bin/python(+0x1eb7f9) [0x55b430b447f9]
=================================
2023-03-08 00:00:29,701 - distributed.worker - ERROR - Worker stream died during communication: ucx://127.0.0.1:40639
Traceback (most recent call last):
  File "/datasets/pentschev/miniconda3/envs/gdf/lib/python3.8/site-packages/distributed/comm/ucx.py", line 349, in read
    await self.ep.recv(msg)
  File "/datasets/pentschev/miniconda3/envs/gdf/lib/python3.8/site-packages/ucp/core.py", line 725, in recv
    ret = await comm.tag_recv(self._ep, buffer, nbytes, tag, name=log)
ucp._libs.exceptions.UCXCanceled: <[Recv #000] ep: 0x7fc46c06a200, tag: 0x6ace08d6d855683a, nbytes: 16, type: <class 'numpy.ndarray'>>: 

During handling of the above exception, another exception occurred:

Traceback (most recent call last):
  File "/datasets/pentschev/miniconda3/envs/gdf/lib/python3.8/site-packages/distributed/comm/core.py", line 328, in connect
    handshake = await asyncio.wait_for(comm.read(), time_left())
  File "/datasets/pentschev/miniconda3/envs/gdf/lib/python3.8/asyncio/tasks.py", line 494, in wait_for
    return fut.result()
  File "/datasets/pentschev/miniconda3/envs/gdf/lib/python3.8/site-packages/distributed/utils.py", line 741, in wrapper
    return await func(*args, **kwargs)
  File "/datasets/pentschev/miniconda3/envs/gdf/lib/python3.8/site-packages/distributed/comm/ucx.py", line 367, in read
    raise CommClosedError(
distributed.comm.core.CommClosedError: Connection closed by writer.
Inner exception: UCXCanceled("<[Recv #000] ep: 0x7fc46c06a200, tag: 0x6ace08d6d855683a, nbytes: 16, type: <class 'numpy.ndarray'>>: ")

The above exception was the direct cause of the following exception:

Traceback (most recent call last):
  File "/datasets/pentschev/miniconda3/envs/gdf/lib/python3.8/site-packages/distributed/worker.py", line 2081, in gather_dep
    response = await get_data_from_worker(
  File "/datasets/pentschev/miniconda3/envs/gdf/lib/python3.8/site-packages/distributed/worker.py", line 2900, in get_data_from_worker
    comm = await rpc.connect(worker)
  File "/datasets/pentschev/miniconda3/envs/gdf/lib/python3.8/site-packages/distributed/core.py", line 1474, in connect
    return await connect_attempt
  File "/datasets/pentschev/miniconda3/envs/gdf/lib/python3.8/site-packages/distributed/core.py", line 1395, in _connect
    comm = await connect(
  File "/datasets/pentschev/miniconda3/envs/gdf/lib/python3.8/site-packages/distributed/comm/core.py", line 333, in connect
    raise OSError(
OSError: Timed out during handshake while connecting to ucx://127.0.0.1:40639 after 30 s
2023-03-08 00:00:29,702 - distributed.worker - ERROR - Worker stream died during communication: ucx://127.0.0.1:40639
Traceback (most recent call last):
  File "/datasets/pentschev/miniconda3/envs/gdf/lib/python3.8/site-packages/distributed/comm/ucx.py", line 349, in read
    await self.ep.recv(msg)
  File "/datasets/pentschev/miniconda3/envs/gdf/lib/python3.8/site-packages/ucp/core.py", line 725, in recv
    ret = await comm.tag_recv(self._ep, buffer, nbytes, tag, name=log)
ucp._libs.exceptions.UCXCanceled: <[Recv #000] ep: 0x7f38ec03e180, tag: 0xda01c9d9564da831, nbytes: 16, type: <class 'numpy.ndarray'>>: 

During handling of the above exception, another exception occurred:

Traceback (most recent call last):
  File "/datasets/pentschev/miniconda3/envs/gdf/lib/python3.8/site-packages/distributed/comm/core.py", line 328, in connect
    handshake = await asyncio.wait_for(comm.read(), time_left())
  File "/datasets/pentschev/miniconda3/envs/gdf/lib/python3.8/asyncio/tasks.py", line 494, in wait_for
    return fut.result()
  File "/datasets/pentschev/miniconda3/envs/gdf/lib/python3.8/site-packages/distributed/utils.py", line 741, in wrapper
    return await func(*args, **kwargs)
  File "/datasets/pentschev/miniconda3/envs/gdf/lib/python3.8/site-packages/distributed/comm/ucx.py", line 367, in read
    raise CommClosedError(
distributed.comm.core.CommClosedError: Connection closed by writer.
Inner exception: UCXCanceled("<[Recv #000] ep: 0x7f38ec03e180, tag: 0xda01c9d9564da831, nbytes: 16, type: <class 'numpy.ndarray'>>: ")

The above exception was the direct cause of the following exception:

Traceback (most recent call last):
  File "/datasets/pentschev/miniconda3/envs/gdf/lib/python3.8/site-packages/distributed/worker.py", line 2081, in gather_dep
    response = await get_data_from_worker(
  File "/datasets/pentschev/miniconda3/envs/gdf/lib/python3.8/site-packages/distributed/worker.py", line 2900, in get_data_from_worker
    comm = await rpc.connect(worker)
  File "/datasets/pentschev/miniconda3/envs/gdf/lib/python3.8/site-packages/distributed/core.py", line 1474, in connect
    return await connect_attempt
  File "/datasets/pentschev/miniconda3/envs/gdf/lib/python3.8/site-packages/distributed/core.py", line 1395, in _connect
    comm = await connect(
  File "/datasets/pentschev/miniconda3/envs/gdf/lib/python3.8/site-packages/distributed/comm/core.py", line 333, in connect
    raise OSError(
OSError: Timed out during handshake while connecting to ucx://127.0.0.1:40639 after 30 s
2023-03-08 00:00:29,719 - distributed.worker - ERROR - failed during get data with ucx://127.0.0.1:55431 -> ucx://127.0.0.1:38653
Traceback (most recent call last):
  File "/datasets/pentschev/miniconda3/envs/gdf/lib/python3.8/site-packages/distributed/comm/ucx.py", line 333, in write
    await self.ep.send(each_frame)
  File "/datasets/pentschev/miniconda3/envs/gdf/lib/python3.8/site-packages/ucp/core.py", line 650, in send
    return await comm.tag_send(self._ep, buffer, nbytes, tag, name=log)
ucp._libs.exceptions.UCXError: <[Send #007] ep: 0x7fc46c06a240, tag: 0x448a4ab0f6255fff, nbytes: 50000000, type: <class 'cupy.ndarray'>>: Connection reset by remote peer

During handling of the above exception, another exception occurred:

Traceback (most recent call last):
  File "/datasets/pentschev/miniconda3/envs/gdf/lib/python3.8/site-packages/distributed/worker.py", line 1795, in get_data
    compressed = await comm.write(msg, serializers=serializers)
  File "/datasets/pentschev/miniconda3/envs/gdf/lib/python3.8/site-packages/distributed/utils.py", line 741, in wrapper
    return await func(*args, **kwargs)
  File "/datasets/pentschev/miniconda3/envs/gdf/lib/python3.8/site-packages/distributed/comm/ucx.py", line 337, in write
    raise CommClosedError("While writing, the connection was closed")
distributed.comm.core.CommClosedError: While writing, the connection was closed
2023-03-08 00:00:29,719 - distributed.worker - ERROR - Worker stream died during communication: ucx://127.0.0.1:38653
Traceback (most recent call last):
  File "/datasets/pentschev/miniconda3/envs/gdf/lib/python3.8/site-packages/distributed/comm/ucx.py", line 391, in read
    await self.ep.recv(each_frame)
  File "/datasets/pentschev/miniconda3/envs/gdf/lib/python3.8/site-packages/ucp/core.py", line 725, in recv
    ret = await comm.tag_recv(self._ep, buffer, nbytes, tag, name=log)
ucp._libs.exceptions.UCXError: <[Recv #007] ep: 0x7fc46c06a1c0, tag: 0x659f093e64f25d9b, nbytes: 50000000, type: <class 'rmm._lib.device_buffer.DeviceBuffer'>>: Connection reset by remote peer

During handling of the above exception, another exception occurred:

Traceback (most recent call last):
  File "/datasets/pentschev/miniconda3/envs/gdf/lib/python3.8/site-packages/distributed/worker.py", line 2081, in gather_dep
    response = await get_data_from_worker(
  File "/datasets/pentschev/miniconda3/envs/gdf/lib/python3.8/site-packages/distributed/worker.py", line 2903, in get_data_from_worker
    response = await send_recv(
  File "/datasets/pentschev/miniconda3/envs/gdf/lib/python3.8/site-packages/distributed/core.py", line 992, in send_recv
    response = await comm.read(deserializers=deserializers)
  File "/datasets/pentschev/miniconda3/envs/gdf/lib/python3.8/site-packages/distributed/utils.py", line 741, in wrapper
    return await func(*args, **kwargs)
  File "/datasets/pentschev/miniconda3/envs/gdf/lib/python3.8/site-packages/distributed/comm/ucx.py", line 397, in read
    raise CommClosedError(
distributed.comm.core.CommClosedError: Connection closed by writer.
Inner exception: UCXError("<[Recv #007] ep: 0x7fc46c06a1c0, tag: 0x659f093e64f25d9b, nbytes: 50000000, type: <class 'rmm._lib.device_buffer.DeviceBuffer'>>: Connection reset by remote peer")
2023-03-08 00:00:29,729 - distributed.worker - ERROR - failed during get data with ucx://127.0.0.1:55431 -> ucx://127.0.0.1:58077
Traceback (most recent call last):
  File "/datasets/pentschev/miniconda3/envs/gdf/lib/python3.8/site-packages/distributed/comm/ucx.py", line 333, in write
    await self.ep.send(each_frame)
  File "/datasets/pentschev/miniconda3/envs/gdf/lib/python3.8/site-packages/ucp/core.py", line 650, in send
    return await comm.tag_send(self._ep, buffer, nbytes, tag, name=log)
ucp._libs.exceptions.UCXError: <[Send #007] ep: 0x7fc46c06a280, tag: 0x2f7caf950aef6ee6, nbytes: 50000000, type: <class 'cupy.ndarray'>>: Connection reset by remote peer

During handling of the above exception, another exception occurred:

Traceback (most recent call last):
  File "/datasets/pentschev/miniconda3/envs/gdf/lib/python3.8/site-packages/distributed/worker.py", line 1795, in get_data
    compressed = await comm.write(msg, serializers=serializers)
  File "/datasets/pentschev/miniconda3/envs/gdf/lib/python3.8/site-packages/distributed/utils.py", line 741, in wrapper
    return await func(*args, **kwargs)
  File "/datasets/pentschev/miniconda3/envs/gdf/lib/python3.8/site-packages/distributed/comm/ucx.py", line 337, in write
    raise CommClosedError("While writing, the connection was closed")
distributed.comm.core.CommClosedError: While writing, the connection was closed
2023-03-08 00:00:29,729 - distributed.worker - ERROR - Worker stream died during communication: ucx://127.0.0.1:58077
Traceback (most recent call last):
  File "/datasets/pentschev/miniconda3/envs/gdf/lib/python3.8/site-packages/distributed/comm/ucx.py", line 391, in read
    await self.ep.recv(each_frame)
  File "/datasets/pentschev/miniconda3/envs/gdf/lib/python3.8/site-packages/ucp/core.py", line 725, in recv
    ret = await comm.tag_recv(self._ep, buffer, nbytes, tag, name=log)
ucp._libs.exceptions.UCXError: <[Recv #007] ep: 0x7f38ec03e1c0, tag: 0x3e7f37e2fb1ec7a5, nbytes: 50000000, type: <class 'rmm._lib.device_buffer.DeviceBuffer'>>: Connection reset by remote peer

During handling of the above exception, another exception occurred:

Traceback (most recent call last):
  File "/datasets/pentschev/miniconda3/envs/gdf/lib/python3.8/site-packages/distributed/worker.py", line 2081, in gather_dep
    response = await get_data_from_worker(
  File "/datasets/pentschev/miniconda3/envs/gdf/lib/python3.8/site-packages/distributed/worker.py", line 2903, in get_data_from_worker
    response = await send_recv(
  File "/datasets/pentschev/miniconda3/envs/gdf/lib/python3.8/site-packages/distributed/core.py", line 992, in send_recv
    response = await comm.read(deserializers=deserializers)
  File "/datasets/pentschev/miniconda3/envs/gdf/lib/python3.8/site-packages/distributed/utils.py", line 741, in wrapper
    return await func(*args, **kwargs)
  File "/datasets/pentschev/miniconda3/envs/gdf/lib/python3.8/site-packages/distributed/comm/ucx.py", line 397, in read
    raise CommClosedError(
distributed.comm.core.CommClosedError: Connection closed by writer.
Inner exception: UCXError("<[Recv #007] ep: 0x7f38ec03e1c0, tag: 0x3e7f37e2fb1ec7a5, nbytes: 50000000, type: <class 'rmm._lib.device_buffer.DeviceBuffer'>>: Connection reset by remote peer")
2023-03-08 00:00:29,730 - distributed.worker - ERROR - Worker stream died during communication: ucx://127.0.0.1:58077
Traceback (most recent call last):
  File "/datasets/pentschev/miniconda3/envs/gdf/lib/python3.8/site-packages/distributed/comm/ucx.py", line 349, in read
    await self.ep.recv(msg)
  File "/datasets/pentschev/miniconda3/envs/gdf/lib/python3.8/site-packages/ucp/core.py", line 725, in recv
    ret = await comm.tag_recv(self._ep, buffer, nbytes, tag, name=log)
ucp._libs.exceptions.UCXCanceled: <[Recv #003] ep: 0x7fc46c06a140, tag: 0x5b0bbbff9f0b6b93, nbytes: 16, type: <class 'numpy.ndarray'>>: 

During handling of the above exception, another exception occurred:

Traceback (most recent call last):
  File "/datasets/pentschev/miniconda3/envs/gdf/lib/python3.8/site-packages/distributed/worker.py", line 2081, in gather_dep
    response = await get_data_from_worker(
  File "/datasets/pentschev/miniconda3/envs/gdf/lib/python3.8/site-packages/distributed/worker.py", line 2903, in get_data_from_worker
    response = await send_recv(
  File "/datasets/pentschev/miniconda3/envs/gdf/lib/python3.8/site-packages/distributed/core.py", line 992, in send_recv
    response = await comm.read(deserializers=deserializers)
  File "/datasets/pentschev/miniconda3/envs/gdf/lib/python3.8/site-packages/distributed/utils.py", line 741, in wrapper
    return await func(*args, **kwargs)
  File "/datasets/pentschev/miniconda3/envs/gdf/lib/python3.8/site-packages/distributed/comm/ucx.py", line 367, in read
    raise CommClosedError(
distributed.comm.core.CommClosedError: Connection closed by writer.
Inner exception: UCXCanceled("<[Recv #003] ep: 0x7fc46c06a140, tag: 0x5b0bbbff9f0b6b93, nbytes: 16, type: <class 'numpy.ndarray'>>: ")
2023-03-08 00:00:29,762 - distributed.nanny - WARNING - Restarting worker
2023-03-08 00:00:29,809 - distributed.worker - ERROR - Worker stream died during communication: ucx://127.0.0.1:58077
Traceback (most recent call last):
  File "/datasets/pentschev/miniconda3/envs/gdf/lib/python3.8/site-packages/distributed/comm/ucx.py", line 349, in read
    await self.ep.recv(msg)
  File "/datasets/pentschev/miniconda3/envs/gdf/lib/python3.8/site-packages/ucp/core.py", line 725, in recv
    ret = await comm.tag_recv(self._ep, buffer, nbytes, tag, name=log)
ucp._libs.exceptions.UCXCanceled: <[Recv #003] ep: 0x7fa3201a8180, tag: 0x3a341765c5cf8677, nbytes: 16, type: <class 'numpy.ndarray'>>: 

During handling of the above exception, another exception occurred:

Traceback (most recent call last):
  File "/datasets/pentschev/miniconda3/envs/gdf/lib/python3.8/site-packages/distributed/worker.py", line 2081, in gather_dep
    response = await get_data_from_worker(
  File "/datasets/pentschev/miniconda3/envs/gdf/lib/python3.8/site-packages/distributed/worker.py", line 2903, in get_data_from_worker
    response = await send_recv(
  File "/datasets/pentschev/miniconda3/envs/gdf/lib/python3.8/site-packages/distributed/core.py", line 992, in send_recv
    response = await comm.read(deserializers=deserializers)
  File "/datasets/pentschev/miniconda3/envs/gdf/lib/python3.8/site-packages/distributed/utils.py", line 741, in wrapper
    return await func(*args, **kwargs)
  File "/datasets/pentschev/miniconda3/envs/gdf/lib/python3.8/site-packages/distributed/comm/ucx.py", line 367, in read
    raise CommClosedError(
distributed.comm.core.CommClosedError: Connection closed by writer.
Inner exception: UCXCanceled("<[Recv #003] ep: 0x7fa3201a8180, tag: 0x3a341765c5cf8677, nbytes: 16, type: <class 'numpy.ndarray'>>: ")
2023-03-08 00:00:29,814 - distributed.worker - ERROR - Worker stream died during communication: ucx://127.0.0.1:40639
Traceback (most recent call last):
  File "/datasets/pentschev/miniconda3/envs/gdf/lib/python3.8/site-packages/distributed/comm/ucx.py", line 349, in read
    await self.ep.recv(msg)
  File "/datasets/pentschev/miniconda3/envs/gdf/lib/python3.8/site-packages/ucp/core.py", line 725, in recv
    ret = await comm.tag_recv(self._ep, buffer, nbytes, tag, name=log)
ucp._libs.exceptions.UCXCanceled: <[Recv #000] ep: 0x7fa3201a8140, tag: 0x2ed1718329ecafb5, nbytes: 16, type: <class 'numpy.ndarray'>>: 

During handling of the above exception, another exception occurred:

Traceback (most recent call last):
  File "/datasets/pentschev/miniconda3/envs/gdf/lib/python3.8/site-packages/distributed/comm/core.py", line 328, in connect
    handshake = await asyncio.wait_for(comm.read(), time_left())
  File "/datasets/pentschev/miniconda3/envs/gdf/lib/python3.8/asyncio/tasks.py", line 494, in wait_for
    return fut.result()
  File "/datasets/pentschev/miniconda3/envs/gdf/lib/python3.8/site-packages/distributed/utils.py", line 741, in wrapper
    return await func(*args, **kwargs)
  File "/datasets/pentschev/miniconda3/envs/gdf/lib/python3.8/site-packages/distributed/comm/ucx.py", line 367, in read
    raise CommClosedError(
distributed.comm.core.CommClosedError: Connection closed by writer.
Inner exception: UCXCanceled("<[Recv #000] ep: 0x7fa3201a8140, tag: 0x2ed1718329ecafb5, nbytes: 16, type: <class 'numpy.ndarray'>>: ")

The above exception was the direct cause of the following exception:

Traceback (most recent call last):
  File "/datasets/pentschev/miniconda3/envs/gdf/lib/python3.8/site-packages/distributed/worker.py", line 2081, in gather_dep
    response = await get_data_from_worker(
  File "/datasets/pentschev/miniconda3/envs/gdf/lib/python3.8/site-packages/distributed/worker.py", line 2900, in get_data_from_worker
    comm = await rpc.connect(worker)
  File "/datasets/pentschev/miniconda3/envs/gdf/lib/python3.8/site-packages/distributed/core.py", line 1474, in connect
    return await connect_attempt
  File "/datasets/pentschev/miniconda3/envs/gdf/lib/python3.8/site-packages/distributed/core.py", line 1395, in _connect
    comm = await connect(
  File "/datasets/pentschev/miniconda3/envs/gdf/lib/python3.8/site-packages/distributed/comm/core.py", line 333, in connect
    raise OSError(
OSError: Timed out during handshake while connecting to ucx://127.0.0.1:40639 after 30 s
2023-03-08 00:00:29,817 - distributed.nanny - WARNING - Restarting worker
2023-03-08 00:00:29,822 - distributed.worker - ERROR - Worker stream died during communication: ucx://127.0.0.1:33091
Traceback (most recent call last):
  File "/datasets/pentschev/miniconda3/envs/gdf/lib/python3.8/site-packages/distributed/comm/ucx.py", line 349, in read
    await self.ep.recv(msg)
  File "/datasets/pentschev/miniconda3/envs/gdf/lib/python3.8/site-packages/ucp/core.py", line 725, in recv
    ret = await comm.tag_recv(self._ep, buffer, nbytes, tag, name=log)
ucp._libs.exceptions.UCXCanceled: <[Recv #008] ep: 0x7ff6d8079140, tag: 0x1c309e5f6198eab8, nbytes: 16, type: <class 'numpy.ndarray'>>: 

During handling of the above exception, another exception occurred:

Traceback (most recent call last):
  File "/datasets/pentschev/miniconda3/envs/gdf/lib/python3.8/site-packages/distributed/worker.py", line 2081, in gather_dep
    response = await get_data_from_worker(
  File "/datasets/pentschev/miniconda3/envs/gdf/lib/python3.8/site-packages/distributed/worker.py", line 2903, in get_data_from_worker
    response = await send_recv(
  File "/datasets/pentschev/miniconda3/envs/gdf/lib/python3.8/site-packages/distributed/core.py", line 992, in send_recv
    response = await comm.read(deserializers=deserializers)
  File "/datasets/pentschev/miniconda3/envs/gdf/lib/python3.8/site-packages/distributed/utils.py", line 741, in wrapper
    return await func(*args, **kwargs)
  File "/datasets/pentschev/miniconda3/envs/gdf/lib/python3.8/site-packages/distributed/comm/ucx.py", line 367, in read
    raise CommClosedError(
distributed.comm.core.CommClosedError: Connection closed by writer.
Inner exception: UCXCanceled("<[Recv #008] ep: 0x7ff6d8079140, tag: 0x1c309e5f6198eab8, nbytes: 16, type: <class 'numpy.ndarray'>>: ")
2023-03-08 00:00:29,848 - distributed.worker - ERROR - failed during get data with ucx://127.0.0.1:55431 -> ucx://127.0.0.1:33091
Traceback (most recent call last):
  File "/datasets/pentschev/miniconda3/envs/gdf/lib/python3.8/site-packages/distributed/comm/ucx.py", line 333, in write
    await self.ep.send(each_frame)
  File "/datasets/pentschev/miniconda3/envs/gdf/lib/python3.8/site-packages/ucp/core.py", line 650, in send
    return await comm.tag_send(self._ep, buffer, nbytes, tag, name=log)
ucp._libs.exceptions.UCXError: <[Send #007] ep: 0x7fc46c06a2c0, tag: 0x254b90a1a84a3d5f, nbytes: 50000000, type: <class 'cupy.ndarray'>>: Connection reset by remote peer

During handling of the above exception, another exception occurred:

Traceback (most recent call last):
  File "/datasets/pentschev/miniconda3/envs/gdf/lib/python3.8/site-packages/distributed/worker.py", line 1795, in get_data
    compressed = await comm.write(msg, serializers=serializers)
  File "/datasets/pentschev/miniconda3/envs/gdf/lib/python3.8/site-packages/distributed/utils.py", line 741, in wrapper
    return await func(*args, **kwargs)
  File "/datasets/pentschev/miniconda3/envs/gdf/lib/python3.8/site-packages/distributed/comm/ucx.py", line 337, in write
    raise CommClosedError("While writing, the connection was closed")
distributed.comm.core.CommClosedError: While writing, the connection was closed
2023-03-08 00:00:29,849 - distributed.worker - ERROR - Worker stream died during communication: ucx://127.0.0.1:33091
Traceback (most recent call last):
  File "/datasets/pentschev/miniconda3/envs/gdf/lib/python3.8/site-packages/distributed/comm/ucx.py", line 391, in read
    await self.ep.recv(each_frame)
  File "/datasets/pentschev/miniconda3/envs/gdf/lib/python3.8/site-packages/ucp/core.py", line 725, in recv
    ret = await comm.tag_recv(self._ep, buffer, nbytes, tag, name=log)
ucp._libs.exceptions.UCXError: <[Recv #007] ep: 0x7fc46c06a180, tag: 0xc58f741b48926410, nbytes: 50000000, type: <class 'rmm._lib.device_buffer.DeviceBuffer'>>: Connection reset by remote peer

During handling of the above exception, another exception occurred:

Traceback (most recent call last):
  File "/datasets/pentschev/miniconda3/envs/gdf/lib/python3.8/site-packages/distributed/worker.py", line 2081, in gather_dep
    response = await get_data_from_worker(
  File "/datasets/pentschev/miniconda3/envs/gdf/lib/python3.8/site-packages/distributed/worker.py", line 2903, in get_data_from_worker
    response = await send_recv(
  File "/datasets/pentschev/miniconda3/envs/gdf/lib/python3.8/site-packages/distributed/core.py", line 992, in send_recv
    response = await comm.read(deserializers=deserializers)
  File "/datasets/pentschev/miniconda3/envs/gdf/lib/python3.8/site-packages/distributed/utils.py", line 741, in wrapper
    return await func(*args, **kwargs)
  File "/datasets/pentschev/miniconda3/envs/gdf/lib/python3.8/site-packages/distributed/comm/ucx.py", line 397, in read
    raise CommClosedError(
distributed.comm.core.CommClosedError: Connection closed by writer.
Inner exception: UCXError("<[Recv #007] ep: 0x7fc46c06a180, tag: 0xc58f741b48926410, nbytes: 50000000, type: <class 'rmm._lib.device_buffer.DeviceBuffer'>>: Connection reset by remote peer")
2023-03-08 00:00:29,853 - distributed.nanny - WARNING - Restarting worker
2023-03-08 00:00:29,922 - distributed.nanny - WARNING - Restarting worker
2023-03-08 00:00:31,601 - distributed.preloading - INFO - Creating preload: dask_cuda.initialize
2023-03-08 00:00:31,601 - distributed.preloading - INFO - Import preload module: dask_cuda.initialize
2023-03-08 00:00:31,678 - distributed.preloading - INFO - Creating preload: dask_cuda.initialize
2023-03-08 00:00:31,678 - distributed.preloading - INFO - Import preload module: dask_cuda.initialize
2023-03-08 00:00:31,693 - distributed.preloading - INFO - Creating preload: dask_cuda.initialize
2023-03-08 00:00:31,693 - distributed.preloading - INFO - Import preload module: dask_cuda.initialize
2023-03-08 00:00:31,703 - distributed.preloading - INFO - Creating preload: dask_cuda.initialize
2023-03-08 00:00:31,703 - distributed.preloading - INFO - Import preload module: dask_cuda.initialize
2023-03-08 00:00:59,702 - distributed.worker - ERROR - Worker stream died during communication: ucx://127.0.0.1:38653
Traceback (most recent call last):
  File "/datasets/pentschev/miniconda3/envs/gdf/lib/python3.8/site-packages/distributed/comm/core.py", line 291, in connect
    comm = await asyncio.wait_for(
  File "/datasets/pentschev/miniconda3/envs/gdf/lib/python3.8/asyncio/tasks.py", line 501, in wait_for
    raise exceptions.TimeoutError()
asyncio.exceptions.TimeoutError

The above exception was the direct cause of the following exception:

Traceback (most recent call last):
  File "/datasets/pentschev/miniconda3/envs/gdf/lib/python3.8/site-packages/distributed/worker.py", line 2081, in gather_dep
    response = await get_data_from_worker(
  File "/datasets/pentschev/miniconda3/envs/gdf/lib/python3.8/site-packages/distributed/worker.py", line 2900, in get_data_from_worker
    comm = await rpc.connect(worker)
  File "/datasets/pentschev/miniconda3/envs/gdf/lib/python3.8/site-packages/distributed/core.py", line 1474, in connect
    return await connect_attempt
  File "/datasets/pentschev/miniconda3/envs/gdf/lib/python3.8/site-packages/distributed/core.py", line 1395, in _connect
    comm = await connect(
  File "/datasets/pentschev/miniconda3/envs/gdf/lib/python3.8/site-packages/distributed/comm/core.py", line 317, in connect
    raise OSError(
OSError: Timed out trying to connect to ucx://127.0.0.1:38653 after 30 s
/datasets/pentschev/miniconda3/envs/gdf/lib/python3.8/multiprocessing/resource_tracker.py:216: UserWarning: resource_tracker: There appear to be 48 leaked semaphore objects to clean up at shutdown
  warnings.warn('resource_tracker: There appear to be %d '
