/datasets/pentschev/miniconda3/envs/gdf/lib/python3.8/site-packages/distributed/node.py:182: UserWarning: Port 8787 is already in use.
Perhaps you already have a cluster running?
Hosting the HTTP server on port 39401 instead
  warnings.warn(
2023-03-25 01:12:11,587 - distributed.preloading - INFO - Creating preload: dask_cuda.initialize
2023-03-25 01:12:11,587 - distributed.preloading - INFO - Import preload module: dask_cuda.initialize
2023-03-25 01:12:11,621 - distributed.preloading - INFO - Creating preload: dask_cuda.initialize
2023-03-25 01:12:11,621 - distributed.preloading - INFO - Import preload module: dask_cuda.initialize
2023-03-25 01:12:11,626 - distributed.preloading - INFO - Creating preload: dask_cuda.initialize
2023-03-25 01:12:11,626 - distributed.preloading - INFO - Import preload module: dask_cuda.initialize
2023-03-25 01:12:11,627 - distributed.preloading - INFO - Creating preload: dask_cuda.initialize
2023-03-25 01:12:11,627 - distributed.preloading - INFO - Import preload module: dask_cuda.initialize
2023-03-25 01:12:11,630 - distributed.preloading - INFO - Creating preload: dask_cuda.initialize
2023-03-25 01:12:11,630 - distributed.preloading - INFO - Import preload module: dask_cuda.initialize
2023-03-25 01:12:11,630 - distributed.preloading - INFO - Creating preload: dask_cuda.initialize
2023-03-25 01:12:11,630 - distributed.preloading - INFO - Import preload module: dask_cuda.initialize
2023-03-25 01:12:11,667 - distributed.preloading - INFO - Creating preload: dask_cuda.initialize
2023-03-25 01:12:11,667 - distributed.preloading - INFO - Import preload module: dask_cuda.initialize
2023-03-25 01:12:11,674 - distributed.preloading - INFO - Creating preload: dask_cuda.initialize
2023-03-25 01:12:11,674 - distributed.preloading - INFO - Import preload module: dask_cuda.initialize
[dgx13:40210:0:40210] Caught signal 11 (Segmentation fault: address not mapped to object at address 0x448)
==== backtrace (tid:  40210) ====
 0  /datasets/pentschev/miniconda3/envs/gdf/lib/libucs.so.0(ucs_handle_error+0x2d4) [0x7f5b6026c714]
 1  /datasets/pentschev/miniconda3/envs/gdf/lib/libucs.so.0(+0x2e8ef) [0x7f5b6026c8ef]
 2  /datasets/pentschev/miniconda3/envs/gdf/lib/libucs.so.0(+0x2ec14) [0x7f5b6026cc14]
 3  /lib/x86_64-linux-gnu/libpthread.so.0(+0x12980) [0x7f5be3d2e980]
 4  /datasets/pentschev/miniconda3/envs/gdf/lib/libucp.so.0(ucp_mem_type_unpack+0x14) [0x7f5b604f58d4]
 5  /datasets/pentschev/miniconda3/envs/gdf/lib/libucp.so.0(ucp_rndv_data_handler+0x508) [0x7f5b60529608]
 6  /datasets/pentschev/miniconda3/envs/gdf/lib/libuct.so.0(+0x20b6f) [0x7f5b60020b6f]
 7  /datasets/pentschev/miniconda3/envs/gdf/lib/libuct.so.0(+0x21144) [0x7f5b60021144]
 8  /datasets/pentschev/miniconda3/envs/gdf/lib/libuct.so.0(+0x235a8) [0x7f5b600235a8]
 9  /datasets/pentschev/miniconda3/envs/gdf/lib/libucs.so.0(ucs_event_set_wait+0xb9) [0x7f5b60276de9]
10  /datasets/pentschev/miniconda3/envs/gdf/lib/libuct.so.0(uct_tcp_iface_progress+0x7b) [0x7f5b6002364b]
11  /datasets/pentschev/miniconda3/envs/gdf/lib/libucp.so.0(ucp_worker_progress+0x6a) [0x7f5b604f1eba]
12  /datasets/pentschev/miniconda3/envs/gdf/lib/python3.8/site-packages/ucp/_libs/ucx_api.cpython-38-x86_64-linux-gnu.so(+0x272b9) [0x7f5b607b12b9]
13  /datasets/pentschev/miniconda3/envs/gdf/bin/python(+0x12e343) [0x5617d1f41343]
14  /datasets/pentschev/miniconda3/envs/gdf/bin/python(PyObject_Call+0x24a) [0x5617d1f4c1fa]
15  /datasets/pentschev/miniconda3/envs/gdf/bin/python(_PyEval_EvalFrameDefault+0x680b) [0x5617d1f32b8b]
16  /datasets/pentschev/miniconda3/envs/gdf/bin/python(_PyEval_EvalCodeWithName+0x2f1) [0x5617d1f2b2f1]
17  /datasets/pentschev/miniconda3/envs/gdf/bin/python(_PyFunction_Vectorcall+0x19c) [0x5617d1f3c93c]
18  /datasets/pentschev/miniconda3/envs/gdf/bin/python(_PyEval_EvalFrameDefault+0x6d5) [0x5617d1f2ca55]
19  /datasets/pentschev/miniconda3/envs/gdf/bin/python(+0x13e1e8) [0x5617d1f511e8]
20  /datasets/pentschev/miniconda3/envs/gdf/lib/python3.8/lib-dynload/_asyncio.cpython-38-x86_64-linux-gnu.so(+0x7003) [0x7f5b7e42e003]
21  /datasets/pentschev/miniconda3/envs/gdf/bin/python(_PyObject_MakeTpCall+0x3db) [0x5617d1f3530b]
22  /datasets/pentschev/miniconda3/envs/gdf/bin/python(+0xe0b07) [0x5617d1ef3b07]
23  /datasets/pentschev/miniconda3/envs/gdf/bin/python(+0x120f96) [0x5617d1f33f96]
24  /datasets/pentschev/miniconda3/envs/gdf/bin/python(PyVectorcall_Call+0x7a) [0x5617d1f4a1ea]
25  /datasets/pentschev/miniconda3/envs/gdf/bin/python(_PyEval_EvalFrameDefault+0x5df8) [0x5617d1f32178]
26  /datasets/pentschev/miniconda3/envs/gdf/bin/python(_PyFunction_Vectorcall+0x106) [0x5617d1f3c8a6]
27  /datasets/pentschev/miniconda3/envs/gdf/bin/python(_PyEval_EvalFrameDefault+0x6d5) [0x5617d1f2ca55]
28  /datasets/pentschev/miniconda3/envs/gdf/bin/python(_PyFunction_Vectorcall+0x106) [0x5617d1f3c8a6]
29  /datasets/pentschev/miniconda3/envs/gdf/bin/python(_PyEval_EvalFrameDefault+0x6d5) [0x5617d1f2ca55]
30  /datasets/pentschev/miniconda3/envs/gdf/bin/python(_PyFunction_Vectorcall+0x106) [0x5617d1f3c8a6]
31  /datasets/pentschev/miniconda3/envs/gdf/bin/python(_PyEval_EvalFrameDefault+0x6d5) [0x5617d1f2ca55]
32  /datasets/pentschev/miniconda3/envs/gdf/bin/python(_PyFunction_Vectorcall+0x106) [0x5617d1f3c8a6]
33  /datasets/pentschev/miniconda3/envs/gdf/bin/python(_PyEval_EvalFrameDefault+0x6d5) [0x5617d1f2ca55]
34  /datasets/pentschev/miniconda3/envs/gdf/bin/python(_PyEval_EvalCodeWithName+0x2f1) [0x5617d1f2b2f1]
35  /datasets/pentschev/miniconda3/envs/gdf/bin/python(_PyFunction_Vectorcall+0x19c) [0x5617d1f3c93c]
36  /datasets/pentschev/miniconda3/envs/gdf/bin/python(_PyEval_EvalFrameDefault+0x4b7b) [0x5617d1f30efb]
37  /datasets/pentschev/miniconda3/envs/gdf/bin/python(_PyEval_EvalCodeWithName+0x2f1) [0x5617d1f2b2f1]
38  /datasets/pentschev/miniconda3/envs/gdf/bin/python(_PyFunction_Vectorcall+0x19c) [0x5617d1f3c93c]
39  /datasets/pentschev/miniconda3/envs/gdf/bin/python(+0x136e8c) [0x5617d1f49e8c]
40  /datasets/pentschev/miniconda3/envs/gdf/bin/python(_PyObject_FastCallDict+0x282) [0x5617d1f34a92]
41  /datasets/pentschev/miniconda3/envs/gdf/bin/python(+0x1ee049) [0x5617d2001049]
42  /datasets/pentschev/miniconda3/envs/gdf/bin/python(PyObject_Call+0x2d3) [0x5617d1f4c283]
43  /datasets/pentschev/miniconda3/envs/gdf/bin/python(_PyEval_EvalFrameDefault+0x205e) [0x5617d1f2e3de]
44  /datasets/pentschev/miniconda3/envs/gdf/bin/python(_PyFunction_Vectorcall+0x106) [0x5617d1f3c8a6]
45  /datasets/pentschev/miniconda3/envs/gdf/bin/python(+0x136e8c) [0x5617d1f49e8c]
46  /datasets/pentschev/miniconda3/envs/gdf/bin/python(PyObject_Call+0x24a) [0x5617d1f4c1fa]
47  /datasets/pentschev/miniconda3/envs/gdf/bin/python(_PyEval_EvalFrameDefault+0x205e) [0x5617d1f2e3de]
48  /datasets/pentschev/miniconda3/envs/gdf/bin/python(_PyFunction_Vectorcall+0x106) [0x5617d1f3c8a6]
49  /datasets/pentschev/miniconda3/envs/gdf/bin/python(_PyEval_EvalFrameDefault+0x6d5) [0x5617d1f2ca55]
50  /datasets/pentschev/miniconda3/envs/gdf/bin/python(_PyEval_EvalCodeWithName+0x2f1) [0x5617d1f2b2f1]
51  /datasets/pentschev/miniconda3/envs/gdf/bin/python(_PyFunction_Vectorcall+0x19c) [0x5617d1f3c93c]
52  /datasets/pentschev/miniconda3/envs/gdf/bin/python(_PyEval_EvalFrameDefault+0x6d5) [0x5617d1f2ca55]
53  /datasets/pentschev/miniconda3/envs/gdf/bin/python(_PyFunction_Vectorcall+0x106) [0x5617d1f3c8a6]
54  /datasets/pentschev/miniconda3/envs/gdf/bin/python(_PyEval_EvalFrameDefault+0x3a9) [0x5617d1f2c729]
55  /datasets/pentschev/miniconda3/envs/gdf/bin/python(_PyEval_EvalCodeWithName+0x2f1) [0x5617d1f2b2f1]
56  /datasets/pentschev/miniconda3/envs/gdf/bin/python(_PyFunction_Vectorcall+0x19c) [0x5617d1f3c93c]
57  /datasets/pentschev/miniconda3/envs/gdf/bin/python(_PyEval_EvalFrameDefault+0x11bf) [0x5617d1f2d53f]
58  /datasets/pentschev/miniconda3/envs/gdf/bin/python(_PyEval_EvalCodeWithName+0x2f1) [0x5617d1f2b2f1]
59  /datasets/pentschev/miniconda3/envs/gdf/bin/python(PyEval_EvalCodeEx+0x39) [0x5617d1fdde99]
60  /datasets/pentschev/miniconda3/envs/gdf/bin/python(PyEval_EvalCode+0x1b) [0x5617d1fdde5b]
61  /datasets/pentschev/miniconda3/envs/gdf/bin/python(+0x1eb7f9) [0x5617d1ffe7f9]
=================================
2023-03-25 01:12:20,672 - distributed.worker - ERROR - failed during get data with ucx://127.0.0.1:41217 -> ucx://127.0.0.1:56243
Traceback (most recent call last):
  File "/datasets/pentschev/miniconda3/envs/gdf/lib/python3.8/site-packages/distributed/comm/ucx.py", line 333, in write
    await self.ep.send(each_frame)
  File "/datasets/pentschev/miniconda3/envs/gdf/lib/python3.8/site-packages/ucp/core.py", line 650, in send
    return await comm.tag_send(self._ep, buffer, nbytes, tag, name=log)
ucp._libs.exceptions.UCXError: <[Send #007] ep: 0x7fc5e8051100, tag: 0x12326c830bf2c62a, nbytes: 800000000, type: <class 'cudf.core.buffer.buffer.Buffer'>>: Connection reset by remote peer

During handling of the above exception, another exception occurred:

Traceback (most recent call last):
  File "/datasets/pentschev/miniconda3/envs/gdf/lib/python3.8/site-packages/distributed/worker.py", line 1792, in get_data
    compressed = await comm.write(msg, serializers=serializers)
  File "/datasets/pentschev/miniconda3/envs/gdf/lib/python3.8/site-packages/distributed/utils.py", line 752, in wrapper
    return await func(*args, **kwargs)
  File "/datasets/pentschev/miniconda3/envs/gdf/lib/python3.8/site-packages/distributed/comm/ucx.py", line 337, in write
    raise CommClosedError("While writing, the connection was closed")
distributed.comm.core.CommClosedError: While writing, the connection was closed
2023-03-25 01:12:20,761 - distributed.nanny - WARNING - Restarting worker
[dgx13:40193:0:40193] Caught signal 11 (Segmentation fault: address not mapped to object at address 0x448)
==== backtrace (tid:  40193) ====
 0  /datasets/pentschev/miniconda3/envs/gdf/lib/libucs.so.0(ucs_handle_error+0x2d4) [0x7f0558892714]
 1  /datasets/pentschev/miniconda3/envs/gdf/lib/libucs.so.0(+0x2e8ef) [0x7f05588928ef]
 2  /datasets/pentschev/miniconda3/envs/gdf/lib/libucs.so.0(+0x2ec14) [0x7f0558892c14]
 3  /lib/x86_64-linux-gnu/libpthread.so.0(+0x12980) [0x7f05ce30b980]
 4  /datasets/pentschev/miniconda3/envs/gdf/lib/libucp.so.0(ucp_mem_type_unpack+0x14) [0x7f0558b1b8d4]
 5  /datasets/pentschev/miniconda3/envs/gdf/lib/libucp.so.0(ucp_rndv_data_handler+0x508) [0x7f0558b4f608]
 6  /datasets/pentschev/miniconda3/envs/gdf/lib/libuct.so.0(+0x20b6f) [0x7f0558646b6f]
 7  /datasets/pentschev/miniconda3/envs/gdf/lib/libuct.so.0(+0x21144) [0x7f0558647144]
 8  /datasets/pentschev/miniconda3/envs/gdf/lib/libuct.so.0(+0x235a8) [0x7f05586495a8]
 9  /datasets/pentschev/miniconda3/envs/gdf/lib/libucs.so.0(ucs_event_set_wait+0xb9) [0x7f055889cde9]
10  /datasets/pentschev/miniconda3/envs/gdf/lib/libuct.so.0(uct_tcp_iface_progress+0x7b) [0x7f055864964b]
11  /datasets/pentschev/miniconda3/envs/gdf/lib/libucp.so.0(ucp_worker_progress+0x6a) [0x7f0558b17eba]
12  /datasets/pentschev/miniconda3/envs/gdf/lib/python3.8/site-packages/ucp/_libs/ucx_api.cpython-38-x86_64-linux-gnu.so(+0x272b9) [0x7f0558dd72b9]
13  /datasets/pentschev/miniconda3/envs/gdf/bin/python(+0x12e343) [0x564ca5b1b343]
14  /datasets/pentschev/miniconda3/envs/gdf/bin/python(PyObject_Call+0x24a) [0x564ca5b261fa]
15  /datasets/pentschev/miniconda3/envs/gdf/bin/python(_PyEval_EvalFrameDefault+0x680b) [0x564ca5b0cb8b]
16  /datasets/pentschev/miniconda3/envs/gdf/bin/python(_PyEval_EvalCodeWithName+0x2f1) [0x564ca5b052f1]
17  /datasets/pentschev/miniconda3/envs/gdf/bin/python(_PyFunction_Vectorcall+0x19c) [0x564ca5b1693c]
18  /datasets/pentschev/miniconda3/envs/gdf/bin/python(_PyEval_EvalFrameDefault+0x6d5) [0x564ca5b06a55]
19  /datasets/pentschev/miniconda3/envs/gdf/bin/python(_PyFunction_Vectorcall+0x106) [0x564ca5b168a6]
20  /datasets/pentschev/miniconda3/envs/gdf/bin/python(+0x136c36) [0x564ca5b23c36]
21  /datasets/pentschev/miniconda3/envs/gdf/bin/python(+0x23565a) [0x564ca5c2265a]
22  /datasets/pentschev/miniconda3/envs/gdf/bin/python(+0xe0b07) [0x564ca5acdb07]
23  /datasets/pentschev/miniconda3/envs/gdf/bin/python(+0x120f96) [0x564ca5b0df96]
24  /datasets/pentschev/miniconda3/envs/gdf/bin/python(PyVectorcall_Call+0x7a) [0x564ca5b241ea]
25  /datasets/pentschev/miniconda3/envs/gdf/bin/python(_PyEval_EvalFrameDefault+0x5df8) [0x564ca5b0c178]
26  /datasets/pentschev/miniconda3/envs/gdf/bin/python(_PyFunction_Vectorcall+0x106) [0x564ca5b168a6]
27  /datasets/pentschev/miniconda3/envs/gdf/bin/python(_PyEval_EvalFrameDefault+0x6d5) [0x564ca5b06a55]
28  /datasets/pentschev/miniconda3/envs/gdf/bin/python(_PyFunction_Vectorcall+0x106) [0x564ca5b168a6]
29  /datasets/pentschev/miniconda3/envs/gdf/bin/python(_PyEval_EvalFrameDefault+0x6d5) [0x564ca5b06a55]
30  /datasets/pentschev/miniconda3/envs/gdf/bin/python(_PyFunction_Vectorcall+0x106) [0x564ca5b168a6]
31  /datasets/pentschev/miniconda3/envs/gdf/bin/python(_PyEval_EvalFrameDefault+0x6d5) [0x564ca5b06a55]
32  /datasets/pentschev/miniconda3/envs/gdf/bin/python(_PyFunction_Vectorcall+0x106) [0x564ca5b168a6]
33  /datasets/pentschev/miniconda3/envs/gdf/bin/python(_PyEval_EvalFrameDefault+0x6d5) [0x564ca5b06a55]
34  /datasets/pentschev/miniconda3/envs/gdf/bin/python(_PyEval_EvalCodeWithName+0x2f1) [0x564ca5b052f1]
35  /datasets/pentschev/miniconda3/envs/gdf/bin/python(_PyFunction_Vectorcall+0x19c) [0x564ca5b1693c]
36  /datasets/pentschev/miniconda3/envs/gdf/bin/python(_PyEval_EvalFrameDefault+0x4b7b) [0x564ca5b0aefb]
37  /datasets/pentschev/miniconda3/envs/gdf/bin/python(_PyEval_EvalCodeWithName+0x2f1) [0x564ca5b052f1]
38  /datasets/pentschev/miniconda3/envs/gdf/bin/python(_PyFunction_Vectorcall+0x19c) [0x564ca5b1693c]
39  /datasets/pentschev/miniconda3/envs/gdf/bin/python(+0x136e8c) [0x564ca5b23e8c]
40  /datasets/pentschev/miniconda3/envs/gdf/bin/python(_PyObject_FastCallDict+0x282) [0x564ca5b0ea92]
41  /datasets/pentschev/miniconda3/envs/gdf/bin/python(+0x1ee049) [0x564ca5bdb049]
42  /datasets/pentschev/miniconda3/envs/gdf/bin/python(PyObject_Call+0x2d3) [0x564ca5b26283]
43  /datasets/pentschev/miniconda3/envs/gdf/bin/python(_PyEval_EvalFrameDefault+0x205e) [0x564ca5b083de]
44  /datasets/pentschev/miniconda3/envs/gdf/bin/python(_PyFunction_Vectorcall+0x106) [0x564ca5b168a6]
45  /datasets/pentschev/miniconda3/envs/gdf/bin/python(+0x136e8c) [0x564ca5b23e8c]
46  /datasets/pentschev/miniconda3/envs/gdf/bin/python(PyObject_Call+0x24a) [0x564ca5b261fa]
47  /datasets/pentschev/miniconda3/envs/gdf/bin/python(_PyEval_EvalFrameDefault+0x205e) [0x564ca5b083de]
48  /datasets/pentschev/miniconda3/envs/gdf/bin/python(_PyFunction_Vectorcall+0x106) [0x564ca5b168a6]
49  /datasets/pentschev/miniconda3/envs/gdf/bin/python(_PyEval_EvalFrameDefault+0x6d5) [0x564ca5b06a55]
50  /datasets/pentschev/miniconda3/envs/gdf/bin/python(_PyEval_EvalCodeWithName+0x2f1) [0x564ca5b052f1]
51  /datasets/pentschev/miniconda3/envs/gdf/bin/python(_PyFunction_Vectorcall+0x19c) [0x564ca5b1693c]
52  /datasets/pentschev/miniconda3/envs/gdf/bin/python(_PyEval_EvalFrameDefault+0x6d5) [0x564ca5b06a55]
53  /datasets/pentschev/miniconda3/envs/gdf/bin/python(_PyFunction_Vectorcall+0x106) [0x564ca5b168a6]
54  /datasets/pentschev/miniconda3/envs/gdf/bin/python(_PyEval_EvalFrameDefault+0x3a9) [0x564ca5b06729]
55  /datasets/pentschev/miniconda3/envs/gdf/bin/python(_PyEval_EvalCodeWithName+0x2f1) [0x564ca5b052f1]
56  /datasets/pentschev/miniconda3/envs/gdf/bin/python(_PyFunction_Vectorcall+0x19c) [0x564ca5b1693c]
57  /datasets/pentschev/miniconda3/envs/gdf/bin/python(_PyEval_EvalFrameDefault+0x11bf) [0x564ca5b0753f]
58  /datasets/pentschev/miniconda3/envs/gdf/bin/python(_PyEval_EvalCodeWithName+0x2f1) [0x564ca5b052f1]
59  /datasets/pentschev/miniconda3/envs/gdf/bin/python(PyEval_EvalCodeEx+0x39) [0x564ca5bb7e99]
60  /datasets/pentschev/miniconda3/envs/gdf/bin/python(PyEval_EvalCode+0x1b) [0x564ca5bb7e5b]
61  /datasets/pentschev/miniconda3/envs/gdf/bin/python(+0x1eb7f9) [0x564ca5bd87f9]
=================================
[dgx13:40213:0:40213] Caught signal 11 (Segmentation fault: address not mapped to object at address 0x448)
==== backtrace (tid:  40213) ====
 0  /datasets/pentschev/miniconda3/envs/gdf/lib/libucs.so.0(ucs_handle_error+0x2d4) [0x7f89040a7714]
 1  /datasets/pentschev/miniconda3/envs/gdf/lib/libucs.so.0(+0x2e8ef) [0x7f89040a78ef]
 2  /datasets/pentschev/miniconda3/envs/gdf/lib/libucs.so.0(+0x2ec14) [0x7f89040a7c14]
 3  /lib/x86_64-linux-gnu/libpthread.so.0(+0x12980) [0x7f8975832980]
 4  /datasets/pentschev/miniconda3/envs/gdf/lib/libucp.so.0(ucp_mem_type_unpack+0x14) [0x7f88f1d6b8d4]
 5  /datasets/pentschev/miniconda3/envs/gdf/lib/libucp.so.0(ucp_rndv_data_handler+0x508) [0x7f88f1d9f608]
 6  /datasets/pentschev/miniconda3/envs/gdf/lib/libuct.so.0(+0x20b6f) [0x7f88f1afab6f]
 7  /datasets/pentschev/miniconda3/envs/gdf/lib/libuct.so.0(+0x21144) [0x7f88f1afb144]
 8  /datasets/pentschev/miniconda3/envs/gdf/lib/libuct.so.0(+0x235a8) [0x7f88f1afd5a8]
 9  /datasets/pentschev/miniconda3/envs/gdf/lib/libucs.so.0(ucs_event_set_wait+0xb9) [0x7f89040b1de9]
10  /datasets/pentschev/miniconda3/envs/gdf/lib/libuct.so.0(uct_tcp_iface_progress+0x7b) [0x7f88f1afd64b]
11  /datasets/pentschev/miniconda3/envs/gdf/lib/libucp.so.0(ucp_worker_progress+0x6a) [0x7f88f1d67eba]
12  /datasets/pentschev/miniconda3/envs/gdf/lib/python3.8/site-packages/ucp/_libs/ucx_api.cpython-38-x86_64-linux-gnu.so(+0x272b9) [0x7f89043042b9]
13  /datasets/pentschev/miniconda3/envs/gdf/bin/python(+0x12e343) [0x5556a555c343]
14  /datasets/pentschev/miniconda3/envs/gdf/bin/python(PyObject_Call+0x24a) [0x5556a55671fa]
15  /datasets/pentschev/miniconda3/envs/gdf/bin/python(_PyEval_EvalFrameDefault+0x680b) [0x5556a554db8b]
16  /datasets/pentschev/miniconda3/envs/gdf/bin/python(_PyEval_EvalCodeWithName+0x2f1) [0x5556a55462f1]
17  /datasets/pentschev/miniconda3/envs/gdf/bin/python(_PyFunction_Vectorcall+0x19c) [0x5556a555793c]
18  /datasets/pentschev/miniconda3/envs/gdf/bin/python(_PyEval_EvalFrameDefault+0x6d5) [0x5556a5547a55]
19  /datasets/pentschev/miniconda3/envs/gdf/bin/python(+0x13e1e8) [0x5556a556c1e8]
20  /datasets/pentschev/miniconda3/envs/gdf/lib/python3.8/lib-dynload/_asyncio.cpython-38-x86_64-linux-gnu.so(+0x7003) [0x7f890ff2d003]
21  /datasets/pentschev/miniconda3/envs/gdf/bin/python(_PyObject_MakeTpCall+0x3db) [0x5556a555030b]
22  /datasets/pentschev/miniconda3/envs/gdf/bin/python(+0xe0b07) [0x5556a550eb07]
23  /datasets/pentschev/miniconda3/envs/gdf/bin/python(+0x120f96) [0x5556a554ef96]
24  /datasets/pentschev/miniconda3/envs/gdf/bin/python(PyVectorcall_Call+0x7a) [0x5556a55651ea]
25  /datasets/pentschev/miniconda3/envs/gdf/bin/python(_PyEval_EvalFrameDefault+0x5df8) [0x5556a554d178]
26  /datasets/pentschev/miniconda3/envs/gdf/bin/python(_PyFunction_Vectorcall+0x106) [0x5556a55578a6]
27  /datasets/pentschev/miniconda3/envs/gdf/bin/python(_PyEval_EvalFrameDefault+0x6d5) [0x5556a5547a55]
28  /datasets/pentschev/miniconda3/envs/gdf/bin/python(_PyFunction_Vectorcall+0x106) [0x5556a55578a6]
29  /datasets/pentschev/miniconda3/envs/gdf/bin/python(_PyEval_EvalFrameDefault+0x6d5) [0x5556a5547a55]
30  /datasets/pentschev/miniconda3/envs/gdf/bin/python(_PyFunction_Vectorcall+0x106) [0x5556a55578a6]
31  /datasets/pentschev/miniconda3/envs/gdf/bin/python(_PyEval_EvalFrameDefault+0x6d5) [0x5556a5547a55]
32  /datasets/pentschev/miniconda3/envs/gdf/bin/python(_PyFunction_Vectorcall+0x106) [0x5556a55578a6]
33  /datasets/pentschev/miniconda3/envs/gdf/bin/python(_PyEval_EvalFrameDefault+0x6d5) [0x5556a5547a55]
34  /datasets/pentschev/miniconda3/envs/gdf/bin/python(_PyEval_EvalCodeWithName+0x2f1) [0x5556a55462f1]
35  /datasets/pentschev/miniconda3/envs/gdf/bin/python(_PyFunction_Vectorcall+0x19c) [0x5556a555793c]
36  /datasets/pentschev/miniconda3/envs/gdf/bin/python(_PyEval_EvalFrameDefault+0x4b7b) [0x5556a554befb]
37  /datasets/pentschev/miniconda3/envs/gdf/bin/python(_PyEval_EvalCodeWithName+0x2f1) [0x5556a55462f1]
38  /datasets/pentschev/miniconda3/envs/gdf/bin/python(_PyFunction_Vectorcall+0x19c) [0x5556a555793c]
39  /datasets/pentschev/miniconda3/envs/gdf/bin/python(+0x136e8c) [0x5556a5564e8c]
40  /datasets/pentschev/miniconda3/envs/gdf/bin/python(_PyObject_FastCallDict+0x282) [0x5556a554fa92]
41  /datasets/pentschev/miniconda3/envs/gdf/bin/python(+0x1ee049) [0x5556a561c049]
42  /datasets/pentschev/miniconda3/envs/gdf/bin/python(PyObject_Call+0x2d3) [0x5556a5567283]
43  /datasets/pentschev/miniconda3/envs/gdf/bin/python(_PyEval_EvalFrameDefault+0x205e) [0x5556a55493de]
44  /datasets/pentschev/miniconda3/envs/gdf/bin/python(_PyFunction_Vectorcall+0x106) [0x5556a55578a6]
45  /datasets/pentschev/miniconda3/envs/gdf/bin/python(+0x136e8c) [0x5556a5564e8c]
46  /datasets/pentschev/miniconda3/envs/gdf/bin/python(PyObject_Call+0x24a) [0x5556a55671fa]
47  /datasets/pentschev/miniconda3/envs/gdf/bin/python(_PyEval_EvalFrameDefault+0x205e) [0x5556a55493de]
48  /datasets/pentschev/miniconda3/envs/gdf/bin/python(_PyFunction_Vectorcall+0x106) [0x5556a55578a6]
49  /datasets/pentschev/miniconda3/envs/gdf/bin/python(_PyEval_EvalFrameDefault+0x6d5) [0x5556a5547a55]
50  /datasets/pentschev/miniconda3/envs/gdf/bin/python(_PyEval_EvalCodeWithName+0x2f1) [0x5556a55462f1]
51  /datasets/pentschev/miniconda3/envs/gdf/bin/python(_PyFunction_Vectorcall+0x19c) [0x5556a555793c]
52  /datasets/pentschev/miniconda3/envs/gdf/bin/python(_PyEval_EvalFrameDefault+0x6d5) [0x5556a5547a55]
53  /datasets/pentschev/miniconda3/envs/gdf/bin/python(_PyFunction_Vectorcall+0x106) [0x5556a55578a6]
54  /datasets/pentschev/miniconda3/envs/gdf/bin/python(_PyEval_EvalFrameDefault+0x3a9) [0x5556a5547729]
55  /datasets/pentschev/miniconda3/envs/gdf/bin/python(_PyEval_EvalCodeWithName+0x2f1) [0x5556a55462f1]
56  /datasets/pentschev/miniconda3/envs/gdf/bin/python(_PyFunction_Vectorcall+0x19c) [0x5556a555793c]
57  /datasets/pentschev/miniconda3/envs/gdf/bin/python(_PyEval_EvalFrameDefault+0x11bf) [0x5556a554853f]
58  /datasets/pentschev/miniconda3/envs/gdf/bin/python(_PyEval_EvalCodeWithName+0x2f1) [0x5556a55462f1]
59  /datasets/pentschev/miniconda3/envs/gdf/bin/python(PyEval_EvalCodeEx+0x39) [0x5556a55f8e99]
60  /datasets/pentschev/miniconda3/envs/gdf/bin/python(PyEval_EvalCode+0x1b) [0x5556a55f8e5b]
61  /datasets/pentschev/miniconda3/envs/gdf/bin/python(+0x1eb7f9) [0x5556a56197f9]
=================================
[dgx13:40207:0:40207] Caught signal 11 (Segmentation fault: address not mapped to object at address 0x448)
==== backtrace (tid:  40207) ====
 0  /datasets/pentschev/miniconda3/envs/gdf/lib/libucs.so.0(ucs_handle_error+0x2d4) [0x7fc5492aa714]
 1  /datasets/pentschev/miniconda3/envs/gdf/lib/libucs.so.0(+0x2e8ef) [0x7fc5492aa8ef]
 2  /datasets/pentschev/miniconda3/envs/gdf/lib/libucs.so.0(+0x2ec14) [0x7fc5492aac14]
 3  /lib/x86_64-linux-gnu/libpthread.so.0(+0x12980) [0x7fc5bed53980]
 4  /datasets/pentschev/miniconda3/envs/gdf/lib/libucp.so.0(ucp_mem_type_unpack+0x14) [0x7fc5495338d4]
 5  /datasets/pentschev/miniconda3/envs/gdf/lib/libucp.so.0(ucp_rndv_data_handler+0x508) [0x7fc549567608]
 6  /datasets/pentschev/miniconda3/envs/gdf/lib/libuct.so.0(+0x20b6f) [0x7fc54905eb6f]
 7  /datasets/pentschev/miniconda3/envs/gdf/lib/libuct.so.0(+0x21144) [0x7fc54905f144]
 8  /datasets/pentschev/miniconda3/envs/gdf/lib/libuct.so.0(+0x235a8) [0x7fc5490615a8]
 9  /datasets/pentschev/miniconda3/envs/gdf/lib/libucs.so.0(ucs_event_set_wait+0xb9) [0x7fc5492b4de9]
10  /datasets/pentschev/miniconda3/envs/gdf/lib/libuct.so.0(uct_tcp_iface_progress+0x7b) [0x7fc54906164b]
11  /datasets/pentschev/miniconda3/envs/gdf/lib/libucp.so.0(ucp_worker_progress+0x6a) [0x7fc54952feba]
12  /datasets/pentschev/miniconda3/envs/gdf/lib/python3.8/site-packages/ucp/_libs/ucx_api.cpython-38-x86_64-linux-gnu.so(+0x272b9) [0x7fc5497ef2b9]
13  /datasets/pentschev/miniconda3/envs/gdf/bin/python(+0x12e343) [0x562a66636343]
14  /datasets/pentschev/miniconda3/envs/gdf/bin/python(PyObject_Call+0x24a) [0x562a666411fa]
15  /datasets/pentschev/miniconda3/envs/gdf/bin/python(_PyEval_EvalFrameDefault+0x680b) [0x562a66627b8b]
16  /datasets/pentschev/miniconda3/envs/gdf/bin/python(_PyEval_EvalCodeWithName+0x2f1) [0x562a666202f1]
17  /datasets/pentschev/miniconda3/envs/gdf/bin/python(_PyFunction_Vectorcall+0x19c) [0x562a6663193c]
18  /datasets/pentschev/miniconda3/envs/gdf/bin/python(_PyEval_EvalFrameDefault+0x6d5) [0x562a66621a55]
19  /datasets/pentschev/miniconda3/envs/gdf/bin/python(+0x13e1e8) [0x562a666461e8]
20  /datasets/pentschev/miniconda3/envs/gdf/lib/python3.8/lib-dynload/_asyncio.cpython-38-x86_64-linux-gnu.so(+0x7003) [0x7fc559455003]
21  /datasets/pentschev/miniconda3/envs/gdf/bin/python(_PyObject_MakeTpCall+0x3db) [0x562a6662a30b]
22  /datasets/pentschev/miniconda3/envs/gdf/bin/python(+0xe0b07) [0x562a665e8b07]
23  /datasets/pentschev/miniconda3/envs/gdf/bin/python(+0x120f96) [0x562a66628f96]
24  /datasets/pentschev/miniconda3/envs/gdf/bin/python(PyVectorcall_Call+0x7a) [0x562a6663f1ea]
25  /datasets/pentschev/miniconda3/envs/gdf/bin/python(_PyEval_EvalFrameDefault+0x5df8) [0x562a66627178]
26  /datasets/pentschev/miniconda3/envs/gdf/bin/python(_PyFunction_Vectorcall+0x106) [0x562a666318a6]
27  /datasets/pentschev/miniconda3/envs/gdf/bin/python(_PyEval_EvalFrameDefault+0x6d5) [0x562a66621a55]
28  /datasets/pentschev/miniconda3/envs/gdf/bin/python(_PyFunction_Vectorcall+0x106) [0x562a666318a6]
29  /datasets/pentschev/miniconda3/envs/gdf/bin/python(_PyEval_EvalFrameDefault+0x6d5) [0x562a66621a55]
30  /datasets/pentschev/miniconda3/envs/gdf/bin/python(_PyFunction_Vectorcall+0x106) [0x562a666318a6]
31  /datasets/pentschev/miniconda3/envs/gdf/bin/python(_PyEval_EvalFrameDefault+0x6d5) [0x562a66621a55]
32  /datasets/pentschev/miniconda3/envs/gdf/bin/python(_PyFunction_Vectorcall+0x106) [0x562a666318a6]
33  /datasets/pentschev/miniconda3/envs/gdf/bin/python(_PyEval_EvalFrameDefault+0x6d5) [0x562a66621a55]
34  /datasets/pentschev/miniconda3/envs/gdf/bin/python(_PyEval_EvalCodeWithName+0x2f1) [0x562a666202f1]
35  /datasets/pentschev/miniconda3/envs/gdf/bin/python(_PyFunction_Vectorcall+0x19c) [0x562a6663193c]
36  /datasets/pentschev/miniconda3/envs/gdf/bin/python(_PyEval_EvalFrameDefault+0x4b7b) [0x562a66625efb]
37  /datasets/pentschev/miniconda3/envs/gdf/bin/python(_PyEval_EvalCodeWithName+0x2f1) [0x562a666202f1]
38  /datasets/pentschev/miniconda3/envs/gdf/bin/python(_PyFunction_Vectorcall+0x19c) [0x562a6663193c]
39  /datasets/pentschev/miniconda3/envs/gdf/bin/python(+0x136e8c) [0x562a6663ee8c]
40  /datasets/pentschev/miniconda3/envs/gdf/bin/python(_PyObject_FastCallDict+0x282) [0x562a66629a92]
41  /datasets/pentschev/miniconda3/envs/gdf/bin/python(+0x1ee049) [0x562a666f6049]
42  /datasets/pentschev/miniconda3/envs/gdf/bin/python(PyObject_Call+0x2d3) [0x562a66641283]
43  /datasets/pentschev/miniconda3/envs/gdf/bin/python(_PyEval_EvalFrameDefault+0x205e) [0x562a666233de]
44  /datasets/pentschev/miniconda3/envs/gdf/bin/python(_PyFunction_Vectorcall+0x106) [0x562a666318a6]
45  /datasets/pentschev/miniconda3/envs/gdf/bin/python(+0x136e8c) [0x562a6663ee8c]
46  /datasets/pentschev/miniconda3/envs/gdf/bin/python(PyObject_Call+0x24a) [0x562a666411fa]
47  /datasets/pentschev/miniconda3/envs/gdf/bin/python(_PyEval_EvalFrameDefault+0x205e) [0x562a666233de]
48  /datasets/pentschev/miniconda3/envs/gdf/bin/python(_PyFunction_Vectorcall+0x106) [0x562a666318a6]
49  /datasets/pentschev/miniconda3/envs/gdf/bin/python(_PyEval_EvalFrameDefault+0x6d5) [0x562a66621a55]
50  /datasets/pentschev/miniconda3/envs/gdf/bin/python(_PyEval_EvalCodeWithName+0x2f1) [0x562a666202f1]
51  /datasets/pentschev/miniconda3/envs/gdf/bin/python(_PyFunction_Vectorcall+0x19c) [0x562a6663193c]
52  /datasets/pentschev/miniconda3/envs/gdf/bin/python(_PyEval_EvalFrameDefault+0x6d5) [0x562a66621a55]
53  /datasets/pentschev/miniconda3/envs/gdf/bin/python(_PyFunction_Vectorcall+0x106) [0x562a666318a6]
54  /datasets/pentschev/miniconda3/envs/gdf/bin/python(_PyEval_EvalFrameDefault+0x3a9) [0x562a66621729]
55  /datasets/pentschev/miniconda3/envs/gdf/bin/python(_PyEval_EvalCodeWithName+0x2f1) [0x562a666202f1]
56  /datasets/pentschev/miniconda3/envs/gdf/bin/python(_PyFunction_Vectorcall+0x19c) [0x562a6663193c]
57  /datasets/pentschev/miniconda3/envs/gdf/bin/python(_PyEval_EvalFrameDefault+0x11bf) [0x562a6662253f]
58  /datasets/pentschev/miniconda3/envs/gdf/bin/python(_PyEval_EvalCodeWithName+0x2f1) [0x562a666202f1]
59  /datasets/pentschev/miniconda3/envs/gdf/bin/python(PyEval_EvalCodeEx+0x39) [0x562a666d2e99]
60  /datasets/pentschev/miniconda3/envs/gdf/bin/python(PyEval_EvalCode+0x1b) [0x562a666d2e5b]
61  /datasets/pentschev/miniconda3/envs/gdf/bin/python(+0x1eb7f9) [0x562a666f37f9]
=================================
[dgx13:40197:0:40197] Caught signal 11 (Segmentation fault: address not mapped to object at address 0x448)
==== backtrace (tid:  40197) ====
 0  /datasets/pentschev/miniconda3/envs/gdf/lib/libucs.so.0(ucs_handle_error+0x2d4) [0x7f01d94ac714]
 1  /datasets/pentschev/miniconda3/envs/gdf/lib/libucs.so.0(+0x2e8ef) [0x7f01d94ac8ef]
 2  /datasets/pentschev/miniconda3/envs/gdf/lib/libucs.so.0(+0x2ec14) [0x7f01d94acc14]
 3  /lib/x86_64-linux-gnu/libpthread.so.0(+0x12980) [0x7f024ef47980]
 4  /datasets/pentschev/miniconda3/envs/gdf/lib/libucp.so.0(ucp_mem_type_unpack+0x14) [0x7f01d97358d4]
 5  /datasets/pentschev/miniconda3/envs/gdf/lib/libucp.so.0(ucp_rndv_data_handler+0x508) [0x7f01d9769608]
 6  /datasets/pentschev/miniconda3/envs/gdf/lib/libuct.so.0(+0x20b6f) [0x7f01d9260b6f]
 7  /datasets/pentschev/miniconda3/envs/gdf/lib/libuct.so.0(+0x21144) [0x7f01d9261144]
 8  /datasets/pentschev/miniconda3/envs/gdf/lib/libuct.so.0(+0x235a8) [0x7f01d92635a8]
 9  /datasets/pentschev/miniconda3/envs/gdf/lib/libucs.so.0(ucs_event_set_wait+0xb9) [0x7f01d94b6de9]
10  /datasets/pentschev/miniconda3/envs/gdf/lib/libuct.so.0(uct_tcp_iface_progress+0x7b) [0x7f01d926364b]
11  /datasets/pentschev/miniconda3/envs/gdf/lib/libucp.so.0(ucp_worker_progress+0x6a) [0x7f01d9731eba]
12  /datasets/pentschev/miniconda3/envs/gdf/lib/python3.8/site-packages/ucp/_libs/ucx_api.cpython-38-x86_64-linux-gnu.so(+0x272b9) [0x7f01d99f12b9]
13  /datasets/pentschev/miniconda3/envs/gdf/bin/python(+0x12e343) [0x561d3ebb1343]
14  /datasets/pentschev/miniconda3/envs/gdf/bin/python(PyObject_Call+0x24a) [0x561d3ebbc1fa]
15  /datasets/pentschev/miniconda3/envs/gdf/bin/python(_PyEval_EvalFrameDefault+0x680b) [0x561d3eba2b8b]
16  /datasets/pentschev/miniconda3/envs/gdf/bin/python(_PyEval_EvalCodeWithName+0x2f1) [0x561d3eb9b2f1]
17  /datasets/pentschev/miniconda3/envs/gdf/bin/python(_PyFunction_Vectorcall+0x19c) [0x561d3ebac93c]
18  /datasets/pentschev/miniconda3/envs/gdf/bin/python(_PyEval_EvalFrameDefault+0x6d5) [0x561d3eb9ca55]
19  /datasets/pentschev/miniconda3/envs/gdf/bin/python(+0x13e1e8) [0x561d3ebc11e8]
20  /datasets/pentschev/miniconda3/envs/gdf/lib/python3.8/lib-dynload/_asyncio.cpython-38-x86_64-linux-gnu.so(+0x7003) [0x7f01e964a003]
21  /datasets/pentschev/miniconda3/envs/gdf/bin/python(_PyObject_MakeTpCall+0x3db) [0x561d3eba530b]
22  /datasets/pentschev/miniconda3/envs/gdf/bin/python(+0xe0b07) [0x561d3eb63b07]
23  /datasets/pentschev/miniconda3/envs/gdf/bin/python(+0x120f96) [0x561d3eba3f96]
24  /datasets/pentschev/miniconda3/envs/gdf/bin/python(PyVectorcall_Call+0x7a) [0x561d3ebba1ea]
25  /datasets/pentschev/miniconda3/envs/gdf/bin/python(_PyEval_EvalFrameDefault+0x5df8) [0x561d3eba2178]
26  /datasets/pentschev/miniconda3/envs/gdf/bin/python(_PyFunction_Vectorcall+0x106) [0x561d3ebac8a6]
27  /datasets/pentschev/miniconda3/envs/gdf/bin/python(_PyEval_EvalFrameDefault+0x6d5) [0x561d3eb9ca55]
28  /datasets/pentschev/miniconda3/envs/gdf/bin/python(_PyFunction_Vectorcall+0x106) [0x561d3ebac8a6]
29  /datasets/pentschev/miniconda3/envs/gdf/bin/python(_PyEval_EvalFrameDefault+0x6d5) [0x561d3eb9ca55]
30  /datasets/pentschev/miniconda3/envs/gdf/bin/python(_PyFunction_Vectorcall+0x106) [0x561d3ebac8a6]
31  /datasets/pentschev/miniconda3/envs/gdf/bin/python(_PyEval_EvalFrameDefault+0x6d5) [0x561d3eb9ca55]
32  /datasets/pentschev/miniconda3/envs/gdf/bin/python(_PyFunction_Vectorcall+0x106) [0x561d3ebac8a6]
33  /datasets/pentschev/miniconda3/envs/gdf/bin/python(_PyEval_EvalFrameDefault+0x6d5) [0x561d3eb9ca55]
34  /datasets/pentschev/miniconda3/envs/gdf/bin/python(_PyEval_EvalCodeWithName+0x2f1) [0x561d3eb9b2f1]
35  /datasets/pentschev/miniconda3/envs/gdf/bin/python(_PyFunction_Vectorcall+0x19c) [0x561d3ebac93c]
36  /datasets/pentschev/miniconda3/envs/gdf/bin/python(_PyEval_EvalFrameDefault+0x4b7b) [0x561d3eba0efb]
37  /datasets/pentschev/miniconda3/envs/gdf/bin/python(_PyEval_EvalCodeWithName+0x2f1) [0x561d3eb9b2f1]
38  /datasets/pentschev/miniconda3/envs/gdf/bin/python(_PyFunction_Vectorcall+0x19c) [0x561d3ebac93c]
39  /datasets/pentschev/miniconda3/envs/gdf/bin/python(+0x136e8c) [0x561d3ebb9e8c]
40  /datasets/pentschev/miniconda3/envs/gdf/bin/python(_PyObject_FastCallDict+0x282) [0x561d3eba4a92]
41  /datasets/pentschev/miniconda3/envs/gdf/bin/python(+0x1ee049) [0x561d3ec71049]
42  /datasets/pentschev/miniconda3/envs/gdf/bin/python(PyObject_Call+0x2d3) [0x561d3ebbc283]
43  /datasets/pentschev/miniconda3/envs/gdf/bin/python(_PyEval_EvalFrameDefault+0x205e) [0x561d3eb9e3de]
44  /datasets/pentschev/miniconda3/envs/gdf/bin/python(_PyFunction_Vectorcall+0x106) [0x561d3ebac8a6]
45  /datasets/pentschev/miniconda3/envs/gdf/bin/python(+0x136e8c) [0x561d3ebb9e8c]
46  /datasets/pentschev/miniconda3/envs/gdf/bin/python(PyObject_Call+0x24a) [0x561d3ebbc1fa]
47  /datasets/pentschev/miniconda3/envs/gdf/bin/python(_PyEval_EvalFrameDefault+0x205e) [0x561d3eb9e3de]
48  /datasets/pentschev/miniconda3/envs/gdf/bin/python(_PyFunction_Vectorcall+0x106) [0x561d3ebac8a6]
49  /datasets/pentschev/miniconda3/envs/gdf/bin/python(_PyEval_EvalFrameDefault+0x6d5) [0x561d3eb9ca55]
50  /datasets/pentschev/miniconda3/envs/gdf/bin/python(_PyEval_EvalCodeWithName+0x2f1) [0x561d3eb9b2f1]
51  /datasets/pentschev/miniconda3/envs/gdf/bin/python(_PyFunction_Vectorcall+0x19c) [0x561d3ebac93c]
52  /datasets/pentschev/miniconda3/envs/gdf/bin/python(_PyEval_EvalFrameDefault+0x6d5) [0x561d3eb9ca55]
53  /datasets/pentschev/miniconda3/envs/gdf/bin/python(_PyFunction_Vectorcall+0x106) [0x561d3ebac8a6]
54  /datasets/pentschev/miniconda3/envs/gdf/bin/python(_PyEval_EvalFrameDefault+0x3a9) [0x561d3eb9c729]
55  /datasets/pentschev/miniconda3/envs/gdf/bin/python(_PyEval_EvalCodeWithName+0x2f1) [0x561d3eb9b2f1]
56  /datasets/pentschev/miniconda3/envs/gdf/bin/python(_PyFunction_Vectorcall+0x19c) [0x561d3ebac93c]
57  /datasets/pentschev/miniconda3/envs/gdf/bin/python(_PyEval_EvalFrameDefault+0x11bf) [0x561d3eb9d53f]
58  /datasets/pentschev/miniconda3/envs/gdf/bin/python(_PyEval_EvalCodeWithName+0x2f1) [0x561d3eb9b2f1]
59  /datasets/pentschev/miniconda3/envs/gdf/bin/python(PyEval_EvalCodeEx+0x39) [0x561d3ec4de99]
60  /datasets/pentschev/miniconda3/envs/gdf/bin/python(PyEval_EvalCode+0x1b) [0x561d3ec4de5b]
61  /datasets/pentschev/miniconda3/envs/gdf/bin/python(+0x1eb7f9) [0x561d3ec6e7f9]
=================================
2023-03-25 01:12:21,299 - distributed.worker - ERROR - Worker stream died during communication: ucx://127.0.0.1:39727
Traceback (most recent call last):
  File "/datasets/pentschev/miniconda3/envs/gdf/lib/python3.8/site-packages/distributed/comm/ucx.py", line 391, in read
    await self.ep.recv(each_frame)
  File "/datasets/pentschev/miniconda3/envs/gdf/lib/python3.8/site-packages/ucp/core.py", line 725, in recv
    ret = await comm.tag_recv(self._ep, buffer, nbytes, tag, name=log)
ucp._libs.exceptions.UCXCanceled: <[Recv #009] ep: 0x7fc5e8051200, tag: 0xd5028756c481e43b, nbytes: 100000000, type: <class 'rmm._lib.device_buffer.DeviceBuffer'>>: 

During handling of the above exception, another exception occurred:

Traceback (most recent call last):
  File "/datasets/pentschev/miniconda3/envs/gdf/lib/python3.8/site-packages/distributed/worker.py", line 2066, in gather_dep
    response = await get_data_from_worker(
  File "/datasets/pentschev/miniconda3/envs/gdf/lib/python3.8/site-packages/distributed/worker.py", line 2892, in get_data_from_worker
    response = await send_recv(
  File "/datasets/pentschev/miniconda3/envs/gdf/lib/python3.8/site-packages/distributed/core.py", line 1024, in send_recv
    response = await comm.read(deserializers=deserializers)
  File "/datasets/pentschev/miniconda3/envs/gdf/lib/python3.8/site-packages/distributed/utils.py", line 752, in wrapper
    return await func(*args, **kwargs)
  File "/datasets/pentschev/miniconda3/envs/gdf/lib/python3.8/site-packages/distributed/comm/ucx.py", line 397, in read
    raise CommClosedError(
distributed.comm.core.CommClosedError: Connection closed by writer.
Inner exception: UCXCanceled("<[Recv #009] ep: 0x7fc5e8051200, tag: 0xd5028756c481e43b, nbytes: 100000000, type: <class 'rmm._lib.device_buffer.DeviceBuffer'>>: ")
2023-03-25 01:12:21,300 - distributed.worker - ERROR - Worker stream died during communication: ucx://127.0.0.1:39727
Traceback (most recent call last):
  File "/datasets/pentschev/miniconda3/envs/gdf/lib/python3.8/site-packages/distributed/comm/ucx.py", line 349, in read
    await self.ep.recv(msg)
  File "/datasets/pentschev/miniconda3/envs/gdf/lib/python3.8/site-packages/ucp/core.py", line 725, in recv
    ret = await comm.tag_recv(self._ep, buffer, nbytes, tag, name=log)
ucp._libs.exceptions.UCXCanceled: <[Recv #003] ep: 0x7fe6ac19f180, tag: 0x4b418834e4da59a6, nbytes: 16, type: <class 'numpy.ndarray'>>: 

During handling of the above exception, another exception occurred:

Traceback (most recent call last):
  File "/datasets/pentschev/miniconda3/envs/gdf/lib/python3.8/site-packages/distributed/worker.py", line 2066, in gather_dep
    response = await get_data_from_worker(
  File "/datasets/pentschev/miniconda3/envs/gdf/lib/python3.8/site-packages/distributed/worker.py", line 2892, in get_data_from_worker
    response = await send_recv(
  File "/datasets/pentschev/miniconda3/envs/gdf/lib/python3.8/site-packages/distributed/core.py", line 1024, in send_recv
    response = await comm.read(deserializers=deserializers)
  File "/datasets/pentschev/miniconda3/envs/gdf/lib/python3.8/site-packages/distributed/utils.py", line 752, in wrapper
    return await func(*args, **kwargs)
  File "/datasets/pentschev/miniconda3/envs/gdf/lib/python3.8/site-packages/distributed/comm/ucx.py", line 367, in read
    raise CommClosedError(
distributed.comm.core.CommClosedError: Connection closed by writer.
Inner exception: UCXCanceled("<[Recv #003] ep: 0x7fe6ac19f180, tag: 0x4b418834e4da59a6, nbytes: 16, type: <class 'numpy.ndarray'>>: ")
2023-03-25 01:12:21,315 - distributed.worker - ERROR - Worker stream died during communication: ucx://127.0.0.1:37099
Traceback (most recent call last):
  File "/datasets/pentschev/miniconda3/envs/gdf/lib/python3.8/site-packages/distributed/comm/ucx.py", line 391, in read
    await self.ep.recv(each_frame)
  File "/datasets/pentschev/miniconda3/envs/gdf/lib/python3.8/site-packages/ucp/core.py", line 725, in recv
    ret = await comm.tag_recv(self._ep, buffer, nbytes, tag, name=log)
ucp._libs.exceptions.UCXError: <[Recv #007] ep: 0x7fc5e8051140, tag: 0xb88ce01a8c67b5ce, nbytes: 100000000, type: <class 'rmm._lib.device_buffer.DeviceBuffer'>>: Connection reset by remote peer

During handling of the above exception, another exception occurred:

Traceback (most recent call last):
  File "/datasets/pentschev/miniconda3/envs/gdf/lib/python3.8/site-packages/distributed/worker.py", line 2066, in gather_dep
    response = await get_data_from_worker(
  File "/datasets/pentschev/miniconda3/envs/gdf/lib/python3.8/site-packages/distributed/worker.py", line 2892, in get_data_from_worker
    response = await send_recv(
  File "/datasets/pentschev/miniconda3/envs/gdf/lib/python3.8/site-packages/distributed/core.py", line 1024, in send_recv
    response = await comm.read(deserializers=deserializers)
  File "/datasets/pentschev/miniconda3/envs/gdf/lib/python3.8/site-packages/distributed/utils.py", line 752, in wrapper
    return await func(*args, **kwargs)
  File "/datasets/pentschev/miniconda3/envs/gdf/lib/python3.8/site-packages/distributed/comm/ucx.py", line 397, in read
    raise CommClosedError(
distributed.comm.core.CommClosedError: Connection closed by writer.
Inner exception: UCXError("<[Recv #007] ep: 0x7fc5e8051140, tag: 0xb88ce01a8c67b5ce, nbytes: 100000000, type: <class 'rmm._lib.device_buffer.DeviceBuffer'>>: Connection reset by remote peer")
2023-03-25 01:12:21,321 - distributed.worker - ERROR - failed during get data with ucx://127.0.0.1:42639 -> ucx://127.0.0.1:39727
Traceback (most recent call last):
  File "/datasets/pentschev/miniconda3/envs/gdf/lib/python3.8/site-packages/distributed/worker.py", line 1792, in get_data
    compressed = await comm.write(msg, serializers=serializers)
  File "/datasets/pentschev/miniconda3/envs/gdf/lib/python3.8/site-packages/distributed/utils.py", line 752, in wrapper
    return await func(*args, **kwargs)
  File "/datasets/pentschev/miniconda3/envs/gdf/lib/python3.8/site-packages/distributed/comm/ucx.py", line 289, in write
    raise CommClosedError("Endpoint is closed -- unable to send message")
distributed.comm.core.CommClosedError: Endpoint is closed -- unable to send message
2023-03-25 01:12:21,333 - distributed.worker - ERROR - Worker stream died during communication: ucx://127.0.0.1:60793
Traceback (most recent call last):
  File "/datasets/pentschev/miniconda3/envs/gdf/lib/python3.8/site-packages/distributed/comm/ucx.py", line 391, in read
    await self.ep.recv(each_frame)
  File "/datasets/pentschev/miniconda3/envs/gdf/lib/python3.8/site-packages/ucp/core.py", line 725, in recv
    ret = await comm.tag_recv(self._ep, buffer, nbytes, tag, name=log)
ucp._libs.exceptions.UCXError: <[Recv #007] ep: 0x7fc5e8051240, tag: 0xf9ced4d67e0fb644, nbytes: 100000000, type: <class 'rmm._lib.device_buffer.DeviceBuffer'>>: Connection reset by remote peer

During handling of the above exception, another exception occurred:

Traceback (most recent call last):
  File "/datasets/pentschev/miniconda3/envs/gdf/lib/python3.8/site-packages/distributed/worker.py", line 2066, in gather_dep
    response = await get_data_from_worker(
  File "/datasets/pentschev/miniconda3/envs/gdf/lib/python3.8/site-packages/distributed/worker.py", line 2892, in get_data_from_worker
    response = await send_recv(
  File "/datasets/pentschev/miniconda3/envs/gdf/lib/python3.8/site-packages/distributed/core.py", line 1024, in send_recv
    response = await comm.read(deserializers=deserializers)
  File "/datasets/pentschev/miniconda3/envs/gdf/lib/python3.8/site-packages/distributed/utils.py", line 752, in wrapper
    return await func(*args, **kwargs)
  File "/datasets/pentschev/miniconda3/envs/gdf/lib/python3.8/site-packages/distributed/comm/ucx.py", line 397, in read
    raise CommClosedError(
distributed.comm.core.CommClosedError: Connection closed by writer.
Inner exception: UCXError("<[Recv #007] ep: 0x7fc5e8051240, tag: 0xf9ced4d67e0fb644, nbytes: 100000000, type: <class 'rmm._lib.device_buffer.DeviceBuffer'>>: Connection reset by remote peer")
2023-03-25 01:12:21,333 - distributed.worker - ERROR - failed during get data with ucx://127.0.0.1:41217 -> ucx://127.0.0.1:60793
Traceback (most recent call last):
  File "/datasets/pentschev/miniconda3/envs/gdf/lib/python3.8/site-packages/distributed/comm/ucx.py", line 333, in write
    await self.ep.send(each_frame)
  File "/datasets/pentschev/miniconda3/envs/gdf/lib/python3.8/site-packages/ucp/core.py", line 650, in send
    return await comm.tag_send(self._ep, buffer, nbytes, tag, name=log)
ucp._libs.exceptions.UCXError: <[Send #007] ep: 0x7fc5e8051300, tag: 0xec240c5353965547, nbytes: 100000000, type: <class 'cudf.core.buffer.buffer.Buffer'>>: Connection reset by remote peer

During handling of the above exception, another exception occurred:

Traceback (most recent call last):
  File "/datasets/pentschev/miniconda3/envs/gdf/lib/python3.8/site-packages/distributed/worker.py", line 1792, in get_data
    compressed = await comm.write(msg, serializers=serializers)
  File "/datasets/pentschev/miniconda3/envs/gdf/lib/python3.8/site-packages/distributed/utils.py", line 752, in wrapper
    return await func(*args, **kwargs)
  File "/datasets/pentschev/miniconda3/envs/gdf/lib/python3.8/site-packages/distributed/comm/ucx.py", line 337, in write
    raise CommClosedError("While writing, the connection was closed")
distributed.comm.core.CommClosedError: While writing, the connection was closed
2023-03-25 01:12:21,381 - distributed.nanny - WARNING - Restarting worker
2023-03-25 01:12:21,422 - distributed.worker - ERROR - failed during get data with ucx://127.0.0.1:40043 -> ucx://127.0.0.1:60793
Traceback (most recent call last):
  File "/datasets/pentschev/miniconda3/envs/gdf/lib/python3.8/site-packages/distributed/comm/ucx.py", line 333, in write
    await self.ep.send(each_frame)
  File "/datasets/pentschev/miniconda3/envs/gdf/lib/python3.8/site-packages/ucp/core.py", line 650, in send
    return await comm.tag_send(self._ep, buffer, nbytes, tag, name=log)
ucp._libs.exceptions.UCXError: <[Send #007] ep: 0x7fe6ac19f340, tag: 0xb496b2e956f78759, nbytes: 100000000, type: <class 'cudf.core.buffer.buffer.Buffer'>>: Connection reset by remote peer

During handling of the above exception, another exception occurred:

Traceback (most recent call last):
  File "/datasets/pentschev/miniconda3/envs/gdf/lib/python3.8/site-packages/distributed/worker.py", line 1792, in get_data
    compressed = await comm.write(msg, serializers=serializers)
  File "/datasets/pentschev/miniconda3/envs/gdf/lib/python3.8/site-packages/distributed/utils.py", line 752, in wrapper
    return await func(*args, **kwargs)
  File "/datasets/pentschev/miniconda3/envs/gdf/lib/python3.8/site-packages/distributed/comm/ucx.py", line 337, in write
    raise CommClosedError("While writing, the connection was closed")
distributed.comm.core.CommClosedError: While writing, the connection was closed
2023-03-25 01:12:21,423 - distributed.worker - ERROR - Worker stream died during communication: ucx://127.0.0.1:60793
Traceback (most recent call last):
  File "/datasets/pentschev/miniconda3/envs/gdf/lib/python3.8/site-packages/distributed/comm/ucx.py", line 349, in read
    await self.ep.recv(msg)
  File "/datasets/pentschev/miniconda3/envs/gdf/lib/python3.8/site-packages/ucp/core.py", line 725, in recv
    ret = await comm.tag_recv(self._ep, buffer, nbytes, tag, name=log)
ucp._libs.exceptions.UCXCanceled: <[Recv #003] ep: 0x7fe6ac19f140, tag: 0x53f241d3f69bf230, nbytes: 16, type: <class 'numpy.ndarray'>>: 

During handling of the above exception, another exception occurred:

Traceback (most recent call last):
  File "/datasets/pentschev/miniconda3/envs/gdf/lib/python3.8/site-packages/distributed/worker.py", line 2066, in gather_dep
    response = await get_data_from_worker(
  File "/datasets/pentschev/miniconda3/envs/gdf/lib/python3.8/site-packages/distributed/worker.py", line 2892, in get_data_from_worker
    response = await send_recv(
  File "/datasets/pentschev/miniconda3/envs/gdf/lib/python3.8/site-packages/distributed/core.py", line 1024, in send_recv
    response = await comm.read(deserializers=deserializers)
  File "/datasets/pentschev/miniconda3/envs/gdf/lib/python3.8/site-packages/distributed/utils.py", line 752, in wrapper
    return await func(*args, **kwargs)
  File "/datasets/pentschev/miniconda3/envs/gdf/lib/python3.8/site-packages/distributed/comm/ucx.py", line 367, in read
    raise CommClosedError(
distributed.comm.core.CommClosedError: Connection closed by writer.
Inner exception: UCXCanceled("<[Recv #003] ep: 0x7fe6ac19f140, tag: 0x53f241d3f69bf230, nbytes: 16, type: <class 'numpy.ndarray'>>: ")
2023-03-25 01:12:21,423 - distributed.worker - ERROR - Worker stream died during communication: ucx://127.0.0.1:38581
Traceback (most recent call last):
  File "/datasets/pentschev/miniconda3/envs/gdf/lib/python3.8/site-packages/distributed/comm/ucx.py", line 349, in read
    await self.ep.recv(msg)
  File "/datasets/pentschev/miniconda3/envs/gdf/lib/python3.8/site-packages/ucp/core.py", line 725, in recv
    ret = await comm.tag_recv(self._ep, buffer, nbytes, tag, name=log)
ucp._libs.exceptions.UCXCanceled: <[Recv #003] ep: 0x7fe6ac19f1c0, tag: 0x9c67cd431a0da3b7, nbytes: 16, type: <class 'numpy.ndarray'>>: 

During handling of the above exception, another exception occurred:

Traceback (most recent call last):
  File "/datasets/pentschev/miniconda3/envs/gdf/lib/python3.8/site-packages/distributed/worker.py", line 2066, in gather_dep
    response = await get_data_from_worker(
  File "/datasets/pentschev/miniconda3/envs/gdf/lib/python3.8/site-packages/distributed/worker.py", line 2892, in get_data_from_worker
    response = await send_recv(
  File "/datasets/pentschev/miniconda3/envs/gdf/lib/python3.8/site-packages/distributed/core.py", line 1024, in send_recv
    response = await comm.read(deserializers=deserializers)
  File "/datasets/pentschev/miniconda3/envs/gdf/lib/python3.8/site-packages/distributed/utils.py", line 752, in wrapper
    return await func(*args, **kwargs)
  File "/datasets/pentschev/miniconda3/envs/gdf/lib/python3.8/site-packages/distributed/comm/ucx.py", line 367, in read
    raise CommClosedError(
distributed.comm.core.CommClosedError: Connection closed by writer.
Inner exception: UCXCanceled("<[Recv #003] ep: 0x7fe6ac19f1c0, tag: 0x9c67cd431a0da3b7, nbytes: 16, type: <class 'numpy.ndarray'>>: ")
2023-03-25 01:12:21,424 - distributed.worker - ERROR - Worker stream died during communication: ucx://127.0.0.1:37099
Traceback (most recent call last):
  File "/datasets/pentschev/miniconda3/envs/gdf/lib/python3.8/site-packages/distributed/comm/ucx.py", line 391, in read
    await self.ep.recv(each_frame)
  File "/datasets/pentschev/miniconda3/envs/gdf/lib/python3.8/site-packages/ucp/core.py", line 725, in recv
    ret = await comm.tag_recv(self._ep, buffer, nbytes, tag, name=log)
ucp._libs.exceptions.UCXCanceled: <[Recv #008] ep: 0x7fe6ac19f100, tag: 0xb2b7b45a7ad35365, nbytes: 100000000, type: <class 'rmm._lib.device_buffer.DeviceBuffer'>>: 

During handling of the above exception, another exception occurred:

Traceback (most recent call last):
  File "/datasets/pentschev/miniconda3/envs/gdf/lib/python3.8/site-packages/distributed/worker.py", line 2066, in gather_dep
    response = await get_data_from_worker(
  File "/datasets/pentschev/miniconda3/envs/gdf/lib/python3.8/site-packages/distributed/worker.py", line 2892, in get_data_from_worker
    response = await send_recv(
  File "/datasets/pentschev/miniconda3/envs/gdf/lib/python3.8/site-packages/distributed/core.py", line 1024, in send_recv
    response = await comm.read(deserializers=deserializers)
  File "/datasets/pentschev/miniconda3/envs/gdf/lib/python3.8/site-packages/distributed/utils.py", line 752, in wrapper
    return await func(*args, **kwargs)
  File "/datasets/pentschev/miniconda3/envs/gdf/lib/python3.8/site-packages/distributed/comm/ucx.py", line 397, in read
    raise CommClosedError(
distributed.comm.core.CommClosedError: Connection closed by writer.
Inner exception: UCXCanceled("<[Recv #008] ep: 0x7fe6ac19f100, tag: 0xb2b7b45a7ad35365, nbytes: 100000000, type: <class 'rmm._lib.device_buffer.DeviceBuffer'>>: ")
2023-03-25 01:12:21,454 - distributed.worker - ERROR - Worker stream died during communication: ucx://127.0.0.1:38581
Traceback (most recent call last):
  File "/datasets/pentschev/miniconda3/envs/gdf/lib/python3.8/site-packages/distributed/comm/ucx.py", line 391, in read
    await self.ep.recv(each_frame)
  File "/datasets/pentschev/miniconda3/envs/gdf/lib/python3.8/site-packages/ucp/core.py", line 725, in recv
    ret = await comm.tag_recv(self._ep, buffer, nbytes, tag, name=log)
ucp._libs.exceptions.UCXCanceled: <[Recv #009] ep: 0x7fc5e8051180, tag: 0x78486f4639d1301c, nbytes: 100000000, type: <class 'rmm._lib.device_buffer.DeviceBuffer'>>: 

During handling of the above exception, another exception occurred:

Traceback (most recent call last):
  File "/datasets/pentschev/miniconda3/envs/gdf/lib/python3.8/site-packages/distributed/worker.py", line 2066, in gather_dep
    response = await get_data_from_worker(
  File "/datasets/pentschev/miniconda3/envs/gdf/lib/python3.8/site-packages/distributed/worker.py", line 2892, in get_data_from_worker
    response = await send_recv(
  File "/datasets/pentschev/miniconda3/envs/gdf/lib/python3.8/site-packages/distributed/core.py", line 1024, in send_recv
    response = await comm.read(deserializers=deserializers)
  File "/datasets/pentschev/miniconda3/envs/gdf/lib/python3.8/site-packages/distributed/utils.py", line 752, in wrapper
    return await func(*args, **kwargs)
  File "/datasets/pentschev/miniconda3/envs/gdf/lib/python3.8/site-packages/distributed/comm/ucx.py", line 397, in read
    raise CommClosedError(
distributed.comm.core.CommClosedError: Connection closed by writer.
Inner exception: UCXCanceled("<[Recv #009] ep: 0x7fc5e8051180, tag: 0x78486f4639d1301c, nbytes: 100000000, type: <class 'rmm._lib.device_buffer.DeviceBuffer'>>: ")
2023-03-25 01:12:21,464 - distributed.nanny - WARNING - Restarting worker
2023-03-25 01:12:21,534 - distributed.worker - ERROR - failed during get data with ucx://127.0.0.1:42639 -> ucx://127.0.0.1:38581
Traceback (most recent call last):
  File "/datasets/pentschev/miniconda3/envs/gdf/lib/python3.8/site-packages/distributed/worker.py", line 1792, in get_data
    compressed = await comm.write(msg, serializers=serializers)
  File "/datasets/pentschev/miniconda3/envs/gdf/lib/python3.8/site-packages/distributed/utils.py", line 752, in wrapper
    return await func(*args, **kwargs)
  File "/datasets/pentschev/miniconda3/envs/gdf/lib/python3.8/site-packages/distributed/comm/ucx.py", line 289, in write
    raise CommClosedError("Endpoint is closed -- unable to send message")
distributed.comm.core.CommClosedError: Endpoint is closed -- unable to send message
2023-03-25 01:12:21,537 - distributed.worker - ERROR - Worker stream died during communication: ucx://127.0.0.1:37099
Traceback (most recent call last):
  File "/datasets/pentschev/miniconda3/envs/gdf/lib/python3.8/site-packages/distributed/comm/core.py", line 330, in connect
    await wait_for(comm.write(local_info), time_left())
  File "/datasets/pentschev/miniconda3/envs/gdf/lib/python3.8/site-packages/distributed/utils.py", line 1849, in wait_for
    return await asyncio.wait_for(fut, timeout)
  File "/datasets/pentschev/miniconda3/envs/gdf/lib/python3.8/asyncio/tasks.py", line 494, in wait_for
    return fut.result()
  File "/datasets/pentschev/miniconda3/envs/gdf/lib/python3.8/site-packages/distributed/utils.py", line 752, in wrapper
    return await func(*args, **kwargs)
  File "/datasets/pentschev/miniconda3/envs/gdf/lib/python3.8/site-packages/distributed/comm/ucx.py", line 289, in write
    raise CommClosedError("Endpoint is closed -- unable to send message")
distributed.comm.core.CommClosedError: Endpoint is closed -- unable to send message

The above exception was the direct cause of the following exception:

Traceback (most recent call last):
  File "/datasets/pentschev/miniconda3/envs/gdf/lib/python3.8/site-packages/distributed/worker.py", line 2066, in gather_dep
    response = await get_data_from_worker(
  File "/datasets/pentschev/miniconda3/envs/gdf/lib/python3.8/site-packages/distributed/worker.py", line 2889, in get_data_from_worker
    comm = await rpc.connect(worker)
  File "/datasets/pentschev/miniconda3/envs/gdf/lib/python3.8/site-packages/distributed/core.py", line 1506, in connect
    return await connect_attempt
  File "/datasets/pentschev/miniconda3/envs/gdf/lib/python3.8/site-packages/distributed/core.py", line 1427, in _connect
    comm = await connect(
  File "/datasets/pentschev/miniconda3/envs/gdf/lib/python3.8/site-packages/distributed/comm/core.py", line 334, in connect
    raise OSError(
OSError: Timed out during handshake while connecting to ucx://127.0.0.1:37099 after 30 s
2023-03-25 01:12:21,604 - distributed.nanny - WARNING - Restarting worker
2023-03-25 01:12:21,606 - distributed.nanny - WARNING - Restarting worker
2023-03-25 01:12:21,542 - distributed.worker - ERROR - Worker stream died during communication: ucx://127.0.0.1:38581
Traceback (most recent call last):
  File "/datasets/pentschev/miniconda3/envs/gdf/lib/python3.8/asyncio/tasks.py", line 481, in wait_for
    await waiter
asyncio.exceptions.CancelledError

During handling of the above exception, another exception occurred:

Traceback (most recent call last):
  File "/datasets/pentschev/miniconda3/envs/gdf/lib/python3.8/site-packages/distributed/comm/core.py", line 330, in connect
    await wait_for(comm.write(local_info), time_left())
  File "/datasets/pentschev/miniconda3/envs/gdf/lib/python3.8/site-packages/distributed/utils.py", line 1849, in wait_for
    return await asyncio.wait_for(fut, timeout)
  File "/datasets/pentschev/miniconda3/envs/gdf/lib/python3.8/asyncio/tasks.py", line 484, in wait_for
    return fut.result()
  File "/datasets/pentschev/miniconda3/envs/gdf/lib/python3.8/site-packages/distributed/utils.py", line 752, in wrapper
    return await func(*args, **kwargs)
  File "/datasets/pentschev/miniconda3/envs/gdf/lib/python3.8/site-packages/distributed/comm/ucx.py", line 289, in write
    raise CommClosedError("Endpoint is closed -- unable to send message")
distributed.comm.core.CommClosedError: Endpoint is closed -- unable to send message

The above exception was the direct cause of the following exception:

Traceback (most recent call last):
  File "/datasets/pentschev/miniconda3/envs/gdf/lib/python3.8/site-packages/distributed/worker.py", line 2066, in gather_dep
    response = await get_data_from_worker(
  File "/datasets/pentschev/miniconda3/envs/gdf/lib/python3.8/site-packages/distributed/worker.py", line 2889, in get_data_from_worker
    comm = await rpc.connect(worker)
  File "/datasets/pentschev/miniconda3/envs/gdf/lib/python3.8/site-packages/distributed/core.py", line 1506, in connect
    return await connect_attempt
  File "/datasets/pentschev/miniconda3/envs/gdf/lib/python3.8/site-packages/distributed/core.py", line 1427, in _connect
    comm = await connect(
  File "/datasets/pentschev/miniconda3/envs/gdf/lib/python3.8/site-packages/distributed/comm/core.py", line 334, in connect
    raise OSError(
OSError: Timed out during handshake while connecting to ucx://127.0.0.1:38581 after 30 s
2023-03-25 01:12:21,721 - distributed.worker - ERROR - Worker stream died during communication: ucx://127.0.0.1:39727
Traceback (most recent call last):
  File "/datasets/pentschev/miniconda3/envs/gdf/lib/python3.8/site-packages/distributed/comm/core.py", line 330, in connect
    await wait_for(comm.write(local_info), time_left())
  File "/datasets/pentschev/miniconda3/envs/gdf/lib/python3.8/site-packages/distributed/utils.py", line 1849, in wait_for
    return await asyncio.wait_for(fut, timeout)
  File "/datasets/pentschev/miniconda3/envs/gdf/lib/python3.8/asyncio/tasks.py", line 494, in wait_for
    return fut.result()
  File "/datasets/pentschev/miniconda3/envs/gdf/lib/python3.8/site-packages/distributed/utils.py", line 752, in wrapper
    return await func(*args, **kwargs)
  File "/datasets/pentschev/miniconda3/envs/gdf/lib/python3.8/site-packages/distributed/comm/ucx.py", line 289, in write
    raise CommClosedError("Endpoint is closed -- unable to send message")
distributed.comm.core.CommClosedError: Endpoint is closed -- unable to send message

The above exception was the direct cause of the following exception:

Traceback (most recent call last):
  File "/datasets/pentschev/miniconda3/envs/gdf/lib/python3.8/site-packages/distributed/worker.py", line 2066, in gather_dep
    response = await get_data_from_worker(
  File "/datasets/pentschev/miniconda3/envs/gdf/lib/python3.8/site-packages/distributed/worker.py", line 2889, in get_data_from_worker
    comm = await rpc.connect(worker)
  File "/datasets/pentschev/miniconda3/envs/gdf/lib/python3.8/site-packages/distributed/core.py", line 1506, in connect
    return await connect_attempt
  File "/datasets/pentschev/miniconda3/envs/gdf/lib/python3.8/site-packages/distributed/core.py", line 1427, in _connect
    comm = await connect(
  File "/datasets/pentschev/miniconda3/envs/gdf/lib/python3.8/site-packages/distributed/comm/core.py", line 334, in connect
    raise OSError(
OSError: Timed out during handshake while connecting to ucx://127.0.0.1:39727 after 30 s
[dgx13:40204:0:40204] Caught signal 11 (Segmentation fault: address not mapped to object at address 0x448)
==== backtrace (tid:  40204) ====
 0  /datasets/pentschev/miniconda3/envs/gdf/lib/libucs.so.0(ucs_handle_error+0x2d4) [0x7fee68b6f714]
 1  /datasets/pentschev/miniconda3/envs/gdf/lib/libucs.so.0(+0x2e8ef) [0x7fee68b6f8ef]
 2  /datasets/pentschev/miniconda3/envs/gdf/lib/libucs.so.0(+0x2ec14) [0x7fee68b6fc14]
 3  /lib/x86_64-linux-gnu/libpthread.so.0(+0x12980) [0x7feeec620980]
 4  /datasets/pentschev/miniconda3/envs/gdf/lib/libucp.so.0(ucp_mem_type_unpack+0x14) [0x7fee68df88d4]
 5  /datasets/pentschev/miniconda3/envs/gdf/lib/libucp.so.0(ucp_rndv_data_handler+0x508) [0x7fee68e2c608]
 6  /datasets/pentschev/miniconda3/envs/gdf/lib/libuct.so.0(+0x20b6f) [0x7fee68923b6f]
 7  /datasets/pentschev/miniconda3/envs/gdf/lib/libuct.so.0(+0x21144) [0x7fee68924144]
 8  /datasets/pentschev/miniconda3/envs/gdf/lib/libuct.so.0(+0x235a8) [0x7fee689265a8]
 9  /datasets/pentschev/miniconda3/envs/gdf/lib/libucs.so.0(ucs_event_set_wait+0xb9) [0x7fee68b79de9]
10  /datasets/pentschev/miniconda3/envs/gdf/lib/libuct.so.0(uct_tcp_iface_progress+0x7b) [0x7fee6892664b]
11  /datasets/pentschev/miniconda3/envs/gdf/lib/libucp.so.0(ucp_worker_progress+0x6a) [0x7fee68df4eba]
12  /datasets/pentschev/miniconda3/envs/gdf/lib/python3.8/site-packages/ucp/_libs/ucx_api.cpython-38-x86_64-linux-gnu.so(+0x272b9) [0x7fee690b42b9]
13  /datasets/pentschev/miniconda3/envs/gdf/bin/python(+0x12e343) [0x56538c002343]
14  /datasets/pentschev/miniconda3/envs/gdf/bin/python(PyObject_Call+0x24a) [0x56538c00d1fa]
15  /datasets/pentschev/miniconda3/envs/gdf/bin/python(_PyEval_EvalFrameDefault+0x680b) [0x56538bff3b8b]
16  /datasets/pentschev/miniconda3/envs/gdf/bin/python(_PyEval_EvalCodeWithName+0x2f1) [0x56538bfec2f1]
17  /datasets/pentschev/miniconda3/envs/gdf/bin/python(_PyFunction_Vectorcall+0x19c) [0x56538bffd93c]
18  /datasets/pentschev/miniconda3/envs/gdf/bin/python(_PyEval_EvalFrameDefault+0x6d5) [0x56538bfeda55]
19  /datasets/pentschev/miniconda3/envs/gdf/bin/python(_PyFunction_Vectorcall+0x106) [0x56538bffd8a6]
20  /datasets/pentschev/miniconda3/envs/gdf/bin/python(+0x136c36) [0x56538c00ac36]
21  /datasets/pentschev/miniconda3/envs/gdf/bin/python(+0x23565a) [0x56538c10965a]
22  /datasets/pentschev/miniconda3/envs/gdf/bin/python(+0xe0b07) [0x56538bfb4b07]
23  /datasets/pentschev/miniconda3/envs/gdf/bin/python(+0x120f96) [0x56538bff4f96]
24  /datasets/pentschev/miniconda3/envs/gdf/bin/python(PyVectorcall_Call+0x7a) [0x56538c00b1ea]
25  /datasets/pentschev/miniconda3/envs/gdf/bin/python(_PyEval_EvalFrameDefault+0x5df8) [0x56538bff3178]
26  /datasets/pentschev/miniconda3/envs/gdf/bin/python(_PyFunction_Vectorcall+0x106) [0x56538bffd8a6]
27  /datasets/pentschev/miniconda3/envs/gdf/bin/python(_PyEval_EvalFrameDefault+0x6d5) [0x56538bfeda55]
28  /datasets/pentschev/miniconda3/envs/gdf/bin/python(_PyFunction_Vectorcall+0x106) [0x56538bffd8a6]
29  /datasets/pentschev/miniconda3/envs/gdf/bin/python(_PyEval_EvalFrameDefault+0x6d5) [0x56538bfeda55]
30  /datasets/pentschev/miniconda3/envs/gdf/bin/python(_PyFunction_Vectorcall+0x106) [0x56538bffd8a6]
31  /datasets/pentschev/miniconda3/envs/gdf/bin/python(_PyEval_EvalFrameDefault+0x6d5) [0x56538bfeda55]
32  /datasets/pentschev/miniconda3/envs/gdf/bin/python(_PyFunction_Vectorcall+0x106) [0x56538bffd8a6]
33  /datasets/pentschev/miniconda3/envs/gdf/bin/python(_PyEval_EvalFrameDefault+0x6d5) [0x56538bfeda55]
34  /datasets/pentschev/miniconda3/envs/gdf/bin/python(_PyEval_EvalCodeWithName+0x2f1) [0x56538bfec2f1]
35  /datasets/pentschev/miniconda3/envs/gdf/bin/python(_PyFunction_Vectorcall+0x19c) [0x56538bffd93c]
36  /datasets/pentschev/miniconda3/envs/gdf/bin/python(_PyEval_EvalFrameDefault+0x4b7b) [0x56538bff1efb]
37  /datasets/pentschev/miniconda3/envs/gdf/bin/python(_PyEval_EvalCodeWithName+0x2f1) [0x56538bfec2f1]
38  /datasets/pentschev/miniconda3/envs/gdf/bin/python(_PyFunction_Vectorcall+0x19c) [0x56538bffd93c]
39  /datasets/pentschev/miniconda3/envs/gdf/bin/python(+0x136e8c) [0x56538c00ae8c]
40  /datasets/pentschev/miniconda3/envs/gdf/bin/python(_PyObject_FastCallDict+0x282) [0x56538bff5a92]
41  /datasets/pentschev/miniconda3/envs/gdf/bin/python(+0x1ee049) [0x56538c0c2049]
42  /datasets/pentschev/miniconda3/envs/gdf/bin/python(PyObject_Call+0x2d3) [0x56538c00d283]
43  /datasets/pentschev/miniconda3/envs/gdf/bin/python(_PyEval_EvalFrameDefault+0x205e) [0x56538bfef3de]
44  /datasets/pentschev/miniconda3/envs/gdf/bin/python(_PyFunction_Vectorcall+0x106) [0x56538bffd8a6]
45  /datasets/pentschev/miniconda3/envs/gdf/bin/python(+0x136e8c) [0x56538c00ae8c]
46  /datasets/pentschev/miniconda3/envs/gdf/bin/python(PyObject_Call+0x24a) [0x56538c00d1fa]
47  /datasets/pentschev/miniconda3/envs/gdf/bin/python(_PyEval_EvalFrameDefault+0x205e) [0x56538bfef3de]
48  /datasets/pentschev/miniconda3/envs/gdf/bin/python(_PyFunction_Vectorcall+0x106) [0x56538bffd8a6]
49  /datasets/pentschev/miniconda3/envs/gdf/bin/python(_PyEval_EvalFrameDefault+0x6d5) [0x56538bfeda55]
50  /datasets/pentschev/miniconda3/envs/gdf/bin/python(_PyEval_EvalCodeWithName+0x2f1) [0x56538bfec2f1]
51  /datasets/pentschev/miniconda3/envs/gdf/bin/python(_PyFunction_Vectorcall+0x19c) [0x56538bffd93c]
52  /datasets/pentschev/miniconda3/envs/gdf/bin/python(_PyEval_EvalFrameDefault+0x6d5) [0x56538bfeda55]
53  /datasets/pentschev/miniconda3/envs/gdf/bin/python(_PyFunction_Vectorcall+0x106) [0x56538bffd8a6]
54  /datasets/pentschev/miniconda3/envs/gdf/bin/python(_PyEval_EvalFrameDefault+0x3a9) [0x56538bfed729]
55  /datasets/pentschev/miniconda3/envs/gdf/bin/python(_PyEval_EvalCodeWithName+0x2f1) [0x56538bfec2f1]
56  /datasets/pentschev/miniconda3/envs/gdf/bin/python(_PyFunction_Vectorcall+0x19c) [0x56538bffd93c]
57  /datasets/pentschev/miniconda3/envs/gdf/bin/python(_PyEval_EvalFrameDefault+0x11bf) [0x56538bfee53f]
58  /datasets/pentschev/miniconda3/envs/gdf/bin/python(_PyEval_EvalCodeWithName+0x2f1) [0x56538bfec2f1]
59  /datasets/pentschev/miniconda3/envs/gdf/bin/python(PyEval_EvalCodeEx+0x39) [0x56538c09ee99]
60  /datasets/pentschev/miniconda3/envs/gdf/bin/python(PyEval_EvalCode+0x1b) [0x56538c09ee5b]
61  /datasets/pentschev/miniconda3/envs/gdf/bin/python(+0x1eb7f9) [0x56538c0bf7f9]
=================================
2023-03-25 01:12:21,949 - distributed.worker - ERROR - Worker stream died during communication: ucx://127.0.0.1:42639
Traceback (most recent call last):
  File "/datasets/pentschev/miniconda3/envs/gdf/lib/python3.8/site-packages/distributed/comm/ucx.py", line 391, in read
    await self.ep.recv(each_frame)
  File "/datasets/pentschev/miniconda3/envs/gdf/lib/python3.8/site-packages/ucp/core.py", line 725, in recv
    ret = await comm.tag_recv(self._ep, buffer, nbytes, tag, name=log)
ucp._libs.exceptions.UCXCanceled: <[Recv #008] ep: 0x7fc5e80511c0, tag: 0xb75e6f8792852465, nbytes: 100000000, type: <class 'rmm._lib.device_buffer.DeviceBuffer'>>: 

During handling of the above exception, another exception occurred:

Traceback (most recent call last):
  File "/datasets/pentschev/miniconda3/envs/gdf/lib/python3.8/site-packages/distributed/worker.py", line 2066, in gather_dep
    response = await get_data_from_worker(
  File "/datasets/pentschev/miniconda3/envs/gdf/lib/python3.8/site-packages/distributed/worker.py", line 2892, in get_data_from_worker
    response = await send_recv(
  File "/datasets/pentschev/miniconda3/envs/gdf/lib/python3.8/site-packages/distributed/core.py", line 1024, in send_recv
    response = await comm.read(deserializers=deserializers)
  File "/datasets/pentschev/miniconda3/envs/gdf/lib/python3.8/site-packages/distributed/utils.py", line 752, in wrapper
    return await func(*args, **kwargs)
  File "/datasets/pentschev/miniconda3/envs/gdf/lib/python3.8/site-packages/distributed/comm/ucx.py", line 397, in read
    raise CommClosedError(
distributed.comm.core.CommClosedError: Connection closed by writer.
Inner exception: UCXCanceled("<[Recv #008] ep: 0x7fc5e80511c0, tag: 0xb75e6f8792852465, nbytes: 100000000, type: <class 'rmm._lib.device_buffer.DeviceBuffer'>>: ")
2023-03-25 01:12:21,949 - distributed.worker - ERROR - failed during get data with ucx://127.0.0.1:40043 -> ucx://127.0.0.1:42639
Traceback (most recent call last):
  File "/datasets/pentschev/miniconda3/envs/gdf/lib/python3.8/site-packages/distributed/comm/ucx.py", line 333, in write
    await self.ep.send(each_frame)
  File "/datasets/pentschev/miniconda3/envs/gdf/lib/python3.8/site-packages/ucp/core.py", line 650, in send
    return await comm.tag_send(self._ep, buffer, nbytes, tag, name=log)
ucp._libs.exceptions.UCXError: <[Send #007] ep: 0x7fe6ac19f3c0, tag: 0xa2b9198bf817c6cb, nbytes: 100000000, type: <class 'cudf.core.buffer.buffer.Buffer'>>: Connection reset by remote peer

During handling of the above exception, another exception occurred:

Traceback (most recent call last):
  File "/datasets/pentschev/miniconda3/envs/gdf/lib/python3.8/site-packages/distributed/worker.py", line 1792, in get_data
    compressed = await comm.write(msg, serializers=serializers)
  File "/datasets/pentschev/miniconda3/envs/gdf/lib/python3.8/site-packages/distributed/utils.py", line 752, in wrapper
    return await func(*args, **kwargs)
  File "/datasets/pentschev/miniconda3/envs/gdf/lib/python3.8/site-packages/distributed/comm/ucx.py", line 337, in write
    raise CommClosedError("While writing, the connection was closed")
distributed.comm.core.CommClosedError: While writing, the connection was closed
2023-03-25 01:12:21,950 - distributed.worker - ERROR - Worker stream died during communication: ucx://127.0.0.1:42639
Traceback (most recent call last):
  File "/datasets/pentschev/miniconda3/envs/gdf/lib/python3.8/site-packages/distributed/comm/ucx.py", line 391, in read
    await self.ep.recv(each_frame)
  File "/datasets/pentschev/miniconda3/envs/gdf/lib/python3.8/site-packages/ucp/core.py", line 725, in recv
    ret = await comm.tag_recv(self._ep, buffer, nbytes, tag, name=log)
ucp._libs.exceptions.UCXError: <[Recv #007] ep: 0x7fe6ac19f240, tag: 0x61d7ff48d8982c13, nbytes: 100000000, type: <class 'rmm._lib.device_buffer.DeviceBuffer'>>: Connection reset by remote peer

During handling of the above exception, another exception occurred:

Traceback (most recent call last):
  File "/datasets/pentschev/miniconda3/envs/gdf/lib/python3.8/site-packages/distributed/worker.py", line 2066, in gather_dep
    response = await get_data_from_worker(
  File "/datasets/pentschev/miniconda3/envs/gdf/lib/python3.8/site-packages/distributed/worker.py", line 2892, in get_data_from_worker
    response = await send_recv(
  File "/datasets/pentschev/miniconda3/envs/gdf/lib/python3.8/site-packages/distributed/core.py", line 1024, in send_recv
    response = await comm.read(deserializers=deserializers)
  File "/datasets/pentschev/miniconda3/envs/gdf/lib/python3.8/site-packages/distributed/utils.py", line 752, in wrapper
    return await func(*args, **kwargs)
  File "/datasets/pentschev/miniconda3/envs/gdf/lib/python3.8/site-packages/distributed/comm/ucx.py", line 397, in read
    raise CommClosedError(
distributed.comm.core.CommClosedError: Connection closed by writer.
Inner exception: UCXError("<[Recv #007] ep: 0x7fe6ac19f240, tag: 0x61d7ff48d8982c13, nbytes: 100000000, type: <class 'rmm._lib.device_buffer.DeviceBuffer'>>: Connection reset by remote peer")
2023-03-25 01:12:22,017 - distributed.nanny - WARNING - Restarting worker
2023-03-25 01:12:22,779 - distributed.preloading - INFO - Creating preload: dask_cuda.initialize
2023-03-25 01:12:22,779 - distributed.preloading - INFO - Import preload module: dask_cuda.initialize
terminate called after throwing an instance of 'rmm::out_of_memory'
  what():  std::bad_alloc: out_of_memory: RMM failure at:/datasets/pentschev/miniconda3/envs/gdf/include/rmm/mr/device/pool_memory_resource.hpp:195: Maximum pool size exceeded
terminate called after throwing an instance of 'rmm::out_of_memory'
  what():  std::bad_alloc: out_of_memory: RMM failure at:/datasets/pentschev/miniconda3/envs/gdf/include/rmm/mr/device/pool_memory_resource.hpp:195: Maximum pool size exceeded
2023-03-25 01:12:23,355 - distributed.preloading - INFO - Creating preload: dask_cuda.initialize
2023-03-25 01:12:23,355 - distributed.preloading - INFO - Import preload module: dask_cuda.initialize
2023-03-25 01:12:23,475 - distributed.diskutils - INFO - Found stale lock file and directory '/tmp/dask-worker-space/worker-xd459ty0', purging
2023-03-25 01:12:23,475 - distributed.diskutils - INFO - Found stale lock file and directory '/tmp/dask-worker-space/worker-8m62z5sy', purging
2023-03-25 01:12:23,476 - distributed.preloading - INFO - Creating preload: dask_cuda.initialize
2023-03-25 01:12:23,476 - distributed.preloading - INFO - Import preload module: dask_cuda.initialize
2023-03-25 01:12:23,545 - distributed.nanny - WARNING - Restarting worker
2023-03-25 01:12:23,613 - distributed.preloading - INFO - Creating preload: dask_cuda.initialize
2023-03-25 01:12:23,613 - distributed.preloading - INFO - Import preload module: dask_cuda.initialize
2023-03-25 01:12:23,655 - distributed.preloading - INFO - Creating preload: dask_cuda.initialize
2023-03-25 01:12:23,655 - distributed.preloading - INFO - Import preload module: dask_cuda.initialize
2023-03-25 01:12:23,689 - distributed.nanny - WARNING - Restarting worker
2023-03-25 01:12:24,028 - distributed.preloading - INFO - Creating preload: dask_cuda.initialize
2023-03-25 01:12:24,028 - distributed.preloading - INFO - Import preload module: dask_cuda.initialize
2023-03-25 01:12:25,584 - distributed.preloading - INFO - Creating preload: dask_cuda.initialize
2023-03-25 01:12:25,584 - distributed.preloading - INFO - Import preload module: dask_cuda.initialize
2023-03-25 01:12:25,703 - distributed.preloading - INFO - Creating preload: dask_cuda.initialize
2023-03-25 01:12:25,703 - distributed.preloading - INFO - Import preload module: dask_cuda.initialize
[dgx13:40924:0:40924] Caught signal 11 (Segmentation fault: address not mapped to object at address 0x448)
==== backtrace (tid:  40924) ====
 0  /datasets/pentschev/miniconda3/envs/gdf/lib/libucs.so.0(ucs_handle_error+0x2d4) [0x7fdc242e4714]
 1  /datasets/pentschev/miniconda3/envs/gdf/lib/libucs.so.0(+0x2e8ef) [0x7fdc242e48ef]
 2  /datasets/pentschev/miniconda3/envs/gdf/lib/libucs.so.0(+0x2ec14) [0x7fdc242e4c14]
 3  /lib/x86_64-linux-gnu/libpthread.so.0(+0x12980) [0x7fdc99bfb980]
 4  /datasets/pentschev/miniconda3/envs/gdf/lib/libucp.so.0(ucp_mem_type_unpack+0x14) [0x7fdc2456d8d4]
 5  /datasets/pentschev/miniconda3/envs/gdf/lib/libucp.so.0(ucp_rndv_data_handler+0x508) [0x7fdc245a1608]
 6  /datasets/pentschev/miniconda3/envs/gdf/lib/libuct.so.0(+0x20b6f) [0x7fdc24098b6f]
 7  /datasets/pentschev/miniconda3/envs/gdf/lib/libuct.so.0(+0x21144) [0x7fdc24099144]
 8  /datasets/pentschev/miniconda3/envs/gdf/lib/libuct.so.0(+0x235a8) [0x7fdc2409b5a8]
 9  /datasets/pentschev/miniconda3/envs/gdf/lib/libucs.so.0(ucs_event_set_wait+0xb9) [0x7fdc242eede9]
10  /datasets/pentschev/miniconda3/envs/gdf/lib/libuct.so.0(uct_tcp_iface_progress+0x7b) [0x7fdc2409b64b]
11  /datasets/pentschev/miniconda3/envs/gdf/lib/libucp.so.0(ucp_worker_progress+0x6a) [0x7fdc24569eba]
12  /datasets/pentschev/miniconda3/envs/gdf/lib/python3.8/site-packages/ucp/_libs/ucx_api.cpython-38-x86_64-linux-gnu.so(+0x272b9) [0x7fdc248292b9]
13  /datasets/pentschev/miniconda3/envs/gdf/bin/python(+0x12e343) [0x556dbfd36343]
14  /datasets/pentschev/miniconda3/envs/gdf/bin/python(PyObject_Call+0x24a) [0x556dbfd411fa]
15  /datasets/pentschev/miniconda3/envs/gdf/bin/python(_PyEval_EvalFrameDefault+0x680b) [0x556dbfd27b8b]
16  /datasets/pentschev/miniconda3/envs/gdf/bin/python(_PyEval_EvalCodeWithName+0x2f1) [0x556dbfd202f1]
17  /datasets/pentschev/miniconda3/envs/gdf/bin/python(_PyFunction_Vectorcall+0x19c) [0x556dbfd3193c]
18  /datasets/pentschev/miniconda3/envs/gdf/bin/python(_PyEval_EvalFrameDefault+0x6d5) [0x556dbfd21a55]
19  /datasets/pentschev/miniconda3/envs/gdf/bin/python(+0x13e1e8) [0x556dbfd461e8]
20  /datasets/pentschev/miniconda3/envs/gdf/lib/python3.8/lib-dynload/_asyncio.cpython-38-x86_64-linux-gnu.so(+0x7003) [0x7fdc8c02c003]
21  /datasets/pentschev/miniconda3/envs/gdf/bin/python(_PyObject_MakeTpCall+0x3db) [0x556dbfd2a30b]
22  /datasets/pentschev/miniconda3/envs/gdf/bin/python(+0xe0b07) [0x556dbfce8b07]
23  /datasets/pentschev/miniconda3/envs/gdf/bin/python(+0x120f96) [0x556dbfd28f96]
24  /datasets/pentschev/miniconda3/envs/gdf/bin/python(PyVectorcall_Call+0x7a) [0x556dbfd3f1ea]
25  /datasets/pentschev/miniconda3/envs/gdf/bin/python(_PyEval_EvalFrameDefault+0x5df8) [0x556dbfd27178]
26  /datasets/pentschev/miniconda3/envs/gdf/bin/python(_PyFunction_Vectorcall+0x106) [0x556dbfd318a6]
27  /datasets/pentschev/miniconda3/envs/gdf/bin/python(_PyEval_EvalFrameDefault+0x6d5) [0x556dbfd21a55]
28  /datasets/pentschev/miniconda3/envs/gdf/bin/python(_PyFunction_Vectorcall+0x106) [0x556dbfd318a6]
29  /datasets/pentschev/miniconda3/envs/gdf/bin/python(_PyEval_EvalFrameDefault+0x6d5) [0x556dbfd21a55]
30  /datasets/pentschev/miniconda3/envs/gdf/bin/python(_PyFunction_Vectorcall+0x106) [0x556dbfd318a6]
31  /datasets/pentschev/miniconda3/envs/gdf/bin/python(_PyEval_EvalFrameDefault+0x6d5) [0x556dbfd21a55]
32  /datasets/pentschev/miniconda3/envs/gdf/bin/python(_PyFunction_Vectorcall+0x106) [0x556dbfd318a6]
33  /datasets/pentschev/miniconda3/envs/gdf/bin/python(_PyEval_EvalFrameDefault+0x6d5) [0x556dbfd21a55]
34  /datasets/pentschev/miniconda3/envs/gdf/bin/python(_PyEval_EvalCodeWithName+0x2f1) [0x556dbfd202f1]
35  /datasets/pentschev/miniconda3/envs/gdf/bin/python(_PyFunction_Vectorcall+0x19c) [0x556dbfd3193c]
36  /datasets/pentschev/miniconda3/envs/gdf/bin/python(_PyEval_EvalFrameDefault+0x4b7b) [0x556dbfd25efb]
37  /datasets/pentschev/miniconda3/envs/gdf/bin/python(_PyEval_EvalCodeWithName+0x2f1) [0x556dbfd202f1]
38  /datasets/pentschev/miniconda3/envs/gdf/bin/python(_PyFunction_Vectorcall+0x19c) [0x556dbfd3193c]
39  /datasets/pentschev/miniconda3/envs/gdf/bin/python(+0x136e8c) [0x556dbfd3ee8c]
40  /datasets/pentschev/miniconda3/envs/gdf/bin/python(_PyObject_FastCallDict+0x282) [0x556dbfd29a92]
41  /datasets/pentschev/miniconda3/envs/gdf/bin/python(+0x1ee049) [0x556dbfdf6049]
42  /datasets/pentschev/miniconda3/envs/gdf/bin/python(PyObject_Call+0x2d3) [0x556dbfd41283]
43  /datasets/pentschev/miniconda3/envs/gdf/bin/python(_PyEval_EvalFrameDefault+0x205e) [0x556dbfd233de]
44  /datasets/pentschev/miniconda3/envs/gdf/bin/python(_PyFunction_Vectorcall+0x106) [0x556dbfd318a6]
45  /datasets/pentschev/miniconda3/envs/gdf/bin/python(+0x136e8c) [0x556dbfd3ee8c]
46  /datasets/pentschev/miniconda3/envs/gdf/bin/python(PyObject_Call+0x24a) [0x556dbfd411fa]
47  /datasets/pentschev/miniconda3/envs/gdf/bin/python(_PyEval_EvalFrameDefault+0x205e) [0x556dbfd233de]
48  /datasets/pentschev/miniconda3/envs/gdf/bin/python(_PyFunction_Vectorcall+0x106) [0x556dbfd318a6]
49  /datasets/pentschev/miniconda3/envs/gdf/bin/python(_PyEval_EvalFrameDefault+0x6d5) [0x556dbfd21a55]
50  /datasets/pentschev/miniconda3/envs/gdf/bin/python(_PyEval_EvalCodeWithName+0x2f1) [0x556dbfd202f1]
51  /datasets/pentschev/miniconda3/envs/gdf/bin/python(_PyFunction_Vectorcall+0x19c) [0x556dbfd3193c]
52  /datasets/pentschev/miniconda3/envs/gdf/bin/python(_PyEval_EvalFrameDefault+0x6d5) [0x556dbfd21a55]
53  /datasets/pentschev/miniconda3/envs/gdf/bin/python(_PyFunction_Vectorcall+0x106) [0x556dbfd318a6]
54  /datasets/pentschev/miniconda3/envs/gdf/bin/python(_PyEval_EvalFrameDefault+0x3a9) [0x556dbfd21729]
55  /datasets/pentschev/miniconda3/envs/gdf/bin/python(_PyEval_EvalCodeWithName+0x2f1) [0x556dbfd202f1]
56  /datasets/pentschev/miniconda3/envs/gdf/bin/python(_PyFunction_Vectorcall+0x19c) [0x556dbfd3193c]
57  /datasets/pentschev/miniconda3/envs/gdf/bin/python(_PyEval_EvalFrameDefault+0x11bf) [0x556dbfd2253f]
58  /datasets/pentschev/miniconda3/envs/gdf/bin/python(_PyEval_EvalCodeWithName+0x2f1) [0x556dbfd202f1]
59  /datasets/pentschev/miniconda3/envs/gdf/bin/python(PyEval_EvalCodeEx+0x39) [0x556dbfdd2e99]
60  /datasets/pentschev/miniconda3/envs/gdf/bin/python(PyEval_EvalCode+0x1b) [0x556dbfdd2e5b]
61  /datasets/pentschev/miniconda3/envs/gdf/bin/python(+0x1eb7f9) [0x556dbfdf37f9]
=================================
[dgx13:40777:0:40777] Caught signal 11 (Segmentation fault: address not mapped to object at address 0x448)
==== backtrace (tid:  40777) ====
 0  /datasets/pentschev/miniconda3/envs/gdf/lib/libucs.so.0(ucs_handle_error+0x2d4) [0x7fab90c86714]
 1  /datasets/pentschev/miniconda3/envs/gdf/lib/libucs.so.0(+0x2e8ef) [0x7fab90c868ef]
 2  /datasets/pentschev/miniconda3/envs/gdf/lib/libucs.so.0(+0x2ec14) [0x7fab90c86c14]
 3  /lib/x86_64-linux-gnu/libpthread.so.0(+0x12980) [0x7fac145a7980]
 4  /datasets/pentschev/miniconda3/envs/gdf/lib/libucp.so.0(ucp_mem_type_unpack+0x14) [0x7fab90f0f8d4]
 5  /datasets/pentschev/miniconda3/envs/gdf/lib/libucp.so.0(ucp_rndv_data_handler+0x508) [0x7fab90f43608]
 6  /datasets/pentschev/miniconda3/envs/gdf/lib/libuct.so.0(+0x20b6f) [0x7fab90a3ab6f]
 7  /datasets/pentschev/miniconda3/envs/gdf/lib/libuct.so.0(+0x21144) [0x7fab90a3b144]
 8  /datasets/pentschev/miniconda3/envs/gdf/lib/libuct.so.0(+0x235a8) [0x7fab90a3d5a8]
 9  /datasets/pentschev/miniconda3/envs/gdf/lib/libucs.so.0(ucs_event_set_wait+0xb9) [0x7fab90c90de9]
10  /datasets/pentschev/miniconda3/envs/gdf/lib/libuct.so.0(uct_tcp_iface_progress+0x7b) [0x7fab90a3d64b]
11  /datasets/pentschev/miniconda3/envs/gdf/lib/libucp.so.0(ucp_worker_progress+0x6a) [0x7fab90f0beba]
12  /datasets/pentschev/miniconda3/envs/gdf/lib/python3.8/site-packages/ucp/_libs/ucx_api.cpython-38-x86_64-linux-gnu.so(+0x272b9) [0x7fab911cb2b9]
13  /datasets/pentschev/miniconda3/envs/gdf/bin/python(+0x12e343) [0x55fed2e67343]
14  /datasets/pentschev/miniconda3/envs/gdf/bin/python(PyObject_Call+0x24a) [0x55fed2e721fa]
15  /datasets/pentschev/miniconda3/envs/gdf/bin/python(_PyEval_EvalFrameDefault+0x680b) [0x55fed2e58b8b]
16  /datasets/pentschev/miniconda3/envs/gdf/bin/python(_PyEval_EvalCodeWithName+0x2f1) [0x55fed2e512f1]
17  /datasets/pentschev/miniconda3/envs/gdf/bin/python(_PyFunction_Vectorcall+0x19c) [0x55fed2e6293c]
18  /datasets/pentschev/miniconda3/envs/gdf/bin/python(_PyEval_EvalFrameDefault+0x6d5) [0x55fed2e52a55]
19  /datasets/pentschev/miniconda3/envs/gdf/bin/python(+0x13e1e8) [0x55fed2e771e8]
20  /datasets/pentschev/miniconda3/envs/gdf/lib/python3.8/lib-dynload/_asyncio.cpython-38-x86_64-linux-gnu.so(+0x7003) [0x7fabaeca6003]
21  /datasets/pentschev/miniconda3/envs/gdf/bin/python(_PyObject_MakeTpCall+0x3db) [0x55fed2e5b30b]
22  /datasets/pentschev/miniconda3/envs/gdf/bin/python(+0xe0b07) [0x55fed2e19b07]
23  /datasets/pentschev/miniconda3/envs/gdf/bin/python(+0x120f96) [0x55fed2e59f96]
24  /datasets/pentschev/miniconda3/envs/gdf/bin/python(PyVectorcall_Call+0x7a) [0x55fed2e701ea]
25  /datasets/pentschev/miniconda3/envs/gdf/bin/python(_PyEval_EvalFrameDefault+0x5df8) [0x55fed2e58178]
26  /datasets/pentschev/miniconda3/envs/gdf/bin/python(_PyFunction_Vectorcall+0x106) [0x55fed2e628a6]
27  /datasets/pentschev/miniconda3/envs/gdf/bin/python(_PyEval_EvalFrameDefault+0x6d5) [0x55fed2e52a55]
28  /datasets/pentschev/miniconda3/envs/gdf/bin/python(_PyFunction_Vectorcall+0x106) [0x55fed2e628a6]
29  /datasets/pentschev/miniconda3/envs/gdf/bin/python(_PyEval_EvalFrameDefault+0x6d5) [0x55fed2e52a55]
30  /datasets/pentschev/miniconda3/envs/gdf/bin/python(_PyFunction_Vectorcall+0x106) [0x55fed2e628a6]
31  /datasets/pentschev/miniconda3/envs/gdf/bin/python(_PyEval_EvalFrameDefault+0x6d5) [0x55fed2e52a55]
32  /datasets/pentschev/miniconda3/envs/gdf/bin/python(_PyFunction_Vectorcall+0x106) [0x55fed2e628a6]
33  /datasets/pentschev/miniconda3/envs/gdf/bin/python(_PyEval_EvalFrameDefault+0x6d5) [0x55fed2e52a55]
34  /datasets/pentschev/miniconda3/envs/gdf/bin/python(_PyEval_EvalCodeWithName+0x2f1) [0x55fed2e512f1]
35  /datasets/pentschev/miniconda3/envs/gdf/bin/python(_PyFunction_Vectorcall+0x19c) [0x55fed2e6293c]
36  /datasets/pentschev/miniconda3/envs/gdf/bin/python(_PyEval_EvalFrameDefault+0x4b7b) [0x55fed2e56efb]
37  /datasets/pentschev/miniconda3/envs/gdf/bin/python(_PyEval_EvalCodeWithName+0x2f1) [0x55fed2e512f1]
38  /datasets/pentschev/miniconda3/envs/gdf/bin/python(_PyFunction_Vectorcall+0x19c) [0x55fed2e6293c]
39  /datasets/pentschev/miniconda3/envs/gdf/bin/python(+0x136e8c) [0x55fed2e6fe8c]
40  /datasets/pentschev/miniconda3/envs/gdf/bin/python(_PyObject_FastCallDict+0x282) [0x55fed2e5aa92]
41  /datasets/pentschev/miniconda3/envs/gdf/bin/python(+0x1ee049) [0x55fed2f27049]
42  /datasets/pentschev/miniconda3/envs/gdf/bin/python(PyObject_Call+0x2d3) [0x55fed2e72283]
43  /datasets/pentschev/miniconda3/envs/gdf/bin/python(_PyEval_EvalFrameDefault+0x205e) [0x55fed2e543de]
44  /datasets/pentschev/miniconda3/envs/gdf/bin/python(_PyFunction_Vectorcall+0x106) [0x55fed2e628a6]
45  /datasets/pentschev/miniconda3/envs/gdf/bin/python(+0x136e8c) [0x55fed2e6fe8c]
46  /datasets/pentschev/miniconda3/envs/gdf/bin/python(PyObject_Call+0x24a) [0x55fed2e721fa]
47  /datasets/pentschev/miniconda3/envs/gdf/bin/python(_PyEval_EvalFrameDefault+0x205e) [0x55fed2e543de]
48  /datasets/pentschev/miniconda3/envs/gdf/bin/python(_PyFunction_Vectorcall+0x106) [0x55fed2e628a6]
49  /datasets/pentschev/miniconda3/envs/gdf/bin/python(_PyEval_EvalFrameDefault+0x6d5) [0x55fed2e52a55]
50  /datasets/pentschev/miniconda3/envs/gdf/bin/python(_PyEval_EvalCodeWithName+0x2f1) [0x55fed2e512f1]
51  /datasets/pentschev/miniconda3/envs/gdf/bin/python(_PyFunction_Vectorcall+0x19c) [0x55fed2e6293c]
52  /datasets/pentschev/miniconda3/envs/gdf/bin/python(_PyEval_EvalFrameDefault+0x6d5) [0x55fed2e52a55]
53  /datasets/pentschev/miniconda3/envs/gdf/bin/python(_PyFunction_Vectorcall+0x106) [0x55fed2e628a6]
54  /datasets/pentschev/miniconda3/envs/gdf/bin/python(_PyEval_EvalFrameDefault+0x3a9) [0x55fed2e52729]
55  /datasets/pentschev/miniconda3/envs/gdf/bin/python(_PyEval_EvalCodeWithName+0x2f1) [0x55fed2e512f1]
56  /datasets/pentschev/miniconda3/envs/gdf/bin/python(_PyFunction_Vectorcall+0x19c) [0x55fed2e6293c]
57  /datasets/pentschev/miniconda3/envs/gdf/bin/python(_PyEval_EvalFrameDefault+0x11bf) [0x55fed2e5353f]
58  /datasets/pentschev/miniconda3/envs/gdf/bin/python(_PyEval_EvalCodeWithName+0x2f1) [0x55fed2e512f1]
59  /datasets/pentschev/miniconda3/envs/gdf/bin/python(PyEval_EvalCodeEx+0x39) [0x55fed2f03e99]
60  /datasets/pentschev/miniconda3/envs/gdf/bin/python(PyEval_EvalCode+0x1b) [0x55fed2f03e5b]
61  /datasets/pentschev/miniconda3/envs/gdf/bin/python(+0x1eb7f9) [0x55fed2f247f9]
=================================
[dgx13:40795:0:40795] Caught signal 11 (Segmentation fault: address not mapped to object at address 0x448)
==== backtrace (tid:  40795) ====
 0  /datasets/pentschev/miniconda3/envs/gdf/lib/libucs.so.0(ucs_handle_error+0x2d4) [0x7f8fc0a4b714]
 1  /datasets/pentschev/miniconda3/envs/gdf/lib/libucs.so.0(+0x2e8ef) [0x7f8fc0a4b8ef]
 2  /datasets/pentschev/miniconda3/envs/gdf/lib/libucs.so.0(+0x2ec14) [0x7f8fc0a4bc14]
 3  /lib/x86_64-linux-gnu/libpthread.so.0(+0x12980) [0x7f9036367980]
 4  /datasets/pentschev/miniconda3/envs/gdf/lib/libucp.so.0(ucp_mem_type_unpack+0x14) [0x7f8fc0cd48d4]
 5  /datasets/pentschev/miniconda3/envs/gdf/lib/libucp.so.0(ucp_rndv_data_handler+0x508) [0x7f8fc0d08608]
 6  /datasets/pentschev/miniconda3/envs/gdf/lib/libuct.so.0(+0x20b6f) [0x7f8fc07ffb6f]
 7  /datasets/pentschev/miniconda3/envs/gdf/lib/libuct.so.0(+0x21144) [0x7f8fc0800144]
 8  /datasets/pentschev/miniconda3/envs/gdf/lib/libuct.so.0(+0x235a8) [0x7f8fc08025a8]
 9  /datasets/pentschev/miniconda3/envs/gdf/lib/libucs.so.0(ucs_event_set_wait+0xb9) [0x7f8fc0a55de9]
10  /datasets/pentschev/miniconda3/envs/gdf/lib/libuct.so.0(uct_tcp_iface_progress+0x7b) [0x7f8fc080264b]
11  /datasets/pentschev/miniconda3/envs/gdf/lib/libucp.so.0(ucp_worker_progress+0x6a) [0x7f8fc0cd0eba]
12  /datasets/pentschev/miniconda3/envs/gdf/lib/python3.8/site-packages/ucp/_libs/ucx_api.cpython-38-x86_64-linux-gnu.so(+0x272b9) [0x7f8fc0f902b9]
13  /datasets/pentschev/miniconda3/envs/gdf/bin/python(+0x12e343) [0x55e170116343]
14  /datasets/pentschev/miniconda3/envs/gdf/bin/python(PyObject_Call+0x24a) [0x55e1701211fa]
15  /datasets/pentschev/miniconda3/envs/gdf/bin/python(_PyEval_EvalFrameDefault+0x680b) [0x55e170107b8b]
16  /datasets/pentschev/miniconda3/envs/gdf/bin/python(_PyEval_EvalCodeWithName+0x2f1) [0x55e1701002f1]
17  /datasets/pentschev/miniconda3/envs/gdf/bin/python(_PyFunction_Vectorcall+0x19c) [0x55e17011193c]
18  /datasets/pentschev/miniconda3/envs/gdf/bin/python(_PyEval_EvalFrameDefault+0x6d5) [0x55e170101a55]
19  /datasets/pentschev/miniconda3/envs/gdf/bin/python(+0x13e1e8) [0x55e1701261e8]
20  /datasets/pentschev/miniconda3/envs/gdf/lib/python3.8/lib-dynload/_asyncio.cpython-38-x86_64-linux-gnu.so(+0x7003) [0x7f9028794003]
21  /datasets/pentschev/miniconda3/envs/gdf/bin/python(_PyObject_MakeTpCall+0x3db) [0x55e17010a30b]
22  /datasets/pentschev/miniconda3/envs/gdf/bin/python(+0xe0b07) [0x55e1700c8b07]
23  /datasets/pentschev/miniconda3/envs/gdf/bin/python(+0x120f96) [0x55e170108f96]
24  /datasets/pentschev/miniconda3/envs/gdf/bin/python(PyVectorcall_Call+0x7a) [0x55e17011f1ea]
25  /datasets/pentschev/miniconda3/envs/gdf/bin/python(_PyEval_EvalFrameDefault+0x5df8) [0x55e170107178]
26  /datasets/pentschev/miniconda3/envs/gdf/bin/python(_PyFunction_Vectorcall+0x106) [0x55e1701118a6]
27  /datasets/pentschev/miniconda3/envs/gdf/bin/python(_PyEval_EvalFrameDefault+0x6d5) [0x55e170101a55]
28  /datasets/pentschev/miniconda3/envs/gdf/bin/python(_PyFunction_Vectorcall+0x106) [0x55e1701118a6]
29  /datasets/pentschev/miniconda3/envs/gdf/bin/python(_PyEval_EvalFrameDefault+0x6d5) [0x55e170101a55]
30  /datasets/pentschev/miniconda3/envs/gdf/bin/python(_PyFunction_Vectorcall+0x106) [0x55e1701118a6]
31  /datasets/pentschev/miniconda3/envs/gdf/bin/python(_PyEval_EvalFrameDefault+0x6d5) [0x55e170101a55]
32  /datasets/pentschev/miniconda3/envs/gdf/bin/python(_PyFunction_Vectorcall+0x106) [0x55e1701118a6]
33  /datasets/pentschev/miniconda3/envs/gdf/bin/python(_PyEval_EvalFrameDefault+0x6d5) [0x55e170101a55]
34  /datasets/pentschev/miniconda3/envs/gdf/bin/python(_PyEval_EvalCodeWithName+0x2f1) [0x55e1701002f1]
35  /datasets/pentschev/miniconda3/envs/gdf/bin/python(_PyFunction_Vectorcall+0x19c) [0x55e17011193c]
36  /datasets/pentschev/miniconda3/envs/gdf/bin/python(_PyEval_EvalFrameDefault+0x4b7b) [0x55e170105efb]
37  /datasets/pentschev/miniconda3/envs/gdf/bin/python(_PyEval_EvalCodeWithName+0x2f1) [0x55e1701002f1]
38  /datasets/pentschev/miniconda3/envs/gdf/bin/python(_PyFunction_Vectorcall+0x19c) [0x55e17011193c]
39  /datasets/pentschev/miniconda3/envs/gdf/bin/python(+0x136e8c) [0x55e17011ee8c]
40  /datasets/pentschev/miniconda3/envs/gdf/bin/python(_PyObject_FastCallDict+0x282) [0x55e170109a92]
41  /datasets/pentschev/miniconda3/envs/gdf/bin/python(+0x1ee049) [0x55e1701d6049]
42  /datasets/pentschev/miniconda3/envs/gdf/bin/python(PyObject_Call+0x2d3) [0x55e170121283]
43  /datasets/pentschev/miniconda3/envs/gdf/bin/python(_PyEval_EvalFrameDefault+0x205e) [0x55e1701033de]
44  /datasets/pentschev/miniconda3/envs/gdf/bin/python(_PyFunction_Vectorcall+0x106) [0x55e1701118a6]
45  /datasets/pentschev/miniconda3/envs/gdf/bin/python(+0x136e8c) [0x55e17011ee8c]
46  /datasets/pentschev/miniconda3/envs/gdf/bin/python(PyObject_Call+0x24a) [0x55e1701211fa]
47  /datasets/pentschev/miniconda3/envs/gdf/bin/python(_PyEval_EvalFrameDefault+0x205e) [0x55e1701033de]
48  /datasets/pentschev/miniconda3/envs/gdf/bin/python(_PyFunction_Vectorcall+0x106) [0x55e1701118a6]
49  /datasets/pentschev/miniconda3/envs/gdf/bin/python(_PyEval_EvalFrameDefault+0x6d5) [0x55e170101a55]
50  /datasets/pentschev/miniconda3/envs/gdf/bin/python(_PyEval_EvalCodeWithName+0x2f1) [0x55e1701002f1]
51  /datasets/pentschev/miniconda3/envs/gdf/bin/python(_PyFunction_Vectorcall+0x19c) [0x55e17011193c]
52  /datasets/pentschev/miniconda3/envs/gdf/bin/python(_PyEval_EvalFrameDefault+0x6d5) [0x55e170101a55]
53  /datasets/pentschev/miniconda3/envs/gdf/bin/python(_PyFunction_Vectorcall+0x106) [0x55e1701118a6]
54  /datasets/pentschev/miniconda3/envs/gdf/bin/python(_PyEval_EvalFrameDefault+0x3a9) [0x55e170101729]
55  /datasets/pentschev/miniconda3/envs/gdf/bin/python(_PyEval_EvalCodeWithName+0x2f1) [0x55e1701002f1]
56  /datasets/pentschev/miniconda3/envs/gdf/bin/python(_PyFunction_Vectorcall+0x19c) [0x55e17011193c]
57  /datasets/pentschev/miniconda3/envs/gdf/bin/python(_PyEval_EvalFrameDefault+0x11bf) [0x55e17010253f]
58  /datasets/pentschev/miniconda3/envs/gdf/bin/python(_PyEval_EvalCodeWithName+0x2f1) [0x55e1701002f1]
59  /datasets/pentschev/miniconda3/envs/gdf/bin/python(PyEval_EvalCodeEx+0x39) [0x55e1701b2e99]
60  /datasets/pentschev/miniconda3/envs/gdf/bin/python(PyEval_EvalCode+0x1b) [0x55e1701b2e5b]
61  /datasets/pentschev/miniconda3/envs/gdf/bin/python(+0x1eb7f9) [0x55e1701d37f9]
=================================
2023-03-25 01:12:30,485 - distributed.worker - ERROR - Worker stream died during communication: ucx://127.0.0.1:48575
Traceback (most recent call last):
  File "/datasets/pentschev/miniconda3/envs/gdf/lib/python3.8/site-packages/distributed/comm/ucx.py", line 391, in read
    await self.ep.recv(each_frame)
  File "/datasets/pentschev/miniconda3/envs/gdf/lib/python3.8/site-packages/ucp/core.py", line 725, in recv
    ret = await comm.tag_recv(self._ep, buffer, nbytes, tag, name=log)
ucp._libs.exceptions.UCXCanceled: <[Recv #008] ep: 0x7efb9c0b5100, tag: 0xf693021f57f5df8c, nbytes: 100000000, type: <class 'rmm._lib.device_buffer.DeviceBuffer'>>: 

During handling of the above exception, another exception occurred:

Traceback (most recent call last):
  File "/datasets/pentschev/miniconda3/envs/gdf/lib/python3.8/site-packages/distributed/worker.py", line 2066, in gather_dep
    response = await get_data_from_worker(
  File "/datasets/pentschev/miniconda3/envs/gdf/lib/python3.8/site-packages/distributed/worker.py", line 2892, in get_data_from_worker
    response = await send_recv(
  File "/datasets/pentschev/miniconda3/envs/gdf/lib/python3.8/site-packages/distributed/core.py", line 1024, in send_recv
    response = await comm.read(deserializers=deserializers)
  File "/datasets/pentschev/miniconda3/envs/gdf/lib/python3.8/site-packages/distributed/utils.py", line 752, in wrapper
    return await func(*args, **kwargs)
  File "/datasets/pentschev/miniconda3/envs/gdf/lib/python3.8/site-packages/distributed/comm/ucx.py", line 397, in read
    raise CommClosedError(
distributed.comm.core.CommClosedError: Connection closed by writer.
Inner exception: UCXCanceled("<[Recv #008] ep: 0x7efb9c0b5100, tag: 0xf693021f57f5df8c, nbytes: 100000000, type: <class 'rmm._lib.device_buffer.DeviceBuffer'>>: ")
2023-03-25 01:12:30,485 - distributed.worker - ERROR - Worker stream died during communication: ucx://127.0.0.1:48575
Traceback (most recent call last):
  File "/datasets/pentschev/miniconda3/envs/gdf/lib/python3.8/site-packages/distributed/comm/ucx.py", line 391, in read
    await self.ep.recv(each_frame)
  File "/datasets/pentschev/miniconda3/envs/gdf/lib/python3.8/site-packages/ucp/core.py", line 725, in recv
    ret = await comm.tag_recv(self._ep, buffer, nbytes, tag, name=log)
ucp._libs.exceptions.UCXError: <[Recv #007] ep: 0x7f08a098c100, tag: 0x1e0d4320e7db54a1, nbytes: 100000000, type: <class 'rmm._lib.device_buffer.DeviceBuffer'>>: Connection reset by remote peer

During handling of the above exception, another exception occurred:

Traceback (most recent call last):
  File "/datasets/pentschev/miniconda3/envs/gdf/lib/python3.8/site-packages/distributed/worker.py", line 2066, in gather_dep
    response = await get_data_from_worker(
  File "/datasets/pentschev/miniconda3/envs/gdf/lib/python3.8/site-packages/distributed/worker.py", line 2892, in get_data_from_worker
    response = await send_recv(
  File "/datasets/pentschev/miniconda3/envs/gdf/lib/python3.8/site-packages/distributed/core.py", line 1024, in send_recv
    response = await comm.read(deserializers=deserializers)
  File "/datasets/pentschev/miniconda3/envs/gdf/lib/python3.8/site-packages/distributed/utils.py", line 752, in wrapper
    return await func(*args, **kwargs)
  File "/datasets/pentschev/miniconda3/envs/gdf/lib/python3.8/site-packages/distributed/comm/ucx.py", line 397, in read
    raise CommClosedError(
distributed.comm.core.CommClosedError: Connection closed by writer.
Inner exception: UCXError("<[Recv #007] ep: 0x7f08a098c100, tag: 0x1e0d4320e7db54a1, nbytes: 100000000, type: <class 'rmm._lib.device_buffer.DeviceBuffer'>>: Connection reset by remote peer")
2023-03-25 01:12:30,498 - distributed.worker - ERROR - Worker stream died during communication: ucx://127.0.0.1:41373
Traceback (most recent call last):
  File "/datasets/pentschev/miniconda3/envs/gdf/lib/python3.8/site-packages/distributed/comm/ucx.py", line 391, in read
    await self.ep.recv(each_frame)
  File "/datasets/pentschev/miniconda3/envs/gdf/lib/python3.8/site-packages/ucp/core.py", line 725, in recv
    ret = await comm.tag_recv(self._ep, buffer, nbytes, tag, name=log)
ucp._libs.exceptions.UCXCanceled: <[Recv #009] ep: 0x7f08a098c140, tag: 0xdd4d5e0fa325ed23, nbytes: 100000000, type: <class 'rmm._lib.device_buffer.DeviceBuffer'>>: 

During handling of the above exception, another exception occurred:

Traceback (most recent call last):
  File "/datasets/pentschev/miniconda3/envs/gdf/lib/python3.8/site-packages/distributed/worker.py", line 2066, in gather_dep
    response = await get_data_from_worker(
  File "/datasets/pentschev/miniconda3/envs/gdf/lib/python3.8/site-packages/distributed/worker.py", line 2892, in get_data_from_worker
    response = await send_recv(
  File "/datasets/pentschev/miniconda3/envs/gdf/lib/python3.8/site-packages/distributed/core.py", line 1024, in send_recv
    response = await comm.read(deserializers=deserializers)
  File "/datasets/pentschev/miniconda3/envs/gdf/lib/python3.8/site-packages/distributed/utils.py", line 752, in wrapper
    return await func(*args, **kwargs)
  File "/datasets/pentschev/miniconda3/envs/gdf/lib/python3.8/site-packages/distributed/comm/ucx.py", line 397, in read
    raise CommClosedError(
distributed.comm.core.CommClosedError: Connection closed by writer.
Inner exception: UCXCanceled("<[Recv #009] ep: 0x7f08a098c140, tag: 0xdd4d5e0fa325ed23, nbytes: 100000000, type: <class 'rmm._lib.device_buffer.DeviceBuffer'>>: ")
2023-03-25 01:12:30,498 - distributed.worker - ERROR - failed during get data with ucx://127.0.0.1:40327 -> ucx://127.0.0.1:41373
Traceback (most recent call last):
  File "/datasets/pentschev/miniconda3/envs/gdf/lib/python3.8/site-packages/distributed/comm/ucx.py", line 333, in write
    await self.ep.send(each_frame)
  File "/datasets/pentschev/miniconda3/envs/gdf/lib/python3.8/site-packages/ucp/core.py", line 650, in send
    return await comm.tag_send(self._ep, buffer, nbytes, tag, name=log)
ucp._libs.exceptions.UCXError: <[Send #007] ep: 0x7efb9c0b5200, tag: 0xbc88f9c1f46053db, nbytes: 100000000, type: <class 'cudf.core.buffer.buffer.Buffer'>>: Connection reset by remote peer

During handling of the above exception, another exception occurred:

Traceback (most recent call last):
  File "/datasets/pentschev/miniconda3/envs/gdf/lib/python3.8/site-packages/distributed/worker.py", line 1792, in get_data
    compressed = await comm.write(msg, serializers=serializers)
  File "/datasets/pentschev/miniconda3/envs/gdf/lib/python3.8/site-packages/distributed/utils.py", line 752, in wrapper
    return await func(*args, **kwargs)
  File "/datasets/pentschev/miniconda3/envs/gdf/lib/python3.8/site-packages/distributed/comm/ucx.py", line 337, in write
    raise CommClosedError("While writing, the connection was closed")
distributed.comm.core.CommClosedError: While writing, the connection was closed
2023-03-25 01:12:30,498 - distributed.worker - ERROR - Worker stream died during communication: ucx://127.0.0.1:41373
Traceback (most recent call last):
  File "/datasets/pentschev/miniconda3/envs/gdf/lib/python3.8/site-packages/distributed/comm/ucx.py", line 391, in read
    await self.ep.recv(each_frame)
  File "/datasets/pentschev/miniconda3/envs/gdf/lib/python3.8/site-packages/ucp/core.py", line 725, in recv
    ret = await comm.tag_recv(self._ep, buffer, nbytes, tag, name=log)
ucp._libs.exceptions.UCXError: <[Recv #007] ep: 0x7efb9c0b5140, tag: 0x65a8c292d05bbb9e, nbytes: 100000000, type: <class 'rmm._lib.device_buffer.DeviceBuffer'>>: Connection reset by remote peer

During handling of the above exception, another exception occurred:

Traceback (most recent call last):
  File "/datasets/pentschev/miniconda3/envs/gdf/lib/python3.8/site-packages/distributed/worker.py", line 2066, in gather_dep
    response = await get_data_from_worker(
  File "/datasets/pentschev/miniconda3/envs/gdf/lib/python3.8/site-packages/distributed/worker.py", line 2892, in get_data_from_worker
    response = await send_recv(
  File "/datasets/pentschev/miniconda3/envs/gdf/lib/python3.8/site-packages/distributed/core.py", line 1024, in send_recv
    response = await comm.read(deserializers=deserializers)
  File "/datasets/pentschev/miniconda3/envs/gdf/lib/python3.8/site-packages/distributed/utils.py", line 752, in wrapper
    return await func(*args, **kwargs)
  File "/datasets/pentschev/miniconda3/envs/gdf/lib/python3.8/site-packages/distributed/comm/ucx.py", line 397, in read
    raise CommClosedError(
distributed.comm.core.CommClosedError: Connection closed by writer.
Inner exception: UCXError("<[Recv #007] ep: 0x7efb9c0b5140, tag: 0x65a8c292d05bbb9e, nbytes: 100000000, type: <class 'rmm._lib.device_buffer.DeviceBuffer'>>: Connection reset by remote peer")
2023-03-25 01:12:30,606 - distributed.nanny - WARNING - Restarting worker
2023-03-25 01:12:30,750 - distributed.nanny - WARNING - Restarting worker
2023-03-25 01:12:30,816 - distributed.nanny - WARNING - Restarting worker
[dgx13:40816:0:40816] Caught signal 11 (Segmentation fault: address not mapped to object at address 0x448)
==== backtrace (tid:  40816) ====
 0  /datasets/pentschev/miniconda3/envs/gdf/lib/libucs.so.0(ucs_handle_error+0x2d4) [0x7f149d602714]
 1  /datasets/pentschev/miniconda3/envs/gdf/lib/libucs.so.0(+0x2e8ef) [0x7f149d6028ef]
 2  /datasets/pentschev/miniconda3/envs/gdf/lib/libucs.so.0(+0x2ec14) [0x7f149d602c14]
 3  /lib/x86_64-linux-gnu/libpthread.so.0(+0x12980) [0x7f1512fad980]
 4  /datasets/pentschev/miniconda3/envs/gdf/lib/libucp.so.0(ucp_mem_type_unpack+0x14) [0x7f149d88b8d4]
 5  /datasets/pentschev/miniconda3/envs/gdf/lib/libucp.so.0(ucp_rndv_data_handler+0x508) [0x7f149d8bf608]
 6  /datasets/pentschev/miniconda3/envs/gdf/lib/libuct.so.0(+0x20b6f) [0x7f149d3b6b6f]
 7  /datasets/pentschev/miniconda3/envs/gdf/lib/libuct.so.0(+0x21144) [0x7f149d3b7144]
 8  /datasets/pentschev/miniconda3/envs/gdf/lib/libuct.so.0(+0x235a8) [0x7f149d3b95a8]
 9  /datasets/pentschev/miniconda3/envs/gdf/lib/libucs.so.0(ucs_event_set_wait+0xb9) [0x7f149d60cde9]
10  /datasets/pentschev/miniconda3/envs/gdf/lib/libuct.so.0(uct_tcp_iface_progress+0x7b) [0x7f149d3b964b]
11  /datasets/pentschev/miniconda3/envs/gdf/lib/libucp.so.0(ucp_worker_progress+0x6a) [0x7f149d887eba]
12  /datasets/pentschev/miniconda3/envs/gdf/lib/python3.8/site-packages/ucp/_libs/ucx_api.cpython-38-x86_64-linux-gnu.so(+0x272b9) [0x7f149db472b9]
13  /datasets/pentschev/miniconda3/envs/gdf/bin/python(+0x12e343) [0x55b5e1eff343]
14  /datasets/pentschev/miniconda3/envs/gdf/bin/python(PyObject_Call+0x24a) [0x55b5e1f0a1fa]
15  /datasets/pentschev/miniconda3/envs/gdf/bin/python(_PyEval_EvalFrameDefault+0x680b) [0x55b5e1ef0b8b]
16  /datasets/pentschev/miniconda3/envs/gdf/bin/python(_PyEval_EvalCodeWithName+0x2f1) [0x55b5e1ee92f1]
17  /datasets/pentschev/miniconda3/envs/gdf/bin/python(_PyFunction_Vectorcall+0x19c) [0x55b5e1efa93c]
18  /datasets/pentschev/miniconda3/envs/gdf/bin/python(_PyEval_EvalFrameDefault+0x6d5) [0x55b5e1eeaa55]
19  /datasets/pentschev/miniconda3/envs/gdf/bin/python(+0x13e1e8) [0x55b5e1f0f1e8]
20  /datasets/pentschev/miniconda3/envs/gdf/lib/python3.8/lib-dynload/_asyncio.cpython-38-x86_64-linux-gnu.so(+0x7003) [0x7f14ad6b0003]
21  /datasets/pentschev/miniconda3/envs/gdf/bin/python(_PyObject_MakeTpCall+0x3db) [0x55b5e1ef330b]
22  /datasets/pentschev/miniconda3/envs/gdf/bin/python(+0xe0b07) [0x55b5e1eb1b07]
23  /datasets/pentschev/miniconda3/envs/gdf/bin/python(+0x120f96) [0x55b5e1ef1f96]
24  /datasets/pentschev/miniconda3/envs/gdf/bin/python(PyVectorcall_Call+0x7a) [0x55b5e1f081ea]
25  /datasets/pentschev/miniconda3/envs/gdf/bin/python(_PyEval_EvalFrameDefault+0x5df8) [0x55b5e1ef0178]
26  /datasets/pentschev/miniconda3/envs/gdf/bin/python(_PyFunction_Vectorcall+0x106) [0x55b5e1efa8a6]
27  /datasets/pentschev/miniconda3/envs/gdf/bin/python(_PyEval_EvalFrameDefault+0x6d5) [0x55b5e1eeaa55]
28  /datasets/pentschev/miniconda3/envs/gdf/bin/python(_PyFunction_Vectorcall+0x106) [0x55b5e1efa8a6]
29  /datasets/pentschev/miniconda3/envs/gdf/bin/python(_PyEval_EvalFrameDefault+0x6d5) [0x55b5e1eeaa55]
30  /datasets/pentschev/miniconda3/envs/gdf/bin/python(_PyFunction_Vectorcall+0x106) [0x55b5e1efa8a6]
31  /datasets/pentschev/miniconda3/envs/gdf/bin/python(_PyEval_EvalFrameDefault+0x6d5) [0x55b5e1eeaa55]
32  /datasets/pentschev/miniconda3/envs/gdf/bin/python(_PyFunction_Vectorcall+0x106) [0x55b5e1efa8a6]
33  /datasets/pentschev/miniconda3/envs/gdf/bin/python(_PyEval_EvalFrameDefault+0x6d5) [0x55b5e1eeaa55]
34  /datasets/pentschev/miniconda3/envs/gdf/bin/python(_PyEval_EvalCodeWithName+0x2f1) [0x55b5e1ee92f1]
35  /datasets/pentschev/miniconda3/envs/gdf/bin/python(_PyFunction_Vectorcall+0x19c) [0x55b5e1efa93c]
36  /datasets/pentschev/miniconda3/envs/gdf/bin/python(_PyEval_EvalFrameDefault+0x4b7b) [0x55b5e1eeeefb]
37  /datasets/pentschev/miniconda3/envs/gdf/bin/python(_PyEval_EvalCodeWithName+0x2f1) [0x55b5e1ee92f1]
38  /datasets/pentschev/miniconda3/envs/gdf/bin/python(_PyFunction_Vectorcall+0x19c) [0x55b5e1efa93c]
39  /datasets/pentschev/miniconda3/envs/gdf/bin/python(+0x136e8c) [0x55b5e1f07e8c]
40  /datasets/pentschev/miniconda3/envs/gdf/bin/python(_PyObject_FastCallDict+0x282) [0x55b5e1ef2a92]
41  /datasets/pentschev/miniconda3/envs/gdf/bin/python(+0x1ee049) [0x55b5e1fbf049]
42  /datasets/pentschev/miniconda3/envs/gdf/bin/python(PyObject_Call+0x2d3) [0x55b5e1f0a283]
43  /datasets/pentschev/miniconda3/envs/gdf/bin/python(_PyEval_EvalFrameDefault+0x205e) [0x55b5e1eec3de]
44  /datasets/pentschev/miniconda3/envs/gdf/bin/python(_PyFunction_Vectorcall+0x106) [0x55b5e1efa8a6]
45  /datasets/pentschev/miniconda3/envs/gdf/bin/python(+0x136e8c) [0x55b5e1f07e8c]
46  /datasets/pentschev/miniconda3/envs/gdf/bin/python(PyObject_Call+0x24a) [0x55b5e1f0a1fa]
47  /datasets/pentschev/miniconda3/envs/gdf/bin/python(_PyEval_EvalFrameDefault+0x205e) [0x55b5e1eec3de]
48  /datasets/pentschev/miniconda3/envs/gdf/bin/python(_PyFunction_Vectorcall+0x106) [0x55b5e1efa8a6]
49  /datasets/pentschev/miniconda3/envs/gdf/bin/python(_PyEval_EvalFrameDefault+0x6d5) [0x55b5e1eeaa55]
50  /datasets/pentschev/miniconda3/envs/gdf/bin/python(_PyEval_EvalCodeWithName+0x2f1) [0x55b5e1ee92f1]
51  /datasets/pentschev/miniconda3/envs/gdf/bin/python(_PyFunction_Vectorcall+0x19c) [0x55b5e1efa93c]
52  /datasets/pentschev/miniconda3/envs/gdf/bin/python(_PyEval_EvalFrameDefault+0x6d5) [0x55b5e1eeaa55]
53  /datasets/pentschev/miniconda3/envs/gdf/bin/python(_PyFunction_Vectorcall+0x106) [0x55b5e1efa8a6]
54  /datasets/pentschev/miniconda3/envs/gdf/bin/python(_PyEval_EvalFrameDefault+0x3a9) [0x55b5e1eea729]
55  /datasets/pentschev/miniconda3/envs/gdf/bin/python(_PyEval_EvalCodeWithName+0x2f1) [0x55b5e1ee92f1]
56  /datasets/pentschev/miniconda3/envs/gdf/bin/python(_PyFunction_Vectorcall+0x19c) [0x55b5e1efa93c]
57  /datasets/pentschev/miniconda3/envs/gdf/bin/python(_PyEval_EvalFrameDefault+0x11bf) [0x55b5e1eeb53f]
58  /datasets/pentschev/miniconda3/envs/gdf/bin/python(_PyEval_EvalCodeWithName+0x2f1) [0x55b5e1ee92f1]
59  /datasets/pentschev/miniconda3/envs/gdf/bin/python(PyEval_EvalCodeEx+0x39) [0x55b5e1f9be99]
60  /datasets/pentschev/miniconda3/envs/gdf/bin/python(PyEval_EvalCode+0x1b) [0x55b5e1f9be5b]
61  /datasets/pentschev/miniconda3/envs/gdf/bin/python(+0x1eb7f9) [0x55b5e1fbc7f9]
=================================
2023-03-25 01:12:31,917 - distributed.worker - ERROR - Worker stream died during communication: ucx://127.0.0.1:55143
Traceback (most recent call last):
  File "/datasets/pentschev/miniconda3/envs/gdf/lib/python3.8/site-packages/distributed/comm/ucx.py", line 391, in read
    await self.ep.recv(each_frame)
  File "/datasets/pentschev/miniconda3/envs/gdf/lib/python3.8/site-packages/ucp/core.py", line 725, in recv
    ret = await comm.tag_recv(self._ep, buffer, nbytes, tag, name=log)
ucp._libs.exceptions.UCXError: <[Recv #007] ep: 0x7efb9c0b5140, tag: 0xf8d5572a72cf6f53, nbytes: 100000000, type: <class 'rmm._lib.device_buffer.DeviceBuffer'>>: Connection reset by remote peer

During handling of the above exception, another exception occurred:

Traceback (most recent call last):
  File "/datasets/pentschev/miniconda3/envs/gdf/lib/python3.8/site-packages/distributed/worker.py", line 2066, in gather_dep
    response = await get_data_from_worker(
  File "/datasets/pentschev/miniconda3/envs/gdf/lib/python3.8/site-packages/distributed/worker.py", line 2892, in get_data_from_worker
    response = await send_recv(
  File "/datasets/pentschev/miniconda3/envs/gdf/lib/python3.8/site-packages/distributed/core.py", line 1024, in send_recv
    response = await comm.read(deserializers=deserializers)
  File "/datasets/pentschev/miniconda3/envs/gdf/lib/python3.8/site-packages/distributed/utils.py", line 752, in wrapper
    return await func(*args, **kwargs)
  File "/datasets/pentschev/miniconda3/envs/gdf/lib/python3.8/site-packages/distributed/comm/ucx.py", line 397, in read
    raise CommClosedError(
distributed.comm.core.CommClosedError: Connection closed by writer.
Inner exception: UCXError("<[Recv #007] ep: 0x7efb9c0b5140, tag: 0xf8d5572a72cf6f53, nbytes: 100000000, type: <class 'rmm._lib.device_buffer.DeviceBuffer'>>: Connection reset by remote peer")
2023-03-25 01:12:31,917 - distributed.worker - ERROR - failed during get data with ucx://127.0.0.1:48619 -> ucx://127.0.0.1:55143
Traceback (most recent call last):
  File "/datasets/pentschev/miniconda3/envs/gdf/lib/python3.8/site-packages/distributed/comm/ucx.py", line 333, in write
    await self.ep.send(each_frame)
  File "/datasets/pentschev/miniconda3/envs/gdf/lib/python3.8/site-packages/ucp/core.py", line 650, in send
    return await comm.tag_send(self._ep, buffer, nbytes, tag, name=log)
ucp._libs.exceptions.UCXError: <[Send #007] ep: 0x7f08a098c180, tag: 0x74bbd559c2e28994, nbytes: 100000000, type: <class 'cudf.core.buffer.buffer.Buffer'>>: Connection reset by remote peer

During handling of the above exception, another exception occurred:

Traceback (most recent call last):
  File "/datasets/pentschev/miniconda3/envs/gdf/lib/python3.8/site-packages/distributed/worker.py", line 1792, in get_data
    compressed = await comm.write(msg, serializers=serializers)
  File "/datasets/pentschev/miniconda3/envs/gdf/lib/python3.8/site-packages/distributed/utils.py", line 752, in wrapper
    return await func(*args, **kwargs)
  File "/datasets/pentschev/miniconda3/envs/gdf/lib/python3.8/site-packages/distributed/comm/ucx.py", line 337, in write
    raise CommClosedError("While writing, the connection was closed")
distributed.comm.core.CommClosedError: While writing, the connection was closed
2023-03-25 01:12:31,918 - distributed.worker - ERROR - Worker stream died during communication: ucx://127.0.0.1:55143
Traceback (most recent call last):
  File "/datasets/pentschev/miniconda3/envs/gdf/lib/python3.8/site-packages/distributed/comm/ucx.py", line 391, in read
    await self.ep.recv(each_frame)
  File "/datasets/pentschev/miniconda3/envs/gdf/lib/python3.8/site-packages/ucp/core.py", line 725, in recv
    ret = await comm.tag_recv(self._ep, buffer, nbytes, tag, name=log)
ucp._libs.exceptions.UCXError: <[Recv #007] ep: 0x7f08a098c100, tag: 0x9a2ec5a248abd282, nbytes: 100000000, type: <class 'rmm._lib.device_buffer.DeviceBuffer'>>: Connection reset by remote peer

During handling of the above exception, another exception occurred:

Traceback (most recent call last):
  File "/datasets/pentschev/miniconda3/envs/gdf/lib/python3.8/site-packages/distributed/worker.py", line 2066, in gather_dep
    response = await get_data_from_worker(
  File "/datasets/pentschev/miniconda3/envs/gdf/lib/python3.8/site-packages/distributed/worker.py", line 2892, in get_data_from_worker
    response = await send_recv(
  File "/datasets/pentschev/miniconda3/envs/gdf/lib/python3.8/site-packages/distributed/core.py", line 1024, in send_recv
    response = await comm.read(deserializers=deserializers)
  File "/datasets/pentschev/miniconda3/envs/gdf/lib/python3.8/site-packages/distributed/utils.py", line 752, in wrapper
    return await func(*args, **kwargs)
  File "/datasets/pentschev/miniconda3/envs/gdf/lib/python3.8/site-packages/distributed/comm/ucx.py", line 397, in read
    raise CommClosedError(
distributed.comm.core.CommClosedError: Connection closed by writer.
Inner exception: UCXError("<[Recv #007] ep: 0x7f08a098c100, tag: 0x9a2ec5a248abd282, nbytes: 100000000, type: <class 'rmm._lib.device_buffer.DeviceBuffer'>>: Connection reset by remote peer")
2023-03-25 01:12:31,917 - distributed.worker - ERROR - Worker stream died during communication: ucx://127.0.0.1:55143
Traceback (most recent call last):
  File "/datasets/pentschev/miniconda3/envs/gdf/lib/python3.8/site-packages/distributed/comm/ucx.py", line 349, in read
    await self.ep.recv(msg)
  File "/datasets/pentschev/miniconda3/envs/gdf/lib/python3.8/site-packages/ucp/core.py", line 725, in recv
    ret = await comm.tag_recv(self._ep, buffer, nbytes, tag, name=log)
ucp._libs.exceptions.UCXCanceled: <[Recv #003] ep: 0x7f829c18f140, tag: 0xe0657c464a7ff921, nbytes: 16, type: <class 'numpy.ndarray'>>: 

During handling of the above exception, another exception occurred:

Traceback (most recent call last):
  File "/datasets/pentschev/miniconda3/envs/gdf/lib/python3.8/site-packages/distributed/worker.py", line 2066, in gather_dep
    response = await get_data_from_worker(
  File "/datasets/pentschev/miniconda3/envs/gdf/lib/python3.8/site-packages/distributed/worker.py", line 2892, in get_data_from_worker
    response = await send_recv(
  File "/datasets/pentschev/miniconda3/envs/gdf/lib/python3.8/site-packages/distributed/core.py", line 1024, in send_recv
    response = await comm.read(deserializers=deserializers)
  File "/datasets/pentschev/miniconda3/envs/gdf/lib/python3.8/site-packages/distributed/utils.py", line 752, in wrapper
    return await func(*args, **kwargs)
  File "/datasets/pentschev/miniconda3/envs/gdf/lib/python3.8/site-packages/distributed/comm/ucx.py", line 367, in read
    raise CommClosedError(
distributed.comm.core.CommClosedError: Connection closed by writer.
Inner exception: UCXCanceled("<[Recv #003] ep: 0x7f829c18f140, tag: 0xe0657c464a7ff921, nbytes: 16, type: <class 'numpy.ndarray'>>: ")
2023-03-25 01:12:32,028 - distributed.nanny - WARNING - Restarting worker
[dgx13:40803:0:40803] Caught signal 11 (Segmentation fault: address not mapped to object at address 0x448)
==== backtrace (tid:  40803) ====
 0  /datasets/pentschev/miniconda3/envs/gdf/lib/libucs.so.0(ucs_handle_error+0x2d4) [0x7fbe01606714]
 1  /datasets/pentschev/miniconda3/envs/gdf/lib/libucs.so.0(+0x2e8ef) [0x7fbe016068ef]
 2  /datasets/pentschev/miniconda3/envs/gdf/lib/libucs.so.0(+0x2ec14) [0x7fbe01606c14]
 3  /lib/x86_64-linux-gnu/libpthread.so.0(+0x12980) [0x7fbe850cc980]
 4  /datasets/pentschev/miniconda3/envs/gdf/lib/libucp.so.0(ucp_mem_type_unpack+0x14) [0x7fbe0188f8d4]
 5  /datasets/pentschev/miniconda3/envs/gdf/lib/libucp.so.0(ucp_rndv_data_handler+0x508) [0x7fbe018c3608]
 6  /datasets/pentschev/miniconda3/envs/gdf/lib/libuct.so.0(+0x20b6f) [0x7fbe013bab6f]
 7  /datasets/pentschev/miniconda3/envs/gdf/lib/libuct.so.0(+0x21144) [0x7fbe013bb144]
 8  /datasets/pentschev/miniconda3/envs/gdf/lib/libuct.so.0(+0x235a8) [0x7fbe013bd5a8]
 9  /datasets/pentschev/miniconda3/envs/gdf/lib/libucs.so.0(ucs_event_set_wait+0xb9) [0x7fbe01610de9]
10  /datasets/pentschev/miniconda3/envs/gdf/lib/libuct.so.0(uct_tcp_iface_progress+0x7b) [0x7fbe013bd64b]
11  /datasets/pentschev/miniconda3/envs/gdf/lib/libucp.so.0(ucp_worker_progress+0x6a) [0x7fbe0188beba]
12  /datasets/pentschev/miniconda3/envs/gdf/lib/python3.8/site-packages/ucp/_libs/ucx_api.cpython-38-x86_64-linux-gnu.so(+0x272b9) [0x7fbe01b4b2b9]
13  /datasets/pentschev/miniconda3/envs/gdf/bin/python(+0x12e343) [0x55b105c71343]
14  /datasets/pentschev/miniconda3/envs/gdf/bin/python(PyObject_Call+0x24a) [0x55b105c7c1fa]
15  /datasets/pentschev/miniconda3/envs/gdf/bin/python(_PyEval_EvalFrameDefault+0x680b) [0x55b105c62b8b]
16  /datasets/pentschev/miniconda3/envs/gdf/bin/python(_PyEval_EvalCodeWithName+0x2f1) [0x55b105c5b2f1]
17  /datasets/pentschev/miniconda3/envs/gdf/bin/python(_PyFunction_Vectorcall+0x19c) [0x55b105c6c93c]
18  /datasets/pentschev/miniconda3/envs/gdf/bin/python(_PyEval_EvalFrameDefault+0x6d5) [0x55b105c5ca55]
19  /datasets/pentschev/miniconda3/envs/gdf/bin/python(+0x13e1e8) [0x55b105c811e8]
20  /datasets/pentschev/miniconda3/envs/gdf/lib/python3.8/lib-dynload/_asyncio.cpython-38-x86_64-linux-gnu.so(+0x7003) [0x7fbe1f7cd003]
21  /datasets/pentschev/miniconda3/envs/gdf/bin/python(_PyObject_MakeTpCall+0x3db) [0x55b105c6530b]
22  /datasets/pentschev/miniconda3/envs/gdf/bin/python(+0xe0b07) [0x55b105c23b07]
23  /datasets/pentschev/miniconda3/envs/gdf/bin/python(+0x120f96) [0x55b105c63f96]
24  /datasets/pentschev/miniconda3/envs/gdf/bin/python(PyVectorcall_Call+0x7a) [0x55b105c7a1ea]
25  /datasets/pentschev/miniconda3/envs/gdf/bin/python(_PyEval_EvalFrameDefault+0x5df8) [0x55b105c62178]
26  /datasets/pentschev/miniconda3/envs/gdf/bin/python(_PyFunction_Vectorcall+0x106) [0x55b105c6c8a6]
27  /datasets/pentschev/miniconda3/envs/gdf/bin/python(_PyEval_EvalFrameDefault+0x6d5) [0x55b105c5ca55]
28  /datasets/pentschev/miniconda3/envs/gdf/bin/python(_PyFunction_Vectorcall+0x106) [0x55b105c6c8a6]
29  /datasets/pentschev/miniconda3/envs/gdf/bin/python(_PyEval_EvalFrameDefault+0x6d5) [0x55b105c5ca55]
30  /datasets/pentschev/miniconda3/envs/gdf/bin/python(_PyFunction_Vectorcall+0x106) [0x55b105c6c8a6]
31  /datasets/pentschev/miniconda3/envs/gdf/bin/python(_PyEval_EvalFrameDefault+0x6d5) [0x55b105c5ca55]
32  /datasets/pentschev/miniconda3/envs/gdf/bin/python(_PyFunction_Vectorcall+0x106) [0x55b105c6c8a6]
33  /datasets/pentschev/miniconda3/envs/gdf/bin/python(_PyEval_EvalFrameDefault+0x6d5) [0x55b105c5ca55]
34  /datasets/pentschev/miniconda3/envs/gdf/bin/python(_PyEval_EvalCodeWithName+0x2f1) [0x55b105c5b2f1]
35  /datasets/pentschev/miniconda3/envs/gdf/bin/python(_PyFunction_Vectorcall+0x19c) [0x55b105c6c93c]
36  /datasets/pentschev/miniconda3/envs/gdf/bin/python(_PyEval_EvalFrameDefault+0x4b7b) [0x55b105c60efb]
37  /datasets/pentschev/miniconda3/envs/gdf/bin/python(_PyEval_EvalCodeWithName+0x2f1) [0x55b105c5b2f1]
38  /datasets/pentschev/miniconda3/envs/gdf/bin/python(_PyFunction_Vectorcall+0x19c) [0x55b105c6c93c]
39  /datasets/pentschev/miniconda3/envs/gdf/bin/python(+0x136e8c) [0x55b105c79e8c]
40  /datasets/pentschev/miniconda3/envs/gdf/bin/python(_PyObject_FastCallDict+0x282) [0x55b105c64a92]
41  /datasets/pentschev/miniconda3/envs/gdf/bin/python(+0x1ee049) [0x55b105d31049]
42  /datasets/pentschev/miniconda3/envs/gdf/bin/python(PyObject_Call+0x2d3) [0x55b105c7c283]
43  /datasets/pentschev/miniconda3/envs/gdf/bin/python(_PyEval_EvalFrameDefault+0x205e) [0x55b105c5e3de]
44  /datasets/pentschev/miniconda3/envs/gdf/bin/python(_PyFunction_Vectorcall+0x106) [0x55b105c6c8a6]
45  /datasets/pentschev/miniconda3/envs/gdf/bin/python(+0x136e8c) [0x55b105c79e8c]
46  /datasets/pentschev/miniconda3/envs/gdf/bin/python(PyObject_Call+0x24a) [0x55b105c7c1fa]
47  /datasets/pentschev/miniconda3/envs/gdf/bin/python(_PyEval_EvalFrameDefault+0x205e) [0x55b105c5e3de]
48  /datasets/pentschev/miniconda3/envs/gdf/bin/python(_PyFunction_Vectorcall+0x106) [0x55b105c6c8a6]
49  /datasets/pentschev/miniconda3/envs/gdf/bin/python(_PyEval_EvalFrameDefault+0x6d5) [0x55b105c5ca55]
50  /datasets/pentschev/miniconda3/envs/gdf/bin/python(_PyEval_EvalCodeWithName+0x2f1) [0x55b105c5b2f1]
51  /datasets/pentschev/miniconda3/envs/gdf/bin/python(_PyFunction_Vectorcall+0x19c) [0x55b105c6c93c]
52  /datasets/pentschev/miniconda3/envs/gdf/bin/python(_PyEval_EvalFrameDefault+0x6d5) [0x55b105c5ca55]
53  /datasets/pentschev/miniconda3/envs/gdf/bin/python(_PyFunction_Vectorcall+0x106) [0x55b105c6c8a6]
54  /datasets/pentschev/miniconda3/envs/gdf/bin/python(_PyEval_EvalFrameDefault+0x3a9) [0x55b105c5c729]
55  /datasets/pentschev/miniconda3/envs/gdf/bin/python(_PyEval_EvalCodeWithName+0x2f1) [0x55b105c5b2f1]
56  /datasets/pentschev/miniconda3/envs/gdf/bin/python(_PyFunction_Vectorcall+0x19c) [0x55b105c6c93c]
57  /datasets/pentschev/miniconda3/envs/gdf/bin/python(_PyEval_EvalFrameDefault+0x11bf) [0x55b105c5d53f]
58  /datasets/pentschev/miniconda3/envs/gdf/bin/python(_PyEval_EvalCodeWithName+0x2f1) [0x55b105c5b2f1]
59  /datasets/pentschev/miniconda3/envs/gdf/bin/python(PyEval_EvalCodeEx+0x39) [0x55b105d0de99]
60  /datasets/pentschev/miniconda3/envs/gdf/bin/python(PyEval_EvalCode+0x1b) [0x55b105d0de5b]
61  /datasets/pentschev/miniconda3/envs/gdf/bin/python(+0x1eb7f9) [0x55b105d2e7f9]
=================================
2023-03-25 01:12:32,590 - distributed.preloading - INFO - Creating preload: dask_cuda.initialize
2023-03-25 01:12:32,590 - distributed.preloading - INFO - Import preload module: dask_cuda.initialize
2023-03-25 01:12:32,633 - distributed.worker - ERROR - failed during get data with ucx://127.0.0.1:40327 -> ucx://127.0.0.1:51303
Traceback (most recent call last):
  File "/datasets/pentschev/miniconda3/envs/gdf/lib/python3.8/site-packages/distributed/comm/ucx.py", line 333, in write
    await self.ep.send(each_frame)
  File "/datasets/pentschev/miniconda3/envs/gdf/lib/python3.8/site-packages/ucp/core.py", line 650, in send
    return await comm.tag_send(self._ep, buffer, nbytes, tag, name=log)
ucp._libs.exceptions.UCXError: <[Send #007] ep: 0x7efb9c0b5240, tag: 0xe8dac733bc987a4, nbytes: 100000000, type: <class 'cudf.core.buffer.buffer.Buffer'>>: Connection reset by remote peer

During handling of the above exception, another exception occurred:

Traceback (most recent call last):
  File "/datasets/pentschev/miniconda3/envs/gdf/lib/python3.8/site-packages/distributed/worker.py", line 1792, in get_data
    compressed = await comm.write(msg, serializers=serializers)
  File "/datasets/pentschev/miniconda3/envs/gdf/lib/python3.8/site-packages/distributed/utils.py", line 752, in wrapper
    return await func(*args, **kwargs)
  File "/datasets/pentschev/miniconda3/envs/gdf/lib/python3.8/site-packages/distributed/comm/ucx.py", line 337, in write
    raise CommClosedError("While writing, the connection was closed")
distributed.comm.core.CommClosedError: While writing, the connection was closed
2023-03-25 01:12:32,633 - distributed.worker - ERROR - Worker stream died during communication: ucx://127.0.0.1:51303
Traceback (most recent call last):
  File "/datasets/pentschev/miniconda3/envs/gdf/lib/python3.8/site-packages/distributed/comm/ucx.py", line 349, in read
    await self.ep.recv(msg)
  File "/datasets/pentschev/miniconda3/envs/gdf/lib/python3.8/site-packages/ucp/core.py", line 725, in recv
    ret = await comm.tag_recv(self._ep, buffer, nbytes, tag, name=log)
ucp._libs.exceptions.UCXCanceled: <[Recv #003] ep: 0x7f08a098c180, tag: 0x9577cb760359f3bc, nbytes: 16, type: <class 'numpy.ndarray'>>: 

During handling of the above exception, another exception occurred:

Traceback (most recent call last):
  File "/datasets/pentschev/miniconda3/envs/gdf/lib/python3.8/site-packages/distributed/worker.py", line 2066, in gather_dep
    response = await get_data_from_worker(
  File "/datasets/pentschev/miniconda3/envs/gdf/lib/python3.8/site-packages/distributed/worker.py", line 2892, in get_data_from_worker
    response = await send_recv(
  File "/datasets/pentschev/miniconda3/envs/gdf/lib/python3.8/site-packages/distributed/core.py", line 1024, in send_recv
    response = await comm.read(deserializers=deserializers)
  File "/datasets/pentschev/miniconda3/envs/gdf/lib/python3.8/site-packages/distributed/utils.py", line 752, in wrapper
    return await func(*args, **kwargs)
  File "/datasets/pentschev/miniconda3/envs/gdf/lib/python3.8/site-packages/distributed/comm/ucx.py", line 367, in read
    raise CommClosedError(
distributed.comm.core.CommClosedError: Connection closed by writer.
Inner exception: UCXCanceled("<[Recv #003] ep: 0x7f08a098c180, tag: 0x9577cb760359f3bc, nbytes: 16, type: <class 'numpy.ndarray'>>: ")
2023-03-25 01:12:32,633 - distributed.worker - ERROR - Worker stream died during communication: ucx://127.0.0.1:51303
Traceback (most recent call last):
  File "/datasets/pentschev/miniconda3/envs/gdf/lib/python3.8/site-packages/distributed/comm/ucx.py", line 391, in read
    await self.ep.recv(each_frame)
  File "/datasets/pentschev/miniconda3/envs/gdf/lib/python3.8/site-packages/ucp/core.py", line 725, in recv
    ret = await comm.tag_recv(self._ep, buffer, nbytes, tag, name=log)
ucp._libs.exceptions.UCXError: <[Recv #007] ep: 0x7efb9c0b5140, tag: 0x51520530526ddbe8, nbytes: 100000000, type: <class 'rmm._lib.device_buffer.DeviceBuffer'>>: Connection reset by remote peer

During handling of the above exception, another exception occurred:

Traceback (most recent call last):
  File "/datasets/pentschev/miniconda3/envs/gdf/lib/python3.8/site-packages/distributed/worker.py", line 2066, in gather_dep
    response = await get_data_from_worker(
  File "/datasets/pentschev/miniconda3/envs/gdf/lib/python3.8/site-packages/distributed/worker.py", line 2892, in get_data_from_worker
    response = await send_recv(
  File "/datasets/pentschev/miniconda3/envs/gdf/lib/python3.8/site-packages/distributed/core.py", line 1024, in send_recv
    response = await comm.read(deserializers=deserializers)
  File "/datasets/pentschev/miniconda3/envs/gdf/lib/python3.8/site-packages/distributed/utils.py", line 752, in wrapper
    return await func(*args, **kwargs)
  File "/datasets/pentschev/miniconda3/envs/gdf/lib/python3.8/site-packages/distributed/comm/ucx.py", line 397, in read
    raise CommClosedError(
distributed.comm.core.CommClosedError: Connection closed by writer.
Inner exception: UCXError("<[Recv #007] ep: 0x7efb9c0b5140, tag: 0x51520530526ddbe8, nbytes: 100000000, type: <class 'rmm._lib.device_buffer.DeviceBuffer'>>: Connection reset by remote peer")
2023-03-25 01:12:32,687 - distributed.preloading - INFO - Creating preload: dask_cuda.initialize
2023-03-25 01:12:32,687 - distributed.preloading - INFO - Import preload module: dask_cuda.initialize
2023-03-25 01:12:32,769 - distributed.diskutils - INFO - Found stale lock file and directory '/tmp/dask-worker-space/worker-oz2asz4s', purging
2023-03-25 01:12:32,770 - distributed.preloading - INFO - Creating preload: dask_cuda.initialize
2023-03-25 01:12:32,770 - distributed.preloading - INFO - Import preload module: dask_cuda.initialize
2023-03-25 01:12:32,775 - distributed.nanny - WARNING - Restarting worker
2023-03-25 01:12:34,093 - distributed.preloading - INFO - Creating preload: dask_cuda.initialize
2023-03-25 01:12:34,093 - distributed.preloading - INFO - Import preload module: dask_cuda.initialize
[dgx13:41343:0:41343] Caught signal 11 (Segmentation fault: address not mapped to object at address 0x448)
==== backtrace (tid:  41343) ====
 0  /datasets/pentschev/miniconda3/envs/gdf/lib/libucs.so.0(ucs_handle_error+0x2d4) [0x7f78d1577714]
 1  /datasets/pentschev/miniconda3/envs/gdf/lib/libucs.so.0(+0x2e8ef) [0x7f78d15778ef]
 2  /datasets/pentschev/miniconda3/envs/gdf/lib/libucs.so.0(+0x2ec14) [0x7f78d1577c14]
 3  /lib/x86_64-linux-gnu/libpthread.so.0(+0x12980) [0x7f7946e8e980]
 4  /datasets/pentschev/miniconda3/envs/gdf/lib/libucp.so.0(ucp_mem_type_unpack+0x14) [0x7f78d18008d4]
 5  /datasets/pentschev/miniconda3/envs/gdf/lib/libucp.so.0(ucp_rndv_data_handler+0x508) [0x7f78d1834608]
 6  /datasets/pentschev/miniconda3/envs/gdf/lib/libuct.so.0(+0x20b6f) [0x7f78d132bb6f]
 7  /datasets/pentschev/miniconda3/envs/gdf/lib/libuct.so.0(+0x21144) [0x7f78d132c144]
 8  /datasets/pentschev/miniconda3/envs/gdf/lib/libuct.so.0(+0x235a8) [0x7f78d132e5a8]
 9  /datasets/pentschev/miniconda3/envs/gdf/lib/libucs.so.0(ucs_event_set_wait+0xb9) [0x7f78d1581de9]
10  /datasets/pentschev/miniconda3/envs/gdf/lib/libuct.so.0(uct_tcp_iface_progress+0x7b) [0x7f78d132e64b]
11  /datasets/pentschev/miniconda3/envs/gdf/lib/libucp.so.0(ucp_worker_progress+0x6a) [0x7f78d17fceba]
12  /datasets/pentschev/miniconda3/envs/gdf/lib/python3.8/site-packages/ucp/_libs/ucx_api.cpython-38-x86_64-linux-gnu.so(+0x272b9) [0x7f78d1abc2b9]
13  /datasets/pentschev/miniconda3/envs/gdf/bin/python(+0x12e343) [0x55c4c4a75343]
14  /datasets/pentschev/miniconda3/envs/gdf/bin/python(PyObject_Call+0x24a) [0x55c4c4a801fa]
15  /datasets/pentschev/miniconda3/envs/gdf/bin/python(_PyEval_EvalFrameDefault+0x680b) [0x55c4c4a66b8b]
16  /datasets/pentschev/miniconda3/envs/gdf/bin/python(_PyEval_EvalCodeWithName+0x2f1) [0x55c4c4a5f2f1]
17  /datasets/pentschev/miniconda3/envs/gdf/bin/python(_PyFunction_Vectorcall+0x19c) [0x55c4c4a7093c]
18  /datasets/pentschev/miniconda3/envs/gdf/bin/python(_PyEval_EvalFrameDefault+0x6d5) [0x55c4c4a60a55]
19  /datasets/pentschev/miniconda3/envs/gdf/bin/python(_PyFunction_Vectorcall+0x106) [0x55c4c4a708a6]
20  /datasets/pentschev/miniconda3/envs/gdf/bin/python(+0x136c36) [0x55c4c4a7dc36]
21  /datasets/pentschev/miniconda3/envs/gdf/bin/python(+0x23565a) [0x55c4c4b7c65a]
22  /datasets/pentschev/miniconda3/envs/gdf/bin/python(+0xe0b07) [0x55c4c4a27b07]
23  /datasets/pentschev/miniconda3/envs/gdf/bin/python(+0x120f96) [0x55c4c4a67f96]
24  /datasets/pentschev/miniconda3/envs/gdf/bin/python(PyVectorcall_Call+0x7a) [0x55c4c4a7e1ea]
25  /datasets/pentschev/miniconda3/envs/gdf/bin/python(_PyEval_EvalFrameDefault+0x5df8) [0x55c4c4a66178]
26  /datasets/pentschev/miniconda3/envs/gdf/bin/python(_PyFunction_Vectorcall+0x106) [0x55c4c4a708a6]
27  /datasets/pentschev/miniconda3/envs/gdf/bin/python(_PyEval_EvalFrameDefault+0x6d5) [0x55c4c4a60a55]
28  /datasets/pentschev/miniconda3/envs/gdf/bin/python(_PyFunction_Vectorcall+0x106) [0x55c4c4a708a6]
29  /datasets/pentschev/miniconda3/envs/gdf/bin/python(_PyEval_EvalFrameDefault+0x6d5) [0x55c4c4a60a55]
30  /datasets/pentschev/miniconda3/envs/gdf/bin/python(_PyFunction_Vectorcall+0x106) [0x55c4c4a708a6]
31  /datasets/pentschev/miniconda3/envs/gdf/bin/python(_PyEval_EvalFrameDefault+0x6d5) [0x55c4c4a60a55]
32  /datasets/pentschev/miniconda3/envs/gdf/bin/python(_PyFunction_Vectorcall+0x106) [0x55c4c4a708a6]
33  /datasets/pentschev/miniconda3/envs/gdf/bin/python(_PyEval_EvalFrameDefault+0x6d5) [0x55c4c4a60a55]
34  /datasets/pentschev/miniconda3/envs/gdf/bin/python(_PyEval_EvalCodeWithName+0x2f1) [0x55c4c4a5f2f1]
35  /datasets/pentschev/miniconda3/envs/gdf/bin/python(_PyFunction_Vectorcall+0x19c) [0x55c4c4a7093c]
36  /datasets/pentschev/miniconda3/envs/gdf/bin/python(_PyEval_EvalFrameDefault+0x4b7b) [0x55c4c4a64efb]
37  /datasets/pentschev/miniconda3/envs/gdf/bin/python(_PyEval_EvalCodeWithName+0x2f1) [0x55c4c4a5f2f1]
38  /datasets/pentschev/miniconda3/envs/gdf/bin/python(_PyFunction_Vectorcall+0x19c) [0x55c4c4a7093c]
39  /datasets/pentschev/miniconda3/envs/gdf/bin/python(+0x136e8c) [0x55c4c4a7de8c]
40  /datasets/pentschev/miniconda3/envs/gdf/bin/python(_PyObject_FastCallDict+0x282) [0x55c4c4a68a92]
41  /datasets/pentschev/miniconda3/envs/gdf/bin/python(+0x1ee049) [0x55c4c4b35049]
42  /datasets/pentschev/miniconda3/envs/gdf/bin/python(PyObject_Call+0x2d3) [0x55c4c4a80283]
43  /datasets/pentschev/miniconda3/envs/gdf/bin/python(_PyEval_EvalFrameDefault+0x205e) [0x55c4c4a623de]
44  /datasets/pentschev/miniconda3/envs/gdf/bin/python(_PyFunction_Vectorcall+0x106) [0x55c4c4a708a6]
45  /datasets/pentschev/miniconda3/envs/gdf/bin/python(+0x136e8c) [0x55c4c4a7de8c]
46  /datasets/pentschev/miniconda3/envs/gdf/bin/python(PyObject_Call+0x24a) [0x55c4c4a801fa]
47  /datasets/pentschev/miniconda3/envs/gdf/bin/python(_PyEval_EvalFrameDefault+0x205e) [0x55c4c4a623de]
48  /datasets/pentschev/miniconda3/envs/gdf/bin/python(_PyFunction_Vectorcall+0x106) [0x55c4c4a708a6]
49  /datasets/pentschev/miniconda3/envs/gdf/bin/python(_PyEval_EvalFrameDefault+0x6d5) [0x55c4c4a60a55]
50  /datasets/pentschev/miniconda3/envs/gdf/bin/python(_PyEval_EvalCodeWithName+0x2f1) [0x55c4c4a5f2f1]
51  /datasets/pentschev/miniconda3/envs/gdf/bin/python(_PyFunction_Vectorcall+0x19c) [0x55c4c4a7093c]
52  /datasets/pentschev/miniconda3/envs/gdf/bin/python(_PyEval_EvalFrameDefault+0x6d5) [0x55c4c4a60a55]
53  /datasets/pentschev/miniconda3/envs/gdf/bin/python(_PyFunction_Vectorcall+0x106) [0x55c4c4a708a6]
54  /datasets/pentschev/miniconda3/envs/gdf/bin/python(_PyEval_EvalFrameDefault+0x3a9) [0x55c4c4a60729]
55  /datasets/pentschev/miniconda3/envs/gdf/bin/python(_PyEval_EvalCodeWithName+0x2f1) [0x55c4c4a5f2f1]
56  /datasets/pentschev/miniconda3/envs/gdf/bin/python(_PyFunction_Vectorcall+0x19c) [0x55c4c4a7093c]
57  /datasets/pentschev/miniconda3/envs/gdf/bin/python(_PyEval_EvalFrameDefault+0x11bf) [0x55c4c4a6153f]
58  /datasets/pentschev/miniconda3/envs/gdf/bin/python(_PyEval_EvalCodeWithName+0x2f1) [0x55c4c4a5f2f1]
59  /datasets/pentschev/miniconda3/envs/gdf/bin/python(PyEval_EvalCodeEx+0x39) [0x55c4c4b11e99]
60  /datasets/pentschev/miniconda3/envs/gdf/bin/python(PyEval_EvalCode+0x1b) [0x55c4c4b11e5b]
61  /datasets/pentschev/miniconda3/envs/gdf/bin/python(+0x1eb7f9) [0x55c4c4b327f9]
=================================
2023-03-25 01:12:34,479 - distributed.worker - ERROR - failed during get data with ucx://127.0.0.1:45929 -> ucx://127.0.0.1:38281
Traceback (most recent call last):
  File "/datasets/pentschev/miniconda3/envs/gdf/lib/python3.8/site-packages/distributed/comm/ucx.py", line 333, in write
    await self.ep.send(each_frame)
  File "/datasets/pentschev/miniconda3/envs/gdf/lib/python3.8/site-packages/ucp/core.py", line 650, in send
    return await comm.tag_send(self._ep, buffer, nbytes, tag, name=log)
ucp._libs.exceptions.UCXError: <[Send #007] ep: 0x7f829c18f280, tag: 0x47e399348b396991, nbytes: 800000000, type: <class 'cudf.core.buffer.buffer.Buffer'>>: Connection reset by remote peer

During handling of the above exception, another exception occurred:

Traceback (most recent call last):
  File "/datasets/pentschev/miniconda3/envs/gdf/lib/python3.8/site-packages/distributed/worker.py", line 1792, in get_data
    compressed = await comm.write(msg, serializers=serializers)
  File "/datasets/pentschev/miniconda3/envs/gdf/lib/python3.8/site-packages/distributed/utils.py", line 752, in wrapper
    return await func(*args, **kwargs)
  File "/datasets/pentschev/miniconda3/envs/gdf/lib/python3.8/site-packages/distributed/comm/ucx.py", line 337, in write
    raise CommClosedError("While writing, the connection was closed")
distributed.comm.core.CommClosedError: While writing, the connection was closed
2023-03-25 01:12:34,583 - distributed.nanny - WARNING - Restarting worker
2023-03-25 01:12:34,680 - distributed.worker - WARNING - Compute Failed
Key:       ('group-simple-shuffle-84a0276e6a854cf0d6c4324869a61d39', 7)
Function:  <dask.layers.CallableLazyImport object at 0x7efad0
args:      (                 key   payload
0         1518863339  99051695
1         1552208751  78953234
2          689778035  81293845
3         1553618300  74974697
4         1502090160  62919800
...              ...       ...
99999995    87713713  72068972
99999996  1549206659  33160153
99999997  1559655348  40095643
99999998  1552540937  33956372
99999999  1512812172  90324512

[100000000 rows x 2 columns], ['key'], 0, 8, 8, False, 8)
kwargs:    {}
Exception: "MemoryError('std::bad_alloc: out_of_memory: CUDA error at: /datasets/pentschev/miniconda3/envs/gdf/include/rmm/mr/device/cuda_memory_resource.hpp')"

2023-03-25 01:12:34,724 - distributed.preloading - INFO - Creating preload: dask_cuda.initialize
2023-03-25 01:12:34,724 - distributed.preloading - INFO - Import preload module: dask_cuda.initialize
2023-03-25 01:12:34,923 - distributed.worker - WARNING - Compute Failed
Key:       ('group-simple-shuffle-84a0276e6a854cf0d6c4324869a61d39', 6)
Function:  <dask.layers.CallableLazyImport object at 0x7f812f
args:      (                 key   payload
0         1418863339  99051695
1         1452208751  78953234
2          677278035  81293845
3         1453618300  74974697
4         1402090160  62919800
...              ...       ...
99999995    75213713  72068972
99999996  1449206659  33160153
99999997  1459655348  40095643
99999998  1452540937  33956372
99999999  1412812172  90324512

[100000000 rows x 2 columns], ['key'], 0, 8, 8, False, 8)
kwargs:    {}
Exception: "MemoryError('std::bad_alloc: out_of_memory: CUDA error at: /datasets/pentschev/miniconda3/envs/gdf/include/rmm/mr/device/cuda_memory_resource.hpp')"

2023-03-25 01:12:36,594 - distributed.preloading - INFO - Creating preload: dask_cuda.initialize
2023-03-25 01:12:36,594 - distributed.preloading - INFO - Import preload module: dask_cuda.initialize
[dgx13:41360:0:41360] Caught signal 11 (Segmentation fault: address not mapped to object at address 0x448)
==== backtrace (tid:  41360) ====
 0  /datasets/pentschev/miniconda3/envs/gdf/lib/libucs.so.0(ucs_handle_error+0x2d4) [0x7f0c71837714]
 1  /datasets/pentschev/miniconda3/envs/gdf/lib/libucs.so.0(+0x2e8ef) [0x7f0c718378ef]
 2  /datasets/pentschev/miniconda3/envs/gdf/lib/libucs.so.0(+0x2ec14) [0x7f0c71837c14]
 3  /lib/x86_64-linux-gnu/libpthread.so.0(+0x12980) [0x7f0cf91d4980]
 4  /datasets/pentschev/miniconda3/envs/gdf/lib/libucp.so.0(ucp_mem_type_unpack+0x14) [0x7f0c71ac08d4]
 5  /datasets/pentschev/miniconda3/envs/gdf/lib/libucp.so.0(ucp_rndv_data_handler+0x508) [0x7f0c71af4608]
 6  /datasets/pentschev/miniconda3/envs/gdf/lib/libuct.so.0(+0x20b6f) [0x7f0c715ebb6f]
 7  /datasets/pentschev/miniconda3/envs/gdf/lib/libuct.so.0(+0x21144) [0x7f0c715ec144]
 8  /datasets/pentschev/miniconda3/envs/gdf/lib/libuct.so.0(+0x235a8) [0x7f0c715ee5a8]
 9  /datasets/pentschev/miniconda3/envs/gdf/lib/libucs.so.0(ucs_event_set_wait+0xb9) [0x7f0c71841de9]
10  /datasets/pentschev/miniconda3/envs/gdf/lib/libuct.so.0(uct_tcp_iface_progress+0x7b) [0x7f0c715ee64b]
11  /datasets/pentschev/miniconda3/envs/gdf/lib/libucp.so.0(ucp_worker_progress+0x6a) [0x7f0c71abceba]
12  /datasets/pentschev/miniconda3/envs/gdf/lib/python3.8/site-packages/ucp/_libs/ucx_api.cpython-38-x86_64-linux-gnu.so(+0x272b9) [0x7f0c71d7c2b9]
13  /datasets/pentschev/miniconda3/envs/gdf/bin/python(+0x12e343) [0x559a72670343]
14  /datasets/pentschev/miniconda3/envs/gdf/bin/python(PyObject_Call+0x24a) [0x559a7267b1fa]
15  /datasets/pentschev/miniconda3/envs/gdf/bin/python(_PyEval_EvalFrameDefault+0x680b) [0x559a72661b8b]
16  /datasets/pentschev/miniconda3/envs/gdf/bin/python(_PyEval_EvalCodeWithName+0x2f1) [0x559a7265a2f1]
17  /datasets/pentschev/miniconda3/envs/gdf/bin/python(_PyFunction_Vectorcall+0x19c) [0x559a7266b93c]
18  /datasets/pentschev/miniconda3/envs/gdf/bin/python(_PyEval_EvalFrameDefault+0x6d5) [0x559a7265ba55]
19  /datasets/pentschev/miniconda3/envs/gdf/bin/python(+0x13e1e8) [0x559a726801e8]
20  /datasets/pentschev/miniconda3/envs/gdf/lib/python3.8/lib-dynload/_asyncio.cpython-38-x86_64-linux-gnu.so(+0x7003) [0x7f0c938d7003]
21  /datasets/pentschev/miniconda3/envs/gdf/bin/python(_PyObject_MakeTpCall+0x3db) [0x559a7266430b]
22  /datasets/pentschev/miniconda3/envs/gdf/bin/python(+0xe0b07) [0x559a72622b07]
23  /datasets/pentschev/miniconda3/envs/gdf/bin/python(+0x120f96) [0x559a72662f96]
24  /datasets/pentschev/miniconda3/envs/gdf/bin/python(PyVectorcall_Call+0x7a) [0x559a726791ea]
25  /datasets/pentschev/miniconda3/envs/gdf/bin/python(_PyEval_EvalFrameDefault+0x5df8) [0x559a72661178]
26  /datasets/pentschev/miniconda3/envs/gdf/bin/python(_PyFunction_Vectorcall+0x106) [0x559a7266b8a6]
27  /datasets/pentschev/miniconda3/envs/gdf/bin/python(_PyEval_EvalFrameDefault+0x6d5) [0x559a7265ba55]
28  /datasets/pentschev/miniconda3/envs/gdf/bin/python(_PyFunction_Vectorcall+0x106) [0x559a7266b8a6]
29  /datasets/pentschev/miniconda3/envs/gdf/bin/python(_PyEval_EvalFrameDefault+0x6d5) [0x559a7265ba55]
30  /datasets/pentschev/miniconda3/envs/gdf/bin/python(_PyFunction_Vectorcall+0x106) [0x559a7266b8a6]
31  /datasets/pentschev/miniconda3/envs/gdf/bin/python(_PyEval_EvalFrameDefault+0x6d5) [0x559a7265ba55]
32  /datasets/pentschev/miniconda3/envs/gdf/bin/python(_PyFunction_Vectorcall+0x106) [0x559a7266b8a6]
33  /datasets/pentschev/miniconda3/envs/gdf/bin/python(_PyEval_EvalFrameDefault+0x6d5) [0x559a7265ba55]
34  /datasets/pentschev/miniconda3/envs/gdf/bin/python(_PyEval_EvalCodeWithName+0x2f1) [0x559a7265a2f1]
35  /datasets/pentschev/miniconda3/envs/gdf/bin/python(_PyFunction_Vectorcall+0x19c) [0x559a7266b93c]
36  /datasets/pentschev/miniconda3/envs/gdf/bin/python(_PyEval_EvalFrameDefault+0x4b7b) [0x559a7265fefb]
37  /datasets/pentschev/miniconda3/envs/gdf/bin/python(_PyEval_EvalCodeWithName+0x2f1) [0x559a7265a2f1]
38  /datasets/pentschev/miniconda3/envs/gdf/bin/python(_PyFunction_Vectorcall+0x19c) [0x559a7266b93c]
39  /datasets/pentschev/miniconda3/envs/gdf/bin/python(+0x136e8c) [0x559a72678e8c]
40  /datasets/pentschev/miniconda3/envs/gdf/bin/python(_PyObject_FastCallDict+0x282) [0x559a72663a92]
41  /datasets/pentschev/miniconda3/envs/gdf/bin/python(+0x1ee049) [0x559a72730049]
42  /datasets/pentschev/miniconda3/envs/gdf/bin/python(PyObject_Call+0x2d3) [0x559a7267b283]
43  /datasets/pentschev/miniconda3/envs/gdf/bin/python(_PyEval_EvalFrameDefault+0x205e) [0x559a7265d3de]
44  /datasets/pentschev/miniconda3/envs/gdf/bin/python(_PyFunction_Vectorcall+0x106) [0x559a7266b8a6]
45  /datasets/pentschev/miniconda3/envs/gdf/bin/python(+0x136e8c) [0x559a72678e8c]
46  /datasets/pentschev/miniconda3/envs/gdf/bin/python(PyObject_Call+0x24a) [0x559a7267b1fa]
47  /datasets/pentschev/miniconda3/envs/gdf/bin/python(_PyEval_EvalFrameDefault+0x205e) [0x559a7265d3de]
48  /datasets/pentschev/miniconda3/envs/gdf/bin/python(_PyFunction_Vectorcall+0x106) [0x559a7266b8a6]
49  /datasets/pentschev/miniconda3/envs/gdf/bin/python(_PyEval_EvalFrameDefault+0x6d5) [0x559a7265ba55]
50  /datasets/pentschev/miniconda3/envs/gdf/bin/python(_PyEval_EvalCodeWithName+0x2f1) [0x559a7265a2f1]
51  /datasets/pentschev/miniconda3/envs/gdf/bin/python(_PyFunction_Vectorcall+0x19c) [0x559a7266b93c]
52  /datasets/pentschev/miniconda3/envs/gdf/bin/python(_PyEval_EvalFrameDefault+0x6d5) [0x559a7265ba55]
53  /datasets/pentschev/miniconda3/envs/gdf/bin/python(_PyFunction_Vectorcall+0x106) [0x559a7266b8a6]
54  /datasets/pentschev/miniconda3/envs/gdf/bin/python(_PyEval_EvalFrameDefault+0x3a9) [0x559a7265b729]
55  /datasets/pentschev/miniconda3/envs/gdf/bin/python(_PyEval_EvalCodeWithName+0x2f1) [0x559a7265a2f1]
56  /datasets/pentschev/miniconda3/envs/gdf/bin/python(_PyFunction_Vectorcall+0x19c) [0x559a7266b93c]
57  /datasets/pentschev/miniconda3/envs/gdf/bin/python(_PyEval_EvalFrameDefault+0x11bf) [0x559a7265c53f]
58  /datasets/pentschev/miniconda3/envs/gdf/bin/python(_PyEval_EvalCodeWithName+0x2f1) [0x559a7265a2f1]
59  /datasets/pentschev/miniconda3/envs/gdf/bin/python(PyEval_EvalCodeEx+0x39) [0x559a7270ce99]
60  /datasets/pentschev/miniconda3/envs/gdf/bin/python(PyEval_EvalCode+0x1b) [0x559a7270ce5b]
61  /datasets/pentschev/miniconda3/envs/gdf/bin/python(+0x1eb7f9) [0x559a7272d7f9]
=================================
2023-03-25 01:12:38,581 - distributed.worker - ERROR - failed during get data with ucx://127.0.0.1:48619 -> ucx://127.0.0.1:42099
Traceback (most recent call last):
  File "/datasets/pentschev/miniconda3/envs/gdf/lib/python3.8/site-packages/distributed/comm/ucx.py", line 333, in write
    await self.ep.send(each_frame)
  File "/datasets/pentschev/miniconda3/envs/gdf/lib/python3.8/site-packages/ucp/core.py", line 650, in send
    return await comm.tag_send(self._ep, buffer, nbytes, tag, name=log)
ucp._libs.exceptions.UCXError: <[Send #007] ep: 0x7f08a098c3c0, tag: 0xdfbc7e2383e5ed4, nbytes: 100000000, type: <class 'cudf.core.buffer.buffer.Buffer'>>: Endpoint timeout

During handling of the above exception, another exception occurred:

Traceback (most recent call last):
  File "/datasets/pentschev/miniconda3/envs/gdf/lib/python3.8/site-packages/distributed/worker.py", line 1792, in get_data
    compressed = await comm.write(msg, serializers=serializers)
  File "/datasets/pentschev/miniconda3/envs/gdf/lib/python3.8/site-packages/distributed/utils.py", line 752, in wrapper
    return await func(*args, **kwargs)
  File "/datasets/pentschev/miniconda3/envs/gdf/lib/python3.8/site-packages/distributed/comm/ucx.py", line 337, in write
    raise CommClosedError("While writing, the connection was closed")
distributed.comm.core.CommClosedError: While writing, the connection was closed
2023-03-25 01:12:38,582 - distributed.worker - ERROR - failed during get data with ucx://127.0.0.1:45929 -> ucx://127.0.0.1:42099
Traceback (most recent call last):
  File "/datasets/pentschev/miniconda3/envs/gdf/lib/python3.8/site-packages/distributed/comm/ucx.py", line 333, in write
    await self.ep.send(each_frame)
  File "/datasets/pentschev/miniconda3/envs/gdf/lib/python3.8/site-packages/ucp/core.py", line 650, in send
    return await comm.tag_send(self._ep, buffer, nbytes, tag, name=log)
ucp._libs.exceptions.UCXError: <[Send #007] ep: 0x7f829c18f380, tag: 0xdf05c3ac2e46c45f, nbytes: 100000000, type: <class 'cudf.core.buffer.buffer.Buffer'>>: Connection reset by remote peer

During handling of the above exception, another exception occurred:

Traceback (most recent call last):
  File "/datasets/pentschev/miniconda3/envs/gdf/lib/python3.8/site-packages/distributed/worker.py", line 1792, in get_data
    compressed = await comm.write(msg, serializers=serializers)
  File "/datasets/pentschev/miniconda3/envs/gdf/lib/python3.8/site-packages/distributed/utils.py", line 752, in wrapper
    return await func(*args, **kwargs)
  File "/datasets/pentschev/miniconda3/envs/gdf/lib/python3.8/site-packages/distributed/comm/ucx.py", line 337, in write
    raise CommClosedError("While writing, the connection was closed")
distributed.comm.core.CommClosedError: While writing, the connection was closed
2023-03-25 01:12:38,687 - distributed.nanny - WARNING - Restarting worker
[dgx13:41376:0:41376] Caught signal 11 (Segmentation fault: address not mapped to object at address 0x448)
==== backtrace (tid:  41376) ====
 0  /datasets/pentschev/miniconda3/envs/gdf/lib/libucs.so.0(ucs_handle_error+0x2d4) [0x7fa1be034714]
 1  /datasets/pentschev/miniconda3/envs/gdf/lib/libucs.so.0(+0x2e8ef) [0x7fa1be0348ef]
 2  /datasets/pentschev/miniconda3/envs/gdf/lib/libucs.so.0(+0x2ec14) [0x7fa1be034c14]
 3  /lib/x86_64-linux-gnu/libpthread.so.0(+0x12980) [0x7fa233992980]
 4  /datasets/pentschev/miniconda3/envs/gdf/lib/libucp.so.0(ucp_mem_type_unpack+0x14) [0x7fa1be2bd8d4]
 5  /datasets/pentschev/miniconda3/envs/gdf/lib/libucp.so.0(ucp_rndv_data_handler+0x508) [0x7fa1be2f1608]
 6  /datasets/pentschev/miniconda3/envs/gdf/lib/libuct.so.0(+0x20b6f) [0x7fa1bdde8b6f]
 7  /datasets/pentschev/miniconda3/envs/gdf/lib/libuct.so.0(+0x21144) [0x7fa1bdde9144]
 8  /datasets/pentschev/miniconda3/envs/gdf/lib/libuct.so.0(+0x235a8) [0x7fa1bddeb5a8]
 9  /datasets/pentschev/miniconda3/envs/gdf/lib/libucs.so.0(ucs_event_set_wait+0xb9) [0x7fa1be03ede9]
10  /datasets/pentschev/miniconda3/envs/gdf/lib/libuct.so.0(uct_tcp_iface_progress+0x7b) [0x7fa1bddeb64b]
11  /datasets/pentschev/miniconda3/envs/gdf/lib/libucp.so.0(ucp_worker_progress+0x6a) [0x7fa1be2b9eba]
12  /datasets/pentschev/miniconda3/envs/gdf/lib/python3.8/site-packages/ucp/_libs/ucx_api.cpython-38-x86_64-linux-gnu.so(+0x272b9) [0x7fa1be5792b9]
13  /datasets/pentschev/miniconda3/envs/gdf/bin/python(+0x12e343) [0x55ca10e53343]
14  /datasets/pentschev/miniconda3/envs/gdf/bin/python(PyObject_Call+0x24a) [0x55ca10e5e1fa]
15  /datasets/pentschev/miniconda3/envs/gdf/bin/python(_PyEval_EvalFrameDefault+0x680b) [0x55ca10e44b8b]
16  /datasets/pentschev/miniconda3/envs/gdf/bin/python(_PyEval_EvalCodeWithName+0x2f1) [0x55ca10e3d2f1]
17  /datasets/pentschev/miniconda3/envs/gdf/bin/python(_PyFunction_Vectorcall+0x19c) [0x55ca10e4e93c]
18  /datasets/pentschev/miniconda3/envs/gdf/bin/python(_PyEval_EvalFrameDefault+0x6d5) [0x55ca10e3ea55]
19  /datasets/pentschev/miniconda3/envs/gdf/bin/python(+0x13e1e8) [0x55ca10e631e8]
20  /datasets/pentschev/miniconda3/envs/gdf/lib/python3.8/lib-dynload/_asyncio.cpython-38-x86_64-linux-gnu.so(+0x7003) [0x7fa1ce08f003]
21  /datasets/pentschev/miniconda3/envs/gdf/bin/python(_PyObject_MakeTpCall+0x3db) [0x55ca10e4730b]
22  /datasets/pentschev/miniconda3/envs/gdf/bin/python(+0xe0b07) [0x55ca10e05b07]
23  /datasets/pentschev/miniconda3/envs/gdf/bin/python(+0x120f96) [0x55ca10e45f96]
24  /datasets/pentschev/miniconda3/envs/gdf/bin/python(PyVectorcall_Call+0x7a) [0x55ca10e5c1ea]
25  /datasets/pentschev/miniconda3/envs/gdf/bin/python(_PyEval_EvalFrameDefault+0x5df8) [0x55ca10e44178]
26  /datasets/pentschev/miniconda3/envs/gdf/bin/python(_PyFunction_Vectorcall+0x106) [0x55ca10e4e8a6]
27  /datasets/pentschev/miniconda3/envs/gdf/bin/python(_PyEval_EvalFrameDefault+0x6d5) [0x55ca10e3ea55]
28  /datasets/pentschev/miniconda3/envs/gdf/bin/python(_PyFunction_Vectorcall+0x106) [0x55ca10e4e8a6]
29  /datasets/pentschev/miniconda3/envs/gdf/bin/python(_PyEval_EvalFrameDefault+0x6d5) [0x55ca10e3ea55]
30  /datasets/pentschev/miniconda3/envs/gdf/bin/python(_PyFunction_Vectorcall+0x106) [0x55ca10e4e8a6]
31  /datasets/pentschev/miniconda3/envs/gdf/bin/python(_PyEval_EvalFrameDefault+0x6d5) [0x55ca10e3ea55]
32  /datasets/pentschev/miniconda3/envs/gdf/bin/python(_PyFunction_Vectorcall+0x106) [0x55ca10e4e8a6]
33  /datasets/pentschev/miniconda3/envs/gdf/bin/python(_PyEval_EvalFrameDefault+0x6d5) [0x55ca10e3ea55]
34  /datasets/pentschev/miniconda3/envs/gdf/bin/python(_PyEval_EvalCodeWithName+0x2f1) [0x55ca10e3d2f1]
35  /datasets/pentschev/miniconda3/envs/gdf/bin/python(_PyFunction_Vectorcall+0x19c) [0x55ca10e4e93c]
36  /datasets/pentschev/miniconda3/envs/gdf/bin/python(_PyEval_EvalFrameDefault+0x4b7b) [0x55ca10e42efb]
37  /datasets/pentschev/miniconda3/envs/gdf/bin/python(_PyEval_EvalCodeWithName+0x2f1) [0x55ca10e3d2f1]
38  /datasets/pentschev/miniconda3/envs/gdf/bin/python(_PyFunction_Vectorcall+0x19c) [0x55ca10e4e93c]
39  /datasets/pentschev/miniconda3/envs/gdf/bin/python(+0x136e8c) [0x55ca10e5be8c]
40  /datasets/pentschev/miniconda3/envs/gdf/bin/python(_PyObject_FastCallDict+0x282) [0x55ca10e46a92]
41  /datasets/pentschev/miniconda3/envs/gdf/bin/python(+0x1ee049) [0x55ca10f13049]
42  /datasets/pentschev/miniconda3/envs/gdf/bin/python(PyObject_Call+0x2d3) [0x55ca10e5e283]
43  /datasets/pentschev/miniconda3/envs/gdf/bin/python(_PyEval_EvalFrameDefault+0x205e) [0x55ca10e403de]
44  /datasets/pentschev/miniconda3/envs/gdf/bin/python(_PyFunction_Vectorcall+0x106) [0x55ca10e4e8a6]
45  /datasets/pentschev/miniconda3/envs/gdf/bin/python(+0x136e8c) [0x55ca10e5be8c]
46  /datasets/pentschev/miniconda3/envs/gdf/bin/python(PyObject_Call+0x24a) [0x55ca10e5e1fa]
47  /datasets/pentschev/miniconda3/envs/gdf/bin/python(_PyEval_EvalFrameDefault+0x205e) [0x55ca10e403de]
48  /datasets/pentschev/miniconda3/envs/gdf/bin/python(_PyFunction_Vectorcall+0x106) [0x55ca10e4e8a6]
49  /datasets/pentschev/miniconda3/envs/gdf/bin/python(_PyEval_EvalFrameDefault+0x6d5) [0x55ca10e3ea55]
50  /datasets/pentschev/miniconda3/envs/gdf/bin/python(_PyEval_EvalCodeWithName+0x2f1) [0x55ca10e3d2f1]
51  /datasets/pentschev/miniconda3/envs/gdf/bin/python(_PyFunction_Vectorcall+0x19c) [0x55ca10e4e93c]
52  /datasets/pentschev/miniconda3/envs/gdf/bin/python(_PyEval_EvalFrameDefault+0x6d5) [0x55ca10e3ea55]
53  /datasets/pentschev/miniconda3/envs/gdf/bin/python(_PyFunction_Vectorcall+0x106) [0x55ca10e4e8a6]
54  /datasets/pentschev/miniconda3/envs/gdf/bin/python(_PyEval_EvalFrameDefault+0x3a9) [0x55ca10e3e729]
55  /datasets/pentschev/miniconda3/envs/gdf/bin/python(_PyEval_EvalCodeWithName+0x2f1) [0x55ca10e3d2f1]
56  /datasets/pentschev/miniconda3/envs/gdf/bin/python(_PyFunction_Vectorcall+0x19c) [0x55ca10e4e93c]
57  /datasets/pentschev/miniconda3/envs/gdf/bin/python(_PyEval_EvalFrameDefault+0x11bf) [0x55ca10e3f53f]
58  /datasets/pentschev/miniconda3/envs/gdf/bin/python(_PyEval_EvalCodeWithName+0x2f1) [0x55ca10e3d2f1]
59  /datasets/pentschev/miniconda3/envs/gdf/bin/python(PyEval_EvalCodeEx+0x39) [0x55ca10eefe99]
60  /datasets/pentschev/miniconda3/envs/gdf/bin/python(PyEval_EvalCode+0x1b) [0x55ca10eefe5b]
61  /datasets/pentschev/miniconda3/envs/gdf/bin/python(+0x1eb7f9) [0x55ca10f107f9]
=================================
2023-03-25 01:12:39,083 - distributed.worker - ERROR - failed during get data with ucx://127.0.0.1:40327 -> ucx://127.0.0.1:60213
Traceback (most recent call last):
  File "/datasets/pentschev/miniconda3/envs/gdf/lib/python3.8/site-packages/distributed/comm/ucx.py", line 333, in write
    await self.ep.send(each_frame)
  File "/datasets/pentschev/miniconda3/envs/gdf/lib/python3.8/site-packages/ucp/core.py", line 650, in send
    return await comm.tag_send(self._ep, buffer, nbytes, tag, name=log)
ucp._libs.exceptions.UCXError: <[Send #007] ep: 0x7efb9c0b53c0, tag: 0xc865d4329ea0b89f, nbytes: 100000000, type: <class 'cudf.core.buffer.buffer.Buffer'>>: Connection reset by remote peer

During handling of the above exception, another exception occurred:

Traceback (most recent call last):
  File "/datasets/pentschev/miniconda3/envs/gdf/lib/python3.8/site-packages/distributed/worker.py", line 1792, in get_data
    compressed = await comm.write(msg, serializers=serializers)
  File "/datasets/pentschev/miniconda3/envs/gdf/lib/python3.8/site-packages/distributed/utils.py", line 752, in wrapper
    return await func(*args, **kwargs)
  File "/datasets/pentschev/miniconda3/envs/gdf/lib/python3.8/site-packages/distributed/comm/ucx.py", line 337, in write
    raise CommClosedError("While writing, the connection was closed")
distributed.comm.core.CommClosedError: While writing, the connection was closed
Task exception was never retrieved
future: <Task finished name='Task-3444' coro=<_listener_handler_coroutine() done, defined at /datasets/pentschev/miniconda3/envs/gdf/lib/python3.8/site-packages/ucp/core.py:128> exception=UCXError('<stream_send>: Endpoint timeout')>
Traceback (most recent call last):
  File "/datasets/pentschev/miniconda3/envs/gdf/lib/python3.8/site-packages/ucp/core.py", line 143, in _listener_handler_coroutine
    peer_info = await exchange_peer_info(
  File "/datasets/pentschev/miniconda3/envs/gdf/lib/python3.8/site-packages/ucp/core.py", line 51, in exchange_peer_info
    await comm.stream_send(endpoint, my_info_arr, my_info_arr.nbytes)
ucp._libs.exceptions.UCXError: <stream_send>: Endpoint timeout
2023-03-25 01:12:39,171 - distributed.nanny - WARNING - Restarting worker
[1679731959.176524] [dgx13:41347:0]            sock.c:323  UCX  ERROR   connect(fd=209, dest_addr=127.0.0.1:43275) failed: Connection refused
Task exception was never retrieved
future: <Task finished name='Task-795' coro=<_listener_handler_coroutine() done, defined at /datasets/pentschev/miniconda3/envs/gdf/lib/python3.8/site-packages/ucp/core.py:128> exception=UCXError('Destination is unreachable')>
Traceback (most recent call last):
  File "/datasets/pentschev/miniconda3/envs/gdf/lib/python3.8/site-packages/ucp/core.py", line 135, in _listener_handler_coroutine
    endpoint = ucx_api.UCXEndpoint.create_from_conn_request(
  File "ucp/_libs/ucx_endpoint.pyx", line 315, in ucp._libs.ucx_api.UCXEndpoint.create_from_conn_request
  File "ucp/_libs/ucx_endpoint.pyx", line 231, in ucp._libs.ucx_api.UCXEndpoint.__init__
  File "ucp/_libs/utils.pyx", line 107, in ucp._libs.ucx_api.assert_ucs_status
ucp._libs.exceptions.UCXError: Destination is unreachable
[1679731959.176540] [dgx13:41347:0]       wireup_cm.c:1237 UCX  WARN  server ep 0x7f0d3c030300 failed to connect to remote address on device lo, tl_bitmap 0x40 0x0, status Destination is unreachable
[1679731959.179645] [dgx13:41347:0]            sock.c:323  UCX  ERROR   connect(fd=206, dest_addr=127.0.0.1:44131) failed: Connection refused
Task exception was never retrieved
future: <Task finished name='Task-796' coro=<_listener_handler_coroutine() done, defined at /datasets/pentschev/miniconda3/envs/gdf/lib/python3.8/site-packages/ucp/core.py:128> exception=UCXError('Destination is unreachable')>
Traceback (most recent call last):
  File "/datasets/pentschev/miniconda3/envs/gdf/lib/python3.8/site-packages/ucp/core.py", line 135, in _listener_handler_coroutine
    endpoint = ucx_api.UCXEndpoint.create_from_conn_request(
  File "ucp/_libs/ucx_endpoint.pyx", line 315, in ucp._libs.ucx_api.UCXEndpoint.create_from_conn_request
  File "ucp/_libs/ucx_endpoint.pyx", line 231, in ucp._libs.ucx_api.UCXEndpoint.__init__
  File "ucp/_libs/utils.pyx", line 107, in ucp._libs.ucx_api.assert_ucs_status
ucp._libs.exceptions.UCXError: Destination is unreachable
[1679731959.179655] [dgx13:41347:0]       wireup_cm.c:1237 UCX  WARN  server ep 0x7f0d3c030340 failed to connect to remote address on device lo, tl_bitmap 0x40 0x0, status Destination is unreachable
[dgx13:41347:0:41347] Caught signal 11 (Segmentation fault: address not mapped to object at address 0x448)
==== backtrace (tid:  41347) ====
 0  /datasets/pentschev/miniconda3/envs/gdf/lib/libucs.so.0(ucs_handle_error+0x2d4) [0x7f0d28cef714]
 1  /datasets/pentschev/miniconda3/envs/gdf/lib/libucs.so.0(+0x2e8ef) [0x7f0d28cef8ef]
 2  /datasets/pentschev/miniconda3/envs/gdf/lib/libucs.so.0(+0x2ec14) [0x7f0d28cefc14]
 3  /lib/x86_64-linux-gnu/libpthread.so.0(+0x12980) [0x7f0dac687980]
 4  /datasets/pentschev/miniconda3/envs/gdf/lib/libucp.so.0(ucp_mem_type_unpack+0x14) [0x7f0d28f788d4]
 5  /datasets/pentschev/miniconda3/envs/gdf/lib/libucp.so.0(ucp_rndv_data_handler+0x508) [0x7f0d28fac608]
 6  /datasets/pentschev/miniconda3/envs/gdf/lib/libuct.so.0(+0x20b6f) [0x7f0d28aa3b6f]
 7  /datasets/pentschev/miniconda3/envs/gdf/lib/libuct.so.0(+0x21144) [0x7f0d28aa4144]
 8  /datasets/pentschev/miniconda3/envs/gdf/lib/libuct.so.0(+0x235a8) [0x7f0d28aa65a8]
 9  /datasets/pentschev/miniconda3/envs/gdf/lib/libucs.so.0(ucs_event_set_wait+0xb9) [0x7f0d28cf9de9]
10  /datasets/pentschev/miniconda3/envs/gdf/lib/libuct.so.0(uct_tcp_iface_progress+0x7b) [0x7f0d28aa664b]
11  /datasets/pentschev/miniconda3/envs/gdf/lib/libucp.so.0(ucp_worker_progress+0x6a) [0x7f0d28f74eba]
12  /datasets/pentschev/miniconda3/envs/gdf/lib/python3.8/site-packages/ucp/_libs/ucx_api.cpython-38-x86_64-linux-gnu.so(+0x272b9) [0x7f0d292342b9]
13  /datasets/pentschev/miniconda3/envs/gdf/bin/python(+0x12e343) [0x56194611a343]
14  /datasets/pentschev/miniconda3/envs/gdf/bin/python(PyObject_Call+0x24a) [0x5619461251fa]
15  /datasets/pentschev/miniconda3/envs/gdf/bin/python(_PyEval_EvalFrameDefault+0x680b) [0x56194610bb8b]
16  /datasets/pentschev/miniconda3/envs/gdf/bin/python(_PyEval_EvalCodeWithName+0x2f1) [0x5619461042f1]
17  /datasets/pentschev/miniconda3/envs/gdf/bin/python(_PyFunction_Vectorcall+0x19c) [0x56194611593c]
18  /datasets/pentschev/miniconda3/envs/gdf/bin/python(_PyEval_EvalFrameDefault+0x6d5) [0x561946105a55]
19  /datasets/pentschev/miniconda3/envs/gdf/bin/python(_PyFunction_Vectorcall+0x106) [0x5619461158a6]
20  /datasets/pentschev/miniconda3/envs/gdf/bin/python(+0x136c36) [0x561946122c36]
21  /datasets/pentschev/miniconda3/envs/gdf/bin/python(+0x23565a) [0x56194622165a]
22  /datasets/pentschev/miniconda3/envs/gdf/bin/python(+0xe0b07) [0x5619460ccb07]
23  /datasets/pentschev/miniconda3/envs/gdf/bin/python(+0x120f96) [0x56194610cf96]
24  /datasets/pentschev/miniconda3/envs/gdf/bin/python(PyVectorcall_Call+0x7a) [0x5619461231ea]
25  /datasets/pentschev/miniconda3/envs/gdf/bin/python(_PyEval_EvalFrameDefault+0x5df8) [0x56194610b178]
26  /datasets/pentschev/miniconda3/envs/gdf/bin/python(_PyFunction_Vectorcall+0x106) [0x5619461158a6]
27  /datasets/pentschev/miniconda3/envs/gdf/bin/python(_PyEval_EvalFrameDefault+0x6d5) [0x561946105a55]
28  /datasets/pentschev/miniconda3/envs/gdf/bin/python(_PyFunction_Vectorcall+0x106) [0x5619461158a6]
29  /datasets/pentschev/miniconda3/envs/gdf/bin/python(_PyEval_EvalFrameDefault+0x6d5) [0x561946105a55]
30  /datasets/pentschev/miniconda3/envs/gdf/bin/python(_PyFunction_Vectorcall+0x106) [0x5619461158a6]
31  /datasets/pentschev/miniconda3/envs/gdf/bin/python(_PyEval_EvalFrameDefault+0x6d5) [0x561946105a55]
32  /datasets/pentschev/miniconda3/envs/gdf/bin/python(_PyFunction_Vectorcall+0x106) [0x5619461158a6]
33  /datasets/pentschev/miniconda3/envs/gdf/bin/python(_PyEval_EvalFrameDefault+0x6d5) [0x561946105a55]
34  /datasets/pentschev/miniconda3/envs/gdf/bin/python(_PyEval_EvalCodeWithName+0x2f1) [0x5619461042f1]
35  /datasets/pentschev/miniconda3/envs/gdf/bin/python(_PyFunction_Vectorcall+0x19c) [0x56194611593c]
36  /datasets/pentschev/miniconda3/envs/gdf/bin/python(_PyEval_EvalFrameDefault+0x4b7b) [0x561946109efb]
37  /datasets/pentschev/miniconda3/envs/gdf/bin/python(_PyEval_EvalCodeWithName+0x2f1) [0x5619461042f1]
38  /datasets/pentschev/miniconda3/envs/gdf/bin/python(_PyFunction_Vectorcall+0x19c) [0x56194611593c]
39  /datasets/pentschev/miniconda3/envs/gdf/bin/python(+0x136e8c) [0x561946122e8c]
40  /datasets/pentschev/miniconda3/envs/gdf/bin/python(_PyObject_FastCallDict+0x282) [0x56194610da92]
41  /datasets/pentschev/miniconda3/envs/gdf/bin/python(+0x1ee049) [0x5619461da049]
42  /datasets/pentschev/miniconda3/envs/gdf/bin/python(PyObject_Call+0x2d3) [0x561946125283]
43  /datasets/pentschev/miniconda3/envs/gdf/bin/python(_PyEval_EvalFrameDefault+0x205e) [0x5619461073de]
44  /datasets/pentschev/miniconda3/envs/gdf/bin/python(_PyFunction_Vectorcall+0x106) [0x5619461158a6]
45  /datasets/pentschev/miniconda3/envs/gdf/bin/python(+0x136e8c) [0x561946122e8c]
46  /datasets/pentschev/miniconda3/envs/gdf/bin/python(PyObject_Call+0x24a) [0x5619461251fa]
47  /datasets/pentschev/miniconda3/envs/gdf/bin/python(_PyEval_EvalFrameDefault+0x205e) [0x5619461073de]
48  /datasets/pentschev/miniconda3/envs/gdf/bin/python(_PyFunction_Vectorcall+0x106) [0x5619461158a6]
49  /datasets/pentschev/miniconda3/envs/gdf/bin/python(_PyEval_EvalFrameDefault+0x6d5) [0x561946105a55]
50  /datasets/pentschev/miniconda3/envs/gdf/bin/python(_PyEval_EvalCodeWithName+0x2f1) [0x5619461042f1]
51  /datasets/pentschev/miniconda3/envs/gdf/bin/python(_PyFunction_Vectorcall+0x19c) [0x56194611593c]
52  /datasets/pentschev/miniconda3/envs/gdf/bin/python(_PyEval_EvalFrameDefault+0x6d5) [0x561946105a55]
53  /datasets/pentschev/miniconda3/envs/gdf/bin/python(_PyFunction_Vectorcall+0x106) [0x5619461158a6]
54  /datasets/pentschev/miniconda3/envs/gdf/bin/python(_PyEval_EvalFrameDefault+0x3a9) [0x561946105729]
55  /datasets/pentschev/miniconda3/envs/gdf/bin/python(_PyEval_EvalCodeWithName+0x2f1) [0x5619461042f1]
56  /datasets/pentschev/miniconda3/envs/gdf/bin/python(_PyFunction_Vectorcall+0x19c) [0x56194611593c]
57  /datasets/pentschev/miniconda3/envs/gdf/bin/python(_PyEval_EvalFrameDefault+0x11bf) [0x56194610653f]
58  /datasets/pentschev/miniconda3/envs/gdf/bin/python(_PyEval_EvalCodeWithName+0x2f1) [0x5619461042f1]
59  /datasets/pentschev/miniconda3/envs/gdf/bin/python(PyEval_EvalCodeEx+0x39) [0x5619461b6e99]
60  /datasets/pentschev/miniconda3/envs/gdf/bin/python(PyEval_EvalCode+0x1b) [0x5619461b6e5b]
61  /datasets/pentschev/miniconda3/envs/gdf/bin/python(+0x1eb7f9) [0x5619461d77f9]
=================================
2023-03-25 01:12:39,377 - distributed.worker - ERROR - failed during get data with ucx://127.0.0.1:45929 -> ucx://127.0.0.1:60631
Traceback (most recent call last):
  File "/datasets/pentschev/miniconda3/envs/gdf/lib/python3.8/site-packages/distributed/comm/ucx.py", line 333, in write
    await self.ep.send(each_frame)
  File "/datasets/pentschev/miniconda3/envs/gdf/lib/python3.8/site-packages/ucp/core.py", line 650, in send
    return await comm.tag_send(self._ep, buffer, nbytes, tag, name=log)
ucp._libs.exceptions.UCXError: <[Send #007] ep: 0x7f829c18f340, tag: 0x606b068384782329, nbytes: 100000000, type: <class 'cudf.core.buffer.buffer.Buffer'>>: Connection reset by remote peer

During handling of the above exception, another exception occurred:

Traceback (most recent call last):
  File "/datasets/pentschev/miniconda3/envs/gdf/lib/python3.8/site-packages/distributed/worker.py", line 1792, in get_data
    compressed = await comm.write(msg, serializers=serializers)
  File "/datasets/pentschev/miniconda3/envs/gdf/lib/python3.8/site-packages/distributed/utils.py", line 752, in wrapper
    return await func(*args, **kwargs)
  File "/datasets/pentschev/miniconda3/envs/gdf/lib/python3.8/site-packages/distributed/comm/ucx.py", line 337, in write
    raise CommClosedError("While writing, the connection was closed")
distributed.comm.core.CommClosedError: While writing, the connection was closed
2023-03-25 01:12:39,377 - distributed.worker - ERROR - Worker stream died during communication: ucx://127.0.0.1:60631
Traceback (most recent call last):
  File "/datasets/pentschev/miniconda3/envs/gdf/lib/python3.8/site-packages/distributed/comm/ucx.py", line 391, in read
    await self.ep.recv(each_frame)
  File "/datasets/pentschev/miniconda3/envs/gdf/lib/python3.8/site-packages/ucp/core.py", line 725, in recv
    ret = await comm.tag_recv(self._ep, buffer, nbytes, tag, name=log)
ucp._libs.exceptions.UCXCanceled: <[Recv #009] ep: 0x7f08a098c180, tag: 0x424a77f821250600, nbytes: 100000000, type: <class 'rmm._lib.device_buffer.DeviceBuffer'>>: 

During handling of the above exception, another exception occurred:

Traceback (most recent call last):
  File "/datasets/pentschev/miniconda3/envs/gdf/lib/python3.8/site-packages/distributed/worker.py", line 2066, in gather_dep
    response = await get_data_from_worker(
  File "/datasets/pentschev/miniconda3/envs/gdf/lib/python3.8/site-packages/distributed/worker.py", line 2892, in get_data_from_worker
    response = await send_recv(
  File "/datasets/pentschev/miniconda3/envs/gdf/lib/python3.8/site-packages/distributed/core.py", line 1024, in send_recv
    response = await comm.read(deserializers=deserializers)
  File "/datasets/pentschev/miniconda3/envs/gdf/lib/python3.8/site-packages/distributed/utils.py", line 752, in wrapper
    return await func(*args, **kwargs)
  File "/datasets/pentschev/miniconda3/envs/gdf/lib/python3.8/site-packages/distributed/comm/ucx.py", line 397, in read
    raise CommClosedError(
distributed.comm.core.CommClosedError: Connection closed by writer.
Inner exception: UCXCanceled("<[Recv #009] ep: 0x7f08a098c180, tag: 0x424a77f821250600, nbytes: 100000000, type: <class 'rmm._lib.device_buffer.DeviceBuffer'>>: ")
2023-03-25 01:12:39,377 - distributed.worker - ERROR - Worker stream died during communication: ucx://127.0.0.1:60631
Traceback (most recent call last):
  File "/datasets/pentschev/miniconda3/envs/gdf/lib/python3.8/site-packages/distributed/comm/ucx.py", line 391, in read
    await self.ep.recv(each_frame)
  File "/datasets/pentschev/miniconda3/envs/gdf/lib/python3.8/site-packages/ucp/core.py", line 725, in recv
    ret = await comm.tag_recv(self._ep, buffer, nbytes, tag, name=log)
ucp._libs.exceptions.UCXError: <[Recv #007] ep: 0x7efb9c0b5240, tag: 0xfd321d1e48038f72, nbytes: 100000000, type: <class 'rmm._lib.device_buffer.DeviceBuffer'>>: Connection reset by remote peer

During handling of the above exception, another exception occurred:

Traceback (most recent call last):
  File "/datasets/pentschev/miniconda3/envs/gdf/lib/python3.8/site-packages/distributed/worker.py", line 2066, in gather_dep
    response = await get_data_from_worker(
  File "/datasets/pentschev/miniconda3/envs/gdf/lib/python3.8/site-packages/distributed/worker.py", line 2892, in get_data_from_worker
    response = await send_recv(
  File "/datasets/pentschev/miniconda3/envs/gdf/lib/python3.8/site-packages/distributed/core.py", line 1024, in send_recv
    response = await comm.read(deserializers=deserializers)
  File "/datasets/pentschev/miniconda3/envs/gdf/lib/python3.8/site-packages/distributed/utils.py", line 752, in wrapper
    return await func(*args, **kwargs)
  File "/datasets/pentschev/miniconda3/envs/gdf/lib/python3.8/site-packages/distributed/comm/ucx.py", line 397, in read
    raise CommClosedError(
distributed.comm.core.CommClosedError: Connection closed by writer.
Inner exception: UCXError("<[Recv #007] ep: 0x7efb9c0b5240, tag: 0xfd321d1e48038f72, nbytes: 100000000, type: <class 'rmm._lib.device_buffer.DeviceBuffer'>>: Connection reset by remote peer")
2023-03-25 01:12:39,377 - distributed.worker - ERROR - Worker stream died during communication: ucx://127.0.0.1:60631
Traceback (most recent call last):
  File "/datasets/pentschev/miniconda3/envs/gdf/lib/python3.8/site-packages/distributed/comm/ucx.py", line 391, in read
    await self.ep.recv(each_frame)
  File "/datasets/pentschev/miniconda3/envs/gdf/lib/python3.8/site-packages/ucp/core.py", line 725, in recv
    ret = await comm.tag_recv(self._ep, buffer, nbytes, tag, name=log)
ucp._libs.exceptions.UCXError: <[Recv #007] ep: 0x7f829c18f300, tag: 0x5e837e13df21277c, nbytes: 100000000, type: <class 'rmm._lib.device_buffer.DeviceBuffer'>>: Connection reset by remote peer

During handling of the above exception, another exception occurred:

Traceback (most recent call last):
  File "/datasets/pentschev/miniconda3/envs/gdf/lib/python3.8/site-packages/distributed/worker.py", line 2066, in gather_dep
    response = await get_data_from_worker(
  File "/datasets/pentschev/miniconda3/envs/gdf/lib/python3.8/site-packages/distributed/worker.py", line 2892, in get_data_from_worker
    response = await send_recv(
  File "/datasets/pentschev/miniconda3/envs/gdf/lib/python3.8/site-packages/distributed/core.py", line 1024, in send_recv
    response = await comm.read(deserializers=deserializers)
  File "/datasets/pentschev/miniconda3/envs/gdf/lib/python3.8/site-packages/distributed/utils.py", line 752, in wrapper
    return await func(*args, **kwargs)
  File "/datasets/pentschev/miniconda3/envs/gdf/lib/python3.8/site-packages/distributed/comm/ucx.py", line 397, in read
    raise CommClosedError(
distributed.comm.core.CommClosedError: Connection closed by writer.
Inner exception: UCXError("<[Recv #007] ep: 0x7f829c18f300, tag: 0x5e837e13df21277c, nbytes: 100000000, type: <class 'rmm._lib.device_buffer.DeviceBuffer'>>: Connection reset by remote peer")
2023-03-25 01:12:39,378 - distributed.worker - ERROR - failed during get data with ucx://127.0.0.1:40327 -> ucx://127.0.0.1:60631
Traceback (most recent call last):
  File "/datasets/pentschev/miniconda3/envs/gdf/lib/python3.8/site-packages/distributed/comm/ucx.py", line 333, in write
    await self.ep.send(each_frame)
  File "/datasets/pentschev/miniconda3/envs/gdf/lib/python3.8/site-packages/ucp/core.py", line 650, in send
    return await comm.tag_send(self._ep, buffer, nbytes, tag, name=log)
ucp._libs.exceptions.UCXError: <[Send #007] ep: 0x7efb9c0b5340, tag: 0x8d1ed8833ee2b089, nbytes: 100000000, type: <class 'cudf.core.buffer.buffer.Buffer'>>: Connection reset by remote peer

During handling of the above exception, another exception occurred:

Traceback (most recent call last):
  File "/datasets/pentschev/miniconda3/envs/gdf/lib/python3.8/site-packages/distributed/worker.py", line 1792, in get_data
    compressed = await comm.write(msg, serializers=serializers)
  File "/datasets/pentschev/miniconda3/envs/gdf/lib/python3.8/site-packages/distributed/utils.py", line 752, in wrapper
    return await func(*args, **kwargs)
  File "/datasets/pentschev/miniconda3/envs/gdf/lib/python3.8/site-packages/distributed/comm/ucx.py", line 337, in write
    raise CommClosedError("While writing, the connection was closed")
distributed.comm.core.CommClosedError: While writing, the connection was closed
2023-03-25 01:12:39,460 - distributed.nanny - WARNING - Restarting worker
2023-03-25 01:12:39,394 - distributed.worker - ERROR - failed during get data with ucx://127.0.0.1:40239 -> ucx://127.0.0.1:60631
Traceback (most recent call last):
  File "/datasets/pentschev/miniconda3/envs/gdf/lib/python3.8/site-packages/distributed/comm/ucx.py", line 333, in write
    await self.ep.send(each_frame)
  File "/datasets/pentschev/miniconda3/envs/gdf/lib/python3.8/site-packages/ucp/core.py", line 650, in send
    return await comm.tag_send(self._ep, buffer, nbytes, tag, name=log)
ucp._libs.exceptions.UCXError: <[Send #007] ep: 0x7fa3fc10f2c0, tag: 0x5b258ae7a09f4a36, nbytes: 100000000, type: <class 'cudf.core.buffer.buffer.Buffer'>>: Connection reset by remote peer

During handling of the above exception, another exception occurred:

Traceback (most recent call last):
  File "/datasets/pentschev/miniconda3/envs/gdf/lib/python3.8/site-packages/distributed/worker.py", line 1792, in get_data
    compressed = await comm.write(msg, serializers=serializers)
  File "/datasets/pentschev/miniconda3/envs/gdf/lib/python3.8/site-packages/distributed/utils.py", line 752, in wrapper
    return await func(*args, **kwargs)
  File "/datasets/pentschev/miniconda3/envs/gdf/lib/python3.8/site-packages/distributed/comm/ucx.py", line 337, in write
    raise CommClosedError("While writing, the connection was closed")
distributed.comm.core.CommClosedError: While writing, the connection was closed
2023-03-25 01:12:39,473 - distributed.worker - ERROR - Worker stream died during communication: ucx://127.0.0.1:60631
Traceback (most recent call last):
  File "/datasets/pentschev/miniconda3/envs/gdf/lib/python3.8/site-packages/distributed/comm/ucx.py", line 391, in read
    await self.ep.recv(each_frame)
  File "/datasets/pentschev/miniconda3/envs/gdf/lib/python3.8/site-packages/ucp/core.py", line 725, in recv
    ret = await comm.tag_recv(self._ep, buffer, nbytes, tag, name=log)
ucp._libs.exceptions.UCXError: <[Recv #007] ep: 0x7fa3fc10f1c0, tag: 0x7494b43aca727aad, nbytes: 100000000, type: <class 'rmm._lib.device_buffer.DeviceBuffer'>>: Connection reset by remote peer

During handling of the above exception, another exception occurred:

Traceback (most recent call last):
  File "/datasets/pentschev/miniconda3/envs/gdf/lib/python3.8/site-packages/distributed/worker.py", line 2066, in gather_dep
    response = await get_data_from_worker(
  File "/datasets/pentschev/miniconda3/envs/gdf/lib/python3.8/site-packages/distributed/worker.py", line 2892, in get_data_from_worker
    response = await send_recv(
  File "/datasets/pentschev/miniconda3/envs/gdf/lib/python3.8/site-packages/distributed/core.py", line 1024, in send_recv
    response = await comm.read(deserializers=deserializers)
  File "/datasets/pentschev/miniconda3/envs/gdf/lib/python3.8/site-packages/distributed/utils.py", line 752, in wrapper
    return await func(*args, **kwargs)
  File "/datasets/pentschev/miniconda3/envs/gdf/lib/python3.8/site-packages/distributed/comm/ucx.py", line 397, in read
    raise CommClosedError(
distributed.comm.core.CommClosedError: Connection closed by writer.
Inner exception: UCXError("<[Recv #007] ep: 0x7fa3fc10f1c0, tag: 0x7494b43aca727aad, nbytes: 100000000, type: <class 'rmm._lib.device_buffer.DeviceBuffer'>>: Connection reset by remote peer")
terminate called after throwing an instance of 'rmm::out_of_memory'
  what():  std::bad_alloc: out_of_memory: CUDA error at: /datasets/pentschev/miniconda3/envs/gdf/include/rmm/mr/device/cuda_memory_resource.hpp
2023-03-25 01:12:40,229 - distributed.worker - ERROR - Worker stream died during communication: ucx://127.0.0.1:40327
Traceback (most recent call last):
  File "/datasets/pentschev/miniconda3/envs/gdf/lib/python3.8/site-packages/distributed/comm/ucx.py", line 349, in read
    await self.ep.recv(msg)
  File "/datasets/pentschev/miniconda3/envs/gdf/lib/python3.8/site-packages/ucp/core.py", line 725, in recv
    ret = await comm.tag_recv(self._ep, buffer, nbytes, tag, name=log)
ucp._libs.exceptions.UCXCanceled: <[Recv #043] ep: 0x7fa3fc10f140, tag: 0xb0e7469627624ac9, nbytes: 16, type: <class 'numpy.ndarray'>>: 

During handling of the above exception, another exception occurred:

Traceback (most recent call last):
  File "/datasets/pentschev/miniconda3/envs/gdf/lib/python3.8/site-packages/distributed/worker.py", line 2066, in gather_dep
    response = await get_data_from_worker(
  File "/datasets/pentschev/miniconda3/envs/gdf/lib/python3.8/site-packages/distributed/worker.py", line 2892, in get_data_from_worker
    response = await send_recv(
  File "/datasets/pentschev/miniconda3/envs/gdf/lib/python3.8/site-packages/distributed/core.py", line 1024, in send_recv
    response = await comm.read(deserializers=deserializers)
  File "/datasets/pentschev/miniconda3/envs/gdf/lib/python3.8/site-packages/distributed/utils.py", line 752, in wrapper
    return await func(*args, **kwargs)
  File "/datasets/pentschev/miniconda3/envs/gdf/lib/python3.8/site-packages/distributed/comm/ucx.py", line 367, in read
    raise CommClosedError(
distributed.comm.core.CommClosedError: Connection closed by writer.
Inner exception: UCXCanceled("<[Recv #043] ep: 0x7fa3fc10f140, tag: 0xb0e7469627624ac9, nbytes: 16, type: <class 'numpy.ndarray'>>: ")
2023-03-25 01:12:40,229 - distributed.worker - ERROR - Worker stream died during communication: ucx://127.0.0.1:40327
Traceback (most recent call last):
  File "/datasets/pentschev/miniconda3/envs/gdf/lib/python3.8/site-packages/distributed/comm/ucx.py", line 391, in read
    await self.ep.recv(each_frame)
  File "/datasets/pentschev/miniconda3/envs/gdf/lib/python3.8/site-packages/ucp/core.py", line 725, in recv
    ret = await comm.tag_recv(self._ep, buffer, nbytes, tag, name=log)
ucp._libs.exceptions.UCXCanceled: <[Recv #172] ep: 0x7f829c18f100, tag: 0xd79e86e5917de5a9, nbytes: 50000000, type: <class 'rmm._lib.device_buffer.DeviceBuffer'>>: 

During handling of the above exception, another exception occurred:

Traceback (most recent call last):
  File "/datasets/pentschev/miniconda3/envs/gdf/lib/python3.8/site-packages/distributed/worker.py", line 2066, in gather_dep
    response = await get_data_from_worker(
  File "/datasets/pentschev/miniconda3/envs/gdf/lib/python3.8/site-packages/distributed/worker.py", line 2892, in get_data_from_worker
    response = await send_recv(
  File "/datasets/pentschev/miniconda3/envs/gdf/lib/python3.8/site-packages/distributed/core.py", line 1024, in send_recv
    response = await comm.read(deserializers=deserializers)
  File "/datasets/pentschev/miniconda3/envs/gdf/lib/python3.8/site-packages/distributed/utils.py", line 752, in wrapper
    return await func(*args, **kwargs)
  File "/datasets/pentschev/miniconda3/envs/gdf/lib/python3.8/site-packages/distributed/comm/ucx.py", line 397, in read
    raise CommClosedError(
distributed.comm.core.CommClosedError: Connection closed by writer.
Inner exception: UCXCanceled("<[Recv #172] ep: 0x7f829c18f100, tag: 0xd79e86e5917de5a9, nbytes: 50000000, type: <class 'rmm._lib.device_buffer.DeviceBuffer'>>: ")
2023-03-25 01:12:40,385 - distributed.nanny - WARNING - Restarting worker
2023-03-25 01:12:40,696 - distributed.preloading - INFO - Creating preload: dask_cuda.initialize
2023-03-25 01:12:40,696 - distributed.preloading - INFO - Import preload module: dask_cuda.initialize
2023-03-25 01:12:41,036 - distributed.preloading - INFO - Creating preload: dask_cuda.initialize
2023-03-25 01:12:41,037 - distributed.preloading - INFO - Import preload module: dask_cuda.initialize
2023-03-25 01:12:41,184 - distributed.worker - WARNING - Compute Failed
Key:       ('generate-data-3393696d3757f92da87d0dddd0c6ae01', 3)
Function:  generate_chunk
args:      (3, 100000000, 8, 'other', 0.3, True)
kwargs:    {}
Exception: "MemoryError('std::bad_alloc: out_of_memory: CUDA error at: /datasets/pentschev/miniconda3/envs/gdf/include/rmm/mr/device/cuda_memory_resource.hpp')"

2023-03-25 01:12:41,223 - distributed.worker - WARNING - Compute Failed
Key:       ('generate-data-5366301a596b755bb8c33997d3ce7726', 6)
Function:  generate_chunk
args:      (6, 100000000, 8, 'build', 0.3, True)
kwargs:    {}
Exception: "MemoryError('std::bad_alloc: out_of_memory: CUDA error at: /datasets/pentschev/miniconda3/envs/gdf/include/rmm/mr/device/cuda_memory_resource.hpp')"

2023-03-25 01:12:41,345 - distributed.preloading - INFO - Creating preload: dask_cuda.initialize
2023-03-25 01:12:41,345 - distributed.preloading - INFO - Import preload module: dask_cuda.initialize
2023-03-25 01:12:42,115 - distributed.worker - WARNING - Compute Failed
Key:       ('simple-shuffle-53d2ea28ca2ddf4e499dbe7999168806', 2)
Function:  <dask.layers.CallableLazyImport object at 0x7f812c
args:      ([               key  shuffle   payload  _partitions
0            17611        2   9435491            2
1            27873        2  75141853            2
2            31846        2  69434626            2
3            21152        2  17659730            2
4            32357        2  76133526            2
...            ...      ...       ...          ...
12499995  99995644        2    876310            2
12499996  99995498        2   2069651            2
12499997  99995503        2  76109806            2
12499998  99995505        2  41509941            2
12499999  99995517        2  52464632            2

[12500000 rows x 4 columns],                 key  shuffle   payload  _partitions
0         100031940        2  73294877            2
1         100031947        2   8593953            2
2         100011458        2  26420060            2
3         100031962        2  15102937            2
4         100011463        2  92565536            2
...             ...      ...       ...      
kwargs:    {}
Exception: "MemoryError('std::bad_alloc: out_of_memory: CUDA error at: /datasets/pentschev/miniconda3/envs/gdf/include/rmm/mr/device/cuda_memory_resource.hpp')"

2023-03-25 01:12:42,321 - distributed.preloading - INFO - Creating preload: dask_cuda.initialize
2023-03-25 01:12:42,321 - distributed.preloading - INFO - Import preload module: dask_cuda.initialize
terminate called after throwing an instance of 'rmm::out_of_memory'
  what():  std::bad_alloc: out_of_memory: CUDA error at: /datasets/pentschev/miniconda3/envs/gdf/include/rmm/mr/device/cuda_memory_resource.hpp
2023-03-25 01:12:42,738 - distributed.nanny - WARNING - Restarting worker
2023-03-25 01:12:44,782 - distributed.preloading - INFO - Creating preload: dask_cuda.initialize
2023-03-25 01:12:44,782 - distributed.preloading - INFO - Import preload module: dask_cuda.initialize
/datasets/pentschev/miniconda3/envs/gdf/lib/python3.8/multiprocessing/resource_tracker.py:216: UserWarning: resource_tracker: There appear to be 42 leaked semaphore objects to clean up at shutdown
  warnings.warn('resource_tracker: There appear to be %d '
