2023-08-07 06:54:00,117 - distributed.preloading - INFO - Creating preload: dask_cuda.initialize
2023-08-07 06:54:00,117 - distributed.preloading - INFO - Import preload module: dask_cuda.initialize
2023-08-07 06:54:00,165 - distributed.preloading - INFO - Creating preload: dask_cuda.initialize
2023-08-07 06:54:00,165 - distributed.preloading - INFO - Import preload module: dask_cuda.initialize
2023-08-07 06:54:00,194 - distributed.preloading - INFO - Creating preload: dask_cuda.initialize
2023-08-07 06:54:00,194 - distributed.preloading - INFO - Import preload module: dask_cuda.initialize
2023-08-07 06:54:00,215 - distributed.preloading - INFO - Creating preload: dask_cuda.initialize
2023-08-07 06:54:00,215 - distributed.preloading - INFO - Import preload module: dask_cuda.initialize
2023-08-07 06:54:00,228 - distributed.preloading - INFO - Creating preload: dask_cuda.initialize
2023-08-07 06:54:00,228 - distributed.preloading - INFO - Import preload module: dask_cuda.initialize
2023-08-07 06:54:00,228 - distributed.preloading - INFO - Creating preload: dask_cuda.initialize
2023-08-07 06:54:00,228 - distributed.preloading - INFO - Import preload module: dask_cuda.initialize
2023-08-07 06:54:00,234 - distributed.preloading - INFO - Creating preload: dask_cuda.initialize
2023-08-07 06:54:00,234 - distributed.preloading - INFO - Import preload module: dask_cuda.initialize
2023-08-07 06:54:00,265 - distributed.preloading - INFO - Creating preload: dask_cuda.initialize
2023-08-07 06:54:00,265 - distributed.preloading - INFO - Import preload module: dask_cuda.initialize
[dgx13:63494:0:63494] Caught signal 11 (Segmentation fault: address not mapped to object at address 0x448)
==== backtrace (tid:  63494) ====
 0  /opt/conda/envs/gdf/lib/libucs.so.0(ucs_handle_error+0x2fd) [0x7fc0752d3f1d]
 1  /opt/conda/envs/gdf/lib/libucs.so.0(+0x29114) [0x7fc0752d4114]
 2  /opt/conda/envs/gdf/lib/libucs.so.0(+0x292da) [0x7fc0752d42da]
 3  /usr/lib/x86_64-linux-gnu/libpthread.so.0(+0x14420) [0x7fc118b49420]
 4  /opt/conda/envs/gdf/lib/libucp.so.0(ucp_mem_type_unpack+0x14) [0x7fc07534d5d4]
 5  /opt/conda/envs/gdf/lib/libucp.so.0(ucp_rndv_data_handler+0x4e9) [0x7fc075372859]
 6  /opt/conda/envs/gdf/lib/libuct.so.0(+0x2042f) [0x7fc07528f42f]
 7  /opt/conda/envs/gdf/lib/libuct.so.0(+0x23798) [0x7fc075292798]
 8  /opt/conda/envs/gdf/lib/libucs.so.0(ucs_event_set_wait+0xb9) [0x7fc0752dc989]
 9  /opt/conda/envs/gdf/lib/libuct.so.0(uct_tcp_iface_progress+0x7d) [0x7fc07529162d]
10  /opt/conda/envs/gdf/lib/libucp.so.0(ucp_worker_progress+0x5a) [0x7fc07534ac4a]
11  /opt/conda/envs/gdf/lib/python3.9/site-packages/ucp/_libs/ucx_api.cpython-39-x86_64-linux-gnu.so(+0x2b17a) [0x7fc0753f517a]
12  /opt/conda/envs/gdf/bin/python(+0x13eb08) [0x55e744d55b08]
13  /opt/conda/envs/gdf/bin/python(_PyEval_EvalFrameDefault+0x5f82) [0x55e744d46112]
14  /opt/conda/envs/gdf/bin/python(+0x12827a) [0x55e744d3f27a]
15  /opt/conda/envs/gdf/bin/python(_PyFunction_Vectorcall+0xd5) [0x55e744d50c05]
16  /opt/conda/envs/gdf/bin/python(_PyEval_EvalFrameDefault+0x68b) [0x55e744d4081b]
17  /opt/conda/envs/gdf/bin/python(+0x14e70e) [0x55e744d6570e]
18  /opt/conda/envs/gdf/lib/python3.9/lib-dynload/_asyncio.cpython-39-x86_64-linux-gnu.so(+0x82fe) [0x7fc10c0122fe]
19  /opt/conda/envs/gdf/bin/python(_PyObject_MakeTpCall+0x2fc) [0x55e744d492bc]
20  /opt/conda/envs/gdf/bin/python(+0xe5817) [0x55e744cfc817]
21  /opt/conda/envs/gdf/bin/python(+0x130f83) [0x55e744d47f83]
22  /opt/conda/envs/gdf/bin/python(_PyEval_EvalFrameDefault+0x5ba6) [0x55e744d45d36]
23  /opt/conda/envs/gdf/bin/python(+0x139ef3) [0x55e744d50ef3]
24  /opt/conda/envs/gdf/bin/python(_PyEval_EvalFrameDefault+0x68b) [0x55e744d4081b]
25  /opt/conda/envs/gdf/bin/python(+0x139ef3) [0x55e744d50ef3]
26  /opt/conda/envs/gdf/bin/python(_PyEval_EvalFrameDefault+0x68b) [0x55e744d4081b]
27  /opt/conda/envs/gdf/bin/python(+0x139ef3) [0x55e744d50ef3]
28  /opt/conda/envs/gdf/bin/python(_PyEval_EvalFrameDefault+0x68b) [0x55e744d4081b]
29  /opt/conda/envs/gdf/bin/python(+0x139ef3) [0x55e744d50ef3]
30  /opt/conda/envs/gdf/bin/python(_PyEval_EvalFrameDefault+0x68b) [0x55e744d4081b]
31  /opt/conda/envs/gdf/bin/python(+0x12827a) [0x55e744d3f27a]
32  /opt/conda/envs/gdf/bin/python(_PyFunction_Vectorcall+0xd5) [0x55e744d50c05]
33  /opt/conda/envs/gdf/bin/python(_PyEval_EvalFrameDefault+0x4e17) [0x55e744d44fa7]
34  /opt/conda/envs/gdf/bin/python(+0x12827a) [0x55e744d3f27a]
35  /opt/conda/envs/gdf/bin/python(+0x147935) [0x55e744d5e935]
36  /opt/conda/envs/gdf/bin/python(PyObject_Call+0xb4) [0x55e744d5f104]
37  /opt/conda/envs/gdf/bin/python(+0x20efc8) [0x55e744e25fc8]
38  /opt/conda/envs/gdf/bin/python(_PyObject_MakeTpCall+0x2fc) [0x55e744d492bc]
39  /opt/conda/envs/gdf/bin/python(_PyEval_EvalFrameDefault+0x402b) [0x55e744d441bb]
40  /opt/conda/envs/gdf/bin/python(+0x139ef3) [0x55e744d50ef3]
41  /opt/conda/envs/gdf/bin/python(+0x147c72) [0x55e744d5ec72]
42  /opt/conda/envs/gdf/bin/python(_PyEval_EvalFrameDefault+0x402b) [0x55e744d441bb]
43  /opt/conda/envs/gdf/bin/python(+0x139ef3) [0x55e744d50ef3]
44  /opt/conda/envs/gdf/bin/python(_PyEval_EvalFrameDefault+0x68b) [0x55e744d4081b]
45  /opt/conda/envs/gdf/bin/python(+0x12827a) [0x55e744d3f27a]
46  /opt/conda/envs/gdf/bin/python(_PyFunction_Vectorcall+0xd5) [0x55e744d50c05]
47  /opt/conda/envs/gdf/bin/python(_PyEval_EvalFrameDefault+0x68b) [0x55e744d4081b]
48  /opt/conda/envs/gdf/bin/python(+0x139ef3) [0x55e744d50ef3]
49  /opt/conda/envs/gdf/bin/python(_PyEval_EvalFrameDefault+0x3d8) [0x55e744d40568]
50  /opt/conda/envs/gdf/bin/python(+0x12827a) [0x55e744d3f27a]
51  /opt/conda/envs/gdf/bin/python(_PyFunction_Vectorcall+0xd5) [0x55e744d50c05]
52  /opt/conda/envs/gdf/bin/python(_PyEval_EvalFrameDefault+0x123b) [0x55e744d413cb]
53  /opt/conda/envs/gdf/bin/python(+0x12827a) [0x55e744d3f27a]
54  /opt/conda/envs/gdf/bin/python(_PyEval_EvalCodeWithName+0x47) [0x55e744d3ef07]
55  /opt/conda/envs/gdf/bin/python(PyEval_EvalCodeEx+0x39) [0x55e744d3eeb9]
56  /opt/conda/envs/gdf/bin/python(PyEval_EvalCode+0x1b) [0x55e744def8bb]
57  /opt/conda/envs/gdf/bin/python(+0x206adc) [0x55e744e1dadc]
58  /opt/conda/envs/gdf/bin/python(+0x202c24) [0x55e744e19c24]
59  /opt/conda/envs/gdf/bin/python(PyRun_StringFlags+0x9d) [0x55e744e117ed]
60  /opt/conda/envs/gdf/bin/python(PyRun_SimpleStringFlags+0x3d) [0x55e744e116bd]
61  /opt/conda/envs/gdf/bin/python(Py_RunMain+0x262) [0x55e744e108a2]
=================================
[dgx13:63503:0:63503] Caught signal 11 (Segmentation fault: address not mapped to object at address 0x448)
==== backtrace (tid:  63503) ====
 0  /opt/conda/envs/gdf/lib/libucs.so.0(ucs_handle_error+0x2fd) [0x7fe34998af1d]
 1  /opt/conda/envs/gdf/lib/libucs.so.0(+0x29114) [0x7fe34998b114]
 2  /opt/conda/envs/gdf/lib/libucs.so.0(+0x292da) [0x7fe34998b2da]
 3  /usr/lib/x86_64-linux-gnu/libpthread.so.0(+0x14420) [0x7fe3ed21f420]
 4  /opt/conda/envs/gdf/lib/libucp.so.0(ucp_mem_type_unpack+0x14) [0x7fe349a045d4]
 5  /opt/conda/envs/gdf/lib/libucp.so.0(ucp_rndv_data_handler+0x4e9) [0x7fe349a29859]
 6  /opt/conda/envs/gdf/lib/libuct.so.0(+0x2042f) [0x7fe34994642f]
 7  /opt/conda/envs/gdf/lib/libuct.so.0(+0x23798) [0x7fe349949798]
 8  /opt/conda/envs/gdf/lib/libucs.so.0(ucs_event_set_wait+0xb9) [0x7fe349993989]
 9  /opt/conda/envs/gdf/lib/libuct.so.0(uct_tcp_iface_progress+0x7d) [0x7fe34994862d]
10  /opt/conda/envs/gdf/lib/libucp.so.0(ucp_worker_progress+0x5a) [0x7fe349a01c4a]
11  /opt/conda/envs/gdf/lib/python3.9/site-packages/ucp/_libs/ucx_api.cpython-39-x86_64-linux-gnu.so(+0x2b17a) [0x7fe349aac17a]
12  /opt/conda/envs/gdf/bin/python(+0x13eb08) [0x55b9467e3b08]
13  /opt/conda/envs/gdf/bin/python(_PyEval_EvalFrameDefault+0x5f82) [0x55b9467d4112]
14  /opt/conda/envs/gdf/bin/python(+0x12827a) [0x55b9467cd27a]
15  /opt/conda/envs/gdf/bin/python(_PyFunction_Vectorcall+0xd5) [0x55b9467dec05]
16  /opt/conda/envs/gdf/bin/python(_PyEval_EvalFrameDefault+0x68b) [0x55b9467ce81b]
17  /opt/conda/envs/gdf/bin/python(+0x14e70e) [0x55b9467f370e]
18  /opt/conda/envs/gdf/lib/python3.9/lib-dynload/_asyncio.cpython-39-x86_64-linux-gnu.so(+0x82fe) [0x7fe3e010c2fe]
19  /opt/conda/envs/gdf/bin/python(_PyObject_MakeTpCall+0x2fc) [0x55b9467d72bc]
20  /opt/conda/envs/gdf/bin/python(+0xe5817) [0x55b94678a817]
21  /opt/conda/envs/gdf/bin/python(+0x130f83) [0x55b9467d5f83]
22  /opt/conda/envs/gdf/bin/python(_PyEval_EvalFrameDefault+0x5ba6) [0x55b9467d3d36]
23  /opt/conda/envs/gdf/bin/python(+0x139ef3) [0x55b9467deef3]
24  /opt/conda/envs/gdf/bin/python(_PyEval_EvalFrameDefault+0x68b) [0x55b9467ce81b]
25  /opt/conda/envs/gdf/bin/python(+0x139ef3) [0x55b9467deef3]
26  /opt/conda/envs/gdf/bin/python(_PyEval_EvalFrameDefault+0x68b) [0x55b9467ce81b]
27  /opt/conda/envs/gdf/bin/python(+0x139ef3) [0x55b9467deef3]
28  /opt/conda/envs/gdf/bin/python(_PyEval_EvalFrameDefault+0x68b) [0x55b9467ce81b]
29  /opt/conda/envs/gdf/bin/python(+0x139ef3) [0x55b9467deef3]
30  /opt/conda/envs/gdf/bin/python(_PyEval_EvalFrameDefault+0x68b) [0x55b9467ce81b]
31  /opt/conda/envs/gdf/bin/python(+0x12827a) [0x55b9467cd27a]
32  /opt/conda/envs/gdf/bin/python(_PyFunction_Vectorcall+0xd5) [0x55b9467dec05]
33  /opt/conda/envs/gdf/bin/python(_PyEval_EvalFrameDefault+0x4e17) [0x55b9467d2fa7]
34  /opt/conda/envs/gdf/bin/python(+0x12827a) [0x55b9467cd27a]
35  /opt/conda/envs/gdf/bin/python(+0x147935) [0x55b9467ec935]
36  /opt/conda/envs/gdf/bin/python(PyObject_Call+0xb4) [0x55b9467ed104]
37  /opt/conda/envs/gdf/bin/python(+0x20efc8) [0x55b9468b3fc8]
38  /opt/conda/envs/gdf/bin/python(_PyObject_MakeTpCall+0x2fc) [0x55b9467d72bc]
39  /opt/conda/envs/gdf/bin/python(_PyEval_EvalFrameDefault+0x402b) [0x55b9467d21bb]
40  /opt/conda/envs/gdf/bin/python(+0x139ef3) [0x55b9467deef3]
41  /opt/conda/envs/gdf/bin/python(+0x147c72) [0x55b9467ecc72]
42  /opt/conda/envs/gdf/bin/python(_PyEval_EvalFrameDefault+0x402b) [0x55b9467d21bb]
43  /opt/conda/envs/gdf/bin/python(+0x139ef3) [0x55b9467deef3]
44  /opt/conda/envs/gdf/bin/python(_PyEval_EvalFrameDefault+0x68b) [0x55b9467ce81b]
45  /opt/conda/envs/gdf/bin/python(+0x12827a) [0x55b9467cd27a]
46  /opt/conda/envs/gdf/bin/python(_PyFunction_Vectorcall+0xd5) [0x55b9467dec05]
47  /opt/conda/envs/gdf/bin/python(_PyEval_EvalFrameDefault+0x68b) [0x55b9467ce81b]
48  /opt/conda/envs/gdf/bin/python(+0x139ef3) [0x55b9467deef3]
49  /opt/conda/envs/gdf/bin/python(_PyEval_EvalFrameDefault+0x3d8) [0x55b9467ce568]
50  /opt/conda/envs/gdf/bin/python(+0x12827a) [0x55b9467cd27a]
51  /opt/conda/envs/gdf/bin/python(_PyFunction_Vectorcall+0xd5) [0x55b9467dec05]
52  /opt/conda/envs/gdf/bin/python(_PyEval_EvalFrameDefault+0x123b) [0x55b9467cf3cb]
53  /opt/conda/envs/gdf/bin/python(+0x12827a) [0x55b9467cd27a]
54  /opt/conda/envs/gdf/bin/python(_PyEval_EvalCodeWithName+0x47) [0x55b9467ccf07]
55  /opt/conda/envs/gdf/bin/python(PyEval_EvalCodeEx+0x39) [0x55b9467cceb9]
56  /opt/conda/envs/gdf/bin/python(PyEval_EvalCode+0x1b) [0x55b94687d8bb]
57  /opt/conda/envs/gdf/bin/python(+0x206adc) [0x55b9468abadc]
58  /opt/conda/envs/gdf/bin/python(+0x202c24) [0x55b9468a7c24]
59  /opt/conda/envs/gdf/bin/python(PyRun_StringFlags+0x9d) [0x55b94689f7ed]
60  /opt/conda/envs/gdf/bin/python(PyRun_SimpleStringFlags+0x3d) [0x55b94689f6bd]
61  /opt/conda/envs/gdf/bin/python(Py_RunMain+0x262) [0x55b94689e8a2]
=================================
[dgx13:63492:0:63492] Caught signal 11 (Segmentation fault: address not mapped to object at address 0x448)
==== backtrace (tid:  63492) ====
 0  /opt/conda/envs/gdf/lib/libucs.so.0(ucs_handle_error+0x2fd) [0x7f9d603fbf1d]
 1  /opt/conda/envs/gdf/lib/libucs.so.0(+0x29114) [0x7f9d603fc114]
 2  /opt/conda/envs/gdf/lib/libucs.so.0(+0x292da) [0x7f9d603fc2da]
 3  /usr/lib/x86_64-linux-gnu/libpthread.so.0(+0x14420) [0x7f9df1c6c420]
 4  /opt/conda/envs/gdf/lib/libucp.so.0(ucp_mem_type_unpack+0x14) [0x7f9d604755d4]
 5  /opt/conda/envs/gdf/lib/libucp.so.0(ucp_rndv_data_handler+0x4e9) [0x7f9d6049a859]
 6  /opt/conda/envs/gdf/lib/libuct.so.0(+0x2042f) [0x7f9d603b742f]
 7  /opt/conda/envs/gdf/lib/libuct.so.0(+0x23798) [0x7f9d603ba798]
 8  /opt/conda/envs/gdf/lib/libucs.so.0(ucs_event_set_wait+0xb9) [0x7f9d60404989]
 9  /opt/conda/envs/gdf/lib/libuct.so.0(uct_tcp_iface_progress+0x7d) [0x7f9d603b962d]
10  /opt/conda/envs/gdf/lib/libucp.so.0(ucp_worker_progress+0x5a) [0x7f9d60472c4a]
11  /opt/conda/envs/gdf/lib/python3.9/site-packages/ucp/_libs/ucx_api.cpython-39-x86_64-linux-gnu.so(+0x2b17a) [0x7f9d6051d17a]
12  /opt/conda/envs/gdf/bin/python(+0x13eb08) [0x5589a8bfab08]
13  /opt/conda/envs/gdf/bin/python(_PyEval_EvalFrameDefault+0x5f82) [0x5589a8beb112]
14  /opt/conda/envs/gdf/bin/python(+0x12827a) [0x5589a8be427a]
15  /opt/conda/envs/gdf/bin/python(_PyFunction_Vectorcall+0xd5) [0x5589a8bf5c05]
16  /opt/conda/envs/gdf/bin/python(_PyEval_EvalFrameDefault+0x68b) [0x5589a8be581b]
17  /opt/conda/envs/gdf/bin/python(+0x14e70e) [0x5589a8c0a70e]
18  /opt/conda/envs/gdf/lib/python3.9/lib-dynload/_asyncio.cpython-39-x86_64-linux-gnu.so(+0x82fe) [0x7f9d727e12fe]
19  /opt/conda/envs/gdf/bin/python(_PyObject_MakeTpCall+0x2fc) [0x5589a8bee2bc]
20  /opt/conda/envs/gdf/bin/python(+0xe5817) [0x5589a8ba1817]
21  /opt/conda/envs/gdf/bin/python(+0x130f83) [0x5589a8becf83]
22  /opt/conda/envs/gdf/bin/python(_PyEval_EvalFrameDefault+0x5ba6) [0x5589a8bead36]
23  /opt/conda/envs/gdf/bin/python(+0x139ef3) [0x5589a8bf5ef3]
24  /opt/conda/envs/gdf/bin/python(_PyEval_EvalFrameDefault+0x68b) [0x5589a8be581b]
25  /opt/conda/envs/gdf/bin/python(+0x139ef3) [0x5589a8bf5ef3]
26  /opt/conda/envs/gdf/bin/python(_PyEval_EvalFrameDefault+0x68b) [0x5589a8be581b]
27  /opt/conda/envs/gdf/bin/python(+0x139ef3) [0x5589a8bf5ef3]
28  /opt/conda/envs/gdf/bin/python(_PyEval_EvalFrameDefault+0x68b) [0x5589a8be581b]
29  /opt/conda/envs/gdf/bin/python(+0x139ef3) [0x5589a8bf5ef3]
30  /opt/conda/envs/gdf/bin/python(_PyEval_EvalFrameDefault+0x68b) [0x5589a8be581b]
31  /opt/conda/envs/gdf/bin/python(+0x12827a) [0x5589a8be427a]
32  /opt/conda/envs/gdf/bin/python(_PyFunction_Vectorcall+0xd5) [0x5589a8bf5c05]
33  /opt/conda/envs/gdf/bin/python(_PyEval_EvalFrameDefault+0x4e17) [0x5589a8be9fa7]
34  /opt/conda/envs/gdf/bin/python(+0x12827a) [0x5589a8be427a]
35  /opt/conda/envs/gdf/bin/python(+0x147935) [0x5589a8c03935]
36  /opt/conda/envs/gdf/bin/python(PyObject_Call+0xb4) [0x5589a8c04104]
37  /opt/conda/envs/gdf/bin/python(+0x20efc8) [0x5589a8ccafc8]
38  /opt/conda/envs/gdf/bin/python(_PyObject_MakeTpCall+0x2fc) [0x5589a8bee2bc]
39  /opt/conda/envs/gdf/bin/python(_PyEval_EvalFrameDefault+0x402b) [0x5589a8be91bb]
40  /opt/conda/envs/gdf/bin/python(+0x139ef3) [0x5589a8bf5ef3]
41  /opt/conda/envs/gdf/bin/python(+0x147c72) [0x5589a8c03c72]
42  /opt/conda/envs/gdf/bin/python(_PyEval_EvalFrameDefault+0x402b) [0x5589a8be91bb]
43  /opt/conda/envs/gdf/bin/python(+0x139ef3) [0x5589a8bf5ef3]
44  /opt/conda/envs/gdf/bin/python(_PyEval_EvalFrameDefault+0x68b) [0x5589a8be581b]
45  /opt/conda/envs/gdf/bin/python(+0x12827a) [0x5589a8be427a]
46  /opt/conda/envs/gdf/bin/python(_PyFunction_Vectorcall+0xd5) [0x5589a8bf5c05]
47  /opt/conda/envs/gdf/bin/python(_PyEval_EvalFrameDefault+0x68b) [0x5589a8be581b]
48  /opt/conda/envs/gdf/bin/python(+0x139ef3) [0x5589a8bf5ef3]
49  /opt/conda/envs/gdf/bin/python(_PyEval_EvalFrameDefault+0x3d8) [0x5589a8be5568]
50  /opt/conda/envs/gdf/bin/python(+0x12827a) [0x5589a8be427a]
51  /opt/conda/envs/gdf/bin/python(_PyFunction_Vectorcall+0xd5) [0x5589a8bf5c05]
52  /opt/conda/envs/gdf/bin/python(_PyEval_EvalFrameDefault+0x123b) [0x5589a8be63cb]
53  /opt/conda/envs/gdf/bin/python(+0x12827a) [0x5589a8be427a]
54  /opt/conda/envs/gdf/bin/python(_PyEval_EvalCodeWithName+0x47) [0x5589a8be3f07]
55  /opt/conda/envs/gdf/bin/python(PyEval_EvalCodeEx+0x39) [0x5589a8be3eb9]
56  /opt/conda/envs/gdf/bin/python(PyEval_EvalCode+0x1b) [0x5589a8c948bb]
57  /opt/conda/envs/gdf/bin/python(+0x206adc) [0x5589a8cc2adc]
58  /opt/conda/envs/gdf/bin/python(+0x202c24) [0x5589a8cbec24]
59  /opt/conda/envs/gdf/bin/python(PyRun_StringFlags+0x9d) [0x5589a8cb67ed]
60  /opt/conda/envs/gdf/bin/python(PyRun_SimpleStringFlags+0x3d) [0x5589a8cb66bd]
61  /opt/conda/envs/gdf/bin/python(Py_RunMain+0x262) [0x5589a8cb58a2]
=================================
[dgx13:63487:0:63487] Caught signal 11 (Segmentation fault: address not mapped to object at address 0x448)
==== backtrace (tid:  63487) ====
 0  /opt/conda/envs/gdf/lib/libucs.so.0(ucs_handle_error+0x2fd) [0x7f2438ed3f1d]
 1  /opt/conda/envs/gdf/lib/libucs.so.0(+0x29114) [0x7f2438ed4114]
 2  /opt/conda/envs/gdf/lib/libucs.so.0(+0x292da) [0x7f2438ed42da]
 3  /usr/lib/x86_64-linux-gnu/libpthread.so.0(+0x14420) [0x7f24d8765420]
 4  /opt/conda/envs/gdf/lib/libucp.so.0(ucp_mem_type_unpack+0x14) [0x7f2438f4d5d4]
 5  /opt/conda/envs/gdf/lib/libucp.so.0(ucp_rndv_data_handler+0x4e9) [0x7f2438f72859]
 6  /opt/conda/envs/gdf/lib/libuct.so.0(+0x2042f) [0x7f2438e8f42f]
 7  /opt/conda/envs/gdf/lib/libuct.so.0(+0x23798) [0x7f2438e92798]
 8  /opt/conda/envs/gdf/lib/libucs.so.0(ucs_event_set_wait+0xb9) [0x7f2438edc989]
 9  /opt/conda/envs/gdf/lib/libuct.so.0(uct_tcp_iface_progress+0x7d) [0x7f2438e9162d]
10  /opt/conda/envs/gdf/lib/libucp.so.0(ucp_worker_progress+0x5a) [0x7f2438f4ac4a]
11  /opt/conda/envs/gdf/lib/python3.9/site-packages/ucp/_libs/ucx_api.cpython-39-x86_64-linux-gnu.so(+0x2b17a) [0x7f2438ff517a]
12  /opt/conda/envs/gdf/bin/python(+0x13eb08) [0x5618b1097b08]
13  /opt/conda/envs/gdf/bin/python(_PyEval_EvalFrameDefault+0x5f82) [0x5618b1088112]
14  /opt/conda/envs/gdf/bin/python(+0x12827a) [0x5618b108127a]
15  /opt/conda/envs/gdf/bin/python(_PyFunction_Vectorcall+0xd5) [0x5618b1092c05]
16  /opt/conda/envs/gdf/bin/python(_PyEval_EvalFrameDefault+0x68b) [0x5618b108281b]
17  /opt/conda/envs/gdf/bin/python(+0x139ef3) [0x5618b1092ef3]
18  /opt/conda/envs/gdf/bin/python(+0x147a16) [0x5618b10a0a16]
19  /opt/conda/envs/gdf/bin/python(+0x2579b1) [0x5618b11b09b1]
20  /opt/conda/envs/gdf/bin/python(+0xe5817) [0x5618b103e817]
21  /opt/conda/envs/gdf/bin/python(+0x130f83) [0x5618b1089f83]
22  /opt/conda/envs/gdf/bin/python(_PyEval_EvalFrameDefault+0x5ba6) [0x5618b1087d36]
23  /opt/conda/envs/gdf/bin/python(+0x139ef3) [0x5618b1092ef3]
24  /opt/conda/envs/gdf/bin/python(_PyEval_EvalFrameDefault+0x68b) [0x5618b108281b]
25  /opt/conda/envs/gdf/bin/python(+0x139ef3) [0x5618b1092ef3]
26  /opt/conda/envs/gdf/bin/python(_PyEval_EvalFrameDefault+0x68b) [0x5618b108281b]
27  /opt/conda/envs/gdf/bin/python(+0x139ef3) [0x5618b1092ef3]
28  /opt/conda/envs/gdf/bin/python(_PyEval_EvalFrameDefault+0x68b) [0x5618b108281b]
29  /opt/conda/envs/gdf/bin/python(+0x139ef3) [0x5618b1092ef3]
30  /opt/conda/envs/gdf/bin/python(_PyEval_EvalFrameDefault+0x68b) [0x5618b108281b]
31  /opt/conda/envs/gdf/bin/python(+0x12827a) [0x5618b108127a]
32  /opt/conda/envs/gdf/bin/python(_PyFunction_Vectorcall+0xd5) [0x5618b1092c05]
33  /opt/conda/envs/gdf/bin/python(_PyEval_EvalFrameDefault+0x4e17) [0x5618b1086fa7]
34  /opt/conda/envs/gdf/bin/python(+0x12827a) [0x5618b108127a]
35  /opt/conda/envs/gdf/bin/python(+0x147935) [0x5618b10a0935]
36  /opt/conda/envs/gdf/bin/python(PyObject_Call+0xb4) [0x5618b10a1104]
37  /opt/conda/envs/gdf/bin/python(+0x20efc8) [0x5618b1167fc8]
38  /opt/conda/envs/gdf/bin/python(_PyObject_MakeTpCall+0x2fc) [0x5618b108b2bc]
39  /opt/conda/envs/gdf/bin/python(_PyEval_EvalFrameDefault+0x402b) [0x5618b10861bb]
40  /opt/conda/envs/gdf/bin/python(+0x139ef3) [0x5618b1092ef3]
41  /opt/conda/envs/gdf/bin/python(+0x147c72) [0x5618b10a0c72]
42  /opt/conda/envs/gdf/bin/python(_PyEval_EvalFrameDefault+0x402b) [0x5618b10861bb]
43  /opt/conda/envs/gdf/bin/python(+0x139ef3) [0x5618b1092ef3]
44  /opt/conda/envs/gdf/bin/python(_PyEval_EvalFrameDefault+0x68b) [0x5618b108281b]
45  /opt/conda/envs/gdf/bin/python(+0x12827a) [0x5618b108127a]
46  /opt/conda/envs/gdf/bin/python(_PyFunction_Vectorcall+0xd5) [0x5618b1092c05]
47  /opt/conda/envs/gdf/bin/python(_PyEval_EvalFrameDefault+0x68b) [0x5618b108281b]
48  /opt/conda/envs/gdf/bin/python(+0x139ef3) [0x5618b1092ef3]
49  /opt/conda/envs/gdf/bin/python(_PyEval_EvalFrameDefault+0x3d8) [0x5618b1082568]
50  /opt/conda/envs/gdf/bin/python(+0x12827a) [0x5618b108127a]
51  /opt/conda/envs/gdf/bin/python(_PyFunction_Vectorcall+0xd5) [0x5618b1092c05]
52  /opt/conda/envs/gdf/bin/python(_PyEval_EvalFrameDefault+0x123b) [0x5618b10833cb]
53  /opt/conda/envs/gdf/bin/python(+0x12827a) [0x5618b108127a]
54  /opt/conda/envs/gdf/bin/python(_PyEval_EvalCodeWithName+0x47) [0x5618b1080f07]
55  /opt/conda/envs/gdf/bin/python(PyEval_EvalCodeEx+0x39) [0x5618b1080eb9]
56  /opt/conda/envs/gdf/bin/python(PyEval_EvalCode+0x1b) [0x5618b11318bb]
57  /opt/conda/envs/gdf/bin/python(+0x206adc) [0x5618b115fadc]
58  /opt/conda/envs/gdf/bin/python(+0x202c24) [0x5618b115bc24]
59  /opt/conda/envs/gdf/bin/python(PyRun_StringFlags+0x9d) [0x5618b11537ed]
60  /opt/conda/envs/gdf/bin/python(PyRun_SimpleStringFlags+0x3d) [0x5618b11536bd]
61  /opt/conda/envs/gdf/bin/python(Py_RunMain+0x262) [0x5618b11528a2]
=================================
Task exception was never retrieved
future: <Task finished name='Task-1226' coro=<_listener_handler_coroutine() done, defined at /opt/conda/envs/gdf/lib/python3.9/site-packages/ucp/core.py:128> exception=UCXError('<stream_recv>: Connection reset by remote peer')>
Traceback (most recent call last):
  File "/opt/conda/envs/gdf/lib/python3.9/site-packages/ucp/core.py", line 143, in _listener_handler_coroutine
    peer_info = await exchange_peer_info(
  File "/opt/conda/envs/gdf/lib/python3.9/site-packages/ucp/core.py", line 52, in exchange_peer_info
    await comm.stream_recv(endpoint, peer_info_arr, peer_info_arr.nbytes)
ucp._libs.exceptions.UCXError: <stream_recv>: Connection reset by remote peer
2023-08-07 06:54:11,182 - distributed.worker - ERROR - Worker stream died during communication: ucx://127.0.0.1:47429
Traceback (most recent call last):
  File "/opt/conda/envs/gdf/lib/python3.9/site-packages/distributed/comm/ucx.py", line 349, in read
    await self.ep.recv(msg)
  File "/opt/conda/envs/gdf/lib/python3.9/site-packages/ucp/core.py", line 725, in recv
    ret = await comm.tag_recv(self._ep, buffer, nbytes, tag, name=log)
ucp._libs.exceptions.UCXCanceled: <[Recv #000] ep: 0x7fa4d30cc240, tag: 0x2011477d0c05fddc, nbytes: 16, type: <class 'numpy.ndarray'>>: 

During handling of the above exception, another exception occurred:

Traceback (most recent call last):
  File "/opt/conda/envs/gdf/lib/python3.9/site-packages/distributed/comm/core.py", line 329, in connect
    handshake = await wait_for(comm.read(), time_left())
  File "/opt/conda/envs/gdf/lib/python3.9/site-packages/distributed/utils.py", line 1849, in wait_for
    return await asyncio.wait_for(fut, timeout)
  File "/opt/conda/envs/gdf/lib/python3.9/asyncio/tasks.py", line 479, in wait_for
    return fut.result()
  File "/opt/conda/envs/gdf/lib/python3.9/site-packages/distributed/utils.py", line 752, in wrapper
    return await func(*args, **kwargs)
  File "/opt/conda/envs/gdf/lib/python3.9/site-packages/distributed/comm/ucx.py", line 367, in read
    raise CommClosedError(
distributed.comm.core.CommClosedError: Connection closed by writer.
Inner exception: UCXCanceled("<[Recv #000] ep: 0x7fa4d30cc240, tag: 0x2011477d0c05fddc, nbytes: 16, type: <class 'numpy.ndarray'>>: ")

The above exception was the direct cause of the following exception:

Traceback (most recent call last):
  File "/opt/conda/envs/gdf/lib/python3.9/site-packages/distributed/worker.py", line 2066, in gather_dep
    response = await get_data_from_worker(
  File "/opt/conda/envs/gdf/lib/python3.9/site-packages/distributed/worker.py", line 2889, in get_data_from_worker
    comm = await rpc.connect(worker)
  File "/opt/conda/envs/gdf/lib/python3.9/site-packages/distributed/core.py", line 1506, in connect
    return await connect_attempt
  File "/opt/conda/envs/gdf/lib/python3.9/site-packages/distributed/core.py", line 1427, in _connect
    comm = await connect(
  File "/opt/conda/envs/gdf/lib/python3.9/site-packages/distributed/comm/core.py", line 334, in connect
    raise OSError(
OSError: Timed out during handshake while connecting to ucx://127.0.0.1:47429 after 30 s
2023-08-07 06:54:11,182 - distributed.worker - ERROR - Worker stream died during communication: ucx://127.0.0.1:47429
Traceback (most recent call last):
  File "/opt/conda/envs/gdf/lib/python3.9/site-packages/distributed/comm/ucx.py", line 349, in read
    await self.ep.recv(msg)
  File "/opt/conda/envs/gdf/lib/python3.9/site-packages/ucp/core.py", line 725, in recv
    ret = await comm.tag_recv(self._ep, buffer, nbytes, tag, name=log)
ucp._libs.exceptions.UCXCanceled: <[Recv #000] ep: 0x7f83cd28a240, tag: 0xcb8959d016c52deb, nbytes: 16, type: <class 'numpy.ndarray'>>: 

During handling of the above exception, another exception occurred:

Traceback (most recent call last):
  File "/opt/conda/envs/gdf/lib/python3.9/site-packages/distributed/comm/core.py", line 329, in connect
    handshake = await wait_for(comm.read(), time_left())
  File "/opt/conda/envs/gdf/lib/python3.9/site-packages/distributed/utils.py", line 1849, in wait_for
    return await asyncio.wait_for(fut, timeout)
  File "/opt/conda/envs/gdf/lib/python3.9/asyncio/tasks.py", line 479, in wait_for
    return fut.result()
  File "/opt/conda/envs/gdf/lib/python3.9/site-packages/distributed/utils.py", line 752, in wrapper
    return await func(*args, **kwargs)
  File "/opt/conda/envs/gdf/lib/python3.9/site-packages/distributed/comm/ucx.py", line 367, in read
    raise CommClosedError(
distributed.comm.core.CommClosedError: Connection closed by writer.
Inner exception: UCXCanceled("<[Recv #000] ep: 0x7f83cd28a240, tag: 0xcb8959d016c52deb, nbytes: 16, type: <class 'numpy.ndarray'>>: ")

The above exception was the direct cause of the following exception:

Traceback (most recent call last):
  File "/opt/conda/envs/gdf/lib/python3.9/site-packages/distributed/worker.py", line 2066, in gather_dep
    response = await get_data_from_worker(
  File "/opt/conda/envs/gdf/lib/python3.9/site-packages/distributed/worker.py", line 2889, in get_data_from_worker
    comm = await rpc.connect(worker)
  File "/opt/conda/envs/gdf/lib/python3.9/site-packages/distributed/core.py", line 1506, in connect
    return await connect_attempt
  File "/opt/conda/envs/gdf/lib/python3.9/site-packages/distributed/core.py", line 1427, in _connect
    comm = await connect(
  File "/opt/conda/envs/gdf/lib/python3.9/site-packages/distributed/comm/core.py", line 334, in connect
    raise OSError(
OSError: Timed out during handshake while connecting to ucx://127.0.0.1:47429 after 30 s
2023-08-07 06:54:11,191 - distributed.worker - ERROR - Worker stream died during communication: ucx://127.0.0.1:42065
Traceback (most recent call last):
  File "/opt/conda/envs/gdf/lib/python3.9/site-packages/distributed/comm/ucx.py", line 349, in read
    await self.ep.recv(msg)
  File "/opt/conda/envs/gdf/lib/python3.9/site-packages/ucp/core.py", line 725, in recv
    ret = await comm.tag_recv(self._ep, buffer, nbytes, tag, name=log)
ucp._libs.exceptions.UCXCanceled: <[Recv #003] ep: 0x7fa4d30cc200, tag: 0x49e6c28138419190, nbytes: 16, type: <class 'numpy.ndarray'>>: 

During handling of the above exception, another exception occurred:

Traceback (most recent call last):
  File "/opt/conda/envs/gdf/lib/python3.9/site-packages/distributed/worker.py", line 2066, in gather_dep
    response = await get_data_from_worker(
  File "/opt/conda/envs/gdf/lib/python3.9/site-packages/distributed/worker.py", line 2892, in get_data_from_worker
    response = await send_recv(
  File "/opt/conda/envs/gdf/lib/python3.9/site-packages/distributed/core.py", line 1024, in send_recv
    response = await comm.read(deserializers=deserializers)
  File "/opt/conda/envs/gdf/lib/python3.9/site-packages/distributed/utils.py", line 752, in wrapper
    return await func(*args, **kwargs)
  File "/opt/conda/envs/gdf/lib/python3.9/site-packages/distributed/comm/ucx.py", line 367, in read
    raise CommClosedError(
distributed.comm.core.CommClosedError: Connection closed by writer.
Inner exception: UCXCanceled("<[Recv #003] ep: 0x7fa4d30cc200, tag: 0x49e6c28138419190, nbytes: 16, type: <class 'numpy.ndarray'>>: ")
2023-08-07 06:54:11,207 - distributed.worker - ERROR - failed during get data with ucx://127.0.0.1:52247 -> ucx://127.0.0.1:48221
Traceback (most recent call last):
  File "/opt/conda/envs/gdf/lib/python3.9/site-packages/distributed/comm/ucx.py", line 333, in write
    await self.ep.send(each_frame)
  File "/opt/conda/envs/gdf/lib/python3.9/site-packages/ucp/core.py", line 650, in send
    return await comm.tag_send(self._ep, buffer, nbytes, tag, name=log)
ucp._libs.exceptions.UCXError: <[Send #007] ep: 0x7fc57853f340, tag: 0x5b772b8d3a9de26f, nbytes: 100000000, type: <class 'cudf.core.buffer.buffer.Buffer'>>: Endpoint timeout

During handling of the above exception, another exception occurred:

Traceback (most recent call last):
  File "/opt/conda/envs/gdf/lib/python3.9/site-packages/distributed/worker.py", line 1792, in get_data
    compressed = await comm.write(msg, serializers=serializers)
  File "/opt/conda/envs/gdf/lib/python3.9/site-packages/distributed/utils.py", line 752, in wrapper
    return await func(*args, **kwargs)
  File "/opt/conda/envs/gdf/lib/python3.9/site-packages/distributed/comm/ucx.py", line 337, in write
    raise CommClosedError("While writing, the connection was closed")
distributed.comm.core.CommClosedError: While writing, the connection was closed
2023-08-07 06:54:11,210 - distributed.worker - ERROR - failed during get data with ucx://127.0.0.1:52247 -> ucx://127.0.0.1:47429
Traceback (most recent call last):
  File "/opt/conda/envs/gdf/lib/python3.9/site-packages/distributed/comm/ucx.py", line 333, in write
    await self.ep.send(each_frame)
  File "/opt/conda/envs/gdf/lib/python3.9/site-packages/ucp/core.py", line 650, in send
    return await comm.tag_send(self._ep, buffer, nbytes, tag, name=log)
ucp._libs.exceptions.UCXError: <[Send #007] ep: 0x7fc57853f2c0, tag: 0x45ef9800fe74868f, nbytes: 100000000, type: <class 'cudf.core.buffer.buffer.Buffer'>>: Connection reset by remote peer

During handling of the above exception, another exception occurred:

Traceback (most recent call last):
  File "/opt/conda/envs/gdf/lib/python3.9/site-packages/distributed/worker.py", line 1792, in get_data
    compressed = await comm.write(msg, serializers=serializers)
  File "/opt/conda/envs/gdf/lib/python3.9/site-packages/distributed/utils.py", line 752, in wrapper
    return await func(*args, **kwargs)
  File "/opt/conda/envs/gdf/lib/python3.9/site-packages/distributed/comm/ucx.py", line 337, in write
    raise CommClosedError("While writing, the connection was closed")
distributed.comm.core.CommClosedError: While writing, the connection was closed
2023-08-07 06:54:11,211 - distributed.worker - ERROR - Worker stream died during communication: ucx://127.0.0.1:42065
Traceback (most recent call last):
  File "/opt/conda/envs/gdf/lib/python3.9/site-packages/distributed/comm/ucx.py", line 349, in read
    await self.ep.recv(msg)
  File "/opt/conda/envs/gdf/lib/python3.9/site-packages/ucp/core.py", line 725, in recv
    ret = await comm.tag_recv(self._ep, buffer, nbytes, tag, name=log)
ucp._libs.exceptions.UCXCanceled: <[Recv #003] ep: 0x7ff6b49fb200, tag: 0x8e9e47799d3f2fc1, nbytes: 16, type: <class 'numpy.ndarray'>>: 

During handling of the above exception, another exception occurred:

Traceback (most recent call last):
  File "/opt/conda/envs/gdf/lib/python3.9/site-packages/distributed/worker.py", line 2066, in gather_dep
    response = await get_data_from_worker(
  File "/opt/conda/envs/gdf/lib/python3.9/site-packages/distributed/worker.py", line 2892, in get_data_from_worker
    response = await send_recv(
  File "/opt/conda/envs/gdf/lib/python3.9/site-packages/distributed/core.py", line 1024, in send_recv
    response = await comm.read(deserializers=deserializers)
  File "/opt/conda/envs/gdf/lib/python3.9/site-packages/distributed/utils.py", line 752, in wrapper
    return await func(*args, **kwargs)
  File "/opt/conda/envs/gdf/lib/python3.9/site-packages/distributed/comm/ucx.py", line 367, in read
    raise CommClosedError(
distributed.comm.core.CommClosedError: Connection closed by writer.
Inner exception: UCXCanceled("<[Recv #003] ep: 0x7ff6b49fb200, tag: 0x8e9e47799d3f2fc1, nbytes: 16, type: <class 'numpy.ndarray'>>: ")
2023-08-07 06:54:11,212 - distributed.worker - ERROR - failed during get data with ucx://127.0.0.1:52247 -> ucx://127.0.0.1:60337
Traceback (most recent call last):
  File "/opt/conda/envs/gdf/lib/python3.9/site-packages/distributed/comm/ucx.py", line 349, in read
    await self.ep.recv(msg)
  File "/opt/conda/envs/gdf/lib/python3.9/site-packages/ucp/core.py", line 725, in recv
    ret = await comm.tag_recv(self._ep, buffer, nbytes, tag, name=log)
ucp._libs.exceptions.UCXCanceled: <[Recv #006] ep: 0x7fc57853f300, tag: 0x11c7b35d1b39532, nbytes: 16, type: <class 'numpy.ndarray'>>: 

During handling of the above exception, another exception occurred:

Traceback (most recent call last):
  File "/opt/conda/envs/gdf/lib/python3.9/site-packages/distributed/worker.py", line 1793, in get_data
    response = await comm.read(deserializers=serializers)
  File "/opt/conda/envs/gdf/lib/python3.9/site-packages/distributed/utils.py", line 752, in wrapper
    return await func(*args, **kwargs)
  File "/opt/conda/envs/gdf/lib/python3.9/site-packages/distributed/comm/ucx.py", line 367, in read
    raise CommClosedError(
distributed.comm.core.CommClosedError: Connection closed by writer.
Inner exception: UCXCanceled("<[Recv #006] ep: 0x7fc57853f300, tag: 0x11c7b35d1b39532, nbytes: 16, type: <class 'numpy.ndarray'>>: ")
2023-08-07 06:54:11,212 - distributed.worker - ERROR - Worker stream died during communication: ucx://127.0.0.1:42065
Traceback (most recent call last):
  File "/opt/conda/envs/gdf/lib/python3.9/site-packages/distributed/comm/ucx.py", line 349, in read
    await self.ep.recv(msg)
  File "/opt/conda/envs/gdf/lib/python3.9/site-packages/ucp/core.py", line 725, in recv
    ret = await comm.tag_recv(self._ep, buffer, nbytes, tag, name=log)
ucp._libs.exceptions.UCXCanceled: <[Recv #003] ep: 0x7fc57853f1c0, tag: 0x7162bfe93cff8a85, nbytes: 16, type: <class 'numpy.ndarray'>>: 

During handling of the above exception, another exception occurred:

Traceback (most recent call last):
  File "/opt/conda/envs/gdf/lib/python3.9/site-packages/distributed/worker.py", line 2066, in gather_dep
    response = await get_data_from_worker(
  File "/opt/conda/envs/gdf/lib/python3.9/site-packages/distributed/worker.py", line 2892, in get_data_from_worker
    response = await send_recv(
  File "/opt/conda/envs/gdf/lib/python3.9/site-packages/distributed/core.py", line 1024, in send_recv
    response = await comm.read(deserializers=deserializers)
  File "/opt/conda/envs/gdf/lib/python3.9/site-packages/distributed/utils.py", line 752, in wrapper
    return await func(*args, **kwargs)
  File "/opt/conda/envs/gdf/lib/python3.9/site-packages/distributed/comm/ucx.py", line 367, in read
    raise CommClosedError(
distributed.comm.core.CommClosedError: Connection closed by writer.
Inner exception: UCXCanceled("<[Recv #003] ep: 0x7fc57853f1c0, tag: 0x7162bfe93cff8a85, nbytes: 16, type: <class 'numpy.ndarray'>>: ")
2023-08-07 06:54:11,213 - distributed.worker - ERROR - Worker stream died during communication: ucx://127.0.0.1:48221
Traceback (most recent call last):
  File "/opt/conda/envs/gdf/lib/python3.9/site-packages/distributed/comm/ucx.py", line 349, in read
    await self.ep.recv(msg)
  File "/opt/conda/envs/gdf/lib/python3.9/site-packages/ucp/core.py", line 725, in recv
    ret = await comm.tag_recv(self._ep, buffer, nbytes, tag, name=log)
ucp._libs.exceptions.UCXCanceled: <[Recv #003] ep: 0x7fc57853f140, tag: 0xc8120795465a5ec6, nbytes: 16, type: <class 'numpy.ndarray'>>: 

During handling of the above exception, another exception occurred:

Traceback (most recent call last):
  File "/opt/conda/envs/gdf/lib/python3.9/site-packages/distributed/worker.py", line 2066, in gather_dep
    response = await get_data_from_worker(
  File "/opt/conda/envs/gdf/lib/python3.9/site-packages/distributed/worker.py", line 2892, in get_data_from_worker
    response = await send_recv(
  File "/opt/conda/envs/gdf/lib/python3.9/site-packages/distributed/core.py", line 1024, in send_recv
    response = await comm.read(deserializers=deserializers)
  File "/opt/conda/envs/gdf/lib/python3.9/site-packages/distributed/utils.py", line 752, in wrapper
    return await func(*args, **kwargs)
  File "/opt/conda/envs/gdf/lib/python3.9/site-packages/distributed/comm/ucx.py", line 367, in read
    raise CommClosedError(
distributed.comm.core.CommClosedError: Connection closed by writer.
Inner exception: UCXCanceled("<[Recv #003] ep: 0x7fc57853f140, tag: 0xc8120795465a5ec6, nbytes: 16, type: <class 'numpy.ndarray'>>: ")
2023-08-07 06:54:11,214 - distributed.worker - ERROR - failed during get data with ucx://127.0.0.1:57107 -> ucx://127.0.0.1:48221
Traceback (most recent call last):
  File "/opt/conda/envs/gdf/lib/python3.9/site-packages/distributed/comm/ucx.py", line 333, in write
    await self.ep.send(each_frame)
  File "/opt/conda/envs/gdf/lib/python3.9/site-packages/ucp/core.py", line 650, in send
    return await comm.tag_send(self._ep, buffer, nbytes, tag, name=log)
ucp._libs.exceptions.UCXError: <[Send #007] ep: 0x7ff6b49fb380, tag: 0x3bd7a3866bedcdf6, nbytes: 100000000, type: <class 'cudf.core.buffer.buffer.Buffer'>>: Connection reset by remote peer

During handling of the above exception, another exception occurred:

Traceback (most recent call last):
  File "/opt/conda/envs/gdf/lib/python3.9/site-packages/distributed/worker.py", line 1792, in get_data
    compressed = await comm.write(msg, serializers=serializers)
  File "/opt/conda/envs/gdf/lib/python3.9/site-packages/distributed/utils.py", line 752, in wrapper
    return await func(*args, **kwargs)
  File "/opt/conda/envs/gdf/lib/python3.9/site-packages/distributed/comm/ucx.py", line 337, in write
    raise CommClosedError("While writing, the connection was closed")
distributed.comm.core.CommClosedError: While writing, the connection was closed
2023-08-07 06:54:11,214 - distributed.worker - ERROR - Worker stream died during communication: ucx://127.0.0.1:60337
Traceback (most recent call last):
  File "/opt/conda/envs/gdf/lib/python3.9/site-packages/distributed/comm/ucx.py", line 349, in read
    await self.ep.recv(msg)
  File "/opt/conda/envs/gdf/lib/python3.9/site-packages/ucp/core.py", line 725, in recv
    ret = await comm.tag_recv(self._ep, buffer, nbytes, tag, name=log)
ucp._libs.exceptions.UCXCanceled: <[Recv #003] ep: 0x7fc57853f240, tag: 0x47c2eb759b24fbcb, nbytes: 16, type: <class 'numpy.ndarray'>>: 

During handling of the above exception, another exception occurred:

Traceback (most recent call last):
  File "/opt/conda/envs/gdf/lib/python3.9/site-packages/distributed/worker.py", line 2066, in gather_dep
    response = await get_data_from_worker(
  File "/opt/conda/envs/gdf/lib/python3.9/site-packages/distributed/worker.py", line 2892, in get_data_from_worker
    response = await send_recv(
  File "/opt/conda/envs/gdf/lib/python3.9/site-packages/distributed/core.py", line 1024, in send_recv
    response = await comm.read(deserializers=deserializers)
  File "/opt/conda/envs/gdf/lib/python3.9/site-packages/distributed/utils.py", line 752, in wrapper
    return await func(*args, **kwargs)
  File "/opt/conda/envs/gdf/lib/python3.9/site-packages/distributed/comm/ucx.py", line 367, in read
    raise CommClosedError(
distributed.comm.core.CommClosedError: Connection closed by writer.
Inner exception: UCXCanceled("<[Recv #003] ep: 0x7fc57853f240, tag: 0x47c2eb759b24fbcb, nbytes: 16, type: <class 'numpy.ndarray'>>: ")
2023-08-07 06:54:11,215 - distributed.worker - ERROR - Worker stream died during communication: ucx://127.0.0.1:60337
Traceback (most recent call last):
  File "/opt/conda/envs/gdf/lib/python3.9/site-packages/distributed/comm/ucx.py", line 349, in read
    await self.ep.recv(msg)
  File "/opt/conda/envs/gdf/lib/python3.9/site-packages/ucp/core.py", line 725, in recv
    ret = await comm.tag_recv(self._ep, buffer, nbytes, tag, name=log)
ucp._libs.exceptions.UCXCanceled: <[Recv #003] ep: 0x7ff6b49fb140, tag: 0xf1e20aaabcd96fb7, nbytes: 16, type: <class 'numpy.ndarray'>>: 

During handling of the above exception, another exception occurred:

Traceback (most recent call last):
  File "/opt/conda/envs/gdf/lib/python3.9/site-packages/distributed/worker.py", line 2066, in gather_dep
    response = await get_data_from_worker(
  File "/opt/conda/envs/gdf/lib/python3.9/site-packages/distributed/worker.py", line 2892, in get_data_from_worker
    response = await send_recv(
  File "/opt/conda/envs/gdf/lib/python3.9/site-packages/distributed/core.py", line 1024, in send_recv
    response = await comm.read(deserializers=deserializers)
  File "/opt/conda/envs/gdf/lib/python3.9/site-packages/distributed/utils.py", line 752, in wrapper
    return await func(*args, **kwargs)
  File "/opt/conda/envs/gdf/lib/python3.9/site-packages/distributed/comm/ucx.py", line 367, in read
    raise CommClosedError(
distributed.comm.core.CommClosedError: Connection closed by writer.
Inner exception: UCXCanceled("<[Recv #003] ep: 0x7ff6b49fb140, tag: 0xf1e20aaabcd96fb7, nbytes: 16, type: <class 'numpy.ndarray'>>: ")
2023-08-07 06:54:11,216 - distributed.worker - ERROR - Worker stream died during communication: ucx://127.0.0.1:48221
Traceback (most recent call last):
  File "/opt/conda/envs/gdf/lib/python3.9/site-packages/distributed/comm/ucx.py", line 349, in read
    await self.ep.recv(msg)
  File "/opt/conda/envs/gdf/lib/python3.9/site-packages/ucp/core.py", line 725, in recv
    ret = await comm.tag_recv(self._ep, buffer, nbytes, tag, name=log)
ucp._libs.exceptions.UCXCanceled: <[Recv #003] ep: 0x7ff6b49fb100, tag: 0x57723bf7a2649482, nbytes: 16, type: <class 'numpy.ndarray'>>: 

During handling of the above exception, another exception occurred:

Traceback (most recent call last):
  File "/opt/conda/envs/gdf/lib/python3.9/site-packages/distributed/worker.py", line 2066, in gather_dep
    response = await get_data_from_worker(
  File "/opt/conda/envs/gdf/lib/python3.9/site-packages/distributed/worker.py", line 2892, in get_data_from_worker
    response = await send_recv(
  File "/opt/conda/envs/gdf/lib/python3.9/site-packages/distributed/core.py", line 1024, in send_recv
    response = await comm.read(deserializers=deserializers)
  File "/opt/conda/envs/gdf/lib/python3.9/site-packages/distributed/utils.py", line 752, in wrapper
    return await func(*args, **kwargs)
  File "/opt/conda/envs/gdf/lib/python3.9/site-packages/distributed/comm/ucx.py", line 367, in read
    raise CommClosedError(
distributed.comm.core.CommClosedError: Connection closed by writer.
Inner exception: UCXCanceled("<[Recv #003] ep: 0x7ff6b49fb100, tag: 0x57723bf7a2649482, nbytes: 16, type: <class 'numpy.ndarray'>>: ")
2023-08-07 06:54:11,234 - distributed.worker - ERROR - failed during get data with ucx://127.0.0.1:49327 -> ucx://127.0.0.1:60337
Traceback (most recent call last):
  File "/opt/conda/envs/gdf/lib/python3.9/site-packages/distributed/comm/ucx.py", line 333, in write
    await self.ep.send(each_frame)
  File "/opt/conda/envs/gdf/lib/python3.9/site-packages/ucp/core.py", line 650, in send
    return await comm.tag_send(self._ep, buffer, nbytes, tag, name=log)
ucp._libs.exceptions.UCXError: <[Send #007] ep: 0x7fa4d30cc300, tag: 0xa1d605c5f60f0852, nbytes: 100000000, type: <class 'cudf.core.buffer.buffer.Buffer'>>: Connection reset by remote peer

During handling of the above exception, another exception occurred:

Traceback (most recent call last):
  File "/opt/conda/envs/gdf/lib/python3.9/site-packages/distributed/worker.py", line 1792, in get_data
    compressed = await comm.write(msg, serializers=serializers)
  File "/opt/conda/envs/gdf/lib/python3.9/site-packages/distributed/utils.py", line 752, in wrapper
    return await func(*args, **kwargs)
  File "/opt/conda/envs/gdf/lib/python3.9/site-packages/distributed/comm/ucx.py", line 337, in write
    raise CommClosedError("While writing, the connection was closed")
distributed.comm.core.CommClosedError: While writing, the connection was closed
2023-08-07 06:54:11,251 - distributed.worker - ERROR - Worker stream died during communication: ucx://127.0.0.1:48221
Traceback (most recent call last):
  File "/opt/conda/envs/gdf/lib/python3.9/site-packages/distributed/comm/ucx.py", line 391, in read
    await self.ep.recv(each_frame)
  File "/opt/conda/envs/gdf/lib/python3.9/site-packages/ucp/core.py", line 725, in recv
    ret = await comm.tag_recv(self._ep, buffer, nbytes, tag, name=log)
ucp._libs.exceptions.UCXError: <[Recv #007] ep: 0x7fa4d30cc280, tag: 0xb8dc74a2384e4693, nbytes: 100000000, type: <class 'rmm._lib.device_buffer.DeviceBuffer'>>: Connection reset by remote peer

During handling of the above exception, another exception occurred:

Traceback (most recent call last):
  File "/opt/conda/envs/gdf/lib/python3.9/site-packages/distributed/worker.py", line 2066, in gather_dep
    response = await get_data_from_worker(
  File "/opt/conda/envs/gdf/lib/python3.9/site-packages/distributed/worker.py", line 2892, in get_data_from_worker
    response = await send_recv(
  File "/opt/conda/envs/gdf/lib/python3.9/site-packages/distributed/core.py", line 1024, in send_recv
    response = await comm.read(deserializers=deserializers)
  File "/opt/conda/envs/gdf/lib/python3.9/site-packages/distributed/utils.py", line 752, in wrapper
    return await func(*args, **kwargs)
  File "/opt/conda/envs/gdf/lib/python3.9/site-packages/distributed/comm/ucx.py", line 397, in read
    raise CommClosedError(
distributed.comm.core.CommClosedError: Connection closed by writer.
Inner exception: UCXError("<[Recv #007] ep: 0x7fa4d30cc280, tag: 0xb8dc74a2384e4693, nbytes: 100000000, type: <class 'rmm._lib.device_buffer.DeviceBuffer'>>: Connection reset by remote peer")
2023-08-07 06:54:11,254 - distributed.worker - ERROR - Worker stream died during communication: ucx://127.0.0.1:60337
Traceback (most recent call last):
  File "/opt/conda/envs/gdf/lib/python3.9/site-packages/distributed/comm/ucx.py", line 391, in read
    await self.ep.recv(each_frame)
  File "/opt/conda/envs/gdf/lib/python3.9/site-packages/ucp/core.py", line 725, in recv
    ret = await comm.tag_recv(self._ep, buffer, nbytes, tag, name=log)
ucp._libs.exceptions.UCXError: <[Recv #007] ep: 0x7fa4d30cc1c0, tag: 0xe0e8af4c0d0b7cad, nbytes: 100000000, type: <class 'rmm._lib.device_buffer.DeviceBuffer'>>: Connection reset by remote peer

During handling of the above exception, another exception occurred:

Traceback (most recent call last):
  File "/opt/conda/envs/gdf/lib/python3.9/site-packages/distributed/worker.py", line 2066, in gather_dep
    response = await get_data_from_worker(
  File "/opt/conda/envs/gdf/lib/python3.9/site-packages/distributed/worker.py", line 2892, in get_data_from_worker
    response = await send_recv(
  File "/opt/conda/envs/gdf/lib/python3.9/site-packages/distributed/core.py", line 1024, in send_recv
    response = await comm.read(deserializers=deserializers)
  File "/opt/conda/envs/gdf/lib/python3.9/site-packages/distributed/utils.py", line 752, in wrapper
    return await func(*args, **kwargs)
  File "/opt/conda/envs/gdf/lib/python3.9/site-packages/distributed/comm/ucx.py", line 397, in read
    raise CommClosedError(
distributed.comm.core.CommClosedError: Connection closed by writer.
Inner exception: UCXError("<[Recv #007] ep: 0x7fa4d30cc1c0, tag: 0xe0e8af4c0d0b7cad, nbytes: 100000000, type: <class 'rmm._lib.device_buffer.DeviceBuffer'>>: Connection reset by remote peer")
2023-08-07 06:54:11,218 - distributed.worker - ERROR - Worker stream died during communication: ucx://127.0.0.1:47429
Traceback (most recent call last):
  File "/opt/conda/envs/gdf/lib/python3.9/asyncio/tasks.py", line 466, in wait_for
    await waiter
asyncio.exceptions.CancelledError

During handling of the above exception, another exception occurred:

Traceback (most recent call last):
  File "/opt/conda/envs/gdf/lib/python3.9/site-packages/distributed/comm/core.py", line 329, in connect
    handshake = await wait_for(comm.read(), time_left())
  File "/opt/conda/envs/gdf/lib/python3.9/site-packages/distributed/utils.py", line 1849, in wait_for
    return await asyncio.wait_for(fut, timeout)
  File "/opt/conda/envs/gdf/lib/python3.9/asyncio/tasks.py", line 469, in wait_for
    return fut.result()
  File "/opt/conda/envs/gdf/lib/python3.9/site-packages/distributed/utils.py", line 752, in wrapper
    return await func(*args, **kwargs)
  File "/opt/conda/envs/gdf/lib/python3.9/site-packages/distributed/comm/ucx.py", line 367, in read
    raise CommClosedError(
distributed.comm.core.CommClosedError: Connection closed by writer.
Inner exception: UCXCanceled("<[Recv #000] ep: 0x7ff6b49fb280, tag: 0xd88fa251482c00fd, nbytes: 16, type: <class 'numpy.ndarray'>>: ")

The above exception was the direct cause of the following exception:

Traceback (most recent call last):
  File "/opt/conda/envs/gdf/lib/python3.9/site-packages/distributed/worker.py", line 2066, in gather_dep
    response = await get_data_from_worker(
  File "/opt/conda/envs/gdf/lib/python3.9/site-packages/distributed/worker.py", line 2889, in get_data_from_worker
    comm = await rpc.connect(worker)
  File "/opt/conda/envs/gdf/lib/python3.9/site-packages/distributed/core.py", line 1506, in connect
    return await connect_attempt
  File "/opt/conda/envs/gdf/lib/python3.9/site-packages/distributed/core.py", line 1427, in _connect
    comm = await connect(
  File "/opt/conda/envs/gdf/lib/python3.9/site-packages/distributed/comm/core.py", line 334, in connect
    raise OSError(
OSError: Timed out during handshake while connecting to ucx://127.0.0.1:47429 after 30 s
2023-08-07 06:54:11,279 - distributed.nanny - WARNING - Restarting worker
2023-08-07 06:54:11,322 - distributed.worker - ERROR - failed during get data with ucx://127.0.0.1:37075 -> ucx://127.0.0.1:42065
Traceback (most recent call last):
  File "/opt/conda/envs/gdf/lib/python3.9/site-packages/distributed/comm/ucx.py", line 333, in write
    await self.ep.send(each_frame)
  File "/opt/conda/envs/gdf/lib/python3.9/site-packages/ucp/core.py", line 650, in send
    return await comm.tag_send(self._ep, buffer, nbytes, tag, name=log)
ucp._libs.exceptions.UCXError: <[Send #007] ep: 0x7f83cd28a300, tag: 0xa3558fe7d8e6551, nbytes: 100000000, type: <class 'cudf.core.buffer.buffer.Buffer'>>: Connection reset by remote peer

During handling of the above exception, another exception occurred:

Traceback (most recent call last):
  File "/opt/conda/envs/gdf/lib/python3.9/site-packages/distributed/worker.py", line 1792, in get_data
    compressed = await comm.write(msg, serializers=serializers)
  File "/opt/conda/envs/gdf/lib/python3.9/site-packages/distributed/utils.py", line 752, in wrapper
    return await func(*args, **kwargs)
  File "/opt/conda/envs/gdf/lib/python3.9/site-packages/distributed/comm/ucx.py", line 337, in write
    raise CommClosedError("While writing, the connection was closed")
distributed.comm.core.CommClosedError: While writing, the connection was closed
2023-08-07 06:54:11,323 - distributed.worker - ERROR - Worker stream died during communication: ucx://127.0.0.1:42065
Traceback (most recent call last):
  File "/opt/conda/envs/gdf/lib/python3.9/site-packages/distributed/comm/ucx.py", line 391, in read
    await self.ep.recv(each_frame)
  File "/opt/conda/envs/gdf/lib/python3.9/site-packages/ucp/core.py", line 725, in recv
    ret = await comm.tag_recv(self._ep, buffer, nbytes, tag, name=log)
ucp._libs.exceptions.UCXError: <[Recv #007] ep: 0x7f83cd28a140, tag: 0x94a9e20a82a75488, nbytes: 100000000, type: <class 'rmm._lib.device_buffer.DeviceBuffer'>>: Connection reset by remote peer

During handling of the above exception, another exception occurred:

Traceback (most recent call last):
  File "/opt/conda/envs/gdf/lib/python3.9/site-packages/distributed/worker.py", line 2066, in gather_dep
    response = await get_data_from_worker(
  File "/opt/conda/envs/gdf/lib/python3.9/site-packages/distributed/worker.py", line 2892, in get_data_from_worker
    response = await send_recv(
  File "/opt/conda/envs/gdf/lib/python3.9/site-packages/distributed/core.py", line 1024, in send_recv
    response = await comm.read(deserializers=deserializers)
  File "/opt/conda/envs/gdf/lib/python3.9/site-packages/distributed/utils.py", line 752, in wrapper
    return await func(*args, **kwargs)
  File "/opt/conda/envs/gdf/lib/python3.9/site-packages/distributed/comm/ucx.py", line 397, in read
    raise CommClosedError(
distributed.comm.core.CommClosedError: Connection closed by writer.
Inner exception: UCXError("<[Recv #007] ep: 0x7f83cd28a140, tag: 0x94a9e20a82a75488, nbytes: 100000000, type: <class 'rmm._lib.device_buffer.DeviceBuffer'>>: Connection reset by remote peer")
2023-08-07 06:54:11,324 - distributed.worker - ERROR - Worker stream died during communication: ucx://127.0.0.1:60337
Traceback (most recent call last):
  File "/opt/conda/envs/gdf/lib/python3.9/site-packages/distributed/comm/ucx.py", line 391, in read
    await self.ep.recv(each_frame)
  File "/opt/conda/envs/gdf/lib/python3.9/site-packages/ucp/core.py", line 725, in recv
    ret = await comm.tag_recv(self._ep, buffer, nbytes, tag, name=log)
ucp._libs.exceptions.UCXCanceled: <[Recv #008] ep: 0x7f83cd28a1c0, tag: 0x9b4e50923008e77, nbytes: 100000000, type: <class 'rmm._lib.device_buffer.DeviceBuffer'>>: 

During handling of the above exception, another exception occurred:

Traceback (most recent call last):
  File "/opt/conda/envs/gdf/lib/python3.9/site-packages/distributed/worker.py", line 2066, in gather_dep
    response = await get_data_from_worker(
  File "/opt/conda/envs/gdf/lib/python3.9/site-packages/distributed/worker.py", line 2892, in get_data_from_worker
    response = await send_recv(
  File "/opt/conda/envs/gdf/lib/python3.9/site-packages/distributed/core.py", line 1024, in send_recv
    response = await comm.read(deserializers=deserializers)
  File "/opt/conda/envs/gdf/lib/python3.9/site-packages/distributed/utils.py", line 752, in wrapper
    return await func(*args, **kwargs)
  File "/opt/conda/envs/gdf/lib/python3.9/site-packages/distributed/comm/ucx.py", line 397, in read
    raise CommClosedError(
distributed.comm.core.CommClosedError: Connection closed by writer.
Inner exception: UCXCanceled("<[Recv #008] ep: 0x7f83cd28a1c0, tag: 0x9b4e50923008e77, nbytes: 100000000, type: <class 'rmm._lib.device_buffer.DeviceBuffer'>>: ")
2023-08-07 06:54:11,325 - distributed.worker - ERROR - Worker stream died during communication: ucx://127.0.0.1:48221
Traceback (most recent call last):
  File "/opt/conda/envs/gdf/lib/python3.9/site-packages/distributed/comm/ucx.py", line 391, in read
    await self.ep.recv(each_frame)
  File "/opt/conda/envs/gdf/lib/python3.9/site-packages/ucp/core.py", line 725, in recv
    ret = await comm.tag_recv(self._ep, buffer, nbytes, tag, name=log)
ucp._libs.exceptions.UCXCanceled: <[Recv #008] ep: 0x7f83cd28a200, tag: 0x1eee400f59e2e0d2, nbytes: 100000000, type: <class 'rmm._lib.device_buffer.DeviceBuffer'>>: 

During handling of the above exception, another exception occurred:

Traceback (most recent call last):
  File "/opt/conda/envs/gdf/lib/python3.9/site-packages/distributed/worker.py", line 2066, in gather_dep
    response = await get_data_from_worker(
  File "/opt/conda/envs/gdf/lib/python3.9/site-packages/distributed/worker.py", line 2892, in get_data_from_worker
    response = await send_recv(
  File "/opt/conda/envs/gdf/lib/python3.9/site-packages/distributed/core.py", line 1024, in send_recv
    response = await comm.read(deserializers=deserializers)
  File "/opt/conda/envs/gdf/lib/python3.9/site-packages/distributed/utils.py", line 752, in wrapper
    return await func(*args, **kwargs)
  File "/opt/conda/envs/gdf/lib/python3.9/site-packages/distributed/comm/ucx.py", line 397, in read
    raise CommClosedError(
distributed.comm.core.CommClosedError: Connection closed by writer.
Inner exception: UCXCanceled("<[Recv #008] ep: 0x7f83cd28a200, tag: 0x1eee400f59e2e0d2, nbytes: 100000000, type: <class 'rmm._lib.device_buffer.DeviceBuffer'>>: ")
2023-08-07 06:54:11,221 - distributed.worker - ERROR - Worker stream died during communication: ucx://127.0.0.1:47429
Traceback (most recent call last):
  File "/opt/conda/envs/gdf/lib/python3.9/site-packages/distributed/core.py", line 1427, in _connect
    comm = await connect(
  File "/opt/conda/envs/gdf/lib/python3.9/site-packages/distributed/comm/core.py", line 329, in connect
    handshake = await wait_for(comm.read(), time_left())
  File "/opt/conda/envs/gdf/lib/python3.9/site-packages/distributed/utils.py", line 1849, in wait_for
    return await asyncio.wait_for(fut, timeout)
  File "/opt/conda/envs/gdf/lib/python3.9/asyncio/tasks.py", line 466, in wait_for
    await waiter
asyncio.exceptions.CancelledError

During handling of the above exception, another exception occurred:

Traceback (most recent call last):
  File "/opt/conda/envs/gdf/lib/python3.9/site-packages/distributed/worker.py", line 2066, in gather_dep
    response = await get_data_from_worker(
  File "/opt/conda/envs/gdf/lib/python3.9/site-packages/distributed/worker.py", line 2889, in get_data_from_worker
    comm = await rpc.connect(worker)
  File "/opt/conda/envs/gdf/lib/python3.9/site-packages/distributed/core.py", line 1506, in connect
    return await connect_attempt
  File "/opt/conda/envs/gdf/lib/python3.9/site-packages/distributed/core.py", line 1450, in _connect
    raise CommClosedError(reason)
distributed.comm.core.CommClosedError: Address removed.
2023-08-07 06:54:11,457 - distributed.nanny - WARNING - Restarting worker
2023-08-07 06:54:11,458 - distributed.nanny - WARNING - Restarting worker
2023-08-07 06:54:11,494 - distributed.nanny - WARNING - Restarting worker
2023-08-07 06:54:12,824 - distributed.preloading - INFO - Creating preload: dask_cuda.initialize
2023-08-07 06:54:12,824 - distributed.preloading - INFO - Import preload module: dask_cuda.initialize
2023-08-07 06:54:12,974 - distributed.preloading - INFO - Creating preload: dask_cuda.initialize
2023-08-07 06:54:12,974 - distributed.preloading - INFO - Import preload module: dask_cuda.initialize
2023-08-07 06:54:13,026 - distributed.preloading - INFO - Creating preload: dask_cuda.initialize
2023-08-07 06:54:13,026 - distributed.preloading - INFO - Import preload module: dask_cuda.initialize
2023-08-07 06:54:13,032 - distributed.preloading - INFO - Creating preload: dask_cuda.initialize
2023-08-07 06:54:13,032 - distributed.preloading - INFO - Import preload module: dask_cuda.initialize
/opt/conda/envs/gdf/lib/python3.9/multiprocessing/resource_tracker.py:216: UserWarning: resource_tracker: There appear to be 48 leaked semaphore objects to clean up at shutdown
  warnings.warn('resource_tracker: There appear to be %d '
