[dgx13:76985:0:76985] Caught signal 11 (Segmentation fault: address not mapped to object at address 0x448)
[dgx13:76975:0:76975] Caught signal 11 (Segmentation fault: address not mapped to object at address 0x448)
==== backtrace (tid:  76985) ====
 0  /opt/conda/envs/gdf/lib/libucs.so.0(ucs_handle_error+0x2fd) [0x7fe9713f307d]
 1  /opt/conda/envs/gdf/lib/libucs.so.0(+0x2a274) [0x7fe9713f3274]
 2  /opt/conda/envs/gdf/lib/libucs.so.0(+0x2a43a) [0x7fe9713f343a]
 3  /usr/lib/x86_64-linux-gnu/libpthread.so.0(+0x14420) [0x7fe9ae2aa420]
 4  /opt/conda/envs/gdf/lib/libucp.so.0(ucp_mem_type_unpack+0x14) [0x7fe9714726b4]
 5  /opt/conda/envs/gdf/lib/libucp.so.0(ucp_rndv_data_handler+0x4e9) [0x7fe97149b839]
 6  /opt/conda/envs/gdf/lib/libuct.so.0(+0x203df) [0x7fe9713ad3df]
 7  /opt/conda/envs/gdf/lib/libuct.so.0(+0x23838) [0x7fe9713b0838]
 8  /opt/conda/envs/gdf/lib/libucs.so.0(ucs_event_set_wait+0xb9) [0x7fe9713fc4a9]
 9  /opt/conda/envs/gdf/lib/libuct.so.0(uct_tcp_iface_progress+0x7d) [0x7fe9713af5dd]
10  /opt/conda/envs/gdf/lib/libucp.so.0(ucp_worker_progress+0x5a) [0x7fe97146f8da]
11  /opt/conda/envs/gdf/lib/python3.9/site-packages/ucp/_libs/ucx_api.cpython-39-x86_64-linux-gnu.so(+0x3206a) [0x7fe97152806a]
12  /opt/conda/envs/gdf/bin/python(_PyEval_EvalFrameDefault+0x45a6) [0x557312c7a3f6]
13  /opt/conda/envs/gdf/bin/python(+0x12dfb4) [0x557312c74fb4]
14  /opt/conda/envs/gdf/bin/python(_PyFunction_Vectorcall+0xd9) [0x557312c86469]
15  /opt/conda/envs/gdf/bin/python(_PyEval_EvalFrameDefault+0x696) [0x557312c764e6]
16  /opt/conda/envs/gdf/bin/python(+0x13f712) [0x557312c86712]
17  /opt/conda/envs/gdf/bin/python(+0x14ca83) [0x557312c93a83]
18  /opt/conda/envs/gdf/bin/python(+0x25819c) [0x557312d9f19c]
19  /opt/conda/envs/gdf/bin/python(+0xf23ff) [0x557312c393ff]
20  /opt/conda/envs/gdf/bin/python(+0x136723) [0x557312c7d723]
21  /opt/conda/envs/gdf/bin/python(_PyEval_EvalFrameDefault+0x5ad9) [0x557312c7b929]
22  /opt/conda/envs/gdf/bin/python(+0x13f712) [0x557312c86712]
23  /opt/conda/envs/gdf/bin/python(_PyEval_EvalFrameDefault+0x696) [0x557312c764e6]
24  /opt/conda/envs/gdf/bin/python(+0x13f712) [0x557312c86712]
25  /opt/conda/envs/gdf/bin/python(_PyEval_EvalFrameDefault+0x696) [0x557312c764e6]
26  /opt/conda/envs/gdf/bin/python(+0x13f712) [0x557312c86712]
27  /opt/conda/envs/gdf/bin/python(_PyEval_EvalFrameDefault+0x696) [0x557312c764e6]
28  /opt/conda/envs/gdf/bin/python(+0x13f712) [0x557312c86712]
29  /opt/conda/envs/gdf/bin/python(_PyEval_EvalFrameDefault+0x696) [0x557312c764e6]
30  /opt/conda/envs/gdf/bin/python(+0x12dfb4) [0x557312c74fb4]
31  /opt/conda/envs/gdf/bin/python(_PyFunction_Vectorcall+0xd9) [0x557312c86469]
32  /opt/conda/envs/gdf/bin/python(_PyEval_EvalFrameDefault+0x11f2) [0x557312c77042]
33  /opt/conda/envs/gdf/bin/python(+0x12dfb4) [0x557312c74fb4]
34  /opt/conda/envs/gdf/bin/python(+0x14c8cb) [0x557312c938cb]
35  /opt/conda/envs/gdf/bin/python(PyObject_Call+0xbc) [0x557312c9404c]
36  /opt/conda/envs/gdf/bin/python(+0x21080e) [0x557312d5780e]
37  /opt/conda/envs/gdf/bin/python(_PyObject_MakeTpCall+0x2ec) [0x557312c7e6ac]
38  /opt/conda/envs/gdf/bin/python(_PyEval_EvalFrameDefault+0x45a6) [0x557312c7a3f6]
39  /opt/conda/envs/gdf/bin/python(+0x13f712) [0x557312c86712]
40  /opt/conda/envs/gdf/bin/python(+0x14c9ac) [0x557312c939ac]
41  /opt/conda/envs/gdf/bin/python(_PyEval_EvalFrameDefault+0x45a6) [0x557312c7a3f6]
42  /opt/conda/envs/gdf/bin/python(+0x13f712) [0x557312c86712]
43  /opt/conda/envs/gdf/bin/python(_PyEval_EvalFrameDefault+0x696) [0x557312c764e6]
44  /opt/conda/envs/gdf/bin/python(+0x12dfb4) [0x557312c74fb4]
45  /opt/conda/envs/gdf/bin/python(_PyFunction_Vectorcall+0xd9) [0x557312c86469]
46  /opt/conda/envs/gdf/bin/python(_PyEval_EvalFrameDefault+0x696) [0x557312c764e6]
47  /opt/conda/envs/gdf/bin/python(+0x13f712) [0x557312c86712]
48  /opt/conda/envs/gdf/bin/python(_PyEval_EvalFrameDefault+0x3e2) [0x557312c76232]
49  /opt/conda/envs/gdf/bin/python(+0x12dfb4) [0x557312c74fb4]
50  /opt/conda/envs/gdf/bin/python(_PyFunction_Vectorcall+0xd9) [0x557312c86469]
51  /opt/conda/envs/gdf/bin/python(_PyEval_EvalFrameDefault+0x11f2) [0x557312c77042]
52  /opt/conda/envs/gdf/bin/python(+0x12dfb4) [0x557312c74fb4]
53  /opt/conda/envs/gdf/bin/python(_PyEval_EvalCodeWithName+0x48) [0x557312c74c88]
54  /opt/conda/envs/gdf/bin/python(PyEval_EvalCodeEx+0x39) [0x557312c74c39]
55  /opt/conda/envs/gdf/bin/python(PyEval_EvalCode+0x1b) [0x557312d222cb]
56  /opt/conda/envs/gdf/bin/python(+0x2086ca) [0x557312d4f6ca]
57  /opt/conda/envs/gdf/bin/python(+0x204a63) [0x557312d4ba63]
58  /opt/conda/envs/gdf/bin/python(PyRun_StringFlags+0x9a) [0x557312d4387a]
59  /opt/conda/envs/gdf/bin/python(PyRun_SimpleStringFlags+0x3c) [0x557312d4376c]
60  /opt/conda/envs/gdf/bin/python(Py_RunMain+0x267) [0x557312d429a7]
61  /opt/conda/envs/gdf/bin/python(Py_BytesMain+0x37) [0x557312d16107]
=================================
==== backtrace (tid:  76975) ====
 0  /opt/conda/envs/gdf/lib/libucs.so.0(ucs_handle_error+0x2fd) [0x7ff0137c607d]
 1  /opt/conda/envs/gdf/lib/libucs.so.0(+0x2a274) [0x7ff0137c6274]
 2  /opt/conda/envs/gdf/lib/libucs.so.0(+0x2a43a) [0x7ff0137c643a]
 3  /usr/lib/x86_64-linux-gnu/libpthread.so.0(+0x14420) [0x7ff0507cd420]
 4  /opt/conda/envs/gdf/lib/libucp.so.0(ucp_mem_type_unpack+0x14) [0x7ff0138456b4]
 5  /opt/conda/envs/gdf/lib/libucp.so.0(ucp_rndv_data_handler+0x4e9) [0x7ff01386e839]
 6  /opt/conda/envs/gdf/lib/libuct.so.0(+0x203df) [0x7ff0137803df]
 7  /opt/conda/envs/gdf/lib/libuct.so.0(+0x23838) [0x7ff013783838]
 8  /opt/conda/envs/gdf/lib/libucs.so.0(ucs_event_set_wait+0xb9) [0x7ff0137cf4a9]
 9  /opt/conda/envs/gdf/lib/libuct.so.0(uct_tcp_iface_progress+0x7d) [0x7ff0137825dd]
10  /opt/conda/envs/gdf/lib/libucp.so.0(ucp_worker_progress+0x5a) [0x7ff0138428da]
11  /opt/conda/envs/gdf/lib/python3.9/site-packages/ucp/_libs/ucx_api.cpython-39-x86_64-linux-gnu.so(+0x3206a) [0x7ff0138fb06a]
12  /opt/conda/envs/gdf/bin/python(_PyEval_EvalFrameDefault+0x45a6) [0x5628425593f6]
13  /opt/conda/envs/gdf/bin/python(+0x12dfb4) [0x562842553fb4]
14  /opt/conda/envs/gdf/bin/python(_PyFunction_Vectorcall+0xd9) [0x562842565469]
15  /opt/conda/envs/gdf/bin/python(_PyEval_EvalFrameDefault+0x696) [0x5628425554e6]
16  /opt/conda/envs/gdf/bin/python(+0x13f712) [0x562842565712]
17  /opt/conda/envs/gdf/bin/python(+0x14ca83) [0x562842572a83]
18  /opt/conda/envs/gdf/bin/python(+0x25819c) [0x56284267e19c]
19  /opt/conda/envs/gdf/bin/python(+0xf23ff) [0x5628425183ff]
20  /opt/conda/envs/gdf/bin/python(+0x136723) [0x56284255c723]
21  /opt/conda/envs/gdf/bin/python(_PyEval_EvalFrameDefault+0x5ad9) [0x56284255a929]
22  /opt/conda/envs/gdf/bin/python(+0x13f712) [0x562842565712]
23  /opt/conda/envs/gdf/bin/python(_PyEval_EvalFrameDefault+0x696) [0x5628425554e6]
24  /opt/conda/envs/gdf/bin/python(+0x13f712) [0x562842565712]
25  /opt/conda/envs/gdf/bin/python(_PyEval_EvalFrameDefault+0x696) [0x5628425554e6]
26  /opt/conda/envs/gdf/bin/python(+0x13f712) [0x562842565712]
27  /opt/conda/envs/gdf/bin/python(_PyEval_EvalFrameDefault+0x696) [0x5628425554e6]
28  /opt/conda/envs/gdf/bin/python(+0x13f712) [0x562842565712]
29  /opt/conda/envs/gdf/bin/python(_PyEval_EvalFrameDefault+0x696) [0x5628425554e6]
30  /opt/conda/envs/gdf/bin/python(+0x12dfb4) [0x562842553fb4]
31  /opt/conda/envs/gdf/bin/python(_PyFunction_Vectorcall+0xd9) [0x562842565469]
32  /opt/conda/envs/gdf/bin/python(_PyEval_EvalFrameDefault+0x11f2) [0x562842556042]
33  /opt/conda/envs/gdf/bin/python(+0x12dfb4) [0x562842553fb4]
34  /opt/conda/envs/gdf/bin/python(+0x14c8cb) [0x5628425728cb]
35  /opt/conda/envs/gdf/bin/python(PyObject_Call+0xbc) [0x56284257304c]
36  /opt/conda/envs/gdf/bin/python(+0x21080e) [0x56284263680e]
37  /opt/conda/envs/gdf/bin/python(_PyObject_MakeTpCall+0x2ec) [0x56284255d6ac]
38  /opt/conda/envs/gdf/bin/python(_PyEval_EvalFrameDefault+0x45a6) [0x5628425593f6]
39  /opt/conda/envs/gdf/bin/python(+0x13f712) [0x562842565712]
40  /opt/conda/envs/gdf/bin/python(+0x14c9ac) [0x5628425729ac]
41  /opt/conda/envs/gdf/bin/python(_PyEval_EvalFrameDefault+0x45a6) [0x5628425593f6]
42  /opt/conda/envs/gdf/bin/python(+0x13f712) [0x562842565712]
43  /opt/conda/envs/gdf/bin/python(_PyEval_EvalFrameDefault+0x696) [0x5628425554e6]
44  /opt/conda/envs/gdf/bin/python(+0x12dfb4) [0x562842553fb4]
45  /opt/conda/envs/gdf/bin/python(_PyFunction_Vectorcall+0xd9) [0x562842565469]
46  /opt/conda/envs/gdf/bin/python(_PyEval_EvalFrameDefault+0x696) [0x5628425554e6]
47  /opt/conda/envs/gdf/bin/python(+0x13f712) [0x562842565712]
48  /opt/conda/envs/gdf/bin/python(_PyEval_EvalFrameDefault+0x3e2) [0x562842555232]
49  /opt/conda/envs/gdf/bin/python(+0x12dfb4) [0x562842553fb4]
50  /opt/conda/envs/gdf/bin/python(_PyFunction_Vectorcall+0xd9) [0x562842565469]
51  /opt/conda/envs/gdf/bin/python(_PyEval_EvalFrameDefault+0x11f2) [0x562842556042]
52  /opt/conda/envs/gdf/bin/python(+0x12dfb4) [0x562842553fb4]
53  /opt/conda/envs/gdf/bin/python(_PyEval_EvalCodeWithName+0x48) [0x562842553c88]
54  /opt/conda/envs/gdf/bin/python(PyEval_EvalCodeEx+0x39) [0x562842553c39]
55  /opt/conda/envs/gdf/bin/python(PyEval_EvalCode+0x1b) [0x5628426012cb]
56  /opt/conda/envs/gdf/bin/python(+0x2086ca) [0x56284262e6ca]
57  /opt/conda/envs/gdf/bin/python(+0x204a63) [0x56284262aa63]
58  /opt/conda/envs/gdf/bin/python(PyRun_StringFlags+0x9a) [0x56284262287a]
59  /opt/conda/envs/gdf/bin/python(PyRun_SimpleStringFlags+0x3c) [0x56284262276c]
60  /opt/conda/envs/gdf/bin/python(Py_RunMain+0x267) [0x5628426219a7]
61  /opt/conda/envs/gdf/bin/python(Py_BytesMain+0x37) [0x5628425f5107]
=================================
[dgx13:77006:0:77006] Caught signal 11 (Segmentation fault: address not mapped to object at address 0x448)
==== backtrace (tid:  77006) ====
 0  /opt/conda/envs/gdf/lib/libucs.so.0(ucs_handle_error+0x2fd) [0x7fa28f02f07d]
 1  /opt/conda/envs/gdf/lib/libucs.so.0(+0x2a274) [0x7fa28f02f274]
 2  /opt/conda/envs/gdf/lib/libucs.so.0(+0x2a43a) [0x7fa28f02f43a]
 3  /usr/lib/x86_64-linux-gnu/libpthread.so.0(+0x14420) [0x7fa2d8041420]
 4  /opt/conda/envs/gdf/lib/libucp.so.0(ucp_mem_type_unpack+0x14) [0x7fa28f0ae6b4]
 5  /opt/conda/envs/gdf/lib/libucp.so.0(ucp_rndv_data_handler+0x4e9) [0x7fa28f0d7839]
 6  /opt/conda/envs/gdf/lib/libuct.so.0(+0x203df) [0x7fa28efe93df]
 7  /opt/conda/envs/gdf/lib/libuct.so.0(+0x23838) [0x7fa28efec838]
 8  /opt/conda/envs/gdf/lib/libucs.so.0(ucs_event_set_wait+0xb9) [0x7fa28f0384a9]
 9  /opt/conda/envs/gdf/lib/libuct.so.0(uct_tcp_iface_progress+0x7d) [0x7fa28efeb5dd]
10  /opt/conda/envs/gdf/lib/libucp.so.0(ucp_worker_progress+0x5a) [0x7fa28f0ab8da]
11  /opt/conda/envs/gdf/lib/python3.9/site-packages/ucp/_libs/ucx_api.cpython-39-x86_64-linux-gnu.so(+0x3206a) [0x7fa28f16406a]
12  /opt/conda/envs/gdf/bin/python(_PyEval_EvalFrameDefault+0x45a6) [0x5598813ba3f6]
13  /opt/conda/envs/gdf/bin/python(+0x12dfb4) [0x5598813b4fb4]
14  /opt/conda/envs/gdf/bin/python(_PyFunction_Vectorcall+0xd9) [0x5598813c6469]
15  /opt/conda/envs/gdf/bin/python(_PyEval_EvalFrameDefault+0x696) [0x5598813b64e6]
16  /opt/conda/envs/gdf/bin/python(+0x13f712) [0x5598813c6712]
17  /opt/conda/envs/gdf/bin/python(+0x14ca83) [0x5598813d3a83]
18  /opt/conda/envs/gdf/bin/python(+0x25819c) [0x5598814df19c]
19  /opt/conda/envs/gdf/bin/python(+0xf23ff) [0x5598813793ff]
20  /opt/conda/envs/gdf/bin/python(+0x136723) [0x5598813bd723]
21  /opt/conda/envs/gdf/bin/python(_PyEval_EvalFrameDefault+0x5ad9) [0x5598813bb929]
22  /opt/conda/envs/gdf/bin/python(+0x13f712) [0x5598813c6712]
23  /opt/conda/envs/gdf/bin/python(_PyEval_EvalFrameDefault+0x696) [0x5598813b64e6]
24  /opt/conda/envs/gdf/bin/python(+0x13f712) [0x5598813c6712]
25  /opt/conda/envs/gdf/bin/python(_PyEval_EvalFrameDefault+0x696) [0x5598813b64e6]
26  /opt/conda/envs/gdf/bin/python(+0x13f712) [0x5598813c6712]
27  /opt/conda/envs/gdf/bin/python(_PyEval_EvalFrameDefault+0x696) [0x5598813b64e6]
28  /opt/conda/envs/gdf/bin/python(+0x13f712) [0x5598813c6712]
29  /opt/conda/envs/gdf/bin/python(_PyEval_EvalFrameDefault+0x696) [0x5598813b64e6]
30  /opt/conda/envs/gdf/bin/python(+0x12dfb4) [0x5598813b4fb4]
31  /opt/conda/envs/gdf/bin/python(_PyFunction_Vectorcall+0xd9) [0x5598813c6469]
32  /opt/conda/envs/gdf/bin/python(_PyEval_EvalFrameDefault+0x11f2) [0x5598813b7042]
33  /opt/conda/envs/gdf/bin/python(+0x12dfb4) [0x5598813b4fb4]
34  /opt/conda/envs/gdf/bin/python(+0x14c8cb) [0x5598813d38cb]
35  /opt/conda/envs/gdf/bin/python(PyObject_Call+0xbc) [0x5598813d404c]
36  /opt/conda/envs/gdf/bin/python(+0x21080e) [0x55988149780e]
37  /opt/conda/envs/gdf/bin/python(_PyObject_MakeTpCall+0x2ec) [0x5598813be6ac]
38  /opt/conda/envs/gdf/bin/python(_PyEval_EvalFrameDefault+0x45a6) [0x5598813ba3f6]
39  /opt/conda/envs/gdf/bin/python(+0x13f712) [0x5598813c6712]
40  /opt/conda/envs/gdf/bin/python(+0x14c9ac) [0x5598813d39ac]
41  /opt/conda/envs/gdf/bin/python(_PyEval_EvalFrameDefault+0x45a6) [0x5598813ba3f6]
42  /opt/conda/envs/gdf/bin/python(+0x13f712) [0x5598813c6712]
43  /opt/conda/envs/gdf/bin/python(_PyEval_EvalFrameDefault+0x696) [0x5598813b64e6]
44  /opt/conda/envs/gdf/bin/python(+0x12dfb4) [0x5598813b4fb4]
45  /opt/conda/envs/gdf/bin/python(_PyFunction_Vectorcall+0xd9) [0x5598813c6469]
46  /opt/conda/envs/gdf/bin/python(_PyEval_EvalFrameDefault+0x696) [0x5598813b64e6]
47  /opt/conda/envs/gdf/bin/python(+0x13f712) [0x5598813c6712]
48  /opt/conda/envs/gdf/bin/python(_PyEval_EvalFrameDefault+0x3e2) [0x5598813b6232]
49  /opt/conda/envs/gdf/bin/python(+0x12dfb4) [0x5598813b4fb4]
50  /opt/conda/envs/gdf/bin/python(_PyFunction_Vectorcall+0xd9) [0x5598813c6469]
51  /opt/conda/envs/gdf/bin/python(_PyEval_EvalFrameDefault+0x11f2) [0x5598813b7042]
52  /opt/conda/envs/gdf/bin/python(+0x12dfb4) [0x5598813b4fb4]
53  /opt/conda/envs/gdf/bin/python(_PyEval_EvalCodeWithName+0x48) [0x5598813b4c88]
54  /opt/conda/envs/gdf/bin/python(PyEval_EvalCodeEx+0x39) [0x5598813b4c39]
55  /opt/conda/envs/gdf/bin/python(PyEval_EvalCode+0x1b) [0x5598814622cb]
56  /opt/conda/envs/gdf/bin/python(+0x2086ca) [0x55988148f6ca]
57  /opt/conda/envs/gdf/bin/python(+0x204a63) [0x55988148ba63]
58  /opt/conda/envs/gdf/bin/python(PyRun_StringFlags+0x9a) [0x55988148387a]
59  /opt/conda/envs/gdf/bin/python(PyRun_SimpleStringFlags+0x3c) [0x55988148376c]
60  /opt/conda/envs/gdf/bin/python(Py_RunMain+0x267) [0x5598814829a7]
61  /opt/conda/envs/gdf/bin/python(Py_BytesMain+0x37) [0x559881456107]
=================================
[dgx13:76994:0:76994] Caught signal 11 (Segmentation fault: address not mapped to object at address 0x448)
==== backtrace (tid:  76994) ====
 0  /opt/conda/envs/gdf/lib/libucs.so.0(ucs_handle_error+0x2fd) [0x7fc7c1cb007d]
 1  /opt/conda/envs/gdf/lib/libucs.so.0(+0x2a274) [0x7fc7c1cb0274]
 2  /opt/conda/envs/gdf/lib/libucs.so.0(+0x2a43a) [0x7fc7c1cb043a]
 3  /usr/lib/x86_64-linux-gnu/libpthread.so.0(+0x14420) [0x7fc800ccb420]
 4  /opt/conda/envs/gdf/lib/libucp.so.0(ucp_mem_type_unpack+0x14) [0x7fc7c1d2f6b4]
 5  /opt/conda/envs/gdf/lib/libucp.so.0(ucp_rndv_data_handler+0x4e9) [0x7fc7c1d58839]
 6  /opt/conda/envs/gdf/lib/libuct.so.0(+0x203df) [0x7fc7c1c6a3df]
 7  /opt/conda/envs/gdf/lib/libuct.so.0(+0x23838) [0x7fc7c1c6d838]
 8  /opt/conda/envs/gdf/lib/libucs.so.0(ucs_event_set_wait+0xb9) [0x7fc7c1cb94a9]
 9  /opt/conda/envs/gdf/lib/libuct.so.0(uct_tcp_iface_progress+0x7d) [0x7fc7c1c6c5dd]
10  /opt/conda/envs/gdf/lib/libucp.so.0(ucp_worker_progress+0x5a) [0x7fc7c1d2c8da]
11  /opt/conda/envs/gdf/lib/python3.9/site-packages/ucp/_libs/ucx_api.cpython-39-x86_64-linux-gnu.so(+0x3206a) [0x7fc7c1de506a]
12  /opt/conda/envs/gdf/bin/python(_PyEval_EvalFrameDefault+0x45a6) [0x558aba7813f6]
13  /opt/conda/envs/gdf/bin/python(+0x12dfb4) [0x558aba77bfb4]
14  /opt/conda/envs/gdf/bin/python(_PyFunction_Vectorcall+0xd9) [0x558aba78d469]
15  /opt/conda/envs/gdf/bin/python(_PyEval_EvalFrameDefault+0x696) [0x558aba77d4e6]
16  /opt/conda/envs/gdf/bin/python(+0x13f712) [0x558aba78d712]
17  /opt/conda/envs/gdf/bin/python(+0x14ca83) [0x558aba79aa83]
18  /opt/conda/envs/gdf/bin/python(+0x25819c) [0x558aba8a619c]
19  /opt/conda/envs/gdf/bin/python(+0xf23ff) [0x558aba7403ff]
20  /opt/conda/envs/gdf/bin/python(+0x136723) [0x558aba784723]
21  /opt/conda/envs/gdf/bin/python(_PyEval_EvalFrameDefault+0x5ad9) [0x558aba782929]
22  /opt/conda/envs/gdf/bin/python(+0x13f712) [0x558aba78d712]
23  /opt/conda/envs/gdf/bin/python(_PyEval_EvalFrameDefault+0x696) [0x558aba77d4e6]
24  /opt/conda/envs/gdf/bin/python(+0x13f712) [0x558aba78d712]
25  /opt/conda/envs/gdf/bin/python(_PyEval_EvalFrameDefault+0x696) [0x558aba77d4e6]
26  /opt/conda/envs/gdf/bin/python(+0x13f712) [0x558aba78d712]
27  /opt/conda/envs/gdf/bin/python(_PyEval_EvalFrameDefault+0x696) [0x558aba77d4e6]
28  /opt/conda/envs/gdf/bin/python(+0x13f712) [0x558aba78d712]
29  /opt/conda/envs/gdf/bin/python(_PyEval_EvalFrameDefault+0x696) [0x558aba77d4e6]
30  /opt/conda/envs/gdf/bin/python(+0x12dfb4) [0x558aba77bfb4]
31  /opt/conda/envs/gdf/bin/python(_PyFunction_Vectorcall+0xd9) [0x558aba78d469]
32  /opt/conda/envs/gdf/bin/python(_PyEval_EvalFrameDefault+0x11f2) [0x558aba77e042]
33  /opt/conda/envs/gdf/bin/python(+0x12dfb4) [0x558aba77bfb4]
34  /opt/conda/envs/gdf/bin/python(+0x14c8cb) [0x558aba79a8cb]
35  /opt/conda/envs/gdf/bin/python(PyObject_Call+0xbc) [0x558aba79b04c]
36  /opt/conda/envs/gdf/bin/python(+0x21080e) [0x558aba85e80e]
37  /opt/conda/envs/gdf/bin/python(_PyObject_MakeTpCall+0x2ec) [0x558aba7856ac]
38  /opt/conda/envs/gdf/bin/python(_PyEval_EvalFrameDefault+0x45a6) [0x558aba7813f6]
39  /opt/conda/envs/gdf/bin/python(+0x13f712) [0x558aba78d712]
40  /opt/conda/envs/gdf/bin/python(+0x14c9ac) [0x558aba79a9ac]
41  /opt/conda/envs/gdf/bin/python(_PyEval_EvalFrameDefault+0x45a6) [0x558aba7813f6]
42  /opt/conda/envs/gdf/bin/python(+0x13f712) [0x558aba78d712]
43  /opt/conda/envs/gdf/bin/python(_PyEval_EvalFrameDefault+0x696) [0x558aba77d4e6]
44  /opt/conda/envs/gdf/bin/python(+0x12dfb4) [0x558aba77bfb4]
45  /opt/conda/envs/gdf/bin/python(_PyFunction_Vectorcall+0xd9) [0x558aba78d469]
46  /opt/conda/envs/gdf/bin/python(_PyEval_EvalFrameDefault+0x696) [0x558aba77d4e6]
47  /opt/conda/envs/gdf/bin/python(+0x13f712) [0x558aba78d712]
48  /opt/conda/envs/gdf/bin/python(_PyEval_EvalFrameDefault+0x3e2) [0x558aba77d232]
49  /opt/conda/envs/gdf/bin/python(+0x12dfb4) [0x558aba77bfb4]
50  /opt/conda/envs/gdf/bin/python(_PyFunction_Vectorcall+0xd9) [0x558aba78d469]
51  /opt/conda/envs/gdf/bin/python(_PyEval_EvalFrameDefault+0x11f2) [0x558aba77e042]
52  /opt/conda/envs/gdf/bin/python(+0x12dfb4) [0x558aba77bfb4]
53  /opt/conda/envs/gdf/bin/python(_PyEval_EvalCodeWithName+0x48) [0x558aba77bc88]
54  /opt/conda/envs/gdf/bin/python(PyEval_EvalCodeEx+0x39) [0x558aba77bc39]
55  /opt/conda/envs/gdf/bin/python(PyEval_EvalCode+0x1b) [0x558aba8292cb]
56  /opt/conda/envs/gdf/bin/python(+0x2086ca) [0x558aba8566ca]
57  /opt/conda/envs/gdf/bin/python(+0x204a63) [0x558aba852a63]
58  /opt/conda/envs/gdf/bin/python(PyRun_StringFlags+0x9a) [0x558aba84a87a]
59  /opt/conda/envs/gdf/bin/python(PyRun_SimpleStringFlags+0x3c) [0x558aba84a76c]
60  /opt/conda/envs/gdf/bin/python(Py_RunMain+0x267) [0x558aba8499a7]
61  /opt/conda/envs/gdf/bin/python(Py_BytesMain+0x37) [0x558aba81d107]
=================================
[dgx13:76998:0:76998] Caught signal 11 (Segmentation fault: address not mapped to object at address 0x448)
==== backtrace (tid:  76998) ====
 0  /opt/conda/envs/gdf/lib/libucs.so.0(ucs_handle_error+0x2fd) [0x7f69a4a8507d]
 1  /opt/conda/envs/gdf/lib/libucs.so.0(+0x2a274) [0x7f69a4a85274]
 2  /opt/conda/envs/gdf/lib/libucs.so.0(+0x2a43a) [0x7f69a4a8543a]
 3  /usr/lib/x86_64-linux-gnu/libpthread.so.0(+0x14420) [0x7f69dda9c420]
 4  /opt/conda/envs/gdf/lib/libucp.so.0(ucp_mem_type_unpack+0x14) [0x7f69a4b046b4]
 5  /opt/conda/envs/gdf/lib/libucp.so.0(ucp_rndv_data_handler+0x4e9) [0x7f69a4b2d839]
 6  /opt/conda/envs/gdf/lib/libuct.so.0(+0x203df) [0x7f69a4a3f3df]
 7  /opt/conda/envs/gdf/lib/libuct.so.0(+0x23838) [0x7f69a4a42838]
 8  /opt/conda/envs/gdf/lib/libucs.so.0(ucs_event_set_wait+0xb9) [0x7f69a4a8e4a9]
 9  /opt/conda/envs/gdf/lib/libuct.so.0(uct_tcp_iface_progress+0x7d) [0x7f69a4a415dd]
10  /opt/conda/envs/gdf/lib/libucp.so.0(ucp_worker_progress+0x5a) [0x7f69a4b018da]
11  /opt/conda/envs/gdf/lib/python3.9/site-packages/ucp/_libs/ucx_api.cpython-39-x86_64-linux-gnu.so(+0x3206a) [0x7f69a4bba06a]
12  /opt/conda/envs/gdf/bin/python(_PyEval_EvalFrameDefault+0x45a6) [0x55a5f2aa63f6]
13  /opt/conda/envs/gdf/bin/python(+0x12dfb4) [0x55a5f2aa0fb4]
14  /opt/conda/envs/gdf/bin/python(_PyFunction_Vectorcall+0xd9) [0x55a5f2ab2469]
15  /opt/conda/envs/gdf/bin/python(_PyEval_EvalFrameDefault+0x696) [0x55a5f2aa24e6]
16  /opt/conda/envs/gdf/bin/python(+0x13f712) [0x55a5f2ab2712]
17  /opt/conda/envs/gdf/bin/python(+0x14ca83) [0x55a5f2abfa83]
18  /opt/conda/envs/gdf/bin/python(+0x25819c) [0x55a5f2bcb19c]
19  /opt/conda/envs/gdf/bin/python(+0xf23ff) [0x55a5f2a653ff]
20  /opt/conda/envs/gdf/bin/python(+0x136723) [0x55a5f2aa9723]
21  /opt/conda/envs/gdf/bin/python(_PyEval_EvalFrameDefault+0x5ad9) [0x55a5f2aa7929]
22  /opt/conda/envs/gdf/bin/python(+0x13f712) [0x55a5f2ab2712]
23  /opt/conda/envs/gdf/bin/python(_PyEval_EvalFrameDefault+0x696) [0x55a5f2aa24e6]
24  /opt/conda/envs/gdf/bin/python(+0x13f712) [0x55a5f2ab2712]
25  /opt/conda/envs/gdf/bin/python(_PyEval_EvalFrameDefault+0x696) [0x55a5f2aa24e6]
26  /opt/conda/envs/gdf/bin/python(+0x13f712) [0x55a5f2ab2712]
27  /opt/conda/envs/gdf/bin/python(_PyEval_EvalFrameDefault+0x696) [0x55a5f2aa24e6]
28  /opt/conda/envs/gdf/bin/python(+0x13f712) [0x55a5f2ab2712]
29  /opt/conda/envs/gdf/bin/python(_PyEval_EvalFrameDefault+0x696) [0x55a5f2aa24e6]
30  /opt/conda/envs/gdf/bin/python(+0x12dfb4) [0x55a5f2aa0fb4]
31  /opt/conda/envs/gdf/bin/python(_PyFunction_Vectorcall+0xd9) [0x55a5f2ab2469]
32  /opt/conda/envs/gdf/bin/python(_PyEval_EvalFrameDefault+0x11f2) [0x55a5f2aa3042]
33  /opt/conda/envs/gdf/bin/python(+0x12dfb4) [0x55a5f2aa0fb4]
34  /opt/conda/envs/gdf/bin/python(+0x14c8cb) [0x55a5f2abf8cb]
35  /opt/conda/envs/gdf/bin/python(PyObject_Call+0xbc) [0x55a5f2ac004c]
36  /opt/conda/envs/gdf/bin/python(+0x21080e) [0x55a5f2b8380e]
37  /opt/conda/envs/gdf/bin/python(_PyObject_MakeTpCall+0x2ec) [0x55a5f2aaa6ac]
38  /opt/conda/envs/gdf/bin/python(_PyEval_EvalFrameDefault+0x45a6) [0x55a5f2aa63f6]
39  /opt/conda/envs/gdf/bin/python(+0x13f712) [0x55a5f2ab2712]
40  /opt/conda/envs/gdf/bin/python(+0x14c9ac) [0x55a5f2abf9ac]
41  /opt/conda/envs/gdf/bin/python(_PyEval_EvalFrameDefault+0x45a6) [0x55a5f2aa63f6]
42  /opt/conda/envs/gdf/bin/python(+0x13f712) [0x55a5f2ab2712]
43  /opt/conda/envs/gdf/bin/python(_PyEval_EvalFrameDefault+0x696) [0x55a5f2aa24e6]
44  /opt/conda/envs/gdf/bin/python(+0x12dfb4) [0x55a5f2aa0fb4]
45  /opt/conda/envs/gdf/bin/python(_PyFunction_Vectorcall+0xd9) [0x55a5f2ab2469]
46  /opt/conda/envs/gdf/bin/python(_PyEval_EvalFrameDefault+0x696) [0x55a5f2aa24e6]
47  /opt/conda/envs/gdf/bin/python(+0x13f712) [0x55a5f2ab2712]
48  /opt/conda/envs/gdf/bin/python(_PyEval_EvalFrameDefault+0x3e2) [0x55a5f2aa2232]
49  /opt/conda/envs/gdf/bin/python(+0x12dfb4) [0x55a5f2aa0fb4]
50  /opt/conda/envs/gdf/bin/python(_PyFunction_Vectorcall+0xd9) [0x55a5f2ab2469]
51  /opt/conda/envs/gdf/bin/python(_PyEval_EvalFrameDefault+0x11f2) [0x55a5f2aa3042]
52  /opt/conda/envs/gdf/bin/python(+0x12dfb4) [0x55a5f2aa0fb4]
53  /opt/conda/envs/gdf/bin/python(_PyEval_EvalCodeWithName+0x48) [0x55a5f2aa0c88]
54  /opt/conda/envs/gdf/bin/python(PyEval_EvalCodeEx+0x39) [0x55a5f2aa0c39]
55  /opt/conda/envs/gdf/bin/python(PyEval_EvalCode+0x1b) [0x55a5f2b4e2cb]
56  /opt/conda/envs/gdf/bin/python(+0x2086ca) [0x55a5f2b7b6ca]
57  /opt/conda/envs/gdf/bin/python(+0x204a63) [0x55a5f2b77a63]
58  /opt/conda/envs/gdf/bin/python(PyRun_StringFlags+0x9a) [0x55a5f2b6f87a]
59  /opt/conda/envs/gdf/bin/python(PyRun_SimpleStringFlags+0x3c) [0x55a5f2b6f76c]
60  /opt/conda/envs/gdf/bin/python(Py_RunMain+0x267) [0x55a5f2b6e9a7]
61  /opt/conda/envs/gdf/bin/python(Py_BytesMain+0x37) [0x55a5f2b42107]
=================================
[dgx13:76980:0:76980] Caught signal 11 (Segmentation fault: address not mapped to object at address 0x448)
==== backtrace (tid:  76980) ====
 0  /opt/conda/envs/gdf/lib/libucs.so.0(ucs_handle_error+0x2fd) [0x7fa11d4e307d]
 1  /opt/conda/envs/gdf/lib/libucs.so.0(+0x2a274) [0x7fa11d4e3274]
 2  /opt/conda/envs/gdf/lib/libucs.so.0(+0x2a43a) [0x7fa11d4e343a]
 3  /usr/lib/x86_64-linux-gnu/libpthread.so.0(+0x14420) [0x7fa15a52b420]
 4  /opt/conda/envs/gdf/lib/libucp.so.0(ucp_mem_type_unpack+0x14) [0x7fa11d5626b4]
 5  /opt/conda/envs/gdf/lib/libucp.so.0(ucp_rndv_data_handler+0x4e9) [0x7fa11d58b839]
 6  /opt/conda/envs/gdf/lib/libuct.so.0(+0x203df) [0x7fa1300243df]
 7  /opt/conda/envs/gdf/lib/libuct.so.0(+0x23838) [0x7fa130027838]
 8  /opt/conda/envs/gdf/lib/libucs.so.0(ucs_event_set_wait+0xb9) [0x7fa11d4ec4a9]
 9  /opt/conda/envs/gdf/lib/libuct.so.0(uct_tcp_iface_progress+0x7d) [0x7fa1300265dd]
10  /opt/conda/envs/gdf/lib/libucp.so.0(ucp_worker_progress+0x5a) [0x7fa11d55f8da]
11  /opt/conda/envs/gdf/lib/python3.9/site-packages/ucp/_libs/ucx_api.cpython-39-x86_64-linux-gnu.so(+0x3206a) [0x7fa11d61806a]
12  /opt/conda/envs/gdf/bin/python(_PyEval_EvalFrameDefault+0x45a6) [0x56316a9cc3f6]
13  /opt/conda/envs/gdf/bin/python(+0x12dfb4) [0x56316a9c6fb4]
14  /opt/conda/envs/gdf/bin/python(_PyFunction_Vectorcall+0xd9) [0x56316a9d8469]
15  /opt/conda/envs/gdf/bin/python(_PyEval_EvalFrameDefault+0x696) [0x56316a9c84e6]
16  /opt/conda/envs/gdf/bin/python(+0x1e26d2) [0x56316aa7b6d2]
17  /opt/conda/envs/gdf/lib/python3.9/lib-dynload/_asyncio.cpython-39-x86_64-linux-gnu.so(+0x81e9) [0x7fa1503b41e9]
18  /opt/conda/envs/gdf/bin/python(_PyObject_MakeTpCall+0x2ec) [0x56316a9d06ac]
19  /opt/conda/envs/gdf/bin/python(+0xf23ff) [0x56316a98b3ff]
20  /opt/conda/envs/gdf/bin/python(+0x136723) [0x56316a9cf723]
21  /opt/conda/envs/gdf/bin/python(_PyEval_EvalFrameDefault+0x5ad9) [0x56316a9cd929]
22  /opt/conda/envs/gdf/bin/python(+0x13f712) [0x56316a9d8712]
23  /opt/conda/envs/gdf/bin/python(_PyEval_EvalFrameDefault+0x696) [0x56316a9c84e6]
24  /opt/conda/envs/gdf/bin/python(+0x13f712) [0x56316a9d8712]
25  /opt/conda/envs/gdf/bin/python(_PyEval_EvalFrameDefault+0x696) [0x56316a9c84e6]
26  /opt/conda/envs/gdf/bin/python(+0x13f712) [0x56316a9d8712]
27  /opt/conda/envs/gdf/bin/python(_PyEval_EvalFrameDefault+0x696) [0x56316a9c84e6]
28  /opt/conda/envs/gdf/bin/python(+0x13f712) [0x56316a9d8712]
29  /opt/conda/envs/gdf/bin/python(_PyEval_EvalFrameDefault+0x696) [0x56316a9c84e6]
30  /opt/conda/envs/gdf/bin/python(+0x12dfb4) [0x56316a9c6fb4]
31  /opt/conda/envs/gdf/bin/python(_PyFunction_Vectorcall+0xd9) [0x56316a9d8469]
32  /opt/conda/envs/gdf/bin/python(_PyEval_EvalFrameDefault+0x11f2) [0x56316a9c9042]
33  /opt/conda/envs/gdf/bin/python(+0x12dfb4) [0x56316a9c6fb4]
34  /opt/conda/envs/gdf/bin/python(+0x14c8cb) [0x56316a9e58cb]
35  /opt/conda/envs/gdf/bin/python(PyObject_Call+0xbc) [0x56316a9e604c]
36  /opt/conda/envs/gdf/bin/python(+0x21080e) [0x56316aaa980e]
37  /opt/conda/envs/gdf/bin/python(_PyObject_MakeTpCall+0x2ec) [0x56316a9d06ac]
38  /opt/conda/envs/gdf/bin/python(_PyEval_EvalFrameDefault+0x45a6) [0x56316a9cc3f6]
39  /opt/conda/envs/gdf/bin/python(+0x13f712) [0x56316a9d8712]
40  /opt/conda/envs/gdf/bin/python(+0x14c9ac) [0x56316a9e59ac]
41  /opt/conda/envs/gdf/bin/python(_PyEval_EvalFrameDefault+0x45a6) [0x56316a9cc3f6]
42  /opt/conda/envs/gdf/bin/python(+0x13f712) [0x56316a9d8712]
43  /opt/conda/envs/gdf/bin/python(_PyEval_EvalFrameDefault+0x696) [0x56316a9c84e6]
44  /opt/conda/envs/gdf/bin/python(+0x12dfb4) [0x56316a9c6fb4]
45  /opt/conda/envs/gdf/bin/python(_PyFunction_Vectorcall+0xd9) [0x56316a9d8469]
46  /opt/conda/envs/gdf/bin/python(_PyEval_EvalFrameDefault+0x696) [0x56316a9c84e6]
47  /opt/conda/envs/gdf/bin/python(+0x13f712) [0x56316a9d8712]
48  /opt/conda/envs/gdf/bin/python(_PyEval_EvalFrameDefault+0x3e2) [0x56316a9c8232]
49  /opt/conda/envs/gdf/bin/python(+0x12dfb4) [0x56316a9c6fb4]
50  /opt/conda/envs/gdf/bin/python(_PyFunction_Vectorcall+0xd9) [0x56316a9d8469]
51  /opt/conda/envs/gdf/bin/python(_PyEval_EvalFrameDefault+0x11f2) [0x56316a9c9042]
52  /opt/conda/envs/gdf/bin/python(+0x12dfb4) [0x56316a9c6fb4]
53  /opt/conda/envs/gdf/bin/python(_PyEval_EvalCodeWithName+0x48) [0x56316a9c6c88]
54  /opt/conda/envs/gdf/bin/python(PyEval_EvalCodeEx+0x39) [0x56316a9c6c39]
55  /opt/conda/envs/gdf/bin/python(PyEval_EvalCode+0x1b) [0x56316aa742cb]
56  /opt/conda/envs/gdf/bin/python(+0x2086ca) [0x56316aaa16ca]
57  /opt/conda/envs/gdf/bin/python(+0x204a63) [0x56316aa9da63]
58  /opt/conda/envs/gdf/bin/python(PyRun_StringFlags+0x9a) [0x56316aa9587a]
59  /opt/conda/envs/gdf/bin/python(PyRun_SimpleStringFlags+0x3c) [0x56316aa9576c]
60  /opt/conda/envs/gdf/bin/python(Py_RunMain+0x267) [0x56316aa949a7]
61  /opt/conda/envs/gdf/bin/python(Py_BytesMain+0x37) [0x56316aa68107]
=================================
Task exception was never retrieved
future: <Task finished name='Task-304' coro=<_listener_handler_coroutine() done, defined at /opt/conda/envs/gdf/lib/python3.9/site-packages/ucp/core.py:140> exception=UCXError('<stream_recv>: Connection reset by remote peer')>
Traceback (most recent call last):
  File "/opt/conda/envs/gdf/lib/python3.9/site-packages/ucp/core.py", line 155, in _listener_handler_coroutine
    peer_info = await exchange_peer_info(
  File "/opt/conda/envs/gdf/lib/python3.9/site-packages/ucp/core.py", line 55, in exchange_peer_info
    await asyncio.wait_for(
  File "/opt/conda/envs/gdf/lib/python3.9/asyncio/tasks.py", line 479, in wait_for
    return fut.result()
ucp._libs.exceptions.UCXError: <stream_recv>: Connection reset by remote peer
Task exception was never retrieved
future: <Task finished name='Task-313' coro=<_listener_handler_coroutine() done, defined at /opt/conda/envs/gdf/lib/python3.9/site-packages/ucp/core.py:140> exception=UCXError('<stream_send>: Endpoint timeout')>
Traceback (most recent call last):
  File "/opt/conda/envs/gdf/lib/python3.9/site-packages/ucp/core.py", line 155, in _listener_handler_coroutine
    peer_info = await exchange_peer_info(
  File "/opt/conda/envs/gdf/lib/python3.9/site-packages/ucp/core.py", line 51, in exchange_peer_info
    await asyncio.wait_for(
  File "/opt/conda/envs/gdf/lib/python3.9/asyncio/tasks.py", line 479, in wait_for
    return fut.result()
ucp._libs.exceptions.UCXError: <stream_send>: Endpoint timeout
2024-02-28 07:30:02,658 - distributed.worker - ERROR - Worker stream died during communication: ucx://127.0.0.1:50885
Traceback (most recent call last):
  File "/opt/conda/envs/gdf/lib/python3.9/site-packages/distributed/comm/ucx.py", line 350, in read
    await self.ep.recv(msg)
  File "/opt/conda/envs/gdf/lib/python3.9/site-packages/ucp/core.py", line 737, in recv
    ret = await comm.tag_recv(self._ep, buffer, nbytes, tag, name=log)
ucp._libs.exceptions.UCXCanceled: <[Recv #000] ep: 0x7fd34502e140, tag: 0x504a6a99587a8f61, nbytes: 16, type: <class 'numpy.ndarray'>>: 

During handling of the above exception, another exception occurred:

Traceback (most recent call last):
  File "/opt/conda/envs/gdf/lib/python3.9/site-packages/distributed/worker.py", line 2056, in gather_dep
    response = await get_data_from_worker(
  File "/opt/conda/envs/gdf/lib/python3.9/site-packages/distributed/worker.py", line 2857, in get_data_from_worker
    comm = await rpc.connect(worker)
  File "/opt/conda/envs/gdf/lib/python3.9/site-packages/distributed/core.py", line 1674, in connect
    return connect_attempt.result()
  File "/opt/conda/envs/gdf/lib/python3.9/site-packages/distributed/core.py", line 1564, in _connect
    comm = await connect(
  File "/opt/conda/envs/gdf/lib/python3.9/site-packages/distributed/comm/core.py", line 377, in connect
    handshake = await comm.read()
  File "/opt/conda/envs/gdf/lib/python3.9/site-packages/distributed/utils.py", line 832, in wrapper
    return await func(*args, **kwargs)
  File "/opt/conda/envs/gdf/lib/python3.9/site-packages/distributed/comm/ucx.py", line 368, in read
    raise CommClosedError(
distributed.comm.core.CommClosedError: Connection closed by writer.
Inner exception: UCXCanceled("<[Recv #000] ep: 0x7fd34502e140, tag: 0x504a6a99587a8f61, nbytes: 16, type: <class 'numpy.ndarray'>>: ")
2024-02-28 07:30:02,716 - distributed.worker - ERROR - Worker stream died during communication: ucx://127.0.0.1:33317
Traceback (most recent call last):
  File "/opt/conda/envs/gdf/lib/python3.9/site-packages/distributed/comm/ucx.py", line 350, in read
    await self.ep.recv(msg)
  File "/opt/conda/envs/gdf/lib/python3.9/site-packages/ucp/core.py", line 737, in recv
    ret = await comm.tag_recv(self._ep, buffer, nbytes, tag, name=log)
ucp._libs.exceptions.UCXCanceled: <[Recv #003] ep: 0x7fd34502e100, tag: 0x1af6cfdf9693fa7c, nbytes: 16, type: <class 'numpy.ndarray'>>: 

During handling of the above exception, another exception occurred:

Traceback (most recent call last):
  File "/opt/conda/envs/gdf/lib/python3.9/site-packages/distributed/worker.py", line 2056, in gather_dep
    response = await get_data_from_worker(
  File "/opt/conda/envs/gdf/lib/python3.9/site-packages/distributed/worker.py", line 2860, in get_data_from_worker
    response = await send_recv(
  File "/opt/conda/envs/gdf/lib/python3.9/site-packages/distributed/core.py", line 1154, in send_recv
    response = await comm.read(deserializers=deserializers)
  File "/opt/conda/envs/gdf/lib/python3.9/site-packages/distributed/utils.py", line 832, in wrapper
    return await func(*args, **kwargs)
  File "/opt/conda/envs/gdf/lib/python3.9/site-packages/distributed/comm/ucx.py", line 368, in read
    raise CommClosedError(
distributed.comm.core.CommClosedError: Connection closed by writer.
Inner exception: UCXCanceled("<[Recv #003] ep: 0x7fd34502e100, tag: 0x1af6cfdf9693fa7c, nbytes: 16, type: <class 'numpy.ndarray'>>: ")
2024-02-28 07:30:02,811 - distributed.worker - ERROR - failed during get data with ucx://127.0.0.1:42499 -> ucx://127.0.0.1:49027
Traceback (most recent call last):
  File "/opt/conda/envs/gdf/lib/python3.9/site-packages/distributed/comm/ucx.py", line 334, in write
    await self.ep.send(each_frame)
  File "/opt/conda/envs/gdf/lib/python3.9/site-packages/ucp/core.py", line 662, in send
    return await comm.tag_send(self._ep, buffer, nbytes, tag, name=log)
ucp._libs.exceptions.UCXError: <[Send #007] ep: 0x7fd34502e2c0, tag: 0x99651d38e0137f25, nbytes: 50000000, type: <class 'cupy.ndarray'>>: Connection reset by remote peer

During handling of the above exception, another exception occurred:

Traceback (most recent call last):
  File "/opt/conda/envs/gdf/lib/python3.9/site-packages/distributed/worker.py", line 1779, in get_data
    compressed = await comm.write(msg, serializers=serializers)
  File "/opt/conda/envs/gdf/lib/python3.9/site-packages/distributed/utils.py", line 832, in wrapper
    return await func(*args, **kwargs)
  File "/opt/conda/envs/gdf/lib/python3.9/site-packages/distributed/comm/ucx.py", line 338, in write
    raise CommClosedError("While writing, the connection was closed")
distributed.comm.core.CommClosedError: While writing, the connection was closed
2024-02-28 07:30:02,825 - distributed.worker - ERROR - failed during get data with ucx://127.0.0.1:42499 -> ucx://127.0.0.1:59283
Traceback (most recent call last):
  File "/opt/conda/envs/gdf/lib/python3.9/site-packages/distributed/comm/ucx.py", line 334, in write
    await self.ep.send(each_frame)
  File "/opt/conda/envs/gdf/lib/python3.9/site-packages/ucp/core.py", line 662, in send
    return await comm.tag_send(self._ep, buffer, nbytes, tag, name=log)
ucp._libs.exceptions.UCXError: <[Send #007] ep: 0x7fd34502e340, tag: 0x429bc695424648da, nbytes: 50000000, type: <class 'cupy.ndarray'>>: Connection reset by remote peer

During handling of the above exception, another exception occurred:

Traceback (most recent call last):
  File "/opt/conda/envs/gdf/lib/python3.9/site-packages/distributed/worker.py", line 1779, in get_data
    compressed = await comm.write(msg, serializers=serializers)
  File "/opt/conda/envs/gdf/lib/python3.9/site-packages/distributed/utils.py", line 832, in wrapper
    return await func(*args, **kwargs)
  File "/opt/conda/envs/gdf/lib/python3.9/site-packages/distributed/comm/ucx.py", line 338, in write
    raise CommClosedError("While writing, the connection was closed")
distributed.comm.core.CommClosedError: While writing, the connection was closed
2024-02-28 07:30:02,833 - distributed.worker - ERROR - Worker stream died during communication: ucx://127.0.0.1:44409
Traceback (most recent call last):
  File "/opt/conda/envs/gdf/lib/python3.9/site-packages/distributed/comm/ucx.py", line 350, in read
    await self.ep.recv(msg)
  File "/opt/conda/envs/gdf/lib/python3.9/site-packages/ucp/core.py", line 737, in recv
    ret = await comm.tag_recv(self._ep, buffer, nbytes, tag, name=log)
ucp._libs.exceptions.UCXCanceled: <[Recv #013] ep: 0x7fd34502e0c0, tag: 0xc03a3f126b89feee, nbytes: 16, type: <class 'numpy.ndarray'>>: 

During handling of the above exception, another exception occurred:

Traceback (most recent call last):
  File "/opt/conda/envs/gdf/lib/python3.9/site-packages/distributed/worker.py", line 2056, in gather_dep
    response = await get_data_from_worker(
  File "/opt/conda/envs/gdf/lib/python3.9/site-packages/distributed/worker.py", line 2860, in get_data_from_worker
    response = await send_recv(
  File "/opt/conda/envs/gdf/lib/python3.9/site-packages/distributed/core.py", line 1154, in send_recv
    response = await comm.read(deserializers=deserializers)
  File "/opt/conda/envs/gdf/lib/python3.9/site-packages/distributed/utils.py", line 832, in wrapper
    return await func(*args, **kwargs)
  File "/opt/conda/envs/gdf/lib/python3.9/site-packages/distributed/comm/ucx.py", line 368, in read
    raise CommClosedError(
distributed.comm.core.CommClosedError: Connection closed by writer.
Inner exception: UCXCanceled("<[Recv #013] ep: 0x7fd34502e0c0, tag: 0xc03a3f126b89feee, nbytes: 16, type: <class 'numpy.ndarray'>>: ")
2024-02-28 07:30:02,832 - distributed.worker - ERROR - Worker stream died during communication: ucx://127.0.0.1:44409
Traceback (most recent call last):
  File "/opt/conda/envs/gdf/lib/python3.9/site-packages/distributed/comm/ucx.py", line 392, in read
    await self.ep.recv(each_frame)
  File "/opt/conda/envs/gdf/lib/python3.9/site-packages/ucp/core.py", line 737, in recv
    ret = await comm.tag_recv(self._ep, buffer, nbytes, tag, name=log)
ucp._libs.exceptions.UCXError: <[Recv #007] ep: 0x7fcdc8177180, tag: 0x45e821cfc135b455, nbytes: 50000000, type: <class 'rmm._lib.device_buffer.DeviceBuffer'>>: Connection reset by remote peer

During handling of the above exception, another exception occurred:

Traceback (most recent call last):
  File "/opt/conda/envs/gdf/lib/python3.9/site-packages/distributed/worker.py", line 2056, in gather_dep
    response = await get_data_from_worker(
  File "/opt/conda/envs/gdf/lib/python3.9/site-packages/distributed/worker.py", line 2860, in get_data_from_worker
    response = await send_recv(
  File "/opt/conda/envs/gdf/lib/python3.9/site-packages/distributed/core.py", line 1154, in send_recv
    response = await comm.read(deserializers=deserializers)
  File "/opt/conda/envs/gdf/lib/python3.9/site-packages/distributed/utils.py", line 832, in wrapper
    return await func(*args, **kwargs)
  File "/opt/conda/envs/gdf/lib/python3.9/site-packages/distributed/comm/ucx.py", line 398, in read
    raise CommClosedError(
distributed.comm.core.CommClosedError: Connection closed by writer.
Inner exception: UCXError("<[Recv #007] ep: 0x7fcdc8177180, tag: 0x45e821cfc135b455, nbytes: 50000000, type: <class 'rmm._lib.device_buffer.DeviceBuffer'>>: Connection reset by remote peer")
2024-02-28 07:30:02,834 - distributed.worker - ERROR - failed during get data with ucx://127.0.0.1:55219 -> ucx://127.0.0.1:44409
Traceback (most recent call last):
  File "/opt/conda/envs/gdf/lib/python3.9/site-packages/distributed/comm/ucx.py", line 334, in write
    await self.ep.send(each_frame)
  File "/opt/conda/envs/gdf/lib/python3.9/site-packages/ucp/core.py", line 662, in send
    return await comm.tag_send(self._ep, buffer, nbytes, tag, name=log)
ucp._libs.exceptions.UCXError: <[Send #007] ep: 0x7fcdc8177200, tag: 0x85c83d1c6e646c5f, nbytes: 50000000, type: <class 'cupy.ndarray'>>: Connection reset by remote peer

During handling of the above exception, another exception occurred:

Traceback (most recent call last):
  File "/opt/conda/envs/gdf/lib/python3.9/site-packages/distributed/worker.py", line 1779, in get_data
    compressed = await comm.write(msg, serializers=serializers)
  File "/opt/conda/envs/gdf/lib/python3.9/site-packages/distributed/utils.py", line 832, in wrapper
    return await func(*args, **kwargs)
  File "/opt/conda/envs/gdf/lib/python3.9/site-packages/distributed/comm/ucx.py", line 338, in write
    raise CommClosedError("While writing, the connection was closed")
distributed.comm.core.CommClosedError: While writing, the connection was closed
2024-02-28 07:30:06,944 - distributed.nanny - WARNING - Restarting worker
2024-02-28 07:30:07,212 - distributed.nanny - WARNING - Restarting worker
2024-02-28 07:30:07,240 - distributed.nanny - WARNING - Restarting worker
2024-02-28 07:30:07,242 - distributed.nanny - WARNING - Restarting worker
2024-02-28 07:30:07,253 - distributed.nanny - WARNING - Restarting worker
2024-02-28 07:30:07,264 - distributed.nanny - WARNING - Restarting worker
[dgx13:77145:0:77145] Caught signal 11 (Segmentation fault: address not mapped to object at address 0x448)
==== backtrace (tid:  77145) ====
 0  /opt/conda/envs/gdf/lib/libucs.so.0(ucs_handle_error+0x2fd) [0x7f3e18ce207d]
 1  /opt/conda/envs/gdf/lib/libucs.so.0(+0x2a274) [0x7f3e18ce2274]
 2  /opt/conda/envs/gdf/lib/libucs.so.0(+0x2a43a) [0x7f3e18ce243a]
 3  /usr/lib/x86_64-linux-gnu/libpthread.so.0(+0x14420) [0x7f3e51b75420]
 4  /opt/conda/envs/gdf/lib/libucp.so.0(ucp_mem_type_unpack+0x14) [0x7f3e18d616b4]
 5  /opt/conda/envs/gdf/lib/libucp.so.0(ucp_rndv_data_handler+0x4e9) [0x7f3e18d8a839]
 6  /opt/conda/envs/gdf/lib/libuct.so.0(+0x203df) [0x7f3e18c9c3df]
 7  /opt/conda/envs/gdf/lib/libuct.so.0(+0x23838) [0x7f3e18c9f838]
 8  /opt/conda/envs/gdf/lib/libucs.so.0(ucs_event_set_wait+0xb9) [0x7f3e18ceb4a9]
 9  /opt/conda/envs/gdf/lib/libuct.so.0(uct_tcp_iface_progress+0x7d) [0x7f3e18c9e5dd]
10  /opt/conda/envs/gdf/lib/libucp.so.0(ucp_worker_progress+0x5a) [0x7f3e18d5e8da]
11  /opt/conda/envs/gdf/lib/python3.9/site-packages/ucp/_libs/ucx_api.cpython-39-x86_64-linux-gnu.so(+0x3206a) [0x7f3e18e1706a]
12  /opt/conda/envs/gdf/bin/python(_PyEval_EvalFrameDefault+0x45a6) [0x55cce4cb03f6]
13  /opt/conda/envs/gdf/bin/python(+0x12dfb4) [0x55cce4caafb4]
14  /opt/conda/envs/gdf/bin/python(_PyFunction_Vectorcall+0xd9) [0x55cce4cbc469]
15  /opt/conda/envs/gdf/bin/python(_PyEval_EvalFrameDefault+0x696) [0x55cce4cac4e6]
16  /opt/conda/envs/gdf/bin/python(+0x13f712) [0x55cce4cbc712]
17  /opt/conda/envs/gdf/bin/python(+0x14ca83) [0x55cce4cc9a83]
18  /opt/conda/envs/gdf/bin/python(+0x25819c) [0x55cce4dd519c]
19  /opt/conda/envs/gdf/bin/python(+0xf23ff) [0x55cce4c6f3ff]
20  /opt/conda/envs/gdf/bin/python(+0x136723) [0x55cce4cb3723]
21  /opt/conda/envs/gdf/bin/python(_PyEval_EvalFrameDefault+0x5ad9) [0x55cce4cb1929]
22  /opt/conda/envs/gdf/bin/python(+0x13f712) [0x55cce4cbc712]
23  /opt/conda/envs/gdf/bin/python(_PyEval_EvalFrameDefault+0x696) [0x55cce4cac4e6]
24  /opt/conda/envs/gdf/bin/python(+0x13f712) [0x55cce4cbc712]
25  /opt/conda/envs/gdf/bin/python(_PyEval_EvalFrameDefault+0x696) [0x55cce4cac4e6]
26  /opt/conda/envs/gdf/bin/python(+0x13f712) [0x55cce4cbc712]
27  /opt/conda/envs/gdf/bin/python(_PyEval_EvalFrameDefault+0x696) [0x55cce4cac4e6]
28  /opt/conda/envs/gdf/bin/python(+0x13f712) [0x55cce4cbc712]
29  /opt/conda/envs/gdf/bin/python(_PyEval_EvalFrameDefault+0x696) [0x55cce4cac4e6]
30  /opt/conda/envs/gdf/bin/python(+0x12dfb4) [0x55cce4caafb4]
31  /opt/conda/envs/gdf/bin/python(_PyFunction_Vectorcall+0xd9) [0x55cce4cbc469]
32  /opt/conda/envs/gdf/bin/python(_PyEval_EvalFrameDefault+0x11f2) [0x55cce4cad042]
33  /opt/conda/envs/gdf/bin/python(+0x12dfb4) [0x55cce4caafb4]
34  /opt/conda/envs/gdf/bin/python(+0x14c8cb) [0x55cce4cc98cb]
35  /opt/conda/envs/gdf/bin/python(PyObject_Call+0xbc) [0x55cce4cca04c]
36  /opt/conda/envs/gdf/bin/python(+0x21080e) [0x55cce4d8d80e]
37  /opt/conda/envs/gdf/bin/python(_PyObject_MakeTpCall+0x2ec) [0x55cce4cb46ac]
38  /opt/conda/envs/gdf/bin/python(_PyEval_EvalFrameDefault+0x45a6) [0x55cce4cb03f6]
39  /opt/conda/envs/gdf/bin/python(+0x13f712) [0x55cce4cbc712]
40  /opt/conda/envs/gdf/bin/python(+0x14c9ac) [0x55cce4cc99ac]
41  /opt/conda/envs/gdf/bin/python(_PyEval_EvalFrameDefault+0x45a6) [0x55cce4cb03f6]
42  /opt/conda/envs/gdf/bin/python(+0x13f712) [0x55cce4cbc712]
43  /opt/conda/envs/gdf/bin/python(_PyEval_EvalFrameDefault+0x696) [0x55cce4cac4e6]
44  /opt/conda/envs/gdf/bin/python(+0x12dfb4) [0x55cce4caafb4]
45  /opt/conda/envs/gdf/bin/python(_PyFunction_Vectorcall+0xd9) [0x55cce4cbc469]
46  /opt/conda/envs/gdf/bin/python(_PyEval_EvalFrameDefault+0x696) [0x55cce4cac4e6]
47  /opt/conda/envs/gdf/bin/python(+0x13f712) [0x55cce4cbc712]
48  /opt/conda/envs/gdf/bin/python(_PyEval_EvalFrameDefault+0x3e2) [0x55cce4cac232]
49  /opt/conda/envs/gdf/bin/python(+0x12dfb4) [0x55cce4caafb4]
50  /opt/conda/envs/gdf/bin/python(_PyFunction_Vectorcall+0xd9) [0x55cce4cbc469]
51  /opt/conda/envs/gdf/bin/python(_PyEval_EvalFrameDefault+0x11f2) [0x55cce4cad042]
52  /opt/conda/envs/gdf/bin/python(+0x12dfb4) [0x55cce4caafb4]
53  /opt/conda/envs/gdf/bin/python(_PyEval_EvalCodeWithName+0x48) [0x55cce4caac88]
54  /opt/conda/envs/gdf/bin/python(PyEval_EvalCodeEx+0x39) [0x55cce4caac39]
55  /opt/conda/envs/gdf/bin/python(PyEval_EvalCode+0x1b) [0x55cce4d582cb]
56  /opt/conda/envs/gdf/bin/python(+0x2086ca) [0x55cce4d856ca]
57  /opt/conda/envs/gdf/bin/python(+0x204a63) [0x55cce4d81a63]
58  /opt/conda/envs/gdf/bin/python(PyRun_StringFlags+0x9a) [0x55cce4d7987a]
59  /opt/conda/envs/gdf/bin/python(PyRun_SimpleStringFlags+0x3c) [0x55cce4d7976c]
60  /opt/conda/envs/gdf/bin/python(Py_RunMain+0x267) [0x55cce4d789a7]
61  /opt/conda/envs/gdf/bin/python(Py_BytesMain+0x37) [0x55cce4d4c107]
=================================
[dgx13:77158:0:77158] Caught signal 11 (Segmentation fault: address not mapped to object at address 0x448)
==== backtrace (tid:  77158) ====
 0  /opt/conda/envs/gdf/lib/libucs.so.0(ucs_handle_error+0x2fd) [0x7fbaa5a2707d]
 1  /opt/conda/envs/gdf/lib/libucs.so.0(+0x2a274) [0x7fbaa5a27274]
 2  /opt/conda/envs/gdf/lib/libucs.so.0(+0x2a43a) [0x7fbaa5a2743a]
 3  /usr/lib/x86_64-linux-gnu/libpthread.so.0(+0x14420) [0x7fbae4a3b420]
 4  /opt/conda/envs/gdf/lib/libucp.so.0(ucp_mem_type_unpack+0x14) [0x7fbaa5aa66b4]
 5  /opt/conda/envs/gdf/lib/libucp.so.0(ucp_rndv_data_handler+0x4e9) [0x7fbaa5acf839]
 6  /opt/conda/envs/gdf/lib/libuct.so.0(+0x203df) [0x7fbaa59e13df]
 7  /opt/conda/envs/gdf/lib/libuct.so.0(+0x23838) [0x7fbaa59e4838]
 8  /opt/conda/envs/gdf/lib/libucs.so.0(ucs_event_set_wait+0xb9) [0x7fbaa5a304a9]
 9  /opt/conda/envs/gdf/lib/libuct.so.0(uct_tcp_iface_progress+0x7d) [0x7fbaa59e35dd]
10  /opt/conda/envs/gdf/lib/libucp.so.0(ucp_worker_progress+0x5a) [0x7fbaa5aa38da]
11  /opt/conda/envs/gdf/lib/python3.9/site-packages/ucp/_libs/ucx_api.cpython-39-x86_64-linux-gnu.so(+0x3206a) [0x7fbaa5b5c06a]
12  /opt/conda/envs/gdf/bin/python(_PyEval_EvalFrameDefault+0x45a6) [0x559abb2573f6]
13  /opt/conda/envs/gdf/bin/python(+0x12dfb4) [0x559abb251fb4]
14  /opt/conda/envs/gdf/bin/python(_PyFunction_Vectorcall+0xd9) [0x559abb263469]
15  /opt/conda/envs/gdf/bin/python(_PyEval_EvalFrameDefault+0x696) [0x559abb2534e6]
16  /opt/conda/envs/gdf/bin/python(+0x1e26d2) [0x559abb3066d2]
17  /opt/conda/envs/gdf/lib/python3.9/lib-dynload/_asyncio.cpython-39-x86_64-linux-gnu.so(+0x81e9) [0x7fbada8c31e9]
18  /opt/conda/envs/gdf/bin/python(_PyObject_MakeTpCall+0x2ec) [0x559abb25b6ac]
19  /opt/conda/envs/gdf/bin/python(+0xf23ff) [0x559abb2163ff]
20  /opt/conda/envs/gdf/bin/python(+0x136723) [0x559abb25a723]
21  /opt/conda/envs/gdf/bin/python(_PyEval_EvalFrameDefault+0x5ad9) [0x559abb258929]
22  /opt/conda/envs/gdf/bin/python(+0x13f712) [0x559abb263712]
23  /opt/conda/envs/gdf/bin/python(_PyEval_EvalFrameDefault+0x696) [0x559abb2534e6]
24  /opt/conda/envs/gdf/bin/python(+0x13f712) [0x559abb263712]
25  /opt/conda/envs/gdf/bin/python(_PyEval_EvalFrameDefault+0x696) [0x559abb2534e6]
26  /opt/conda/envs/gdf/bin/python(+0x13f712) [0x559abb263712]
27  /opt/conda/envs/gdf/bin/python(_PyEval_EvalFrameDefault+0x696) [0x559abb2534e6]
28  /opt/conda/envs/gdf/bin/python(+0x13f712) [0x559abb263712]
29  /opt/conda/envs/gdf/bin/python(_PyEval_EvalFrameDefault+0x696) [0x559abb2534e6]
30  /opt/conda/envs/gdf/bin/python(+0x12dfb4) [0x559abb251fb4]
31  /opt/conda/envs/gdf/bin/python(_PyFunction_Vectorcall+0xd9) [0x559abb263469]
32  /opt/conda/envs/gdf/bin/python(_PyEval_EvalFrameDefault+0x11f2) [0x559abb254042]
33  /opt/conda/envs/gdf/bin/python(+0x12dfb4) [0x559abb251fb4]
34  /opt/conda/envs/gdf/bin/python(+0x14c8cb) [0x559abb2708cb]
35  /opt/conda/envs/gdf/bin/python(PyObject_Call+0xbc) [0x559abb27104c]
36  /opt/conda/envs/gdf/bin/python(+0x21080e) [0x559abb33480e]
37  /opt/conda/envs/gdf/bin/python(_PyObject_MakeTpCall+0x2ec) [0x559abb25b6ac]
38  /opt/conda/envs/gdf/bin/python(_PyEval_EvalFrameDefault+0x45a6) [0x559abb2573f6]
39  /opt/conda/envs/gdf/bin/python(+0x13f712) [0x559abb263712]
40  /opt/conda/envs/gdf/bin/python(+0x14c9ac) [0x559abb2709ac]
41  /opt/conda/envs/gdf/bin/python(_PyEval_EvalFrameDefault+0x45a6) [0x559abb2573f6]
42  /opt/conda/envs/gdf/bin/python(+0x13f712) [0x559abb263712]
43  /opt/conda/envs/gdf/bin/python(_PyEval_EvalFrameDefault+0x696) [0x559abb2534e6]
44  /opt/conda/envs/gdf/bin/python(+0x12dfb4) [0x559abb251fb4]
45  /opt/conda/envs/gdf/bin/python(_PyFunction_Vectorcall+0xd9) [0x559abb263469]
46  /opt/conda/envs/gdf/bin/python(_PyEval_EvalFrameDefault+0x696) [0x559abb2534e6]
47  /opt/conda/envs/gdf/bin/python(+0x13f712) [0x559abb263712]
48  /opt/conda/envs/gdf/bin/python(_PyEval_EvalFrameDefault+0x3e2) [0x559abb253232]
49  /opt/conda/envs/gdf/bin/python(+0x12dfb4) [0x559abb251fb4]
50  /opt/conda/envs/gdf/bin/python(_PyFunction_Vectorcall+0xd9) [0x559abb263469]
51  /opt/conda/envs/gdf/bin/python(_PyEval_EvalFrameDefault+0x11f2) [0x559abb254042]
52  /opt/conda/envs/gdf/bin/python(+0x12dfb4) [0x559abb251fb4]
53  /opt/conda/envs/gdf/bin/python(_PyEval_EvalCodeWithName+0x48) [0x559abb251c88]
54  /opt/conda/envs/gdf/bin/python(PyEval_EvalCodeEx+0x39) [0x559abb251c39]
55  /opt/conda/envs/gdf/bin/python(PyEval_EvalCode+0x1b) [0x559abb2ff2cb]
56  /opt/conda/envs/gdf/bin/python(+0x2086ca) [0x559abb32c6ca]
57  /opt/conda/envs/gdf/bin/python(+0x204a63) [0x559abb328a63]
58  /opt/conda/envs/gdf/bin/python(PyRun_StringFlags+0x9a) [0x559abb32087a]
59  /opt/conda/envs/gdf/bin/python(PyRun_SimpleStringFlags+0x3c) [0x559abb32076c]
60  /opt/conda/envs/gdf/bin/python(Py_RunMain+0x267) [0x559abb31f9a7]
61  /opt/conda/envs/gdf/bin/python(Py_BytesMain+0x37) [0x559abb2f3107]
=================================
[dgx13:77154:0:77154] Caught signal 11 (Segmentation fault: address not mapped to object at address 0x448)
==== backtrace (tid:  77154) ====
 0  /opt/conda/envs/gdf/lib/libucs.so.0(ucs_handle_error+0x2fd) [0x7fd590e8707d]
 1  /opt/conda/envs/gdf/lib/libucs.so.0(+0x2a274) [0x7fd590e87274]
 2  /opt/conda/envs/gdf/lib/libucs.so.0(+0x2a43a) [0x7fd590e8743a]
 3  /usr/lib/x86_64-linux-gnu/libpthread.so.0(+0x14420) [0x7fd5bbea7420]
 4  /opt/conda/envs/gdf/lib/libucp.so.0(ucp_mem_type_unpack+0x14) [0x7fd590f066b4]
 5  /opt/conda/envs/gdf/lib/libucp.so.0(ucp_rndv_data_handler+0x4e9) [0x7fd590f2f839]
 6  /opt/conda/envs/gdf/lib/libuct.so.0(+0x203df) [0x7fd590e413df]
 7  /opt/conda/envs/gdf/lib/libuct.so.0(+0x23838) [0x7fd590e44838]
 8  /opt/conda/envs/gdf/lib/libucs.so.0(ucs_event_set_wait+0xb9) [0x7fd590e904a9]
 9  /opt/conda/envs/gdf/lib/libuct.so.0(uct_tcp_iface_progress+0x7d) [0x7fd590e435dd]
10  /opt/conda/envs/gdf/lib/libucp.so.0(ucp_worker_progress+0x5a) [0x7fd590f038da]
11  /opt/conda/envs/gdf/lib/python3.9/site-packages/ucp/_libs/ucx_api.cpython-39-x86_64-linux-gnu.so(+0x3206a) [0x7fd590fbc06a]
12  /opt/conda/envs/gdf/bin/python(_PyEval_EvalFrameDefault+0x45a6) [0x55b9cdb9e3f6]
13  /opt/conda/envs/gdf/bin/python(+0x12dfb4) [0x55b9cdb98fb4]
14  /opt/conda/envs/gdf/bin/python(_PyFunction_Vectorcall+0xd9) [0x55b9cdbaa469]
15  /opt/conda/envs/gdf/bin/python(_PyEval_EvalFrameDefault+0x696) [0x55b9cdb9a4e6]
16  /opt/conda/envs/gdf/bin/python(+0x13f712) [0x55b9cdbaa712]
17  /opt/conda/envs/gdf/bin/python(+0x14ca83) [0x55b9cdbb7a83]
18  /opt/conda/envs/gdf/bin/python(+0x25819c) [0x55b9cdcc319c]
19  /opt/conda/envs/gdf/bin/python(+0xf23ff) [0x55b9cdb5d3ff]
20  /opt/conda/envs/gdf/bin/python(+0x136723) [0x55b9cdba1723]
21  /opt/conda/envs/gdf/bin/python(_PyEval_EvalFrameDefault+0x5ad9) [0x55b9cdb9f929]
22  /opt/conda/envs/gdf/bin/python(+0x13f712) [0x55b9cdbaa712]
23  /opt/conda/envs/gdf/bin/python(_PyEval_EvalFrameDefault+0x696) [0x55b9cdb9a4e6]
24  /opt/conda/envs/gdf/bin/python(+0x13f712) [0x55b9cdbaa712]
25  /opt/conda/envs/gdf/bin/python(_PyEval_EvalFrameDefault+0x696) [0x55b9cdb9a4e6]
26  /opt/conda/envs/gdf/bin/python(+0x13f712) [0x55b9cdbaa712]
27  /opt/conda/envs/gdf/bin/python(_PyEval_EvalFrameDefault+0x696) [0x55b9cdb9a4e6]
28  /opt/conda/envs/gdf/bin/python(+0x13f712) [0x55b9cdbaa712]
29  /opt/conda/envs/gdf/bin/python(_PyEval_EvalFrameDefault+0x696) [0x55b9cdb9a4e6]
30  /opt/conda/envs/gdf/bin/python(+0x12dfb4) [0x55b9cdb98fb4]
31  /opt/conda/envs/gdf/bin/python(_PyFunction_Vectorcall+0xd9) [0x55b9cdbaa469]
32  /opt/conda/envs/gdf/bin/python(_PyEval_EvalFrameDefault+0x11f2) [0x55b9cdb9b042]
33  /opt/conda/envs/gdf/bin/python(+0x12dfb4) [0x55b9cdb98fb4]
34  /opt/conda/envs/gdf/bin/python(+0x14c8cb) [0x55b9cdbb78cb]
35  /opt/conda/envs/gdf/bin/python(PyObject_Call+0xbc) [0x55b9cdbb804c]
36  /opt/conda/envs/gdf/bin/python(+0x21080e) [0x55b9cdc7b80e]
37  /opt/conda/envs/gdf/bin/python(_PyObject_MakeTpCall+0x2ec) [0x55b9cdba26ac]
38  /opt/conda/envs/gdf/bin/python(_PyEval_EvalFrameDefault+0x45a6) [0x55b9cdb9e3f6]
39  /opt/conda/envs/gdf/bin/python(+0x13f712) [0x55b9cdbaa712]
40  /opt/conda/envs/gdf/bin/python(+0x14c9ac) [0x55b9cdbb79ac]
41  /opt/conda/envs/gdf/bin/python(_PyEval_EvalFrameDefault+0x45a6) [0x55b9cdb9e3f6]
42  /opt/conda/envs/gdf/bin/python(+0x13f712) [0x55b9cdbaa712]
43  /opt/conda/envs/gdf/bin/python(_PyEval_EvalFrameDefault+0x696) [0x55b9cdb9a4e6]
44  /opt/conda/envs/gdf/bin/python(+0x12dfb4) [0x55b9cdb98fb4]
45  /opt/conda/envs/gdf/bin/python(_PyFunction_Vectorcall+0xd9) [0x55b9cdbaa469]
46  /opt/conda/envs/gdf/bin/python(_PyEval_EvalFrameDefault+0x696) [0x55b9cdb9a4e6]
47  /opt/conda/envs/gdf/bin/python(+0x13f712) [0x55b9cdbaa712]
48  /opt/conda/envs/gdf/bin/python(_PyEval_EvalFrameDefault+0x3e2) [0x55b9cdb9a232]
49  /opt/conda/envs/gdf/bin/python(+0x12dfb4) [0x55b9cdb98fb4]
50  /opt/conda/envs/gdf/bin/python(_PyFunction_Vectorcall+0xd9) [0x55b9cdbaa469]
51  /opt/conda/envs/gdf/bin/python(_PyEval_EvalFrameDefault+0x11f2) [0x55b9cdb9b042]
52  /opt/conda/envs/gdf/bin/python(+0x12dfb4) [0x55b9cdb98fb4]
53  /opt/conda/envs/gdf/bin/python(_PyEval_EvalCodeWithName+0x48) [0x55b9cdb98c88]
54  /opt/conda/envs/gdf/bin/python(PyEval_EvalCodeEx+0x39) [0x55b9cdb98c39]
55  /opt/conda/envs/gdf/bin/python(PyEval_EvalCode+0x1b) [0x55b9cdc462cb]
56  /opt/conda/envs/gdf/bin/python(+0x2086ca) [0x55b9cdc736ca]
57  /opt/conda/envs/gdf/bin/python(+0x204a63) [0x55b9cdc6fa63]
58  /opt/conda/envs/gdf/bin/python(PyRun_StringFlags+0x9a) [0x55b9cdc6787a]
59  /opt/conda/envs/gdf/bin/python(PyRun_SimpleStringFlags+0x3c) [0x55b9cdc6776c]
60  /opt/conda/envs/gdf/bin/python(Py_RunMain+0x267) [0x55b9cdc669a7]
61  /opt/conda/envs/gdf/bin/python(Py_BytesMain+0x37) [0x55b9cdc3a107]
=================================
2024-02-28 07:30:10,740 - distributed.worker - ERROR - failed during get data with ucx://127.0.0.1:53035 -> ucx://127.0.0.1:59141
Traceback (most recent call last):
  File "/opt/conda/envs/gdf/lib/python3.9/site-packages/distributed/comm/ucx.py", line 334, in write
    await self.ep.send(each_frame)
  File "/opt/conda/envs/gdf/lib/python3.9/site-packages/ucp/core.py", line 662, in send
    return await comm.tag_send(self._ep, buffer, nbytes, tag, name=log)
ucp._libs.exceptions.UCXError: <[Send #007] ep: 0x7fbf78020140, tag: 0x43561d0d9c529e6c, nbytes: 50000000, type: <class 'cupy.ndarray'>>: Connection reset by remote peer

During handling of the above exception, another exception occurred:

Traceback (most recent call last):
  File "/opt/conda/envs/gdf/lib/python3.9/site-packages/distributed/worker.py", line 1779, in get_data
    compressed = await comm.write(msg, serializers=serializers)
  File "/opt/conda/envs/gdf/lib/python3.9/site-packages/distributed/utils.py", line 832, in wrapper
    return await func(*args, **kwargs)
  File "/opt/conda/envs/gdf/lib/python3.9/site-packages/distributed/comm/ucx.py", line 338, in write
    raise CommClosedError("While writing, the connection was closed")
distributed.comm.core.CommClosedError: While writing, the connection was closed
2024-02-28 07:30:10,741 - distributed.worker - ERROR - Worker stream died during communication: ucx://127.0.0.1:59141
Traceback (most recent call last):
  File "/opt/conda/envs/gdf/lib/python3.9/site-packages/distributed/comm/ucx.py", line 392, in read
    await self.ep.recv(each_frame)
  File "/opt/conda/envs/gdf/lib/python3.9/site-packages/ucp/core.py", line 737, in recv
    ret = await comm.tag_recv(self._ep, buffer, nbytes, tag, name=log)
ucp._libs.exceptions.UCXError: <[Recv #007] ep: 0x7fbf78020100, tag: 0x43b3b2591ef9e30e, nbytes: 50000000, type: <class 'rmm._lib.device_buffer.DeviceBuffer'>>: Connection reset by remote peer

During handling of the above exception, another exception occurred:

Traceback (most recent call last):
  File "/opt/conda/envs/gdf/lib/python3.9/site-packages/distributed/worker.py", line 2056, in gather_dep
    response = await get_data_from_worker(
  File "/opt/conda/envs/gdf/lib/python3.9/site-packages/distributed/worker.py", line 2860, in get_data_from_worker
    response = await send_recv(
  File "/opt/conda/envs/gdf/lib/python3.9/site-packages/distributed/core.py", line 1154, in send_recv
    response = await comm.read(deserializers=deserializers)
  File "/opt/conda/envs/gdf/lib/python3.9/site-packages/distributed/utils.py", line 832, in wrapper
    return await func(*args, **kwargs)
  File "/opt/conda/envs/gdf/lib/python3.9/site-packages/distributed/comm/ucx.py", line 398, in read
    raise CommClosedError(
distributed.comm.core.CommClosedError: Connection closed by writer.
Inner exception: UCXError("<[Recv #007] ep: 0x7fbf78020100, tag: 0x43b3b2591ef9e30e, nbytes: 50000000, type: <class 'rmm._lib.device_buffer.DeviceBuffer'>>: Connection reset by remote peer")
2024-02-28 07:30:10,747 - distributed.worker - ERROR - Worker stream died during communication: ucx://127.0.0.1:59141
Traceback (most recent call last):
  File "/opt/conda/envs/gdf/lib/python3.9/site-packages/distributed/core.py", line 1564, in _connect
    comm = await connect(
  File "/opt/conda/envs/gdf/lib/python3.9/site-packages/distributed/comm/core.py", line 342, in connect
    comm = await wait_for(
  File "/opt/conda/envs/gdf/lib/python3.9/site-packages/distributed/utils.py", line 1940, in wait_for
    return await asyncio.wait_for(fut, timeout)
  File "/opt/conda/envs/gdf/lib/python3.9/asyncio/tasks.py", line 466, in wait_for
    await waiter
asyncio.exceptions.CancelledError

During handling of the above exception, another exception occurred:

Traceback (most recent call last):
  File "/opt/conda/envs/gdf/lib/python3.9/site-packages/distributed/core.py", line 1674, in connect
    return connect_attempt.result()
asyncio.exceptions.CancelledError

During handling of the above exception, another exception occurred:

Traceback (most recent call last):
  File "/opt/conda/envs/gdf/lib/python3.9/site-packages/distributed/worker.py", line 2056, in gather_dep
    response = await get_data_from_worker(
  File "/opt/conda/envs/gdf/lib/python3.9/site-packages/distributed/worker.py", line 2857, in get_data_from_worker
    comm = await rpc.connect(worker)
  File "/opt/conda/envs/gdf/lib/python3.9/site-packages/distributed/core.py", line 1676, in connect
    raise CommClosedError(reason)
distributed.comm.core.CommClosedError: Address removed.
Task exception was never retrieved
future: <Task finished name='Task-147' coro=<_listener_handler_coroutine() done, defined at /opt/conda/envs/gdf/lib/python3.9/site-packages/ucp/core.py:140> exception=UCXError('<stream_recv>: Connection reset by remote peer')>
Traceback (most recent call last):
  File "/opt/conda/envs/gdf/lib/python3.9/site-packages/ucp/core.py", line 155, in _listener_handler_coroutine
    peer_info = await exchange_peer_info(
  File "/opt/conda/envs/gdf/lib/python3.9/site-packages/ucp/core.py", line 55, in exchange_peer_info
    await asyncio.wait_for(
  File "/opt/conda/envs/gdf/lib/python3.9/asyncio/tasks.py", line 479, in wait_for
    return fut.result()
ucp._libs.exceptions.UCXError: <stream_recv>: Connection reset by remote peer
2024-02-28 07:30:10,964 - distributed.worker - ERROR - failed during get data with ucx://127.0.0.1:55219 -> ucx://127.0.0.1:49999
Traceback (most recent call last):
  File "/opt/conda/envs/gdf/lib/python3.9/site-packages/distributed/comm/ucx.py", line 334, in write
    await self.ep.send(each_frame)
  File "/opt/conda/envs/gdf/lib/python3.9/site-packages/ucp/core.py", line 662, in send
    return await comm.tag_send(self._ep, buffer, nbytes, tag, name=log)
ucp._libs.exceptions.UCXError: <[Send #007] ep: 0x7fcdc8177200, tag: 0x2eb48fc657fca9e6, nbytes: 50000000, type: <class 'cupy.ndarray'>>: Connection reset by remote peer

During handling of the above exception, another exception occurred:

Traceback (most recent call last):
  File "/opt/conda/envs/gdf/lib/python3.9/site-packages/distributed/worker.py", line 1779, in get_data
    compressed = await comm.write(msg, serializers=serializers)
  File "/opt/conda/envs/gdf/lib/python3.9/site-packages/distributed/utils.py", line 832, in wrapper
    return await func(*args, **kwargs)
  File "/opt/conda/envs/gdf/lib/python3.9/site-packages/distributed/comm/ucx.py", line 338, in write
    raise CommClosedError("While writing, the connection was closed")
distributed.comm.core.CommClosedError: While writing, the connection was closed
2024-02-28 07:30:11,062 - distributed.worker - ERROR - failed during get data with ucx://127.0.0.1:42499 -> ucx://127.0.0.1:57807
Traceback (most recent call last):
  File "/opt/conda/envs/gdf/lib/python3.9/site-packages/distributed/comm/ucx.py", line 334, in write
    await self.ep.send(each_frame)
  File "/opt/conda/envs/gdf/lib/python3.9/site-packages/ucp/core.py", line 662, in send
    return await comm.tag_send(self._ep, buffer, nbytes, tag, name=log)
ucp._libs.exceptions.UCXError: <[Send #007] ep: 0x7fd34502e140, tag: 0x7a5b77bef541a1c2, nbytes: 50000000, type: <class 'cupy.ndarray'>>: Connection reset by remote peer

During handling of the above exception, another exception occurred:

Traceback (most recent call last):
  File "/opt/conda/envs/gdf/lib/python3.9/site-packages/distributed/worker.py", line 1779, in get_data
    compressed = await comm.write(msg, serializers=serializers)
  File "/opt/conda/envs/gdf/lib/python3.9/site-packages/distributed/utils.py", line 832, in wrapper
    return await func(*args, **kwargs)
  File "/opt/conda/envs/gdf/lib/python3.9/site-packages/distributed/comm/ucx.py", line 338, in write
    raise CommClosedError("While writing, the connection was closed")
distributed.comm.core.CommClosedError: While writing, the connection was closed
2024-02-28 07:30:11,065 - distributed.worker - ERROR - Worker stream died during communication: ucx://127.0.0.1:57807
Traceback (most recent call last):
  File "/opt/conda/envs/gdf/lib/python3.9/site-packages/distributed/comm/ucx.py", line 467, in connect
    ep = await ucp.create_endpoint(ip, port)
  File "/opt/conda/envs/gdf/lib/python3.9/site-packages/ucp/core.py", line 1016, in create_endpoint
    return await _get_ctx().create_endpoint(
  File "/opt/conda/envs/gdf/lib/python3.9/site-packages/ucp/core.py", line 328, in create_endpoint
    peer_info = await exchange_peer_info(
  File "/opt/conda/envs/gdf/lib/python3.9/site-packages/ucp/core.py", line 60, in exchange_peer_info
    await asyncio.wait_for(
  File "/opt/conda/envs/gdf/lib/python3.9/asyncio/tasks.py", line 479, in wait_for
    return fut.result()
ucp._libs.exceptions.UCXError: <stream_recv>: Connection reset by remote peer

During handling of the above exception, another exception occurred:

Traceback (most recent call last):
  File "/opt/conda/envs/gdf/lib/python3.9/site-packages/distributed/comm/core.py", line 342, in connect
    comm = await wait_for(
  File "/opt/conda/envs/gdf/lib/python3.9/site-packages/distributed/utils.py", line 1940, in wait_for
    return await asyncio.wait_for(fut, timeout)
  File "/opt/conda/envs/gdf/lib/python3.9/asyncio/tasks.py", line 479, in wait_for
    return fut.result()
  File "/opt/conda/envs/gdf/lib/python3.9/site-packages/distributed/comm/ucx.py", line 469, in connect
    raise CommClosedError("Connection closed before handshake completed")
distributed.comm.core.CommClosedError: Connection closed before handshake completed

During handling of the above exception, another exception occurred:

Traceback (most recent call last):
  File "/opt/conda/envs/gdf/lib/python3.9/site-packages/distributed/core.py", line 1564, in _connect
    comm = await connect(
  File "/opt/conda/envs/gdf/lib/python3.9/site-packages/distributed/comm/core.py", line 366, in connect
    await asyncio.sleep(backoff)
  File "/opt/conda/envs/gdf/lib/python3.9/asyncio/tasks.py", line 652, in sleep
    return await future
asyncio.exceptions.CancelledError

During handling of the above exception, another exception occurred:

Traceback (most recent call last):
  File "/opt/conda/envs/gdf/lib/python3.9/site-packages/distributed/core.py", line 1674, in connect
    return connect_attempt.result()
asyncio.exceptions.CancelledError

During handling of the above exception, another exception occurred:

Traceback (most recent call last):
  File "/opt/conda/envs/gdf/lib/python3.9/site-packages/distributed/worker.py", line 2056, in gather_dep
    response = await get_data_from_worker(
  File "/opt/conda/envs/gdf/lib/python3.9/site-packages/distributed/worker.py", line 2857, in get_data_from_worker
    comm = await rpc.connect(worker)
  File "/opt/conda/envs/gdf/lib/python3.9/site-packages/distributed/core.py", line 1676, in connect
    raise CommClosedError(reason)
distributed.comm.core.CommClosedError: Address removed.
[dgx13:77166:0:77166] Caught signal 11 (Segmentation fault: address not mapped to object at address 0x448)
==== backtrace (tid:  77166) ====
 0  /opt/conda/envs/gdf/lib/libucs.so.0(ucs_handle_error+0x2fd) [0x7fbf7836c07d]
 1  /opt/conda/envs/gdf/lib/libucs.so.0(+0x2a274) [0x7fbf7836c274]
 2  /opt/conda/envs/gdf/lib/libucs.so.0(+0x2a43a) [0x7fbf7836c43a]
 3  /usr/lib/x86_64-linux-gnu/libpthread.so.0(+0x14420) [0x7fbfb120b420]
 4  /opt/conda/envs/gdf/lib/libucp.so.0(ucp_mem_type_unpack+0x14) [0x7fbf783eb6b4]
 5  /opt/conda/envs/gdf/lib/libucp.so.0(ucp_rndv_data_handler+0x4e9) [0x7fbf78414839]
 6  /opt/conda/envs/gdf/lib/libuct.so.0(+0x203df) [0x7fbf783263df]
 7  /opt/conda/envs/gdf/lib/libuct.so.0(+0x23838) [0x7fbf78329838]
 8  /opt/conda/envs/gdf/lib/libucs.so.0(ucs_event_set_wait+0xb9) [0x7fbf783754a9]
 9  /opt/conda/envs/gdf/lib/libuct.so.0(uct_tcp_iface_progress+0x7d) [0x7fbf783285dd]
10  /opt/conda/envs/gdf/lib/libucp.so.0(ucp_worker_progress+0x5a) [0x7fbf783e88da]
11  /opt/conda/envs/gdf/lib/python3.9/site-packages/ucp/_libs/ucx_api.cpython-39-x86_64-linux-gnu.so(+0x3206a) [0x7fbf784a106a]
12  /opt/conda/envs/gdf/bin/python(_PyEval_EvalFrameDefault+0x45a6) [0x559a8b8dd3f6]
13  /opt/conda/envs/gdf/bin/python(+0x12dfb4) [0x559a8b8d7fb4]
14  /opt/conda/envs/gdf/bin/python(_PyFunction_Vectorcall+0xd9) [0x559a8b8e9469]
15  /opt/conda/envs/gdf/bin/python(_PyEval_EvalFrameDefault+0x696) [0x559a8b8d94e6]
16  /opt/conda/envs/gdf/bin/python(+0x13f712) [0x559a8b8e9712]
17  /opt/conda/envs/gdf/bin/python(+0x14ca83) [0x559a8b8f6a83]
18  /opt/conda/envs/gdf/bin/python(+0x25819c) [0x559a8ba0219c]
19  /opt/conda/envs/gdf/bin/python(+0xf23ff) [0x559a8b89c3ff]
20  /opt/conda/envs/gdf/bin/python(+0x136723) [0x559a8b8e0723]
21  /opt/conda/envs/gdf/bin/python(_PyEval_EvalFrameDefault+0x5ad9) [0x559a8b8de929]
22  /opt/conda/envs/gdf/bin/python(+0x13f712) [0x559a8b8e9712]
23  /opt/conda/envs/gdf/bin/python(_PyEval_EvalFrameDefault+0x696) [0x559a8b8d94e6]
24  /opt/conda/envs/gdf/bin/python(+0x13f712) [0x559a8b8e9712]
25  /opt/conda/envs/gdf/bin/python(_PyEval_EvalFrameDefault+0x696) [0x559a8b8d94e6]
26  /opt/conda/envs/gdf/bin/python(+0x13f712) [0x559a8b8e9712]
27  /opt/conda/envs/gdf/bin/python(_PyEval_EvalFrameDefault+0x696) [0x559a8b8d94e6]
28  /opt/conda/envs/gdf/bin/python(+0x13f712) [0x559a8b8e9712]
29  /opt/conda/envs/gdf/bin/python(_PyEval_EvalFrameDefault+0x696) [0x559a8b8d94e6]
30  /opt/conda/envs/gdf/bin/python(+0x12dfb4) [0x559a8b8d7fb4]
31  /opt/conda/envs/gdf/bin/python(_PyFunction_Vectorcall+0xd9) [0x559a8b8e9469]
32  /opt/conda/envs/gdf/bin/python(_PyEval_EvalFrameDefault+0x11f2) [0x559a8b8da042]
33  /opt/conda/envs/gdf/bin/python(+0x12dfb4) [0x559a8b8d7fb4]
34  /opt/conda/envs/gdf/bin/python(+0x14c8cb) [0x559a8b8f68cb]
35  /opt/conda/envs/gdf/bin/python(PyObject_Call+0xbc) [0x559a8b8f704c]
36  /opt/conda/envs/gdf/bin/python(+0x21080e) [0x559a8b9ba80e]
37  /opt/conda/envs/gdf/bin/python(_PyObject_MakeTpCall+0x2ec) [0x559a8b8e16ac]
38  /opt/conda/envs/gdf/bin/python(_PyEval_EvalFrameDefault+0x45a6) [0x559a8b8dd3f6]
39  /opt/conda/envs/gdf/bin/python(+0x13f712) [0x559a8b8e9712]
40  /opt/conda/envs/gdf/bin/python(+0x14c9ac) [0x559a8b8f69ac]
41  /opt/conda/envs/gdf/bin/python(_PyEval_EvalFrameDefault+0x45a6) [0x559a8b8dd3f6]
42  /opt/conda/envs/gdf/bin/python(+0x13f712) [0x559a8b8e9712]
43  /opt/conda/envs/gdf/bin/python(_PyEval_EvalFrameDefault+0x696) [0x559a8b8d94e6]
44  /opt/conda/envs/gdf/bin/python(+0x12dfb4) [0x559a8b8d7fb4]
45  /opt/conda/envs/gdf/bin/python(_PyFunction_Vectorcall+0xd9) [0x559a8b8e9469]
46  /opt/conda/envs/gdf/bin/python(_PyEval_EvalFrameDefault+0x696) [0x559a8b8d94e6]
47  /opt/conda/envs/gdf/bin/python(+0x13f712) [0x559a8b8e9712]
48  /opt/conda/envs/gdf/bin/python(_PyEval_EvalFrameDefault+0x3e2) [0x559a8b8d9232]
49  /opt/conda/envs/gdf/bin/python(+0x12dfb4) [0x559a8b8d7fb4]
50  /opt/conda/envs/gdf/bin/python(_PyFunction_Vectorcall+0xd9) [0x559a8b8e9469]
51  /opt/conda/envs/gdf/bin/python(_PyEval_EvalFrameDefault+0x11f2) [0x559a8b8da042]
52  /opt/conda/envs/gdf/bin/python(+0x12dfb4) [0x559a8b8d7fb4]
53  /opt/conda/envs/gdf/bin/python(_PyEval_EvalCodeWithName+0x48) [0x559a8b8d7c88]
54  /opt/conda/envs/gdf/bin/python(PyEval_EvalCodeEx+0x39) [0x559a8b8d7c39]
55  /opt/conda/envs/gdf/bin/python(PyEval_EvalCode+0x1b) [0x559a8b9852cb]
56  /opt/conda/envs/gdf/bin/python(+0x2086ca) [0x559a8b9b26ca]
57  /opt/conda/envs/gdf/bin/python(+0x204a63) [0x559a8b9aea63]
58  /opt/conda/envs/gdf/bin/python(PyRun_StringFlags+0x9a) [0x559a8b9a687a]
59  /opt/conda/envs/gdf/bin/python(PyRun_SimpleStringFlags+0x3c) [0x559a8b9a676c]
60  /opt/conda/envs/gdf/bin/python(Py_RunMain+0x267) [0x559a8b9a59a7]
61  /opt/conda/envs/gdf/bin/python(Py_BytesMain+0x37) [0x559a8b979107]
=================================
2024-02-28 07:30:11,538 - distributed.worker - ERROR - failed during get data with ucx://127.0.0.1:55219 -> ucx://127.0.0.1:53035
Traceback (most recent call last):
  File "/opt/conda/envs/gdf/lib/python3.9/site-packages/distributed/comm/ucx.py", line 334, in write
    await self.ep.send(each_frame)
  File "/opt/conda/envs/gdf/lib/python3.9/site-packages/ucp/core.py", line 662, in send
    return await comm.tag_send(self._ep, buffer, nbytes, tag, name=log)
ucp._libs.exceptions.UCXError: <[Send #012] ep: 0x7fcdc8177200, tag: 0x47e4447c6421aedf, nbytes: 50000000, type: <class 'cupy.ndarray'>>: Connection reset by remote peer

During handling of the above exception, another exception occurred:

Traceback (most recent call last):
  File "/opt/conda/envs/gdf/lib/python3.9/site-packages/distributed/worker.py", line 1779, in get_data
    compressed = await comm.write(msg, serializers=serializers)
  File "/opt/conda/envs/gdf/lib/python3.9/site-packages/distributed/utils.py", line 832, in wrapper
    return await func(*args, **kwargs)
  File "/opt/conda/envs/gdf/lib/python3.9/site-packages/distributed/comm/ucx.py", line 338, in write
    raise CommClosedError("While writing, the connection was closed")
distributed.comm.core.CommClosedError: While writing, the connection was closed
2024-02-28 07:30:11,718 - distributed.nanny - WARNING - Restarting worker
2024-02-28 07:30:12,497 - distributed.nanny - WARNING - Restarting worker
2024-02-28 07:30:12,530 - distributed.nanny - WARNING - Restarting worker
2024-02-28 07:30:12,800 - distributed.nanny - WARNING - Restarting worker
[dgx13:77274:0:77274] Caught signal 11 (Segmentation fault: address not mapped to object at address 0x448)
==== backtrace (tid:  77274) ====
 0  /opt/conda/envs/gdf/lib/libucs.so.0(ucs_handle_error+0x2fd) [0x7f0a8006e07d]
 1  /opt/conda/envs/gdf/lib/libucs.so.0(+0x2a274) [0x7f0a8006e274]
 2  /opt/conda/envs/gdf/lib/libucs.so.0(+0x2a43a) [0x7f0a8006e43a]
 3  /usr/lib/x86_64-linux-gnu/libpthread.so.0(+0x14420) [0x7f0ab8a25420]
 4  /opt/conda/envs/gdf/lib/libucp.so.0(ucp_mem_type_unpack+0x14) [0x7f0a65b636b4]
 5  /opt/conda/envs/gdf/lib/libucp.so.0(ucp_rndv_data_handler+0x4e9) [0x7f0a65b8c839]
 6  /opt/conda/envs/gdf/lib/libuct.so.0(+0x203df) [0x7f0a800283df]
 7  /opt/conda/envs/gdf/lib/libuct.so.0(+0x23838) [0x7f0a8002b838]
 8  /opt/conda/envs/gdf/lib/libucs.so.0(ucs_event_set_wait+0xb9) [0x7f0a800774a9]
 9  /opt/conda/envs/gdf/lib/libuct.so.0(uct_tcp_iface_progress+0x7d) [0x7f0a8002a5dd]
10  /opt/conda/envs/gdf/lib/libucp.so.0(ucp_worker_progress+0x5a) [0x7f0a65b608da]
11  /opt/conda/envs/gdf/lib/python3.9/site-packages/ucp/_libs/ucx_api.cpython-39-x86_64-linux-gnu.so(+0x3206a) [0x7f0a65c1906a]
12  /opt/conda/envs/gdf/bin/python(_PyEval_EvalFrameDefault+0x45a6) [0x55e989d6e3f6]
13  /opt/conda/envs/gdf/bin/python(+0x12dfb4) [0x55e989d68fb4]
14  /opt/conda/envs/gdf/bin/python(_PyFunction_Vectorcall+0xd9) [0x55e989d7a469]
15  /opt/conda/envs/gdf/bin/python(_PyEval_EvalFrameDefault+0x696) [0x55e989d6a4e6]
16  /opt/conda/envs/gdf/bin/python(+0x1e26d2) [0x55e989e1d6d2]
17  /opt/conda/envs/gdf/lib/python3.9/lib-dynload/_asyncio.cpython-39-x86_64-linux-gnu.so(+0x81e9) [0x7f0aae8ae1e9]
18  /opt/conda/envs/gdf/bin/python(_PyObject_MakeTpCall+0x2ec) [0x55e989d726ac]
19  /opt/conda/envs/gdf/bin/python(+0xf23ff) [0x55e989d2d3ff]
20  /opt/conda/envs/gdf/bin/python(+0x136723) [0x55e989d71723]
21  /opt/conda/envs/gdf/bin/python(_PyEval_EvalFrameDefault+0x5ad9) [0x55e989d6f929]
22  /opt/conda/envs/gdf/bin/python(+0x13f712) [0x55e989d7a712]
23  /opt/conda/envs/gdf/bin/python(_PyEval_EvalFrameDefault+0x696) [0x55e989d6a4e6]
24  /opt/conda/envs/gdf/bin/python(+0x13f712) [0x55e989d7a712]
25  /opt/conda/envs/gdf/bin/python(_PyEval_EvalFrameDefault+0x696) [0x55e989d6a4e6]
26  /opt/conda/envs/gdf/bin/python(+0x13f712) [0x55e989d7a712]
27  /opt/conda/envs/gdf/bin/python(_PyEval_EvalFrameDefault+0x696) [0x55e989d6a4e6]
28  /opt/conda/envs/gdf/bin/python(+0x13f712) [0x55e989d7a712]
29  /opt/conda/envs/gdf/bin/python(_PyEval_EvalFrameDefault+0x696) [0x55e989d6a4e6]
30  /opt/conda/envs/gdf/bin/python(+0x12dfb4) [0x55e989d68fb4]
31  /opt/conda/envs/gdf/bin/python(_PyFunction_Vectorcall+0xd9) [0x55e989d7a469]
32  /opt/conda/envs/gdf/bin/python(_PyEval_EvalFrameDefault+0x11f2) [0x55e989d6b042]
33  /opt/conda/envs/gdf/bin/python(+0x12dfb4) [0x55e989d68fb4]
34  /opt/conda/envs/gdf/bin/python(+0x14c8cb) [0x55e989d878cb]
35  /opt/conda/envs/gdf/bin/python(PyObject_Call+0xbc) [0x55e989d8804c]
36  /opt/conda/envs/gdf/bin/python(+0x21080e) [0x55e989e4b80e]
37  /opt/conda/envs/gdf/bin/python(_PyObject_MakeTpCall+0x2ec) [0x55e989d726ac]
38  /opt/conda/envs/gdf/bin/python(_PyEval_EvalFrameDefault+0x45a6) [0x55e989d6e3f6]
39  /opt/conda/envs/gdf/bin/python(+0x13f712) [0x55e989d7a712]
40  /opt/conda/envs/gdf/bin/python(+0x14c9ac) [0x55e989d879ac]
41  /opt/conda/envs/gdf/bin/python(_PyEval_EvalFrameDefault+0x45a6) [0x55e989d6e3f6]
42  /opt/conda/envs/gdf/bin/python(+0x13f712) [0x55e989d7a712]
43  /opt/conda/envs/gdf/bin/python(_PyEval_EvalFrameDefault+0x696) [0x55e989d6a4e6]
44  /opt/conda/envs/gdf/bin/python(+0x12dfb4) [0x55e989d68fb4]
45  /opt/conda/envs/gdf/bin/python(_PyFunction_Vectorcall+0xd9) [0x55e989d7a469]
46  /opt/conda/envs/gdf/bin/python(_PyEval_EvalFrameDefault+0x696) [0x55e989d6a4e6]
47  /opt/conda/envs/gdf/bin/python(+0x13f712) [0x55e989d7a712]
48  /opt/conda/envs/gdf/bin/python(_PyEval_EvalFrameDefault+0x3e2) [0x55e989d6a232]
49  /opt/conda/envs/gdf/bin/python(+0x12dfb4) [0x55e989d68fb4]
50  /opt/conda/envs/gdf/bin/python(_PyFunction_Vectorcall+0xd9) [0x55e989d7a469]
51  /opt/conda/envs/gdf/bin/python(_PyEval_EvalFrameDefault+0x11f2) [0x55e989d6b042]
52  /opt/conda/envs/gdf/bin/python(+0x12dfb4) [0x55e989d68fb4]
53  /opt/conda/envs/gdf/bin/python(_PyEval_EvalCodeWithName+0x48) [0x55e989d68c88]
54  /opt/conda/envs/gdf/bin/python(PyEval_EvalCodeEx+0x39) [0x55e989d68c39]
55  /opt/conda/envs/gdf/bin/python(PyEval_EvalCode+0x1b) [0x55e989e162cb]
56  /opt/conda/envs/gdf/bin/python(+0x2086ca) [0x55e989e436ca]
57  /opt/conda/envs/gdf/bin/python(+0x204a63) [0x55e989e3fa63]
58  /opt/conda/envs/gdf/bin/python(PyRun_StringFlags+0x9a) [0x55e989e3787a]
59  /opt/conda/envs/gdf/bin/python(PyRun_SimpleStringFlags+0x3c) [0x55e989e3776c]
60  /opt/conda/envs/gdf/bin/python(Py_RunMain+0x267) [0x55e989e369a7]
61  /opt/conda/envs/gdf/bin/python(Py_BytesMain+0x37) [0x55e989e0a107]
=================================
[dgx13:77284:0:77284] Caught signal 11 (Segmentation fault: address not mapped to object at address 0x448)
==== backtrace (tid:  77284) ====
 0  /opt/conda/envs/gdf/lib/libucs.so.0(ucs_handle_error+0x2fd) [0x7f6a24c6307d]
 1  /opt/conda/envs/gdf/lib/libucs.so.0(+0x2a274) [0x7f6a24c63274]
 2  /opt/conda/envs/gdf/lib/libucs.so.0(+0x2a43a) [0x7f6a24c6343a]
 3  /usr/lib/x86_64-linux-gnu/libpthread.so.0(+0x14420) [0x7f6a4fb0b420]
 4  /opt/conda/envs/gdf/lib/libucp.so.0(ucp_mem_type_unpack+0x14) [0x7f6a24ce26b4]
 5  /opt/conda/envs/gdf/lib/libucp.so.0(ucp_rndv_data_handler+0x4e9) [0x7f6a24d0b839]
 6  /opt/conda/envs/gdf/lib/libuct.so.0(+0x203df) [0x7f6a24c1d3df]
 7  /opt/conda/envs/gdf/lib/libuct.so.0(+0x23838) [0x7f6a24c20838]
 8  /opt/conda/envs/gdf/lib/libucs.so.0(ucs_event_set_wait+0xb9) [0x7f6a24c6c4a9]
 9  /opt/conda/envs/gdf/lib/libuct.so.0(uct_tcp_iface_progress+0x7d) [0x7f6a24c1f5dd]
10  /opt/conda/envs/gdf/lib/libucp.so.0(ucp_worker_progress+0x5a) [0x7f6a24cdf8da]
11  /opt/conda/envs/gdf/lib/python3.9/site-packages/ucp/_libs/ucx_api.cpython-39-x86_64-linux-gnu.so(+0x3206a) [0x7f6a24d9806a]
12  /opt/conda/envs/gdf/bin/python(_PyEval_EvalFrameDefault+0x45a6) [0x55b64ba6d3f6]
13  /opt/conda/envs/gdf/bin/python(+0x12dfb4) [0x55b64ba67fb4]
14  /opt/conda/envs/gdf/bin/python(_PyFunction_Vectorcall+0xd9) [0x55b64ba79469]
15  /opt/conda/envs/gdf/bin/python(_PyEval_EvalFrameDefault+0x696) [0x55b64ba694e6]
16  /opt/conda/envs/gdf/bin/python(+0x13f712) [0x55b64ba79712]
17  /opt/conda/envs/gdf/bin/python(+0x14ca83) [0x55b64ba86a83]
18  /opt/conda/envs/gdf/bin/python(+0x25819c) [0x55b64bb9219c]
19  /opt/conda/envs/gdf/bin/python(+0xf23ff) [0x55b64ba2c3ff]
20  /opt/conda/envs/gdf/bin/python(+0x136723) [0x55b64ba70723]
21  /opt/conda/envs/gdf/bin/python(_PyEval_EvalFrameDefault+0x5ad9) [0x55b64ba6e929]
22  /opt/conda/envs/gdf/bin/python(+0x13f712) [0x55b64ba79712]
23  /opt/conda/envs/gdf/bin/python(_PyEval_EvalFrameDefault+0x696) [0x55b64ba694e6]
24  /opt/conda/envs/gdf/bin/python(+0x13f712) [0x55b64ba79712]
25  /opt/conda/envs/gdf/bin/python(_PyEval_EvalFrameDefault+0x696) [0x55b64ba694e6]
26  /opt/conda/envs/gdf/bin/python(+0x13f712) [0x55b64ba79712]
27  /opt/conda/envs/gdf/bin/python(_PyEval_EvalFrameDefault+0x696) [0x55b64ba694e6]
28  /opt/conda/envs/gdf/bin/python(+0x13f712) [0x55b64ba79712]
29  /opt/conda/envs/gdf/bin/python(_PyEval_EvalFrameDefault+0x696) [0x55b64ba694e6]
30  /opt/conda/envs/gdf/bin/python(+0x12dfb4) [0x55b64ba67fb4]
31  /opt/conda/envs/gdf/bin/python(_PyFunction_Vectorcall+0xd9) [0x55b64ba79469]
32  /opt/conda/envs/gdf/bin/python(_PyEval_EvalFrameDefault+0x11f2) [0x55b64ba6a042]
33  /opt/conda/envs/gdf/bin/python(+0x12dfb4) [0x55b64ba67fb4]
34  /opt/conda/envs/gdf/bin/python(+0x14c8cb) [0x55b64ba868cb]
35  /opt/conda/envs/gdf/bin/python(PyObject_Call+0xbc) [0x55b64ba8704c]
36  /opt/conda/envs/gdf/bin/python(+0x21080e) [0x55b64bb4a80e]
37  /opt/conda/envs/gdf/bin/python(_PyObject_MakeTpCall+0x2ec) [0x55b64ba716ac]
38  /opt/conda/envs/gdf/bin/python(_PyEval_EvalFrameDefault+0x45a6) [0x55b64ba6d3f6]
39  /opt/conda/envs/gdf/bin/python(+0x13f712) [0x55b64ba79712]
40  /opt/conda/envs/gdf/bin/python(+0x14c9ac) [0x55b64ba869ac]
41  /opt/conda/envs/gdf/bin/python(_PyEval_EvalFrameDefault+0x45a6) [0x55b64ba6d3f6]
42  /opt/conda/envs/gdf/bin/python(+0x13f712) [0x55b64ba79712]
43  /opt/conda/envs/gdf/bin/python(_PyEval_EvalFrameDefault+0x696) [0x55b64ba694e6]
44  /opt/conda/envs/gdf/bin/python(+0x12dfb4) [0x55b64ba67fb4]
45  /opt/conda/envs/gdf/bin/python(_PyFunction_Vectorcall+0xd9) [0x55b64ba79469]
46  /opt/conda/envs/gdf/bin/python(_PyEval_EvalFrameDefault+0x696) [0x55b64ba694e6]
47  /opt/conda/envs/gdf/bin/python(+0x13f712) [0x55b64ba79712]
48  /opt/conda/envs/gdf/bin/python(_PyEval_EvalFrameDefault+0x3e2) [0x55b64ba69232]
49  /opt/conda/envs/gdf/bin/python(+0x12dfb4) [0x55b64ba67fb4]
50  /opt/conda/envs/gdf/bin/python(_PyFunction_Vectorcall+0xd9) [0x55b64ba79469]
51  /opt/conda/envs/gdf/bin/python(_PyEval_EvalFrameDefault+0x11f2) [0x55b64ba6a042]
52  /opt/conda/envs/gdf/bin/python(+0x12dfb4) [0x55b64ba67fb4]
53  /opt/conda/envs/gdf/bin/python(_PyEval_EvalCodeWithName+0x48) [0x55b64ba67c88]
54  /opt/conda/envs/gdf/bin/python(PyEval_EvalCodeEx+0x39) [0x55b64ba67c39]
55  /opt/conda/envs/gdf/bin/python(PyEval_EvalCode+0x1b) [0x55b64bb152cb]
56  /opt/conda/envs/gdf/bin/python(+0x2086ca) [0x55b64bb426ca]
57  /opt/conda/envs/gdf/bin/python(+0x204a63) [0x55b64bb3ea63]
58  /opt/conda/envs/gdf/bin/python(PyRun_StringFlags+0x9a) [0x55b64bb3687a]
59  /opt/conda/envs/gdf/bin/python(PyRun_SimpleStringFlags+0x3c) [0x55b64bb3676c]
60  /opt/conda/envs/gdf/bin/python(Py_RunMain+0x267) [0x55b64bb359a7]
61  /opt/conda/envs/gdf/bin/python(Py_BytesMain+0x37) [0x55b64bb09107]
=================================
2024-02-28 07:30:15,473 - distributed.worker - ERROR - failed during get data with ucx://127.0.0.1:35885 -> ucx://127.0.0.1:43965
Traceback (most recent call last):
  File "/opt/conda/envs/gdf/lib/python3.9/site-packages/distributed/comm/ucx.py", line 334, in write
    await self.ep.send(each_frame)
  File "/opt/conda/envs/gdf/lib/python3.9/site-packages/ucp/core.py", line 662, in send
    return await comm.tag_send(self._ep, buffer, nbytes, tag, name=log)
ucp._libs.exceptions.UCXError: <[Send #007] ep: 0x7fb8003f9300, tag: 0xba208f6df0e4694c, nbytes: 50000000, type: <class 'cupy.ndarray'>>: Connection reset by remote peer

During handling of the above exception, another exception occurred:

Traceback (most recent call last):
  File "/opt/conda/envs/gdf/lib/python3.9/site-packages/distributed/worker.py", line 1779, in get_data
    compressed = await comm.write(msg, serializers=serializers)
  File "/opt/conda/envs/gdf/lib/python3.9/site-packages/distributed/utils.py", line 832, in wrapper
    return await func(*args, **kwargs)
  File "/opt/conda/envs/gdf/lib/python3.9/site-packages/distributed/comm/ucx.py", line 338, in write
    raise CommClosedError("While writing, the connection was closed")
distributed.comm.core.CommClosedError: While writing, the connection was closed
Task exception was never retrieved
future: <Task finished name='Task-271' coro=<_listener_handler_coroutine() done, defined at /opt/conda/envs/gdf/lib/python3.9/site-packages/ucp/core.py:140> exception=UCXError('<stream_recv>: Connection reset by remote peer')>
Traceback (most recent call last):
  File "/opt/conda/envs/gdf/lib/python3.9/site-packages/ucp/core.py", line 155, in _listener_handler_coroutine
    peer_info = await exchange_peer_info(
  File "/opt/conda/envs/gdf/lib/python3.9/site-packages/ucp/core.py", line 55, in exchange_peer_info
    await asyncio.wait_for(
  File "/opt/conda/envs/gdf/lib/python3.9/asyncio/tasks.py", line 479, in wait_for
    return fut.result()
ucp._libs.exceptions.UCXError: <stream_recv>: Connection reset by remote peer
2024-02-28 07:30:15,474 - distributed.worker - ERROR - Worker stream died during communication: ucx://127.0.0.1:43965
Traceback (most recent call last):
  File "/opt/conda/envs/gdf/lib/python3.9/site-packages/distributed/comm/ucx.py", line 350, in read
    await self.ep.recv(msg)
  File "/opt/conda/envs/gdf/lib/python3.9/site-packages/ucp/core.py", line 737, in recv
    ret = await comm.tag_recv(self._ep, buffer, nbytes, tag, name=log)
ucp._libs.exceptions.UCXCanceled: <[Recv #000] ep: 0x7f844326c180, tag: 0x5bfc772fa4986066, nbytes: 16, type: <class 'numpy.ndarray'>>: 

During handling of the above exception, another exception occurred:

Traceback (most recent call last):
  File "/opt/conda/envs/gdf/lib/python3.9/site-packages/distributed/worker.py", line 2056, in gather_dep
    response = await get_data_from_worker(
  File "/opt/conda/envs/gdf/lib/python3.9/site-packages/distributed/worker.py", line 2857, in get_data_from_worker
    comm = await rpc.connect(worker)
  File "/opt/conda/envs/gdf/lib/python3.9/site-packages/distributed/core.py", line 1674, in connect
    return connect_attempt.result()
  File "/opt/conda/envs/gdf/lib/python3.9/site-packages/distributed/core.py", line 1564, in _connect
    comm = await connect(
  File "/opt/conda/envs/gdf/lib/python3.9/site-packages/distributed/comm/core.py", line 377, in connect
    handshake = await comm.read()
  File "/opt/conda/envs/gdf/lib/python3.9/site-packages/distributed/utils.py", line 832, in wrapper
    return await func(*args, **kwargs)
  File "/opt/conda/envs/gdf/lib/python3.9/site-packages/distributed/comm/ucx.py", line 368, in read
    raise CommClosedError(
distributed.comm.core.CommClosedError: Connection closed by writer.
Inner exception: UCXCanceled("<[Recv #000] ep: 0x7f844326c180, tag: 0x5bfc772fa4986066, nbytes: 16, type: <class 'numpy.ndarray'>>: ")
2024-02-28 07:30:15,624 - distributed.worker - ERROR - Worker stream died during communication: ucx://127.0.0.1:41827
Traceback (most recent call last):
  File "/opt/conda/envs/gdf/lib/python3.9/site-packages/distributed/comm/ucx.py", line 392, in read
    await self.ep.recv(each_frame)
  File "/opt/conda/envs/gdf/lib/python3.9/site-packages/ucp/core.py", line 737, in recv
    ret = await comm.tag_recv(self._ep, buffer, nbytes, tag, name=log)
ucp._libs.exceptions.UCXError: <[Recv #007] ep: 0x7f844326c200, tag: 0x5b560275d0e9fef4, nbytes: 50000000, type: <class 'rmm._lib.device_buffer.DeviceBuffer'>>: Connection reset by remote peer

During handling of the above exception, another exception occurred:

Traceback (most recent call last):
  File "/opt/conda/envs/gdf/lib/python3.9/site-packages/distributed/worker.py", line 2056, in gather_dep
    response = await get_data_from_worker(
  File "/opt/conda/envs/gdf/lib/python3.9/site-packages/distributed/worker.py", line 2860, in get_data_from_worker
    response = await send_recv(
  File "/opt/conda/envs/gdf/lib/python3.9/site-packages/distributed/core.py", line 1154, in send_recv
    response = await comm.read(deserializers=deserializers)
  File "/opt/conda/envs/gdf/lib/python3.9/site-packages/distributed/utils.py", line 832, in wrapper
    return await func(*args, **kwargs)
  File "/opt/conda/envs/gdf/lib/python3.9/site-packages/distributed/comm/ucx.py", line 398, in read
    raise CommClosedError(
distributed.comm.core.CommClosedError: Connection closed by writer.
Inner exception: UCXError("<[Recv #007] ep: 0x7f844326c200, tag: 0x5b560275d0e9fef4, nbytes: 50000000, type: <class 'rmm._lib.device_buffer.DeviceBuffer'>>: Connection reset by remote peer")
2024-02-28 07:30:15,625 - distributed.worker - ERROR - failed during get data with ucx://127.0.0.1:59839 -> ucx://127.0.0.1:41827
Traceback (most recent call last):
  File "/opt/conda/envs/gdf/lib/python3.9/site-packages/distributed/comm/ucx.py", line 334, in write
    await self.ep.send(each_frame)
  File "/opt/conda/envs/gdf/lib/python3.9/site-packages/ucp/core.py", line 662, in send
    return await comm.tag_send(self._ep, buffer, nbytes, tag, name=log)
ucp._libs.exceptions.UCXError: <[Send #007] ep: 0x7f844326c240, tag: 0x314b4e1a0187db6f, nbytes: 50000000, type: <class 'cupy.ndarray'>>: Connection reset by remote peer

During handling of the above exception, another exception occurred:

Traceback (most recent call last):
  File "/opt/conda/envs/gdf/lib/python3.9/site-packages/distributed/worker.py", line 1779, in get_data
    compressed = await comm.write(msg, serializers=serializers)
  File "/opt/conda/envs/gdf/lib/python3.9/site-packages/distributed/utils.py", line 832, in wrapper
    return await func(*args, **kwargs)
  File "/opt/conda/envs/gdf/lib/python3.9/site-packages/distributed/comm/ucx.py", line 338, in write
    raise CommClosedError("While writing, the connection was closed")
distributed.comm.core.CommClosedError: While writing, the connection was closed
2024-02-28 07:30:16,309 - distributed.nanny - WARNING - Restarting worker
2024-02-28 07:30:16,476 - distributed.nanny - WARNING - Restarting worker
2024-02-28 07:30:40,701 - distributed.worker - ERROR - Worker stream died during communication: ucx://127.0.0.1:49999
Traceback (most recent call last):
  File "/opt/conda/envs/gdf/lib/python3.9/site-packages/distributed/comm/ucx.py", line 467, in connect
    ep = await ucp.create_endpoint(ip, port)
  File "/opt/conda/envs/gdf/lib/python3.9/site-packages/ucp/core.py", line 1016, in create_endpoint
    return await _get_ctx().create_endpoint(
  File "/opt/conda/envs/gdf/lib/python3.9/site-packages/ucp/core.py", line 328, in create_endpoint
    peer_info = await exchange_peer_info(
  File "/opt/conda/envs/gdf/lib/python3.9/site-packages/ucp/core.py", line 60, in exchange_peer_info
    await asyncio.wait_for(
  File "/opt/conda/envs/gdf/lib/python3.9/asyncio/tasks.py", line 466, in wait_for
    await waiter
asyncio.exceptions.CancelledError

During handling of the above exception, another exception occurred:

Traceback (most recent call last):
  File "/opt/conda/envs/gdf/lib/python3.9/asyncio/tasks.py", line 490, in wait_for
    return fut.result()
asyncio.exceptions.CancelledError

The above exception was the direct cause of the following exception:

Traceback (most recent call last):
  File "/opt/conda/envs/gdf/lib/python3.9/site-packages/distributed/comm/core.py", line 342, in connect
    comm = await wait_for(
  File "/opt/conda/envs/gdf/lib/python3.9/site-packages/distributed/utils.py", line 1940, in wait_for
    return await asyncio.wait_for(fut, timeout)
  File "/opt/conda/envs/gdf/lib/python3.9/asyncio/tasks.py", line 492, in wait_for
    raise exceptions.TimeoutError() from exc
asyncio.exceptions.TimeoutError

The above exception was the direct cause of the following exception:

Traceback (most recent call last):
  File "/opt/conda/envs/gdf/lib/python3.9/site-packages/distributed/worker.py", line 2056, in gather_dep
    response = await get_data_from_worker(
  File "/opt/conda/envs/gdf/lib/python3.9/site-packages/distributed/worker.py", line 2857, in get_data_from_worker
    comm = await rpc.connect(worker)
  File "/opt/conda/envs/gdf/lib/python3.9/site-packages/distributed/core.py", line 1674, in connect
    return connect_attempt.result()
  File "/opt/conda/envs/gdf/lib/python3.9/site-packages/distributed/core.py", line 1564, in _connect
    comm = await connect(
  File "/opt/conda/envs/gdf/lib/python3.9/site-packages/distributed/comm/core.py", line 368, in connect
    raise OSError(
OSError: Timed out trying to connect to ucx://127.0.0.1:49999 after 30 s
2024-02-28 07:30:40,958 - distributed.worker - ERROR - Worker stream died during communication: ucx://127.0.0.1:49999
Traceback (most recent call last):
  File "/opt/conda/envs/gdf/lib/python3.9/site-packages/distributed/comm/ucx.py", line 467, in connect
    ep = await ucp.create_endpoint(ip, port)
  File "/opt/conda/envs/gdf/lib/python3.9/site-packages/ucp/core.py", line 1016, in create_endpoint
    return await _get_ctx().create_endpoint(
  File "/opt/conda/envs/gdf/lib/python3.9/site-packages/ucp/core.py", line 328, in create_endpoint
    peer_info = await exchange_peer_info(
  File "/opt/conda/envs/gdf/lib/python3.9/site-packages/ucp/core.py", line 60, in exchange_peer_info
    await asyncio.wait_for(
  File "/opt/conda/envs/gdf/lib/python3.9/asyncio/tasks.py", line 466, in wait_for
    await waiter
asyncio.exceptions.CancelledError

During handling of the above exception, another exception occurred:

Traceback (most recent call last):
  File "/opt/conda/envs/gdf/lib/python3.9/asyncio/tasks.py", line 490, in wait_for
    return fut.result()
asyncio.exceptions.CancelledError

The above exception was the direct cause of the following exception:

Traceback (most recent call last):
  File "/opt/conda/envs/gdf/lib/python3.9/site-packages/distributed/comm/core.py", line 342, in connect
    comm = await wait_for(
  File "/opt/conda/envs/gdf/lib/python3.9/site-packages/distributed/utils.py", line 1940, in wait_for
    return await asyncio.wait_for(fut, timeout)
  File "/opt/conda/envs/gdf/lib/python3.9/asyncio/tasks.py", line 492, in wait_for
    raise exceptions.TimeoutError() from exc
asyncio.exceptions.TimeoutError

The above exception was the direct cause of the following exception:

Traceback (most recent call last):
  File "/opt/conda/envs/gdf/lib/python3.9/site-packages/distributed/worker.py", line 2056, in gather_dep
    response = await get_data_from_worker(
  File "/opt/conda/envs/gdf/lib/python3.9/site-packages/distributed/worker.py", line 2857, in get_data_from_worker
    comm = await rpc.connect(worker)
  File "/opt/conda/envs/gdf/lib/python3.9/site-packages/distributed/core.py", line 1674, in connect
    return connect_attempt.result()
  File "/opt/conda/envs/gdf/lib/python3.9/site-packages/distributed/core.py", line 1564, in _connect
    comm = await connect(
  File "/opt/conda/envs/gdf/lib/python3.9/site-packages/distributed/comm/core.py", line 368, in connect
    raise OSError(
OSError: Timed out trying to connect to ucx://127.0.0.1:49999 after 30 s
/opt/conda/envs/gdf/lib/python3.9/multiprocessing/resource_tracker.py:216: UserWarning: resource_tracker: There appear to be 36 leaked semaphore objects to clean up at shutdown
  warnings.warn('resource_tracker: There appear to be %d '
