[dgx13:83268:0:83268] Caught signal 11 (Segmentation fault: address not mapped to object at address 0x448)
==== backtrace (tid:  83268) ====
 0  /opt/conda/envs/gdf/lib/libucs.so.0(ucs_handle_error+0x2fd) [0x7f3f21efd07d]
 1  /opt/conda/envs/gdf/lib/libucs.so.0(+0x2a274) [0x7f3f21efd274]
 2  /opt/conda/envs/gdf/lib/libucs.so.0(+0x2a43a) [0x7f3f21efd43a]
 3  /usr/lib/x86_64-linux-gnu/libpthread.so.0(+0x14420) [0x7f3fcb0db420]
 4  /opt/conda/envs/gdf/lib/libucp.so.0(ucp_mem_type_unpack+0x14) [0x7f3f21f7c6b4]
 5  /opt/conda/envs/gdf/lib/libucp.so.0(ucp_rndv_data_handler+0x4e9) [0x7f3f21fa5839]
 6  /opt/conda/envs/gdf/lib/libuct.so.0(+0x203df) [0x7f3f380373df]
 7  /opt/conda/envs/gdf/lib/libuct.so.0(+0x23838) [0x7f3f3803a838]
 8  /opt/conda/envs/gdf/lib/libucs.so.0(ucs_event_set_wait+0xb9) [0x7f3f21f064a9]
 9  /opt/conda/envs/gdf/lib/libuct.so.0(uct_tcp_iface_progress+0x7d) [0x7f3f380395dd]
10  /opt/conda/envs/gdf/lib/libucp.so.0(ucp_worker_progress+0x5a) [0x7f3f21f798da]
11  /opt/conda/envs/gdf/lib/python3.9/site-packages/ucp/_libs/ucx_api.cpython-39-x86_64-linux-gnu.so(+0x3206a) [0x7f3f3808506a]
12  /opt/conda/envs/gdf/bin/python(_PyEval_EvalFrameDefault+0x37cb) [0x55f865a426fb]
13  /opt/conda/envs/gdf/bin/python(+0x12f094) [0x55f865a3e094]
14  /opt/conda/envs/gdf/bin/python(_PyFunction_Vectorcall+0xd9) [0x55f865a4f519]
15  /opt/conda/envs/gdf/bin/python(_PyEval_EvalFrameDefault+0x696) [0x55f865a3f5c6]
16  /opt/conda/envs/gdf/bin/python(+0x1407c2) [0x55f865a4f7c2]
17  /opt/conda/envs/gdf/bin/python(+0x14de83) [0x55f865a5ce83]
18  /opt/conda/envs/gdf/bin/python(+0x258b2c) [0x55f865b67b2c]
19  /opt/conda/envs/gdf/bin/python(+0xead05) [0x55f8659f9d05]
20  /opt/conda/envs/gdf/bin/python(+0x1377f3) [0x55f865a467f3]
21  /opt/conda/envs/gdf/bin/python(_PyEval_EvalFrameDefault+0x59f9) [0x55f865a44929]
22  /opt/conda/envs/gdf/bin/python(+0x1407c2) [0x55f865a4f7c2]
23  /opt/conda/envs/gdf/bin/python(_PyEval_EvalFrameDefault+0x696) [0x55f865a3f5c6]
24  /opt/conda/envs/gdf/bin/python(+0x1407c2) [0x55f865a4f7c2]
25  /opt/conda/envs/gdf/bin/python(_PyEval_EvalFrameDefault+0x696) [0x55f865a3f5c6]
26  /opt/conda/envs/gdf/bin/python(+0x1407c2) [0x55f865a4f7c2]
27  /opt/conda/envs/gdf/bin/python(_PyEval_EvalFrameDefault+0x696) [0x55f865a3f5c6]
28  /opt/conda/envs/gdf/bin/python(+0x1407c2) [0x55f865a4f7c2]
29  /opt/conda/envs/gdf/bin/python(_PyEval_EvalFrameDefault+0x696) [0x55f865a3f5c6]
30  /opt/conda/envs/gdf/bin/python(+0x12f094) [0x55f865a3e094]
31  /opt/conda/envs/gdf/bin/python(_PyFunction_Vectorcall+0xd9) [0x55f865a4f519]
32  /opt/conda/envs/gdf/bin/python(_PyEval_EvalFrameDefault+0x11f8) [0x55f865a40128]
33  /opt/conda/envs/gdf/bin/python(+0x12f094) [0x55f865a3e094]
34  /opt/conda/envs/gdf/bin/python(+0x14dccb) [0x55f865a5cccb]
35  /opt/conda/envs/gdf/bin/python(PyObject_Call+0xbc) [0x55f865a5d44c]
36  /opt/conda/envs/gdf/bin/python(+0x21110e) [0x55f865b2010e]
37  /opt/conda/envs/gdf/bin/python(_PyObject_MakeTpCall+0x2ec) [0x55f865a4777c]
38  /opt/conda/envs/gdf/bin/python(_PyEval_EvalFrameDefault+0x37cb) [0x55f865a426fb]
39  /opt/conda/envs/gdf/bin/python(+0x1407c2) [0x55f865a4f7c2]
40  /opt/conda/envs/gdf/bin/python(+0x14ddac) [0x55f865a5cdac]
41  /opt/conda/envs/gdf/bin/python(_PyEval_EvalFrameDefault+0x37cb) [0x55f865a426fb]
42  /opt/conda/envs/gdf/bin/python(+0x1407c2) [0x55f865a4f7c2]
43  /opt/conda/envs/gdf/bin/python(_PyEval_EvalFrameDefault+0x696) [0x55f865a3f5c6]
44  /opt/conda/envs/gdf/bin/python(+0x12f094) [0x55f865a3e094]
45  /opt/conda/envs/gdf/bin/python(_PyFunction_Vectorcall+0xd9) [0x55f865a4f519]
46  /opt/conda/envs/gdf/bin/python(_PyEval_EvalFrameDefault+0x696) [0x55f865a3f5c6]
47  /opt/conda/envs/gdf/bin/python(+0x1407c2) [0x55f865a4f7c2]
48  /opt/conda/envs/gdf/bin/python(_PyEval_EvalFrameDefault+0x3e2) [0x55f865a3f312]
49  /opt/conda/envs/gdf/bin/python(+0x12f094) [0x55f865a3e094]
50  /opt/conda/envs/gdf/bin/python(_PyFunction_Vectorcall+0xd9) [0x55f865a4f519]
51  /opt/conda/envs/gdf/bin/python(_PyEval_EvalFrameDefault+0x11f8) [0x55f865a40128]
52  /opt/conda/envs/gdf/bin/python(+0x12f094) [0x55f865a3e094]
53  /opt/conda/envs/gdf/bin/python(_PyEval_EvalCodeWithName+0x48) [0x55f865a3dd68]
54  /opt/conda/envs/gdf/bin/python(PyEval_EvalCodeEx+0x39) [0x55f865a3dd19]
55  /opt/conda/envs/gdf/bin/python(PyEval_EvalCode+0x1b) [0x55f865aeb07b]
56  /opt/conda/envs/gdf/bin/python(+0x208fca) [0x55f865b17fca]
57  /opt/conda/envs/gdf/bin/python(+0x205353) [0x55f865b14353]
58  /opt/conda/envs/gdf/bin/python(PyRun_StringFlags+0x9a) [0x55f865b0c16a]
59  /opt/conda/envs/gdf/bin/python(PyRun_SimpleStringFlags+0x3c) [0x55f865b0c05c]
60  /opt/conda/envs/gdf/bin/python(Py_RunMain+0x267) [0x55f865b0b297]
61  /opt/conda/envs/gdf/bin/python(Py_BytesMain+0x37) [0x55f865adef07]
=================================
[dgx13:83262:0:83262] Caught signal 11 (Segmentation fault: address not mapped to object at address 0x448)
==== backtrace (tid:  83262) ====
 0  /opt/conda/envs/gdf/lib/libucs.so.0(ucs_handle_error+0x2fd) [0x7fc63c72f07d]
 1  /opt/conda/envs/gdf/lib/libucs.so.0(+0x2a274) [0x7fc63c72f274]
 2  /opt/conda/envs/gdf/lib/libucs.so.0(+0x2a43a) [0x7fc63c72f43a]
 3  /usr/lib/x86_64-linux-gnu/libpthread.so.0(+0x14420) [0x7fc6dd8b3420]
 4  /opt/conda/envs/gdf/lib/libucp.so.0(ucp_mem_type_unpack+0x14) [0x7fc63c7ae6b4]
 5  /opt/conda/envs/gdf/lib/libucp.so.0(ucp_rndv_data_handler+0x4e9) [0x7fc63c7d7839]
 6  /opt/conda/envs/gdf/lib/libuct.so.0(+0x203df) [0x7fc63c6e93df]
 7  /opt/conda/envs/gdf/lib/libuct.so.0(+0x23838) [0x7fc63c6ec838]
 8  /opt/conda/envs/gdf/lib/libucs.so.0(ucs_event_set_wait+0xb9) [0x7fc63c7384a9]
 9  /opt/conda/envs/gdf/lib/libuct.so.0(uct_tcp_iface_progress+0x7d) [0x7fc63c6eb5dd]
10  /opt/conda/envs/gdf/lib/libucp.so.0(ucp_worker_progress+0x5a) [0x7fc63c7ab8da]
11  /opt/conda/envs/gdf/lib/python3.9/site-packages/ucp/_libs/ucx_api.cpython-39-x86_64-linux-gnu.so(+0x3206a) [0x7fc63c86406a]
12  /opt/conda/envs/gdf/bin/python(_PyEval_EvalFrameDefault+0x37cb) [0x55846d2526fb]
13  /opt/conda/envs/gdf/bin/python(+0x12f094) [0x55846d24e094]
14  /opt/conda/envs/gdf/bin/python(_PyFunction_Vectorcall+0xd9) [0x55846d25f519]
15  /opt/conda/envs/gdf/bin/python(_PyEval_EvalFrameDefault+0x696) [0x55846d24f5c6]
16  /opt/conda/envs/gdf/bin/python(+0x1e3162) [0x55846d302162]
17  /opt/conda/envs/gdf/lib/python3.9/lib-dynload/_asyncio.cpython-39-x86_64-linux-gnu.so(+0x81e9) [0x7fc65da3d1e9]
18  /opt/conda/envs/gdf/bin/python(_PyObject_MakeTpCall+0x2ec) [0x55846d25777c]
19  /opt/conda/envs/gdf/bin/python(+0xead05) [0x55846d209d05]
20  /opt/conda/envs/gdf/bin/python(+0x1377f3) [0x55846d2567f3]
21  /opt/conda/envs/gdf/bin/python(_PyEval_EvalFrameDefault+0x59f9) [0x55846d254929]
22  /opt/conda/envs/gdf/bin/python(+0x1407c2) [0x55846d25f7c2]
23  /opt/conda/envs/gdf/bin/python(_PyEval_EvalFrameDefault+0x696) [0x55846d24f5c6]
24  /opt/conda/envs/gdf/bin/python(+0x1407c2) [0x55846d25f7c2]
25  /opt/conda/envs/gdf/bin/python(_PyEval_EvalFrameDefault+0x696) [0x55846d24f5c6]
26  /opt/conda/envs/gdf/bin/python(+0x1407c2) [0x55846d25f7c2]
27  /opt/conda/envs/gdf/bin/python(_PyEval_EvalFrameDefault+0x696) [0x55846d24f5c6]
28  /opt/conda/envs/gdf/bin/python(+0x1407c2) [0x55846d25f7c2]
29  /opt/conda/envs/gdf/bin/python(_PyEval_EvalFrameDefault+0x696) [0x55846d24f5c6]
30  /opt/conda/envs/gdf/bin/python(+0x12f094) [0x55846d24e094]
31  /opt/conda/envs/gdf/bin/python(_PyFunction_Vectorcall+0xd9) [0x55846d25f519]
32  /opt/conda/envs/gdf/bin/python(_PyEval_EvalFrameDefault+0x11f8) [0x55846d250128]
33  /opt/conda/envs/gdf/bin/python(+0x12f094) [0x55846d24e094]
34  /opt/conda/envs/gdf/bin/python(+0x14dccb) [0x55846d26cccb]
35  /opt/conda/envs/gdf/bin/python(PyObject_Call+0xbc) [0x55846d26d44c]
36  /opt/conda/envs/gdf/bin/python(+0x21110e) [0x55846d33010e]
37  /opt/conda/envs/gdf/bin/python(_PyObject_MakeTpCall+0x2ec) [0x55846d25777c]
38  /opt/conda/envs/gdf/bin/python(_PyEval_EvalFrameDefault+0x37cb) [0x55846d2526fb]
39  /opt/conda/envs/gdf/bin/python(+0x1407c2) [0x55846d25f7c2]
40  /opt/conda/envs/gdf/bin/python(+0x14ddac) [0x55846d26cdac]
41  /opt/conda/envs/gdf/bin/python(_PyEval_EvalFrameDefault+0x37cb) [0x55846d2526fb]
42  /opt/conda/envs/gdf/bin/python(+0x1407c2) [0x55846d25f7c2]
43  /opt/conda/envs/gdf/bin/python(_PyEval_EvalFrameDefault+0x696) [0x55846d24f5c6]
44  /opt/conda/envs/gdf/bin/python(+0x12f094) [0x55846d24e094]
45  /opt/conda/envs/gdf/bin/python(_PyFunction_Vectorcall+0xd9) [0x55846d25f519]
46  /opt/conda/envs/gdf/bin/python(_PyEval_EvalFrameDefault+0x696) [0x55846d24f5c6]
47  /opt/conda/envs/gdf/bin/python(+0x1407c2) [0x55846d25f7c2]
48  /opt/conda/envs/gdf/bin/python(_PyEval_EvalFrameDefault+0x3e2) [0x55846d24f312]
49  /opt/conda/envs/gdf/bin/python(+0x12f094) [0x55846d24e094]
50  /opt/conda/envs/gdf/bin/python(_PyFunction_Vectorcall+0xd9) [0x55846d25f519]
51  /opt/conda/envs/gdf/bin/python(_PyEval_EvalFrameDefault+0x11f8) [0x55846d250128]
52  /opt/conda/envs/gdf/bin/python(+0x12f094) [0x55846d24e094]
53  /opt/conda/envs/gdf/bin/python(_PyEval_EvalCodeWithName+0x48) [0x55846d24dd68]
54  /opt/conda/envs/gdf/bin/python(PyEval_EvalCodeEx+0x39) [0x55846d24dd19]
55  /opt/conda/envs/gdf/bin/python(PyEval_EvalCode+0x1b) [0x55846d2fb07b]
56  /opt/conda/envs/gdf/bin/python(+0x208fca) [0x55846d327fca]
57  /opt/conda/envs/gdf/bin/python(+0x205353) [0x55846d324353]
58  /opt/conda/envs/gdf/bin/python(PyRun_StringFlags+0x9a) [0x55846d31c16a]
59  /opt/conda/envs/gdf/bin/python(PyRun_SimpleStringFlags+0x3c) [0x55846d31c05c]
60  /opt/conda/envs/gdf/bin/python(Py_RunMain+0x267) [0x55846d31b297]
61  /opt/conda/envs/gdf/bin/python(Py_BytesMain+0x37) [0x55846d2eef07]
=================================
[dgx13:83256:0:83256] Caught signal 11 (Segmentation fault: address not mapped to object at address 0x448)
[dgx13:83265:0:83265] Caught signal 11 (Segmentation fault: address not mapped to object at address 0x448)
==== backtrace (tid:  83256) ====
 0  /opt/conda/envs/gdf/lib/libucs.so.0(ucs_handle_error+0x2fd) [0x7f796063807d]
 1  /opt/conda/envs/gdf/lib/libucs.so.0(+0x2a274) [0x7f7960638274]
 2  /opt/conda/envs/gdf/lib/libucs.so.0(+0x2a43a) [0x7f796063843a]
 3  /usr/lib/x86_64-linux-gnu/libpthread.so.0(+0x14420) [0x7f79f37a9420]
 4  /opt/conda/envs/gdf/lib/libucp.so.0(ucp_mem_type_unpack+0x14) [0x7f79606b76b4]
 5  /opt/conda/envs/gdf/lib/libucp.so.0(ucp_rndv_data_handler+0x4e9) [0x7f79606e0839]
 6  /opt/conda/envs/gdf/lib/libuct.so.0(+0x203df) [0x7f79605f23df]
 7  /opt/conda/envs/gdf/lib/libuct.so.0(+0x23838) [0x7f79605f5838]
 8  /opt/conda/envs/gdf/lib/libucs.so.0(ucs_event_set_wait+0xb9) [0x7f79606414a9]
 9  /opt/conda/envs/gdf/lib/libuct.so.0(uct_tcp_iface_progress+0x7d) [0x7f79605f45dd]
10  /opt/conda/envs/gdf/lib/libucp.so.0(ucp_worker_progress+0x5a) [0x7f79606b48da]
11  /opt/conda/envs/gdf/lib/python3.9/site-packages/ucp/_libs/ucx_api.cpython-39-x86_64-linux-gnu.so(+0x3206a) [0x7f796076d06a]
12  /opt/conda/envs/gdf/bin/python(_PyEval_EvalFrameDefault+0x37cb) [0x561090daf6fb]
13  /opt/conda/envs/gdf/bin/python(+0x12f094) [0x561090dab094]
14  /opt/conda/envs/gdf/bin/python(_PyFunction_Vectorcall+0xd9) [0x561090dbc519]
15  /opt/conda/envs/gdf/bin/python(_PyEval_EvalFrameDefault+0x696) [0x561090dac5c6]
16  /opt/conda/envs/gdf/bin/python(+0x1407c2) [0x561090dbc7c2]
17  /opt/conda/envs/gdf/bin/python(+0x14de83) [0x561090dc9e83]
18  /opt/conda/envs/gdf/bin/python(+0x258b2c) [0x561090ed4b2c]
19  /opt/conda/envs/gdf/bin/python(+0xead05) [0x561090d66d05]
20  /opt/conda/envs/gdf/bin/python(+0x1377f3) [0x561090db37f3]
21  /opt/conda/envs/gdf/bin/python(_PyEval_EvalFrameDefault+0x59f9) [0x561090db1929]
22  /opt/conda/envs/gdf/bin/python(+0x1407c2) [0x561090dbc7c2]
23  /opt/conda/envs/gdf/bin/python(_PyEval_EvalFrameDefault+0x696) [0x561090dac5c6]
24  /opt/conda/envs/gdf/bin/python(+0x1407c2) [0x561090dbc7c2]
25  /opt/conda/envs/gdf/bin/python(_PyEval_EvalFrameDefault+0x696) [0x561090dac5c6]
26  /opt/conda/envs/gdf/bin/python(+0x1407c2) [0x561090dbc7c2]
27  /opt/conda/envs/gdf/bin/python(_PyEval_EvalFrameDefault+0x696) [0x561090dac5c6]
28  /opt/conda/envs/gdf/bin/python(+0x1407c2) [0x561090dbc7c2]
29  /opt/conda/envs/gdf/bin/python(_PyEval_EvalFrameDefault+0x696) [0x561090dac5c6]
30  /opt/conda/envs/gdf/bin/python(+0x12f094) [0x561090dab094]
31  /opt/conda/envs/gdf/bin/python(_PyFunction_Vectorcall+0xd9) [0x561090dbc519]
32  /opt/conda/envs/gdf/bin/python(_PyEval_EvalFrameDefault+0x11f8) [0x561090dad128]
33  /opt/conda/envs/gdf/bin/python(+0x12f094) [0x561090dab094]
34  /opt/conda/envs/gdf/bin/python(+0x14dccb) [0x561090dc9ccb]
35  /opt/conda/envs/gdf/bin/python(PyObject_Call+0xbc) [0x561090dca44c]
36  /opt/conda/envs/gdf/bin/python(+0x21110e) [0x561090e8d10e]
37  /opt/conda/envs/gdf/bin/python(_PyObject_MakeTpCall+0x2ec) [0x561090db477c]
38  /opt/conda/envs/gdf/bin/python(_PyEval_EvalFrameDefault+0x37cb) [0x561090daf6fb]
39  /opt/conda/envs/gdf/bin/python(+0x1407c2) [0x561090dbc7c2]
40  /opt/conda/envs/gdf/bin/python(+0x14ddac) [0x561090dc9dac]
41  /opt/conda/envs/gdf/bin/python(_PyEval_EvalFrameDefault+0x37cb) [0x561090daf6fb]
42  /opt/conda/envs/gdf/bin/python(+0x1407c2) [0x561090dbc7c2]
==== backtrace (tid:  83265) ====
43  /opt/conda/envs/gdf/bin/python(_PyEval_EvalFrameDefault+0x696) [0x561090dac5c6]
44  /opt/conda/envs/gdf/bin/python(+0x12f094) [0x561090dab094]
 0  /opt/conda/envs/gdf/lib/libucs.so.0(ucs_handle_error+0x2fd) [0x7fe8b98e707d]
 1  /opt/conda/envs/gdf/lib/libucs.so.0(+0x2a274) [0x7fe8b98e7274]
45  /opt/conda/envs/gdf/bin/python(_PyFunction_Vectorcall+0xd9) [0x561090dbc519]
 2  /opt/conda/envs/gdf/lib/libucs.so.0(+0x2a43a) [0x7fe8b98e743a]
46  /opt/conda/envs/gdf/bin/python(_PyEval_EvalFrameDefault+0x696) [0x561090dac5c6]
 3  /usr/lib/x86_64-linux-gnu/libpthread.so.0(+0x14420) [0x7fe95ea6d420]
47  /opt/conda/envs/gdf/bin/python(+0x1407c2) [0x561090dbc7c2]
 4  /opt/conda/envs/gdf/lib/libucp.so.0(ucp_mem_type_unpack+0x14) [0x7fe8b99666b4]
48  /opt/conda/envs/gdf/bin/python(_PyEval_EvalFrameDefault+0x3e2) [0x561090dac312]
 5  /opt/conda/envs/gdf/lib/libucp.so.0(ucp_rndv_data_handler+0x4e9) [0x7fe8b998f839]
49  /opt/conda/envs/gdf/bin/python(+0x12f094) [0x561090dab094]
 6  /opt/conda/envs/gdf/lib/libuct.so.0(+0x203df) [0x7fe8b98a13df]
 7  /opt/conda/envs/gdf/lib/libuct.so.0(+0x23838) [0x7fe8b98a4838]
 8  /opt/conda/envs/gdf/lib/libucs.so.0(ucs_event_set_wait+0xb9) [0x7fe8b98f04a9]
50  /opt/conda/envs/gdf/bin/python(_PyFunction_Vectorcall+0xd9) [0x561090dbc519]
 9  /opt/conda/envs/gdf/lib/libuct.so.0(uct_tcp_iface_progress+0x7d) [0x7fe8b98a35dd]
51  /opt/conda/envs/gdf/bin/python(_PyEval_EvalFrameDefault+0x11f8) [0x561090dad128]
10  /opt/conda/envs/gdf/lib/libucp.so.0(ucp_worker_progress+0x5a) [0x7fe8b99638da]
52  /opt/conda/envs/gdf/bin/python(+0x12f094) [0x561090dab094]
11  /opt/conda/envs/gdf/lib/python3.9/site-packages/ucp/_libs/ucx_api.cpython-39-x86_64-linux-gnu.so(+0x3206a) [0x7fe8b9a1c06a]
53  /opt/conda/envs/gdf/bin/python(_PyEval_EvalCodeWithName+0x48) [0x561090daad68]
12  /opt/conda/envs/gdf/bin/python(_PyEval_EvalFrameDefault+0x37cb) [0x55751cd886fb]
54  /opt/conda/envs/gdf/bin/python(PyEval_EvalCodeEx+0x39) [0x561090daad19]
13  /opt/conda/envs/gdf/bin/python(+0x12f094) [0x55751cd84094]
55  /opt/conda/envs/gdf/bin/python(PyEval_EvalCode+0x1b) [0x561090e5807b]
14  /opt/conda/envs/gdf/bin/python(_PyFunction_Vectorcall+0xd9) [0x55751cd95519]
56  /opt/conda/envs/gdf/bin/python(+0x208fca) [0x561090e84fca]
15  /opt/conda/envs/gdf/bin/python(_PyEval_EvalFrameDefault+0x696) [0x55751cd855c6]
57  /opt/conda/envs/gdf/bin/python(+0x205353) [0x561090e81353]
16  /opt/conda/envs/gdf/bin/python(+0x1407c2) [0x55751cd957c2]
58  /opt/conda/envs/gdf/bin/python(PyRun_StringFlags+0x9a) [0x561090e7916a]
17  /opt/conda/envs/gdf/bin/python(+0x14de83) [0x55751cda2e83]
59  /opt/conda/envs/gdf/bin/python(PyRun_SimpleStringFlags+0x3c) [0x561090e7905c]
18  /opt/conda/envs/gdf/bin/python(+0x258b2c) [0x55751ceadb2c]
19  /opt/conda/envs/gdf/bin/python(+0xead05) [0x55751cd3fd05]
60  /opt/conda/envs/gdf/bin/python(Py_RunMain+0x267) [0x561090e78297]
20  /opt/conda/envs/gdf/bin/python(+0x1377f3) [0x55751cd8c7f3]
61  /opt/conda/envs/gdf/bin/python(Py_BytesMain+0x37) [0x561090e4bf07]
21  /opt/conda/envs/gdf/bin/python(_PyEval_EvalFrameDefault+0x59f9) [0x55751cd8a929]
=================================
22  /opt/conda/envs/gdf/bin/python(+0x1407c2) [0x55751cd957c2]
23  /opt/conda/envs/gdf/bin/python(_PyEval_EvalFrameDefault+0x696) [0x55751cd855c6]
24  /opt/conda/envs/gdf/bin/python(+0x1407c2) [0x55751cd957c2]
25  /opt/conda/envs/gdf/bin/python(_PyEval_EvalFrameDefault+0x696) [0x55751cd855c6]
26  /opt/conda/envs/gdf/bin/python(+0x1407c2) [0x55751cd957c2]
27  /opt/conda/envs/gdf/bin/python(_PyEval_EvalFrameDefault+0x696) [0x55751cd855c6]
28  /opt/conda/envs/gdf/bin/python(+0x1407c2) [0x55751cd957c2]
29  /opt/conda/envs/gdf/bin/python(_PyEval_EvalFrameDefault+0x696) [0x55751cd855c6]
30  /opt/conda/envs/gdf/bin/python(+0x12f094) [0x55751cd84094]
31  /opt/conda/envs/gdf/bin/python(_PyFunction_Vectorcall+0xd9) [0x55751cd95519]
32  /opt/conda/envs/gdf/bin/python(_PyEval_EvalFrameDefault+0x11f8) [0x55751cd86128]
33  /opt/conda/envs/gdf/bin/python(+0x12f094) [0x55751cd84094]
34  /opt/conda/envs/gdf/bin/python(+0x14dccb) [0x55751cda2ccb]
35  /opt/conda/envs/gdf/bin/python(PyObject_Call+0xbc) [0x55751cda344c]
36  /opt/conda/envs/gdf/bin/python(+0x21110e) [0x55751ce6610e]
37  /opt/conda/envs/gdf/bin/python(_PyObject_MakeTpCall+0x2ec) [0x55751cd8d77c]
38  /opt/conda/envs/gdf/bin/python(_PyEval_EvalFrameDefault+0x37cb) [0x55751cd886fb]
39  /opt/conda/envs/gdf/bin/python(+0x1407c2) [0x55751cd957c2]
40  /opt/conda/envs/gdf/bin/python(+0x14ddac) [0x55751cda2dac]
41  /opt/conda/envs/gdf/bin/python(_PyEval_EvalFrameDefault+0x37cb) [0x55751cd886fb]
42  /opt/conda/envs/gdf/bin/python(+0x1407c2) [0x55751cd957c2]
43  /opt/conda/envs/gdf/bin/python(_PyEval_EvalFrameDefault+0x696) [0x55751cd855c6]
44  /opt/conda/envs/gdf/bin/python(+0x12f094) [0x55751cd84094]
45  /opt/conda/envs/gdf/bin/python(_PyFunction_Vectorcall+0xd9) [0x55751cd95519]
46  /opt/conda/envs/gdf/bin/python(_PyEval_EvalFrameDefault+0x696) [0x55751cd855c6]
47  /opt/conda/envs/gdf/bin/python(+0x1407c2) [0x55751cd957c2]
48  /opt/conda/envs/gdf/bin/python(_PyEval_EvalFrameDefault+0x3e2) [0x55751cd85312]
49  /opt/conda/envs/gdf/bin/python(+0x12f094) [0x55751cd84094]
50  /opt/conda/envs/gdf/bin/python(_PyFunction_Vectorcall+0xd9) [0x55751cd95519]
51  /opt/conda/envs/gdf/bin/python(_PyEval_EvalFrameDefault+0x11f8) [0x55751cd86128]
52  /opt/conda/envs/gdf/bin/python(+0x12f094) [0x55751cd84094]
53  /opt/conda/envs/gdf/bin/python(_PyEval_EvalCodeWithName+0x48) [0x55751cd83d68]
54  /opt/conda/envs/gdf/bin/python(PyEval_EvalCodeEx+0x39) [0x55751cd83d19]
55  /opt/conda/envs/gdf/bin/python(PyEval_EvalCode+0x1b) [0x55751ce3107b]
56  /opt/conda/envs/gdf/bin/python(+0x208fca) [0x55751ce5dfca]
57  /opt/conda/envs/gdf/bin/python(+0x205353) [0x55751ce5a353]
58  /opt/conda/envs/gdf/bin/python(PyRun_StringFlags+0x9a) [0x55751ce5216a]
59  /opt/conda/envs/gdf/bin/python(PyRun_SimpleStringFlags+0x3c) [0x55751ce5205c]
60  /opt/conda/envs/gdf/bin/python(Py_RunMain+0x267) [0x55751ce51297]
61  /opt/conda/envs/gdf/bin/python(Py_BytesMain+0x37) [0x55751ce24f07]
=================================
2023-11-06 09:15:29,693 - distributed.worker - ERROR - Worker stream died during communication: ucx://127.0.0.1:41883
Traceback (most recent call last):
  File "/opt/conda/envs/gdf/lib/python3.9/site-packages/distributed/comm/ucx.py", line 354, in read
    await self.ep.recv(msg)
  File "/opt/conda/envs/gdf/lib/python3.9/site-packages/ucp/core.py", line 725, in recv
    ret = await comm.tag_recv(self._ep, buffer, nbytes, tag, name=log)
ucp._libs.exceptions.UCXCanceled: <[Recv #008] ep: 0x7fd0b829e1c0, tag: 0x6c0908e62e127200, nbytes: 16, type: <class 'numpy.ndarray'>>: 

During handling of the above exception, another exception occurred:

Traceback (most recent call last):
  File "/opt/conda/envs/gdf/lib/python3.9/site-packages/distributed/worker.py", line 2059, in gather_dep
    response = await get_data_from_worker(
  File "/opt/conda/envs/gdf/lib/python3.9/site-packages/distributed/worker.py", line 2852, in get_data_from_worker
    response = await send_recv(
  File "/opt/conda/envs/gdf/lib/python3.9/site-packages/distributed/core.py", line 1106, in send_recv
    response = await comm.read(deserializers=deserializers)
  File "/opt/conda/envs/gdf/lib/python3.9/site-packages/distributed/utils.py", line 803, in wrapper
    return await func(*args, **kwargs)
  File "/opt/conda/envs/gdf/lib/python3.9/site-packages/distributed/comm/ucx.py", line 372, in read
    raise CommClosedError(
distributed.comm.core.CommClosedError: Connection closed by writer.
Inner exception: UCXCanceled("<[Recv #008] ep: 0x7fd0b829e1c0, tag: 0x6c0908e62e127200, nbytes: 16, type: <class 'numpy.ndarray'>>: ")
2023-11-06 09:15:29,693 - distributed.worker - ERROR - Worker stream died during communication: ucx://127.0.0.1:41883
Traceback (most recent call last):
  File "/opt/conda/envs/gdf/lib/python3.9/site-packages/distributed/comm/ucx.py", line 354, in read
    await self.ep.recv(msg)
  File "/opt/conda/envs/gdf/lib/python3.9/site-packages/ucp/core.py", line 725, in recv
    ret = await comm.tag_recv(self._ep, buffer, nbytes, tag, name=log)
ucp._libs.exceptions.UCXCanceled: <[Recv #003] ep: 0x7f59ac4411c0, tag: 0xdb5de080d19be2b8, nbytes: 16, type: <class 'numpy.ndarray'>>: 

During handling of the above exception, another exception occurred:

Traceback (most recent call last):
  File "/opt/conda/envs/gdf/lib/python3.9/site-packages/distributed/worker.py", line 2059, in gather_dep
    response = await get_data_from_worker(
  File "/opt/conda/envs/gdf/lib/python3.9/site-packages/distributed/worker.py", line 2852, in get_data_from_worker
    response = await send_recv(
  File "/opt/conda/envs/gdf/lib/python3.9/site-packages/distributed/core.py", line 1106, in send_recv
    response = await comm.read(deserializers=deserializers)
  File "/opt/conda/envs/gdf/lib/python3.9/site-packages/distributed/utils.py", line 803, in wrapper
    return await func(*args, **kwargs)
  File "/opt/conda/envs/gdf/lib/python3.9/site-packages/distributed/comm/ucx.py", line 372, in read
    raise CommClosedError(
distributed.comm.core.CommClosedError: Connection closed by writer.
Inner exception: UCXCanceled("<[Recv #003] ep: 0x7f59ac4411c0, tag: 0xdb5de080d19be2b8, nbytes: 16, type: <class 'numpy.ndarray'>>: ")
2023-11-06 09:15:29,693 - distributed.worker - ERROR - Worker stream died during communication: ucx://127.0.0.1:41883
Traceback (most recent call last):
  File "/opt/conda/envs/gdf/lib/python3.9/site-packages/distributed/comm/ucx.py", line 354, in read
    await self.ep.recv(msg)
  File "/opt/conda/envs/gdf/lib/python3.9/site-packages/ucp/core.py", line 725, in recv
    ret = await comm.tag_recv(self._ep, buffer, nbytes, tag, name=log)
ucp._libs.exceptions.UCXCanceled: <[Recv #003] ep: 0x7fc4049e3240, tag: 0x2c175dfbad846581, nbytes: 16, type: <class 'numpy.ndarray'>>: 

During handling of the above exception, another exception occurred:

Traceback (most recent call last):
  File "/opt/conda/envs/gdf/lib/python3.9/site-packages/distributed/worker.py", line 2059, in gather_dep
    response = await get_data_from_worker(
  File "/opt/conda/envs/gdf/lib/python3.9/site-packages/distributed/worker.py", line 2852, in get_data_from_worker
    response = await send_recv(
  File "/opt/conda/envs/gdf/lib/python3.9/site-packages/distributed/core.py", line 1106, in send_recv
    response = await comm.read(deserializers=deserializers)
  File "/opt/conda/envs/gdf/lib/python3.9/site-packages/distributed/utils.py", line 803, in wrapper
    return await func(*args, **kwargs)
  File "/opt/conda/envs/gdf/lib/python3.9/site-packages/distributed/comm/ucx.py", line 372, in read
    raise CommClosedError(
distributed.comm.core.CommClosedError: Connection closed by writer.
Inner exception: UCXCanceled("<[Recv #003] ep: 0x7fc4049e3240, tag: 0x2c175dfbad846581, nbytes: 16, type: <class 'numpy.ndarray'>>: ")
2023-11-06 09:15:29,698 - distributed.worker - ERROR - Worker stream died during communication: ucx://127.0.0.1:41883
Traceback (most recent call last):
  File "/opt/conda/envs/gdf/lib/python3.9/site-packages/distributed/comm/ucx.py", line 471, in connect
    ep = await ucp.create_endpoint(ip, port)
  File "/opt/conda/envs/gdf/lib/python3.9/site-packages/ucp/core.py", line 1004, in create_endpoint
    return await _get_ctx().create_endpoint(
  File "/opt/conda/envs/gdf/lib/python3.9/site-packages/ucp/core.py", line 316, in create_endpoint
    peer_info = await exchange_peer_info(
  File "/opt/conda/envs/gdf/lib/python3.9/site-packages/ucp/core.py", line 54, in exchange_peer_info
    await comm.stream_recv(endpoint, peer_info_arr, peer_info_arr.nbytes)
ucp._libs.exceptions.UCXNotConnected: <stream_recv>: 

During handling of the above exception, another exception occurred:

Traceback (most recent call last):
  File "/opt/conda/envs/gdf/lib/python3.9/site-packages/distributed/comm/core.py", line 342, in connect
    comm = await wait_for(
  File "/opt/conda/envs/gdf/lib/python3.9/site-packages/distributed/utils.py", line 1920, in wait_for
    return await asyncio.wait_for(fut, timeout)
  File "/opt/conda/envs/gdf/lib/python3.9/asyncio/tasks.py", line 479, in wait_for
    return fut.result()
  File "/opt/conda/envs/gdf/lib/python3.9/site-packages/distributed/comm/ucx.py", line 473, in connect
    raise CommClosedError("Connection closed before handshake completed")
distributed.comm.core.CommClosedError: Connection closed before handshake completed

During handling of the above exception, another exception occurred:

Traceback (most recent call last):
  File "/opt/conda/envs/gdf/lib/python3.9/site-packages/distributed/core.py", line 1516, in _connect
    comm = await connect(
  File "/opt/conda/envs/gdf/lib/python3.9/site-packages/distributed/comm/core.py", line 366, in connect
    await asyncio.sleep(backoff)
  File "/opt/conda/envs/gdf/lib/python3.9/asyncio/tasks.py", line 652, in sleep
    return await future
asyncio.exceptions.CancelledError

During handling of the above exception, another exception occurred:

Traceback (most recent call last):
  File "/opt/conda/envs/gdf/lib/python3.9/site-packages/distributed/core.py", line 1626, in connect
    return connect_attempt.result()
asyncio.exceptions.CancelledError

During handling of the above exception, another exception occurred:

Traceback (most recent call last):
  File "/opt/conda/envs/gdf/lib/python3.9/site-packages/distributed/worker.py", line 2059, in gather_dep
    response = await get_data_from_worker(
  File "/opt/conda/envs/gdf/lib/python3.9/site-packages/distributed/worker.py", line 2849, in get_data_from_worker
    comm = await rpc.connect(worker)
  File "/opt/conda/envs/gdf/lib/python3.9/site-packages/distributed/core.py", line 1628, in connect
    raise CommClosedError(reason)
distributed.comm.core.CommClosedError: Address removed.
2023-11-06 09:15:29,756 - distributed.worker - ERROR - failed during get data with ucx://127.0.0.1:58251 -> ucx://127.0.0.1:43879
Traceback (most recent call last):
  File "/opt/conda/envs/gdf/lib/python3.9/site-packages/distributed/comm/ucx.py", line 338, in write
    await self.ep.send(each_frame)
  File "/opt/conda/envs/gdf/lib/python3.9/site-packages/ucp/core.py", line 650, in send
    return await comm.tag_send(self._ep, buffer, nbytes, tag, name=log)
ucp._libs.exceptions.UCXError: <[Send #007] ep: 0x7f2b2292c200, tag: 0xeec5e10b8151ab89, nbytes: 50000000, type: <class 'cupy.ndarray'>>: Connection reset by remote peer

During handling of the above exception, another exception occurred:

Traceback (most recent call last):
  File "/opt/conda/envs/gdf/lib/python3.9/site-packages/distributed/worker.py", line 1782, in get_data
    compressed = await comm.write(msg, serializers=serializers)
  File "/opt/conda/envs/gdf/lib/python3.9/site-packages/distributed/utils.py", line 803, in wrapper
    return await func(*args, **kwargs)
  File "/opt/conda/envs/gdf/lib/python3.9/site-packages/distributed/comm/ucx.py", line 342, in write
    raise CommClosedError("While writing, the connection was closed")
distributed.comm.core.CommClosedError: While writing, the connection was closed
2023-11-06 09:15:29,757 - distributed.worker - ERROR - Worker stream died during communication: ucx://127.0.0.1:38643
Traceback (most recent call last):
  File "/opt/conda/envs/gdf/lib/python3.9/site-packages/distributed/comm/ucx.py", line 354, in read
    await self.ep.recv(msg)
  File "/opt/conda/envs/gdf/lib/python3.9/site-packages/ucp/core.py", line 725, in recv
    ret = await comm.tag_recv(self._ep, buffer, nbytes, tag, name=log)
ucp._libs.exceptions.UCXCanceled: <[Recv #003] ep: 0x7f2b2292c1c0, tag: 0x6d0168510480f58e, nbytes: 16, type: <class 'numpy.ndarray'>>: 

During handling of the above exception, another exception occurred:

Traceback (most recent call last):
  File "/opt/conda/envs/gdf/lib/python3.9/site-packages/distributed/worker.py", line 2059, in gather_dep
    response = await get_data_from_worker(
  File "/opt/conda/envs/gdf/lib/python3.9/site-packages/distributed/worker.py", line 2852, in get_data_from_worker
    response = await send_recv(
  File "/opt/conda/envs/gdf/lib/python3.9/site-packages/distributed/core.py", line 1106, in send_recv
    response = await comm.read(deserializers=deserializers)
  File "/opt/conda/envs/gdf/lib/python3.9/site-packages/distributed/utils.py", line 803, in wrapper
    return await func(*args, **kwargs)
  File "/opt/conda/envs/gdf/lib/python3.9/site-packages/distributed/comm/ucx.py", line 372, in read
    raise CommClosedError(
distributed.comm.core.CommClosedError: Connection closed by writer.
Inner exception: UCXCanceled("<[Recv #003] ep: 0x7f2b2292c1c0, tag: 0x6d0168510480f58e, nbytes: 16, type: <class 'numpy.ndarray'>>: ")
2023-11-06 09:15:29,757 - distributed.worker - ERROR - Worker stream died during communication: ucx://127.0.0.1:38643
Traceback (most recent call last):
  File "/opt/conda/envs/gdf/lib/python3.9/site-packages/distributed/comm/ucx.py", line 354, in read
    await self.ep.recv(msg)
  File "/opt/conda/envs/gdf/lib/python3.9/site-packages/ucp/core.py", line 725, in recv
    ret = await comm.tag_recv(self._ep, buffer, nbytes, tag, name=log)
ucp._libs.exceptions.UCXCanceled: <[Recv #003] ep: 0x7f59ac441280, tag: 0x7936703de2af4fb5, nbytes: 16, type: <class 'numpy.ndarray'>>: 

During handling of the above exception, another exception occurred:

Traceback (most recent call last):
  File "/opt/conda/envs/gdf/lib/python3.9/site-packages/distributed/worker.py", line 2059, in gather_dep
    response = await get_data_from_worker(
  File "/opt/conda/envs/gdf/lib/python3.9/site-packages/distributed/worker.py", line 2852, in get_data_from_worker
    response = await send_recv(
  File "/opt/conda/envs/gdf/lib/python3.9/site-packages/distributed/core.py", line 1106, in send_recv
    response = await comm.read(deserializers=deserializers)
  File "/opt/conda/envs/gdf/lib/python3.9/site-packages/distributed/utils.py", line 803, in wrapper
    return await func(*args, **kwargs)
  File "/opt/conda/envs/gdf/lib/python3.9/site-packages/distributed/comm/ucx.py", line 372, in read
    raise CommClosedError(
distributed.comm.core.CommClosedError: Connection closed by writer.
Inner exception: UCXCanceled("<[Recv #003] ep: 0x7f59ac441280, tag: 0x7936703de2af4fb5, nbytes: 16, type: <class 'numpy.ndarray'>>: ")
2023-11-06 09:15:29,758 - distributed.worker - ERROR - failed during get data with ucx://127.0.0.1:46935 -> ucx://127.0.0.1:38643
Traceback (most recent call last):
  File "/opt/conda/envs/gdf/lib/python3.9/site-packages/distributed/comm/ucx.py", line 338, in write
    await self.ep.send(each_frame)
  File "/opt/conda/envs/gdf/lib/python3.9/site-packages/ucp/core.py", line 650, in send
    return await comm.tag_send(self._ep, buffer, nbytes, tag, name=log)
ucp._libs.exceptions.UCXError: <[Send #007] ep: 0x7fc4049e3280, tag: 0x6685803f09e1255c, nbytes: 50000000, type: <class 'cupy.ndarray'>>: Connection reset by remote peer

During handling of the above exception, another exception occurred:

Traceback (most recent call last):
  File "/opt/conda/envs/gdf/lib/python3.9/site-packages/distributed/worker.py", line 1782, in get_data
    compressed = await comm.write(msg, serializers=serializers)
  File "/opt/conda/envs/gdf/lib/python3.9/site-packages/distributed/utils.py", line 803, in wrapper
    return await func(*args, **kwargs)
  File "/opt/conda/envs/gdf/lib/python3.9/site-packages/distributed/comm/ucx.py", line 342, in write
    raise CommClosedError("While writing, the connection was closed")
distributed.comm.core.CommClosedError: While writing, the connection was closed
2023-11-06 09:15:29,758 - distributed.worker - ERROR - Worker stream died during communication: ucx://127.0.0.1:38643
Traceback (most recent call last):
  File "/opt/conda/envs/gdf/lib/python3.9/site-packages/distributed/comm/ucx.py", line 354, in read
    await self.ep.recv(msg)
  File "/opt/conda/envs/gdf/lib/python3.9/site-packages/ucp/core.py", line 725, in recv
    ret = await comm.tag_recv(self._ep, buffer, nbytes, tag, name=log)
ucp._libs.exceptions.UCXCanceled: <[Recv #003] ep: 0x7fd0b829e2c0, tag: 0x4cdffad41dff9883, nbytes: 16, type: <class 'numpy.ndarray'>>: 

During handling of the above exception, another exception occurred:

Traceback (most recent call last):
  File "/opt/conda/envs/gdf/lib/python3.9/site-packages/distributed/worker.py", line 2059, in gather_dep
    response = await get_data_from_worker(
  File "/opt/conda/envs/gdf/lib/python3.9/site-packages/distributed/worker.py", line 2852, in get_data_from_worker
    response = await send_recv(
  File "/opt/conda/envs/gdf/lib/python3.9/site-packages/distributed/core.py", line 1106, in send_recv
    response = await comm.read(deserializers=deserializers)
  File "/opt/conda/envs/gdf/lib/python3.9/site-packages/distributed/utils.py", line 803, in wrapper
    return await func(*args, **kwargs)
  File "/opt/conda/envs/gdf/lib/python3.9/site-packages/distributed/comm/ucx.py", line 372, in read
    raise CommClosedError(
distributed.comm.core.CommClosedError: Connection closed by writer.
Inner exception: UCXCanceled("<[Recv #003] ep: 0x7fd0b829e2c0, tag: 0x4cdffad41dff9883, nbytes: 16, type: <class 'numpy.ndarray'>>: ")
2023-11-06 09:15:29,759 - distributed.worker - ERROR - Worker stream died during communication: ucx://127.0.0.1:38643
Traceback (most recent call last):
  File "/opt/conda/envs/gdf/lib/python3.9/site-packages/distributed/comm/ucx.py", line 354, in read
    await self.ep.recv(msg)
  File "/opt/conda/envs/gdf/lib/python3.9/site-packages/ucp/core.py", line 725, in recv
    ret = await comm.tag_recv(self._ep, buffer, nbytes, tag, name=log)
ucp._libs.exceptions.UCXCanceled: <[Recv #003] ep: 0x7fc4049e3140, tag: 0xf3e0cd0c49a76843, nbytes: 16, type: <class 'numpy.ndarray'>>: 

During handling of the above exception, another exception occurred:

Traceback (most recent call last):
  File "/opt/conda/envs/gdf/lib/python3.9/site-packages/distributed/worker.py", line 2059, in gather_dep
    response = await get_data_from_worker(
  File "/opt/conda/envs/gdf/lib/python3.9/site-packages/distributed/worker.py", line 2852, in get_data_from_worker
    response = await send_recv(
  File "/opt/conda/envs/gdf/lib/python3.9/site-packages/distributed/core.py", line 1106, in send_recv
    response = await comm.read(deserializers=deserializers)
  File "/opt/conda/envs/gdf/lib/python3.9/site-packages/distributed/utils.py", line 803, in wrapper
    return await func(*args, **kwargs)
  File "/opt/conda/envs/gdf/lib/python3.9/site-packages/distributed/comm/ucx.py", line 372, in read
    raise CommClosedError(
distributed.comm.core.CommClosedError: Connection closed by writer.
Inner exception: UCXCanceled("<[Recv #003] ep: 0x7fc4049e3140, tag: 0xf3e0cd0c49a76843, nbytes: 16, type: <class 'numpy.ndarray'>>: ")
2023-11-06 09:15:29,765 - distributed.worker - ERROR - Worker stream died during communication: ucx://127.0.0.1:43879
Traceback (most recent call last):
  File "/opt/conda/envs/gdf/lib/python3.9/site-packages/distributed/comm/ucx.py", line 471, in connect
    ep = await ucp.create_endpoint(ip, port)
  File "/opt/conda/envs/gdf/lib/python3.9/site-packages/ucp/core.py", line 1004, in create_endpoint
    return await _get_ctx().create_endpoint(
  File "/opt/conda/envs/gdf/lib/python3.9/site-packages/ucp/core.py", line 316, in create_endpoint
    peer_info = await exchange_peer_info(
  File "/opt/conda/envs/gdf/lib/python3.9/site-packages/ucp/core.py", line 54, in exchange_peer_info
    await comm.stream_recv(endpoint, peer_info_arr, peer_info_arr.nbytes)
ucp._libs.exceptions.UCXNotConnected: <stream_recv>: 

During handling of the above exception, another exception occurred:

Traceback (most recent call last):
  File "/opt/conda/envs/gdf/lib/python3.9/site-packages/distributed/comm/core.py", line 342, in connect
    comm = await wait_for(
  File "/opt/conda/envs/gdf/lib/python3.9/site-packages/distributed/utils.py", line 1920, in wait_for
    return await asyncio.wait_for(fut, timeout)
  File "/opt/conda/envs/gdf/lib/python3.9/asyncio/tasks.py", line 479, in wait_for
    return fut.result()
  File "/opt/conda/envs/gdf/lib/python3.9/site-packages/distributed/comm/ucx.py", line 473, in connect
    raise CommClosedError("Connection closed before handshake completed")
distributed.comm.core.CommClosedError: Connection closed before handshake completed

During handling of the above exception, another exception occurred:

Traceback (most recent call last):
  File "/opt/conda/envs/gdf/lib/python3.9/site-packages/distributed/core.py", line 1516, in _connect
    comm = await connect(
  File "/opt/conda/envs/gdf/lib/python3.9/site-packages/distributed/comm/core.py", line 366, in connect
    await asyncio.sleep(backoff)
  File "/opt/conda/envs/gdf/lib/python3.9/asyncio/tasks.py", line 652, in sleep
    return await future
asyncio.exceptions.CancelledError

During handling of the above exception, another exception occurred:

Traceback (most recent call last):
  File "/opt/conda/envs/gdf/lib/python3.9/site-packages/distributed/core.py", line 1626, in connect
    return connect_attempt.result()
asyncio.exceptions.CancelledError

During handling of the above exception, another exception occurred:

Traceback (most recent call last):
  File "/opt/conda/envs/gdf/lib/python3.9/site-packages/distributed/worker.py", line 2059, in gather_dep
    response = await get_data_from_worker(
  File "/opt/conda/envs/gdf/lib/python3.9/site-packages/distributed/worker.py", line 2849, in get_data_from_worker
    comm = await rpc.connect(worker)
  File "/opt/conda/envs/gdf/lib/python3.9/site-packages/distributed/core.py", line 1628, in connect
    raise CommClosedError(reason)
distributed.comm.core.CommClosedError: Address removed.
2023-11-06 09:15:29,766 - distributed.worker - ERROR - Worker stream died during communication: ucx://127.0.0.1:43879
Traceback (most recent call last):
  File "/opt/conda/envs/gdf/lib/python3.9/site-packages/distributed/comm/ucx.py", line 471, in connect
    ep = await ucp.create_endpoint(ip, port)
  File "/opt/conda/envs/gdf/lib/python3.9/site-packages/ucp/core.py", line 1004, in create_endpoint
    return await _get_ctx().create_endpoint(
  File "/opt/conda/envs/gdf/lib/python3.9/site-packages/ucp/core.py", line 316, in create_endpoint
    peer_info = await exchange_peer_info(
  File "/opt/conda/envs/gdf/lib/python3.9/site-packages/ucp/core.py", line 54, in exchange_peer_info
    await comm.stream_recv(endpoint, peer_info_arr, peer_info_arr.nbytes)
ucp._libs.exceptions.UCXError: <stream_recv>: Connection reset by remote peer

During handling of the above exception, another exception occurred:

Traceback (most recent call last):
  File "/opt/conda/envs/gdf/lib/python3.9/site-packages/distributed/comm/core.py", line 342, in connect
    comm = await wait_for(
  File "/opt/conda/envs/gdf/lib/python3.9/site-packages/distributed/utils.py", line 1920, in wait_for
    return await asyncio.wait_for(fut, timeout)
  File "/opt/conda/envs/gdf/lib/python3.9/asyncio/tasks.py", line 479, in wait_for
    return fut.result()
  File "/opt/conda/envs/gdf/lib/python3.9/site-packages/distributed/comm/ucx.py", line 473, in connect
    raise CommClosedError("Connection closed before handshake completed")
distributed.comm.core.CommClosedError: Connection closed before handshake completed

During handling of the above exception, another exception occurred:

Traceback (most recent call last):
  File "/opt/conda/envs/gdf/lib/python3.9/site-packages/distributed/core.py", line 1516, in _connect
    comm = await connect(
  File "/opt/conda/envs/gdf/lib/python3.9/site-packages/distributed/comm/core.py", line 366, in connect
    await asyncio.sleep(backoff)
  File "/opt/conda/envs/gdf/lib/python3.9/asyncio/tasks.py", line 652, in sleep
    return await future
asyncio.exceptions.CancelledError

During handling of the above exception, another exception occurred:

Traceback (most recent call last):
  File "/opt/conda/envs/gdf/lib/python3.9/site-packages/distributed/core.py", line 1626, in connect
    return connect_attempt.result()
asyncio.exceptions.CancelledError

During handling of the above exception, another exception occurred:

Traceback (most recent call last):
  File "/opt/conda/envs/gdf/lib/python3.9/site-packages/distributed/worker.py", line 2059, in gather_dep
    response = await get_data_from_worker(
  File "/opt/conda/envs/gdf/lib/python3.9/site-packages/distributed/worker.py", line 2849, in get_data_from_worker
    comm = await rpc.connect(worker)
  File "/opt/conda/envs/gdf/lib/python3.9/site-packages/distributed/core.py", line 1628, in connect
    raise CommClosedError(reason)
distributed.comm.core.CommClosedError: Address removed.
2023-11-06 09:15:34,351 - distributed.nanny - WARNING - Restarting worker
2023-11-06 09:15:34,736 - distributed.nanny - WARNING - Restarting worker
2023-11-06 09:15:34,738 - distributed.nanny - WARNING - Restarting worker
2023-11-06 09:15:34,757 - distributed.nanny - WARNING - Restarting worker
2023-11-06 09:15:58,653 - distributed.worker - ERROR - Worker stream died during communication: ucx://127.0.0.1:43879
Traceback (most recent call last):
  File "/opt/conda/envs/gdf/lib/python3.9/site-packages/distributed/comm/ucx.py", line 471, in connect
    ep = await ucp.create_endpoint(ip, port)
  File "/opt/conda/envs/gdf/lib/python3.9/site-packages/ucp/core.py", line 1004, in create_endpoint
    return await _get_ctx().create_endpoint(
  File "/opt/conda/envs/gdf/lib/python3.9/site-packages/ucp/core.py", line 316, in create_endpoint
    peer_info = await exchange_peer_info(
  File "/opt/conda/envs/gdf/lib/python3.9/site-packages/ucp/core.py", line 54, in exchange_peer_info
    await comm.stream_recv(endpoint, peer_info_arr, peer_info_arr.nbytes)
asyncio.exceptions.CancelledError

During handling of the above exception, another exception occurred:

Traceback (most recent call last):
  File "/opt/conda/envs/gdf/lib/python3.9/asyncio/tasks.py", line 490, in wait_for
    return fut.result()
asyncio.exceptions.CancelledError

The above exception was the direct cause of the following exception:

Traceback (most recent call last):
  File "/opt/conda/envs/gdf/lib/python3.9/site-packages/distributed/comm/core.py", line 342, in connect
    comm = await wait_for(
  File "/opt/conda/envs/gdf/lib/python3.9/site-packages/distributed/utils.py", line 1920, in wait_for
    return await asyncio.wait_for(fut, timeout)
  File "/opt/conda/envs/gdf/lib/python3.9/asyncio/tasks.py", line 492, in wait_for
    raise exceptions.TimeoutError() from exc
asyncio.exceptions.TimeoutError

The above exception was the direct cause of the following exception:

Traceback (most recent call last):
  File "/opt/conda/envs/gdf/lib/python3.9/site-packages/distributed/worker.py", line 2059, in gather_dep
    response = await get_data_from_worker(
  File "/opt/conda/envs/gdf/lib/python3.9/site-packages/distributed/worker.py", line 2849, in get_data_from_worker
    comm = await rpc.connect(worker)
  File "/opt/conda/envs/gdf/lib/python3.9/site-packages/distributed/core.py", line 1626, in connect
    return connect_attempt.result()
  File "/opt/conda/envs/gdf/lib/python3.9/site-packages/distributed/core.py", line 1516, in _connect
    comm = await connect(
  File "/opt/conda/envs/gdf/lib/python3.9/site-packages/distributed/comm/core.py", line 368, in connect
    raise OSError(
OSError: Timed out trying to connect to ucx://127.0.0.1:43879 after 30 s
/opt/conda/envs/gdf/lib/python3.9/multiprocessing/resource_tracker.py:216: UserWarning: resource_tracker: There appear to be 48 leaked semaphore objects to clean up at shutdown
  warnings.warn('resource_tracker: There appear to be %d '
