[dgx13:85423:0:85423] Caught signal 11 (Segmentation fault: address not mapped to object at address 0x450)
==== backtrace (tid:  85423) ====
 0  /opt/conda/envs/gdf/lib/libucs.so.0(ucs_handle_error+0x2fd) [0x7f93d012dc0d]
 1  /opt/conda/envs/gdf/lib/libucs.so.0(+0x2de04) [0x7f93d012de04]
 2  /opt/conda/envs/gdf/lib/libucs.so.0(+0x2dfca) [0x7f93d012dfca]
 3  /usr/lib/x86_64-linux-gnu/libpthread.so.0(+0x14420) [0x7f9408e57420]
 4  /opt/conda/envs/gdf/lib/libucp.so.0(ucp_mem_type_unpack+0x17) [0x7f93d01b0997]
 5  /opt/conda/envs/gdf/lib/libucp.so.0(ucp_rndv_data_handler+0x65d) [0x7f93d01da88d]
 6  /opt/conda/envs/gdf/lib/libuct.so.0(+0x2193f) [0x7f93d00e493f]
 7  /opt/conda/envs/gdf/lib/libuct.so.0(+0x24b18) [0x7f93d00e7b18]
 8  /opt/conda/envs/gdf/lib/libucs.so.0(ucs_event_set_wait+0xb9) [0x7f93d0137509]
 9  /opt/conda/envs/gdf/lib/libuct.so.0(uct_tcp_iface_progress+0x7d) [0x7f93d00e6c2d]
10  /opt/conda/envs/gdf/lib/libucp.so.0(ucp_worker_progress+0x5a) [0x7f93d01ad86a]
11  /opt/conda/envs/gdf/lib/python3.9/site-packages/ucp/_libs/ucx_api.cpython-39-x86_64-linux-gnu.so(+0x3206a) [0x7f93d026d06a]
12  /opt/conda/envs/gdf/bin/python(_PyEval_EvalFrameDefault+0x45a6) [0x55cd4c5873f6]
13  /opt/conda/envs/gdf/bin/python(+0x12dfb4) [0x55cd4c581fb4]
14  /opt/conda/envs/gdf/bin/python(_PyFunction_Vectorcall+0xd9) [0x55cd4c593469]
15  /opt/conda/envs/gdf/bin/python(_PyEval_EvalFrameDefault+0x696) [0x55cd4c5834e6]
16  /opt/conda/envs/gdf/bin/python(+0x13f712) [0x55cd4c593712]
17  /opt/conda/envs/gdf/bin/python(+0x14ca83) [0x55cd4c5a0a83]
18  /opt/conda/envs/gdf/bin/python(+0x25819c) [0x55cd4c6ac19c]
19  /opt/conda/envs/gdf/bin/python(+0xf23ff) [0x55cd4c5463ff]
20  /opt/conda/envs/gdf/bin/python(+0x136723) [0x55cd4c58a723]
21  /opt/conda/envs/gdf/bin/python(_PyEval_EvalFrameDefault+0x5ad9) [0x55cd4c588929]
22  /opt/conda/envs/gdf/bin/python(+0x13f712) [0x55cd4c593712]
23  /opt/conda/envs/gdf/bin/python(_PyEval_EvalFrameDefault+0x696) [0x55cd4c5834e6]
24  /opt/conda/envs/gdf/bin/python(+0x13f712) [0x55cd4c593712]
25  /opt/conda/envs/gdf/bin/python(_PyEval_EvalFrameDefault+0x696) [0x55cd4c5834e6]
26  /opt/conda/envs/gdf/bin/python(+0x13f712) [0x55cd4c593712]
27  /opt/conda/envs/gdf/bin/python(_PyEval_EvalFrameDefault+0x696) [0x55cd4c5834e6]
28  /opt/conda/envs/gdf/bin/python(+0x13f712) [0x55cd4c593712]
29  /opt/conda/envs/gdf/bin/python(_PyEval_EvalFrameDefault+0x696) [0x55cd4c5834e6]
30  /opt/conda/envs/gdf/bin/python(+0x12dfb4) [0x55cd4c581fb4]
31  /opt/conda/envs/gdf/bin/python(_PyFunction_Vectorcall+0xd9) [0x55cd4c593469]
32  /opt/conda/envs/gdf/bin/python(_PyEval_EvalFrameDefault+0x11f2) [0x55cd4c584042]
33  /opt/conda/envs/gdf/bin/python(+0x12dfb4) [0x55cd4c581fb4]
34  /opt/conda/envs/gdf/bin/python(+0x14c8cb) [0x55cd4c5a08cb]
35  /opt/conda/envs/gdf/bin/python(PyObject_Call+0xbc) [0x55cd4c5a104c]
36  /opt/conda/envs/gdf/bin/python(+0x21080e) [0x55cd4c66480e]
37  /opt/conda/envs/gdf/bin/python(_PyObject_MakeTpCall+0x2ec) [0x55cd4c58b6ac]
38  /opt/conda/envs/gdf/bin/python(_PyEval_EvalFrameDefault+0x45a6) [0x55cd4c5873f6]
39  /opt/conda/envs/gdf/bin/python(+0x13f712) [0x55cd4c593712]
40  /opt/conda/envs/gdf/bin/python(+0x14c9ac) [0x55cd4c5a09ac]
41  /opt/conda/envs/gdf/bin/python(_PyEval_EvalFrameDefault+0x45a6) [0x55cd4c5873f6]
42  /opt/conda/envs/gdf/bin/python(+0x13f712) [0x55cd4c593712]
43  /opt/conda/envs/gdf/bin/python(_PyEval_EvalFrameDefault+0x696) [0x55cd4c5834e6]
44  /opt/conda/envs/gdf/bin/python(+0x12dfb4) [0x55cd4c581fb4]
45  /opt/conda/envs/gdf/bin/python(_PyFunction_Vectorcall+0xd9) [0x55cd4c593469]
46  /opt/conda/envs/gdf/bin/python(_PyEval_EvalFrameDefault+0x696) [0x55cd4c5834e6]
47  /opt/conda/envs/gdf/bin/python(+0x13f712) [0x55cd4c593712]
48  /opt/conda/envs/gdf/bin/python(_PyEval_EvalFrameDefault+0x3e2) [0x55cd4c583232]
49  /opt/conda/envs/gdf/bin/python(+0x12dfb4) [0x55cd4c581fb4]
50  /opt/conda/envs/gdf/bin/python(_PyFunction_Vectorcall+0xd9) [0x55cd4c593469]
51  /opt/conda/envs/gdf/bin/python(_PyEval_EvalFrameDefault+0x11f2) [0x55cd4c584042]
52  /opt/conda/envs/gdf/bin/python(+0x12dfb4) [0x55cd4c581fb4]
53  /opt/conda/envs/gdf/bin/python(_PyEval_EvalCodeWithName+0x48) [0x55cd4c581c88]
54  /opt/conda/envs/gdf/bin/python(PyEval_EvalCodeEx+0x39) [0x55cd4c581c39]
55  /opt/conda/envs/gdf/bin/python(PyEval_EvalCode+0x1b) [0x55cd4c62f2cb]
56  /opt/conda/envs/gdf/bin/python(+0x2086ca) [0x55cd4c65c6ca]
57  /opt/conda/envs/gdf/bin/python(+0x204a63) [0x55cd4c658a63]
58  /opt/conda/envs/gdf/bin/python(PyRun_StringFlags+0x9a) [0x55cd4c65087a]
59  /opt/conda/envs/gdf/bin/python(PyRun_SimpleStringFlags+0x3c) [0x55cd4c65076c]
60  /opt/conda/envs/gdf/bin/python(Py_RunMain+0x267) [0x55cd4c64f9a7]
61  /opt/conda/envs/gdf/bin/python(Py_BytesMain+0x37) [0x55cd4c623107]
=================================
[dgx13:85434:0:85434] Caught signal 11 (Segmentation fault: address not mapped to object at address 0x450)
==== backtrace (tid:  85434) ====
 0  /opt/conda/envs/gdf/lib/libucs.so.0(ucs_handle_error+0x2fd) [0x7fb3b5a99c0d]
 1  /opt/conda/envs/gdf/lib/libucs.so.0(+0x2de04) [0x7fb3b5a99e04]
 2  /opt/conda/envs/gdf/lib/libucs.so.0(+0x2dfca) [0x7fb3b5a99fca]
 3  /usr/lib/x86_64-linux-gnu/libpthread.so.0(+0x14420) [0x7fb3f47dd420]
 4  /opt/conda/envs/gdf/lib/libucp.so.0(ucp_mem_type_unpack+0x17) [0x7fb3b5b1c997]
 5  /opt/conda/envs/gdf/lib/libucp.so.0(ucp_rndv_data_handler+0x65d) [0x7fb3b5b4688d]
 6  /opt/conda/envs/gdf/lib/libuct.so.0(+0x2193f) [0x7fb3b5a5093f]
 7  /opt/conda/envs/gdf/lib/libuct.so.0(+0x24b18) [0x7fb3b5a53b18]
 8  /opt/conda/envs/gdf/lib/libucs.so.0(ucs_event_set_wait+0xb9) [0x7fb3b5aa3509]
 9  /opt/conda/envs/gdf/lib/libuct.so.0(uct_tcp_iface_progress+0x7d) [0x7fb3b5a52c2d]
10  /opt/conda/envs/gdf/lib/libucp.so.0(ucp_worker_progress+0x5a) [0x7fb3b5b1986a]
11  /opt/conda/envs/gdf/lib/python3.9/site-packages/ucp/_libs/ucx_api.cpython-39-x86_64-linux-gnu.so(+0x3206a) [0x7fb3b5bd906a]
12  /opt/conda/envs/gdf/bin/python(_PyEval_EvalFrameDefault+0x45a6) [0x555d1649f3f6]
13  /opt/conda/envs/gdf/bin/python(+0x12dfb4) [0x555d16499fb4]
14  /opt/conda/envs/gdf/bin/python(_PyFunction_Vectorcall+0xd9) [0x555d164ab469]
15  /opt/conda/envs/gdf/bin/python(_PyEval_EvalFrameDefault+0x696) [0x555d1649b4e6]
16  /opt/conda/envs/gdf/bin/python(+0x13f712) [0x555d164ab712]
17  /opt/conda/envs/gdf/bin/python(+0x14ca83) [0x555d164b8a83]
18  /opt/conda/envs/gdf/bin/python(+0x25819c) [0x555d165c419c]
19  /opt/conda/envs/gdf/bin/python(+0xf23ff) [0x555d1645e3ff]
20  /opt/conda/envs/gdf/bin/python(+0x136723) [0x555d164a2723]
21  /opt/conda/envs/gdf/bin/python(_PyEval_EvalFrameDefault+0x5ad9) [0x555d164a0929]
22  /opt/conda/envs/gdf/bin/python(+0x13f712) [0x555d164ab712]
23  /opt/conda/envs/gdf/bin/python(_PyEval_EvalFrameDefault+0x696) [0x555d1649b4e6]
24  /opt/conda/envs/gdf/bin/python(+0x13f712) [0x555d164ab712]
25  /opt/conda/envs/gdf/bin/python(_PyEval_EvalFrameDefault+0x696) [0x555d1649b4e6]
26  /opt/conda/envs/gdf/bin/python(+0x13f712) [0x555d164ab712]
27  /opt/conda/envs/gdf/bin/python(_PyEval_EvalFrameDefault+0x696) [0x555d1649b4e6]
28  /opt/conda/envs/gdf/bin/python(+0x13f712) [0x555d164ab712]
29  /opt/conda/envs/gdf/bin/python(_PyEval_EvalFrameDefault+0x696) [0x555d1649b4e6]
30  /opt/conda/envs/gdf/bin/python(+0x12dfb4) [0x555d16499fb4]
31  /opt/conda/envs/gdf/bin/python(_PyFunction_Vectorcall+0xd9) [0x555d164ab469]
32  /opt/conda/envs/gdf/bin/python(_PyEval_EvalFrameDefault+0x11f2) [0x555d1649c042]
33  /opt/conda/envs/gdf/bin/python(+0x12dfb4) [0x555d16499fb4]
34  /opt/conda/envs/gdf/bin/python(+0x14c8cb) [0x555d164b88cb]
35  /opt/conda/envs/gdf/bin/python(PyObject_Call+0xbc) [0x555d164b904c]
36  /opt/conda/envs/gdf/bin/python(+0x21080e) [0x555d1657c80e]
37  /opt/conda/envs/gdf/bin/python(_PyObject_MakeTpCall+0x2ec) [0x555d164a36ac]
38  /opt/conda/envs/gdf/bin/python(_PyEval_EvalFrameDefault+0x45a6) [0x555d1649f3f6]
39  /opt/conda/envs/gdf/bin/python(+0x13f712) [0x555d164ab712]
40  /opt/conda/envs/gdf/bin/python(+0x14c9ac) [0x555d164b89ac]
41  /opt/conda/envs/gdf/bin/python(_PyEval_EvalFrameDefault+0x45a6) [0x555d1649f3f6]
42  /opt/conda/envs/gdf/bin/python(+0x13f712) [0x555d164ab712]
43  /opt/conda/envs/gdf/bin/python(_PyEval_EvalFrameDefault+0x696) [0x555d1649b4e6]
44  /opt/conda/envs/gdf/bin/python(+0x12dfb4) [0x555d16499fb4]
45  /opt/conda/envs/gdf/bin/python(_PyFunction_Vectorcall+0xd9) [0x555d164ab469]
46  /opt/conda/envs/gdf/bin/python(_PyEval_EvalFrameDefault+0x696) [0x555d1649b4e6]
47  /opt/conda/envs/gdf/bin/python(+0x13f712) [0x555d164ab712]
48  /opt/conda/envs/gdf/bin/python(_PyEval_EvalFrameDefault+0x3e2) [0x555d1649b232]
49  /opt/conda/envs/gdf/bin/python(+0x12dfb4) [0x555d16499fb4]
50  /opt/conda/envs/gdf/bin/python(_PyFunction_Vectorcall+0xd9) [0x555d164ab469]
51  /opt/conda/envs/gdf/bin/python(_PyEval_EvalFrameDefault+0x11f2) [0x555d1649c042]
52  /opt/conda/envs/gdf/bin/python(+0x12dfb4) [0x555d16499fb4]
53  /opt/conda/envs/gdf/bin/python(_PyEval_EvalCodeWithName+0x48) [0x555d16499c88]
54  /opt/conda/envs/gdf/bin/python(PyEval_EvalCodeEx+0x39) [0x555d16499c39]
55  /opt/conda/envs/gdf/bin/python(PyEval_EvalCode+0x1b) [0x555d165472cb]
56  /opt/conda/envs/gdf/bin/python(+0x2086ca) [0x555d165746ca]
57  /opt/conda/envs/gdf/bin/python(+0x204a63) [0x555d16570a63]
58  /opt/conda/envs/gdf/bin/python(PyRun_StringFlags+0x9a) [0x555d1656887a]
59  /opt/conda/envs/gdf/bin/python(PyRun_SimpleStringFlags+0x3c) [0x555d1656876c]
60  /opt/conda/envs/gdf/bin/python(Py_RunMain+0x267) [0x555d165679a7]
61  /opt/conda/envs/gdf/bin/python(Py_BytesMain+0x37) [0x555d1653b107]
=================================
[dgx13:85454:0:85454] Caught signal 11 (Segmentation fault: address not mapped to object at address 0x450)
==== backtrace (tid:  85454) ====
 0  /opt/conda/envs/gdf/lib/libucs.so.0(ucs_handle_error+0x2fd) [0x7f485c9f9c0d]
 1  /opt/conda/envs/gdf/lib/libucs.so.0(+0x2de04) [0x7f485c9f9e04]
 2  /opt/conda/envs/gdf/lib/libucs.so.0(+0x2dfca) [0x7f485c9f9fca]
 3  /usr/lib/x86_64-linux-gnu/libpthread.so.0(+0x14420) [0x7f488773b420]
 4  /opt/conda/envs/gdf/lib/libucp.so.0(ucp_mem_type_unpack+0x17) [0x7f485ca7c997]
 5  /opt/conda/envs/gdf/lib/libucp.so.0(ucp_rndv_data_handler+0x65d) [0x7f485caa688d]
 6  /opt/conda/envs/gdf/lib/libuct.so.0(+0x2193f) [0x7f485c9b093f]
 7  /opt/conda/envs/gdf/lib/libuct.so.0(+0x24b18) [0x7f485c9b3b18]
 8  /opt/conda/envs/gdf/lib/libucs.so.0(ucs_event_set_wait+0xb9) [0x7f485ca03509]
 9  /opt/conda/envs/gdf/lib/libuct.so.0(uct_tcp_iface_progress+0x7d) [0x7f485c9b2c2d]
10  /opt/conda/envs/gdf/lib/libucp.so.0(ucp_worker_progress+0x5a) [0x7f485ca7986a]
11  /opt/conda/envs/gdf/lib/python3.9/site-packages/ucp/_libs/ucx_api.cpython-39-x86_64-linux-gnu.so(+0x3206a) [0x7f485cb3906a]
12  /opt/conda/envs/gdf/bin/python(_PyEval_EvalFrameDefault+0x45a6) [0x5640a9a4a3f6]
13  /opt/conda/envs/gdf/bin/python(+0x12dfb4) [0x5640a9a44fb4]
14  /opt/conda/envs/gdf/bin/python(_PyFunction_Vectorcall+0xd9) [0x5640a9a56469]
15  /opt/conda/envs/gdf/bin/python(_PyEval_EvalFrameDefault+0x696) [0x5640a9a464e6]
16  /opt/conda/envs/gdf/bin/python(+0x1e26d2) [0x5640a9af96d2]
17  /opt/conda/envs/gdf/lib/python3.9/lib-dynload/_asyncio.cpython-39-x86_64-linux-gnu.so(+0x81e9) [0x7f4871cd11e9]
18  /opt/conda/envs/gdf/bin/python(_PyObject_MakeTpCall+0x2ec) [0x5640a9a4e6ac]
19  /opt/conda/envs/gdf/bin/python(+0xf23ff) [0x5640a9a093ff]
20  /opt/conda/envs/gdf/bin/python(+0x136723) [0x5640a9a4d723]
21  /opt/conda/envs/gdf/bin/python(_PyEval_EvalFrameDefault+0x5ad9) [0x5640a9a4b929]
22  /opt/conda/envs/gdf/bin/python(+0x13f712) [0x5640a9a56712]
23  /opt/conda/envs/gdf/bin/python(_PyEval_EvalFrameDefault+0x696) [0x5640a9a464e6]
24  /opt/conda/envs/gdf/bin/python(+0x13f712) [0x5640a9a56712]
25  /opt/conda/envs/gdf/bin/python(_PyEval_EvalFrameDefault+0x696) [0x5640a9a464e6]
26  /opt/conda/envs/gdf/bin/python(+0x13f712) [0x5640a9a56712]
27  /opt/conda/envs/gdf/bin/python(_PyEval_EvalFrameDefault+0x696) [0x5640a9a464e6]
28  /opt/conda/envs/gdf/bin/python(+0x13f712) [0x5640a9a56712]
29  /opt/conda/envs/gdf/bin/python(_PyEval_EvalFrameDefault+0x696) [0x5640a9a464e6]
30  /opt/conda/envs/gdf/bin/python(+0x12dfb4) [0x5640a9a44fb4]
31  /opt/conda/envs/gdf/bin/python(_PyFunction_Vectorcall+0xd9) [0x5640a9a56469]
32  /opt/conda/envs/gdf/bin/python(_PyEval_EvalFrameDefault+0x11f2) [0x5640a9a47042]
33  /opt/conda/envs/gdf/bin/python(+0x12dfb4) [0x5640a9a44fb4]
34  /opt/conda/envs/gdf/bin/python(+0x14c8cb) [0x5640a9a638cb]
35  /opt/conda/envs/gdf/bin/python(PyObject_Call+0xbc) [0x5640a9a6404c]
36  /opt/conda/envs/gdf/bin/python(+0x21080e) [0x5640a9b2780e]
37  /opt/conda/envs/gdf/bin/python(_PyObject_MakeTpCall+0x2ec) [0x5640a9a4e6ac]
38  /opt/conda/envs/gdf/bin/python(_PyEval_EvalFrameDefault+0x45a6) [0x5640a9a4a3f6]
39  /opt/conda/envs/gdf/bin/python(+0x13f712) [0x5640a9a56712]
40  /opt/conda/envs/gdf/bin/python(+0x14c9ac) [0x5640a9a639ac]
41  /opt/conda/envs/gdf/bin/python(_PyEval_EvalFrameDefault+0x45a6) [0x5640a9a4a3f6]
42  /opt/conda/envs/gdf/bin/python(+0x13f712) [0x5640a9a56712]
43  /opt/conda/envs/gdf/bin/python(_PyEval_EvalFrameDefault+0x696) [0x5640a9a464e6]
44  /opt/conda/envs/gdf/bin/python(+0x12dfb4) [0x5640a9a44fb4]
45  /opt/conda/envs/gdf/bin/python(_PyFunction_Vectorcall+0xd9) [0x5640a9a56469]
46  /opt/conda/envs/gdf/bin/python(_PyEval_EvalFrameDefault+0x696) [0x5640a9a464e6]
47  /opt/conda/envs/gdf/bin/python(+0x13f712) [0x5640a9a56712]
48  /opt/conda/envs/gdf/bin/python(_PyEval_EvalFrameDefault+0x3e2) [0x5640a9a46232]
49  /opt/conda/envs/gdf/bin/python(+0x12dfb4) [0x5640a9a44fb4]
50  /opt/conda/envs/gdf/bin/python(_PyFunction_Vectorcall+0xd9) [0x5640a9a56469]
51  /opt/conda/envs/gdf/bin/python(_PyEval_EvalFrameDefault+0x11f2) [0x5640a9a47042]
52  /opt/conda/envs/gdf/bin/python(+0x12dfb4) [0x5640a9a44fb4]
53  /opt/conda/envs/gdf/bin/python(_PyEval_EvalCodeWithName+0x48) [0x5640a9a44c88]
54  /opt/conda/envs/gdf/bin/python(PyEval_EvalCodeEx+0x39) [0x5640a9a44c39]
55  /opt/conda/envs/gdf/bin/python(PyEval_EvalCode+0x1b) [0x5640a9af22cb]
56  /opt/conda/envs/gdf/bin/python(+0x2086ca) [0x5640a9b1f6ca]
57  /opt/conda/envs/gdf/bin/python(+0x204a63) [0x5640a9b1ba63]
58  /opt/conda/envs/gdf/bin/python(PyRun_StringFlags+0x9a) [0x5640a9b1387a]
59  /opt/conda/envs/gdf/bin/python(PyRun_SimpleStringFlags+0x3c) [0x5640a9b1376c]
60  /opt/conda/envs/gdf/bin/python(Py_RunMain+0x267) [0x5640a9b129a7]
61  /opt/conda/envs/gdf/bin/python(Py_BytesMain+0x37) [0x5640a9ae6107]
=================================
[dgx13:85450:0:85450] Caught signal 11 (Segmentation fault: address not mapped to object at address 0x450)
==== backtrace (tid:  85450) ====
 0  /opt/conda/envs/gdf/lib/libucs.so.0(ucs_handle_error+0x2fd) [0x7fb251764c0d]
 1  /opt/conda/envs/gdf/lib/libucs.so.0(+0x2de04) [0x7fb251764e04]
 2  /opt/conda/envs/gdf/lib/libucs.so.0(+0x2dfca) [0x7fb251764fca]
 3  /usr/lib/x86_64-linux-gnu/libpthread.so.0(+0x14420) [0x7fb28e490420]
 4  /opt/conda/envs/gdf/lib/libucp.so.0(ucp_mem_type_unpack+0x17) [0x7fb2517e7997]
 5  /opt/conda/envs/gdf/lib/libucp.so.0(ucp_rndv_data_handler+0x65d) [0x7fb25181188d]
 6  /opt/conda/envs/gdf/lib/libuct.so.0(+0x2193f) [0x7fb25171b93f]
 7  /opt/conda/envs/gdf/lib/libuct.so.0(+0x24b18) [0x7fb25171eb18]
 8  /opt/conda/envs/gdf/lib/libucs.so.0(ucs_event_set_wait+0xb9) [0x7fb25176e509]
 9  /opt/conda/envs/gdf/lib/libuct.so.0(uct_tcp_iface_progress+0x7d) [0x7fb25171dc2d]
10  /opt/conda/envs/gdf/lib/libucp.so.0(ucp_worker_progress+0x5a) [0x7fb2517e486a]
11  /opt/conda/envs/gdf/lib/python3.9/site-packages/ucp/_libs/ucx_api.cpython-39-x86_64-linux-gnu.so(+0x3206a) [0x7fb2518a406a]
12  /opt/conda/envs/gdf/bin/python(_PyEval_EvalFrameDefault+0x45a6) [0x55a7e59853f6]
13  /opt/conda/envs/gdf/bin/python(+0x12dfb4) [0x55a7e597ffb4]
14  /opt/conda/envs/gdf/bin/python(_PyFunction_Vectorcall+0xd9) [0x55a7e5991469]
15  /opt/conda/envs/gdf/bin/python(_PyEval_EvalFrameDefault+0x696) [0x55a7e59814e6]
16  /opt/conda/envs/gdf/bin/python(+0x13f712) [0x55a7e5991712]
17  /opt/conda/envs/gdf/bin/python(+0x14ca83) [0x55a7e599ea83]
18  /opt/conda/envs/gdf/bin/python(+0x25819c) [0x55a7e5aaa19c]
19  /opt/conda/envs/gdf/bin/python(+0xf23ff) [0x55a7e59443ff]
20  /opt/conda/envs/gdf/bin/python(+0x136723) [0x55a7e5988723]
21  /opt/conda/envs/gdf/bin/python(_PyEval_EvalFrameDefault+0x5ad9) [0x55a7e5986929]
22  /opt/conda/envs/gdf/bin/python(+0x13f712) [0x55a7e5991712]
23  /opt/conda/envs/gdf/bin/python(_PyEval_EvalFrameDefault+0x696) [0x55a7e59814e6]
24  /opt/conda/envs/gdf/bin/python(+0x13f712) [0x55a7e5991712]
25  /opt/conda/envs/gdf/bin/python(_PyEval_EvalFrameDefault+0x696) [0x55a7e59814e6]
26  /opt/conda/envs/gdf/bin/python(+0x13f712) [0x55a7e5991712]
27  /opt/conda/envs/gdf/bin/python(_PyEval_EvalFrameDefault+0x696) [0x55a7e59814e6]
28  /opt/conda/envs/gdf/bin/python(+0x13f712) [0x55a7e5991712]
29  /opt/conda/envs/gdf/bin/python(_PyEval_EvalFrameDefault+0x696) [0x55a7e59814e6]
30  /opt/conda/envs/gdf/bin/python(+0x12dfb4) [0x55a7e597ffb4]
31  /opt/conda/envs/gdf/bin/python(_PyFunction_Vectorcall+0xd9) [0x55a7e5991469]
32  /opt/conda/envs/gdf/bin/python(_PyEval_EvalFrameDefault+0x11f2) [0x55a7e5982042]
33  /opt/conda/envs/gdf/bin/python(+0x12dfb4) [0x55a7e597ffb4]
34  /opt/conda/envs/gdf/bin/python(+0x14c8cb) [0x55a7e599e8cb]
35  /opt/conda/envs/gdf/bin/python(PyObject_Call+0xbc) [0x55a7e599f04c]
36  /opt/conda/envs/gdf/bin/python(+0x21080e) [0x55a7e5a6280e]
37  /opt/conda/envs/gdf/bin/python(_PyObject_MakeTpCall+0x2ec) [0x55a7e59896ac]
38  /opt/conda/envs/gdf/bin/python(_PyEval_EvalFrameDefault+0x45a6) [0x55a7e59853f6]
39  /opt/conda/envs/gdf/bin/python(+0x13f712) [0x55a7e5991712]
40  /opt/conda/envs/gdf/bin/python(+0x14c9ac) [0x55a7e599e9ac]
41  /opt/conda/envs/gdf/bin/python(_PyEval_EvalFrameDefault+0x45a6) [0x55a7e59853f6]
42  /opt/conda/envs/gdf/bin/python(+0x13f712) [0x55a7e5991712]
43  /opt/conda/envs/gdf/bin/python(_PyEval_EvalFrameDefault+0x696) [0x55a7e59814e6]
44  /opt/conda/envs/gdf/bin/python(+0x12dfb4) [0x55a7e597ffb4]
45  /opt/conda/envs/gdf/bin/python(_PyFunction_Vectorcall+0xd9) [0x55a7e5991469]
46  /opt/conda/envs/gdf/bin/python(_PyEval_EvalFrameDefault+0x696) [0x55a7e59814e6]
47  /opt/conda/envs/gdf/bin/python(+0x13f712) [0x55a7e5991712]
48  /opt/conda/envs/gdf/bin/python(_PyEval_EvalFrameDefault+0x3e2) [0x55a7e5981232]
49  /opt/conda/envs/gdf/bin/python(+0x12dfb4) [0x55a7e597ffb4]
50  /opt/conda/envs/gdf/bin/python(_PyFunction_Vectorcall+0xd9) [0x55a7e5991469]
51  /opt/conda/envs/gdf/bin/python(_PyEval_EvalFrameDefault+0x11f2) [0x55a7e5982042]
52  /opt/conda/envs/gdf/bin/python(+0x12dfb4) [0x55a7e597ffb4]
53  /opt/conda/envs/gdf/bin/python(_PyEval_EvalCodeWithName+0x48) [0x55a7e597fc88]
54  /opt/conda/envs/gdf/bin/python(PyEval_EvalCodeEx+0x39) [0x55a7e597fc39]
55  /opt/conda/envs/gdf/bin/python(PyEval_EvalCode+0x1b) [0x55a7e5a2d2cb]
56  /opt/conda/envs/gdf/bin/python(+0x2086ca) [0x55a7e5a5a6ca]
57  /opt/conda/envs/gdf/bin/python(+0x204a63) [0x55a7e5a56a63]
58  /opt/conda/envs/gdf/bin/python(PyRun_StringFlags+0x9a) [0x55a7e5a4e87a]
59  /opt/conda/envs/gdf/bin/python(PyRun_SimpleStringFlags+0x3c) [0x55a7e5a4e76c]
60  /opt/conda/envs/gdf/bin/python(Py_RunMain+0x267) [0x55a7e5a4d9a7]
61  /opt/conda/envs/gdf/bin/python(Py_BytesMain+0x37) [0x55a7e5a21107]
=================================
2024-02-17 07:34:29,906 - distributed.worker - ERROR - failed during get data with ucx://127.0.0.1:52991 -> ucx://127.0.0.1:34667
Traceback (most recent call last):
  File "/opt/conda/envs/gdf/lib/python3.9/site-packages/distributed/comm/ucx.py", line 334, in write
    await self.ep.send(each_frame)
  File "/opt/conda/envs/gdf/lib/python3.9/site-packages/ucp/core.py", line 662, in send
    return await comm.tag_send(self._ep, buffer, nbytes, tag, name=log)
ucp._libs.exceptions.UCXError: <[Send #007] ep: 0x7efe45d59300, tag: 0xb5f3a0672842c9af, nbytes: 50000000, type: <class 'cupy.ndarray'>>: Connection reset by remote peer

During handling of the above exception, another exception occurred:

Traceback (most recent call last):
  File "/opt/conda/envs/gdf/lib/python3.9/site-packages/distributed/worker.py", line 1779, in get_data
    compressed = await comm.write(msg, serializers=serializers)
  File "/opt/conda/envs/gdf/lib/python3.9/site-packages/distributed/utils.py", line 832, in wrapper
    return await func(*args, **kwargs)
  File "/opt/conda/envs/gdf/lib/python3.9/site-packages/distributed/comm/ucx.py", line 338, in write
    raise CommClosedError("While writing, the connection was closed")
distributed.comm.core.CommClosedError: While writing, the connection was closed
2024-02-17 07:34:29,945 - distributed.worker - ERROR - Worker stream died during communication: ucx://127.0.0.1:40899
Traceback (most recent call last):
  File "/opt/conda/envs/gdf/lib/python3.9/site-packages/distributed/comm/ucx.py", line 350, in read
    await self.ep.recv(msg)
  File "/opt/conda/envs/gdf/lib/python3.9/site-packages/ucp/core.py", line 737, in recv
    ret = await comm.tag_recv(self._ep, buffer, nbytes, tag, name=log)
ucp._libs.exceptions.UCXCanceled: <[Recv #000] ep: 0x7efe45d59180, tag: 0x99bf4951aa9a3ade, nbytes: 16, type: <class 'numpy.ndarray'>>: 

During handling of the above exception, another exception occurred:

Traceback (most recent call last):
  File "/opt/conda/envs/gdf/lib/python3.9/site-packages/distributed/worker.py", line 2056, in gather_dep
    response = await get_data_from_worker(
  File "/opt/conda/envs/gdf/lib/python3.9/site-packages/distributed/worker.py", line 2857, in get_data_from_worker
    comm = await rpc.connect(worker)
  File "/opt/conda/envs/gdf/lib/python3.9/site-packages/distributed/core.py", line 1674, in connect
    return connect_attempt.result()
  File "/opt/conda/envs/gdf/lib/python3.9/site-packages/distributed/core.py", line 1564, in _connect
    comm = await connect(
  File "/opt/conda/envs/gdf/lib/python3.9/site-packages/distributed/comm/core.py", line 377, in connect
    handshake = await comm.read()
  File "/opt/conda/envs/gdf/lib/python3.9/site-packages/distributed/utils.py", line 832, in wrapper
    return await func(*args, **kwargs)
  File "/opt/conda/envs/gdf/lib/python3.9/site-packages/distributed/comm/ucx.py", line 368, in read
    raise CommClosedError(
distributed.comm.core.CommClosedError: Connection closed by writer.
Inner exception: UCXCanceled("<[Recv #000] ep: 0x7efe45d59180, tag: 0x99bf4951aa9a3ade, nbytes: 16, type: <class 'numpy.ndarray'>>: ")
2024-02-17 07:34:29,945 - distributed.worker - ERROR - failed during get data with ucx://127.0.0.1:45805 -> ucx://127.0.0.1:40899
Traceback (most recent call last):
  File "/opt/conda/envs/gdf/lib/python3.9/site-packages/distributed/comm/ucx.py", line 334, in write
    await self.ep.send(each_frame)
  File "/opt/conda/envs/gdf/lib/python3.9/site-packages/ucp/core.py", line 662, in send
    return await comm.tag_send(self._ep, buffer, nbytes, tag, name=log)
ucp._libs.exceptions.UCXError: <[Send #007] ep: 0x7fc4a6df92c0, tag: 0xae5f1d7e9362c242, nbytes: 50000000, type: <class 'cupy.ndarray'>>: Connection reset by remote peer

During handling of the above exception, another exception occurred:

Traceback (most recent call last):
  File "/opt/conda/envs/gdf/lib/python3.9/site-packages/distributed/worker.py", line 1779, in get_data
    compressed = await comm.write(msg, serializers=serializers)
  File "/opt/conda/envs/gdf/lib/python3.9/site-packages/distributed/utils.py", line 832, in wrapper
    return await func(*args, **kwargs)
  File "/opt/conda/envs/gdf/lib/python3.9/site-packages/distributed/comm/ucx.py", line 338, in write
    raise CommClosedError("While writing, the connection was closed")
distributed.comm.core.CommClosedError: While writing, the connection was closed
2024-02-17 07:34:29,989 - distributed.worker - ERROR - failed during get data with ucx://127.0.0.1:45805 -> ucx://127.0.0.1:58299
Traceback (most recent call last):
  File "/opt/conda/envs/gdf/lib/python3.9/site-packages/distributed/comm/ucx.py", line 334, in write
    await self.ep.send(each_frame)
  File "/opt/conda/envs/gdf/lib/python3.9/site-packages/ucp/core.py", line 662, in send
    return await comm.tag_send(self._ep, buffer, nbytes, tag, name=log)
ucp._libs.exceptions.UCXError: <[Send #007] ep: 0x7fc4a6df93c0, tag: 0xc9bd342b85d598b8, nbytes: 50000000, type: <class 'cupy.ndarray'>>: Connection reset by remote peer

During handling of the above exception, another exception occurred:

Traceback (most recent call last):
  File "/opt/conda/envs/gdf/lib/python3.9/site-packages/distributed/worker.py", line 1779, in get_data
    compressed = await comm.write(msg, serializers=serializers)
  File "/opt/conda/envs/gdf/lib/python3.9/site-packages/distributed/utils.py", line 832, in wrapper
    return await func(*args, **kwargs)
  File "/opt/conda/envs/gdf/lib/python3.9/site-packages/distributed/comm/ucx.py", line 338, in write
    raise CommClosedError("While writing, the connection was closed")
distributed.comm.core.CommClosedError: While writing, the connection was closed
2024-02-17 07:34:29,989 - distributed.worker - ERROR - Worker stream died during communication: ucx://127.0.0.1:58299
Traceback (most recent call last):
  File "/opt/conda/envs/gdf/lib/python3.9/site-packages/distributed/comm/ucx.py", line 392, in read
    await self.ep.recv(each_frame)
  File "/opt/conda/envs/gdf/lib/python3.9/site-packages/ucp/core.py", line 737, in recv
    ret = await comm.tag_recv(self._ep, buffer, nbytes, tag, name=log)
ucp._libs.exceptions.UCXError: <[Recv #007] ep: 0x7f64a8ca1180, tag: 0x6bacadc8ae805646, nbytes: 50000000, type: <class 'rmm._lib.device_buffer.DeviceBuffer'>>: Connection reset by remote peer

During handling of the above exception, another exception occurred:

Traceback (most recent call last):
  File "/opt/conda/envs/gdf/lib/python3.9/site-packages/distributed/worker.py", line 2056, in gather_dep
    response = await get_data_from_worker(
  File "/opt/conda/envs/gdf/lib/python3.9/site-packages/distributed/worker.py", line 2860, in get_data_from_worker
    response = await send_recv(
  File "/opt/conda/envs/gdf/lib/python3.9/site-packages/distributed/core.py", line 1154, in send_recv
    response = await comm.read(deserializers=deserializers)
  File "/opt/conda/envs/gdf/lib/python3.9/site-packages/distributed/utils.py", line 832, in wrapper
    return await func(*args, **kwargs)
  File "/opt/conda/envs/gdf/lib/python3.9/site-packages/distributed/comm/ucx.py", line 398, in read
    raise CommClosedError(
distributed.comm.core.CommClosedError: Connection closed by writer.
Inner exception: UCXError("<[Recv #007] ep: 0x7f64a8ca1180, tag: 0x6bacadc8ae805646, nbytes: 50000000, type: <class 'rmm._lib.device_buffer.DeviceBuffer'>>: Connection reset by remote peer")
2024-02-17 07:34:29,990 - distributed.worker - ERROR - Worker stream died during communication: ucx://127.0.0.1:58299
Traceback (most recent call last):
  File "/opt/conda/envs/gdf/lib/python3.9/site-packages/distributed/comm/ucx.py", line 392, in read
    await self.ep.recv(each_frame)
  File "/opt/conda/envs/gdf/lib/python3.9/site-packages/ucp/core.py", line 737, in recv
    ret = await comm.tag_recv(self._ep, buffer, nbytes, tag, name=log)
ucp._libs.exceptions.UCXError: <[Recv #007] ep: 0x7fc4a6df9200, tag: 0x6a8a8b8bc7a1481, nbytes: 50000000, type: <class 'rmm._lib.device_buffer.DeviceBuffer'>>: Connection reset by remote peer

During handling of the above exception, another exception occurred:

Traceback (most recent call last):
  File "/opt/conda/envs/gdf/lib/python3.9/site-packages/distributed/worker.py", line 2056, in gather_dep
    response = await get_data_from_worker(
  File "/opt/conda/envs/gdf/lib/python3.9/site-packages/distributed/worker.py", line 2860, in get_data_from_worker
    response = await send_recv(
  File "/opt/conda/envs/gdf/lib/python3.9/site-packages/distributed/core.py", line 1154, in send_recv
    response = await comm.read(deserializers=deserializers)
  File "/opt/conda/envs/gdf/lib/python3.9/site-packages/distributed/utils.py", line 832, in wrapper
    return await func(*args, **kwargs)
  File "/opt/conda/envs/gdf/lib/python3.9/site-packages/distributed/comm/ucx.py", line 398, in read
    raise CommClosedError(
distributed.comm.core.CommClosedError: Connection closed by writer.
Inner exception: UCXError("<[Recv #007] ep: 0x7fc4a6df9200, tag: 0x6a8a8b8bc7a1481, nbytes: 50000000, type: <class 'rmm._lib.device_buffer.DeviceBuffer'>>: Connection reset by remote peer")
2024-02-17 07:34:29,991 - distributed.worker - ERROR - failed during get data with ucx://127.0.0.1:34647 -> ucx://127.0.0.1:58299
Traceback (most recent call last):
  File "/opt/conda/envs/gdf/lib/python3.9/site-packages/distributed/comm/ucx.py", line 334, in write
    await self.ep.send(each_frame)
  File "/opt/conda/envs/gdf/lib/python3.9/site-packages/ucp/core.py", line 662, in send
    return await comm.tag_send(self._ep, buffer, nbytes, tag, name=log)
ucp._libs.exceptions.UCXError: <[Send #007] ep: 0x7f64a8ca12c0, tag: 0xb4846f34794489e8, nbytes: 50000000, type: <class 'cupy.ndarray'>>: Connection reset by remote peer

During handling of the above exception, another exception occurred:

Traceback (most recent call last):
  File "/opt/conda/envs/gdf/lib/python3.9/site-packages/distributed/worker.py", line 1779, in get_data
    compressed = await comm.write(msg, serializers=serializers)
  File "/opt/conda/envs/gdf/lib/python3.9/site-packages/distributed/utils.py", line 832, in wrapper
    return await func(*args, **kwargs)
  File "/opt/conda/envs/gdf/lib/python3.9/site-packages/distributed/comm/ucx.py", line 338, in write
    raise CommClosedError("While writing, the connection was closed")
distributed.comm.core.CommClosedError: While writing, the connection was closed
2024-02-17 07:34:29,990 - distributed.worker - ERROR - failed during get data with ucx://127.0.0.1:58431 -> ucx://127.0.0.1:58299
Traceback (most recent call last):
  File "/opt/conda/envs/gdf/lib/python3.9/site-packages/distributed/comm/ucx.py", line 334, in write
    await self.ep.send(each_frame)
  File "/opt/conda/envs/gdf/lib/python3.9/site-packages/ucp/core.py", line 662, in send
    return await comm.tag_send(self._ep, buffer, nbytes, tag, name=log)
ucp._libs.exceptions.UCXError: <[Send #007] ep: 0x7fb51892f240, tag: 0x86e10899073a8fe3, nbytes: 50000000, type: <class 'cupy.ndarray'>>: Connection reset by remote peer

During handling of the above exception, another exception occurred:

Traceback (most recent call last):
  File "/opt/conda/envs/gdf/lib/python3.9/site-packages/distributed/worker.py", line 1779, in get_data
    compressed = await comm.write(msg, serializers=serializers)
  File "/opt/conda/envs/gdf/lib/python3.9/site-packages/distributed/utils.py", line 832, in wrapper
    return await func(*args, **kwargs)
  File "/opt/conda/envs/gdf/lib/python3.9/site-packages/distributed/comm/ucx.py", line 338, in write
    raise CommClosedError("While writing, the connection was closed")
distributed.comm.core.CommClosedError: While writing, the connection was closed
2024-02-17 07:34:29,992 - distributed.worker - ERROR - failed during get data with ucx://127.0.0.1:34647 -> ucx://127.0.0.1:40899
Traceback (most recent call last):
  File "/opt/conda/envs/gdf/lib/python3.9/site-packages/distributed/comm/ucx.py", line 334, in write
    await self.ep.send(each_frame)
  File "/opt/conda/envs/gdf/lib/python3.9/site-packages/ucp/core.py", line 662, in send
    return await comm.tag_send(self._ep, buffer, nbytes, tag, name=log)
ucp._libs.exceptions.UCXError: <[Send #007] ep: 0x7f64a8ca1240, tag: 0xc5dc98fbd445b33a, nbytes: 50000000, type: <class 'cupy.ndarray'>>: Connection reset by remote peer

During handling of the above exception, another exception occurred:

Traceback (most recent call last):
  File "/opt/conda/envs/gdf/lib/python3.9/site-packages/distributed/worker.py", line 1779, in get_data
    compressed = await comm.write(msg, serializers=serializers)
  File "/opt/conda/envs/gdf/lib/python3.9/site-packages/distributed/utils.py", line 832, in wrapper
    return await func(*args, **kwargs)
  File "/opt/conda/envs/gdf/lib/python3.9/site-packages/distributed/comm/ucx.py", line 338, in write
    raise CommClosedError("While writing, the connection was closed")
distributed.comm.core.CommClosedError: While writing, the connection was closed
2024-02-17 07:34:29,992 - distributed.worker - ERROR - failed during get data with ucx://127.0.0.1:58431 -> ucx://127.0.0.1:34667
Traceback (most recent call last):
  File "/opt/conda/envs/gdf/lib/python3.9/site-packages/distributed/comm/ucx.py", line 334, in write
    await self.ep.send(each_frame)
  File "/opt/conda/envs/gdf/lib/python3.9/site-packages/ucp/core.py", line 662, in send
    return await comm.tag_send(self._ep, buffer, nbytes, tag, name=log)
ucp._libs.exceptions.UCXError: <[Send #012] ep: 0x7fb51892f2c0, tag: 0x3986621d7bcb3dbc, nbytes: 50000000, type: <class 'cupy.ndarray'>>: Connection reset by remote peer

During handling of the above exception, another exception occurred:

Traceback (most recent call last):
  File "/opt/conda/envs/gdf/lib/python3.9/site-packages/distributed/worker.py", line 1779, in get_data
    compressed = await comm.write(msg, serializers=serializers)
  File "/opt/conda/envs/gdf/lib/python3.9/site-packages/distributed/utils.py", line 832, in wrapper
    return await func(*args, **kwargs)
  File "/opt/conda/envs/gdf/lib/python3.9/site-packages/distributed/comm/ucx.py", line 338, in write
    raise CommClosedError("While writing, the connection was closed")
distributed.comm.core.CommClosedError: While writing, the connection was closed
2024-02-17 07:34:30,040 - distributed.worker - ERROR - failed during get data with ucx://127.0.0.1:45805 -> ucx://127.0.0.1:59857
Traceback (most recent call last):
  File "/opt/conda/envs/gdf/lib/python3.9/site-packages/distributed/comm/ucx.py", line 334, in write
    await self.ep.send(each_frame)
  File "/opt/conda/envs/gdf/lib/python3.9/site-packages/ucp/core.py", line 662, in send
    return await comm.tag_send(self._ep, buffer, nbytes, tag, name=log)
ucp._libs.exceptions.UCXError: <[Send #007] ep: 0x7fc4a6df9240, tag: 0x6488c26568ffa1c6, nbytes: 50000000, type: <class 'cupy.ndarray'>>: Connection reset by remote peer

During handling of the above exception, another exception occurred:

Traceback (most recent call last):
  File "/opt/conda/envs/gdf/lib/python3.9/site-packages/distributed/worker.py", line 1779, in get_data
    compressed = await comm.write(msg, serializers=serializers)
  File "/opt/conda/envs/gdf/lib/python3.9/site-packages/distributed/utils.py", line 832, in wrapper
    return await func(*args, **kwargs)
  File "/opt/conda/envs/gdf/lib/python3.9/site-packages/distributed/comm/ucx.py", line 338, in write
    raise CommClosedError("While writing, the connection was closed")
distributed.comm.core.CommClosedError: While writing, the connection was closed
2024-02-17 07:34:30,041 - distributed.worker - ERROR - Worker stream died during communication: ucx://127.0.0.1:59857
Traceback (most recent call last):
  File "/opt/conda/envs/gdf/lib/python3.9/site-packages/distributed/comm/ucx.py", line 350, in read
    await self.ep.recv(msg)
  File "/opt/conda/envs/gdf/lib/python3.9/site-packages/ucp/core.py", line 737, in recv
    ret = await comm.tag_recv(self._ep, buffer, nbytes, tag, name=log)
ucp._libs.exceptions.UCXCanceled: <[Recv #003] ep: 0x7fc4a6df9100, tag: 0x4c0c7e1c625853a3, nbytes: 16, type: <class 'numpy.ndarray'>>: 

During handling of the above exception, another exception occurred:

Traceback (most recent call last):
  File "/opt/conda/envs/gdf/lib/python3.9/site-packages/distributed/worker.py", line 2056, in gather_dep
    response = await get_data_from_worker(
  File "/opt/conda/envs/gdf/lib/python3.9/site-packages/distributed/worker.py", line 2860, in get_data_from_worker
    response = await send_recv(
  File "/opt/conda/envs/gdf/lib/python3.9/site-packages/distributed/core.py", line 1154, in send_recv
    response = await comm.read(deserializers=deserializers)
  File "/opt/conda/envs/gdf/lib/python3.9/site-packages/distributed/utils.py", line 832, in wrapper
    return await func(*args, **kwargs)
  File "/opt/conda/envs/gdf/lib/python3.9/site-packages/distributed/comm/ucx.py", line 368, in read
    raise CommClosedError(
distributed.comm.core.CommClosedError: Connection closed by writer.
Inner exception: UCXCanceled("<[Recv #003] ep: 0x7fc4a6df9100, tag: 0x4c0c7e1c625853a3, nbytes: 16, type: <class 'numpy.ndarray'>>: ")
2024-02-17 07:34:32,187 - distributed.nanny - WARNING - Restarting worker
2024-02-17 07:34:32,190 - distributed.nanny - WARNING - Restarting worker
2024-02-17 07:34:32,213 - distributed.nanny - WARNING - Restarting worker
2024-02-17 07:34:32,240 - distributed.nanny - WARNING - Restarting worker
/opt/conda/envs/gdf/lib/python3.9/multiprocessing/resource_tracker.py:216: UserWarning: resource_tracker: There appear to be 48 leaked semaphore objects to clean up at shutdown
  warnings.warn('resource_tracker: There appear to be %d '
