2023-01-29 00:00:54,088 - distributed.preloading - INFO - Creating preload: dask_cuda.initialize
2023-01-29 00:00:54,089 - distributed.preloading - INFO - Import preload module: dask_cuda.initialize
2023-01-29 00:00:54,101 - distributed.preloading - INFO - Creating preload: dask_cuda.initialize
2023-01-29 00:00:54,101 - distributed.preloading - INFO - Import preload module: dask_cuda.initialize
2023-01-29 00:00:54,111 - distributed.preloading - INFO - Creating preload: dask_cuda.initialize
2023-01-29 00:00:54,111 - distributed.preloading - INFO - Import preload module: dask_cuda.initialize
2023-01-29 00:00:54,114 - distributed.preloading - INFO - Creating preload: dask_cuda.initialize
2023-01-29 00:00:54,114 - distributed.preloading - INFO - Import preload module: dask_cuda.initialize
2023-01-29 00:00:54,118 - distributed.preloading - INFO - Creating preload: dask_cuda.initialize
2023-01-29 00:00:54,118 - distributed.preloading - INFO - Import preload module: dask_cuda.initialize
2023-01-29 00:00:54,121 - distributed.preloading - INFO - Creating preload: dask_cuda.initialize
2023-01-29 00:00:54,121 - distributed.preloading - INFO - Import preload module: dask_cuda.initialize
2023-01-29 00:00:54,122 - distributed.preloading - INFO - Creating preload: dask_cuda.initialize
2023-01-29 00:00:54,122 - distributed.preloading - INFO - Import preload module: dask_cuda.initialize
2023-01-29 00:00:54,167 - distributed.preloading - INFO - Creating preload: dask_cuda.initialize
2023-01-29 00:00:54,167 - distributed.preloading - INFO - Import preload module: dask_cuda.initialize
[dgx13:34720:0:34720] Caught signal 11 (Segmentation fault: address not mapped to object at address 0x448)
==== backtrace (tid:  34720) ====
 0  /datasets/pentschev/miniconda3/envs/gdf/lib/libucs.so.0(ucs_handle_error+0x2d4) [0x7fdee9aeb2c4]
 1  /datasets/pentschev/miniconda3/envs/gdf/lib/libucs.so.0(+0x2e49f) [0x7fdee9aeb49f]
 2  /datasets/pentschev/miniconda3/envs/gdf/lib/libucs.so.0(+0x2e7c4) [0x7fdee9aeb7c4]
 3  /lib/x86_64-linux-gnu/libpthread.so.0(+0x12980) [0x7fdf6d27c980]
 4  /datasets/pentschev/miniconda3/envs/gdf/lib/libucp.so.0(ucp_mem_type_unpack+0x14) [0x7fdee9d703b4]
 5  /datasets/pentschev/miniconda3/envs/gdf/lib/libucp.so.0(ucp_rndv_data_handler+0x508) [0x7fdee9da0a08]
 6  /datasets/pentschev/miniconda3/envs/gdf/lib/libuct.so.0(+0x20b5f) [0x7fdee989fb5f]
 7  /datasets/pentschev/miniconda3/envs/gdf/lib/libuct.so.0(+0x21134) [0x7fdee98a0134]
 8  /datasets/pentschev/miniconda3/envs/gdf/lib/libuct.so.0(+0x23578) [0x7fdee98a2578]
 9  /datasets/pentschev/miniconda3/envs/gdf/lib/libucs.so.0(ucs_event_set_wait+0xb9) [0x7fdee9af5949]
10  /datasets/pentschev/miniconda3/envs/gdf/lib/libuct.so.0(uct_tcp_iface_progress+0x7b) [0x7fdee98a261b]
11  /datasets/pentschev/miniconda3/envs/gdf/lib/libucp.so.0(ucp_worker_progress+0x6a) [0x7fdee9d6ccaa]
12  /datasets/pentschev/miniconda3/envs/gdf/lib/python3.9/site-packages/ucp/_libs/ucx_api.cpython-39-x86_64-linux-gnu.so(+0x26c79) [0x7fdefc137c79]
13  /datasets/pentschev/miniconda3/envs/gdf/bin/python(+0x141eca) [0x557dea2b4eca]
14  /datasets/pentschev/miniconda3/envs/gdf/bin/python(_PyEval_EvalFrameDefault+0x3d99) [0x557dea2a2549]
15  /datasets/pentschev/miniconda3/envs/gdf/bin/python(+0x12a7d7) [0x557dea29d7d7]
16  /datasets/pentschev/miniconda3/envs/gdf/bin/python(_PyFunction_Vectorcall+0xb9) [0x557dea2afbb9]
17  /datasets/pentschev/miniconda3/envs/gdf/bin/python(_PyEval_EvalFrameDefault+0x672) [0x557dea29ee22]
18  /datasets/pentschev/miniconda3/envs/gdf/bin/python(+0x153244) [0x557dea2c6244]
19  /datasets/pentschev/miniconda3/envs/gdf/lib/python3.9/lib-dynload/_asyncio.cpython-39-x86_64-linux-gnu.so(+0x8301) [0x7fdf078bc301]
20  /datasets/pentschev/miniconda3/envs/gdf/bin/python(_PyObject_MakeTpCall+0x347) [0x557dea2a7a57]
21  /datasets/pentschev/miniconda3/envs/gdf/bin/python(+0xf7187) [0x557dea26a187]
22  /datasets/pentschev/miniconda3/envs/gdf/bin/python(+0x133747) [0x557dea2a6747]
23  /datasets/pentschev/miniconda3/envs/gdf/bin/python(_PyEval_EvalFrameDefault+0x5f0a) [0x557dea2a46ba]
24  /datasets/pentschev/miniconda3/envs/gdf/bin/python(+0x13cec3) [0x557dea2afec3]
25  /datasets/pentschev/miniconda3/envs/gdf/bin/python(_PyEval_EvalFrameDefault+0x672) [0x557dea29ee22]
26  /datasets/pentschev/miniconda3/envs/gdf/bin/python(+0x13cec3) [0x557dea2afec3]
27  /datasets/pentschev/miniconda3/envs/gdf/bin/python(_PyEval_EvalFrameDefault+0x672) [0x557dea29ee22]
28  /datasets/pentschev/miniconda3/envs/gdf/bin/python(+0x13cec3) [0x557dea2afec3]
29  /datasets/pentschev/miniconda3/envs/gdf/bin/python(_PyEval_EvalFrameDefault+0x672) [0x557dea29ee22]
30  /datasets/pentschev/miniconda3/envs/gdf/bin/python(+0x13cec3) [0x557dea2afec3]
31  /datasets/pentschev/miniconda3/envs/gdf/bin/python(_PyEval_EvalFrameDefault+0x672) [0x557dea29ee22]
32  /datasets/pentschev/miniconda3/envs/gdf/bin/python(+0x12a7d7) [0x557dea29d7d7]
33  /datasets/pentschev/miniconda3/envs/gdf/bin/python(_PyFunction_Vectorcall+0xb9) [0x557dea2afbb9]
34  /datasets/pentschev/miniconda3/envs/gdf/bin/python(_PyEval_EvalFrameDefault+0x4cbc) [0x557dea2a346c]
35  /datasets/pentschev/miniconda3/envs/gdf/bin/python(+0x12a7d7) [0x557dea29d7d7]
36  /datasets/pentschev/miniconda3/envs/gdf/bin/python(+0x14baf8) [0x557dea2beaf8]
37  /datasets/pentschev/miniconda3/envs/gdf/bin/python(PyObject_Call+0xb4) [0x557dea2bf254]
38  /datasets/pentschev/miniconda3/envs/gdf/bin/python(+0x21b8b8) [0x557dea38e8b8]
39  /datasets/pentschev/miniconda3/envs/gdf/bin/python(_PyObject_MakeTpCall+0x347) [0x557dea2a7a57]
40  /datasets/pentschev/miniconda3/envs/gdf/bin/python(_PyEval_EvalFrameDefault+0x3d99) [0x557dea2a2549]
41  /datasets/pentschev/miniconda3/envs/gdf/bin/python(+0x13cec3) [0x557dea2afec3]
42  /datasets/pentschev/miniconda3/envs/gdf/bin/python(+0x14bb91) [0x557dea2beb91]
43  /datasets/pentschev/miniconda3/envs/gdf/bin/python(_PyEval_EvalFrameDefault+0x3d99) [0x557dea2a2549]
44  /datasets/pentschev/miniconda3/envs/gdf/bin/python(+0x13cec3) [0x557dea2afec3]
45  /datasets/pentschev/miniconda3/envs/gdf/bin/python(_PyEval_EvalFrameDefault+0x672) [0x557dea29ee22]
46  /datasets/pentschev/miniconda3/envs/gdf/bin/python(+0x12a7d7) [0x557dea29d7d7]
47  /datasets/pentschev/miniconda3/envs/gdf/bin/python(_PyFunction_Vectorcall+0xb9) [0x557dea2afbb9]
48  /datasets/pentschev/miniconda3/envs/gdf/bin/python(_PyEval_EvalFrameDefault+0x672) [0x557dea29ee22]
49  /datasets/pentschev/miniconda3/envs/gdf/bin/python(+0x13cec3) [0x557dea2afec3]
50  /datasets/pentschev/miniconda3/envs/gdf/bin/python(_PyEval_EvalFrameDefault+0x3c3) [0x557dea29eb73]
51  /datasets/pentschev/miniconda3/envs/gdf/bin/python(+0x12a7d7) [0x557dea29d7d7]
52  /datasets/pentschev/miniconda3/envs/gdf/bin/python(_PyFunction_Vectorcall+0xb9) [0x557dea2afbb9]
53  /datasets/pentschev/miniconda3/envs/gdf/bin/python(_PyEval_EvalFrameDefault+0x11df) [0x557dea29f98f]
54  /datasets/pentschev/miniconda3/envs/gdf/bin/python(+0x12a7d7) [0x557dea29d7d7]
55  /datasets/pentschev/miniconda3/envs/gdf/bin/python(_PyEval_EvalCodeWithName+0x47) [0x557dea29d497]
56  /datasets/pentschev/miniconda3/envs/gdf/bin/python(PyEval_EvalCodeEx+0x39) [0x557dea29d449]
57  /datasets/pentschev/miniconda3/envs/gdf/bin/python(PyEval_EvalCode+0x1b) [0x557dea357ddb]
58  /datasets/pentschev/miniconda3/envs/gdf/bin/python(+0x213409) [0x557dea386409]
59  /datasets/pentschev/miniconda3/envs/gdf/bin/python(+0x20f5a4) [0x557dea3825a4]
60  /datasets/pentschev/miniconda3/envs/gdf/bin/python(PyRun_StringFlags+0x9d) [0x557dea37a27d]
61  /datasets/pentschev/miniconda3/envs/gdf/bin/python(PyRun_SimpleStringFlags+0x3d) [0x557dea37a14d]
=================================
2023-01-29 00:01:02,695 - distributed.worker - ERROR - failed during get data with ucx://127.0.0.1:55759 -> ucx://127.0.0.1:54865
Traceback (most recent call last):
  File "/datasets/pentschev/miniconda3/envs/gdf/lib/python3.9/site-packages/distributed/comm/ucx.py", line 333, in write
    await self.ep.send(each_frame)
  File "/datasets/pentschev/miniconda3/envs/gdf/lib/python3.9/site-packages/ucp/core.py", line 650, in send
    return await comm.tag_send(self._ep, buffer, nbytes, tag, name=log)
ucp._libs.exceptions.UCXError: <[Send #007] ep: 0x7f6098004100, tag: 0x6ea2e4dc3e030d99, nbytes: 800000000, type: <class 'cudf.core.buffer.buffer.Buffer'>>: Connection reset by remote peer

During handling of the above exception, another exception occurred:

Traceback (most recent call last):
  File "/datasets/pentschev/miniconda3/envs/gdf/lib/python3.9/site-packages/distributed/worker.py", line 1766, in get_data
    compressed = await comm.write(msg, serializers=serializers)
  File "/datasets/pentschev/miniconda3/envs/gdf/lib/python3.9/site-packages/distributed/utils.py", line 741, in wrapper
    return await func(*args, **kwargs)
  File "/datasets/pentschev/miniconda3/envs/gdf/lib/python3.9/site-packages/distributed/comm/ucx.py", line 337, in write
    raise CommClosedError("While writing, the connection was closed")
distributed.comm.core.CommClosedError: While writing, the connection was closed
2023-01-29 00:01:02,779 - distributed.nanny - WARNING - Restarting worker
[dgx13:34702:0:34702] Caught signal 11 (Segmentation fault: address not mapped to object at address 0x448)
==== backtrace (tid:  34702) ====
 0  /datasets/pentschev/miniconda3/envs/gdf/lib/libucs.so.0(ucs_handle_error+0x2d4) [0x7f6081aeb2c4]
 1  /datasets/pentschev/miniconda3/envs/gdf/lib/libucs.so.0(+0x2e49f) [0x7f6081aeb49f]
 2  /datasets/pentschev/miniconda3/envs/gdf/lib/libucs.so.0(+0x2e7c4) [0x7f6081aeb7c4]
 3  /lib/x86_64-linux-gnu/libpthread.so.0(+0x12980) [0x7f6109208980]
 4  /datasets/pentschev/miniconda3/envs/gdf/lib/libucp.so.0(ucp_mem_type_unpack+0x14) [0x7f6081d703b4]
 5  /datasets/pentschev/miniconda3/envs/gdf/lib/libucp.so.0(ucp_rndv_data_handler+0x508) [0x7f6081da0a08]
 6  /datasets/pentschev/miniconda3/envs/gdf/lib/libuct.so.0(+0x20b5f) [0x7f608189fb5f]
 7  /datasets/pentschev/miniconda3/envs/gdf/lib/libuct.so.0(+0x21134) [0x7f60818a0134]
 8  /datasets/pentschev/miniconda3/envs/gdf/lib/libuct.so.0(+0x23578) [0x7f60818a2578]
 9  /datasets/pentschev/miniconda3/envs/gdf/lib/libucs.so.0(ucs_event_set_wait+0xb9) [0x7f6081af5949]
10  /datasets/pentschev/miniconda3/envs/gdf/lib/libuct.so.0(uct_tcp_iface_progress+0x7b) [0x7f60818a261b]
11  /datasets/pentschev/miniconda3/envs/gdf/lib/libucp.so.0(ucp_worker_progress+0x6a) [0x7f6081d6ccaa]
12  /datasets/pentschev/miniconda3/envs/gdf/lib/python3.9/site-packages/ucp/_libs/ucx_api.cpython-39-x86_64-linux-gnu.so(+0x26c79) [0x7f60980c1c79]
13  /datasets/pentschev/miniconda3/envs/gdf/bin/python(+0x141eca) [0x56427449feca]
14  /datasets/pentschev/miniconda3/envs/gdf/bin/python(_PyEval_EvalFrameDefault+0x3d99) [0x56427448d549]
15  /datasets/pentschev/miniconda3/envs/gdf/bin/python(+0x12a7d7) [0x5642744887d7]
16  /datasets/pentschev/miniconda3/envs/gdf/bin/python(_PyFunction_Vectorcall+0xb9) [0x56427449abb9]
17  /datasets/pentschev/miniconda3/envs/gdf/bin/python(_PyEval_EvalFrameDefault+0x672) [0x564274489e22]
18  /datasets/pentschev/miniconda3/envs/gdf/bin/python(+0x13cec3) [0x56427449aec3]
19  /datasets/pentschev/miniconda3/envs/gdf/bin/python(+0x14bc75) [0x5642744a9c75]
20  /datasets/pentschev/miniconda3/envs/gdf/bin/python(+0x264071) [0x5642745c2071]
21  /datasets/pentschev/miniconda3/envs/gdf/bin/python(+0xf7187) [0x564274455187]
22  /datasets/pentschev/miniconda3/envs/gdf/bin/python(+0x133747) [0x564274491747]
23  /datasets/pentschev/miniconda3/envs/gdf/bin/python(_PyEval_EvalFrameDefault+0x5f0a) [0x56427448f6ba]
24  /datasets/pentschev/miniconda3/envs/gdf/bin/python(+0x13cec3) [0x56427449aec3]
25  /datasets/pentschev/miniconda3/envs/gdf/bin/python(_PyEval_EvalFrameDefault+0x672) [0x564274489e22]
26  /datasets/pentschev/miniconda3/envs/gdf/bin/python(+0x13cec3) [0x56427449aec3]
27  /datasets/pentschev/miniconda3/envs/gdf/bin/python(_PyEval_EvalFrameDefault+0x672) [0x564274489e22]
28  /datasets/pentschev/miniconda3/envs/gdf/bin/python(+0x13cec3) [0x56427449aec3]
29  /datasets/pentschev/miniconda3/envs/gdf/bin/python(_PyEval_EvalFrameDefault+0x672) [0x564274489e22]
30  /datasets/pentschev/miniconda3/envs/gdf/bin/python(+0x13cec3) [0x56427449aec3]
31  /datasets/pentschev/miniconda3/envs/gdf/bin/python(_PyEval_EvalFrameDefault+0x672) [0x564274489e22]
32  /datasets/pentschev/miniconda3/envs/gdf/bin/python(+0x12a7d7) [0x5642744887d7]
33  /datasets/pentschev/miniconda3/envs/gdf/bin/python(_PyFunction_Vectorcall+0xb9) [0x56427449abb9]
34  /datasets/pentschev/miniconda3/envs/gdf/bin/python(_PyEval_EvalFrameDefault+0x4cbc) [0x56427448e46c]
35  /datasets/pentschev/miniconda3/envs/gdf/bin/python(+0x12a7d7) [0x5642744887d7]
36  /datasets/pentschev/miniconda3/envs/gdf/bin/python(+0x14baf8) [0x5642744a9af8]
37  /datasets/pentschev/miniconda3/envs/gdf/bin/python(PyObject_Call+0xb4) [0x5642744aa254]
38  /datasets/pentschev/miniconda3/envs/gdf/bin/python(+0x21b8b8) [0x5642745798b8]
39  /datasets/pentschev/miniconda3/envs/gdf/bin/python(_PyObject_MakeTpCall+0x347) [0x564274492a57]
40  /datasets/pentschev/miniconda3/envs/gdf/bin/python(_PyEval_EvalFrameDefault+0x3d99) [0x56427448d549]
41  /datasets/pentschev/miniconda3/envs/gdf/bin/python(+0x13cec3) [0x56427449aec3]
42  /datasets/pentschev/miniconda3/envs/gdf/bin/python(+0x14bb91) [0x5642744a9b91]
43  /datasets/pentschev/miniconda3/envs/gdf/bin/python(_PyEval_EvalFrameDefault+0x3d99) [0x56427448d549]
44  /datasets/pentschev/miniconda3/envs/gdf/bin/python(+0x13cec3) [0x56427449aec3]
45  /datasets/pentschev/miniconda3/envs/gdf/bin/python(_PyEval_EvalFrameDefault+0x672) [0x564274489e22]
46  /datasets/pentschev/miniconda3/envs/gdf/bin/python(+0x12a7d7) [0x5642744887d7]
47  /datasets/pentschev/miniconda3/envs/gdf/bin/python(_PyFunction_Vectorcall+0xb9) [0x56427449abb9]
48  /datasets/pentschev/miniconda3/envs/gdf/bin/python(_PyEval_EvalFrameDefault+0x672) [0x564274489e22]
49  /datasets/pentschev/miniconda3/envs/gdf/bin/python(+0x13cec3) [0x56427449aec3]
50  /datasets/pentschev/miniconda3/envs/gdf/bin/python(_PyEval_EvalFrameDefault+0x3c3) [0x564274489b73]
51  /datasets/pentschev/miniconda3/envs/gdf/bin/python(+0x12a7d7) [0x5642744887d7]
52  /datasets/pentschev/miniconda3/envs/gdf/bin/python(_PyFunction_Vectorcall+0xb9) [0x56427449abb9]
53  /datasets/pentschev/miniconda3/envs/gdf/bin/python(_PyEval_EvalFrameDefault+0x11df) [0x56427448a98f]
54  /datasets/pentschev/miniconda3/envs/gdf/bin/python(+0x12a7d7) [0x5642744887d7]
55  /datasets/pentschev/miniconda3/envs/gdf/bin/python(_PyEval_EvalCodeWithName+0x47) [0x564274488497]
56  /datasets/pentschev/miniconda3/envs/gdf/bin/python(PyEval_EvalCodeEx+0x39) [0x564274488449]
57  /datasets/pentschev/miniconda3/envs/gdf/bin/python(PyEval_EvalCode+0x1b) [0x564274542ddb]
58  /datasets/pentschev/miniconda3/envs/gdf/bin/python(+0x213409) [0x564274571409]
59  /datasets/pentschev/miniconda3/envs/gdf/bin/python(+0x20f5a4) [0x56427456d5a4]
60  /datasets/pentschev/miniconda3/envs/gdf/bin/python(PyRun_StringFlags+0x9d) [0x56427456527d]
61  /datasets/pentschev/miniconda3/envs/gdf/bin/python(PyRun_SimpleStringFlags+0x3d) [0x56427456514d]
=================================
[dgx13:34714:0:34714] Caught signal 11 (Segmentation fault: address not mapped to object at address 0x448)
==== backtrace (tid:  34714) ====
 0  /datasets/pentschev/miniconda3/envs/gdf/lib/libucs.so.0(ucs_handle_error+0x2d4) [0x7fe3bc2b32c4]
 1  /datasets/pentschev/miniconda3/envs/gdf/lib/libucs.so.0(+0x2e49f) [0x7fe3bc2b349f]
 2  /datasets/pentschev/miniconda3/envs/gdf/lib/libucs.so.0(+0x2e7c4) [0x7fe3bc2b37c4]
 3  /lib/x86_64-linux-gnu/libpthread.so.0(+0x12980) [0x7fe43f946980]
 4  /datasets/pentschev/miniconda3/envs/gdf/lib/libucp.so.0(ucp_mem_type_unpack+0x14) [0x7fe3bc5383b4]
 5  /datasets/pentschev/miniconda3/envs/gdf/lib/libucp.so.0(ucp_rndv_data_handler+0x508) [0x7fe3bc568a08]
 6  /datasets/pentschev/miniconda3/envs/gdf/lib/libuct.so.0(+0x20b5f) [0x7fe3bc067b5f]
 7  /datasets/pentschev/miniconda3/envs/gdf/lib/libuct.so.0(+0x21134) [0x7fe3bc068134]
 8  /datasets/pentschev/miniconda3/envs/gdf/lib/libuct.so.0(+0x23578) [0x7fe3bc06a578]
 9  /datasets/pentschev/miniconda3/envs/gdf/lib/libucs.so.0(ucs_event_set_wait+0xb9) [0x7fe3bc2bd949]
10  /datasets/pentschev/miniconda3/envs/gdf/lib/libuct.so.0(uct_tcp_iface_progress+0x7b) [0x7fe3bc06a61b]
11  /datasets/pentschev/miniconda3/envs/gdf/lib/libucp.so.0(ucp_worker_progress+0x6a) [0x7fe3bc534caa]
12  /datasets/pentschev/miniconda3/envs/gdf/lib/python3.9/site-packages/ucp/_libs/ucx_api.cpython-39-x86_64-linux-gnu.so(+0x26c79) [0x7fe3bc7eec79]
13  /datasets/pentschev/miniconda3/envs/gdf/bin/python(+0x141eca) [0x558d0c54beca]
14  /datasets/pentschev/miniconda3/envs/gdf/bin/python(_PyEval_EvalFrameDefault+0x3d99) [0x558d0c539549]
15  /datasets/pentschev/miniconda3/envs/gdf/bin/python(+0x12a7d7) [0x558d0c5347d7]
16  /datasets/pentschev/miniconda3/envs/gdf/bin/python(_PyFunction_Vectorcall+0xb9) [0x558d0c546bb9]
17  /datasets/pentschev/miniconda3/envs/gdf/bin/python(_PyEval_EvalFrameDefault+0x672) [0x558d0c535e22]
18  /datasets/pentschev/miniconda3/envs/gdf/bin/python(+0x13cec3) [0x558d0c546ec3]
19  /datasets/pentschev/miniconda3/envs/gdf/bin/python(+0x14bc75) [0x558d0c555c75]
20  /datasets/pentschev/miniconda3/envs/gdf/bin/python(+0x264071) [0x558d0c66e071]
21  /datasets/pentschev/miniconda3/envs/gdf/bin/python(+0xf7187) [0x558d0c501187]
22  /datasets/pentschev/miniconda3/envs/gdf/bin/python(+0x133747) [0x558d0c53d747]
23  /datasets/pentschev/miniconda3/envs/gdf/bin/python(_PyEval_EvalFrameDefault+0x5f0a) [0x558d0c53b6ba]
24  /datasets/pentschev/miniconda3/envs/gdf/bin/python(+0x13cec3) [0x558d0c546ec3]
25  /datasets/pentschev/miniconda3/envs/gdf/bin/python(_PyEval_EvalFrameDefault+0x672) [0x558d0c535e22]
26  /datasets/pentschev/miniconda3/envs/gdf/bin/python(+0x13cec3) [0x558d0c546ec3]
27  /datasets/pentschev/miniconda3/envs/gdf/bin/python(_PyEval_EvalFrameDefault+0x672) [0x558d0c535e22]
28  /datasets/pentschev/miniconda3/envs/gdf/bin/python(+0x13cec3) [0x558d0c546ec3]
29  /datasets/pentschev/miniconda3/envs/gdf/bin/python(_PyEval_EvalFrameDefault+0x672) [0x558d0c535e22]
30  /datasets/pentschev/miniconda3/envs/gdf/bin/python(+0x13cec3) [0x558d0c546ec3]
31  /datasets/pentschev/miniconda3/envs/gdf/bin/python(_PyEval_EvalFrameDefault+0x672) [0x558d0c535e22]
32  /datasets/pentschev/miniconda3/envs/gdf/bin/python(+0x12a7d7) [0x558d0c5347d7]
33  /datasets/pentschev/miniconda3/envs/gdf/bin/python(_PyFunction_Vectorcall+0xb9) [0x558d0c546bb9]
34  /datasets/pentschev/miniconda3/envs/gdf/bin/python(_PyEval_EvalFrameDefault+0x4cbc) [0x558d0c53a46c]
35  /datasets/pentschev/miniconda3/envs/gdf/bin/python(+0x12a7d7) [0x558d0c5347d7]
36  /datasets/pentschev/miniconda3/envs/gdf/bin/python(+0x14baf8) [0x558d0c555af8]
37  /datasets/pentschev/miniconda3/envs/gdf/bin/python(PyObject_Call+0xb4) [0x558d0c556254]
38  /datasets/pentschev/miniconda3/envs/gdf/bin/python(+0x21b8b8) [0x558d0c6258b8]
39  /datasets/pentschev/miniconda3/envs/gdf/bin/python(_PyObject_MakeTpCall+0x347) [0x558d0c53ea57]
40  /datasets/pentschev/miniconda3/envs/gdf/bin/python(_PyEval_EvalFrameDefault+0x3d99) [0x558d0c539549]
41  /datasets/pentschev/miniconda3/envs/gdf/bin/python(+0x13cec3) [0x558d0c546ec3]
42  /datasets/pentschev/miniconda3/envs/gdf/bin/python(+0x14bb91) [0x558d0c555b91]
43  /datasets/pentschev/miniconda3/envs/gdf/bin/python(_PyEval_EvalFrameDefault+0x3d99) [0x558d0c539549]
44  /datasets/pentschev/miniconda3/envs/gdf/bin/python(+0x13cec3) [0x558d0c546ec3]
45  /datasets/pentschev/miniconda3/envs/gdf/bin/python(_PyEval_EvalFrameDefault+0x672) [0x558d0c535e22]
46  /datasets/pentschev/miniconda3/envs/gdf/bin/python(+0x12a7d7) [0x558d0c5347d7]
47  /datasets/pentschev/miniconda3/envs/gdf/bin/python(_PyFunction_Vectorcall+0xb9) [0x558d0c546bb9]
48  /datasets/pentschev/miniconda3/envs/gdf/bin/python(_PyEval_EvalFrameDefault+0x672) [0x558d0c535e22]
49  /datasets/pentschev/miniconda3/envs/gdf/bin/python(+0x13cec3) [0x558d0c546ec3]
50  /datasets/pentschev/miniconda3/envs/gdf/bin/python(_PyEval_EvalFrameDefault+0x3c3) [0x558d0c535b73]
51  /datasets/pentschev/miniconda3/envs/gdf/bin/python(+0x12a7d7) [0x558d0c5347d7]
52  /datasets/pentschev/miniconda3/envs/gdf/bin/python(_PyFunction_Vectorcall+0xb9) [0x558d0c546bb9]
53  /datasets/pentschev/miniconda3/envs/gdf/bin/python(_PyEval_EvalFrameDefault+0x11df) [0x558d0c53698f]
54  /datasets/pentschev/miniconda3/envs/gdf/bin/python(+0x12a7d7) [0x558d0c5347d7]
55  /datasets/pentschev/miniconda3/envs/gdf/bin/python(_PyEval_EvalCodeWithName+0x47) [0x558d0c534497]
56  /datasets/pentschev/miniconda3/envs/gdf/bin/python(PyEval_EvalCodeEx+0x39) [0x558d0c534449]
57  /datasets/pentschev/miniconda3/envs/gdf/bin/python(PyEval_EvalCode+0x1b) [0x558d0c5eeddb]
58  /datasets/pentschev/miniconda3/envs/gdf/bin/python(+0x213409) [0x558d0c61d409]
59  /datasets/pentschev/miniconda3/envs/gdf/bin/python(+0x20f5a4) [0x558d0c6195a4]
60  /datasets/pentschev/miniconda3/envs/gdf/bin/python(PyRun_StringFlags+0x9d) [0x558d0c61127d]
61  /datasets/pentschev/miniconda3/envs/gdf/bin/python(PyRun_SimpleStringFlags+0x3d) [0x558d0c61114d]
=================================
[dgx13:34706:0:34706] Caught signal 11 (Segmentation fault: address not mapped to object at address 0x448)
==== backtrace (tid:  34706) ====
 0  /datasets/pentschev/miniconda3/envs/gdf/lib/libucs.so.0(ucs_handle_error+0x2d4) [0x7f83e860b2c4]
 1  /datasets/pentschev/miniconda3/envs/gdf/lib/libucs.so.0(+0x2e49f) [0x7f83e860b49f]
 2  /datasets/pentschev/miniconda3/envs/gdf/lib/libucs.so.0(+0x2e7c4) [0x7f83e860b7c4]
 3  /lib/x86_64-linux-gnu/libpthread.so.0(+0x12980) [0x7f846bce0980]
 4  /datasets/pentschev/miniconda3/envs/gdf/lib/libucp.so.0(ucp_mem_type_unpack+0x14) [0x7f83e88903b4]
 5  /datasets/pentschev/miniconda3/envs/gdf/lib/libucp.so.0(ucp_rndv_data_handler+0x508) [0x7f83e88c0a08]
 6  /datasets/pentschev/miniconda3/envs/gdf/lib/libuct.so.0(+0x20b5f) [0x7f83e83bfb5f]
 7  /datasets/pentschev/miniconda3/envs/gdf/lib/libuct.so.0(+0x21134) [0x7f83e83c0134]
 8  /datasets/pentschev/miniconda3/envs/gdf/lib/libuct.so.0(+0x23578) [0x7f83e83c2578]
 9  /datasets/pentschev/miniconda3/envs/gdf/lib/libucs.so.0(ucs_event_set_wait+0xb9) [0x7f83e8615949]
10  /datasets/pentschev/miniconda3/envs/gdf/lib/libuct.so.0(uct_tcp_iface_progress+0x7b) [0x7f83e83c261b]
11  /datasets/pentschev/miniconda3/envs/gdf/lib/libucp.so.0(ucp_worker_progress+0x6a) [0x7f83e888ccaa]
12  /datasets/pentschev/miniconda3/envs/gdf/lib/python3.9/site-packages/ucp/_libs/ucx_api.cpython-39-x86_64-linux-gnu.so(+0x26c79) [0x7f83e8b46c79]
13  /datasets/pentschev/miniconda3/envs/gdf/bin/python(+0x141eca) [0x557afe888eca]
14  /datasets/pentschev/miniconda3/envs/gdf/bin/python(_PyEval_EvalFrameDefault+0x3d99) [0x557afe876549]
15  /datasets/pentschev/miniconda3/envs/gdf/bin/python(+0x12a7d7) [0x557afe8717d7]
16  /datasets/pentschev/miniconda3/envs/gdf/bin/python(_PyFunction_Vectorcall+0xb9) [0x557afe883bb9]
17  /datasets/pentschev/miniconda3/envs/gdf/bin/python(_PyEval_EvalFrameDefault+0x672) [0x557afe872e22]
18  /datasets/pentschev/miniconda3/envs/gdf/bin/python(+0x13cec3) [0x557afe883ec3]
19  /datasets/pentschev/miniconda3/envs/gdf/bin/python(+0x14bc75) [0x557afe892c75]
20  /datasets/pentschev/miniconda3/envs/gdf/bin/python(+0x264071) [0x557afe9ab071]
21  /datasets/pentschev/miniconda3/envs/gdf/bin/python(+0xf7187) [0x557afe83e187]
22  /datasets/pentschev/miniconda3/envs/gdf/bin/python(+0x133747) [0x557afe87a747]
23  /datasets/pentschev/miniconda3/envs/gdf/bin/python(_PyEval_EvalFrameDefault+0x5f0a) [0x557afe8786ba]
24  /datasets/pentschev/miniconda3/envs/gdf/bin/python(+0x13cec3) [0x557afe883ec3]
25  /datasets/pentschev/miniconda3/envs/gdf/bin/python(_PyEval_EvalFrameDefault+0x672) [0x557afe872e22]
26  /datasets/pentschev/miniconda3/envs/gdf/bin/python(+0x13cec3) [0x557afe883ec3]
27  /datasets/pentschev/miniconda3/envs/gdf/bin/python(_PyEval_EvalFrameDefault+0x672) [0x557afe872e22]
28  /datasets/pentschev/miniconda3/envs/gdf/bin/python(+0x13cec3) [0x557afe883ec3]
29  /datasets/pentschev/miniconda3/envs/gdf/bin/python(_PyEval_EvalFrameDefault+0x672) [0x557afe872e22]
30  /datasets/pentschev/miniconda3/envs/gdf/bin/python(+0x13cec3) [0x557afe883ec3]
31  /datasets/pentschev/miniconda3/envs/gdf/bin/python(_PyEval_EvalFrameDefault+0x672) [0x557afe872e22]
32  /datasets/pentschev/miniconda3/envs/gdf/bin/python(+0x12a7d7) [0x557afe8717d7]
33  /datasets/pentschev/miniconda3/envs/gdf/bin/python(_PyFunction_Vectorcall+0xb9) [0x557afe883bb9]
34  /datasets/pentschev/miniconda3/envs/gdf/bin/python(_PyEval_EvalFrameDefault+0x4cbc) [0x557afe87746c]
35  /datasets/pentschev/miniconda3/envs/gdf/bin/python(+0x12a7d7) [0x557afe8717d7]
36  /datasets/pentschev/miniconda3/envs/gdf/bin/python(+0x14baf8) [0x557afe892af8]
37  /datasets/pentschev/miniconda3/envs/gdf/bin/python(PyObject_Call+0xb4) [0x557afe893254]
38  /datasets/pentschev/miniconda3/envs/gdf/bin/python(+0x21b8b8) [0x557afe9628b8]
39  /datasets/pentschev/miniconda3/envs/gdf/bin/python(_PyObject_MakeTpCall+0x347) [0x557afe87ba57]
40  /datasets/pentschev/miniconda3/envs/gdf/bin/python(_PyEval_EvalFrameDefault+0x3d99) [0x557afe876549]
41  /datasets/pentschev/miniconda3/envs/gdf/bin/python(+0x13cec3) [0x557afe883ec3]
42  /datasets/pentschev/miniconda3/envs/gdf/bin/python(+0x14bb91) [0x557afe892b91]
43  /datasets/pentschev/miniconda3/envs/gdf/bin/python(_PyEval_EvalFrameDefault+0x3d99) [0x557afe876549]
44  /datasets/pentschev/miniconda3/envs/gdf/bin/python(+0x13cec3) [0x557afe883ec3]
45  /datasets/pentschev/miniconda3/envs/gdf/bin/python(_PyEval_EvalFrameDefault+0x672) [0x557afe872e22]
46  /datasets/pentschev/miniconda3/envs/gdf/bin/python(+0x12a7d7) [0x557afe8717d7]
47  /datasets/pentschev/miniconda3/envs/gdf/bin/python(_PyFunction_Vectorcall+0xb9) [0x557afe883bb9]
48  /datasets/pentschev/miniconda3/envs/gdf/bin/python(_PyEval_EvalFrameDefault+0x672) [0x557afe872e22]
49  /datasets/pentschev/miniconda3/envs/gdf/bin/python(+0x13cec3) [0x557afe883ec3]
50  /datasets/pentschev/miniconda3/envs/gdf/bin/python(_PyEval_EvalFrameDefault+0x3c3) [0x557afe872b73]
51  /datasets/pentschev/miniconda3/envs/gdf/bin/python(+0x12a7d7) [0x557afe8717d7]
52  /datasets/pentschev/miniconda3/envs/gdf/bin/python(_PyFunction_Vectorcall+0xb9) [0x557afe883bb9]
53  /datasets/pentschev/miniconda3/envs/gdf/bin/python(_PyEval_EvalFrameDefault+0x11df) [0x557afe87398f]
54  /datasets/pentschev/miniconda3/envs/gdf/bin/python(+0x12a7d7) [0x557afe8717d7]
55  /datasets/pentschev/miniconda3/envs/gdf/bin/python(_PyEval_EvalCodeWithName+0x47) [0x557afe871497]
56  /datasets/pentschev/miniconda3/envs/gdf/bin/python(PyEval_EvalCodeEx+0x39) [0x557afe871449]
57  /datasets/pentschev/miniconda3/envs/gdf/bin/python(PyEval_EvalCode+0x1b) [0x557afe92bddb]
58  /datasets/pentschev/miniconda3/envs/gdf/bin/python(+0x213409) [0x557afe95a409]
59  /datasets/pentschev/miniconda3/envs/gdf/bin/python(+0x20f5a4) [0x557afe9565a4]
60  /datasets/pentschev/miniconda3/envs/gdf/bin/python(PyRun_StringFlags+0x9d) [0x557afe94e27d]
61  /datasets/pentschev/miniconda3/envs/gdf/bin/python(PyRun_SimpleStringFlags+0x3d) [0x557afe94e14d]
=================================
[dgx13:34726:0:34726] Caught signal 11 (Segmentation fault: address not mapped to object at address 0x448)
==== backtrace (tid:  34726) ====
 0  /datasets/pentschev/miniconda3/envs/gdf/lib/libucs.so.0(ucs_handle_error+0x2d4) [0x7f9c259b02c4]
 1  /datasets/pentschev/miniconda3/envs/gdf/lib/libucs.so.0(+0x2e49f) [0x7f9c259b049f]
 2  /datasets/pentschev/miniconda3/envs/gdf/lib/libucs.so.0(+0x2e7c4) [0x7f9c259b07c4]
 3  /lib/x86_64-linux-gnu/libpthread.so.0(+0x12980) [0x7f9c9b052980]
 4  /datasets/pentschev/miniconda3/envs/gdf/lib/libucp.so.0(ucp_mem_type_unpack+0x14) [0x7f9c25c353b4]
 5  /datasets/pentschev/miniconda3/envs/gdf/lib/libucp.so.0(ucp_rndv_data_handler+0x508) [0x7f9c25c65a08]
 6  /datasets/pentschev/miniconda3/envs/gdf/lib/libuct.so.0(+0x20b5f) [0x7f9c25764b5f]
 7  /datasets/pentschev/miniconda3/envs/gdf/lib/libuct.so.0(+0x21134) [0x7f9c25765134]
 8  /datasets/pentschev/miniconda3/envs/gdf/lib/libuct.so.0(+0x23578) [0x7f9c25767578]
 9  /datasets/pentschev/miniconda3/envs/gdf/lib/libucs.so.0(ucs_event_set_wait+0xb9) [0x7f9c259ba949]
10  /datasets/pentschev/miniconda3/envs/gdf/lib/libuct.so.0(uct_tcp_iface_progress+0x7b) [0x7f9c2576761b]
11  /datasets/pentschev/miniconda3/envs/gdf/lib/libucp.so.0(ucp_worker_progress+0x6a) [0x7f9c25c31caa]
12  /datasets/pentschev/miniconda3/envs/gdf/lib/python3.9/site-packages/ucp/_libs/ucx_api.cpython-39-x86_64-linux-gnu.so(+0x26c79) [0x7f9c25eebc79]
13  /datasets/pentschev/miniconda3/envs/gdf/bin/python(+0x141eca) [0x555a11d13eca]
14  /datasets/pentschev/miniconda3/envs/gdf/bin/python(_PyEval_EvalFrameDefault+0x3d99) [0x555a11d01549]
15  /datasets/pentschev/miniconda3/envs/gdf/bin/python(+0x12a7d7) [0x555a11cfc7d7]
16  /datasets/pentschev/miniconda3/envs/gdf/bin/python(_PyFunction_Vectorcall+0xb9) [0x555a11d0ebb9]
17  /datasets/pentschev/miniconda3/envs/gdf/bin/python(_PyEval_EvalFrameDefault+0x672) [0x555a11cfde22]
18  /datasets/pentschev/miniconda3/envs/gdf/bin/python(+0x13cec3) [0x555a11d0eec3]
19  /datasets/pentschev/miniconda3/envs/gdf/bin/python(+0x14bc75) [0x555a11d1dc75]
20  /datasets/pentschev/miniconda3/envs/gdf/bin/python(+0x264071) [0x555a11e36071]
21  /datasets/pentschev/miniconda3/envs/gdf/bin/python(+0xf7187) [0x555a11cc9187]
22  /datasets/pentschev/miniconda3/envs/gdf/bin/python(+0x133747) [0x555a11d05747]
23  /datasets/pentschev/miniconda3/envs/gdf/bin/python(_PyEval_EvalFrameDefault+0x5f0a) [0x555a11d036ba]
24  /datasets/pentschev/miniconda3/envs/gdf/bin/python(+0x13cec3) [0x555a11d0eec3]
25  /datasets/pentschev/miniconda3/envs/gdf/bin/python(_PyEval_EvalFrameDefault+0x672) [0x555a11cfde22]
26  /datasets/pentschev/miniconda3/envs/gdf/bin/python(+0x13cec3) [0x555a11d0eec3]
27  /datasets/pentschev/miniconda3/envs/gdf/bin/python(_PyEval_EvalFrameDefault+0x672) [0x555a11cfde22]
28  /datasets/pentschev/miniconda3/envs/gdf/bin/python(+0x13cec3) [0x555a11d0eec3]
29  /datasets/pentschev/miniconda3/envs/gdf/bin/python(_PyEval_EvalFrameDefault+0x672) [0x555a11cfde22]
30  /datasets/pentschev/miniconda3/envs/gdf/bin/python(+0x13cec3) [0x555a11d0eec3]
31  /datasets/pentschev/miniconda3/envs/gdf/bin/python(_PyEval_EvalFrameDefault+0x672) [0x555a11cfde22]
32  /datasets/pentschev/miniconda3/envs/gdf/bin/python(+0x12a7d7) [0x555a11cfc7d7]
33  /datasets/pentschev/miniconda3/envs/gdf/bin/python(_PyFunction_Vectorcall+0xb9) [0x555a11d0ebb9]
34  /datasets/pentschev/miniconda3/envs/gdf/bin/python(_PyEval_EvalFrameDefault+0x4cbc) [0x555a11d0246c]
35  /datasets/pentschev/miniconda3/envs/gdf/bin/python(+0x12a7d7) [0x555a11cfc7d7]
36  /datasets/pentschev/miniconda3/envs/gdf/bin/python(+0x14baf8) [0x555a11d1daf8]
37  /datasets/pentschev/miniconda3/envs/gdf/bin/python(PyObject_Call+0xb4) [0x555a11d1e254]
38  /datasets/pentschev/miniconda3/envs/gdf/bin/python(+0x21b8b8) [0x555a11ded8b8]
39  /datasets/pentschev/miniconda3/envs/gdf/bin/python(_PyObject_MakeTpCall+0x347) [0x555a11d06a57]
40  /datasets/pentschev/miniconda3/envs/gdf/bin/python(_PyEval_EvalFrameDefault+0x3d99) [0x555a11d01549]
41  /datasets/pentschev/miniconda3/envs/gdf/bin/python(+0x13cec3) [0x555a11d0eec3]
42  /datasets/pentschev/miniconda3/envs/gdf/bin/python(+0x14bb91) [0x555a11d1db91]
43  /datasets/pentschev/miniconda3/envs/gdf/bin/python(_PyEval_EvalFrameDefault+0x3d99) [0x555a11d01549]
44  /datasets/pentschev/miniconda3/envs/gdf/bin/python(+0x13cec3) [0x555a11d0eec3]
45  /datasets/pentschev/miniconda3/envs/gdf/bin/python(_PyEval_EvalFrameDefault+0x672) [0x555a11cfde22]
46  /datasets/pentschev/miniconda3/envs/gdf/bin/python(+0x12a7d7) [0x555a11cfc7d7]
47  /datasets/pentschev/miniconda3/envs/gdf/bin/python(_PyFunction_Vectorcall+0xb9) [0x555a11d0ebb9]
48  /datasets/pentschev/miniconda3/envs/gdf/bin/python(_PyEval_EvalFrameDefault+0x672) [0x555a11cfde22]
49  /datasets/pentschev/miniconda3/envs/gdf/bin/python(+0x13cec3) [0x555a11d0eec3]
50  /datasets/pentschev/miniconda3/envs/gdf/bin/python(_PyEval_EvalFrameDefault+0x3c3) [0x555a11cfdb73]
51  /datasets/pentschev/miniconda3/envs/gdf/bin/python(+0x12a7d7) [0x555a11cfc7d7]
52  /datasets/pentschev/miniconda3/envs/gdf/bin/python(_PyFunction_Vectorcall+0xb9) [0x555a11d0ebb9]
53  /datasets/pentschev/miniconda3/envs/gdf/bin/python(_PyEval_EvalFrameDefault+0x11df) [0x555a11cfe98f]
54  /datasets/pentschev/miniconda3/envs/gdf/bin/python(+0x12a7d7) [0x555a11cfc7d7]
55  /datasets/pentschev/miniconda3/envs/gdf/bin/python(_PyEval_EvalCodeWithName+0x47) [0x555a11cfc497]
56  /datasets/pentschev/miniconda3/envs/gdf/bin/python(PyEval_EvalCodeEx+0x39) [0x555a11cfc449]
57  /datasets/pentschev/miniconda3/envs/gdf/bin/python(PyEval_EvalCode+0x1b) [0x555a11db6ddb]
58  /datasets/pentschev/miniconda3/envs/gdf/bin/python(+0x213409) [0x555a11de5409]
59  /datasets/pentschev/miniconda3/envs/gdf/bin/python(+0x20f5a4) [0x555a11de15a4]
60  /datasets/pentschev/miniconda3/envs/gdf/bin/python(PyRun_StringFlags+0x9d) [0x555a11dd927d]
61  /datasets/pentschev/miniconda3/envs/gdf/bin/python(PyRun_SimpleStringFlags+0x3d) [0x555a11dd914d]
=================================
2023-01-29 00:01:03,341 - distributed.worker - ERROR - failed during get data with ucx://127.0.0.1:52717 -> ucx://127.0.0.1:55759
Traceback (most recent call last):
  File "/datasets/pentschev/miniconda3/envs/gdf/lib/python3.9/site-packages/distributed/comm/ucx.py", line 333, in write
    await self.ep.send(each_frame)
  File "/datasets/pentschev/miniconda3/envs/gdf/lib/python3.9/site-packages/ucp/core.py", line 650, in send
    return await comm.tag_send(self._ep, buffer, nbytes, tag, name=log)
ucp._libs.exceptions.UCXError: <[Send #007] ep: 0x7f6700faa2c0, tag: 0x6ff23456ed28d3ca, nbytes: 100000000, type: <class 'cudf.core.buffer.buffer.Buffer'>>: Connection reset by remote peer

During handling of the above exception, another exception occurred:

Traceback (most recent call last):
  File "/datasets/pentschev/miniconda3/envs/gdf/lib/python3.9/site-packages/distributed/worker.py", line 1766, in get_data
    compressed = await comm.write(msg, serializers=serializers)
  File "/datasets/pentschev/miniconda3/envs/gdf/lib/python3.9/site-packages/distributed/utils.py", line 741, in wrapper
    return await func(*args, **kwargs)
  File "/datasets/pentschev/miniconda3/envs/gdf/lib/python3.9/site-packages/distributed/comm/ucx.py", line 337, in write
    raise CommClosedError("While writing, the connection was closed")
distributed.comm.core.CommClosedError: While writing, the connection was closed
2023-01-29 00:01:03,342 - distributed.worker - ERROR - Worker stream died during communication: ucx://127.0.0.1:55759
Traceback (most recent call last):
  File "/datasets/pentschev/miniconda3/envs/gdf/lib/python3.9/site-packages/distributed/comm/ucx.py", line 349, in read
    await self.ep.recv(msg)
  File "/datasets/pentschev/miniconda3/envs/gdf/lib/python3.9/site-packages/ucp/core.py", line 725, in recv
    ret = await comm.tag_recv(self._ep, buffer, nbytes, tag, name=log)
ucp._libs.exceptions.UCXCanceled: <[Recv #003] ep: 0x7f6700faa140, tag: 0xbff1bb38b7d46974, nbytes: 16, type: <class 'numpy.ndarray'>>: 

During handling of the above exception, another exception occurred:

Traceback (most recent call last):
  File "/datasets/pentschev/miniconda3/envs/gdf/lib/python3.9/site-packages/distributed/worker.py", line 2058, in gather_dep
    response = await get_data_from_worker(
  File "/datasets/pentschev/miniconda3/envs/gdf/lib/python3.9/site-packages/distributed/worker.py", line 2872, in get_data_from_worker
    return await retry_operation(_get_data, operation="get_data_from_worker")
  File "/datasets/pentschev/miniconda3/envs/gdf/lib/python3.9/site-packages/distributed/utils_comm.py", line 419, in retry_operation
    return await retry(
  File "/datasets/pentschev/miniconda3/envs/gdf/lib/python3.9/site-packages/distributed/utils_comm.py", line 404, in retry
    return await coro()
  File "/datasets/pentschev/miniconda3/envs/gdf/lib/python3.9/site-packages/distributed/worker.py", line 2852, in _get_data
    response = await send_recv(
  File "/datasets/pentschev/miniconda3/envs/gdf/lib/python3.9/site-packages/distributed/core.py", line 986, in send_recv
    response = await comm.read(deserializers=deserializers)
  File "/datasets/pentschev/miniconda3/envs/gdf/lib/python3.9/site-packages/distributed/utils.py", line 741, in wrapper
    return await func(*args, **kwargs)
  File "/datasets/pentschev/miniconda3/envs/gdf/lib/python3.9/site-packages/distributed/comm/ucx.py", line 367, in read
    raise CommClosedError(
distributed.comm.core.CommClosedError: Connection closed by writer.
Inner exception: UCXCanceled("<[Recv #003] ep: 0x7f6700faa140, tag: 0xbff1bb38b7d46974, nbytes: 16, type: <class 'numpy.ndarray'>>: ")
2023-01-29 00:01:03,341 - distributed.worker - ERROR - Worker stream died during communication: ucx://127.0.0.1:55759
Traceback (most recent call last):
  File "/datasets/pentschev/miniconda3/envs/gdf/lib/python3.9/site-packages/distributed/comm/ucx.py", line 391, in read
    await self.ep.recv(each_frame)
  File "/datasets/pentschev/miniconda3/envs/gdf/lib/python3.9/site-packages/ucp/core.py", line 725, in recv
    ret = await comm.tag_recv(self._ep, buffer, nbytes, tag, name=log)
ucp._libs.exceptions.UCXCanceled: <[Recv #008] ep: 0x7f6820003200, tag: 0x276b0e4a1162aeec, nbytes: 100000000, type: <class 'rmm._lib.device_buffer.DeviceBuffer'>>: 

During handling of the above exception, another exception occurred:

Traceback (most recent call last):
  File "/datasets/pentschev/miniconda3/envs/gdf/lib/python3.9/site-packages/distributed/worker.py", line 2058, in gather_dep
    response = await get_data_from_worker(
  File "/datasets/pentschev/miniconda3/envs/gdf/lib/python3.9/site-packages/distributed/worker.py", line 2872, in get_data_from_worker
    return await retry_operation(_get_data, operation="get_data_from_worker")
  File "/datasets/pentschev/miniconda3/envs/gdf/lib/python3.9/site-packages/distributed/utils_comm.py", line 419, in retry_operation
    return await retry(
  File "/datasets/pentschev/miniconda3/envs/gdf/lib/python3.9/site-packages/distributed/utils_comm.py", line 404, in retry
    return await coro()
  File "/datasets/pentschev/miniconda3/envs/gdf/lib/python3.9/site-packages/distributed/worker.py", line 2852, in _get_data
    response = await send_recv(
  File "/datasets/pentschev/miniconda3/envs/gdf/lib/python3.9/site-packages/distributed/core.py", line 986, in send_recv
    response = await comm.read(deserializers=deserializers)
  File "/datasets/pentschev/miniconda3/envs/gdf/lib/python3.9/site-packages/distributed/utils.py", line 741, in wrapper
    return await func(*args, **kwargs)
  File "/datasets/pentschev/miniconda3/envs/gdf/lib/python3.9/site-packages/distributed/comm/ucx.py", line 397, in read
    raise CommClosedError(
distributed.comm.core.CommClosedError: Connection closed by writer.
Inner exception: UCXCanceled("<[Recv #008] ep: 0x7f6820003200, tag: 0x276b0e4a1162aeec, nbytes: 100000000, type: <class 'rmm._lib.device_buffer.DeviceBuffer'>>: ")
2023-01-29 00:01:03,368 - distributed.worker - ERROR - failed during get data with ucx://127.0.0.1:52717 -> ucx://127.0.0.1:58897
Traceback (most recent call last):
  File "/datasets/pentschev/miniconda3/envs/gdf/lib/python3.9/site-packages/distributed/comm/ucx.py", line 333, in write
    await self.ep.send(each_frame)
  File "/datasets/pentschev/miniconda3/envs/gdf/lib/python3.9/site-packages/ucp/core.py", line 650, in send
    return await comm.tag_send(self._ep, buffer, nbytes, tag, name=log)
ucp._libs.exceptions.UCXError: <[Send #007] ep: 0x7f6700faa300, tag: 0xdca4c2dbef7f6344, nbytes: 100000000, type: <class 'cudf.core.buffer.buffer.Buffer'>>: Connection reset by remote peer

During handling of the above exception, another exception occurred:

Traceback (most recent call last):
  File "/datasets/pentschev/miniconda3/envs/gdf/lib/python3.9/site-packages/distributed/worker.py", line 1766, in get_data
    compressed = await comm.write(msg, serializers=serializers)
  File "/datasets/pentschev/miniconda3/envs/gdf/lib/python3.9/site-packages/distributed/utils.py", line 741, in wrapper
    return await func(*args, **kwargs)
  File "/datasets/pentschev/miniconda3/envs/gdf/lib/python3.9/site-packages/distributed/comm/ucx.py", line 337, in write
    raise CommClosedError("While writing, the connection was closed")
distributed.comm.core.CommClosedError: While writing, the connection was closed
2023-01-29 00:01:03,369 - distributed.worker - ERROR - Worker stream died during communication: ucx://127.0.0.1:58897
Traceback (most recent call last):
  File "/datasets/pentschev/miniconda3/envs/gdf/lib/python3.9/site-packages/distributed/comm/ucx.py", line 391, in read
    await self.ep.recv(each_frame)
  File "/datasets/pentschev/miniconda3/envs/gdf/lib/python3.9/site-packages/ucp/core.py", line 725, in recv
    ret = await comm.tag_recv(self._ep, buffer, nbytes, tag, name=log)
ucp._libs.exceptions.UCXError: <[Recv #007] ep: 0x7f6700faa1c0, tag: 0x31bdc53977ad9e13, nbytes: 100000000, type: <class 'rmm._lib.device_buffer.DeviceBuffer'>>: Connection reset by remote peer

During handling of the above exception, another exception occurred:

Traceback (most recent call last):
  File "/datasets/pentschev/miniconda3/envs/gdf/lib/python3.9/site-packages/distributed/worker.py", line 2058, in gather_dep
    response = await get_data_from_worker(
  File "/datasets/pentschev/miniconda3/envs/gdf/lib/python3.9/site-packages/distributed/worker.py", line 2872, in get_data_from_worker
    return await retry_operation(_get_data, operation="get_data_from_worker")
  File "/datasets/pentschev/miniconda3/envs/gdf/lib/python3.9/site-packages/distributed/utils_comm.py", line 419, in retry_operation
    return await retry(
  File "/datasets/pentschev/miniconda3/envs/gdf/lib/python3.9/site-packages/distributed/utils_comm.py", line 404, in retry
    return await coro()
  File "/datasets/pentschev/miniconda3/envs/gdf/lib/python3.9/site-packages/distributed/worker.py", line 2852, in _get_data
    response = await send_recv(
  File "/datasets/pentschev/miniconda3/envs/gdf/lib/python3.9/site-packages/distributed/core.py", line 986, in send_recv
    response = await comm.read(deserializers=deserializers)
  File "/datasets/pentschev/miniconda3/envs/gdf/lib/python3.9/site-packages/distributed/utils.py", line 741, in wrapper
    return await func(*args, **kwargs)
  File "/datasets/pentschev/miniconda3/envs/gdf/lib/python3.9/site-packages/distributed/comm/ucx.py", line 397, in read
    raise CommClosedError(
distributed.comm.core.CommClosedError: Connection closed by writer.
Inner exception: UCXError("<[Recv #007] ep: 0x7f6700faa1c0, tag: 0x31bdc53977ad9e13, nbytes: 100000000, type: <class 'rmm._lib.device_buffer.DeviceBuffer'>>: Connection reset by remote peer")
2023-01-29 00:01:03,367 - distributed.worker - ERROR - Worker stream died during communication: ucx://127.0.0.1:55759
Traceback (most recent call last):
  File "/datasets/pentschev/miniconda3/envs/gdf/lib/python3.9/site-packages/distributed/comm/ucx.py", line 391, in read
    await self.ep.recv(each_frame)
  File "/datasets/pentschev/miniconda3/envs/gdf/lib/python3.9/site-packages/ucp/core.py", line 725, in recv
    ret = await comm.tag_recv(self._ep, buffer, nbytes, tag, name=log)
ucp._libs.exceptions.UCXCanceled: <[Recv #008] ep: 0x7f7194128180, tag: 0xb0fa48a40751fcf8, nbytes: 100000000, type: <class 'rmm._lib.device_buffer.DeviceBuffer'>>: 

During handling of the above exception, another exception occurred:

Traceback (most recent call last):
  File "/datasets/pentschev/miniconda3/envs/gdf/lib/python3.9/site-packages/distributed/worker.py", line 2058, in gather_dep
    response = await get_data_from_worker(
  File "/datasets/pentschev/miniconda3/envs/gdf/lib/python3.9/site-packages/distributed/worker.py", line 2872, in get_data_from_worker
    return await retry_operation(_get_data, operation="get_data_from_worker")
  File "/datasets/pentschev/miniconda3/envs/gdf/lib/python3.9/site-packages/distributed/utils_comm.py", line 419, in retry_operation
    return await retry(
  File "/datasets/pentschev/miniconda3/envs/gdf/lib/python3.9/site-packages/distributed/utils_comm.py", line 404, in retry
    return await coro()
  File "/datasets/pentschev/miniconda3/envs/gdf/lib/python3.9/site-packages/distributed/worker.py", line 2852, in _get_data
    response = await send_recv(
  File "/datasets/pentschev/miniconda3/envs/gdf/lib/python3.9/site-packages/distributed/core.py", line 986, in send_recv
    response = await comm.read(deserializers=deserializers)
  File "/datasets/pentschev/miniconda3/envs/gdf/lib/python3.9/site-packages/distributed/utils.py", line 741, in wrapper
    return await func(*args, **kwargs)
  File "/datasets/pentschev/miniconda3/envs/gdf/lib/python3.9/site-packages/distributed/comm/ucx.py", line 397, in read
    raise CommClosedError(
distributed.comm.core.CommClosedError: Connection closed by writer.
Inner exception: UCXCanceled("<[Recv #008] ep: 0x7f7194128180, tag: 0xb0fa48a40751fcf8, nbytes: 100000000, type: <class 'rmm._lib.device_buffer.DeviceBuffer'>>: ")
2023-01-29 00:01:03,407 - distributed.nanny - WARNING - Restarting worker
2023-01-29 00:01:03,488 - distributed.worker - ERROR - Worker stream died during communication: ucx://127.0.0.1:58481
Traceback (most recent call last):
  File "/datasets/pentschev/miniconda3/envs/gdf/lib/python3.9/site-packages/distributed/comm/ucx.py", line 391, in read
    await self.ep.recv(each_frame)
  File "/datasets/pentschev/miniconda3/envs/gdf/lib/python3.9/site-packages/ucp/core.py", line 725, in recv
    ret = await comm.tag_recv(self._ep, buffer, nbytes, tag, name=log)
ucp._libs.exceptions.UCXCanceled: <[Recv #017] ep: 0x7f6700faa180, tag: 0xdd2b34f9a14a581, nbytes: 100000000, type: <class 'rmm._lib.device_buffer.DeviceBuffer'>>: 

During handling of the above exception, another exception occurred:

Traceback (most recent call last):
  File "/datasets/pentschev/miniconda3/envs/gdf/lib/python3.9/site-packages/distributed/worker.py", line 2058, in gather_dep
    response = await get_data_from_worker(
  File "/datasets/pentschev/miniconda3/envs/gdf/lib/python3.9/site-packages/distributed/worker.py", line 2872, in get_data_from_worker
    return await retry_operation(_get_data, operation="get_data_from_worker")
  File "/datasets/pentschev/miniconda3/envs/gdf/lib/python3.9/site-packages/distributed/utils_comm.py", line 419, in retry_operation
    return await retry(
  File "/datasets/pentschev/miniconda3/envs/gdf/lib/python3.9/site-packages/distributed/utils_comm.py", line 404, in retry
    return await coro()
  File "/datasets/pentschev/miniconda3/envs/gdf/lib/python3.9/site-packages/distributed/worker.py", line 2852, in _get_data
    response = await send_recv(
  File "/datasets/pentschev/miniconda3/envs/gdf/lib/python3.9/site-packages/distributed/core.py", line 986, in send_recv
    response = await comm.read(deserializers=deserializers)
  File "/datasets/pentschev/miniconda3/envs/gdf/lib/python3.9/site-packages/distributed/utils.py", line 741, in wrapper
    return await func(*args, **kwargs)
  File "/datasets/pentschev/miniconda3/envs/gdf/lib/python3.9/site-packages/distributed/comm/ucx.py", line 397, in read
    raise CommClosedError(
distributed.comm.core.CommClosedError: Connection closed by writer.
Inner exception: UCXCanceled("<[Recv #017] ep: 0x7f6700faa180, tag: 0xdd2b34f9a14a581, nbytes: 100000000, type: <class 'rmm._lib.device_buffer.DeviceBuffer'>>: ")
Task exception was never retrieved
future: <Task finished name='Task-1086' coro=<_listener_handler_coroutine() done, defined at /datasets/pentschev/miniconda3/envs/gdf/lib/python3.9/site-packages/ucp/core.py:128> exception=UCXError('<stream_send>: Connection reset by remote peer')>
Traceback (most recent call last):
  File "/datasets/pentschev/miniconda3/envs/gdf/lib/python3.9/site-packages/ucp/core.py", line 143, in _listener_handler_coroutine
    peer_info = await exchange_peer_info(
  File "/datasets/pentschev/miniconda3/envs/gdf/lib/python3.9/site-packages/ucp/core.py", line 51, in exchange_peer_info
    await comm.stream_send(endpoint, my_info_arr, my_info_arr.nbytes)
ucp._libs.exceptions.UCXError: <stream_send>: Connection reset by remote peer
2023-01-29 00:01:03,498 - distributed.worker - ERROR - Worker stream died during communication: ucx://127.0.0.1:58481
Traceback (most recent call last):
  File "/datasets/pentschev/miniconda3/envs/gdf/lib/python3.9/site-packages/distributed/comm/ucx.py", line 391, in read
    await self.ep.recv(each_frame)
  File "/datasets/pentschev/miniconda3/envs/gdf/lib/python3.9/site-packages/ucp/core.py", line 725, in recv
    ret = await comm.tag_recv(self._ep, buffer, nbytes, tag, name=log)
ucp._libs.exceptions.UCXError: <[Recv #007] ep: 0x7f6820003240, tag: 0x53ecafeb197accd5, nbytes: 100000000, type: <class 'rmm._lib.device_buffer.DeviceBuffer'>>: Connection reset by remote peer

During handling of the above exception, another exception occurred:

Traceback (most recent call last):
  File "/datasets/pentschev/miniconda3/envs/gdf/lib/python3.9/site-packages/distributed/worker.py", line 2058, in gather_dep
    response = await get_data_from_worker(
  File "/datasets/pentschev/miniconda3/envs/gdf/lib/python3.9/site-packages/distributed/worker.py", line 2872, in get_data_from_worker
    return await retry_operation(_get_data, operation="get_data_from_worker")
  File "/datasets/pentschev/miniconda3/envs/gdf/lib/python3.9/site-packages/distributed/utils_comm.py", line 419, in retry_operation
    return await retry(
  File "/datasets/pentschev/miniconda3/envs/gdf/lib/python3.9/site-packages/distributed/utils_comm.py", line 404, in retry
    return await coro()
  File "/datasets/pentschev/miniconda3/envs/gdf/lib/python3.9/site-packages/distributed/worker.py", line 2852, in _get_data
    response = await send_recv(
  File "/datasets/pentschev/miniconda3/envs/gdf/lib/python3.9/site-packages/distributed/core.py", line 986, in send_recv
    response = await comm.read(deserializers=deserializers)
  File "/datasets/pentschev/miniconda3/envs/gdf/lib/python3.9/site-packages/distributed/utils.py", line 741, in wrapper
    return await func(*args, **kwargs)
  File "/datasets/pentschev/miniconda3/envs/gdf/lib/python3.9/site-packages/distributed/comm/ucx.py", line 397, in read
    raise CommClosedError(
distributed.comm.core.CommClosedError: Connection closed by writer.
Inner exception: UCXError("<[Recv #007] ep: 0x7f6820003240, tag: 0x53ecafeb197accd5, nbytes: 100000000, type: <class 'rmm._lib.device_buffer.DeviceBuffer'>>: Connection reset by remote peer")
2023-01-29 00:01:03,499 - distributed.worker - ERROR - failed during get data with ucx://127.0.0.1:37255 -> ucx://127.0.0.1:58481
Traceback (most recent call last):
  File "/datasets/pentschev/miniconda3/envs/gdf/lib/python3.9/site-packages/distributed/comm/ucx.py", line 333, in write
    await self.ep.send(each_frame)
  File "/datasets/pentschev/miniconda3/envs/gdf/lib/python3.9/site-packages/ucp/core.py", line 650, in send
    return await comm.tag_send(self._ep, buffer, nbytes, tag, name=log)
ucp._libs.exceptions.UCXError: <[Send #007] ep: 0x7f68200032c0, tag: 0x1edceb2864250141, nbytes: 100000000, type: <class 'cudf.core.buffer.buffer.Buffer'>>: Connection reset by remote peer

During handling of the above exception, another exception occurred:

Traceback (most recent call last):
  File "/datasets/pentschev/miniconda3/envs/gdf/lib/python3.9/site-packages/distributed/worker.py", line 1766, in get_data
    compressed = await comm.write(msg, serializers=serializers)
  File "/datasets/pentschev/miniconda3/envs/gdf/lib/python3.9/site-packages/distributed/utils.py", line 741, in wrapper
    return await func(*args, **kwargs)
  File "/datasets/pentschev/miniconda3/envs/gdf/lib/python3.9/site-packages/distributed/comm/ucx.py", line 337, in write
    raise CommClosedError("While writing, the connection was closed")
distributed.comm.core.CommClosedError: While writing, the connection was closed
2023-01-29 00:01:03,499 - distributed.worker - ERROR - Worker stream died during communication: ucx://127.0.0.1:58897
Traceback (most recent call last):
  File "/datasets/pentschev/miniconda3/envs/gdf/lib/python3.9/site-packages/distributed/comm/ucx.py", line 349, in read
    await self.ep.recv(msg)
  File "/datasets/pentschev/miniconda3/envs/gdf/lib/python3.9/site-packages/ucp/core.py", line 725, in recv
    ret = await comm.tag_recv(self._ep, buffer, nbytes, tag, name=log)
ucp._libs.exceptions.UCXCanceled: <[Recv #003] ep: 0x7f6820003180, tag: 0xe0a89d8234648311, nbytes: 16, type: <class 'numpy.ndarray'>>: 

During handling of the above exception, another exception occurred:

Traceback (most recent call last):
  File "/datasets/pentschev/miniconda3/envs/gdf/lib/python3.9/site-packages/distributed/worker.py", line 2058, in gather_dep
    response = await get_data_from_worker(
  File "/datasets/pentschev/miniconda3/envs/gdf/lib/python3.9/site-packages/distributed/worker.py", line 2872, in get_data_from_worker
    return await retry_operation(_get_data, operation="get_data_from_worker")
  File "/datasets/pentschev/miniconda3/envs/gdf/lib/python3.9/site-packages/distributed/utils_comm.py", line 419, in retry_operation
    return await retry(
  File "/datasets/pentschev/miniconda3/envs/gdf/lib/python3.9/site-packages/distributed/utils_comm.py", line 404, in retry
    return await coro()
  File "/datasets/pentschev/miniconda3/envs/gdf/lib/python3.9/site-packages/distributed/worker.py", line 2852, in _get_data
    response = await send_recv(
  File "/datasets/pentschev/miniconda3/envs/gdf/lib/python3.9/site-packages/distributed/core.py", line 986, in send_recv
    response = await comm.read(deserializers=deserializers)
  File "/datasets/pentschev/miniconda3/envs/gdf/lib/python3.9/site-packages/distributed/utils.py", line 741, in wrapper
    return await func(*args, **kwargs)
  File "/datasets/pentschev/miniconda3/envs/gdf/lib/python3.9/site-packages/distributed/comm/ucx.py", line 367, in read
    raise CommClosedError(
distributed.comm.core.CommClosedError: Connection closed by writer.
Inner exception: UCXCanceled("<[Recv #003] ep: 0x7f6820003180, tag: 0xe0a89d8234648311, nbytes: 16, type: <class 'numpy.ndarray'>>: ")
2023-01-29 00:01:03,514 - distributed.nanny - WARNING - Restarting worker
2023-01-29 00:01:03,560 - distributed.nanny - WARNING - Restarting worker
2023-01-29 00:01:03,633 - distributed.nanny - WARNING - Restarting worker
2023-01-29 00:01:03,642 - distributed.worker - ERROR - Worker stream died during communication: ucx://127.0.0.1:58897
Traceback (most recent call last):
  File "/datasets/pentschev/miniconda3/envs/gdf/lib/python3.9/site-packages/distributed/worker.py", line 2058, in gather_dep
    response = await get_data_from_worker(
  File "/datasets/pentschev/miniconda3/envs/gdf/lib/python3.9/site-packages/distributed/worker.py", line 2872, in get_data_from_worker
    return await retry_operation(_get_data, operation="get_data_from_worker")
  File "/datasets/pentschev/miniconda3/envs/gdf/lib/python3.9/site-packages/distributed/utils_comm.py", line 419, in retry_operation
    return await retry(
  File "/datasets/pentschev/miniconda3/envs/gdf/lib/python3.9/site-packages/distributed/utils_comm.py", line 404, in retry
    return await coro()
  File "/datasets/pentschev/miniconda3/envs/gdf/lib/python3.9/site-packages/distributed/worker.py", line 2852, in _get_data
    response = await send_recv(
  File "/datasets/pentschev/miniconda3/envs/gdf/lib/python3.9/site-packages/distributed/core.py", line 984, in send_recv
    await comm.write(msg, serializers=serializers, on_error="raise")
  File "/datasets/pentschev/miniconda3/envs/gdf/lib/python3.9/site-packages/distributed/utils.py", line 741, in wrapper
    return await func(*args, **kwargs)
  File "/datasets/pentschev/miniconda3/envs/gdf/lib/python3.9/site-packages/distributed/comm/ucx.py", line 289, in write
    raise CommClosedError("Endpoint is closed -- unable to send message")
distributed.comm.core.CommClosedError: Endpoint is closed -- unable to send message
Task exception was never retrieved
future: <Task finished name='Task-1063' coro=<_listener_handler_coroutine() done, defined at /datasets/pentschev/miniconda3/envs/gdf/lib/python3.9/site-packages/ucp/core.py:128> exception=UCXError('<stream_send>: Connection reset by remote peer')>
Traceback (most recent call last):
  File "/datasets/pentschev/miniconda3/envs/gdf/lib/python3.9/site-packages/ucp/core.py", line 143, in _listener_handler_coroutine
    peer_info = await exchange_peer_info(
  File "/datasets/pentschev/miniconda3/envs/gdf/lib/python3.9/site-packages/ucp/core.py", line 51, in exchange_peer_info
    await comm.stream_send(endpoint, my_info_arr, my_info_arr.nbytes)
ucp._libs.exceptions.UCXError: <stream_send>: Connection reset by remote peer
2023-01-29 00:01:03,643 - distributed.worker - ERROR - Worker stream died during communication: ucx://127.0.0.1:58481
Traceback (most recent call last):
  File "/datasets/pentschev/miniconda3/envs/gdf/lib/python3.9/site-packages/distributed/comm/ucx.py", line 391, in read
    await self.ep.recv(each_frame)
  File "/datasets/pentschev/miniconda3/envs/gdf/lib/python3.9/site-packages/ucp/core.py", line 725, in recv
    ret = await comm.tag_recv(self._ep, buffer, nbytes, tag, name=log)
ucp._libs.exceptions.UCXCanceled: <[Recv #009] ep: 0x7f71941281c0, tag: 0x38e2174a71a73e4c, nbytes: 100000000, type: <class 'rmm._lib.device_buffer.DeviceBuffer'>>: 

During handling of the above exception, another exception occurred:

Traceback (most recent call last):
  File "/datasets/pentschev/miniconda3/envs/gdf/lib/python3.9/site-packages/distributed/worker.py", line 2058, in gather_dep
    response = await get_data_from_worker(
  File "/datasets/pentschev/miniconda3/envs/gdf/lib/python3.9/site-packages/distributed/worker.py", line 2872, in get_data_from_worker
    return await retry_operation(_get_data, operation="get_data_from_worker")
  File "/datasets/pentschev/miniconda3/envs/gdf/lib/python3.9/site-packages/distributed/utils_comm.py", line 419, in retry_operation
    return await retry(
  File "/datasets/pentschev/miniconda3/envs/gdf/lib/python3.9/site-packages/distributed/utils_comm.py", line 404, in retry
    return await coro()
  File "/datasets/pentschev/miniconda3/envs/gdf/lib/python3.9/site-packages/distributed/worker.py", line 2852, in _get_data
    response = await send_recv(
  File "/datasets/pentschev/miniconda3/envs/gdf/lib/python3.9/site-packages/distributed/core.py", line 986, in send_recv
    response = await comm.read(deserializers=deserializers)
  File "/datasets/pentschev/miniconda3/envs/gdf/lib/python3.9/site-packages/distributed/utils.py", line 741, in wrapper
    return await func(*args, **kwargs)
  File "/datasets/pentschev/miniconda3/envs/gdf/lib/python3.9/site-packages/distributed/comm/ucx.py", line 397, in read
    raise CommClosedError(
distributed.comm.core.CommClosedError: Connection closed by writer.
Inner exception: UCXCanceled("<[Recv #009] ep: 0x7f71941281c0, tag: 0x38e2174a71a73e4c, nbytes: 100000000, type: <class 'rmm._lib.device_buffer.DeviceBuffer'>>: ")
terminate called after throwing an instance of 'rmm::out_of_memory'
  what():  std::bad_alloc: out_of_memory: RMM failure at:/datasets/pentschev/miniconda3/envs/gdf/include/rmm/mr/device/pool_memory_resource.hpp:193: Maximum pool size exceeded
2023-01-29 00:01:04,817 - distributed.preloading - INFO - Creating preload: dask_cuda.initialize
2023-01-29 00:01:04,818 - distributed.preloading - INFO - Import preload module: dask_cuda.initialize
2023-01-29 00:01:04,850 - distributed.worker - ERROR - Worker stream died during communication: ucx://127.0.0.1:52717
Traceback (most recent call last):
  File "/datasets/pentschev/miniconda3/envs/gdf/lib/python3.9/site-packages/distributed/comm/ucx.py", line 391, in read
    await self.ep.recv(each_frame)
  File "/datasets/pentschev/miniconda3/envs/gdf/lib/python3.9/site-packages/ucp/core.py", line 725, in recv
    ret = await comm.tag_recv(self._ep, buffer, nbytes, tag, name=log)
ucp._libs.exceptions.UCXCanceled: <[Recv #097] ep: 0x7f6820003140, tag: 0xf78e246419ba359e, nbytes: 100000000, type: <class 'rmm._lib.device_buffer.DeviceBuffer'>>: 

During handling of the above exception, another exception occurred:

Traceback (most recent call last):
  File "/datasets/pentschev/miniconda3/envs/gdf/lib/python3.9/site-packages/distributed/worker.py", line 2058, in gather_dep
    response = await get_data_from_worker(
  File "/datasets/pentschev/miniconda3/envs/gdf/lib/python3.9/site-packages/distributed/worker.py", line 2872, in get_data_from_worker
    return await retry_operation(_get_data, operation="get_data_from_worker")
  File "/datasets/pentschev/miniconda3/envs/gdf/lib/python3.9/site-packages/distributed/utils_comm.py", line 419, in retry_operation
    return await retry(
  File "/datasets/pentschev/miniconda3/envs/gdf/lib/python3.9/site-packages/distributed/utils_comm.py", line 404, in retry
    return await coro()
  File "/datasets/pentschev/miniconda3/envs/gdf/lib/python3.9/site-packages/distributed/worker.py", line 2852, in _get_data
    response = await send_recv(
  File "/datasets/pentschev/miniconda3/envs/gdf/lib/python3.9/site-packages/distributed/core.py", line 986, in send_recv
    response = await comm.read(deserializers=deserializers)
  File "/datasets/pentschev/miniconda3/envs/gdf/lib/python3.9/site-packages/distributed/utils.py", line 741, in wrapper
    return await func(*args, **kwargs)
  File "/datasets/pentschev/miniconda3/envs/gdf/lib/python3.9/site-packages/distributed/comm/ucx.py", line 397, in read
    raise CommClosedError(
distributed.comm.core.CommClosedError: Connection closed by writer.
Inner exception: UCXCanceled("<[Recv #097] ep: 0x7f6820003140, tag: 0xf78e246419ba359e, nbytes: 100000000, type: <class 'rmm._lib.device_buffer.DeviceBuffer'>>: ")
2023-01-29 00:01:04,850 - distributed.worker - ERROR - Worker stream died during communication: ucx://127.0.0.1:52717
Traceback (most recent call last):
  File "/datasets/pentschev/miniconda3/envs/gdf/lib/python3.9/site-packages/distributed/comm/ucx.py", line 391, in read
    await self.ep.recv(each_frame)
  File "/datasets/pentschev/miniconda3/envs/gdf/lib/python3.9/site-packages/ucp/core.py", line 725, in recv
    ret = await comm.tag_recv(self._ep, buffer, nbytes, tag, name=log)
ucp._libs.exceptions.UCXCanceled: <[Recv #058] ep: 0x7f7194128140, tag: 0x8549c3f0de923a53, nbytes: 50000000, type: <class 'rmm._lib.device_buffer.DeviceBuffer'>>: 

During handling of the above exception, another exception occurred:

Traceback (most recent call last):
  File "/datasets/pentschev/miniconda3/envs/gdf/lib/python3.9/site-packages/distributed/worker.py", line 2058, in gather_dep
    response = await get_data_from_worker(
  File "/datasets/pentschev/miniconda3/envs/gdf/lib/python3.9/site-packages/distributed/worker.py", line 2872, in get_data_from_worker
    return await retry_operation(_get_data, operation="get_data_from_worker")
  File "/datasets/pentschev/miniconda3/envs/gdf/lib/python3.9/site-packages/distributed/utils_comm.py", line 419, in retry_operation
    return await retry(
  File "/datasets/pentschev/miniconda3/envs/gdf/lib/python3.9/site-packages/distributed/utils_comm.py", line 404, in retry
    return await coro()
  File "/datasets/pentschev/miniconda3/envs/gdf/lib/python3.9/site-packages/distributed/worker.py", line 2852, in _get_data
    response = await send_recv(
  File "/datasets/pentschev/miniconda3/envs/gdf/lib/python3.9/site-packages/distributed/core.py", line 986, in send_recv
    response = await comm.read(deserializers=deserializers)
  File "/datasets/pentschev/miniconda3/envs/gdf/lib/python3.9/site-packages/distributed/utils.py", line 741, in wrapper
    return await func(*args, **kwargs)
  File "/datasets/pentschev/miniconda3/envs/gdf/lib/python3.9/site-packages/distributed/comm/ucx.py", line 397, in read
    raise CommClosedError(
distributed.comm.core.CommClosedError: Connection closed by writer.
Inner exception: UCXCanceled("<[Recv #058] ep: 0x7f7194128140, tag: 0x8549c3f0de923a53, nbytes: 50000000, type: <class 'rmm._lib.device_buffer.DeviceBuffer'>>: ")
2023-01-29 00:01:04,926 - distributed.nanny - WARNING - Restarting worker
2023-01-29 00:01:05,462 - distributed.preloading - INFO - Creating preload: dask_cuda.initialize
2023-01-29 00:01:05,463 - distributed.preloading - INFO - Import preload module: dask_cuda.initialize
2023-01-29 00:01:05,553 - distributed.preloading - INFO - Creating preload: dask_cuda.initialize
2023-01-29 00:01:05,553 - distributed.preloading - INFO - Import preload module: dask_cuda.initialize
2023-01-29 00:01:05,597 - distributed.preloading - INFO - Creating preload: dask_cuda.initialize
2023-01-29 00:01:05,597 - distributed.preloading - INFO - Import preload module: dask_cuda.initialize
2023-01-29 00:01:05,670 - distributed.preloading - INFO - Creating preload: dask_cuda.initialize
2023-01-29 00:01:05,670 - distributed.preloading - INFO - Import preload module: dask_cuda.initialize
2023-01-29 00:01:06,955 - distributed.preloading - INFO - Creating preload: dask_cuda.initialize
2023-01-29 00:01:06,956 - distributed.preloading - INFO - Import preload module: dask_cuda.initialize
[dgx13:35325:0:35325] Caught signal 11 (Segmentation fault: address not mapped to object at address 0x448)
==== backtrace (tid:  35325) ====
 0  /datasets/pentschev/miniconda3/envs/gdf/lib/libucs.so.0(ucs_handle_error+0x2d4) [0x7f93719fe2c4]
 1  /datasets/pentschev/miniconda3/envs/gdf/lib/libucs.so.0(+0x2e49f) [0x7f93719fe49f]
 2  /datasets/pentschev/miniconda3/envs/gdf/lib/libucs.so.0(+0x2e7c4) [0x7f93719fe7c4]
 3  /lib/x86_64-linux-gnu/libpthread.so.0(+0x12980) [0x7f93e6f12980]
 4  /datasets/pentschev/miniconda3/envs/gdf/lib/libucp.so.0(ucp_mem_type_unpack+0x14) [0x7f9371c833b4]
 5  /datasets/pentschev/miniconda3/envs/gdf/lib/libucp.so.0(ucp_rndv_data_handler+0x508) [0x7f9371cb3a08]
 6  /datasets/pentschev/miniconda3/envs/gdf/lib/libuct.so.0(+0x20b5f) [0x7f93717b2b5f]
 7  /datasets/pentschev/miniconda3/envs/gdf/lib/libuct.so.0(+0x21134) [0x7f93717b3134]
 8  /datasets/pentschev/miniconda3/envs/gdf/lib/libuct.so.0(+0x23578) [0x7f93717b5578]
 9  /datasets/pentschev/miniconda3/envs/gdf/lib/libucs.so.0(ucs_event_set_wait+0xb9) [0x7f9371a08949]
10  /datasets/pentschev/miniconda3/envs/gdf/lib/libuct.so.0(uct_tcp_iface_progress+0x7b) [0x7f93717b561b]
11  /datasets/pentschev/miniconda3/envs/gdf/lib/libucp.so.0(ucp_worker_progress+0x6a) [0x7f9371c7fcaa]
12  /datasets/pentschev/miniconda3/envs/gdf/lib/python3.9/site-packages/ucp/_libs/ucx_api.cpython-39-x86_64-linux-gnu.so(+0x26c79) [0x7f9371f39c79]
13  /datasets/pentschev/miniconda3/envs/gdf/bin/python(+0x141eca) [0x5627f7be9eca]
14  /datasets/pentschev/miniconda3/envs/gdf/bin/python(_PyEval_EvalFrameDefault+0x3d99) [0x5627f7bd7549]
15  /datasets/pentschev/miniconda3/envs/gdf/bin/python(+0x12a7d7) [0x5627f7bd27d7]
16  /datasets/pentschev/miniconda3/envs/gdf/bin/python(_PyFunction_Vectorcall+0xb9) [0x5627f7be4bb9]
17  /datasets/pentschev/miniconda3/envs/gdf/bin/python(_PyEval_EvalFrameDefault+0x672) [0x5627f7bd3e22]
18  /datasets/pentschev/miniconda3/envs/gdf/bin/python(+0x153244) [0x5627f7bfb244]
19  /datasets/pentschev/miniconda3/envs/gdf/lib/python3.9/lib-dynload/_asyncio.cpython-39-x86_64-linux-gnu.so(+0x8301) [0x7f938154c301]
20  /datasets/pentschev/miniconda3/envs/gdf/bin/python(_PyObject_MakeTpCall+0x347) [0x5627f7bdca57]
21  /datasets/pentschev/miniconda3/envs/gdf/bin/python(+0xf7187) [0x5627f7b9f187]
22  /datasets/pentschev/miniconda3/envs/gdf/bin/python(+0x133747) [0x5627f7bdb747]
23  /datasets/pentschev/miniconda3/envs/gdf/bin/python(_PyEval_EvalFrameDefault+0x5f0a) [0x5627f7bd96ba]
24  /datasets/pentschev/miniconda3/envs/gdf/bin/python(+0x13cec3) [0x5627f7be4ec3]
25  /datasets/pentschev/miniconda3/envs/gdf/bin/python(_PyEval_EvalFrameDefault+0x672) [0x5627f7bd3e22]
26  /datasets/pentschev/miniconda3/envs/gdf/bin/python(+0x13cec3) [0x5627f7be4ec3]
27  /datasets/pentschev/miniconda3/envs/gdf/bin/python(_PyEval_EvalFrameDefault+0x672) [0x5627f7bd3e22]
28  /datasets/pentschev/miniconda3/envs/gdf/bin/python(+0x13cec3) [0x5627f7be4ec3]
29  /datasets/pentschev/miniconda3/envs/gdf/bin/python(_PyEval_EvalFrameDefault+0x672) [0x5627f7bd3e22]
30  /datasets/pentschev/miniconda3/envs/gdf/bin/python(+0x13cec3) [0x5627f7be4ec3]
31  /datasets/pentschev/miniconda3/envs/gdf/bin/python(_PyEval_EvalFrameDefault+0x672) [0x5627f7bd3e22]
32  /datasets/pentschev/miniconda3/envs/gdf/bin/python(+0x12a7d7) [0x5627f7bd27d7]
33  /datasets/pentschev/miniconda3/envs/gdf/bin/python(_PyFunction_Vectorcall+0xb9) [0x5627f7be4bb9]
34  /datasets/pentschev/miniconda3/envs/gdf/bin/python(_PyEval_EvalFrameDefault+0x4cbc) [0x5627f7bd846c]
35  /datasets/pentschev/miniconda3/envs/gdf/bin/python(+0x12a7d7) [0x5627f7bd27d7]
36  /datasets/pentschev/miniconda3/envs/gdf/bin/python(+0x14baf8) [0x5627f7bf3af8]
37  /datasets/pentschev/miniconda3/envs/gdf/bin/python(PyObject_Call+0xb4) [0x5627f7bf4254]
38  /datasets/pentschev/miniconda3/envs/gdf/bin/python(+0x21b8b8) [0x5627f7cc38b8]
39  /datasets/pentschev/miniconda3/envs/gdf/bin/python(_PyObject_MakeTpCall+0x347) [0x5627f7bdca57]
40  /datasets/pentschev/miniconda3/envs/gdf/bin/python(_PyEval_EvalFrameDefault+0x3d99) [0x5627f7bd7549]
41  /datasets/pentschev/miniconda3/envs/gdf/bin/python(+0x13cec3) [0x5627f7be4ec3]
42  /datasets/pentschev/miniconda3/envs/gdf/bin/python(+0x14bb91) [0x5627f7bf3b91]
43  /datasets/pentschev/miniconda3/envs/gdf/bin/python(_PyEval_EvalFrameDefault+0x3d99) [0x5627f7bd7549]
44  /datasets/pentschev/miniconda3/envs/gdf/bin/python(+0x13cec3) [0x5627f7be4ec3]
45  /datasets/pentschev/miniconda3/envs/gdf/bin/python(_PyEval_EvalFrameDefault+0x672) [0x5627f7bd3e22]
46  /datasets/pentschev/miniconda3/envs/gdf/bin/python(+0x12a7d7) [0x5627f7bd27d7]
47  /datasets/pentschev/miniconda3/envs/gdf/bin/python(_PyFunction_Vectorcall+0xb9) [0x5627f7be4bb9]
48  /datasets/pentschev/miniconda3/envs/gdf/bin/python(_PyEval_EvalFrameDefault+0x672) [0x5627f7bd3e22]
49  /datasets/pentschev/miniconda3/envs/gdf/bin/python(+0x13cec3) [0x5627f7be4ec3]
50  /datasets/pentschev/miniconda3/envs/gdf/bin/python(_PyEval_EvalFrameDefault+0x3c3) [0x5627f7bd3b73]
51  /datasets/pentschev/miniconda3/envs/gdf/bin/python(+0x12a7d7) [0x5627f7bd27d7]
52  /datasets/pentschev/miniconda3/envs/gdf/bin/python(_PyFunction_Vectorcall+0xb9) [0x5627f7be4bb9]
53  /datasets/pentschev/miniconda3/envs/gdf/bin/python(_PyEval_EvalFrameDefault+0x11df) [0x5627f7bd498f]
54  /datasets/pentschev/miniconda3/envs/gdf/bin/python(+0x12a7d7) [0x5627f7bd27d7]
55  /datasets/pentschev/miniconda3/envs/gdf/bin/python(_PyEval_EvalCodeWithName+0x47) [0x5627f7bd2497]
56  /datasets/pentschev/miniconda3/envs/gdf/bin/python(PyEval_EvalCodeEx+0x39) [0x5627f7bd2449]
57  /datasets/pentschev/miniconda3/envs/gdf/bin/python(PyEval_EvalCode+0x1b) [0x5627f7c8cddb]
58  /datasets/pentschev/miniconda3/envs/gdf/bin/python(+0x213409) [0x5627f7cbb409]
59  /datasets/pentschev/miniconda3/envs/gdf/bin/python(+0x20f5a4) [0x5627f7cb75a4]
60  /datasets/pentschev/miniconda3/envs/gdf/bin/python(PyRun_StringFlags+0x9d) [0x5627f7caf27d]
61  /datasets/pentschev/miniconda3/envs/gdf/bin/python(PyRun_SimpleStringFlags+0x3d) [0x5627f7caf14d]
=================================
[dgx13:35302:0:35302] Caught signal 11 (Segmentation fault: address not mapped to object at address 0x448)
==== backtrace (tid:  35302) ====
 0  /datasets/pentschev/miniconda3/envs/gdf/lib/libucs.so.0(ucs_handle_error+0x2d4) [0x7effece582c4]
 1  /datasets/pentschev/miniconda3/envs/gdf/lib/libucs.so.0(+0x2e49f) [0x7effece5849f]
 2  /datasets/pentschev/miniconda3/envs/gdf/lib/libucs.so.0(+0x2e7c4) [0x7effece587c4]
 3  /lib/x86_64-linux-gnu/libpthread.so.0(+0x12980) [0x7f00623b1980]
 4  /datasets/pentschev/miniconda3/envs/gdf/lib/libucp.so.0(ucp_mem_type_unpack+0x14) [0x7effed0dd3b4]
 5  /datasets/pentschev/miniconda3/envs/gdf/lib/libucp.so.0(ucp_rndv_data_handler+0x508) [0x7effed10da08]
 6  /datasets/pentschev/miniconda3/envs/gdf/lib/libuct.so.0(+0x20b5f) [0x7effecc0cb5f]
 7  /datasets/pentschev/miniconda3/envs/gdf/lib/libuct.so.0(+0x21134) [0x7effecc0d134]
 8  /datasets/pentschev/miniconda3/envs/gdf/lib/libuct.so.0(+0x23578) [0x7effecc0f578]
 9  /datasets/pentschev/miniconda3/envs/gdf/lib/libucs.so.0(ucs_event_set_wait+0xb9) [0x7effece62949]
10  /datasets/pentschev/miniconda3/envs/gdf/lib/libuct.so.0(uct_tcp_iface_progress+0x7b) [0x7effecc0f61b]
11  /datasets/pentschev/miniconda3/envs/gdf/lib/libucp.so.0(ucp_worker_progress+0x6a) [0x7effed0d9caa]
12  /datasets/pentschev/miniconda3/envs/gdf/lib/python3.9/site-packages/ucp/_libs/ucx_api.cpython-39-x86_64-linux-gnu.so(+0x26c79) [0x7effed393c79]
13  /datasets/pentschev/miniconda3/envs/gdf/bin/python(+0x141eca) [0x55819c925eca]
14  /datasets/pentschev/miniconda3/envs/gdf/bin/python(_PyEval_EvalFrameDefault+0x3d99) [0x55819c913549]
15  /datasets/pentschev/miniconda3/envs/gdf/bin/python(+0x12a7d7) [0x55819c90e7d7]
16  /datasets/pentschev/miniconda3/envs/gdf/bin/python(_PyFunction_Vectorcall+0xb9) [0x55819c920bb9]
17  /datasets/pentschev/miniconda3/envs/gdf/bin/python(_PyEval_EvalFrameDefault+0x672) [0x55819c90fe22]
18  /datasets/pentschev/miniconda3/envs/gdf/bin/python(+0x153244) [0x55819c937244]
19  /datasets/pentschev/miniconda3/envs/gdf/lib/python3.9/lib-dynload/_asyncio.cpython-39-x86_64-linux-gnu.so(+0x8301) [0x7efffc9e9301]
20  /datasets/pentschev/miniconda3/envs/gdf/bin/python(_PyObject_MakeTpCall+0x347) [0x55819c918a57]
21  /datasets/pentschev/miniconda3/envs/gdf/bin/python(+0xf7187) [0x55819c8db187]
22  /datasets/pentschev/miniconda3/envs/gdf/bin/python(+0x133747) [0x55819c917747]
23  /datasets/pentschev/miniconda3/envs/gdf/bin/python(_PyEval_EvalFrameDefault+0x5f0a) [0x55819c9156ba]
24  /datasets/pentschev/miniconda3/envs/gdf/bin/python(+0x13cec3) [0x55819c920ec3]
25  /datasets/pentschev/miniconda3/envs/gdf/bin/python(_PyEval_EvalFrameDefault+0x672) [0x55819c90fe22]
26  /datasets/pentschev/miniconda3/envs/gdf/bin/python(+0x13cec3) [0x55819c920ec3]
27  /datasets/pentschev/miniconda3/envs/gdf/bin/python(_PyEval_EvalFrameDefault+0x672) [0x55819c90fe22]
28  /datasets/pentschev/miniconda3/envs/gdf/bin/python(+0x13cec3) [0x55819c920ec3]
29  /datasets/pentschev/miniconda3/envs/gdf/bin/python(_PyEval_EvalFrameDefault+0x672) [0x55819c90fe22]
30  /datasets/pentschev/miniconda3/envs/gdf/bin/python(+0x13cec3) [0x55819c920ec3]
31  /datasets/pentschev/miniconda3/envs/gdf/bin/python(_PyEval_EvalFrameDefault+0x672) [0x55819c90fe22]
32  /datasets/pentschev/miniconda3/envs/gdf/bin/python(+0x12a7d7) [0x55819c90e7d7]
33  /datasets/pentschev/miniconda3/envs/gdf/bin/python(_PyFunction_Vectorcall+0xb9) [0x55819c920bb9]
34  /datasets/pentschev/miniconda3/envs/gdf/bin/python(_PyEval_EvalFrameDefault+0x4cbc) [0x55819c91446c]
35  /datasets/pentschev/miniconda3/envs/gdf/bin/python(+0x12a7d7) [0x55819c90e7d7]
36  /datasets/pentschev/miniconda3/envs/gdf/bin/python(+0x14baf8) [0x55819c92faf8]
37  /datasets/pentschev/miniconda3/envs/gdf/bin/python(PyObject_Call+0xb4) [0x55819c930254]
38  /datasets/pentschev/miniconda3/envs/gdf/bin/python(+0x21b8b8) [0x55819c9ff8b8]
39  /datasets/pentschev/miniconda3/envs/gdf/bin/python(_PyObject_MakeTpCall+0x347) [0x55819c918a57]
40  /datasets/pentschev/miniconda3/envs/gdf/bin/python(_PyEval_EvalFrameDefault+0x3d99) [0x55819c913549]
41  /datasets/pentschev/miniconda3/envs/gdf/bin/python(+0x13cec3) [0x55819c920ec3]
42  /datasets/pentschev/miniconda3/envs/gdf/bin/python(+0x14bb91) [0x55819c92fb91]
43  /datasets/pentschev/miniconda3/envs/gdf/bin/python(_PyEval_EvalFrameDefault+0x3d99) [0x55819c913549]
44  /datasets/pentschev/miniconda3/envs/gdf/bin/python(+0x13cec3) [0x55819c920ec3]
45  /datasets/pentschev/miniconda3/envs/gdf/bin/python(_PyEval_EvalFrameDefault+0x672) [0x55819c90fe22]
46  /datasets/pentschev/miniconda3/envs/gdf/bin/python(+0x12a7d7) [0x55819c90e7d7]
47  /datasets/pentschev/miniconda3/envs/gdf/bin/python(_PyFunction_Vectorcall+0xb9) [0x55819c920bb9]
48  /datasets/pentschev/miniconda3/envs/gdf/bin/python(_PyEval_EvalFrameDefault+0x672) [0x55819c90fe22]
49  /datasets/pentschev/miniconda3/envs/gdf/bin/python(+0x13cec3) [0x55819c920ec3]
50  /datasets/pentschev/miniconda3/envs/gdf/bin/python(_PyEval_EvalFrameDefault+0x3c3) [0x55819c90fb73]
51  /datasets/pentschev/miniconda3/envs/gdf/bin/python(+0x12a7d7) [0x55819c90e7d7]
52  /datasets/pentschev/miniconda3/envs/gdf/bin/python(_PyFunction_Vectorcall+0xb9) [0x55819c920bb9]
53  /datasets/pentschev/miniconda3/envs/gdf/bin/python(_PyEval_EvalFrameDefault+0x11df) [0x55819c91098f]
54  /datasets/pentschev/miniconda3/envs/gdf/bin/python(+0x12a7d7) [0x55819c90e7d7]
55  /datasets/pentschev/miniconda3/envs/gdf/bin/python(_PyEval_EvalCodeWithName+0x47) [0x55819c90e497]
56  /datasets/pentschev/miniconda3/envs/gdf/bin/python(PyEval_EvalCodeEx+0x39) [0x55819c90e449]
57  /datasets/pentschev/miniconda3/envs/gdf/bin/python(PyEval_EvalCode+0x1b) [0x55819c9c8ddb]
58  /datasets/pentschev/miniconda3/envs/gdf/bin/python(+0x213409) [0x55819c9f7409]
59  /datasets/pentschev/miniconda3/envs/gdf/bin/python(+0x20f5a4) [0x55819c9f35a4]
60  /datasets/pentschev/miniconda3/envs/gdf/bin/python(PyRun_StringFlags+0x9d) [0x55819c9eb27d]
61  /datasets/pentschev/miniconda3/envs/gdf/bin/python(PyRun_SimpleStringFlags+0x3d) [0x55819c9eb14d]
=================================
2023-01-29 00:01:10,860 - distributed.worker - ERROR - failed during get data with ucx://127.0.0.1:37255 -> ucx://127.0.0.1:52973
Traceback (most recent call last):
  File "/datasets/pentschev/miniconda3/envs/gdf/lib/python3.9/site-packages/distributed/comm/ucx.py", line 333, in write
    await self.ep.send(each_frame)
  File "/datasets/pentschev/miniconda3/envs/gdf/lib/python3.9/site-packages/ucp/core.py", line 650, in send
    return await comm.tag_send(self._ep, buffer, nbytes, tag, name=log)
ucp._libs.exceptions.UCXError: <[Send #007] ep: 0x7f68200032c0, tag: 0x2fea5997d77521c3, nbytes: 100000000, type: <class 'cudf.core.buffer.buffer.Buffer'>>: Connection reset by remote peer

During handling of the above exception, another exception occurred:

Traceback (most recent call last):
  File "/datasets/pentschev/miniconda3/envs/gdf/lib/python3.9/site-packages/distributed/worker.py", line 1766, in get_data
    compressed = await comm.write(msg, serializers=serializers)
  File "/datasets/pentschev/miniconda3/envs/gdf/lib/python3.9/site-packages/distributed/utils.py", line 741, in wrapper
    return await func(*args, **kwargs)
  File "/datasets/pentschev/miniconda3/envs/gdf/lib/python3.9/site-packages/distributed/comm/ucx.py", line 337, in write
    raise CommClosedError("While writing, the connection was closed")
distributed.comm.core.CommClosedError: While writing, the connection was closed
2023-01-29 00:01:10,860 - distributed.worker - ERROR - failed during get data with ucx://127.0.0.1:56859 -> ucx://127.0.0.1:52973
Traceback (most recent call last):
  File "/datasets/pentschev/miniconda3/envs/gdf/lib/python3.9/site-packages/distributed/comm/ucx.py", line 333, in write
    await self.ep.send(each_frame)
  File "/datasets/pentschev/miniconda3/envs/gdf/lib/python3.9/site-packages/ucp/core.py", line 650, in send
    return await comm.tag_send(self._ep, buffer, nbytes, tag, name=log)
ucp._libs.exceptions.UCXError: <[Send #007] ep: 0x7f4158047200, tag: 0x1c93ab8c6f20dbb8, nbytes: 100000000, type: <class 'cudf.core.buffer.buffer.Buffer'>>: Connection reset by remote peer

During handling of the above exception, another exception occurred:

Traceback (most recent call last):
  File "/datasets/pentschev/miniconda3/envs/gdf/lib/python3.9/site-packages/distributed/worker.py", line 1766, in get_data
    compressed = await comm.write(msg, serializers=serializers)
  File "/datasets/pentschev/miniconda3/envs/gdf/lib/python3.9/site-packages/distributed/utils.py", line 741, in wrapper
    return await func(*args, **kwargs)
  File "/datasets/pentschev/miniconda3/envs/gdf/lib/python3.9/site-packages/distributed/comm/ucx.py", line 337, in write
    raise CommClosedError("While writing, the connection was closed")
distributed.comm.core.CommClosedError: While writing, the connection was closed
2023-01-29 00:01:10,875 - distributed.worker - ERROR - failed during get data with ucx://127.0.0.1:37255 -> ucx://127.0.0.1:53295
Traceback (most recent call last):
  File "/datasets/pentschev/miniconda3/envs/gdf/lib/python3.9/site-packages/distributed/comm/ucx.py", line 333, in write
    await self.ep.send(each_frame)
  File "/datasets/pentschev/miniconda3/envs/gdf/lib/python3.9/site-packages/ucp/core.py", line 650, in send
    return await comm.tag_send(self._ep, buffer, nbytes, tag, name=log)
ucp._libs.exceptions.UCXError: <[Send #007] ep: 0x7f6820003240, tag: 0x3bbbfd1be3448a96, nbytes: 100000000, type: <class 'cudf.core.buffer.buffer.Buffer'>>: Connection reset by remote peer

During handling of the above exception, another exception occurred:

Traceback (most recent call last):
  File "/datasets/pentschev/miniconda3/envs/gdf/lib/python3.9/site-packages/distributed/worker.py", line 1766, in get_data
    compressed = await comm.write(msg, serializers=serializers)
  File "/datasets/pentschev/miniconda3/envs/gdf/lib/python3.9/site-packages/distributed/utils.py", line 741, in wrapper
    return await func(*args, **kwargs)
  File "/datasets/pentschev/miniconda3/envs/gdf/lib/python3.9/site-packages/distributed/comm/ucx.py", line 337, in write
    raise CommClosedError("While writing, the connection was closed")
distributed.comm.core.CommClosedError: While writing, the connection was closed
2023-01-29 00:01:10,874 - distributed.worker - ERROR - failed during get data with ucx://127.0.0.1:48847 -> ucx://127.0.0.1:53295
Traceback (most recent call last):
  File "/datasets/pentschev/miniconda3/envs/gdf/lib/python3.9/site-packages/distributed/comm/ucx.py", line 349, in read
    await self.ep.recv(msg)
  File "/datasets/pentschev/miniconda3/envs/gdf/lib/python3.9/site-packages/ucp/core.py", line 725, in recv
    ret = await comm.tag_recv(self._ep, buffer, nbytes, tag, name=log)
ucp._libs.exceptions.UCXCanceled: <[Recv #006] ep: 0x7fb4e2648140, tag: 0xf104eac95516070c, nbytes: 16, type: <class 'numpy.ndarray'>>: 

During handling of the above exception, another exception occurred:

Traceback (most recent call last):
  File "/datasets/pentschev/miniconda3/envs/gdf/lib/python3.9/site-packages/distributed/worker.py", line 1767, in get_data
    response = await comm.read(deserializers=serializers)
  File "/datasets/pentschev/miniconda3/envs/gdf/lib/python3.9/site-packages/distributed/utils.py", line 741, in wrapper
    return await func(*args, **kwargs)
  File "/datasets/pentschev/miniconda3/envs/gdf/lib/python3.9/site-packages/distributed/comm/ucx.py", line 367, in read
    raise CommClosedError(
distributed.comm.core.CommClosedError: Connection closed by writer.
Inner exception: UCXCanceled("<[Recv #006] ep: 0x7fb4e2648140, tag: 0xf104eac95516070c, nbytes: 16, type: <class 'numpy.ndarray'>>: ")
2023-01-29 00:01:10,875 - distributed.worker - ERROR - failed during get data with ucx://127.0.0.1:45945 -> ucx://127.0.0.1:53295
Traceback (most recent call last):
  File "/datasets/pentschev/miniconda3/envs/gdf/lib/python3.9/site-packages/distributed/comm/ucx.py", line 349, in read
    await self.ep.recv(msg)
  File "/datasets/pentschev/miniconda3/envs/gdf/lib/python3.9/site-packages/ucp/core.py", line 725, in recv
    ret = await comm.tag_recv(self._ep, buffer, nbytes, tag, name=log)
ucp._libs.exceptions.UCXCanceled: <[Recv #006] ep: 0x7f19a4003140, tag: 0x1ab724ae6c34041d, nbytes: 16, type: <class 'numpy.ndarray'>>: 

During handling of the above exception, another exception occurred:

Traceback (most recent call last):
  File "/datasets/pentschev/miniconda3/envs/gdf/lib/python3.9/site-packages/distributed/worker.py", line 1767, in get_data
    response = await comm.read(deserializers=serializers)
  File "/datasets/pentschev/miniconda3/envs/gdf/lib/python3.9/site-packages/distributed/utils.py", line 741, in wrapper
    return await func(*args, **kwargs)
  File "/datasets/pentschev/miniconda3/envs/gdf/lib/python3.9/site-packages/distributed/comm/ucx.py", line 367, in read
    raise CommClosedError(
distributed.comm.core.CommClosedError: Connection closed by writer.
Inner exception: UCXCanceled("<[Recv #006] ep: 0x7f19a4003140, tag: 0x1ab724ae6c34041d, nbytes: 16, type: <class 'numpy.ndarray'>>: ")
2023-01-29 00:01:10,875 - distributed.worker - ERROR - failed during get data with ucx://127.0.0.1:59901 -> ucx://127.0.0.1:53295
Traceback (most recent call last):
  File "/datasets/pentschev/miniconda3/envs/gdf/lib/python3.9/site-packages/distributed/comm/ucx.py", line 333, in write
    await self.ep.send(each_frame)
  File "/datasets/pentschev/miniconda3/envs/gdf/lib/python3.9/site-packages/ucp/core.py", line 650, in send
    return await comm.tag_send(self._ep, buffer, nbytes, tag, name=log)
ucp._libs.exceptions.UCXError: <[Send #007] ep: 0x7f9d5c0151c0, tag: 0x4359fa675909c59d, nbytes: 100000000, type: <class 'cudf.core.buffer.buffer.Buffer'>>: Connection reset by remote peer

During handling of the above exception, another exception occurred:

Traceback (most recent call last):
  File "/datasets/pentschev/miniconda3/envs/gdf/lib/python3.9/site-packages/distributed/worker.py", line 1766, in get_data
    compressed = await comm.write(msg, serializers=serializers)
  File "/datasets/pentschev/miniconda3/envs/gdf/lib/python3.9/site-packages/distributed/utils.py", line 741, in wrapper
    return await func(*args, **kwargs)
  File "/datasets/pentschev/miniconda3/envs/gdf/lib/python3.9/site-packages/distributed/comm/ucx.py", line 337, in write
    raise CommClosedError("While writing, the connection was closed")
distributed.comm.core.CommClosedError: While writing, the connection was closed
2023-01-29 00:01:10,975 - distributed.nanny - WARNING - Restarting worker
2023-01-29 00:01:11,067 - distributed.nanny - WARNING - Restarting worker
Traceback (most recent call last):
  File "cupy/cuda/memory.pyx", line 742, in cupy.cuda.memory.alloc
  File "/datasets/pentschev/miniconda3/envs/gdf/lib/python3.9/site-packages/rmm/rmm.py", line 230, in rmm_cupy_allocator
    buf = librmm.device_buffer.DeviceBuffer(size=nbytes, stream=stream)
  File "device_buffer.pyx", line 85, in rmm._lib.device_buffer.DeviceBuffer.__cinit__
MemoryError: std::bad_alloc: out_of_memory: CUDA error at: /datasets/pentschev/miniconda3/envs/gdf/include/rmm/mr/device/cuda_memory_resource.hpp
Exception ignored in: 'cupy.cuda.thrust.cupy_malloc'
Traceback (most recent call last):
  File "cupy/cuda/memory.pyx", line 742, in cupy.cuda.memory.alloc
  File "/datasets/pentschev/miniconda3/envs/gdf/lib/python3.9/site-packages/rmm/rmm.py", line 230, in rmm_cupy_allocator
    buf = librmm.device_buffer.DeviceBuffer(size=nbytes, stream=stream)
  File "device_buffer.pyx", line 85, in rmm._lib.device_buffer.DeviceBuffer.__cinit__
MemoryError: std::bad_alloc: out_of_memory: CUDA error at: /datasets/pentschev/miniconda3/envs/gdf/include/rmm/mr/device/cuda_memory_resource.hpp
2023-01-29 00:01:11,197 - distributed.worker - WARNING - Compute Failed
Key:       ('generate-data-5366301a596b755bb8c33997d3ce7726', 2)
Function:  generate_chunk
args:      (2, 100000000, 8, 'build', 0.3, True)
kwargs:    {}
Exception: "RuntimeError('transform: failed to synchronize: cudaErrorIllegalAddress: an illegal memory access was encountered')"

2023-01-29 00:01:12,882 - distributed.preloading - INFO - Creating preload: dask_cuda.initialize
2023-01-29 00:01:12,883 - distributed.preloading - INFO - Import preload module: dask_cuda.initialize
2023-01-29 00:01:12,987 - distributed.preloading - INFO - Creating preload: dask_cuda.initialize
2023-01-29 00:01:12,987 - distributed.preloading - INFO - Import preload module: dask_cuda.initialize
/datasets/pentschev/miniconda3/envs/gdf/lib/python3.9/multiprocessing/resource_tracker.py:216: UserWarning: resource_tracker: There appear to be 48 leaked semaphore objects to clean up at shutdown
  warnings.warn('resource_tracker: There appear to be %d '
