2023-07-02 06:07:27,757 - distributed.preloading - INFO - Creating preload: dask_cuda.initialize
2023-07-02 06:07:27,757 - distributed.preloading - INFO - Import preload module: dask_cuda.initialize
2023-07-02 06:07:27,845 - distributed.preloading - INFO - Creating preload: dask_cuda.initialize
2023-07-02 06:07:27,845 - distributed.preloading - INFO - Import preload module: dask_cuda.initialize
2023-07-02 06:07:27,905 - distributed.preloading - INFO - Creating preload: dask_cuda.initialize
2023-07-02 06:07:27,905 - distributed.preloading - INFO - Import preload module: dask_cuda.initialize
2023-07-02 06:07:27,908 - distributed.preloading - INFO - Creating preload: dask_cuda.initialize
2023-07-02 06:07:27,908 - distributed.preloading - INFO - Import preload module: dask_cuda.initialize
2023-07-02 06:07:27,945 - distributed.preloading - INFO - Creating preload: dask_cuda.initialize
2023-07-02 06:07:27,945 - distributed.preloading - INFO - Import preload module: dask_cuda.initialize
2023-07-02 06:07:27,957 - distributed.preloading - INFO - Creating preload: dask_cuda.initialize
2023-07-02 06:07:27,957 - distributed.preloading - INFO - Import preload module: dask_cuda.initialize
2023-07-02 06:07:27,959 - distributed.preloading - INFO - Creating preload: dask_cuda.initialize
2023-07-02 06:07:27,959 - distributed.preloading - INFO - Import preload module: dask_cuda.initialize
2023-07-02 06:07:27,978 - distributed.preloading - INFO - Creating preload: dask_cuda.initialize
2023-07-02 06:07:27,978 - distributed.preloading - INFO - Import preload module: dask_cuda.initialize
[dgx13:72961:0:72961] Caught signal 11 (Segmentation fault: address not mapped to object at address 0x448)
==== backtrace (tid:  72961) ====
 0  /opt/conda/envs/gdf/lib/libucs.so.0(ucs_handle_error+0x2fd) [0x7f06a8788ced]
 1  /opt/conda/envs/gdf/lib/libucs.so.0(+0x2aee4) [0x7f06a8788ee4]
 2  /opt/conda/envs/gdf/lib/libucs.so.0(+0x2b0aa) [0x7f06a87890aa]
 3  /usr/lib/x86_64-linux-gnu/libpthread.so.0(+0x14420) [0x7f0747ebf420]
 4  /opt/conda/envs/gdf/lib/libucp.so.0(ucp_mem_type_unpack+0x14) [0x7f06a8807bb4]
 5  /opt/conda/envs/gdf/lib/libucp.so.0(ucp_rndv_data_handler+0x4e9) [0x7f06a882ee09]
 6  /opt/conda/envs/gdf/lib/libuct.so.0(+0x2045f) [0x7f06a874245f]
 7  /opt/conda/envs/gdf/lib/libuct.so.0(+0x238c8) [0x7f06a87458c8]
 8  /opt/conda/envs/gdf/lib/libucs.so.0(ucs_event_set_wait+0xb9) [0x7f06a8792399]
 9  /opt/conda/envs/gdf/lib/libuct.so.0(uct_tcp_iface_progress+0x7d) [0x7f06a874465d]
10  /opt/conda/envs/gdf/lib/libucp.so.0(ucp_worker_progress+0x5a) [0x7f06a8804daa]
11  /opt/conda/envs/gdf/lib/python3.9/site-packages/ucp/_libs/ucx_api.cpython-39-x86_64-linux-gnu.so(+0x2b17a) [0x7f06a88b617a]
12  /opt/conda/envs/gdf/bin/python(+0x13eb08) [0x564b06551b08]
13  /opt/conda/envs/gdf/bin/python(_PyEval_EvalFrameDefault+0x5f82) [0x564b06542112]
14  /opt/conda/envs/gdf/bin/python(+0x12827a) [0x564b0653b27a]
15  /opt/conda/envs/gdf/bin/python(_PyFunction_Vectorcall+0xd5) [0x564b0654cc05]
16  /opt/conda/envs/gdf/bin/python(_PyEval_EvalFrameDefault+0x68b) [0x564b0653c81b]
17  /opt/conda/envs/gdf/bin/python(+0x14e70e) [0x564b0656170e]
18  /opt/conda/envs/gdf/lib/python3.9/lib-dynload/_asyncio.cpython-39-x86_64-linux-gnu.so(+0x82fe) [0x7f06c8b672fe]
19  /opt/conda/envs/gdf/bin/python(_PyObject_MakeTpCall+0x2fc) [0x564b065452bc]
20  /opt/conda/envs/gdf/bin/python(+0xe5817) [0x564b064f8817]
21  /opt/conda/envs/gdf/bin/python(+0x130f83) [0x564b06543f83]
22  /opt/conda/envs/gdf/bin/python(_PyEval_EvalFrameDefault+0x5ba6) [0x564b06541d36]
23  /opt/conda/envs/gdf/bin/python(+0x139ef3) [0x564b0654cef3]
24  /opt/conda/envs/gdf/bin/python(_PyEval_EvalFrameDefault+0x68b) [0x564b0653c81b]
25  /opt/conda/envs/gdf/bin/python(+0x139ef3) [0x564b0654cef3]
26  /opt/conda/envs/gdf/bin/python(_PyEval_EvalFrameDefault+0x68b) [0x564b0653c81b]
27  /opt/conda/envs/gdf/bin/python(+0x139ef3) [0x564b0654cef3]
28  /opt/conda/envs/gdf/bin/python(_PyEval_EvalFrameDefault+0x68b) [0x564b0653c81b]
29  /opt/conda/envs/gdf/bin/python(+0x139ef3) [0x564b0654cef3]
30  /opt/conda/envs/gdf/bin/python(_PyEval_EvalFrameDefault+0x68b) [0x564b0653c81b]
31  /opt/conda/envs/gdf/bin/python(+0x12827a) [0x564b0653b27a]
32  /opt/conda/envs/gdf/bin/python(_PyFunction_Vectorcall+0xd5) [0x564b0654cc05]
33  /opt/conda/envs/gdf/bin/python(_PyEval_EvalFrameDefault+0x4e17) [0x564b06540fa7]
34  /opt/conda/envs/gdf/bin/python(+0x12827a) [0x564b0653b27a]
35  /opt/conda/envs/gdf/bin/python(+0x147935) [0x564b0655a935]
36  /opt/conda/envs/gdf/bin/python(PyObject_Call+0xb4) [0x564b0655b104]
37  /opt/conda/envs/gdf/bin/python(+0x20efc8) [0x564b06621fc8]
38  /opt/conda/envs/gdf/bin/python(_PyObject_MakeTpCall+0x2fc) [0x564b065452bc]
39  /opt/conda/envs/gdf/bin/python(_PyEval_EvalFrameDefault+0x402b) [0x564b065401bb]
40  /opt/conda/envs/gdf/bin/python(+0x139ef3) [0x564b0654cef3]
41  /opt/conda/envs/gdf/bin/python(+0x147c72) [0x564b0655ac72]
42  /opt/conda/envs/gdf/bin/python(_PyEval_EvalFrameDefault+0x402b) [0x564b065401bb]
43  /opt/conda/envs/gdf/bin/python(+0x139ef3) [0x564b0654cef3]
44  /opt/conda/envs/gdf/bin/python(_PyEval_EvalFrameDefault+0x68b) [0x564b0653c81b]
45  /opt/conda/envs/gdf/bin/python(+0x12827a) [0x564b0653b27a]
46  /opt/conda/envs/gdf/bin/python(_PyFunction_Vectorcall+0xd5) [0x564b0654cc05]
47  /opt/conda/envs/gdf/bin/python(_PyEval_EvalFrameDefault+0x68b) [0x564b0653c81b]
48  /opt/conda/envs/gdf/bin/python(+0x139ef3) [0x564b0654cef3]
49  /opt/conda/envs/gdf/bin/python(_PyEval_EvalFrameDefault+0x3d8) [0x564b0653c568]
50  /opt/conda/envs/gdf/bin/python(+0x12827a) [0x564b0653b27a]
51  /opt/conda/envs/gdf/bin/python(_PyFunction_Vectorcall+0xd5) [0x564b0654cc05]
52  /opt/conda/envs/gdf/bin/python(_PyEval_EvalFrameDefault+0x123b) [0x564b0653d3cb]
53  /opt/conda/envs/gdf/bin/python(+0x12827a) [0x564b0653b27a]
54  /opt/conda/envs/gdf/bin/python(_PyEval_EvalCodeWithName+0x47) [0x564b0653af07]
55  /opt/conda/envs/gdf/bin/python(PyEval_EvalCodeEx+0x39) [0x564b0653aeb9]
56  /opt/conda/envs/gdf/bin/python(PyEval_EvalCode+0x1b) [0x564b065eb8bb]
57  /opt/conda/envs/gdf/bin/python(+0x206adc) [0x564b06619adc]
58  /opt/conda/envs/gdf/bin/python(+0x202c24) [0x564b06615c24]
59  /opt/conda/envs/gdf/bin/python(PyRun_StringFlags+0x9d) [0x564b0660d7ed]
60  /opt/conda/envs/gdf/bin/python(PyRun_SimpleStringFlags+0x3d) [0x564b0660d6bd]
61  /opt/conda/envs/gdf/bin/python(Py_RunMain+0x262) [0x564b0660c8a2]
=================================
[dgx13:72945:0:72945] Caught signal 11 (Segmentation fault: address not mapped to object at address 0x448)
==== backtrace (tid:  72945) ====
 0  /opt/conda/envs/gdf/lib/libucs.so.0(ucs_handle_error+0x2fd) [0x7fcf509bdced]
 1  /opt/conda/envs/gdf/lib/libucs.so.0(+0x2aee4) [0x7fcf509bdee4]
 2  /opt/conda/envs/gdf/lib/libucs.so.0(+0x2b0aa) [0x7fcf509be0aa]
 3  /usr/lib/x86_64-linux-gnu/libpthread.so.0(+0x14420) [0x7fcff00ef420]
 4  /opt/conda/envs/gdf/lib/libucp.so.0(ucp_mem_type_unpack+0x14) [0x7fcf50a3cbb4]
 5  /opt/conda/envs/gdf/lib/libucp.so.0(ucp_rndv_data_handler+0x4e9) [0x7fcf50a63e09]
 6  /opt/conda/envs/gdf/lib/libuct.so.0(+0x2045f) [0x7fcf5097745f]
 7  /opt/conda/envs/gdf/lib/libuct.so.0(+0x238c8) [0x7fcf5097a8c8]
 8  /opt/conda/envs/gdf/lib/libucs.so.0(ucs_event_set_wait+0xb9) [0x7fcf509c7399]
 9  /opt/conda/envs/gdf/lib/libuct.so.0(uct_tcp_iface_progress+0x7d) [0x7fcf5097965d]
10  /opt/conda/envs/gdf/lib/libucp.so.0(ucp_worker_progress+0x5a) [0x7fcf50a39daa]
11  /opt/conda/envs/gdf/lib/python3.9/site-packages/ucp/_libs/ucx_api.cpython-39-x86_64-linux-gnu.so(+0x2b17a) [0x7fcf50aeb17a]
12  /opt/conda/envs/gdf/bin/python(+0x13eb08) [0x556ae8a5db08]
13  /opt/conda/envs/gdf/bin/python(_PyEval_EvalFrameDefault+0x5f82) [0x556ae8a4e112]
14  /opt/conda/envs/gdf/bin/python(+0x12827a) [0x556ae8a4727a]
15  /opt/conda/envs/gdf/bin/python(_PyFunction_Vectorcall+0xd5) [0x556ae8a58c05]
16  /opt/conda/envs/gdf/bin/python(_PyEval_EvalFrameDefault+0x68b) [0x556ae8a4881b]
17  /opt/conda/envs/gdf/bin/python(+0x14e70e) [0x556ae8a6d70e]
18  /opt/conda/envs/gdf/lib/python3.9/lib-dynload/_asyncio.cpython-39-x86_64-linux-gnu.so(+0x82fe) [0x7fcf70d982fe]
19  /opt/conda/envs/gdf/bin/python(_PyObject_MakeTpCall+0x2fc) [0x556ae8a512bc]
20  /opt/conda/envs/gdf/bin/python(+0xe5817) [0x556ae8a04817]
21  /opt/conda/envs/gdf/bin/python(+0x130f83) [0x556ae8a4ff83]
22  /opt/conda/envs/gdf/bin/python(_PyEval_EvalFrameDefault+0x5ba6) [0x556ae8a4dd36]
23  /opt/conda/envs/gdf/bin/python(+0x139ef3) [0x556ae8a58ef3]
24  /opt/conda/envs/gdf/bin/python(_PyEval_EvalFrameDefault+0x68b) [0x556ae8a4881b]
25  /opt/conda/envs/gdf/bin/python(+0x139ef3) [0x556ae8a58ef3]
26  /opt/conda/envs/gdf/bin/python(_PyEval_EvalFrameDefault+0x68b) [0x556ae8a4881b]
27  /opt/conda/envs/gdf/bin/python(+0x139ef3) [0x556ae8a58ef3]
28  /opt/conda/envs/gdf/bin/python(_PyEval_EvalFrameDefault+0x68b) [0x556ae8a4881b]
29  /opt/conda/envs/gdf/bin/python(+0x139ef3) [0x556ae8a58ef3]
30  /opt/conda/envs/gdf/bin/python(_PyEval_EvalFrameDefault+0x68b) [0x556ae8a4881b]
31  /opt/conda/envs/gdf/bin/python(+0x12827a) [0x556ae8a4727a]
32  /opt/conda/envs/gdf/bin/python(_PyFunction_Vectorcall+0xd5) [0x556ae8a58c05]
33  /opt/conda/envs/gdf/bin/python(_PyEval_EvalFrameDefault+0x4e17) [0x556ae8a4cfa7]
34  /opt/conda/envs/gdf/bin/python(+0x12827a) [0x556ae8a4727a]
35  /opt/conda/envs/gdf/bin/python(+0x147935) [0x556ae8a66935]
36  /opt/conda/envs/gdf/bin/python(PyObject_Call+0xb4) [0x556ae8a67104]
37  /opt/conda/envs/gdf/bin/python(+0x20efc8) [0x556ae8b2dfc8]
38  /opt/conda/envs/gdf/bin/python(_PyObject_MakeTpCall+0x2fc) [0x556ae8a512bc]
39  /opt/conda/envs/gdf/bin/python(_PyEval_EvalFrameDefault+0x402b) [0x556ae8a4c1bb]
40  /opt/conda/envs/gdf/bin/python(+0x139ef3) [0x556ae8a58ef3]
41  /opt/conda/envs/gdf/bin/python(+0x147c72) [0x556ae8a66c72]
42  /opt/conda/envs/gdf/bin/python(_PyEval_EvalFrameDefault+0x402b) [0x556ae8a4c1bb]
43  /opt/conda/envs/gdf/bin/python(+0x139ef3) [0x556ae8a58ef3]
44  /opt/conda/envs/gdf/bin/python(_PyEval_EvalFrameDefault+0x68b) [0x556ae8a4881b]
45  /opt/conda/envs/gdf/bin/python(+0x12827a) [0x556ae8a4727a]
46  /opt/conda/envs/gdf/bin/python(_PyFunction_Vectorcall+0xd5) [0x556ae8a58c05]
47  /opt/conda/envs/gdf/bin/python(_PyEval_EvalFrameDefault+0x68b) [0x556ae8a4881b]
48  /opt/conda/envs/gdf/bin/python(+0x139ef3) [0x556ae8a58ef3]
49  /opt/conda/envs/gdf/bin/python(_PyEval_EvalFrameDefault+0x3d8) [0x556ae8a48568]
50  /opt/conda/envs/gdf/bin/python(+0x12827a) [0x556ae8a4727a]
51  /opt/conda/envs/gdf/bin/python(_PyFunction_Vectorcall+0xd5) [0x556ae8a58c05]
52  /opt/conda/envs/gdf/bin/python(_PyEval_EvalFrameDefault+0x123b) [0x556ae8a493cb]
53  /opt/conda/envs/gdf/bin/python(+0x12827a) [0x556ae8a4727a]
54  /opt/conda/envs/gdf/bin/python(_PyEval_EvalCodeWithName+0x47) [0x556ae8a46f07]
55  /opt/conda/envs/gdf/bin/python(PyEval_EvalCodeEx+0x39) [0x556ae8a46eb9]
56  /opt/conda/envs/gdf/bin/python(PyEval_EvalCode+0x1b) [0x556ae8af78bb]
57  /opt/conda/envs/gdf/bin/python(+0x206adc) [0x556ae8b25adc]
58  /opt/conda/envs/gdf/bin/python(+0x202c24) [0x556ae8b21c24]
59  /opt/conda/envs/gdf/bin/python(PyRun_StringFlags+0x9d) [0x556ae8b197ed]
60  /opt/conda/envs/gdf/bin/python(PyRun_SimpleStringFlags+0x3d) [0x556ae8b196bd]
61  /opt/conda/envs/gdf/bin/python(Py_RunMain+0x262) [0x556ae8b188a2]
=================================
2023-07-02 06:07:36,861 - distributed.worker - ERROR - Worker stream died during communication: ucx://127.0.0.1:34181
Traceback (most recent call last):
  File "/opt/conda/envs/gdf/lib/python3.9/site-packages/distributed/comm/ucx.py", line 349, in read
    await self.ep.recv(msg)
  File "/opt/conda/envs/gdf/lib/python3.9/site-packages/ucp/core.py", line 725, in recv
    ret = await comm.tag_recv(self._ep, buffer, nbytes, tag, name=log)
ucp._libs.exceptions.UCXCanceled: <[Recv #003] ep: 0x7f45b1f3c1c0, tag: 0xb2d2ef8462cf6d37, nbytes: 16, type: <class 'numpy.ndarray'>>: 

During handling of the above exception, another exception occurred:

Traceback (most recent call last):
  File "/opt/conda/envs/gdf/lib/python3.9/site-packages/distributed/worker.py", line 2066, in gather_dep
    response = await get_data_from_worker(
  File "/opt/conda/envs/gdf/lib/python3.9/site-packages/distributed/worker.py", line 2892, in get_data_from_worker
    response = await send_recv(
  File "/opt/conda/envs/gdf/lib/python3.9/site-packages/distributed/core.py", line 1024, in send_recv
    response = await comm.read(deserializers=deserializers)
  File "/opt/conda/envs/gdf/lib/python3.9/site-packages/distributed/utils.py", line 752, in wrapper
    return await func(*args, **kwargs)
  File "/opt/conda/envs/gdf/lib/python3.9/site-packages/distributed/comm/ucx.py", line 367, in read
    raise CommClosedError(
distributed.comm.core.CommClosedError: Connection closed by writer.
Inner exception: UCXCanceled("<[Recv #003] ep: 0x7f45b1f3c1c0, tag: 0xb2d2ef8462cf6d37, nbytes: 16, type: <class 'numpy.ndarray'>>: ")
2023-07-02 06:07:36,861 - distributed.worker - ERROR - Worker stream died during communication: ucx://127.0.0.1:34181
Traceback (most recent call last):
  File "/opt/conda/envs/gdf/lib/python3.9/site-packages/distributed/comm/ucx.py", line 349, in read
    await self.ep.recv(msg)
  File "/opt/conda/envs/gdf/lib/python3.9/site-packages/ucp/core.py", line 725, in recv
    ret = await comm.tag_recv(self._ep, buffer, nbytes, tag, name=log)
ucp._libs.exceptions.UCXCanceled: <[Recv #003] ep: 0x7f99f70e8200, tag: 0xbca4d1fd2477f4eb, nbytes: 16, type: <class 'numpy.ndarray'>>: 

During handling of the above exception, another exception occurred:

Traceback (most recent call last):
  File "/opt/conda/envs/gdf/lib/python3.9/site-packages/distributed/worker.py", line 2066, in gather_dep
    response = await get_data_from_worker(
  File "/opt/conda/envs/gdf/lib/python3.9/site-packages/distributed/worker.py", line 2892, in get_data_from_worker
    response = await send_recv(
  File "/opt/conda/envs/gdf/lib/python3.9/site-packages/distributed/core.py", line 1024, in send_recv
    response = await comm.read(deserializers=deserializers)
  File "/opt/conda/envs/gdf/lib/python3.9/site-packages/distributed/utils.py", line 752, in wrapper
    return await func(*args, **kwargs)
  File "/opt/conda/envs/gdf/lib/python3.9/site-packages/distributed/comm/ucx.py", line 367, in read
    raise CommClosedError(
distributed.comm.core.CommClosedError: Connection closed by writer.
Inner exception: UCXCanceled("<[Recv #003] ep: 0x7f99f70e8200, tag: 0xbca4d1fd2477f4eb, nbytes: 16, type: <class 'numpy.ndarray'>>: ")
2023-07-02 06:07:36,861 - distributed.worker - ERROR - Worker stream died during communication: ucx://127.0.0.1:34181
Traceback (most recent call last):
  File "/opt/conda/envs/gdf/lib/python3.9/site-packages/distributed/comm/ucx.py", line 349, in read
    await self.ep.recv(msg)
  File "/opt/conda/envs/gdf/lib/python3.9/site-packages/ucp/core.py", line 725, in recv
    ret = await comm.tag_recv(self._ep, buffer, nbytes, tag, name=log)
ucp._libs.exceptions.UCXCanceled: <[Recv #003] ep: 0x7f7a735e7240, tag: 0x86681faec3794e70, nbytes: 16, type: <class 'numpy.ndarray'>>: 

During handling of the above exception, another exception occurred:

Traceback (most recent call last):
  File "/opt/conda/envs/gdf/lib/python3.9/site-packages/distributed/worker.py", line 2066, in gather_dep
    response = await get_data_from_worker(
  File "/opt/conda/envs/gdf/lib/python3.9/site-packages/distributed/worker.py", line 2892, in get_data_from_worker
    response = await send_recv(
  File "/opt/conda/envs/gdf/lib/python3.9/site-packages/distributed/core.py", line 1024, in send_recv
    response = await comm.read(deserializers=deserializers)
  File "/opt/conda/envs/gdf/lib/python3.9/site-packages/distributed/utils.py", line 752, in wrapper
    return await func(*args, **kwargs)
  File "/opt/conda/envs/gdf/lib/python3.9/site-packages/distributed/comm/ucx.py", line 367, in read
    raise CommClosedError(
distributed.comm.core.CommClosedError: Connection closed by writer.
Inner exception: UCXCanceled("<[Recv #003] ep: 0x7f7a735e7240, tag: 0x86681faec3794e70, nbytes: 16, type: <class 'numpy.ndarray'>>: ")
2023-07-02 06:07:36,863 - distributed.worker - ERROR - failed during get data with ucx://127.0.0.1:34105 -> ucx://127.0.0.1:53259
Traceback (most recent call last):
  File "/opt/conda/envs/gdf/lib/python3.9/site-packages/distributed/comm/ucx.py", line 333, in write
    await self.ep.send(each_frame)
  File "/opt/conda/envs/gdf/lib/python3.9/site-packages/ucp/core.py", line 650, in send
    return await comm.tag_send(self._ep, buffer, nbytes, tag, name=log)
ucp._libs.exceptions.UCXError: <[Send #007] ep: 0x7f45b1f3c3c0, tag: 0xec7847b7299264d6, nbytes: 100000000, type: <class 'cudf.core.buffer.buffer.Buffer'>>: Connection reset by remote peer

During handling of the above exception, another exception occurred:

Traceback (most recent call last):
  File "/opt/conda/envs/gdf/lib/python3.9/site-packages/distributed/worker.py", line 1792, in get_data
    compressed = await comm.write(msg, serializers=serializers)
  File "/opt/conda/envs/gdf/lib/python3.9/site-packages/distributed/utils.py", line 752, in wrapper
    return await func(*args, **kwargs)
  File "/opt/conda/envs/gdf/lib/python3.9/site-packages/distributed/comm/ucx.py", line 337, in write
    raise CommClosedError("While writing, the connection was closed")
distributed.comm.core.CommClosedError: While writing, the connection was closed
2023-07-02 06:07:36,864 - distributed.worker - ERROR - failed during get data with ucx://127.0.0.1:59701 -> ucx://127.0.0.1:53259
Traceback (most recent call last):
  File "/opt/conda/envs/gdf/lib/python3.9/site-packages/distributed/comm/ucx.py", line 333, in write
    await self.ep.send(each_frame)
  File "/opt/conda/envs/gdf/lib/python3.9/site-packages/ucp/core.py", line 650, in send
    return await comm.tag_send(self._ep, buffer, nbytes, tag, name=log)
ucp._libs.exceptions.UCXError: <[Send #007] ep: 0x7f99f70e8300, tag: 0x15ee8497c73cfc3e, nbytes: 100000000, type: <class 'cudf.core.buffer.buffer.Buffer'>>: Connection reset by remote peer

During handling of the above exception, another exception occurred:

Traceback (most recent call last):
  File "/opt/conda/envs/gdf/lib/python3.9/site-packages/distributed/worker.py", line 1792, in get_data
    compressed = await comm.write(msg, serializers=serializers)
  File "/opt/conda/envs/gdf/lib/python3.9/site-packages/distributed/utils.py", line 752, in wrapper
    return await func(*args, **kwargs)
  File "/opt/conda/envs/gdf/lib/python3.9/site-packages/distributed/comm/ucx.py", line 337, in write
    raise CommClosedError("While writing, the connection was closed")
distributed.comm.core.CommClosedError: While writing, the connection was closed
2023-07-02 06:07:36,864 - distributed.worker - ERROR - Worker stream died during communication: ucx://127.0.0.1:53259
Traceback (most recent call last):
  File "/opt/conda/envs/gdf/lib/python3.9/site-packages/distributed/comm/ucx.py", line 349, in read
    await self.ep.recv(msg)
  File "/opt/conda/envs/gdf/lib/python3.9/site-packages/ucp/core.py", line 725, in recv
    ret = await comm.tag_recv(self._ep, buffer, nbytes, tag, name=log)
ucp._libs.exceptions.UCXCanceled: <[Recv #003] ep: 0x7f45b1f3c100, tag: 0x85db01ec3a3ae2c7, nbytes: 16, type: <class 'numpy.ndarray'>>: 

During handling of the above exception, another exception occurred:

Traceback (most recent call last):
  File "/opt/conda/envs/gdf/lib/python3.9/site-packages/distributed/worker.py", line 2066, in gather_dep
    response = await get_data_from_worker(
  File "/opt/conda/envs/gdf/lib/python3.9/site-packages/distributed/worker.py", line 2892, in get_data_from_worker
    response = await send_recv(
  File "/opt/conda/envs/gdf/lib/python3.9/site-packages/distributed/core.py", line 1024, in send_recv
    response = await comm.read(deserializers=deserializers)
  File "/opt/conda/envs/gdf/lib/python3.9/site-packages/distributed/utils.py", line 752, in wrapper
    return await func(*args, **kwargs)
  File "/opt/conda/envs/gdf/lib/python3.9/site-packages/distributed/comm/ucx.py", line 367, in read
    raise CommClosedError(
distributed.comm.core.CommClosedError: Connection closed by writer.
Inner exception: UCXCanceled("<[Recv #003] ep: 0x7f45b1f3c100, tag: 0x85db01ec3a3ae2c7, nbytes: 16, type: <class 'numpy.ndarray'>>: ")
2023-07-02 06:07:36,864 - distributed.worker - ERROR - Worker stream died during communication: ucx://127.0.0.1:53259
Traceback (most recent call last):
  File "/opt/conda/envs/gdf/lib/python3.9/site-packages/distributed/comm/ucx.py", line 349, in read
    await self.ep.recv(msg)
  File "/opt/conda/envs/gdf/lib/python3.9/site-packages/ucp/core.py", line 725, in recv
    ret = await comm.tag_recv(self._ep, buffer, nbytes, tag, name=log)
ucp._libs.exceptions.UCXCanceled: <[Recv #003] ep: 0x7f99f70e8280, tag: 0x7825a8053bfcf106, nbytes: 16, type: <class 'numpy.ndarray'>>: 

During handling of the above exception, another exception occurred:

Traceback (most recent call last):
  File "/opt/conda/envs/gdf/lib/python3.9/site-packages/distributed/worker.py", line 2066, in gather_dep
    response = await get_data_from_worker(
  File "/opt/conda/envs/gdf/lib/python3.9/site-packages/distributed/worker.py", line 2892, in get_data_from_worker
    response = await send_recv(
  File "/opt/conda/envs/gdf/lib/python3.9/site-packages/distributed/core.py", line 1024, in send_recv
    response = await comm.read(deserializers=deserializers)
  File "/opt/conda/envs/gdf/lib/python3.9/site-packages/distributed/utils.py", line 752, in wrapper
    return await func(*args, **kwargs)
  File "/opt/conda/envs/gdf/lib/python3.9/site-packages/distributed/comm/ucx.py", line 367, in read
    raise CommClosedError(
distributed.comm.core.CommClosedError: Connection closed by writer.
Inner exception: UCXCanceled("<[Recv #003] ep: 0x7f99f70e8280, tag: 0x7825a8053bfcf106, nbytes: 16, type: <class 'numpy.ndarray'>>: ")
2023-07-02 06:07:36,865 - distributed.worker - ERROR - Worker stream died during communication: ucx://127.0.0.1:53259
Traceback (most recent call last):
  File "/opt/conda/envs/gdf/lib/python3.9/site-packages/distributed/comm/ucx.py", line 391, in read
    await self.ep.recv(each_frame)
  File "/opt/conda/envs/gdf/lib/python3.9/site-packages/ucp/core.py", line 725, in recv
    ret = await comm.tag_recv(self._ep, buffer, nbytes, tag, name=log)
ucp._libs.exceptions.UCXCanceled: <[Recv #009] ep: 0x7f7a735e71c0, tag: 0xf9144e5f63934a2b, nbytes: 100000000, type: <class 'rmm._lib.device_buffer.DeviceBuffer'>>: 

During handling of the above exception, another exception occurred:

Traceback (most recent call last):
  File "/opt/conda/envs/gdf/lib/python3.9/site-packages/distributed/worker.py", line 2066, in gather_dep
    response = await get_data_from_worker(
  File "/opt/conda/envs/gdf/lib/python3.9/site-packages/distributed/worker.py", line 2892, in get_data_from_worker
    response = await send_recv(
  File "/opt/conda/envs/gdf/lib/python3.9/site-packages/distributed/core.py", line 1024, in send_recv
    response = await comm.read(deserializers=deserializers)
  File "/opt/conda/envs/gdf/lib/python3.9/site-packages/distributed/utils.py", line 752, in wrapper
    return await func(*args, **kwargs)
  File "/opt/conda/envs/gdf/lib/python3.9/site-packages/distributed/comm/ucx.py", line 397, in read
    raise CommClosedError(
distributed.comm.core.CommClosedError: Connection closed by writer.
Inner exception: UCXCanceled("<[Recv #009] ep: 0x7f7a735e71c0, tag: 0xf9144e5f63934a2b, nbytes: 100000000, type: <class 'rmm._lib.device_buffer.DeviceBuffer'>>: ")
2023-07-02 06:07:36,865 - distributed.worker - ERROR - failed during get data with ucx://127.0.0.1:38111 -> ucx://127.0.0.1:53259
Traceback (most recent call last):
  File "/opt/conda/envs/gdf/lib/python3.9/site-packages/distributed/comm/ucx.py", line 349, in read
    await self.ep.recv(msg)
  File "/opt/conda/envs/gdf/lib/python3.9/site-packages/ucp/core.py", line 725, in recv
    ret = await comm.tag_recv(self._ep, buffer, nbytes, tag, name=log)
ucp._libs.exceptions.UCXCanceled: <[Recv #006] ep: 0x7f7a735e72c0, tag: 0x74aa0cca00884f7b, nbytes: 16, type: <class 'numpy.ndarray'>>: 

During handling of the above exception, another exception occurred:

Traceback (most recent call last):
  File "/opt/conda/envs/gdf/lib/python3.9/site-packages/distributed/worker.py", line 1793, in get_data
    response = await comm.read(deserializers=serializers)
  File "/opt/conda/envs/gdf/lib/python3.9/site-packages/distributed/utils.py", line 752, in wrapper
    return await func(*args, **kwargs)
  File "/opt/conda/envs/gdf/lib/python3.9/site-packages/distributed/comm/ucx.py", line 367, in read
    raise CommClosedError(
distributed.comm.core.CommClosedError: Connection closed by writer.
Inner exception: UCXCanceled("<[Recv #006] ep: 0x7f7a735e72c0, tag: 0x74aa0cca00884f7b, nbytes: 16, type: <class 'numpy.ndarray'>>: ")
[dgx13:72940:0:72940] Caught signal 11 (Segmentation fault: address not mapped to object at address 0x448)
==== backtrace (tid:  72940) ====
 0  /opt/conda/envs/gdf/lib/libucs.so.0(ucs_handle_error+0x2fd) [0x7f7a73894ced]
 1  /opt/conda/envs/gdf/lib/libucs.so.0(+0x2aee4) [0x7f7a73894ee4]
 2  /opt/conda/envs/gdf/lib/libucs.so.0(+0x2b0aa) [0x7f7a738950aa]
 3  /usr/lib/x86_64-linux-gnu/libpthread.so.0(+0x14420) [0x7f7b12e64420]
 4  /opt/conda/envs/gdf/lib/libucp.so.0(ucp_mem_type_unpack+0x14) [0x7f7a73913bb4]
 5  /opt/conda/envs/gdf/lib/libucp.so.0(ucp_rndv_data_handler+0x4e9) [0x7f7a7393ae09]
 6  /opt/conda/envs/gdf/lib/libuct.so.0(+0x2045f) [0x7f7a7384e45f]
 7  /opt/conda/envs/gdf/lib/libuct.so.0(+0x238c8) [0x7f7a738518c8]
 8  /opt/conda/envs/gdf/lib/libucs.so.0(ucs_event_set_wait+0xb9) [0x7f7a7389e399]
 9  /opt/conda/envs/gdf/lib/libuct.so.0(uct_tcp_iface_progress+0x7d) [0x7f7a7385065d]
10  /opt/conda/envs/gdf/lib/libucp.so.0(ucp_worker_progress+0x5a) [0x7f7a73910daa]
11  /opt/conda/envs/gdf/lib/python3.9/site-packages/ucp/_libs/ucx_api.cpython-39-x86_64-linux-gnu.so(+0x2b17a) [0x7f7a739c217a]
12  /opt/conda/envs/gdf/bin/python(+0x13eb08) [0x55b0a601cb08]
13  /opt/conda/envs/gdf/bin/python(_PyEval_EvalFrameDefault+0x5f82) [0x55b0a600d112]
14  /opt/conda/envs/gdf/bin/python(+0x12827a) [0x55b0a600627a]
15  /opt/conda/envs/gdf/bin/python(_PyFunction_Vectorcall+0xd5) [0x55b0a6017c05]
16  /opt/conda/envs/gdf/bin/python(_PyEval_EvalFrameDefault+0x68b) [0x55b0a600781b]
17  /opt/conda/envs/gdf/bin/python(+0x14e70e) [0x55b0a602c70e]
18  /opt/conda/envs/gdf/lib/python3.9/lib-dynload/_asyncio.cpython-39-x86_64-linux-gnu.so(+0x82fe) [0x7f7a93b0e2fe]
19  /opt/conda/envs/gdf/bin/python(_PyObject_MakeTpCall+0x2fc) [0x55b0a60102bc]
20  /opt/conda/envs/gdf/bin/python(+0xe5817) [0x55b0a5fc3817]
21  /opt/conda/envs/gdf/bin/python(+0x130f83) [0x55b0a600ef83]
22  /opt/conda/envs/gdf/bin/python(_PyEval_EvalFrameDefault+0x5ba6) [0x55b0a600cd36]
23  /opt/conda/envs/gdf/bin/python(+0x139ef3) [0x55b0a6017ef3]
24  /opt/conda/envs/gdf/bin/python(_PyEval_EvalFrameDefault+0x68b) [0x55b0a600781b]
25  /opt/conda/envs/gdf/bin/python(+0x139ef3) [0x55b0a6017ef3]
26  /opt/conda/envs/gdf/bin/python(_PyEval_EvalFrameDefault+0x68b) [0x55b0a600781b]
27  /opt/conda/envs/gdf/bin/python(+0x139ef3) [0x55b0a6017ef3]
28  /opt/conda/envs/gdf/bin/python(_PyEval_EvalFrameDefault+0x68b) [0x55b0a600781b]
29  /opt/conda/envs/gdf/bin/python(+0x139ef3) [0x55b0a6017ef3]
30  /opt/conda/envs/gdf/bin/python(_PyEval_EvalFrameDefault+0x68b) [0x55b0a600781b]
31  /opt/conda/envs/gdf/bin/python(+0x12827a) [0x55b0a600627a]
32  /opt/conda/envs/gdf/bin/python(_PyFunction_Vectorcall+0xd5) [0x55b0a6017c05]
33  /opt/conda/envs/gdf/bin/python(_PyEval_EvalFrameDefault+0x4e17) [0x55b0a600bfa7]
34  /opt/conda/envs/gdf/bin/python(+0x12827a) [0x55b0a600627a]
35  /opt/conda/envs/gdf/bin/python(+0x147935) [0x55b0a6025935]
36  /opt/conda/envs/gdf/bin/python(PyObject_Call+0xb4) [0x55b0a6026104]
37  /opt/conda/envs/gdf/bin/python(+0x20efc8) [0x55b0a60ecfc8]
38  /opt/conda/envs/gdf/bin/python(_PyObject_MakeTpCall+0x2fc) [0x55b0a60102bc]
39  /opt/conda/envs/gdf/bin/python(_PyEval_EvalFrameDefault+0x402b) [0x55b0a600b1bb]
40  /opt/conda/envs/gdf/bin/python(+0x139ef3) [0x55b0a6017ef3]
41  /opt/conda/envs/gdf/bin/python(+0x147c72) [0x55b0a6025c72]
42  /opt/conda/envs/gdf/bin/python(_PyEval_EvalFrameDefault+0x402b) [0x55b0a600b1bb]
43  /opt/conda/envs/gdf/bin/python(+0x139ef3) [0x55b0a6017ef3]
44  /opt/conda/envs/gdf/bin/python(_PyEval_EvalFrameDefault+0x68b) [0x55b0a600781b]
45  /opt/conda/envs/gdf/bin/python(+0x12827a) [0x55b0a600627a]
46  /opt/conda/envs/gdf/bin/python(_PyFunction_Vectorcall+0xd5) [0x55b0a6017c05]
47  /opt/conda/envs/gdf/bin/python(_PyEval_EvalFrameDefault+0x68b) [0x55b0a600781b]
48  /opt/conda/envs/gdf/bin/python(+0x139ef3) [0x55b0a6017ef3]
49  /opt/conda/envs/gdf/bin/python(_PyEval_EvalFrameDefault+0x3d8) [0x55b0a6007568]
50  /opt/conda/envs/gdf/bin/python(+0x12827a) [0x55b0a600627a]
51  /opt/conda/envs/gdf/bin/python(_PyFunction_Vectorcall+0xd5) [0x55b0a6017c05]
52  /opt/conda/envs/gdf/bin/python(_PyEval_EvalFrameDefault+0x123b) [0x55b0a60083cb]
53  /opt/conda/envs/gdf/bin/python(+0x12827a) [0x55b0a600627a]
54  /opt/conda/envs/gdf/bin/python(_PyEval_EvalCodeWithName+0x47) [0x55b0a6005f07]
55  /opt/conda/envs/gdf/bin/python(PyEval_EvalCodeEx+0x39) [0x55b0a6005eb9]
56  /opt/conda/envs/gdf/bin/python(PyEval_EvalCode+0x1b) [0x55b0a60b68bb]
57  /opt/conda/envs/gdf/bin/python(+0x206adc) [0x55b0a60e4adc]
58  /opt/conda/envs/gdf/bin/python(+0x202c24) [0x55b0a60e0c24]
59  /opt/conda/envs/gdf/bin/python(PyRun_StringFlags+0x9d) [0x55b0a60d87ed]
60  /opt/conda/envs/gdf/bin/python(PyRun_SimpleStringFlags+0x3d) [0x55b0a60d86bd]
61  /opt/conda/envs/gdf/bin/python(Py_RunMain+0x262) [0x55b0a60d78a2]
=================================
2023-07-02 06:07:36,880 - distributed.worker - ERROR - failed during get data with ucx://127.0.0.1:58261 -> ucx://127.0.0.1:34181
Traceback (most recent call last):
  File "/opt/conda/envs/gdf/lib/python3.9/site-packages/distributed/comm/ucx.py", line 315, in write
    await self.ep.send(struct.pack("?Q", False, nframes))
  File "/opt/conda/envs/gdf/lib/python3.9/site-packages/ucp/core.py", line 629, in send
    self._ep.raise_on_error()
  File "ucp/_libs/ucx_endpoint.pyx", line 353, in ucp._libs.ucx_api.UCXEndpoint.raise_on_error
ucp._libs.exceptions.UCXConnectionReset: Endpoint 0x7f33a0980340 error: Connection reset by remote peer

During handling of the above exception, another exception occurred:

Traceback (most recent call last):
  File "/opt/conda/envs/gdf/lib/python3.9/site-packages/distributed/worker.py", line 1792, in get_data
    compressed = await comm.write(msg, serializers=serializers)
  File "/opt/conda/envs/gdf/lib/python3.9/site-packages/distributed/utils.py", line 752, in wrapper
    return await func(*args, **kwargs)
  File "/opt/conda/envs/gdf/lib/python3.9/site-packages/distributed/comm/ucx.py", line 337, in write
    raise CommClosedError("While writing, the connection was closed")
distributed.comm.core.CommClosedError: While writing, the connection was closed
2023-07-02 06:07:36,882 - distributed.worker - ERROR - failed during get data with ucx://127.0.0.1:45747 -> ucx://127.0.0.1:53259
Traceback (most recent call last):
  File "/opt/conda/envs/gdf/lib/python3.9/site-packages/distributed/comm/ucx.py", line 333, in write
    await self.ep.send(each_frame)
  File "/opt/conda/envs/gdf/lib/python3.9/site-packages/ucp/core.py", line 629, in send
    self._ep.raise_on_error()
  File "ucp/_libs/ucx_endpoint.pyx", line 353, in ucp._libs.ucx_api.UCXEndpoint.raise_on_error
ucp._libs.exceptions.UCXConnectionReset: Endpoint 0x7f5ab00653c0 error: Connection reset by remote peer

During handling of the above exception, another exception occurred:

Traceback (most recent call last):
  File "/opt/conda/envs/gdf/lib/python3.9/site-packages/distributed/worker.py", line 1792, in get_data
    compressed = await comm.write(msg, serializers=serializers)
  File "/opt/conda/envs/gdf/lib/python3.9/site-packages/distributed/utils.py", line 752, in wrapper
    return await func(*args, **kwargs)
  File "/opt/conda/envs/gdf/lib/python3.9/site-packages/distributed/comm/ucx.py", line 337, in write
    raise CommClosedError("While writing, the connection was closed")
distributed.comm.core.CommClosedError: While writing, the connection was closed
2023-07-02 06:07:36,884 - distributed.worker - ERROR - Worker stream died during communication: ucx://127.0.0.1:53259
Traceback (most recent call last):
  File "/opt/conda/envs/gdf/lib/python3.9/site-packages/distributed/comm/ucx.py", line 391, in read
    await self.ep.recv(each_frame)
  File "/opt/conda/envs/gdf/lib/python3.9/site-packages/ucp/core.py", line 708, in recv
    self._ep.raise_on_error()
  File "ucp/_libs/ucx_endpoint.pyx", line 353, in ucp._libs.ucx_api.UCXEndpoint.raise_on_error
ucp._libs.exceptions.UCXConnectionReset: Endpoint 0x7f5ab0065200 error: Connection reset by remote peer

During handling of the above exception, another exception occurred:

Traceback (most recent call last):
  File "/opt/conda/envs/gdf/lib/python3.9/site-packages/distributed/worker.py", line 2066, in gather_dep
    response = await get_data_from_worker(
  File "/opt/conda/envs/gdf/lib/python3.9/site-packages/distributed/worker.py", line 2892, in get_data_from_worker
    response = await send_recv(
  File "/opt/conda/envs/gdf/lib/python3.9/site-packages/distributed/core.py", line 1024, in send_recv
    response = await comm.read(deserializers=deserializers)
  File "/opt/conda/envs/gdf/lib/python3.9/site-packages/distributed/utils.py", line 752, in wrapper
    return await func(*args, **kwargs)
  File "/opt/conda/envs/gdf/lib/python3.9/site-packages/distributed/comm/ucx.py", line 397, in read
    raise CommClosedError(
distributed.comm.core.CommClosedError: Connection closed by writer.
Inner exception: UCXConnectionReset('Endpoint 0x7f5ab0065200 error: Connection reset by remote peer')
2023-07-02 06:07:36,884 - distributed.worker - ERROR - Worker stream died during communication: ucx://127.0.0.1:34181
Traceback (most recent call last):
  File "/opt/conda/envs/gdf/lib/python3.9/site-packages/distributed/comm/ucx.py", line 391, in read
    await self.ep.recv(each_frame)
  File "/opt/conda/envs/gdf/lib/python3.9/site-packages/ucp/core.py", line 708, in recv
    self._ep.raise_on_error()
  File "ucp/_libs/ucx_endpoint.pyx", line 353, in ucp._libs.ucx_api.UCXEndpoint.raise_on_error
ucp._libs.exceptions.UCXConnectionReset: Endpoint 0x7f5ab0065240 error: Connection reset by remote peer

During handling of the above exception, another exception occurred:

Traceback (most recent call last):
  File "/opt/conda/envs/gdf/lib/python3.9/site-packages/distributed/worker.py", line 2066, in gather_dep
    response = await get_data_from_worker(
  File "/opt/conda/envs/gdf/lib/python3.9/site-packages/distributed/worker.py", line 2892, in get_data_from_worker
    response = await send_recv(
  File "/opt/conda/envs/gdf/lib/python3.9/site-packages/distributed/core.py", line 1024, in send_recv
    response = await comm.read(deserializers=deserializers)
  File "/opt/conda/envs/gdf/lib/python3.9/site-packages/distributed/utils.py", line 752, in wrapper
    return await func(*args, **kwargs)
  File "/opt/conda/envs/gdf/lib/python3.9/site-packages/distributed/comm/ucx.py", line 397, in read
    raise CommClosedError(
distributed.comm.core.CommClosedError: Connection closed by writer.
Inner exception: UCXConnectionReset('Endpoint 0x7f5ab0065240 error: Connection reset by remote peer')
2023-07-02 06:07:36,890 - distributed.worker - ERROR - Worker stream died during communication: ucx://127.0.0.1:34181
Traceback (most recent call last):
  File "/opt/conda/envs/gdf/lib/python3.9/site-packages/distributed/comm/ucx.py", line 391, in read
    await self.ep.recv(each_frame)
  File "/opt/conda/envs/gdf/lib/python3.9/site-packages/ucp/core.py", line 708, in recv
    self._ep.raise_on_error()
  File "ucp/_libs/ucx_endpoint.pyx", line 353, in ucp._libs.ucx_api.UCXEndpoint.raise_on_error
ucp._libs.exceptions.UCXConnectionReset: Endpoint 0x7f33a09801c0 error: Connection reset by remote peer

During handling of the above exception, another exception occurred:

Traceback (most recent call last):
  File "/opt/conda/envs/gdf/lib/python3.9/site-packages/distributed/worker.py", line 2066, in gather_dep
    response = await get_data_from_worker(
  File "/opt/conda/envs/gdf/lib/python3.9/site-packages/distributed/worker.py", line 2892, in get_data_from_worker
    response = await send_recv(
  File "/opt/conda/envs/gdf/lib/python3.9/site-packages/distributed/core.py", line 1024, in send_recv
    response = await comm.read(deserializers=deserializers)
  File "/opt/conda/envs/gdf/lib/python3.9/site-packages/distributed/utils.py", line 752, in wrapper
    return await func(*args, **kwargs)
  File "/opt/conda/envs/gdf/lib/python3.9/site-packages/distributed/comm/ucx.py", line 397, in read
    raise CommClosedError(
distributed.comm.core.CommClosedError: Connection closed by writer.
Inner exception: UCXConnectionReset('Endpoint 0x7f33a09801c0 error: Connection reset by remote peer')
2023-07-02 06:07:36,890 - distributed.worker - ERROR - Worker stream died during communication: ucx://127.0.0.1:34181
Traceback (most recent call last):
  File "/opt/conda/envs/gdf/lib/python3.9/site-packages/distributed/comm/ucx.py", line 391, in read
    await self.ep.recv(each_frame)
  File "/opt/conda/envs/gdf/lib/python3.9/site-packages/ucp/core.py", line 708, in recv
    self._ep.raise_on_error()
  File "ucp/_libs/ucx_endpoint.pyx", line 353, in ucp._libs.ucx_api.UCXEndpoint.raise_on_error
ucp._libs.exceptions.UCXConnectionReset: Endpoint 0x7f4451f40240 error: Connection reset by remote peer

During handling of the above exception, another exception occurred:

Traceback (most recent call last):
  File "/opt/conda/envs/gdf/lib/python3.9/site-packages/distributed/worker.py", line 2066, in gather_dep
    response = await get_data_from_worker(
  File "/opt/conda/envs/gdf/lib/python3.9/site-packages/distributed/worker.py", line 2892, in get_data_from_worker
    response = await send_recv(
  File "/opt/conda/envs/gdf/lib/python3.9/site-packages/distributed/core.py", line 1024, in send_recv
    response = await comm.read(deserializers=deserializers)
  File "/opt/conda/envs/gdf/lib/python3.9/site-packages/distributed/utils.py", line 752, in wrapper
    return await func(*args, **kwargs)
  File "/opt/conda/envs/gdf/lib/python3.9/site-packages/distributed/comm/ucx.py", line 397, in read
    raise CommClosedError(
distributed.comm.core.CommClosedError: Connection closed by writer.
Inner exception: UCXConnectionReset('Endpoint 0x7f4451f40240 error: Connection reset by remote peer')
2023-07-02 06:07:36,899 - distributed.worker - ERROR - failed during get data with ucx://127.0.0.1:58261 -> ucx://127.0.0.1:53259
Traceback (most recent call last):
  File "/opt/conda/envs/gdf/lib/python3.9/site-packages/distributed/worker.py", line 1792, in get_data
    compressed = await comm.write(msg, serializers=serializers)
  File "/opt/conda/envs/gdf/lib/python3.9/site-packages/distributed/utils.py", line 752, in wrapper
    return await func(*args, **kwargs)
  File "/opt/conda/envs/gdf/lib/python3.9/site-packages/distributed/comm/ucx.py", line 289, in write
    raise CommClosedError("Endpoint is closed -- unable to send message")
distributed.comm.core.CommClosedError: Endpoint is closed -- unable to send message
2023-07-02 06:07:36,899 - distributed.worker - ERROR - failed during get data with ucx://127.0.0.1:48121 -> ucx://127.0.0.1:34181
Traceback (most recent call last):
  File "/opt/conda/envs/gdf/lib/python3.9/site-packages/distributed/worker.py", line 1792, in get_data
    compressed = await comm.write(msg, serializers=serializers)
  File "/opt/conda/envs/gdf/lib/python3.9/site-packages/distributed/utils.py", line 752, in wrapper
    return await func(*args, **kwargs)
  File "/opt/conda/envs/gdf/lib/python3.9/site-packages/distributed/comm/ucx.py", line 289, in write
    raise CommClosedError("Endpoint is closed -- unable to send message")
distributed.comm.core.CommClosedError: Endpoint is closed -- unable to send message
[dgx13:72955:0:72955] Caught signal 11 (Segmentation fault: address not mapped to object at address 0x448)
==== backtrace (tid:  72955) ====
 0  /opt/conda/envs/gdf/lib/libucs.so.0(ucs_handle_error+0x2fd) [0x7f44581d8ced]
 1  /opt/conda/envs/gdf/lib/libucs.so.0(+0x2aee4) [0x7f44581d8ee4]
 2  /opt/conda/envs/gdf/lib/libucs.so.0(+0x2b0aa) [0x7f44581d90aa]
 3  /usr/lib/x86_64-linux-gnu/libpthread.so.0(+0x14420) [0x7f44f790b420]
 4  /opt/conda/envs/gdf/lib/libucp.so.0(ucp_mem_type_unpack+0x14) [0x7f4458257bb4]
 5  /opt/conda/envs/gdf/lib/libucp.so.0(ucp_rndv_data_handler+0x4e9) [0x7f445827ee09]
 6  /opt/conda/envs/gdf/lib/libuct.so.0(+0x2045f) [0x7f445819245f]
 7  /opt/conda/envs/gdf/lib/libuct.so.0(+0x238c8) [0x7f44581958c8]
 8  /opt/conda/envs/gdf/lib/libucs.so.0(ucs_event_set_wait+0xb9) [0x7f44581e2399]
 9  /opt/conda/envs/gdf/lib/libuct.so.0(uct_tcp_iface_progress+0x7d) [0x7f445819465d]
10  /opt/conda/envs/gdf/lib/libucp.so.0(ucp_worker_progress+0x5a) [0x7f4458254daa]
11  /opt/conda/envs/gdf/lib/python3.9/site-packages/ucp/_libs/ucx_api.cpython-39-x86_64-linux-gnu.so(+0x2b17a) [0x7f445830617a]
12  /opt/conda/envs/gdf/bin/python(+0x13eb08) [0x55fbc34d7b08]
13  /opt/conda/envs/gdf/bin/python(_PyEval_EvalFrameDefault+0x5f82) [0x55fbc34c8112]
14  /opt/conda/envs/gdf/bin/python(+0x12827a) [0x55fbc34c127a]
15  /opt/conda/envs/gdf/bin/python(_PyFunction_Vectorcall+0xd5) [0x55fbc34d2c05]
16  /opt/conda/envs/gdf/bin/python(_PyEval_EvalFrameDefault+0x68b) [0x55fbc34c281b]
17  /opt/conda/envs/gdf/bin/python(+0x14e70e) [0x55fbc34e770e]
18  /opt/conda/envs/gdf/lib/python3.9/lib-dynload/_asyncio.cpython-39-x86_64-linux-gnu.so(+0x82fe) [0x7f44785b62fe]
19  /opt/conda/envs/gdf/bin/python(_PyObject_MakeTpCall+0x2fc) [0x55fbc34cb2bc]
20  /opt/conda/envs/gdf/bin/python(+0xe5817) [0x55fbc347e817]
21  /opt/conda/envs/gdf/bin/python(+0x130f83) [0x55fbc34c9f83]
22  /opt/conda/envs/gdf/bin/python(_PyEval_EvalFrameDefault+0x5ba6) [0x55fbc34c7d36]
23  /opt/conda/envs/gdf/bin/python(+0x139ef3) [0x55fbc34d2ef3]
24  /opt/conda/envs/gdf/bin/python(_PyEval_EvalFrameDefault+0x68b) [0x55fbc34c281b]
25  /opt/conda/envs/gdf/bin/python(+0x139ef3) [0x55fbc34d2ef3]
26  /opt/conda/envs/gdf/bin/python(_PyEval_EvalFrameDefault+0x68b) [0x55fbc34c281b]
27  /opt/conda/envs/gdf/bin/python(+0x139ef3) [0x55fbc34d2ef3]
28  /opt/conda/envs/gdf/bin/python(_PyEval_EvalFrameDefault+0x68b) [0x55fbc34c281b]
29  /opt/conda/envs/gdf/bin/python(+0x139ef3) [0x55fbc34d2ef3]
30  /opt/conda/envs/gdf/bin/python(_PyEval_EvalFrameDefault+0x68b) [0x55fbc34c281b]
31  /opt/conda/envs/gdf/bin/python(+0x12827a) [0x55fbc34c127a]
32  /opt/conda/envs/gdf/bin/python(_PyFunction_Vectorcall+0xd5) [0x55fbc34d2c05]
33  /opt/conda/envs/gdf/bin/python(_PyEval_EvalFrameDefault+0x4e17) [0x55fbc34c6fa7]
34  /opt/conda/envs/gdf/bin/python(+0x12827a) [0x55fbc34c127a]
35  /opt/conda/envs/gdf/bin/python(+0x147935) [0x55fbc34e0935]
36  /opt/conda/envs/gdf/bin/python(PyObject_Call+0xb4) [0x55fbc34e1104]
37  /opt/conda/envs/gdf/bin/python(+0x20efc8) [0x55fbc35a7fc8]
38  /opt/conda/envs/gdf/bin/python(_PyObject_MakeTpCall+0x2fc) [0x55fbc34cb2bc]
39  /opt/conda/envs/gdf/bin/python(_PyEval_EvalFrameDefault+0x402b) [0x55fbc34c61bb]
40  /opt/conda/envs/gdf/bin/python(+0x139ef3) [0x55fbc34d2ef3]
41  /opt/conda/envs/gdf/bin/python(+0x147c72) [0x55fbc34e0c72]
42  /opt/conda/envs/gdf/bin/python(_PyEval_EvalFrameDefault+0x402b) [0x55fbc34c61bb]
43  /opt/conda/envs/gdf/bin/python(+0x139ef3) [0x55fbc34d2ef3]
44  /opt/conda/envs/gdf/bin/python(_PyEval_EvalFrameDefault+0x68b) [0x55fbc34c281b]
45  /opt/conda/envs/gdf/bin/python(+0x12827a) [0x55fbc34c127a]
46  /opt/conda/envs/gdf/bin/python(_PyFunction_Vectorcall+0xd5) [0x55fbc34d2c05]
47  /opt/conda/envs/gdf/bin/python(_PyEval_EvalFrameDefault+0x68b) [0x55fbc34c281b]
48  /opt/conda/envs/gdf/bin/python(+0x139ef3) [0x55fbc34d2ef3]
49  /opt/conda/envs/gdf/bin/python(_PyEval_EvalFrameDefault+0x3d8) [0x55fbc34c2568]
50  /opt/conda/envs/gdf/bin/python(+0x12827a) [0x55fbc34c127a]
51  /opt/conda/envs/gdf/bin/python(_PyFunction_Vectorcall+0xd5) [0x55fbc34d2c05]
52  /opt/conda/envs/gdf/bin/python(_PyEval_EvalFrameDefault+0x123b) [0x55fbc34c33cb]
53  /opt/conda/envs/gdf/bin/python(+0x12827a) [0x55fbc34c127a]
54  /opt/conda/envs/gdf/bin/python(_PyEval_EvalCodeWithName+0x47) [0x55fbc34c0f07]
55  /opt/conda/envs/gdf/bin/python(PyEval_EvalCodeEx+0x39) [0x55fbc34c0eb9]
56  /opt/conda/envs/gdf/bin/python(PyEval_EvalCode+0x1b) [0x55fbc35718bb]
57  /opt/conda/envs/gdf/bin/python(+0x206adc) [0x55fbc359fadc]
58  /opt/conda/envs/gdf/bin/python(+0x202c24) [0x55fbc359bc24]
59  /opt/conda/envs/gdf/bin/python(PyRun_StringFlags+0x9d) [0x55fbc35937ed]
60  /opt/conda/envs/gdf/bin/python(PyRun_SimpleStringFlags+0x3d) [0x55fbc35936bd]
61  /opt/conda/envs/gdf/bin/python(Py_RunMain+0x262) [0x55fbc35928a2]
=================================
2023-07-02 06:07:36,945 - distributed.nanny - WARNING - Restarting worker
2023-07-02 06:07:36,999 - distributed.nanny - WARNING - Restarting worker
2023-07-02 06:07:37,025 - distributed.worker - ERROR - Worker stream died during communication: ucx://127.0.0.1:53259
Traceback (most recent call last):
  File "/opt/conda/envs/gdf/lib/python3.9/site-packages/distributed/comm/core.py", line 330, in connect
    await wait_for(comm.write(local_info), time_left())
  File "/opt/conda/envs/gdf/lib/python3.9/site-packages/distributed/utils.py", line 1849, in wait_for
    return await asyncio.wait_for(fut, timeout)
  File "/opt/conda/envs/gdf/lib/python3.9/asyncio/tasks.py", line 479, in wait_for
    return fut.result()
  File "/opt/conda/envs/gdf/lib/python3.9/site-packages/distributed/utils.py", line 752, in wrapper
    return await func(*args, **kwargs)
  File "/opt/conda/envs/gdf/lib/python3.9/site-packages/distributed/comm/ucx.py", line 289, in write
    raise CommClosedError("Endpoint is closed -- unable to send message")
distributed.comm.core.CommClosedError: Endpoint is closed -- unable to send message

The above exception was the direct cause of the following exception:

Traceback (most recent call last):
  File "/opt/conda/envs/gdf/lib/python3.9/site-packages/distributed/worker.py", line 2066, in gather_dep
    response = await get_data_from_worker(
  File "/opt/conda/envs/gdf/lib/python3.9/site-packages/distributed/worker.py", line 2889, in get_data_from_worker
    comm = await rpc.connect(worker)
  File "/opt/conda/envs/gdf/lib/python3.9/site-packages/distributed/core.py", line 1506, in connect
    return await connect_attempt
  File "/opt/conda/envs/gdf/lib/python3.9/site-packages/distributed/core.py", line 1427, in _connect
    comm = await connect(
  File "/opt/conda/envs/gdf/lib/python3.9/site-packages/distributed/comm/core.py", line 334, in connect
    raise OSError(
OSError: Timed out during handshake while connecting to ucx://127.0.0.1:53259 after 30 s
2023-07-02 06:07:37,031 - distributed.worker - ERROR - failed during get data with ucx://127.0.0.1:45747 -> ucx://127.0.0.1:34181
Traceback (most recent call last):
  File "/opt/conda/envs/gdf/lib/python3.9/site-packages/distributed/comm/ucx.py", line 333, in write
    await self.ep.send(each_frame)
  File "/opt/conda/envs/gdf/lib/python3.9/site-packages/ucp/core.py", line 650, in send
    return await comm.tag_send(self._ep, buffer, nbytes, tag, name=log)
ucp._libs.exceptions.UCXError: <[Send #007] ep: 0x7f5ab0065400, tag: 0x4bec6ec705eed2f6, nbytes: 100000000, type: <class 'cudf.core.buffer.buffer.Buffer'>>: Connection reset by remote peer

During handling of the above exception, another exception occurred:

Traceback (most recent call last):
  File "/opt/conda/envs/gdf/lib/python3.9/site-packages/distributed/worker.py", line 1792, in get_data
    compressed = await comm.write(msg, serializers=serializers)
  File "/opt/conda/envs/gdf/lib/python3.9/site-packages/distributed/utils.py", line 752, in wrapper
    return await func(*args, **kwargs)
  File "/opt/conda/envs/gdf/lib/python3.9/site-packages/distributed/comm/ucx.py", line 337, in write
    raise CommClosedError("While writing, the connection was closed")
distributed.comm.core.CommClosedError: While writing, the connection was closed
2023-07-02 06:07:37,140 - distributed.worker - ERROR - Worker stream died during communication: ucx://127.0.0.1:38111
Traceback (most recent call last):
  File "/opt/conda/envs/gdf/lib/python3.9/site-packages/distributed/comm/ucx.py", line 391, in read
    await self.ep.recv(each_frame)
  File "/opt/conda/envs/gdf/lib/python3.9/site-packages/ucp/core.py", line 725, in recv
    ret = await comm.tag_recv(self._ep, buffer, nbytes, tag, name=log)
ucp._libs.exceptions.UCXError: <[Recv #007] ep: 0x7f33a0980240, tag: 0xd625e645fb512033, nbytes: 100000000, type: <class 'rmm._lib.device_buffer.DeviceBuffer'>>: Connection reset by remote peer

During handling of the above exception, another exception occurred:

Traceback (most recent call last):
  File "/opt/conda/envs/gdf/lib/python3.9/site-packages/distributed/worker.py", line 2066, in gather_dep
    response = await get_data_from_worker(
  File "/opt/conda/envs/gdf/lib/python3.9/site-packages/distributed/worker.py", line 2892, in get_data_from_worker
    response = await send_recv(
  File "/opt/conda/envs/gdf/lib/python3.9/site-packages/distributed/core.py", line 1024, in send_recv
    response = await comm.read(deserializers=deserializers)
  File "/opt/conda/envs/gdf/lib/python3.9/site-packages/distributed/utils.py", line 752, in wrapper
    return await func(*args, **kwargs)
  File "/opt/conda/envs/gdf/lib/python3.9/site-packages/distributed/comm/ucx.py", line 397, in read
    raise CommClosedError(
distributed.comm.core.CommClosedError: Connection closed by writer.
Inner exception: UCXError("<[Recv #007] ep: 0x7f33a0980240, tag: 0xd625e645fb512033, nbytes: 100000000, type: <class 'rmm._lib.device_buffer.DeviceBuffer'>>: Connection reset by remote peer")
2023-07-02 06:07:37,140 - distributed.worker - ERROR - failed during get data with ucx://127.0.0.1:58261 -> ucx://127.0.0.1:38111
Traceback (most recent call last):
  File "/opt/conda/envs/gdf/lib/python3.9/site-packages/distributed/comm/ucx.py", line 333, in write
    await self.ep.send(each_frame)
  File "/opt/conda/envs/gdf/lib/python3.9/site-packages/ucp/core.py", line 650, in send
    return await comm.tag_send(self._ep, buffer, nbytes, tag, name=log)
ucp._libs.exceptions.UCXError: <[Send #007] ep: 0x7f33a09802c0, tag: 0x2b63fc3f10e8b3e4, nbytes: 100000000, type: <class 'cudf.core.buffer.buffer.Buffer'>>: Connection reset by remote peer

During handling of the above exception, another exception occurred:

Traceback (most recent call last):
  File "/opt/conda/envs/gdf/lib/python3.9/site-packages/distributed/worker.py", line 1792, in get_data
    compressed = await comm.write(msg, serializers=serializers)
  File "/opt/conda/envs/gdf/lib/python3.9/site-packages/distributed/utils.py", line 752, in wrapper
    return await func(*args, **kwargs)
  File "/opt/conda/envs/gdf/lib/python3.9/site-packages/distributed/comm/ucx.py", line 337, in write
    raise CommClosedError("While writing, the connection was closed")
distributed.comm.core.CommClosedError: While writing, the connection was closed
2023-07-02 06:07:37,155 - distributed.worker - ERROR - Worker stream died during communication: ucx://127.0.0.1:48121
Traceback (most recent call last):
  File "/opt/conda/envs/gdf/lib/python3.9/site-packages/distributed/comm/ucx.py", line 391, in read
    await self.ep.recv(each_frame)
  File "/opt/conda/envs/gdf/lib/python3.9/site-packages/ucp/core.py", line 725, in recv
    ret = await comm.tag_recv(self._ep, buffer, nbytes, tag, name=log)
ucp._libs.exceptions.UCXCanceled: <[Recv #008] ep: 0x7f33a0980180, tag: 0x5c5378183f710f4e, nbytes: 100000000, type: <class 'rmm._lib.device_buffer.DeviceBuffer'>>: 

During handling of the above exception, another exception occurred:

Traceback (most recent call last):
  File "/opt/conda/envs/gdf/lib/python3.9/site-packages/distributed/worker.py", line 2066, in gather_dep
    response = await get_data_from_worker(
  File "/opt/conda/envs/gdf/lib/python3.9/site-packages/distributed/worker.py", line 2892, in get_data_from_worker
    response = await send_recv(
  File "/opt/conda/envs/gdf/lib/python3.9/site-packages/distributed/core.py", line 1024, in send_recv
    response = await comm.read(deserializers=deserializers)
  File "/opt/conda/envs/gdf/lib/python3.9/site-packages/distributed/utils.py", line 752, in wrapper
    return await func(*args, **kwargs)
  File "/opt/conda/envs/gdf/lib/python3.9/site-packages/distributed/comm/ucx.py", line 397, in read
    raise CommClosedError(
distributed.comm.core.CommClosedError: Connection closed by writer.
Inner exception: UCXCanceled("<[Recv #008] ep: 0x7f33a0980180, tag: 0x5c5378183f710f4e, nbytes: 100000000, type: <class 'rmm._lib.device_buffer.DeviceBuffer'>>: ")
2023-07-02 06:07:37,169 - distributed.worker - ERROR - Worker stream died during communication: ucx://127.0.0.1:48121
Traceback (most recent call last):
  File "/opt/conda/envs/gdf/lib/python3.9/site-packages/distributed/comm/ucx.py", line 349, in read
    await self.ep.recv(msg)
  File "/opt/conda/envs/gdf/lib/python3.9/site-packages/ucp/core.py", line 725, in recv
    ret = await comm.tag_recv(self._ep, buffer, nbytes, tag, name=log)
ucp._libs.exceptions.UCXCanceled: <[Recv #003] ep: 0x7f5ab0065180, tag: 0xdf2d2a56b9d86ed5, nbytes: 16, type: <class 'numpy.ndarray'>>: 

During handling of the above exception, another exception occurred:

Traceback (most recent call last):
  File "/opt/conda/envs/gdf/lib/python3.9/site-packages/distributed/worker.py", line 2066, in gather_dep
    response = await get_data_from_worker(
  File "/opt/conda/envs/gdf/lib/python3.9/site-packages/distributed/worker.py", line 2892, in get_data_from_worker
    response = await send_recv(
  File "/opt/conda/envs/gdf/lib/python3.9/site-packages/distributed/core.py", line 1024, in send_recv
    response = await comm.read(deserializers=deserializers)
  File "/opt/conda/envs/gdf/lib/python3.9/site-packages/distributed/utils.py", line 752, in wrapper
    return await func(*args, **kwargs)
  File "/opt/conda/envs/gdf/lib/python3.9/site-packages/distributed/comm/ucx.py", line 367, in read
    raise CommClosedError(
distributed.comm.core.CommClosedError: Connection closed by writer.
Inner exception: UCXCanceled("<[Recv #003] ep: 0x7f5ab0065180, tag: 0xdf2d2a56b9d86ed5, nbytes: 16, type: <class 'numpy.ndarray'>>: ")
2023-07-02 06:07:37,169 - distributed.worker - ERROR - Worker stream died during communication: ucx://127.0.0.1:38111
Traceback (most recent call last):
  File "/opt/conda/envs/gdf/lib/python3.9/site-packages/distributed/comm/ucx.py", line 349, in read
    await self.ep.recv(msg)
  File "/opt/conda/envs/gdf/lib/python3.9/site-packages/ucp/core.py", line 725, in recv
    ret = await comm.tag_recv(self._ep, buffer, nbytes, tag, name=log)
ucp._libs.exceptions.UCXCanceled: <[Recv #003] ep: 0x7f5ab0065280, tag: 0xc718c0933de8e563, nbytes: 16, type: <class 'numpy.ndarray'>>: 

During handling of the above exception, another exception occurred:

Traceback (most recent call last):
  File "/opt/conda/envs/gdf/lib/python3.9/site-packages/distributed/worker.py", line 2066, in gather_dep
    response = await get_data_from_worker(
  File "/opt/conda/envs/gdf/lib/python3.9/site-packages/distributed/worker.py", line 2892, in get_data_from_worker
    response = await send_recv(
  File "/opt/conda/envs/gdf/lib/python3.9/site-packages/distributed/core.py", line 1024, in send_recv
    response = await comm.read(deserializers=deserializers)
  File "/opt/conda/envs/gdf/lib/python3.9/site-packages/distributed/utils.py", line 752, in wrapper
    return await func(*args, **kwargs)
  File "/opt/conda/envs/gdf/lib/python3.9/site-packages/distributed/comm/ucx.py", line 367, in read
    raise CommClosedError(
distributed.comm.core.CommClosedError: Connection closed by writer.
Inner exception: UCXCanceled("<[Recv #003] ep: 0x7f5ab0065280, tag: 0xc718c0933de8e563, nbytes: 16, type: <class 'numpy.ndarray'>>: ")
2023-07-02 06:07:37,187 - distributed.worker - ERROR - Worker stream died during communication: ucx://127.0.0.1:48121
Traceback (most recent call last):
  File "/opt/conda/envs/gdf/lib/python3.9/site-packages/distributed/comm/ucx.py", line 391, in read
    await self.ep.recv(each_frame)
  File "/opt/conda/envs/gdf/lib/python3.9/site-packages/ucp/core.py", line 725, in recv
    ret = await comm.tag_recv(self._ep, buffer, nbytes, tag, name=log)
ucp._libs.exceptions.UCXCanceled: <[Recv #009] ep: 0x7f99f70e8100, tag: 0x246b1d32a8b47c9f, nbytes: 100000000, type: <class 'rmm._lib.device_buffer.DeviceBuffer'>>: 

During handling of the above exception, another exception occurred:

Traceback (most recent call last):
  File "/opt/conda/envs/gdf/lib/python3.9/site-packages/distributed/worker.py", line 2066, in gather_dep
    response = await get_data_from_worker(
  File "/opt/conda/envs/gdf/lib/python3.9/site-packages/distributed/worker.py", line 2892, in get_data_from_worker
    response = await send_recv(
  File "/opt/conda/envs/gdf/lib/python3.9/site-packages/distributed/core.py", line 1024, in send_recv
    response = await comm.read(deserializers=deserializers)
  File "/opt/conda/envs/gdf/lib/python3.9/site-packages/distributed/utils.py", line 752, in wrapper
    return await func(*args, **kwargs)
  File "/opt/conda/envs/gdf/lib/python3.9/site-packages/distributed/comm/ucx.py", line 397, in read
    raise CommClosedError(
distributed.comm.core.CommClosedError: Connection closed by writer.
Inner exception: UCXCanceled("<[Recv #009] ep: 0x7f99f70e8100, tag: 0x246b1d32a8b47c9f, nbytes: 100000000, type: <class 'rmm._lib.device_buffer.DeviceBuffer'>>: ")
2023-07-02 06:07:37,209 - distributed.nanny - WARNING - Restarting worker
[dgx13:72958:0:72958] Caught signal 11 (Segmentation fault: address not mapped to object at address 0x448)
==== backtrace (tid:  72958) ====
 0  /opt/conda/envs/gdf/lib/libucs.so.0(ucs_handle_error+0x2fd) [0x7f5ab02f7ced]
 1  /opt/conda/envs/gdf/lib/libucs.so.0(+0x2aee4) [0x7f5ab02f7ee4]
 2  /opt/conda/envs/gdf/lib/libucs.so.0(+0x2b0aa) [0x7f5ab02f80aa]
 3  /usr/lib/x86_64-linux-gnu/libpthread.so.0(+0x14420) [0x7f5b4fa29420]
 4  /opt/conda/envs/gdf/lib/libucp.so.0(ucp_mem_type_unpack+0x14) [0x7f5ab0376bb4]
 5  /opt/conda/envs/gdf/lib/libucp.so.0(ucp_rndv_data_handler+0x4e9) [0x7f5ab039de09]
 6  /opt/conda/envs/gdf/lib/libuct.so.0(+0x2045f) [0x7f5ab02b145f]
 7  /opt/conda/envs/gdf/lib/libuct.so.0(+0x238c8) [0x7f5ab02b48c8]
 8  /opt/conda/envs/gdf/lib/libucs.so.0(ucs_event_set_wait+0xb9) [0x7f5ab0301399]
 9  /opt/conda/envs/gdf/lib/libuct.so.0(uct_tcp_iface_progress+0x7d) [0x7f5ab02b365d]
10  /opt/conda/envs/gdf/lib/libucp.so.0(ucp_worker_progress+0x5a) [0x7f5ab0373daa]
11  /opt/conda/envs/gdf/lib/python3.9/site-packages/ucp/_libs/ucx_api.cpython-39-x86_64-linux-gnu.so(+0x2b17a) [0x7f5ab042517a]
12  /opt/conda/envs/gdf/bin/python(+0x13eb08) [0x5563acd42b08]
13  /opt/conda/envs/gdf/bin/python(_PyEval_EvalFrameDefault+0x5f82) [0x5563acd33112]
14  /opt/conda/envs/gdf/bin/python(+0x12827a) [0x5563acd2c27a]
15  /opt/conda/envs/gdf/bin/python(_PyFunction_Vectorcall+0xd5) [0x5563acd3dc05]
16  /opt/conda/envs/gdf/bin/python(_PyEval_EvalFrameDefault+0x68b) [0x5563acd2d81b]
17  /opt/conda/envs/gdf/bin/python(+0x139ef3) [0x5563acd3def3]
18  /opt/conda/envs/gdf/bin/python(+0x147a16) [0x5563acd4ba16]
19  /opt/conda/envs/gdf/bin/python(+0x2579b1) [0x5563ace5b9b1]
20  /opt/conda/envs/gdf/bin/python(+0xe5817) [0x5563acce9817]
21  /opt/conda/envs/gdf/bin/python(+0x130f83) [0x5563acd34f83]
22  /opt/conda/envs/gdf/bin/python(_PyEval_EvalFrameDefault+0x5ba6) [0x5563acd32d36]
23  /opt/conda/envs/gdf/bin/python(+0x139ef3) [0x5563acd3def3]
24  /opt/conda/envs/gdf/bin/python(_PyEval_EvalFrameDefault+0x68b) [0x5563acd2d81b]
25  /opt/conda/envs/gdf/bin/python(+0x139ef3) [0x5563acd3def3]
26  /opt/conda/envs/gdf/bin/python(_PyEval_EvalFrameDefault+0x68b) [0x5563acd2d81b]
27  /opt/conda/envs/gdf/bin/python(+0x139ef3) [0x5563acd3def3]
28  /opt/conda/envs/gdf/bin/python(_PyEval_EvalFrameDefault+0x68b) [0x5563acd2d81b]
29  /opt/conda/envs/gdf/bin/python(+0x139ef3) [0x5563acd3def3]
30  /opt/conda/envs/gdf/bin/python(_PyEval_EvalFrameDefault+0x68b) [0x5563acd2d81b]
31  /opt/conda/envs/gdf/bin/python(+0x12827a) [0x5563acd2c27a]
32  /opt/conda/envs/gdf/bin/python(_PyFunction_Vectorcall+0xd5) [0x5563acd3dc05]
33  /opt/conda/envs/gdf/bin/python(_PyEval_EvalFrameDefault+0x4e17) [0x5563acd31fa7]
34  /opt/conda/envs/gdf/bin/python(+0x12827a) [0x5563acd2c27a]
35  /opt/conda/envs/gdf/bin/python(+0x147935) [0x5563acd4b935]
36  /opt/conda/envs/gdf/bin/python(PyObject_Call+0xb4) [0x5563acd4c104]
37  /opt/conda/envs/gdf/bin/python(+0x20efc8) [0x5563ace12fc8]
38  /opt/conda/envs/gdf/bin/python(_PyObject_MakeTpCall+0x2fc) [0x5563acd362bc]
39  /opt/conda/envs/gdf/bin/python(_PyEval_EvalFrameDefault+0x402b) [0x5563acd311bb]
40  /opt/conda/envs/gdf/bin/python(+0x139ef3) [0x5563acd3def3]
41  /opt/conda/envs/gdf/bin/python(+0x147c72) [0x5563acd4bc72]
42  /opt/conda/envs/gdf/bin/python(_PyEval_EvalFrameDefault+0x402b) [0x5563acd311bb]
43  /opt/conda/envs/gdf/bin/python(+0x139ef3) [0x5563acd3def3]
44  /opt/conda/envs/gdf/bin/python(_PyEval_EvalFrameDefault+0x68b) [0x5563acd2d81b]
45  /opt/conda/envs/gdf/bin/python(+0x12827a) [0x5563acd2c27a]
46  /opt/conda/envs/gdf/bin/python(_PyFunction_Vectorcall+0xd5) [0x5563acd3dc05]
47  /opt/conda/envs/gdf/bin/python(_PyEval_EvalFrameDefault+0x68b) [0x5563acd2d81b]
48  /opt/conda/envs/gdf/bin/python(+0x139ef3) [0x5563acd3def3]
49  /opt/conda/envs/gdf/bin/python(_PyEval_EvalFrameDefault+0x3d8) [0x5563acd2d568]
50  /opt/conda/envs/gdf/bin/python(+0x12827a) [0x5563acd2c27a]
51  /opt/conda/envs/gdf/bin/python(_PyFunction_Vectorcall+0xd5) [0x5563acd3dc05]
52  /opt/conda/envs/gdf/bin/python(_PyEval_EvalFrameDefault+0x123b) [0x5563acd2e3cb]
53  /opt/conda/envs/gdf/bin/python(+0x12827a) [0x5563acd2c27a]
54  /opt/conda/envs/gdf/bin/python(_PyEval_EvalCodeWithName+0x47) [0x5563acd2bf07]
55  /opt/conda/envs/gdf/bin/python(PyEval_EvalCodeEx+0x39) [0x5563acd2beb9]
56  /opt/conda/envs/gdf/bin/python(PyEval_EvalCode+0x1b) [0x5563acddc8bb]
57  /opt/conda/envs/gdf/bin/python(+0x206adc) [0x5563ace0aadc]
58  /opt/conda/envs/gdf/bin/python(+0x202c24) [0x5563ace06c24]
59  /opt/conda/envs/gdf/bin/python(PyRun_StringFlags+0x9d) [0x5563acdfe7ed]
60  /opt/conda/envs/gdf/bin/python(PyRun_SimpleStringFlags+0x3d) [0x5563acdfe6bd]
61  /opt/conda/envs/gdf/bin/python(Py_RunMain+0x262) [0x5563acdfd8a2]
=================================
2023-07-02 06:07:37,261 - distributed.worker - ERROR - failed during get data with ucx://127.0.0.1:34105 -> ucx://127.0.0.1:48121
Traceback (most recent call last):
  File "/opt/conda/envs/gdf/lib/python3.9/site-packages/distributed/comm/ucx.py", line 333, in write
    await self.ep.send(each_frame)
  File "/opt/conda/envs/gdf/lib/python3.9/site-packages/ucp/core.py", line 650, in send
    return await comm.tag_send(self._ep, buffer, nbytes, tag, name=log)
ucp._libs.exceptions.UCXError: <[Send #007] ep: 0x7f45b1f3c400, tag: 0x97ce39ab8c61f6b0, nbytes: 100000000, type: <class 'cudf.core.buffer.buffer.Buffer'>>: Connection reset by remote peer

During handling of the above exception, another exception occurred:

Traceback (most recent call last):
  File "/opt/conda/envs/gdf/lib/python3.9/site-packages/distributed/worker.py", line 1792, in get_data
    compressed = await comm.write(msg, serializers=serializers)
  File "/opt/conda/envs/gdf/lib/python3.9/site-packages/distributed/utils.py", line 752, in wrapper
    return await func(*args, **kwargs)
  File "/opt/conda/envs/gdf/lib/python3.9/site-packages/distributed/comm/ucx.py", line 337, in write
    raise CommClosedError("While writing, the connection was closed")
distributed.comm.core.CommClosedError: While writing, the connection was closed
2023-07-02 06:07:37,262 - distributed.worker - ERROR - Worker stream died during communication: ucx://127.0.0.1:48121
Traceback (most recent call last):
  File "/opt/conda/envs/gdf/lib/python3.9/site-packages/distributed/comm/ucx.py", line 391, in read
    await self.ep.recv(each_frame)
  File "/opt/conda/envs/gdf/lib/python3.9/site-packages/ucp/core.py", line 725, in recv
    ret = await comm.tag_recv(self._ep, buffer, nbytes, tag, name=log)
ucp._libs.exceptions.UCXError: <[Recv #007] ep: 0x7f45b1f3c240, tag: 0x502e8ec93de4d1d4, nbytes: 100000000, type: <class 'rmm._lib.device_buffer.DeviceBuffer'>>: Connection reset by remote peer

During handling of the above exception, another exception occurred:

Traceback (most recent call last):
  File "/opt/conda/envs/gdf/lib/python3.9/site-packages/distributed/worker.py", line 2066, in gather_dep
    response = await get_data_from_worker(
  File "/opt/conda/envs/gdf/lib/python3.9/site-packages/distributed/worker.py", line 2892, in get_data_from_worker
    response = await send_recv(
  File "/opt/conda/envs/gdf/lib/python3.9/site-packages/distributed/core.py", line 1024, in send_recv
    response = await comm.read(deserializers=deserializers)
  File "/opt/conda/envs/gdf/lib/python3.9/site-packages/distributed/utils.py", line 752, in wrapper
    return await func(*args, **kwargs)
  File "/opt/conda/envs/gdf/lib/python3.9/site-packages/distributed/comm/ucx.py", line 397, in read
    raise CommClosedError(
distributed.comm.core.CommClosedError: Connection closed by writer.
Inner exception: UCXError("<[Recv #007] ep: 0x7f45b1f3c240, tag: 0x502e8ec93de4d1d4, nbytes: 100000000, type: <class 'rmm._lib.device_buffer.DeviceBuffer'>>: Connection reset by remote peer")
2023-07-02 06:07:37,264 - distributed.nanny - WARNING - Restarting worker
2023-07-02 06:07:37,460 - distributed.worker - ERROR - failed during get data with ucx://127.0.0.1:59701 -> ucx://127.0.0.1:45747
Traceback (most recent call last):
  File "/opt/conda/envs/gdf/lib/python3.9/site-packages/distributed/comm/ucx.py", line 333, in write
    await self.ep.send(each_frame)
  File "/opt/conda/envs/gdf/lib/python3.9/site-packages/ucp/core.py", line 650, in send
    return await comm.tag_send(self._ep, buffer, nbytes, tag, name=log)
ucp._libs.exceptions.UCXError: <[Send #007] ep: 0x7f99f70e8340, tag: 0xf40bae742d1b8464, nbytes: 100000000, type: <class 'cudf.core.buffer.buffer.Buffer'>>: Connection reset by remote peer

During handling of the above exception, another exception occurred:

Traceback (most recent call last):
  File "/opt/conda/envs/gdf/lib/python3.9/site-packages/distributed/worker.py", line 1792, in get_data
    compressed = await comm.write(msg, serializers=serializers)
  File "/opt/conda/envs/gdf/lib/python3.9/site-packages/distributed/utils.py", line 752, in wrapper
    return await func(*args, **kwargs)
  File "/opt/conda/envs/gdf/lib/python3.9/site-packages/distributed/comm/ucx.py", line 337, in write
    raise CommClosedError("While writing, the connection was closed")
distributed.comm.core.CommClosedError: While writing, the connection was closed
2023-07-02 06:07:37,461 - distributed.worker - ERROR - failed during get data with ucx://127.0.0.1:59701 -> ucx://127.0.0.1:48121
Traceback (most recent call last):
  File "/opt/conda/envs/gdf/lib/python3.9/site-packages/distributed/comm/ucx.py", line 333, in write
    await self.ep.send(each_frame)
  File "/opt/conda/envs/gdf/lib/python3.9/site-packages/ucp/core.py", line 650, in send
    return await comm.tag_send(self._ep, buffer, nbytes, tag, name=log)
ucp._libs.exceptions.UCXError: <[Send #008] ep: 0x7f99f70e8400, tag: 0xb82384c9e0622f87, nbytes: 100000000, type: <class 'cudf.core.buffer.buffer.Buffer'>>: Connection reset by remote peer

During handling of the above exception, another exception occurred:

Traceback (most recent call last):
  File "/opt/conda/envs/gdf/lib/python3.9/site-packages/distributed/worker.py", line 1792, in get_data
    compressed = await comm.write(msg, serializers=serializers)
  File "/opt/conda/envs/gdf/lib/python3.9/site-packages/distributed/utils.py", line 752, in wrapper
    return await func(*args, **kwargs)
  File "/opt/conda/envs/gdf/lib/python3.9/site-packages/distributed/comm/ucx.py", line 337, in write
    raise CommClosedError("While writing, the connection was closed")
distributed.comm.core.CommClosedError: While writing, the connection was closed
2023-07-02 06:07:37,462 - distributed.worker - ERROR - Worker stream died during communication: ucx://127.0.0.1:45747
Traceback (most recent call last):
  File "/opt/conda/envs/gdf/lib/python3.9/site-packages/distributed/comm/ucx.py", line 391, in read
    await self.ep.recv(each_frame)
  File "/opt/conda/envs/gdf/lib/python3.9/site-packages/ucp/core.py", line 725, in recv
    ret = await comm.tag_recv(self._ep, buffer, nbytes, tag, name=log)
ucp._libs.exceptions.UCXError: <[Recv #007] ep: 0x7f99f70e8180, tag: 0xd7dc56242bf63bd2, nbytes: 100000000, type: <class 'rmm._lib.device_buffer.DeviceBuffer'>>: Connection reset by remote peer

During handling of the above exception, another exception occurred:

Traceback (most recent call last):
  File "/opt/conda/envs/gdf/lib/python3.9/site-packages/distributed/worker.py", line 2066, in gather_dep
    response = await get_data_from_worker(
  File "/opt/conda/envs/gdf/lib/python3.9/site-packages/distributed/worker.py", line 2892, in get_data_from_worker
    response = await send_recv(
  File "/opt/conda/envs/gdf/lib/python3.9/site-packages/distributed/core.py", line 1024, in send_recv
    response = await comm.read(deserializers=deserializers)
  File "/opt/conda/envs/gdf/lib/python3.9/site-packages/distributed/utils.py", line 752, in wrapper
    return await func(*args, **kwargs)
  File "/opt/conda/envs/gdf/lib/python3.9/site-packages/distributed/comm/ucx.py", line 397, in read
    raise CommClosedError(
distributed.comm.core.CommClosedError: Connection closed by writer.
Inner exception: UCXError("<[Recv #007] ep: 0x7f99f70e8180, tag: 0xd7dc56242bf63bd2, nbytes: 100000000, type: <class 'rmm._lib.device_buffer.DeviceBuffer'>>: Connection reset by remote peer")
2023-07-02 06:07:37,478 - distributed.worker - ERROR - failed during get data with ucx://127.0.0.1:34105 -> ucx://127.0.0.1:45747
Traceback (most recent call last):
  File "/opt/conda/envs/gdf/lib/python3.9/site-packages/distributed/comm/ucx.py", line 333, in write
    await self.ep.send(each_frame)
  File "/opt/conda/envs/gdf/lib/python3.9/site-packages/ucp/core.py", line 650, in send
    return await comm.tag_send(self._ep, buffer, nbytes, tag, name=log)
ucp._libs.exceptions.UCXError: <[Send #007] ep: 0x7f45b1f3c340, tag: 0x886c7f7b2eea91b2, nbytes: 100000000, type: <class 'cudf.core.buffer.buffer.Buffer'>>: Connection reset by remote peer

During handling of the above exception, another exception occurred:

Traceback (most recent call last):
  File "/opt/conda/envs/gdf/lib/python3.9/site-packages/distributed/worker.py", line 1792, in get_data
    compressed = await comm.write(msg, serializers=serializers)
  File "/opt/conda/envs/gdf/lib/python3.9/site-packages/distributed/utils.py", line 752, in wrapper
    return await func(*args, **kwargs)
  File "/opt/conda/envs/gdf/lib/python3.9/site-packages/distributed/comm/ucx.py", line 337, in write
    raise CommClosedError("While writing, the connection was closed")
distributed.comm.core.CommClosedError: While writing, the connection was closed
2023-07-02 06:07:37,479 - distributed.worker - ERROR - Worker stream died during communication: ucx://127.0.0.1:45747
Traceback (most recent call last):
  File "/opt/conda/envs/gdf/lib/python3.9/site-packages/distributed/comm/ucx.py", line 391, in read
    await self.ep.recv(each_frame)
  File "/opt/conda/envs/gdf/lib/python3.9/site-packages/ucp/core.py", line 725, in recv
    ret = await comm.tag_recv(self._ep, buffer, nbytes, tag, name=log)
ucp._libs.exceptions.UCXError: <[Recv #007] ep: 0x7f45b1f3c140, tag: 0xdfea8649d2ad8404, nbytes: 100000000, type: <class 'rmm._lib.device_buffer.DeviceBuffer'>>: Connection reset by remote peer

During handling of the above exception, another exception occurred:

Traceback (most recent call last):
  File "/opt/conda/envs/gdf/lib/python3.9/site-packages/distributed/worker.py", line 2066, in gather_dep
    response = await get_data_from_worker(
  File "/opt/conda/envs/gdf/lib/python3.9/site-packages/distributed/worker.py", line 2892, in get_data_from_worker
    response = await send_recv(
  File "/opt/conda/envs/gdf/lib/python3.9/site-packages/distributed/core.py", line 1024, in send_recv
    response = await comm.read(deserializers=deserializers)
  File "/opt/conda/envs/gdf/lib/python3.9/site-packages/distributed/utils.py", line 752, in wrapper
    return await func(*args, **kwargs)
  File "/opt/conda/envs/gdf/lib/python3.9/site-packages/distributed/comm/ucx.py", line 397, in read
    raise CommClosedError(
distributed.comm.core.CommClosedError: Connection closed by writer.
Inner exception: UCXError("<[Recv #007] ep: 0x7f45b1f3c140, tag: 0xdfea8649d2ad8404, nbytes: 100000000, type: <class 'rmm._lib.device_buffer.DeviceBuffer'>>: Connection reset by remote peer")
2023-07-02 06:07:37,570 - distributed.nanny - WARNING - Restarting worker
2023-07-02 06:07:38,582 - distributed.preloading - INFO - Creating preload: dask_cuda.initialize
2023-07-02 06:07:38,582 - distributed.preloading - INFO - Import preload module: dask_cuda.initialize
2023-07-02 06:07:38,583 - distributed.preloading - INFO - Creating preload: dask_cuda.initialize
2023-07-02 06:07:38,584 - distributed.preloading - INFO - Import preload module: dask_cuda.initialize
2023-07-02 06:07:38,794 - distributed.preloading - INFO - Creating preload: dask_cuda.initialize
2023-07-02 06:07:38,794 - distributed.preloading - INFO - Import preload module: dask_cuda.initialize
2023-07-02 06:07:38,841 - distributed.preloading - INFO - Creating preload: dask_cuda.initialize
2023-07-02 06:07:38,841 - distributed.preloading - INFO - Import preload module: dask_cuda.initialize
2023-07-02 06:07:39,040 - distributed.preloading - INFO - Creating preload: dask_cuda.initialize
2023-07-02 06:07:39,040 - distributed.preloading - INFO - Import preload module: dask_cuda.initialize
/opt/conda/envs/gdf/lib/python3.9/multiprocessing/resource_tracker.py:216: UserWarning: resource_tracker: There appear to be 48 leaked semaphore objects to clean up at shutdown
  warnings.warn('resource_tracker: There appear to be %d '
