2023-06-04 06:07:58,888 - distributed.preloading - INFO - Creating preload: dask_cuda.initialize
2023-06-04 06:07:58,888 - distributed.preloading - INFO - Import preload module: dask_cuda.initialize
2023-06-04 06:07:58,917 - distributed.preloading - INFO - Creating preload: dask_cuda.initialize
2023-06-04 06:07:58,917 - distributed.preloading - INFO - Import preload module: dask_cuda.initialize
2023-06-04 06:07:58,989 - distributed.preloading - INFO - Creating preload: dask_cuda.initialize
2023-06-04 06:07:58,989 - distributed.preloading - INFO - Import preload module: dask_cuda.initialize
2023-06-04 06:07:59,020 - distributed.preloading - INFO - Creating preload: dask_cuda.initialize
2023-06-04 06:07:59,020 - distributed.preloading - INFO - Import preload module: dask_cuda.initialize
2023-06-04 06:07:59,021 - distributed.preloading - INFO - Creating preload: dask_cuda.initialize
2023-06-04 06:07:59,021 - distributed.preloading - INFO - Import preload module: dask_cuda.initialize
2023-06-04 06:07:59,023 - distributed.preloading - INFO - Creating preload: dask_cuda.initialize
2023-06-04 06:07:59,023 - distributed.preloading - INFO - Import preload module: dask_cuda.initialize
2023-06-04 06:07:59,058 - distributed.preloading - INFO - Creating preload: dask_cuda.initialize
2023-06-04 06:07:59,058 - distributed.preloading - INFO - Import preload module: dask_cuda.initialize
2023-06-04 06:07:59,061 - distributed.preloading - INFO - Creating preload: dask_cuda.initialize
2023-06-04 06:07:59,062 - distributed.preloading - INFO - Import preload module: dask_cuda.initialize
[dgx13:74609:0:74609] Caught signal 11 (Segmentation fault: address not mapped to object at address 0x448)
==== backtrace (tid:  74609) ====
 0  /opt/conda/envs/gdf/lib/libucs.so.0(ucs_handle_error+0x2fd) [0x7faf149a9f1d]
 1  /opt/conda/envs/gdf/lib/libucs.so.0(+0x29114) [0x7faf149aa114]
 2  /opt/conda/envs/gdf/lib/libucs.so.0(+0x292da) [0x7faf149aa2da]
 3  /usr/lib/x86_64-linux-gnu/libpthread.so.0(+0x14420) [0x7fafa73b0420]
 4  /opt/conda/envs/gdf/lib/libucp.so.0(ucp_mem_type_unpack+0x14) [0x7faf14a235d4]
 5  /opt/conda/envs/gdf/lib/libucp.so.0(ucp_rndv_data_handler+0x4e9) [0x7faf14a48859]
 6  /opt/conda/envs/gdf/lib/libuct.so.0(+0x2041f) [0x7faf1496541f]
 7  /opt/conda/envs/gdf/lib/libuct.so.0(+0x23788) [0x7faf14968788]
 8  /opt/conda/envs/gdf/lib/libucs.so.0(ucs_event_set_wait+0xb9) [0x7faf149b2989]
 9  /opt/conda/envs/gdf/lib/libuct.so.0(uct_tcp_iface_progress+0x7d) [0x7faf1496761d]
10  /opt/conda/envs/gdf/lib/libucp.so.0(ucp_worker_progress+0x5a) [0x7faf14a20c4a]
11  /opt/conda/envs/gdf/lib/python3.9/site-packages/ucp/_libs/ucx_api.cpython-39-x86_64-linux-gnu.so(+0x2b17a) [0x7faf14acb17a]
12  /opt/conda/envs/gdf/bin/python(+0x13eb08) [0x561592b09b08]
13  /opt/conda/envs/gdf/bin/python(_PyEval_EvalFrameDefault+0x5f82) [0x561592afa112]
14  /opt/conda/envs/gdf/bin/python(+0x12827a) [0x561592af327a]
15  /opt/conda/envs/gdf/bin/python(_PyFunction_Vectorcall+0xd5) [0x561592b04c05]
16  /opt/conda/envs/gdf/bin/python(_PyEval_EvalFrameDefault+0x68b) [0x561592af481b]
17  /opt/conda/envs/gdf/bin/python(+0x14e70e) [0x561592b1970e]
18  /opt/conda/envs/gdf/lib/python3.9/lib-dynload/_asyncio.cpython-39-x86_64-linux-gnu.so(+0x82fe) [0x7faf26d572fe]
19  /opt/conda/envs/gdf/bin/python(_PyObject_MakeTpCall+0x2fc) [0x561592afd2bc]
20  /opt/conda/envs/gdf/bin/python(+0xe5817) [0x561592ab0817]
21  /opt/conda/envs/gdf/bin/python(+0x130f83) [0x561592afbf83]
22  /opt/conda/envs/gdf/bin/python(_PyEval_EvalFrameDefault+0x5ba6) [0x561592af9d36]
23  /opt/conda/envs/gdf/bin/python(+0x139ef3) [0x561592b04ef3]
24  /opt/conda/envs/gdf/bin/python(_PyEval_EvalFrameDefault+0x68b) [0x561592af481b]
25  /opt/conda/envs/gdf/bin/python(+0x139ef3) [0x561592b04ef3]
26  /opt/conda/envs/gdf/bin/python(_PyEval_EvalFrameDefault+0x68b) [0x561592af481b]
27  /opt/conda/envs/gdf/bin/python(+0x139ef3) [0x561592b04ef3]
28  /opt/conda/envs/gdf/bin/python(_PyEval_EvalFrameDefault+0x68b) [0x561592af481b]
29  /opt/conda/envs/gdf/bin/python(+0x139ef3) [0x561592b04ef3]
30  /opt/conda/envs/gdf/bin/python(_PyEval_EvalFrameDefault+0x68b) [0x561592af481b]
31  /opt/conda/envs/gdf/bin/python(+0x12827a) [0x561592af327a]
32  /opt/conda/envs/gdf/bin/python(_PyFunction_Vectorcall+0xd5) [0x561592b04c05]
33  /opt/conda/envs/gdf/bin/python(_PyEval_EvalFrameDefault+0x4e17) [0x561592af8fa7]
34  /opt/conda/envs/gdf/bin/python(+0x12827a) [0x561592af327a]
35  /opt/conda/envs/gdf/bin/python(+0x147935) [0x561592b12935]
36  /opt/conda/envs/gdf/bin/python(PyObject_Call+0xb4) [0x561592b13104]
37  /opt/conda/envs/gdf/bin/python(+0x20efc8) [0x561592bd9fc8]
38  /opt/conda/envs/gdf/bin/python(_PyObject_MakeTpCall+0x2fc) [0x561592afd2bc]
39  /opt/conda/envs/gdf/bin/python(_PyEval_EvalFrameDefault+0x402b) [0x561592af81bb]
40  /opt/conda/envs/gdf/bin/python(+0x139ef3) [0x561592b04ef3]
41  /opt/conda/envs/gdf/bin/python(+0x147c72) [0x561592b12c72]
42  /opt/conda/envs/gdf/bin/python(_PyEval_EvalFrameDefault+0x402b) [0x561592af81bb]
43  /opt/conda/envs/gdf/bin/python(+0x139ef3) [0x561592b04ef3]
44  /opt/conda/envs/gdf/bin/python(_PyEval_EvalFrameDefault+0x68b) [0x561592af481b]
45  /opt/conda/envs/gdf/bin/python(+0x12827a) [0x561592af327a]
46  /opt/conda/envs/gdf/bin/python(_PyFunction_Vectorcall+0xd5) [0x561592b04c05]
47  /opt/conda/envs/gdf/bin/python(_PyEval_EvalFrameDefault+0x68b) [0x561592af481b]
48  /opt/conda/envs/gdf/bin/python(+0x139ef3) [0x561592b04ef3]
49  /opt/conda/envs/gdf/bin/python(_PyEval_EvalFrameDefault+0x3d8) [0x561592af4568]
50  /opt/conda/envs/gdf/bin/python(+0x12827a) [0x561592af327a]
51  /opt/conda/envs/gdf/bin/python(_PyFunction_Vectorcall+0xd5) [0x561592b04c05]
52  /opt/conda/envs/gdf/bin/python(_PyEval_EvalFrameDefault+0x123b) [0x561592af53cb]
53  /opt/conda/envs/gdf/bin/python(+0x12827a) [0x561592af327a]
54  /opt/conda/envs/gdf/bin/python(_PyEval_EvalCodeWithName+0x47) [0x561592af2f07]
55  /opt/conda/envs/gdf/bin/python(PyEval_EvalCodeEx+0x39) [0x561592af2eb9]
56  /opt/conda/envs/gdf/bin/python(PyEval_EvalCode+0x1b) [0x561592ba38bb]
57  /opt/conda/envs/gdf/bin/python(+0x206adc) [0x561592bd1adc]
58  /opt/conda/envs/gdf/bin/python(+0x202c24) [0x561592bcdc24]
59  /opt/conda/envs/gdf/bin/python(PyRun_StringFlags+0x9d) [0x561592bc57ed]
60  /opt/conda/envs/gdf/bin/python(PyRun_SimpleStringFlags+0x3d) [0x561592bc56bd]
61  /opt/conda/envs/gdf/bin/python(Py_RunMain+0x262) [0x561592bc48a2]
=================================
[dgx13:74594:0:74594] Caught signal 11 (Segmentation fault: address not mapped to object at address 0x448)
==== backtrace (tid:  74594) ====
 0  /opt/conda/envs/gdf/lib/libucs.so.0(ucs_handle_error+0x2fd) [0x7f9a412d3f1d]
 1  /opt/conda/envs/gdf/lib/libucs.so.0(+0x29114) [0x7f9a412d4114]
 2  /opt/conda/envs/gdf/lib/libucs.so.0(+0x292da) [0x7f9a412d42da]
 3  /usr/lib/x86_64-linux-gnu/libpthread.so.0(+0x14420) [0x7f9ae5bb5420]
 4  /opt/conda/envs/gdf/lib/libucp.so.0(ucp_mem_type_unpack+0x14) [0x7f9a4134d5d4]
 5  /opt/conda/envs/gdf/lib/libucp.so.0(ucp_rndv_data_handler+0x4e9) [0x7f9a41372859]
 6  /opt/conda/envs/gdf/lib/libuct.so.0(+0x2041f) [0x7f9a4128f41f]
 7  /opt/conda/envs/gdf/lib/libuct.so.0(+0x23788) [0x7f9a41292788]
 8  /opt/conda/envs/gdf/lib/libucs.so.0(ucs_event_set_wait+0xb9) [0x7f9a412dc989]
 9  /opt/conda/envs/gdf/lib/libuct.so.0(uct_tcp_iface_progress+0x7d) [0x7f9a4129161d]
10  /opt/conda/envs/gdf/lib/libucp.so.0(ucp_worker_progress+0x5a) [0x7f9a4134ac4a]
11  /opt/conda/envs/gdf/lib/python3.9/site-packages/ucp/_libs/ucx_api.cpython-39-x86_64-linux-gnu.so(+0x2b17a) [0x7f9a413f517a]
12  /opt/conda/envs/gdf/bin/python(+0x13eb08) [0x55c94f678b08]
13  /opt/conda/envs/gdf/bin/python(_PyEval_EvalFrameDefault+0x5f82) [0x55c94f669112]
14  /opt/conda/envs/gdf/bin/python(+0x12827a) [0x55c94f66227a]
15  /opt/conda/envs/gdf/bin/python(_PyFunction_Vectorcall+0xd5) [0x55c94f673c05]
16  /opt/conda/envs/gdf/bin/python(_PyEval_EvalFrameDefault+0x68b) [0x55c94f66381b]
17  /opt/conda/envs/gdf/bin/python(+0x14e70e) [0x55c94f68870e]
18  /opt/conda/envs/gdf/lib/python3.9/lib-dynload/_asyncio.cpython-39-x86_64-linux-gnu.so(+0x82fe) [0x7f9a6555e2fe]
19  /opt/conda/envs/gdf/bin/python(_PyObject_MakeTpCall+0x2fc) [0x55c94f66c2bc]
20  /opt/conda/envs/gdf/bin/python(+0xe5817) [0x55c94f61f817]
21  /opt/conda/envs/gdf/bin/python(+0x130f83) [0x55c94f66af83]
22  /opt/conda/envs/gdf/bin/python(_PyEval_EvalFrameDefault+0x5ba6) [0x55c94f668d36]
23  /opt/conda/envs/gdf/bin/python(+0x139ef3) [0x55c94f673ef3]
24  /opt/conda/envs/gdf/bin/python(_PyEval_EvalFrameDefault+0x68b) [0x55c94f66381b]
25  /opt/conda/envs/gdf/bin/python(+0x139ef3) [0x55c94f673ef3]
26  /opt/conda/envs/gdf/bin/python(_PyEval_EvalFrameDefault+0x68b) [0x55c94f66381b]
27  /opt/conda/envs/gdf/bin/python(+0x139ef3) [0x55c94f673ef3]
28  /opt/conda/envs/gdf/bin/python(_PyEval_EvalFrameDefault+0x68b) [0x55c94f66381b]
29  /opt/conda/envs/gdf/bin/python(+0x139ef3) [0x55c94f673ef3]
30  /opt/conda/envs/gdf/bin/python(_PyEval_EvalFrameDefault+0x68b) [0x55c94f66381b]
31  /opt/conda/envs/gdf/bin/python(+0x12827a) [0x55c94f66227a]
32  /opt/conda/envs/gdf/bin/python(_PyFunction_Vectorcall+0xd5) [0x55c94f673c05]
33  /opt/conda/envs/gdf/bin/python(_PyEval_EvalFrameDefault+0x4e17) [0x55c94f667fa7]
34  /opt/conda/envs/gdf/bin/python(+0x12827a) [0x55c94f66227a]
35  /opt/conda/envs/gdf/bin/python(+0x147935) [0x55c94f681935]
36  /opt/conda/envs/gdf/bin/python(PyObject_Call+0xb4) [0x55c94f682104]
37  /opt/conda/envs/gdf/bin/python(+0x20efc8) [0x55c94f748fc8]
38  /opt/conda/envs/gdf/bin/python(_PyObject_MakeTpCall+0x2fc) [0x55c94f66c2bc]
39  /opt/conda/envs/gdf/bin/python(_PyEval_EvalFrameDefault+0x402b) [0x55c94f6671bb]
40  /opt/conda/envs/gdf/bin/python(+0x139ef3) [0x55c94f673ef3]
41  /opt/conda/envs/gdf/bin/python(+0x147c72) [0x55c94f681c72]
42  /opt/conda/envs/gdf/bin/python(_PyEval_EvalFrameDefault+0x402b) [0x55c94f6671bb]
43  /opt/conda/envs/gdf/bin/python(+0x139ef3) [0x55c94f673ef3]
44  /opt/conda/envs/gdf/bin/python(_PyEval_EvalFrameDefault+0x68b) [0x55c94f66381b]
45  /opt/conda/envs/gdf/bin/python(+0x12827a) [0x55c94f66227a]
46  /opt/conda/envs/gdf/bin/python(_PyFunction_Vectorcall+0xd5) [0x55c94f673c05]
47  /opt/conda/envs/gdf/bin/python(_PyEval_EvalFrameDefault+0x68b) [0x55c94f66381b]
48  /opt/conda/envs/gdf/bin/python(+0x139ef3) [0x55c94f673ef3]
49  /opt/conda/envs/gdf/bin/python(_PyEval_EvalFrameDefault+0x3d8) [0x55c94f663568]
50  /opt/conda/envs/gdf/bin/python(+0x12827a) [0x55c94f66227a]
51  /opt/conda/envs/gdf/bin/python(_PyFunction_Vectorcall+0xd5) [0x55c94f673c05]
52  /opt/conda/envs/gdf/bin/python(_PyEval_EvalFrameDefault+0x123b) [0x55c94f6643cb]
53  /opt/conda/envs/gdf/bin/python(+0x12827a) [0x55c94f66227a]
54  /opt/conda/envs/gdf/bin/python(_PyEval_EvalCodeWithName+0x47) [0x55c94f661f07]
55  /opt/conda/envs/gdf/bin/python(PyEval_EvalCodeEx+0x39) [0x55c94f661eb9]
56  /opt/conda/envs/gdf/bin/python(PyEval_EvalCode+0x1b) [0x55c94f7128bb]
57  /opt/conda/envs/gdf/bin/python(+0x206adc) [0x55c94f740adc]
58  /opt/conda/envs/gdf/bin/python(+0x202c24) [0x55c94f73cc24]
59  /opt/conda/envs/gdf/bin/python(PyRun_StringFlags+0x9d) [0x55c94f7347ed]
60  /opt/conda/envs/gdf/bin/python(PyRun_SimpleStringFlags+0x3d) [0x55c94f7346bd]
61  /opt/conda/envs/gdf/bin/python(Py_RunMain+0x262) [0x55c94f7338a2]
=================================
[dgx13:74615:0:74615] Caught signal 11 (Segmentation fault: address not mapped to object at address 0x448)
==== backtrace (tid:  74615) ====
 0  /opt/conda/envs/gdf/lib/libucs.so.0(ucs_handle_error+0x2fd) [0x7f98b32a9f1d]
 1  /opt/conda/envs/gdf/lib/libucs.so.0(+0x29114) [0x7f98b32aa114]
 2  /opt/conda/envs/gdf/lib/libucs.so.0(+0x292da) [0x7f98b32aa2da]
 3  /usr/lib/x86_64-linux-gnu/libpthread.so.0(+0x14420) [0x7f9953cb2420]
 4  /opt/conda/envs/gdf/lib/libucp.so.0(ucp_mem_type_unpack+0x14) [0x7f98b33235d4]
 5  /opt/conda/envs/gdf/lib/libucp.so.0(ucp_rndv_data_handler+0x4e9) [0x7f98b3348859]
 6  /opt/conda/envs/gdf/lib/libuct.so.0(+0x2041f) [0x7f98b326541f]
 7  /opt/conda/envs/gdf/lib/libuct.so.0(+0x23788) [0x7f98b3268788]
 8  /opt/conda/envs/gdf/lib/libucs.so.0(ucs_event_set_wait+0xb9) [0x7f98b32b2989]
 9  /opt/conda/envs/gdf/lib/libuct.so.0(uct_tcp_iface_progress+0x7d) [0x7f98b326761d]
10  /opt/conda/envs/gdf/lib/libucp.so.0(ucp_worker_progress+0x5a) [0x7f98b3320c4a]
11  /opt/conda/envs/gdf/lib/python3.9/site-packages/ucp/_libs/ucx_api.cpython-39-x86_64-linux-gnu.so(+0x2b17a) [0x7f98b33cb17a]
12  /opt/conda/envs/gdf/bin/python(+0x13eb08) [0x55df937f0b08]
13  /opt/conda/envs/gdf/bin/python(_PyEval_EvalFrameDefault+0x5f82) [0x55df937e1112]
14  /opt/conda/envs/gdf/bin/python(+0x12827a) [0x55df937da27a]
15  /opt/conda/envs/gdf/bin/python(_PyFunction_Vectorcall+0xd5) [0x55df937ebc05]
16  /opt/conda/envs/gdf/bin/python(_PyEval_EvalFrameDefault+0x68b) [0x55df937db81b]
17  /opt/conda/envs/gdf/bin/python(+0x14e70e) [0x55df9380070e]
18  /opt/conda/envs/gdf/lib/python3.9/lib-dynload/_asyncio.cpython-39-x86_64-linux-gnu.so(+0x82fe) [0x7f98d36562fe]
19  /opt/conda/envs/gdf/bin/python(_PyObject_MakeTpCall+0x2fc) [0x55df937e42bc]
20  /opt/conda/envs/gdf/bin/python(+0xe5817) [0x55df93797817]
21  /opt/conda/envs/gdf/bin/python(+0x130f83) [0x55df937e2f83]
22  /opt/conda/envs/gdf/bin/python(_PyEval_EvalFrameDefault+0x5ba6) [0x55df937e0d36]
23  /opt/conda/envs/gdf/bin/python(+0x139ef3) [0x55df937ebef3]
24  /opt/conda/envs/gdf/bin/python(_PyEval_EvalFrameDefault+0x68b) [0x55df937db81b]
25  /opt/conda/envs/gdf/bin/python(+0x139ef3) [0x55df937ebef3]
26  /opt/conda/envs/gdf/bin/python(_PyEval_EvalFrameDefault+0x68b) [0x55df937db81b]
27  /opt/conda/envs/gdf/bin/python(+0x139ef3) [0x55df937ebef3]
28  /opt/conda/envs/gdf/bin/python(_PyEval_EvalFrameDefault+0x68b) [0x55df937db81b]
29  /opt/conda/envs/gdf/bin/python(+0x139ef3) [0x55df937ebef3]
30  /opt/conda/envs/gdf/bin/python(_PyEval_EvalFrameDefault+0x68b) [0x55df937db81b]
31  /opt/conda/envs/gdf/bin/python(+0x12827a) [0x55df937da27a]
32  /opt/conda/envs/gdf/bin/python(_PyFunction_Vectorcall+0xd5) [0x55df937ebc05]
33  /opt/conda/envs/gdf/bin/python(_PyEval_EvalFrameDefault+0x4e17) [0x55df937dffa7]
34  /opt/conda/envs/gdf/bin/python(+0x12827a) [0x55df937da27a]
35  /opt/conda/envs/gdf/bin/python(+0x147935) [0x55df937f9935]
36  /opt/conda/envs/gdf/bin/python(PyObject_Call+0xb4) [0x55df937fa104]
37  /opt/conda/envs/gdf/bin/python(+0x20efc8) [0x55df938c0fc8]
38  /opt/conda/envs/gdf/bin/python(_PyObject_MakeTpCall+0x2fc) [0x55df937e42bc]
39  /opt/conda/envs/gdf/bin/python(_PyEval_EvalFrameDefault+0x402b) [0x55df937df1bb]
40  /opt/conda/envs/gdf/bin/python(+0x139ef3) [0x55df937ebef3]
41  /opt/conda/envs/gdf/bin/python(+0x147c72) [0x55df937f9c72]
42  /opt/conda/envs/gdf/bin/python(_PyEval_EvalFrameDefault+0x402b) [0x55df937df1bb]
43  /opt/conda/envs/gdf/bin/python(+0x139ef3) [0x55df937ebef3]
44  /opt/conda/envs/gdf/bin/python(_PyEval_EvalFrameDefault+0x68b) [0x55df937db81b]
45  /opt/conda/envs/gdf/bin/python(+0x12827a) [0x55df937da27a]
46  /opt/conda/envs/gdf/bin/python(_PyFunction_Vectorcall+0xd5) [0x55df937ebc05]
47  /opt/conda/envs/gdf/bin/python(_PyEval_EvalFrameDefault+0x68b) [0x55df937db81b]
48  /opt/conda/envs/gdf/bin/python(+0x139ef3) [0x55df937ebef3]
49  /opt/conda/envs/gdf/bin/python(_PyEval_EvalFrameDefault+0x3d8) [0x55df937db568]
50  /opt/conda/envs/gdf/bin/python(+0x12827a) [0x55df937da27a]
51  /opt/conda/envs/gdf/bin/python(_PyFunction_Vectorcall+0xd5) [0x55df937ebc05]
52  /opt/conda/envs/gdf/bin/python(_PyEval_EvalFrameDefault+0x123b) [0x55df937dc3cb]
53  /opt/conda/envs/gdf/bin/python(+0x12827a) [0x55df937da27a]
54  /opt/conda/envs/gdf/bin/python(_PyEval_EvalCodeWithName+0x47) [0x55df937d9f07]
55  /opt/conda/envs/gdf/bin/python(PyEval_EvalCodeEx+0x39) [0x55df937d9eb9]
56  /opt/conda/envs/gdf/bin/python(PyEval_EvalCode+0x1b) [0x55df9388a8bb]
57  /opt/conda/envs/gdf/bin/python(+0x206adc) [0x55df938b8adc]
58  /opt/conda/envs/gdf/bin/python(+0x202c24) [0x55df938b4c24]
59  /opt/conda/envs/gdf/bin/python(PyRun_StringFlags+0x9d) [0x55df938ac7ed]
60  /opt/conda/envs/gdf/bin/python(PyRun_SimpleStringFlags+0x3d) [0x55df938ac6bd]
61  /opt/conda/envs/gdf/bin/python(Py_RunMain+0x262) [0x55df938ab8a2]
=================================
[dgx13:74618:0:74618] Caught signal 11 (Segmentation fault: address not mapped to object at address 0x448)
[dgx13:74602:0:74602] Caught signal 11 (Segmentation fault: address not mapped to object at address 0x448)
==== backtrace (tid:  74618) ====
 0  /opt/conda/envs/gdf/lib/libucs.so.0(ucs_handle_error+0x2fd) [0x7f97e089df1d]
 1  /opt/conda/envs/gdf/lib/libucs.so.0(+0x29114) [0x7f97e089e114]
 2  /opt/conda/envs/gdf/lib/libucs.so.0(+0x292da) [0x7f97e089e2da]
 3  /usr/lib/x86_64-linux-gnu/libpthread.so.0(+0x14420) [0x7f98732a3420]
 4  /opt/conda/envs/gdf/lib/libucp.so.0(ucp_mem_type_unpack+0x14) [0x7f97e09175d4]
 5  /opt/conda/envs/gdf/lib/libucp.so.0(ucp_rndv_data_handler+0x4e9) [0x7f97e093c859]
 6  /opt/conda/envs/gdf/lib/libuct.so.0(+0x2041f) [0x7f97e085941f]
 7  /opt/conda/envs/gdf/lib/libuct.so.0(+0x23788) [0x7f97e085c788]
 8  /opt/conda/envs/gdf/lib/libucs.so.0(ucs_event_set_wait+0xb9) [0x7f97e08a6989]
 9  /opt/conda/envs/gdf/lib/libuct.so.0(uct_tcp_iface_progress+0x7d) [0x7f97e085b61d]
10  /opt/conda/envs/gdf/lib/libucp.so.0(ucp_worker_progress+0x5a) [0x7f97e0914c4a]
11  /opt/conda/envs/gdf/lib/python3.9/site-packages/ucp/_libs/ucx_api.cpython-39-x86_64-linux-gnu.so(+0x2b17a) [0x7f97e09bf17a]
12  /opt/conda/envs/gdf/bin/python(+0x13eb08) [0x555f53ad5b08]
13  /opt/conda/envs/gdf/bin/python(_PyEval_EvalFrameDefault+0x5f82) [0x555f53ac6112]
14  /opt/conda/envs/gdf/bin/python(+0x12827a) [0x555f53abf27a]
15  /opt/conda/envs/gdf/bin/python(_PyFunction_Vectorcall+0xd5) [0x555f53ad0c05]
16  /opt/conda/envs/gdf/bin/python(_PyEval_EvalFrameDefault+0x68b) [0x555f53ac081b]
17  /opt/conda/envs/gdf/bin/python(+0x139ef3) [0x555f53ad0ef3]
18  /opt/conda/envs/gdf/bin/python(+0x147a16) [0x555f53adea16]
19  /opt/conda/envs/gdf/bin/python(+0x2579b1) [0x555f53bee9b1]
20  /opt/conda/envs/gdf/bin/python(+0xe5817) [0x555f53a7c817]
21  /opt/conda/envs/gdf/bin/python(+0x130f83) [0x555f53ac7f83]
22  /opt/conda/envs/gdf/bin/python(_PyEval_EvalFrameDefault+0x5ba6) [0x555f53ac5d36]
23  /opt/conda/envs/gdf/bin/python(+0x139ef3) [0x555f53ad0ef3]
24  /opt/conda/envs/gdf/bin/python(_PyEval_EvalFrameDefault+0x68b) [0x555f53ac081b]
25  /opt/conda/envs/gdf/bin/python(+0x139ef3) [0x555f53ad0ef3]
26  /opt/conda/envs/gdf/bin/python(_PyEval_EvalFrameDefault+0x68b) [0x555f53ac081b]
27  /opt/conda/envs/gdf/bin/python(+0x139ef3) [0x555f53ad0ef3]
28  /opt/conda/envs/gdf/bin/python(_PyEval_EvalFrameDefault+0x68b) [0x555f53ac081b]
29  /opt/conda/envs/gdf/bin/python(+0x139ef3) [0x555f53ad0ef3]
30  /opt/conda/envs/gdf/bin/python(_PyEval_EvalFrameDefault+0x68b) [0x555f53ac081b]
31  /opt/conda/envs/gdf/bin/python(+0x12827a) [0x555f53abf27a]
32  /opt/conda/envs/gdf/bin/python(_PyFunction_Vectorcall+0xd5) [0x555f53ad0c05]
33  /opt/conda/envs/gdf/bin/python(_PyEval_EvalFrameDefault+0x4e17) [0x555f53ac4fa7]
34  /opt/conda/envs/gdf/bin/python(+0x12827a) [0x555f53abf27a]
35  /opt/conda/envs/gdf/bin/python(+0x147935) [0x555f53ade935]
36  /opt/conda/envs/gdf/bin/python(PyObject_Call+0xb4) [0x555f53adf104]
37  /opt/conda/envs/gdf/bin/python(+0x20efc8) [0x555f53ba5fc8]
38  /opt/conda/envs/gdf/bin/python(_PyObject_MakeTpCall+0x2fc) [0x555f53ac92bc]
39  /opt/conda/envs/gdf/bin/python(_PyEval_EvalFrameDefault+0x402b) [0x555f53ac41bb]
40  /opt/conda/envs/gdf/bin/python(+0x139ef3) [0x555f53ad0ef3]
41  /opt/conda/envs/gdf/bin/python(+0x147c72) [0x555f53adec72]
42  /opt/conda/envs/gdf/bin/python(_PyEval_EvalFrameDefault+0x402b) [0x555f53ac41bb]
43  /opt/conda/envs/gdf/bin/python(+0x139ef3) [0x555f53ad0ef3]
44  /opt/conda/envs/gdf/bin/python(_PyEval_EvalFrameDefault+0x68b) [0x555f53ac081b]
45  /opt/conda/envs/gdf/bin/python(+0x12827a) [0x555f53abf27a]
46  /opt/conda/envs/gdf/bin/python(_PyFunction_Vectorcall+0xd5) [0x555f53ad0c05]
47  /opt/conda/envs/gdf/bin/python(_PyEval_EvalFrameDefault+0x68b) [0x555f53ac081b]
48  /opt/conda/envs/gdf/bin/python(+0x139ef3) [0x555f53ad0ef3]
49  /opt/conda/envs/gdf/bin/python(_PyEval_EvalFrameDefault+0x3d8) [0x555f53ac0568]
50  /opt/conda/envs/gdf/bin/python(+0x12827a) [0x555f53abf27a]
51  /opt/conda/envs/gdf/bin/python(_PyFunction_Vectorcall+0xd5) [0x555f53ad0c05]
52  /opt/conda/envs/gdf/bin/python(_PyEval_EvalFrameDefault+0x123b) [0x555f53ac13cb]
53  /opt/conda/envs/gdf/bin/python(+0x12827a) [0x555f53abf27a]
54  /opt/conda/envs/gdf/bin/python(_PyEval_EvalCodeWithName+0x47) [0x555f53abef07]
55  /opt/conda/envs/gdf/bin/python(PyEval_EvalCodeEx+0x39) [0x555f53abeeb9]
56  /opt/conda/envs/gdf/bin/python(PyEval_EvalCode+0x1b) [0x555f53b6f8bb]
57  /opt/conda/envs/gdf/bin/python(+0x206adc) [0x555f53b9dadc]
58  /opt/conda/envs/gdf/bin/python(+0x202c24) [0x555f53b99c24]
59  /opt/conda/envs/gdf/bin/python(PyRun_StringFlags+0x9d) [0x555f53b917ed]
60  /opt/conda/envs/gdf/bin/python(PyRun_SimpleStringFlags+0x3d) [0x555f53b916bd]
61  /opt/conda/envs/gdf/bin/python(Py_RunMain+0x262) [0x555f53b908a2]
=================================
==== backtrace (tid:  74602) ====
 0  /opt/conda/envs/gdf/lib/libucs.so.0(ucs_handle_error+0x2fd) [0x7feae4b00f1d]
 1  /opt/conda/envs/gdf/lib/libucs.so.0(+0x29114) [0x7feae4b01114]
 2  /opt/conda/envs/gdf/lib/libucs.so.0(+0x292da) [0x7feae4b012da]
 3  /usr/lib/x86_64-linux-gnu/libpthread.so.0(+0x14420) [0x7feb85522420]
 4  /opt/conda/envs/gdf/lib/libucp.so.0(ucp_mem_type_unpack+0x14) [0x7feae4b7a5d4]
 5  /opt/conda/envs/gdf/lib/libucp.so.0(ucp_rndv_data_handler+0x4e9) [0x7feae4b9f859]
 6  /opt/conda/envs/gdf/lib/libuct.so.0(+0x2041f) [0x7feaf802741f]
 7  /opt/conda/envs/gdf/lib/libuct.so.0(+0x23788) [0x7feaf802a788]
 8  /opt/conda/envs/gdf/lib/libucs.so.0(ucs_event_set_wait+0xb9) [0x7feae4b09989]
 9  /opt/conda/envs/gdf/lib/libuct.so.0(uct_tcp_iface_progress+0x7d) [0x7feaf802961d]
10  /opt/conda/envs/gdf/lib/libucp.so.0(ucp_worker_progress+0x5a) [0x7feae4b77c4a]
11  /opt/conda/envs/gdf/lib/python3.9/site-packages/ucp/_libs/ucx_api.cpython-39-x86_64-linux-gnu.so(+0x2b17a) [0x7feae4c2217a]
12  /opt/conda/envs/gdf/bin/python(+0x13eb08) [0x562fdc1b7b08]
13  /opt/conda/envs/gdf/bin/python(_PyEval_EvalFrameDefault+0x5f82) [0x562fdc1a8112]
14  /opt/conda/envs/gdf/bin/python(+0x12827a) [0x562fdc1a127a]
15  /opt/conda/envs/gdf/bin/python(_PyFunction_Vectorcall+0xd5) [0x562fdc1b2c05]
16  /opt/conda/envs/gdf/bin/python(_PyEval_EvalFrameDefault+0x68b) [0x562fdc1a281b]
17  /opt/conda/envs/gdf/bin/python(+0x139ef3) [0x562fdc1b2ef3]
18  /opt/conda/envs/gdf/bin/python(+0x147a16) [0x562fdc1c0a16]
19  /opt/conda/envs/gdf/bin/python(+0x2579b1) [0x562fdc2d09b1]
20  /opt/conda/envs/gdf/bin/python(+0xe5817) [0x562fdc15e817]
21  /opt/conda/envs/gdf/bin/python(+0x130f83) [0x562fdc1a9f83]
22  /opt/conda/envs/gdf/bin/python(_PyEval_EvalFrameDefault+0x5ba6) [0x562fdc1a7d36]
23  /opt/conda/envs/gdf/bin/python(+0x139ef3) [0x562fdc1b2ef3]
24  /opt/conda/envs/gdf/bin/python(_PyEval_EvalFrameDefault+0x68b) [0x562fdc1a281b]
25  /opt/conda/envs/gdf/bin/python(+0x139ef3) [0x562fdc1b2ef3]
26  /opt/conda/envs/gdf/bin/python(_PyEval_EvalFrameDefault+0x68b) [0x562fdc1a281b]
27  /opt/conda/envs/gdf/bin/python(+0x139ef3) [0x562fdc1b2ef3]
28  /opt/conda/envs/gdf/bin/python(_PyEval_EvalFrameDefault+0x68b) [0x562fdc1a281b]
29  /opt/conda/envs/gdf/bin/python(+0x139ef3) [0x562fdc1b2ef3]
30  /opt/conda/envs/gdf/bin/python(_PyEval_EvalFrameDefault+0x68b) [0x562fdc1a281b]
31  /opt/conda/envs/gdf/bin/python(+0x12827a) [0x562fdc1a127a]
32  /opt/conda/envs/gdf/bin/python(_PyFunction_Vectorcall+0xd5) [0x562fdc1b2c05]
33  /opt/conda/envs/gdf/bin/python(_PyEval_EvalFrameDefault+0x4e17) [0x562fdc1a6fa7]
34  /opt/conda/envs/gdf/bin/python(+0x12827a) [0x562fdc1a127a]
35  /opt/conda/envs/gdf/bin/python(+0x147935) [0x562fdc1c0935]
36  /opt/conda/envs/gdf/bin/python(PyObject_Call+0xb4) [0x562fdc1c1104]
37  /opt/conda/envs/gdf/bin/python(+0x20efc8) [0x562fdc287fc8]
38  /opt/conda/envs/gdf/bin/python(_PyObject_MakeTpCall+0x2fc) [0x562fdc1ab2bc]
39  /opt/conda/envs/gdf/bin/python(_PyEval_EvalFrameDefault+0x402b) [0x562fdc1a61bb]
40  /opt/conda/envs/gdf/bin/python(+0x139ef3) [0x562fdc1b2ef3]
41  /opt/conda/envs/gdf/bin/python(+0x147c72) [0x562fdc1c0c72]
42  /opt/conda/envs/gdf/bin/python(_PyEval_EvalFrameDefault+0x402b) [0x562fdc1a61bb]
43  /opt/conda/envs/gdf/bin/python(+0x139ef3) [0x562fdc1b2ef3]
44  /opt/conda/envs/gdf/bin/python(_PyEval_EvalFrameDefault+0x68b) [0x562fdc1a281b]
45  /opt/conda/envs/gdf/bin/python(+0x12827a) [0x562fdc1a127a]
46  /opt/conda/envs/gdf/bin/python(_PyFunction_Vectorcall+0xd5) [0x562fdc1b2c05]
47  /opt/conda/envs/gdf/bin/python(_PyEval_EvalFrameDefault+0x68b) [0x562fdc1a281b]
48  /opt/conda/envs/gdf/bin/python(+0x139ef3) [0x562fdc1b2ef3]
49  /opt/conda/envs/gdf/bin/python(_PyEval_EvalFrameDefault+0x3d8) [0x562fdc1a2568]
50  /opt/conda/envs/gdf/bin/python(+0x12827a) [0x562fdc1a127a]
51  /opt/conda/envs/gdf/bin/python(_PyFunction_Vectorcall+0xd5) [0x562fdc1b2c05]
52  /opt/conda/envs/gdf/bin/python(_PyEval_EvalFrameDefault+0x123b) [0x562fdc1a33cb]
53  /opt/conda/envs/gdf/bin/python(+0x12827a) [0x562fdc1a127a]
54  /opt/conda/envs/gdf/bin/python(_PyEval_EvalCodeWithName+0x47) [0x562fdc1a0f07]
55  /opt/conda/envs/gdf/bin/python(PyEval_EvalCodeEx+0x39) [0x562fdc1a0eb9]
56  /opt/conda/envs/gdf/bin/python(PyEval_EvalCode+0x1b) [0x562fdc2518bb]
57  /opt/conda/envs/gdf/bin/python(+0x206adc) [0x562fdc27fadc]
58  /opt/conda/envs/gdf/bin/python(+0x202c24) [0x562fdc27bc24]
59  /opt/conda/envs/gdf/bin/python(PyRun_StringFlags+0x9d) [0x562fdc2737ed]
60  /opt/conda/envs/gdf/bin/python(PyRun_SimpleStringFlags+0x3d) [0x562fdc2736bd]
61  /opt/conda/envs/gdf/bin/python(Py_RunMain+0x262) [0x562fdc2728a2]
=================================
2023-06-04 06:08:07,676 - distributed.worker - ERROR - failed during get data with ucx://127.0.0.1:55771 -> ucx://127.0.0.1:44599
Traceback (most recent call last):
  File "/opt/conda/envs/gdf/lib/python3.9/site-packages/distributed/comm/ucx.py", line 333, in write
    await self.ep.send(each_frame)
  File "/opt/conda/envs/gdf/lib/python3.9/site-packages/ucp/core.py", line 650, in send
    return await comm.tag_send(self._ep, buffer, nbytes, tag, name=log)
ucp._libs.exceptions.UCXError: <[Send #007] ep: 0x7fb871cdb2c0, tag: 0x12814b4c9470a672, nbytes: 100000000, type: <class 'cudf.core.buffer.buffer.Buffer'>>: Connection reset by remote peer

During handling of the above exception, another exception occurred:

Traceback (most recent call last):
  File "/opt/conda/envs/gdf/lib/python3.9/site-packages/distributed/worker.py", line 1792, in get_data
    compressed = await comm.write(msg, serializers=serializers)
  File "/opt/conda/envs/gdf/lib/python3.9/site-packages/distributed/utils.py", line 752, in wrapper
    return await func(*args, **kwargs)
  File "/opt/conda/envs/gdf/lib/python3.9/site-packages/distributed/comm/ucx.py", line 337, in write
    raise CommClosedError("While writing, the connection was closed")
distributed.comm.core.CommClosedError: While writing, the connection was closed
2023-06-04 06:08:07,678 - distributed.worker - ERROR - Worker stream died during communication: ucx://127.0.0.1:44599
Traceback (most recent call last):
  File "/opt/conda/envs/gdf/lib/python3.9/site-packages/distributed/comm/ucx.py", line 391, in read
    await self.ep.recv(each_frame)
  File "/opt/conda/envs/gdf/lib/python3.9/site-packages/ucp/core.py", line 725, in recv
    ret = await comm.tag_recv(self._ep, buffer, nbytes, tag, name=log)
ucp._libs.exceptions.UCXError: <[Recv #007] ep: 0x7fb871cdb200, tag: 0xb6bc42368b128092, nbytes: 100000000, type: <class 'rmm._lib.device_buffer.DeviceBuffer'>>: Connection reset by remote peer

During handling of the above exception, another exception occurred:

Traceback (most recent call last):
  File "/opt/conda/envs/gdf/lib/python3.9/site-packages/distributed/worker.py", line 2066, in gather_dep
    response = await get_data_from_worker(
  File "/opt/conda/envs/gdf/lib/python3.9/site-packages/distributed/worker.py", line 2892, in get_data_from_worker
    response = await send_recv(
  File "/opt/conda/envs/gdf/lib/python3.9/site-packages/distributed/core.py", line 1024, in send_recv
    response = await comm.read(deserializers=deserializers)
  File "/opt/conda/envs/gdf/lib/python3.9/site-packages/distributed/utils.py", line 752, in wrapper
    return await func(*args, **kwargs)
  File "/opt/conda/envs/gdf/lib/python3.9/site-packages/distributed/comm/ucx.py", line 397, in read
    raise CommClosedError(
distributed.comm.core.CommClosedError: Connection closed by writer.
Inner exception: UCXError("<[Recv #007] ep: 0x7fb871cdb200, tag: 0xb6bc42368b128092, nbytes: 100000000, type: <class 'rmm._lib.device_buffer.DeviceBuffer'>>: Connection reset by remote peer")
Task exception was never retrieved
future: <Task finished name='Task-828' coro=<_listener_handler_coroutine() done, defined at /opt/conda/envs/gdf/lib/python3.9/site-packages/ucp/core.py:128> exception=UCXError('<stream_recv>: Connection reset by remote peer')>
Traceback (most recent call last):
  File "/opt/conda/envs/gdf/lib/python3.9/site-packages/ucp/core.py", line 143, in _listener_handler_coroutine
    peer_info = await exchange_peer_info(
  File "/opt/conda/envs/gdf/lib/python3.9/site-packages/ucp/core.py", line 52, in exchange_peer_info
    await comm.stream_recv(endpoint, peer_info_arr, peer_info_arr.nbytes)
ucp._libs.exceptions.UCXError: <stream_recv>: Connection reset by remote peer
Task exception was never retrieved
future: <Task finished name='Task-835' coro=<_listener_handler_coroutine() done, defined at /opt/conda/envs/gdf/lib/python3.9/site-packages/ucp/core.py:128> exception=UCXError('<stream_send>: Endpoint timeout')>
Traceback (most recent call last):
  File "/opt/conda/envs/gdf/lib/python3.9/site-packages/ucp/core.py", line 143, in _listener_handler_coroutine
    peer_info = await exchange_peer_info(
  File "/opt/conda/envs/gdf/lib/python3.9/site-packages/ucp/core.py", line 51, in exchange_peer_info
    await comm.stream_send(endpoint, my_info_arr, my_info_arr.nbytes)
ucp._libs.exceptions.UCXError: <stream_send>: Endpoint timeout
2023-06-04 06:08:07,682 - distributed.worker - ERROR - Worker stream died during communication: ucx://127.0.0.1:42659
Traceback (most recent call last):
  File "/opt/conda/envs/gdf/lib/python3.9/site-packages/distributed/comm/ucx.py", line 349, in read
    await self.ep.recv(msg)
  File "/opt/conda/envs/gdf/lib/python3.9/site-packages/ucp/core.py", line 725, in recv
    ret = await comm.tag_recv(self._ep, buffer, nbytes, tag, name=log)
ucp._libs.exceptions.UCXCanceled: <[Recv #000] ep: 0x7fb871cdb280, tag: 0x8877d1b56a3376f3, nbytes: 16, type: <class 'numpy.ndarray'>>: 

During handling of the above exception, another exception occurred:

Traceback (most recent call last):
  File "/opt/conda/envs/gdf/lib/python3.9/site-packages/distributed/comm/core.py", line 329, in connect
    handshake = await wait_for(comm.read(), time_left())
  File "/opt/conda/envs/gdf/lib/python3.9/site-packages/distributed/utils.py", line 1849, in wait_for
    return await asyncio.wait_for(fut, timeout)
  File "/opt/conda/envs/gdf/lib/python3.9/asyncio/tasks.py", line 479, in wait_for
    return fut.result()
  File "/opt/conda/envs/gdf/lib/python3.9/site-packages/distributed/utils.py", line 752, in wrapper
    return await func(*args, **kwargs)
  File "/opt/conda/envs/gdf/lib/python3.9/site-packages/distributed/comm/ucx.py", line 367, in read
    raise CommClosedError(
distributed.comm.core.CommClosedError: Connection closed by writer.
Inner exception: UCXCanceled("<[Recv #000] ep: 0x7fb871cdb280, tag: 0x8877d1b56a3376f3, nbytes: 16, type: <class 'numpy.ndarray'>>: ")

The above exception was the direct cause of the following exception:

Traceback (most recent call last):
  File "/opt/conda/envs/gdf/lib/python3.9/site-packages/distributed/worker.py", line 2066, in gather_dep
    response = await get_data_from_worker(
  File "/opt/conda/envs/gdf/lib/python3.9/site-packages/distributed/worker.py", line 2889, in get_data_from_worker
    comm = await rpc.connect(worker)
  File "/opt/conda/envs/gdf/lib/python3.9/site-packages/distributed/core.py", line 1506, in connect
    return await connect_attempt
  File "/opt/conda/envs/gdf/lib/python3.9/site-packages/distributed/core.py", line 1427, in _connect
    comm = await connect(
  File "/opt/conda/envs/gdf/lib/python3.9/site-packages/distributed/comm/core.py", line 334, in connect
    raise OSError(
OSError: Timed out during handshake while connecting to ucx://127.0.0.1:42659 after 30 s
2023-06-04 06:08:07,684 - distributed.worker - ERROR - Worker stream died during communication: ucx://127.0.0.1:42659
Traceback (most recent call last):
  File "/opt/conda/envs/gdf/lib/python3.9/site-packages/distributed/comm/ucx.py", line 349, in read
    await self.ep.recv(msg)
  File "/opt/conda/envs/gdf/lib/python3.9/site-packages/ucp/core.py", line 725, in recv
    ret = await comm.tag_recv(self._ep, buffer, nbytes, tag, name=log)
ucp._libs.exceptions.UCXCanceled: <[Recv #000] ep: 0x7f76942d2280, tag: 0x29f5269f7e08a965, nbytes: 16, type: <class 'numpy.ndarray'>>: 

During handling of the above exception, another exception occurred:

Traceback (most recent call last):
  File "/opt/conda/envs/gdf/lib/python3.9/site-packages/distributed/comm/core.py", line 329, in connect
    handshake = await wait_for(comm.read(), time_left())
  File "/opt/conda/envs/gdf/lib/python3.9/site-packages/distributed/utils.py", line 1849, in wait_for
    return await asyncio.wait_for(fut, timeout)
  File "/opt/conda/envs/gdf/lib/python3.9/asyncio/tasks.py", line 479, in wait_for
    return fut.result()
  File "/opt/conda/envs/gdf/lib/python3.9/site-packages/distributed/utils.py", line 752, in wrapper
    return await func(*args, **kwargs)
  File "/opt/conda/envs/gdf/lib/python3.9/site-packages/distributed/comm/ucx.py", line 367, in read
    raise CommClosedError(
distributed.comm.core.CommClosedError: Connection closed by writer.
Inner exception: UCXCanceled("<[Recv #000] ep: 0x7f76942d2280, tag: 0x29f5269f7e08a965, nbytes: 16, type: <class 'numpy.ndarray'>>: ")

The above exception was the direct cause of the following exception:

Traceback (most recent call last):
  File "/opt/conda/envs/gdf/lib/python3.9/site-packages/distributed/worker.py", line 2066, in gather_dep
    response = await get_data_from_worker(
  File "/opt/conda/envs/gdf/lib/python3.9/site-packages/distributed/worker.py", line 2889, in get_data_from_worker
    comm = await rpc.connect(worker)
  File "/opt/conda/envs/gdf/lib/python3.9/site-packages/distributed/core.py", line 1506, in connect
    return await connect_attempt
  File "/opt/conda/envs/gdf/lib/python3.9/site-packages/distributed/core.py", line 1427, in _connect
    comm = await connect(
  File "/opt/conda/envs/gdf/lib/python3.9/site-packages/distributed/comm/core.py", line 334, in connect
    raise OSError(
OSError: Timed out during handshake while connecting to ucx://127.0.0.1:42659 after 30 s
2023-06-04 06:08:07,685 - distributed.worker - ERROR - Worker stream died during communication: ucx://127.0.0.1:44599
Traceback (most recent call last):
  File "/opt/conda/envs/gdf/lib/python3.9/site-packages/distributed/core.py", line 1427, in _connect
    comm = await connect(
  File "/opt/conda/envs/gdf/lib/python3.9/site-packages/distributed/comm/core.py", line 292, in connect
    comm = await wait_for(
  File "/opt/conda/envs/gdf/lib/python3.9/site-packages/distributed/utils.py", line 1849, in wait_for
    return await asyncio.wait_for(fut, timeout)
  File "/opt/conda/envs/gdf/lib/python3.9/asyncio/tasks.py", line 466, in wait_for
    await waiter
asyncio.exceptions.CancelledError

During handling of the above exception, another exception occurred:

Traceback (most recent call last):
  File "/opt/conda/envs/gdf/lib/python3.9/site-packages/distributed/worker.py", line 2066, in gather_dep
    response = await get_data_from_worker(
  File "/opt/conda/envs/gdf/lib/python3.9/site-packages/distributed/worker.py", line 2889, in get_data_from_worker
    comm = await rpc.connect(worker)
  File "/opt/conda/envs/gdf/lib/python3.9/site-packages/distributed/core.py", line 1506, in connect
    return await connect_attempt
  File "/opt/conda/envs/gdf/lib/python3.9/site-packages/distributed/core.py", line 1450, in _connect
    raise CommClosedError(reason)
distributed.comm.core.CommClosedError: Address removed.
2023-06-04 06:08:07,693 - distributed.worker - ERROR - Worker stream died during communication: ucx://127.0.0.1:57665
Traceback (most recent call last):
  File "/opt/conda/envs/gdf/lib/python3.9/site-packages/distributed/comm/ucx.py", line 349, in read
    await self.ep.recv(msg)
  File "/opt/conda/envs/gdf/lib/python3.9/site-packages/ucp/core.py", line 725, in recv
    ret = await comm.tag_recv(self._ep, buffer, nbytes, tag, name=log)
ucp._libs.exceptions.UCXCanceled: <[Recv #003] ep: 0x7fb871cdb180, tag: 0xd50070b4e48c6d0b, nbytes: 16, type: <class 'numpy.ndarray'>>: 

During handling of the above exception, another exception occurred:

Traceback (most recent call last):
  File "/opt/conda/envs/gdf/lib/python3.9/site-packages/distributed/worker.py", line 2066, in gather_dep
    response = await get_data_from_worker(
  File "/opt/conda/envs/gdf/lib/python3.9/site-packages/distributed/worker.py", line 2892, in get_data_from_worker
    response = await send_recv(
  File "/opt/conda/envs/gdf/lib/python3.9/site-packages/distributed/core.py", line 1024, in send_recv
    response = await comm.read(deserializers=deserializers)
  File "/opt/conda/envs/gdf/lib/python3.9/site-packages/distributed/utils.py", line 752, in wrapper
    return await func(*args, **kwargs)
  File "/opt/conda/envs/gdf/lib/python3.9/site-packages/distributed/comm/ucx.py", line 367, in read
    raise CommClosedError(
distributed.comm.core.CommClosedError: Connection closed by writer.
Inner exception: UCXCanceled("<[Recv #003] ep: 0x7fb871cdb180, tag: 0xd50070b4e48c6d0b, nbytes: 16, type: <class 'numpy.ndarray'>>: ")
Task exception was never retrieved
future: <Task finished name='Task-842' coro=<_listener_handler_coroutine() done, defined at /opt/conda/envs/gdf/lib/python3.9/site-packages/ucp/core.py:128> exception=UCXError('<stream_recv>: Connection reset by remote peer')>
Traceback (most recent call last):
  File "/opt/conda/envs/gdf/lib/python3.9/site-packages/ucp/core.py", line 143, in _listener_handler_coroutine
    peer_info = await exchange_peer_info(
  File "/opt/conda/envs/gdf/lib/python3.9/site-packages/ucp/core.py", line 52, in exchange_peer_info
    await comm.stream_recv(endpoint, peer_info_arr, peer_info_arr.nbytes)
ucp._libs.exceptions.UCXError: <stream_recv>: Connection reset by remote peer
2023-06-04 06:08:07,738 - distributed.worker - ERROR - Worker stream died during communication: ucx://127.0.0.1:57665
Traceback (most recent call last):
  File "/opt/conda/envs/gdf/lib/python3.9/site-packages/distributed/comm/ucx.py", line 349, in read
    await self.ep.recv(msg)
  File "/opt/conda/envs/gdf/lib/python3.9/site-packages/ucp/core.py", line 725, in recv
    ret = await comm.tag_recv(self._ep, buffer, nbytes, tag, name=log)
ucp._libs.exceptions.UCXCanceled: <[Recv #003] ep: 0x7f76942d21c0, tag: 0x897f222397a67327, nbytes: 16, type: <class 'numpy.ndarray'>>: 

During handling of the above exception, another exception occurred:

Traceback (most recent call last):
  File "/opt/conda/envs/gdf/lib/python3.9/site-packages/distributed/worker.py", line 2066, in gather_dep
    response = await get_data_from_worker(
  File "/opt/conda/envs/gdf/lib/python3.9/site-packages/distributed/worker.py", line 2892, in get_data_from_worker
    response = await send_recv(
  File "/opt/conda/envs/gdf/lib/python3.9/site-packages/distributed/core.py", line 1024, in send_recv
    response = await comm.read(deserializers=deserializers)
  File "/opt/conda/envs/gdf/lib/python3.9/site-packages/distributed/utils.py", line 752, in wrapper
    return await func(*args, **kwargs)
  File "/opt/conda/envs/gdf/lib/python3.9/site-packages/distributed/comm/ucx.py", line 367, in read
    raise CommClosedError(
distributed.comm.core.CommClosedError: Connection closed by writer.
Inner exception: UCXCanceled("<[Recv #003] ep: 0x7f76942d21c0, tag: 0x897f222397a67327, nbytes: 16, type: <class 'numpy.ndarray'>>: ")
2023-06-04 06:08:07,754 - distributed.worker - ERROR - Worker stream died during communication: ucx://127.0.0.1:51257
Traceback (most recent call last):
  File "/opt/conda/envs/gdf/lib/python3.9/site-packages/distributed/comm/ucx.py", line 349, in read
    await self.ep.recv(msg)
  File "/opt/conda/envs/gdf/lib/python3.9/site-packages/ucp/core.py", line 725, in recv
    ret = await comm.tag_recv(self._ep, buffer, nbytes, tag, name=log)
ucp._libs.exceptions.UCXCanceled: <[Recv #003] ep: 0x7f76942d2200, tag: 0x392ca5993eb4e28d, nbytes: 16, type: <class 'numpy.ndarray'>>: 

During handling of the above exception, another exception occurred:

Traceback (most recent call last):
  File "/opt/conda/envs/gdf/lib/python3.9/site-packages/distributed/worker.py", line 2066, in gather_dep
    response = await get_data_from_worker(
  File "/opt/conda/envs/gdf/lib/python3.9/site-packages/distributed/worker.py", line 2892, in get_data_from_worker
    response = await send_recv(
  File "/opt/conda/envs/gdf/lib/python3.9/site-packages/distributed/core.py", line 1024, in send_recv
    response = await comm.read(deserializers=deserializers)
  File "/opt/conda/envs/gdf/lib/python3.9/site-packages/distributed/utils.py", line 752, in wrapper
    return await func(*args, **kwargs)
  File "/opt/conda/envs/gdf/lib/python3.9/site-packages/distributed/comm/ucx.py", line 367, in read
    raise CommClosedError(
distributed.comm.core.CommClosedError: Connection closed by writer.
Inner exception: UCXCanceled("<[Recv #003] ep: 0x7f76942d2200, tag: 0x392ca5993eb4e28d, nbytes: 16, type: <class 'numpy.ndarray'>>: ")
2023-06-04 06:08:07,780 - distributed.nanny - WARNING - Restarting worker
2023-06-04 06:08:07,789 - distributed.worker - ERROR - Worker stream died during communication: ucx://127.0.0.1:51865
Traceback (most recent call last):
  File "/opt/conda/envs/gdf/lib/python3.9/site-packages/distributed/worker.py", line 2066, in gather_dep
    response = await get_data_from_worker(
  File "/opt/conda/envs/gdf/lib/python3.9/site-packages/distributed/worker.py", line 2892, in get_data_from_worker
    response = await send_recv(
  File "/opt/conda/envs/gdf/lib/python3.9/site-packages/distributed/core.py", line 1022, in send_recv
    await comm.write(msg, serializers=serializers, on_error="raise")
  File "/opt/conda/envs/gdf/lib/python3.9/site-packages/distributed/utils.py", line 752, in wrapper
    return await func(*args, **kwargs)
  File "/opt/conda/envs/gdf/lib/python3.9/site-packages/distributed/comm/ucx.py", line 289, in write
    raise CommClosedError("Endpoint is closed -- unable to send message")
distributed.comm.core.CommClosedError: Endpoint is closed -- unable to send message
2023-06-04 06:08:07,756 - distributed.worker - ERROR - Worker stream died during communication: ucx://127.0.0.1:51865
Traceback (most recent call last):
  File "/opt/conda/envs/gdf/lib/python3.9/asyncio/tasks.py", line 466, in wait_for
    await waiter
asyncio.exceptions.CancelledError

During handling of the above exception, another exception occurred:

Traceback (most recent call last):
  File "/opt/conda/envs/gdf/lib/python3.9/site-packages/distributed/comm/core.py", line 329, in connect
    handshake = await wait_for(comm.read(), time_left())
  File "/opt/conda/envs/gdf/lib/python3.9/site-packages/distributed/utils.py", line 1849, in wait_for
    return await asyncio.wait_for(fut, timeout)
  File "/opt/conda/envs/gdf/lib/python3.9/asyncio/tasks.py", line 469, in wait_for
    return fut.result()
  File "/opt/conda/envs/gdf/lib/python3.9/site-packages/distributed/utils.py", line 752, in wrapper
    return await func(*args, **kwargs)
  File "/opt/conda/envs/gdf/lib/python3.9/site-packages/distributed/comm/ucx.py", line 367, in read
    raise CommClosedError(
distributed.comm.core.CommClosedError: Connection closed by writer.
Inner exception: UCXCanceled("<[Recv #000] ep: 0x7f76942d22c0, tag: 0xe67689c012a0406c, nbytes: 16, type: <class 'numpy.ndarray'>>: ")

The above exception was the direct cause of the following exception:

Traceback (most recent call last):
  File "/opt/conda/envs/gdf/lib/python3.9/site-packages/distributed/worker.py", line 2066, in gather_dep
    response = await get_data_from_worker(
  File "/opt/conda/envs/gdf/lib/python3.9/site-packages/distributed/worker.py", line 2889, in get_data_from_worker
    comm = await rpc.connect(worker)
  File "/opt/conda/envs/gdf/lib/python3.9/site-packages/distributed/core.py", line 1506, in connect
    return await connect_attempt
  File "/opt/conda/envs/gdf/lib/python3.9/site-packages/distributed/core.py", line 1427, in _connect
    comm = await connect(
  File "/opt/conda/envs/gdf/lib/python3.9/site-packages/distributed/comm/core.py", line 334, in connect
    raise OSError(
OSError: Timed out during handshake while connecting to ucx://127.0.0.1:51865 after 30 s
2023-06-04 06:08:07,811 - distributed.worker - ERROR - failed during get data with ucx://127.0.0.1:55771 -> ucx://127.0.0.1:51865
Traceback (most recent call last):
  File "/opt/conda/envs/gdf/lib/python3.9/site-packages/distributed/comm/ucx.py", line 333, in write
    await self.ep.send(each_frame)
  File "/opt/conda/envs/gdf/lib/python3.9/site-packages/ucp/core.py", line 650, in send
    return await comm.tag_send(self._ep, buffer, nbytes, tag, name=log)
ucp._libs.exceptions.UCXError: <[Send #007] ep: 0x7fb871cdb440, tag: 0xce371b0404387498, nbytes: 100000000, type: <class 'cudf.core.buffer.buffer.Buffer'>>: Connection reset by remote peer

During handling of the above exception, another exception occurred:

Traceback (most recent call last):
  File "/opt/conda/envs/gdf/lib/python3.9/site-packages/distributed/worker.py", line 1792, in get_data
    compressed = await comm.write(msg, serializers=serializers)
  File "/opt/conda/envs/gdf/lib/python3.9/site-packages/distributed/utils.py", line 752, in wrapper
    return await func(*args, **kwargs)
  File "/opt/conda/envs/gdf/lib/python3.9/site-packages/distributed/comm/ucx.py", line 337, in write
    raise CommClosedError("While writing, the connection was closed")
distributed.comm.core.CommClosedError: While writing, the connection was closed
2023-06-04 06:08:07,812 - distributed.worker - ERROR - Worker stream died during communication: ucx://127.0.0.1:51257
Traceback (most recent call last):
  File "/opt/conda/envs/gdf/lib/python3.9/site-packages/distributed/comm/ucx.py", line 391, in read
    await self.ep.recv(each_frame)
  File "/opt/conda/envs/gdf/lib/python3.9/site-packages/ucp/core.py", line 725, in recv
    ret = await comm.tag_recv(self._ep, buffer, nbytes, tag, name=log)
ucp._libs.exceptions.UCXError: <[Recv #007] ep: 0x7fb871cdb100, tag: 0x85fa148187e667e7, nbytes: 100000000, type: <class 'rmm._lib.device_buffer.DeviceBuffer'>>: Connection reset by remote peer

During handling of the above exception, another exception occurred:

Traceback (most recent call last):
  File "/opt/conda/envs/gdf/lib/python3.9/site-packages/distributed/worker.py", line 2066, in gather_dep
    response = await get_data_from_worker(
  File "/opt/conda/envs/gdf/lib/python3.9/site-packages/distributed/worker.py", line 2892, in get_data_from_worker
    response = await send_recv(
  File "/opt/conda/envs/gdf/lib/python3.9/site-packages/distributed/core.py", line 1024, in send_recv
    response = await comm.read(deserializers=deserializers)
  File "/opt/conda/envs/gdf/lib/python3.9/site-packages/distributed/utils.py", line 752, in wrapper
    return await func(*args, **kwargs)
  File "/opt/conda/envs/gdf/lib/python3.9/site-packages/distributed/comm/ucx.py", line 397, in read
    raise CommClosedError(
distributed.comm.core.CommClosedError: Connection closed by writer.
Inner exception: UCXError("<[Recv #007] ep: 0x7fb871cdb100, tag: 0x85fa148187e667e7, nbytes: 100000000, type: <class 'rmm._lib.device_buffer.DeviceBuffer'>>: Connection reset by remote peer")
2023-06-04 06:08:07,814 - distributed.worker - ERROR - Worker stream died during communication: ucx://127.0.0.1:51865
Traceback (most recent call last):
  File "/opt/conda/envs/gdf/lib/python3.9/site-packages/distributed/comm/ucx.py", line 349, in read
    await self.ep.recv(msg)
  File "/opt/conda/envs/gdf/lib/python3.9/site-packages/ucp/core.py", line 725, in recv
    ret = await comm.tag_recv(self._ep, buffer, nbytes, tag, name=log)
ucp._libs.exceptions.UCXCanceled: <[Recv #003] ep: 0x7fb871cdb1c0, tag: 0x3997b1d367b7bb14, nbytes: 16, type: <class 'numpy.ndarray'>>: 

During handling of the above exception, another exception occurred:

Traceback (most recent call last):
  File "/opt/conda/envs/gdf/lib/python3.9/site-packages/distributed/worker.py", line 2066, in gather_dep
    response = await get_data_from_worker(
  File "/opt/conda/envs/gdf/lib/python3.9/site-packages/distributed/worker.py", line 2892, in get_data_from_worker
    response = await send_recv(
  File "/opt/conda/envs/gdf/lib/python3.9/site-packages/distributed/core.py", line 1024, in send_recv
    response = await comm.read(deserializers=deserializers)
  File "/opt/conda/envs/gdf/lib/python3.9/site-packages/distributed/utils.py", line 752, in wrapper
    return await func(*args, **kwargs)
  File "/opt/conda/envs/gdf/lib/python3.9/site-packages/distributed/comm/ucx.py", line 367, in read
    raise CommClosedError(
distributed.comm.core.CommClosedError: Connection closed by writer.
Inner exception: UCXCanceled("<[Recv #003] ep: 0x7fb871cdb1c0, tag: 0x3997b1d367b7bb14, nbytes: 16, type: <class 'numpy.ndarray'>>: ")
2023-06-04 06:08:07,848 - distributed.nanny - WARNING - Restarting worker
2023-06-04 06:08:07,903 - distributed.nanny - WARNING - Restarting worker
2023-06-04 06:08:07,904 - distributed.worker - ERROR - failed during get data with ucx://127.0.0.1:60211 -> ucx://127.0.0.1:57665
Traceback (most recent call last):
  File "/opt/conda/envs/gdf/lib/python3.9/site-packages/distributed/worker.py", line 1792, in get_data
    compressed = await comm.write(msg, serializers=serializers)
  File "/opt/conda/envs/gdf/lib/python3.9/site-packages/distributed/utils.py", line 752, in wrapper
    return await func(*args, **kwargs)
  File "/opt/conda/envs/gdf/lib/python3.9/site-packages/distributed/comm/ucx.py", line 289, in write
    raise CommClosedError("Endpoint is closed -- unable to send message")
distributed.comm.core.CommClosedError: Endpoint is closed -- unable to send message
2023-06-04 06:08:07,904 - distributed.worker - ERROR - failed during get data with ucx://127.0.0.1:60211 -> ucx://127.0.0.1:51257
Traceback (most recent call last):
  File "/opt/conda/envs/gdf/lib/python3.9/site-packages/distributed/worker.py", line 1792, in get_data
    compressed = await comm.write(msg, serializers=serializers)
  File "/opt/conda/envs/gdf/lib/python3.9/site-packages/distributed/utils.py", line 752, in wrapper
    return await func(*args, **kwargs)
  File "/opt/conda/envs/gdf/lib/python3.9/site-packages/distributed/comm/ucx.py", line 289, in write
    raise CommClosedError("Endpoint is closed -- unable to send message")
distributed.comm.core.CommClosedError: Endpoint is closed -- unable to send message
2023-06-04 06:08:07,907 - distributed.worker - ERROR - Worker stream died during communication: ucx://127.0.0.1:42659
Traceback (most recent call last):
  File "/opt/conda/envs/gdf/lib/python3.9/asyncio/tasks.py", line 466, in wait_for
    await waiter
asyncio.exceptions.CancelledError

During handling of the above exception, another exception occurred:

Traceback (most recent call last):
  File "/opt/conda/envs/gdf/lib/python3.9/site-packages/distributed/comm/core.py", line 329, in connect
    handshake = await wait_for(comm.read(), time_left())
  File "/opt/conda/envs/gdf/lib/python3.9/site-packages/distributed/utils.py", line 1849, in wait_for
    return await asyncio.wait_for(fut, timeout)
  File "/opt/conda/envs/gdf/lib/python3.9/asyncio/tasks.py", line 469, in wait_for
    return fut.result()
  File "/opt/conda/envs/gdf/lib/python3.9/site-packages/distributed/utils.py", line 752, in wrapper
    return await func(*args, **kwargs)
  File "/opt/conda/envs/gdf/lib/python3.9/site-packages/distributed/comm/ucx.py", line 367, in read
    raise CommClosedError(
distributed.comm.core.CommClosedError: Connection closed by writer.
Inner exception: UCXCanceled("<[Recv #000] ep: 0x7f9038e4c240, tag: 0xdf6b41251f9ec2f7, nbytes: 16, type: <class 'numpy.ndarray'>>: ")

The above exception was the direct cause of the following exception:

Traceback (most recent call last):
  File "/opt/conda/envs/gdf/lib/python3.9/site-packages/distributed/worker.py", line 2066, in gather_dep
    response = await get_data_from_worker(
  File "/opt/conda/envs/gdf/lib/python3.9/site-packages/distributed/worker.py", line 2889, in get_data_from_worker
    comm = await rpc.connect(worker)
  File "/opt/conda/envs/gdf/lib/python3.9/site-packages/distributed/core.py", line 1506, in connect
    return await connect_attempt
  File "/opt/conda/envs/gdf/lib/python3.9/site-packages/distributed/core.py", line 1427, in _connect
    comm = await connect(
  File "/opt/conda/envs/gdf/lib/python3.9/site-packages/distributed/comm/core.py", line 334, in connect
    raise OSError(
OSError: Timed out during handshake while connecting to ucx://127.0.0.1:42659 after 30 s
2023-06-04 06:08:07,970 - distributed.nanny - WARNING - Restarting worker
2023-06-04 06:08:07,974 - distributed.worker - ERROR - Worker stream died during communication: ucx://127.0.0.1:57665
Traceback (most recent call last):
  File "/opt/conda/envs/gdf/lib/python3.9/asyncio/tasks.py", line 466, in wait_for
    await waiter
asyncio.exceptions.CancelledError

During handling of the above exception, another exception occurred:

Traceback (most recent call last):
  File "/opt/conda/envs/gdf/lib/python3.9/site-packages/distributed/comm/core.py", line 330, in connect
    await wait_for(comm.write(local_info), time_left())
  File "/opt/conda/envs/gdf/lib/python3.9/site-packages/distributed/utils.py", line 1849, in wait_for
    return await asyncio.wait_for(fut, timeout)
  File "/opt/conda/envs/gdf/lib/python3.9/asyncio/tasks.py", line 469, in wait_for
    return fut.result()
  File "/opt/conda/envs/gdf/lib/python3.9/site-packages/distributed/utils.py", line 752, in wrapper
    return await func(*args, **kwargs)
  File "/opt/conda/envs/gdf/lib/python3.9/site-packages/distributed/comm/ucx.py", line 289, in write
    raise CommClosedError("Endpoint is closed -- unable to send message")
distributed.comm.core.CommClosedError: Endpoint is closed -- unable to send message

The above exception was the direct cause of the following exception:

Traceback (most recent call last):
  File "/opt/conda/envs/gdf/lib/python3.9/site-packages/distributed/worker.py", line 2066, in gather_dep
    response = await get_data_from_worker(
  File "/opt/conda/envs/gdf/lib/python3.9/site-packages/distributed/worker.py", line 2889, in get_data_from_worker
    comm = await rpc.connect(worker)
  File "/opt/conda/envs/gdf/lib/python3.9/site-packages/distributed/core.py", line 1506, in connect
    return await connect_attempt
  File "/opt/conda/envs/gdf/lib/python3.9/site-packages/distributed/core.py", line 1427, in _connect
    comm = await connect(
  File "/opt/conda/envs/gdf/lib/python3.9/site-packages/distributed/comm/core.py", line 334, in connect
    raise OSError(
OSError: Timed out during handshake while connecting to ucx://127.0.0.1:57665 after 30 s
2023-06-04 06:08:08,053 - distributed.nanny - WARNING - Restarting worker
2023-06-04 06:08:08,099 - distributed.worker - ERROR - Worker stream died during communication: ucx://127.0.0.1:51257
Traceback (most recent call last):
  File "/opt/conda/envs/gdf/lib/python3.9/site-packages/distributed/comm/ucx.py", line 466, in connect
    ep = await ucp.create_endpoint(ip, port)
  File "/opt/conda/envs/gdf/lib/python3.9/site-packages/ucp/core.py", line 1004, in create_endpoint
    return await _get_ctx().create_endpoint(
  File "/opt/conda/envs/gdf/lib/python3.9/site-packages/ucp/core.py", line 316, in create_endpoint
    peer_info = await exchange_peer_info(
  File "/opt/conda/envs/gdf/lib/python3.9/site-packages/ucp/core.py", line 55, in exchange_peer_info
    await comm.stream_send(endpoint, my_info_arr, my_info_arr.nbytes)
  File "/opt/conda/envs/gdf/lib/python3.9/site-packages/ucp/comm.py", line 79, in stream_send
    return _call_ucx_api(
  File "/opt/conda/envs/gdf/lib/python3.9/site-packages/ucp/comm.py", line 31, in _call_ucx_api
    req = func(*args, **kwargs)
  File "ucp/_libs/transfer_stream.pyx", line 64, in ucp._libs.ucx_api.stream_send_nb
  File "ucp/_libs/ucx_endpoint.pyx", line 353, in ucp._libs.ucx_api.UCXEndpoint.raise_on_error
ucp._libs.exceptions.UCXConnectionReset: Endpoint 0x7f9038e4c180 error: Connection reset by remote peer

During handling of the above exception, another exception occurred:

Traceback (most recent call last):
  File "/opt/conda/envs/gdf/lib/python3.9/site-packages/distributed/comm/core.py", line 292, in connect
    comm = await wait_for(
  File "/opt/conda/envs/gdf/lib/python3.9/site-packages/distributed/utils.py", line 1849, in wait_for
    return await asyncio.wait_for(fut, timeout)
  File "/opt/conda/envs/gdf/lib/python3.9/asyncio/tasks.py", line 479, in wait_for
    return fut.result()
  File "/opt/conda/envs/gdf/lib/python3.9/site-packages/distributed/comm/ucx.py", line 468, in connect
    raise CommClosedError("Connection closed before handshake completed")
distributed.comm.core.CommClosedError: Connection closed before handshake completed

During handling of the above exception, another exception occurred:

Traceback (most recent call last):
  File "/opt/conda/envs/gdf/lib/python3.9/site-packages/distributed/core.py", line 1427, in _connect
    comm = await connect(
  File "/opt/conda/envs/gdf/lib/python3.9/site-packages/distributed/comm/core.py", line 316, in connect
    await asyncio.sleep(backoff)
  File "/opt/conda/envs/gdf/lib/python3.9/asyncio/tasks.py", line 652, in sleep
    return await future
asyncio.exceptions.CancelledError

During handling of the above exception, another exception occurred:

Traceback (most recent call last):
  File "/opt/conda/envs/gdf/lib/python3.9/site-packages/distributed/worker.py", line 2066, in gather_dep
    response = await get_data_from_worker(
  File "/opt/conda/envs/gdf/lib/python3.9/site-packages/distributed/worker.py", line 2889, in get_data_from_worker
    comm = await rpc.connect(worker)
  File "/opt/conda/envs/gdf/lib/python3.9/site-packages/distributed/core.py", line 1506, in connect
    return await connect_attempt
  File "/opt/conda/envs/gdf/lib/python3.9/site-packages/distributed/core.py", line 1450, in _connect
    raise CommClosedError(reason)
distributed.comm.core.CommClosedError: Address removed.
2023-06-04 06:08:09,281 - distributed.preloading - INFO - Creating preload: dask_cuda.initialize
2023-06-04 06:08:09,281 - distributed.preloading - INFO - Import preload module: dask_cuda.initialize
2023-06-04 06:08:09,283 - distributed.preloading - INFO - Creating preload: dask_cuda.initialize
2023-06-04 06:08:09,283 - distributed.preloading - INFO - Import preload module: dask_cuda.initialize
2023-06-04 06:08:09,461 - distributed.preloading - INFO - Creating preload: dask_cuda.initialize
2023-06-04 06:08:09,461 - distributed.preloading - INFO - Import preload module: dask_cuda.initialize
2023-06-04 06:08:09,540 - distributed.preloading - INFO - Creating preload: dask_cuda.initialize
2023-06-04 06:08:09,540 - distributed.preloading - INFO - Import preload module: dask_cuda.initialize
2023-06-04 06:08:09,597 - distributed.preloading - INFO - Creating preload: dask_cuda.initialize
2023-06-04 06:08:09,597 - distributed.preloading - INFO - Import preload module: dask_cuda.initialize
2023-06-04 06:08:37,277 - distributed.worker - ERROR - Worker stream died during communication: ucx://127.0.0.1:44599
Traceback (most recent call last):
  File "/opt/conda/envs/gdf/lib/python3.9/site-packages/distributed/comm/ucx.py", line 466, in connect
    ep = await ucp.create_endpoint(ip, port)
  File "/opt/conda/envs/gdf/lib/python3.9/site-packages/ucp/core.py", line 1004, in create_endpoint
    return await _get_ctx().create_endpoint(
  File "/opt/conda/envs/gdf/lib/python3.9/site-packages/ucp/core.py", line 316, in create_endpoint
    peer_info = await exchange_peer_info(
  File "/opt/conda/envs/gdf/lib/python3.9/site-packages/ucp/core.py", line 54, in exchange_peer_info
    await comm.stream_recv(endpoint, peer_info_arr, peer_info_arr.nbytes)
asyncio.exceptions.CancelledError

During handling of the above exception, another exception occurred:

Traceback (most recent call last):
  File "/opt/conda/envs/gdf/lib/python3.9/asyncio/tasks.py", line 490, in wait_for
    return fut.result()
asyncio.exceptions.CancelledError

The above exception was the direct cause of the following exception:

Traceback (most recent call last):
  File "/opt/conda/envs/gdf/lib/python3.9/site-packages/distributed/comm/core.py", line 292, in connect
    comm = await wait_for(
  File "/opt/conda/envs/gdf/lib/python3.9/site-packages/distributed/utils.py", line 1849, in wait_for
    return await asyncio.wait_for(fut, timeout)
  File "/opt/conda/envs/gdf/lib/python3.9/asyncio/tasks.py", line 492, in wait_for
    raise exceptions.TimeoutError() from exc
asyncio.exceptions.TimeoutError

The above exception was the direct cause of the following exception:

Traceback (most recent call last):
  File "/opt/conda/envs/gdf/lib/python3.9/site-packages/distributed/worker.py", line 2066, in gather_dep
    response = await get_data_from_worker(
  File "/opt/conda/envs/gdf/lib/python3.9/site-packages/distributed/worker.py", line 2889, in get_data_from_worker
    comm = await rpc.connect(worker)
  File "/opt/conda/envs/gdf/lib/python3.9/site-packages/distributed/core.py", line 1506, in connect
    return await connect_attempt
  File "/opt/conda/envs/gdf/lib/python3.9/site-packages/distributed/core.py", line 1427, in _connect
    comm = await connect(
  File "/opt/conda/envs/gdf/lib/python3.9/site-packages/distributed/comm/core.py", line 318, in connect
    raise OSError(
OSError: Timed out trying to connect to ucx://127.0.0.1:44599 after 30 s
/opt/conda/envs/gdf/lib/python3.9/multiprocessing/resource_tracker.py:216: UserWarning: resource_tracker: There appear to be 48 leaked semaphore objects to clean up at shutdown
  warnings.warn('resource_tracker: There appear to be %d '
