2023-07-05 05:53:20,689 - distributed.preloading - INFO - Creating preload: dask_cuda.initialize
2023-07-05 05:53:20,690 - distributed.preloading - INFO - Import preload module: dask_cuda.initialize
2023-07-05 05:53:20,754 - distributed.preloading - INFO - Creating preload: dask_cuda.initialize
2023-07-05 05:53:20,754 - distributed.preloading - INFO - Import preload module: dask_cuda.initialize
2023-07-05 05:53:20,779 - distributed.preloading - INFO - Creating preload: dask_cuda.initialize
2023-07-05 05:53:20,779 - distributed.preloading - INFO - Import preload module: dask_cuda.initialize
2023-07-05 05:53:20,788 - distributed.preloading - INFO - Creating preload: dask_cuda.initialize
2023-07-05 05:53:20,788 - distributed.preloading - INFO - Import preload module: dask_cuda.initialize
2023-07-05 05:53:20,791 - distributed.preloading - INFO - Creating preload: dask_cuda.initialize
2023-07-05 05:53:20,791 - distributed.preloading - INFO - Import preload module: dask_cuda.initialize
2023-07-05 05:53:20,791 - distributed.preloading - INFO - Creating preload: dask_cuda.initialize
2023-07-05 05:53:20,791 - distributed.preloading - INFO - Import preload module: dask_cuda.initialize
2023-07-05 05:53:20,824 - distributed.preloading - INFO - Creating preload: dask_cuda.initialize
2023-07-05 05:53:20,824 - distributed.preloading - INFO - Import preload module: dask_cuda.initialize
2023-07-05 05:53:20,838 - distributed.preloading - INFO - Creating preload: dask_cuda.initialize
2023-07-05 05:53:20,838 - distributed.preloading - INFO - Import preload module: dask_cuda.initialize
[dgx13:72942:0:72942] Caught signal 11 (Segmentation fault: address not mapped to object at address 0x448)
==== backtrace (tid:  72942) ====
 0  /opt/conda/envs/gdf/lib/libucs.so.0(ucs_handle_error+0x2fd) [0x7fdd707b7ced]
 1  /opt/conda/envs/gdf/lib/libucs.so.0(+0x2aee4) [0x7fdd707b7ee4]
 2  /opt/conda/envs/gdf/lib/libucs.so.0(+0x2b0aa) [0x7fdd707b80aa]
 3  /usr/lib/x86_64-linux-gnu/libpthread.so.0(+0x14420) [0x7fde0fef0420]
 4  /opt/conda/envs/gdf/lib/libucp.so.0(ucp_mem_type_unpack+0x14) [0x7fdd708376d4]
 5  /opt/conda/envs/gdf/lib/libucp.so.0(ucp_rndv_data_handler+0x4e9) [0x7fdd7085fa29]
 6  /opt/conda/envs/gdf/lib/libuct.so.0(+0x2045f) [0x7fdd7077145f]
 7  /opt/conda/envs/gdf/lib/libuct.so.0(+0x238c8) [0x7fdd707748c8]
 8  /opt/conda/envs/gdf/lib/libucs.so.0(ucs_event_set_wait+0xb9) [0x7fdd707c1399]
 9  /opt/conda/envs/gdf/lib/libuct.so.0(uct_tcp_iface_progress+0x7d) [0x7fdd7077365d]
10  /opt/conda/envs/gdf/lib/libucp.so.0(ucp_worker_progress+0x5a) [0x7fdd7083450a]
11  /opt/conda/envs/gdf/lib/python3.9/site-packages/ucp/_libs/ucx_api.cpython-39-x86_64-linux-gnu.so(+0x2b17a) [0x7fdd708e917a]
12  /opt/conda/envs/gdf/bin/python(+0x13eb08) [0x56197f527b08]
13  /opt/conda/envs/gdf/bin/python(_PyEval_EvalFrameDefault+0x5f82) [0x56197f518112]
14  /opt/conda/envs/gdf/bin/python(+0x12827a) [0x56197f51127a]
15  /opt/conda/envs/gdf/bin/python(_PyFunction_Vectorcall+0xd5) [0x56197f522c05]
16  /opt/conda/envs/gdf/bin/python(_PyEval_EvalFrameDefault+0x68b) [0x56197f51281b]
17  /opt/conda/envs/gdf/bin/python(+0x139ef3) [0x56197f522ef3]
18  /opt/conda/envs/gdf/bin/python(+0x147a16) [0x56197f530a16]
19  /opt/conda/envs/gdf/bin/python(+0x2579b1) [0x56197f6409b1]
20  /opt/conda/envs/gdf/bin/python(+0xe5817) [0x56197f4ce817]
21  /opt/conda/envs/gdf/bin/python(+0x130f83) [0x56197f519f83]
22  /opt/conda/envs/gdf/bin/python(_PyEval_EvalFrameDefault+0x5ba6) [0x56197f517d36]
23  /opt/conda/envs/gdf/bin/python(+0x139ef3) [0x56197f522ef3]
24  /opt/conda/envs/gdf/bin/python(_PyEval_EvalFrameDefault+0x68b) [0x56197f51281b]
25  /opt/conda/envs/gdf/bin/python(+0x139ef3) [0x56197f522ef3]
26  /opt/conda/envs/gdf/bin/python(_PyEval_EvalFrameDefault+0x68b) [0x56197f51281b]
27  /opt/conda/envs/gdf/bin/python(+0x139ef3) [0x56197f522ef3]
28  /opt/conda/envs/gdf/bin/python(_PyEval_EvalFrameDefault+0x68b) [0x56197f51281b]
29  /opt/conda/envs/gdf/bin/python(+0x139ef3) [0x56197f522ef3]
30  /opt/conda/envs/gdf/bin/python(_PyEval_EvalFrameDefault+0x68b) [0x56197f51281b]
31  /opt/conda/envs/gdf/bin/python(+0x12827a) [0x56197f51127a]
32  /opt/conda/envs/gdf/bin/python(_PyFunction_Vectorcall+0xd5) [0x56197f522c05]
33  /opt/conda/envs/gdf/bin/python(_PyEval_EvalFrameDefault+0x4e17) [0x56197f516fa7]
34  /opt/conda/envs/gdf/bin/python(+0x12827a) [0x56197f51127a]
35  /opt/conda/envs/gdf/bin/python(+0x147935) [0x56197f530935]
36  /opt/conda/envs/gdf/bin/python(PyObject_Call+0xb4) [0x56197f531104]
37  /opt/conda/envs/gdf/bin/python(+0x20efc8) [0x56197f5f7fc8]
38  /opt/conda/envs/gdf/bin/python(_PyObject_MakeTpCall+0x2fc) [0x56197f51b2bc]
39  /opt/conda/envs/gdf/bin/python(_PyEval_EvalFrameDefault+0x402b) [0x56197f5161bb]
40  /opt/conda/envs/gdf/bin/python(+0x139ef3) [0x56197f522ef3]
41  /opt/conda/envs/gdf/bin/python(+0x147c72) [0x56197f530c72]
42  /opt/conda/envs/gdf/bin/python(_PyEval_EvalFrameDefault+0x402b) [0x56197f5161bb]
43  /opt/conda/envs/gdf/bin/python(+0x139ef3) [0x56197f522ef3]
44  /opt/conda/envs/gdf/bin/python(_PyEval_EvalFrameDefault+0x68b) [0x56197f51281b]
45  /opt/conda/envs/gdf/bin/python(+0x12827a) [0x56197f51127a]
46  /opt/conda/envs/gdf/bin/python(_PyFunction_Vectorcall+0xd5) [0x56197f522c05]
47  /opt/conda/envs/gdf/bin/python(_PyEval_EvalFrameDefault+0x68b) [0x56197f51281b]
48  /opt/conda/envs/gdf/bin/python(+0x139ef3) [0x56197f522ef3]
49  /opt/conda/envs/gdf/bin/python(_PyEval_EvalFrameDefault+0x3d8) [0x56197f512568]
50  /opt/conda/envs/gdf/bin/python(+0x12827a) [0x56197f51127a]
51  /opt/conda/envs/gdf/bin/python(_PyFunction_Vectorcall+0xd5) [0x56197f522c05]
52  /opt/conda/envs/gdf/bin/python(_PyEval_EvalFrameDefault+0x123b) [0x56197f5133cb]
53  /opt/conda/envs/gdf/bin/python(+0x12827a) [0x56197f51127a]
54  /opt/conda/envs/gdf/bin/python(_PyEval_EvalCodeWithName+0x47) [0x56197f510f07]
55  /opt/conda/envs/gdf/bin/python(PyEval_EvalCodeEx+0x39) [0x56197f510eb9]
56  /opt/conda/envs/gdf/bin/python(PyEval_EvalCode+0x1b) [0x56197f5c18bb]
57  /opt/conda/envs/gdf/bin/python(+0x206adc) [0x56197f5efadc]
58  /opt/conda/envs/gdf/bin/python(+0x202c24) [0x56197f5ebc24]
59  /opt/conda/envs/gdf/bin/python(PyRun_StringFlags+0x9d) [0x56197f5e37ed]
60  /opt/conda/envs/gdf/bin/python(PyRun_SimpleStringFlags+0x3d) [0x56197f5e36bd]
61  /opt/conda/envs/gdf/bin/python(Py_RunMain+0x262) [0x56197f5e28a2]
=================================
2023-07-05 05:53:29,185 - distributed.worker - ERROR - failed during get data with ucx://127.0.0.1:52739 -> ucx://127.0.0.1:45731
Traceback (most recent call last):
  File "/opt/conda/envs/gdf/lib/python3.9/site-packages/distributed/comm/ucx.py", line 333, in write
    await self.ep.send(each_frame)
  File "/opt/conda/envs/gdf/lib/python3.9/site-packages/ucp/core.py", line 650, in send
    return await comm.tag_send(self._ep, buffer, nbytes, tag, name=log)
ucp._libs.exceptions.UCXError: <[Send #007] ep: 0x7f71b830f100, tag: 0x87a9e502ebb7e7a, nbytes: 800000000, type: <class 'cudf.core.buffer.buffer.Buffer'>>: Connection reset by remote peer

During handling of the above exception, another exception occurred:

Traceback (most recent call last):
  File "/opt/conda/envs/gdf/lib/python3.9/site-packages/distributed/worker.py", line 1792, in get_data
    compressed = await comm.write(msg, serializers=serializers)
  File "/opt/conda/envs/gdf/lib/python3.9/site-packages/distributed/utils.py", line 752, in wrapper
    return await func(*args, **kwargs)
  File "/opt/conda/envs/gdf/lib/python3.9/site-packages/distributed/comm/ucx.py", line 337, in write
    raise CommClosedError("While writing, the connection was closed")
distributed.comm.core.CommClosedError: While writing, the connection was closed
2023-07-05 05:53:29,264 - distributed.nanny - WARNING - Restarting worker
[dgx13:72952:0:72952] Caught signal 11 (Segmentation fault: address not mapped to object at address 0x448)
==== backtrace (tid:  72952) ====
 0  /opt/conda/envs/gdf/lib/libucs.so.0(ucs_handle_error+0x2fd) [0x7f51bc58cced]
 1  /opt/conda/envs/gdf/lib/libucs.so.0(+0x2aee4) [0x7f51bc58cee4]
 2  /opt/conda/envs/gdf/lib/libucs.so.0(+0x2b0aa) [0x7f51bc58d0aa]
 3  /usr/lib/x86_64-linux-gnu/libpthread.so.0(+0x14420) [0x7f525bcbf420]
 4  /opt/conda/envs/gdf/lib/libucp.so.0(ucp_mem_type_unpack+0x14) [0x7f51bc60c6d4]
 5  /opt/conda/envs/gdf/lib/libucp.so.0(ucp_rndv_data_handler+0x4e9) [0x7f51bc634a29]
 6  /opt/conda/envs/gdf/lib/libuct.so.0(+0x2045f) [0x7f51bc54645f]
 7  /opt/conda/envs/gdf/lib/libuct.so.0(+0x238c8) [0x7f51bc5498c8]
 8  /opt/conda/envs/gdf/lib/libucs.so.0(ucs_event_set_wait+0xb9) [0x7f51bc596399]
 9  /opt/conda/envs/gdf/lib/libuct.so.0(uct_tcp_iface_progress+0x7d) [0x7f51bc54865d]
10  /opt/conda/envs/gdf/lib/libucp.so.0(ucp_worker_progress+0x5a) [0x7f51bc60950a]
11  /opt/conda/envs/gdf/lib/python3.9/site-packages/ucp/_libs/ucx_api.cpython-39-x86_64-linux-gnu.so(+0x2b17a) [0x7f51bc6be17a]
12  /opt/conda/envs/gdf/bin/python(+0x13eb08) [0x55ca42e96b08]
13  /opt/conda/envs/gdf/bin/python(_PyEval_EvalFrameDefault+0x5f82) [0x55ca42e87112]
14  /opt/conda/envs/gdf/bin/python(+0x12827a) [0x55ca42e8027a]
15  /opt/conda/envs/gdf/bin/python(_PyFunction_Vectorcall+0xd5) [0x55ca42e91c05]
16  /opt/conda/envs/gdf/bin/python(_PyEval_EvalFrameDefault+0x68b) [0x55ca42e8181b]
17  /opt/conda/envs/gdf/bin/python(+0x14e70e) [0x55ca42ea670e]
18  /opt/conda/envs/gdf/lib/python3.9/lib-dynload/_asyncio.cpython-39-x86_64-linux-gnu.so(+0x82fe) [0x7f51dc9682fe]
19  /opt/conda/envs/gdf/bin/python(_PyObject_MakeTpCall+0x2fc) [0x55ca42e8a2bc]
20  /opt/conda/envs/gdf/bin/python(+0xe5817) [0x55ca42e3d817]
21  /opt/conda/envs/gdf/bin/python(+0x130f83) [0x55ca42e88f83]
22  /opt/conda/envs/gdf/bin/python(_PyEval_EvalFrameDefault+0x5ba6) [0x55ca42e86d36]
23  /opt/conda/envs/gdf/bin/python(+0x139ef3) [0x55ca42e91ef3]
24  /opt/conda/envs/gdf/bin/python(_PyEval_EvalFrameDefault+0x68b) [0x55ca42e8181b]
25  /opt/conda/envs/gdf/bin/python(+0x139ef3) [0x55ca42e91ef3]
26  /opt/conda/envs/gdf/bin/python(_PyEval_EvalFrameDefault+0x68b) [0x55ca42e8181b]
27  /opt/conda/envs/gdf/bin/python(+0x139ef3) [0x55ca42e91ef3]
28  /opt/conda/envs/gdf/bin/python(_PyEval_EvalFrameDefault+0x68b) [0x55ca42e8181b]
29  /opt/conda/envs/gdf/bin/python(+0x139ef3) [0x55ca42e91ef3]
30  /opt/conda/envs/gdf/bin/python(_PyEval_EvalFrameDefault+0x68b) [0x55ca42e8181b]
31  /opt/conda/envs/gdf/bin/python(+0x12827a) [0x55ca42e8027a]
32  /opt/conda/envs/gdf/bin/python(_PyFunction_Vectorcall+0xd5) [0x55ca42e91c05]
33  /opt/conda/envs/gdf/bin/python(_PyEval_EvalFrameDefault+0x4e17) [0x55ca42e85fa7]
34  /opt/conda/envs/gdf/bin/python(+0x12827a) [0x55ca42e8027a]
35  /opt/conda/envs/gdf/bin/python(+0x147935) [0x55ca42e9f935]
36  /opt/conda/envs/gdf/bin/python(PyObject_Call+0xb4) [0x55ca42ea0104]
37  /opt/conda/envs/gdf/bin/python(+0x20efc8) [0x55ca42f66fc8]
38  /opt/conda/envs/gdf/bin/python(_PyObject_MakeTpCall+0x2fc) [0x55ca42e8a2bc]
39  /opt/conda/envs/gdf/bin/python(_PyEval_EvalFrameDefault+0x402b) [0x55ca42e851bb]
40  /opt/conda/envs/gdf/bin/python(+0x139ef3) [0x55ca42e91ef3]
41  /opt/conda/envs/gdf/bin/python(+0x147c72) [0x55ca42e9fc72]
42  /opt/conda/envs/gdf/bin/python(_PyEval_EvalFrameDefault+0x402b) [0x55ca42e851bb]
43  /opt/conda/envs/gdf/bin/python(+0x139ef3) [0x55ca42e91ef3]
44  /opt/conda/envs/gdf/bin/python(_PyEval_EvalFrameDefault+0x68b) [0x55ca42e8181b]
45  /opt/conda/envs/gdf/bin/python(+0x12827a) [0x55ca42e8027a]
46  /opt/conda/envs/gdf/bin/python(_PyFunction_Vectorcall+0xd5) [0x55ca42e91c05]
47  /opt/conda/envs/gdf/bin/python(_PyEval_EvalFrameDefault+0x68b) [0x55ca42e8181b]
48  /opt/conda/envs/gdf/bin/python(+0x139ef3) [0x55ca42e91ef3]
49  /opt/conda/envs/gdf/bin/python(_PyEval_EvalFrameDefault+0x3d8) [0x55ca42e81568]
50  /opt/conda/envs/gdf/bin/python(+0x12827a) [0x55ca42e8027a]
51  /opt/conda/envs/gdf/bin/python(_PyFunction_Vectorcall+0xd5) [0x55ca42e91c05]
52  /opt/conda/envs/gdf/bin/python(_PyEval_EvalFrameDefault+0x123b) [0x55ca42e823cb]
53  /opt/conda/envs/gdf/bin/python(+0x12827a) [0x55ca42e8027a]
54  /opt/conda/envs/gdf/bin/python(_PyEval_EvalCodeWithName+0x47) [0x55ca42e7ff07]
55  /opt/conda/envs/gdf/bin/python(PyEval_EvalCodeEx+0x39) [0x55ca42e7feb9]
56  /opt/conda/envs/gdf/bin/python(PyEval_EvalCode+0x1b) [0x55ca42f308bb]
57  /opt/conda/envs/gdf/bin/python(+0x206adc) [0x55ca42f5eadc]
58  /opt/conda/envs/gdf/bin/python(+0x202c24) [0x55ca42f5ac24]
59  /opt/conda/envs/gdf/bin/python(PyRun_StringFlags+0x9d) [0x55ca42f527ed]
60  /opt/conda/envs/gdf/bin/python(PyRun_SimpleStringFlags+0x3d) [0x55ca42f526bd]
61  /opt/conda/envs/gdf/bin/python(Py_RunMain+0x262) [0x55ca42f518a2]
=================================
[dgx13:72948:0:72948] Caught signal 11 (Segmentation fault: address not mapped to object at address 0x448)
[dgx13:72961:0:72961] Caught signal 11 (Segmentation fault: address not mapped to object at address 0x448)
==== backtrace (tid:  72948) ====
 0  /opt/conda/envs/gdf/lib/libucs.so.0(ucs_handle_error+0x2fd) [0x7f8860bf9ced]
 1  /opt/conda/envs/gdf/lib/libucs.so.0(+0x2aee4) [0x7f8860bf9ee4]
 2  /opt/conda/envs/gdf/lib/libucs.so.0(+0x2b0aa) [0x7f8860bfa0aa]
 3  /usr/lib/x86_64-linux-gnu/libpthread.so.0(+0x14420) [0x7f8900342420]
 4  /opt/conda/envs/gdf/lib/libucp.so.0(ucp_mem_type_unpack+0x14) [0x7f8860c796d4]
 5  /opt/conda/envs/gdf/lib/libucp.so.0(ucp_rndv_data_handler+0x4e9) [0x7f8860ca1a29]
 6  /opt/conda/envs/gdf/lib/libuct.so.0(+0x2045f) [0x7f8860bb345f]
 7  /opt/conda/envs/gdf/lib/libuct.so.0(+0x238c8) [0x7f8860bb68c8]
 8  /opt/conda/envs/gdf/lib/libucs.so.0(ucs_event_set_wait+0xb9) [0x7f8860c03399]
 9  /opt/conda/envs/gdf/lib/libuct.so.0(uct_tcp_iface_progress+0x7d) [0x7f8860bb565d]
10  /opt/conda/envs/gdf/lib/libucp.so.0(ucp_worker_progress+0x5a) [0x7f8860c7650a]
11  /opt/conda/envs/gdf/lib/python3.9/site-packages/ucp/_libs/ucx_api.cpython-39-x86_64-linux-gnu.so(+0x2b17a) [0x7f8860d2b17a]
12  /opt/conda/envs/gdf/bin/python(+0x13eb08) [0x562aaadeab08]
13  /opt/conda/envs/gdf/bin/python(_PyEval_EvalFrameDefault+0x5f82) [0x562aaaddb112]
14  /opt/conda/envs/gdf/bin/python(+0x12827a) [0x562aaadd427a]
15  /opt/conda/envs/gdf/bin/python(_PyFunction_Vectorcall+0xd5) [0x562aaade5c05]
16  /opt/conda/envs/gdf/bin/python(_PyEval_EvalFrameDefault+0x68b) [0x562aaadd581b]
17  /opt/conda/envs/gdf/bin/python(+0x14e70e) [0x562aaadfa70e]
18  /opt/conda/envs/gdf/lib/python3.9/lib-dynload/_asyncio.cpython-39-x86_64-linux-gnu.so(+0x82fe) [0x7f8880fde2fe]
19  /opt/conda/envs/gdf/bin/python(_PyObject_MakeTpCall+0x2fc) [0x562aaadde2bc]
20  /opt/conda/envs/gdf/bin/python(+0xe5817) [0x562aaad91817]
21  /opt/conda/envs/gdf/bin/python(+0x130f83) [0x562aaaddcf83]
22  /opt/conda/envs/gdf/bin/python(_PyEval_EvalFrameDefault+0x5ba6) [0x562aaaddad36]
23  /opt/conda/envs/gdf/bin/python(+0x139ef3) [0x562aaade5ef3]
24  /opt/conda/envs/gdf/bin/python(_PyEval_EvalFrameDefault+0x68b) [0x562aaadd581b]
25  /opt/conda/envs/gdf/bin/python(+0x139ef3) [0x562aaade5ef3]
26  /opt/conda/envs/gdf/bin/python(_PyEval_EvalFrameDefault+0x68b) [0x562aaadd581b]
27  /opt/conda/envs/gdf/bin/python(+0x139ef3) [0x562aaade5ef3]
28  /opt/conda/envs/gdf/bin/python(_PyEval_EvalFrameDefault+0x68b) [0x562aaadd581b]
29  /opt/conda/envs/gdf/bin/python(+0x139ef3) [0x562aaade5ef3]
30  /opt/conda/envs/gdf/bin/python(_PyEval_EvalFrameDefault+0x68b) [0x562aaadd581b]
31  /opt/conda/envs/gdf/bin/python(+0x12827a) [0x562aaadd427a]
32  /opt/conda/envs/gdf/bin/python(_PyFunction_Vectorcall+0xd5) [0x562aaade5c05]
33  /opt/conda/envs/gdf/bin/python(_PyEval_EvalFrameDefault+0x4e17) [0x562aaadd9fa7]
34  /opt/conda/envs/gdf/bin/python(+0x12827a) [0x562aaadd427a]
35  /opt/conda/envs/gdf/bin/python(+0x147935) [0x562aaadf3935]
36  /opt/conda/envs/gdf/bin/python(PyObject_Call+0xb4) [0x562aaadf4104]
37  /opt/conda/envs/gdf/bin/python(+0x20efc8) [0x562aaaebafc8]
38  /opt/conda/envs/gdf/bin/python(_PyObject_MakeTpCall+0x2fc) [0x562aaadde2bc]
39  /opt/conda/envs/gdf/bin/python(_PyEval_EvalFrameDefault+0x402b) [0x562aaadd91bb]
40  /opt/conda/envs/gdf/bin/python(+0x139ef3) [0x562aaade5ef3]
41  /opt/conda/envs/gdf/bin/python(+0x147c72) [0x562aaadf3c72]
42  /opt/conda/envs/gdf/bin/python(_PyEval_EvalFrameDefault+0x402b) [0x562aaadd91bb]
43  /opt/conda/envs/gdf/bin/python(+0x139ef3) [0x562aaade5ef3]
44  /opt/conda/envs/gdf/bin/python(_PyEval_EvalFrameDefault+0x68b) [0x562aaadd581b]
45  /opt/conda/envs/gdf/bin/python(+0x12827a) [0x562aaadd427a]
46  /opt/conda/envs/gdf/bin/python(_PyFunction_Vectorcall+0xd5) [0x562aaade5c05]
47  /opt/conda/envs/gdf/bin/python(_PyEval_EvalFrameDefault+0x68b) [0x562aaadd581b]
48  /opt/conda/envs/gdf/bin/python(+0x139ef3) [0x562aaade5ef3]
49  /opt/conda/envs/gdf/bin/python(_PyEval_EvalFrameDefault+0x3d8) [0x562aaadd5568]
50  /opt/conda/envs/gdf/bin/python(+0x12827a) [0x562aaadd427a]
51  /opt/conda/envs/gdf/bin/python(_PyFunction_Vectorcall+0xd5) [0x562aaade5c05]
52  /opt/conda/envs/gdf/bin/python(_PyEval_EvalFrameDefault+0x123b) [0x562aaadd63cb]
53  /opt/conda/envs/gdf/bin/python(+0x12827a) [0x562aaadd427a]
54  /opt/conda/envs/gdf/bin/python(_PyEval_EvalCodeWithName+0x47) [0x562aaadd3f07]
55  /opt/conda/envs/gdf/bin/python(PyEval_EvalCodeEx+0x39) [0x562aaadd3eb9]
56  /opt/conda/envs/gdf/bin/python(PyEval_EvalCode+0x1b) [0x562aaae848bb]
57  /opt/conda/envs/gdf/bin/python(+0x206adc) [0x562aaaeb2adc]
58  /opt/conda/envs/gdf/bin/python(+0x202c24) [0x562aaaeaec24]
59  /opt/conda/envs/gdf/bin/python(PyRun_StringFlags+0x9d) [0x562aaaea67ed]
60  /opt/conda/envs/gdf/bin/python(PyRun_SimpleStringFlags+0x3d) [0x562aaaea66bd]
61  /opt/conda/envs/gdf/bin/python(Py_RunMain+0x262) [0x562aaaea58a2]
=================================
==== backtrace (tid:  72961) ====
 0  /opt/conda/envs/gdf/lib/libucs.so.0(ucs_handle_error+0x2fd) [0x7f71b85a1ced]
 1  /opt/conda/envs/gdf/lib/libucs.so.0(+0x2aee4) [0x7f71b85a1ee4]
 2  /opt/conda/envs/gdf/lib/libucs.so.0(+0x2b0aa) [0x7f71b85a20aa]
 3  /usr/lib/x86_64-linux-gnu/libpthread.so.0(+0x14420) [0x7f7257cd7420]
 4  /opt/conda/envs/gdf/lib/libucp.so.0(ucp_mem_type_unpack+0x14) [0x7f71b86216d4]
 5  /opt/conda/envs/gdf/lib/libucp.so.0(ucp_rndv_data_handler+0x4e9) [0x7f71b8649a29]
 6  /opt/conda/envs/gdf/lib/libuct.so.0(+0x2045f) [0x7f71b855b45f]
 7  /opt/conda/envs/gdf/lib/libuct.so.0(+0x238c8) [0x7f71b855e8c8]
 8  /opt/conda/envs/gdf/lib/libucs.so.0(ucs_event_set_wait+0xb9) [0x7f71b85ab399]
 9  /opt/conda/envs/gdf/lib/libuct.so.0(uct_tcp_iface_progress+0x7d) [0x7f71b855d65d]
10  /opt/conda/envs/gdf/lib/libucp.so.0(ucp_worker_progress+0x5a) [0x7f71b861e50a]
11  /opt/conda/envs/gdf/lib/python3.9/site-packages/ucp/_libs/ucx_api.cpython-39-x86_64-linux-gnu.so(+0x2b17a) [0x7f71b86d317a]
12  /opt/conda/envs/gdf/bin/python(+0x13eb08) [0x558f3eb97b08]
13  /opt/conda/envs/gdf/bin/python(_PyEval_EvalFrameDefault+0x5f82) [0x558f3eb88112]
14  /opt/conda/envs/gdf/bin/python(+0x12827a) [0x558f3eb8127a]
15  /opt/conda/envs/gdf/bin/python(_PyFunction_Vectorcall+0xd5) [0x558f3eb92c05]
16  /opt/conda/envs/gdf/bin/python(_PyEval_EvalFrameDefault+0x68b) [0x558f3eb8281b]
17  /opt/conda/envs/gdf/bin/python(+0x14e70e) [0x558f3eba770e]
18  /opt/conda/envs/gdf/lib/python3.9/lib-dynload/_asyncio.cpython-39-x86_64-linux-gnu.so(+0x82fe) [0x7f71d897f2fe]
19  /opt/conda/envs/gdf/bin/python(_PyObject_MakeTpCall+0x2fc) [0x558f3eb8b2bc]
20  /opt/conda/envs/gdf/bin/python(+0xe5817) [0x558f3eb3e817]
21  /opt/conda/envs/gdf/bin/python(+0x130f83) [0x558f3eb89f83]
22  /opt/conda/envs/gdf/bin/python(_PyEval_EvalFrameDefault+0x5ba6) [0x558f3eb87d36]
23  /opt/conda/envs/gdf/bin/python(+0x139ef3) [0x558f3eb92ef3]
24  /opt/conda/envs/gdf/bin/python(_PyEval_EvalFrameDefault+0x68b) [0x558f3eb8281b]
25  /opt/conda/envs/gdf/bin/python(+0x139ef3) [0x558f3eb92ef3]
26  /opt/conda/envs/gdf/bin/python(_PyEval_EvalFrameDefault+0x68b) [0x558f3eb8281b]
27  /opt/conda/envs/gdf/bin/python(+0x139ef3) [0x558f3eb92ef3]
28  /opt/conda/envs/gdf/bin/python(_PyEval_EvalFrameDefault+0x68b) [0x558f3eb8281b]
29  /opt/conda/envs/gdf/bin/python(+0x139ef3) [0x558f3eb92ef3]
30  /opt/conda/envs/gdf/bin/python(_PyEval_EvalFrameDefault+0x68b) [0x558f3eb8281b]
31  /opt/conda/envs/gdf/bin/python(+0x12827a) [0x558f3eb8127a]
32  /opt/conda/envs/gdf/bin/python(_PyFunction_Vectorcall+0xd5) [0x558f3eb92c05]
33  /opt/conda/envs/gdf/bin/python(_PyEval_EvalFrameDefault+0x4e17) [0x558f3eb86fa7]
34  /opt/conda/envs/gdf/bin/python(+0x12827a) [0x558f3eb8127a]
35  /opt/conda/envs/gdf/bin/python(+0x147935) [0x558f3eba0935]
36  /opt/conda/envs/gdf/bin/python(PyObject_Call+0xb4) [0x558f3eba1104]
37  /opt/conda/envs/gdf/bin/python(+0x20efc8) [0x558f3ec67fc8]
38  /opt/conda/envs/gdf/bin/python(_PyObject_MakeTpCall+0x2fc) [0x558f3eb8b2bc]
39  /opt/conda/envs/gdf/bin/python(_PyEval_EvalFrameDefault+0x402b) [0x558f3eb861bb]
40  /opt/conda/envs/gdf/bin/python(+0x139ef3) [0x558f3eb92ef3]
41  /opt/conda/envs/gdf/bin/python(+0x147c72) [0x558f3eba0c72]
42  /opt/conda/envs/gdf/bin/python(_PyEval_EvalFrameDefault+0x402b) [0x558f3eb861bb]
43  /opt/conda/envs/gdf/bin/python(+0x139ef3) [0x558f3eb92ef3]
44  /opt/conda/envs/gdf/bin/python(_PyEval_EvalFrameDefault+0x68b) [0x558f3eb8281b]
45  /opt/conda/envs/gdf/bin/python(+0x12827a) [0x558f3eb8127a]
46  /opt/conda/envs/gdf/bin/python(_PyFunction_Vectorcall+0xd5) [0x558f3eb92c05]
47  /opt/conda/envs/gdf/bin/python(_PyEval_EvalFrameDefault+0x68b) [0x558f3eb8281b]
48  /opt/conda/envs/gdf/bin/python(+0x139ef3) [0x558f3eb92ef3]
49  /opt/conda/envs/gdf/bin/python(_PyEval_EvalFrameDefault+0x3d8) [0x558f3eb82568]
50  /opt/conda/envs/gdf/bin/python(+0x12827a) [0x558f3eb8127a]
51  /opt/conda/envs/gdf/bin/python(_PyFunction_Vectorcall+0xd5) [0x558f3eb92c05]
52  /opt/conda/envs/gdf/bin/python(_PyEval_EvalFrameDefault+0x123b) [0x558f3eb833cb]
53  /opt/conda/envs/gdf/bin/python(+0x12827a) [0x558f3eb8127a]
54  /opt/conda/envs/gdf/bin/python(_PyEval_EvalCodeWithName+0x47) [0x558f3eb80f07]
55  /opt/conda/envs/gdf/bin/python(PyEval_EvalCodeEx+0x39) [0x558f3eb80eb9]
56  /opt/conda/envs/gdf/bin/python(PyEval_EvalCode+0x1b) [0x558f3ec318bb]
57  /opt/conda/envs/gdf/bin/python(+0x206adc) [0x558f3ec5fadc]
58  /opt/conda/envs/gdf/bin/python(+0x202c24) [0x558f3ec5bc24]
59  /opt/conda/envs/gdf/bin/python(PyRun_StringFlags+0x9d) [0x558f3ec537ed]
60  /opt/conda/envs/gdf/bin/python(PyRun_SimpleStringFlags+0x3d) [0x558f3ec536bd]
61  /opt/conda/envs/gdf/bin/python(Py_RunMain+0x262) [0x558f3ec528a2]
=================================
[dgx13:72946:0:72946] Caught signal 11 (Segmentation fault: address not mapped to object at address 0x448)
==== backtrace (tid:  72946) ====
 0  /opt/conda/envs/gdf/lib/libucs.so.0(ucs_handle_error+0x2fd) [0x7f69187c4ced]
 1  /opt/conda/envs/gdf/lib/libucs.so.0(+0x2aee4) [0x7f69187c4ee4]
 2  /opt/conda/envs/gdf/lib/libucs.so.0(+0x2b0aa) [0x7f69187c50aa]
 3  /usr/lib/x86_64-linux-gnu/libpthread.so.0(+0x14420) [0x7f69b7f02420]
 4  /opt/conda/envs/gdf/lib/libucp.so.0(ucp_mem_type_unpack+0x14) [0x7f69188446d4]
 5  /opt/conda/envs/gdf/lib/libucp.so.0(ucp_rndv_data_handler+0x4e9) [0x7f691886ca29]
 6  /opt/conda/envs/gdf/lib/libuct.so.0(+0x2045f) [0x7f691877e45f]
 7  /opt/conda/envs/gdf/lib/libuct.so.0(+0x238c8) [0x7f69187818c8]
 8  /opt/conda/envs/gdf/lib/libucs.so.0(ucs_event_set_wait+0xb9) [0x7f69187ce399]
 9  /opt/conda/envs/gdf/lib/libuct.so.0(uct_tcp_iface_progress+0x7d) [0x7f691878065d]
10  /opt/conda/envs/gdf/lib/libucp.so.0(ucp_worker_progress+0x5a) [0x7f691884150a]
11  /opt/conda/envs/gdf/lib/python3.9/site-packages/ucp/_libs/ucx_api.cpython-39-x86_64-linux-gnu.so(+0x2b17a) [0x7f69188f617a]
12  /opt/conda/envs/gdf/bin/python(+0x13eb08) [0x55f21457ab08]
13  /opt/conda/envs/gdf/bin/python(_PyEval_EvalFrameDefault+0x5f82) [0x55f21456b112]
14  /opt/conda/envs/gdf/bin/python(+0x12827a) [0x55f21456427a]
15  /opt/conda/envs/gdf/bin/python(_PyFunction_Vectorcall+0xd5) [0x55f214575c05]
16  /opt/conda/envs/gdf/bin/python(_PyEval_EvalFrameDefault+0x68b) [0x55f21456581b]
17  /opt/conda/envs/gdf/bin/python(+0x14e70e) [0x55f21458a70e]
18  /opt/conda/envs/gdf/lib/python3.9/lib-dynload/_asyncio.cpython-39-x86_64-linux-gnu.so(+0x82fe) [0x7f6938ba72fe]
19  /opt/conda/envs/gdf/bin/python(_PyObject_MakeTpCall+0x2fc) [0x55f21456e2bc]
20  /opt/conda/envs/gdf/bin/python(+0xe5817) [0x55f214521817]
21  /opt/conda/envs/gdf/bin/python(+0x130f83) [0x55f21456cf83]
22  /opt/conda/envs/gdf/bin/python(_PyEval_EvalFrameDefault+0x5ba6) [0x55f21456ad36]
23  /opt/conda/envs/gdf/bin/python(+0x139ef3) [0x55f214575ef3]
24  /opt/conda/envs/gdf/bin/python(_PyEval_EvalFrameDefault+0x68b) [0x55f21456581b]
25  /opt/conda/envs/gdf/bin/python(+0x139ef3) [0x55f214575ef3]
26  /opt/conda/envs/gdf/bin/python(_PyEval_EvalFrameDefault+0x68b) [0x55f21456581b]
27  /opt/conda/envs/gdf/bin/python(+0x139ef3) [0x55f214575ef3]
28  /opt/conda/envs/gdf/bin/python(_PyEval_EvalFrameDefault+0x68b) [0x55f21456581b]
29  /opt/conda/envs/gdf/bin/python(+0x139ef3) [0x55f214575ef3]
30  /opt/conda/envs/gdf/bin/python(_PyEval_EvalFrameDefault+0x68b) [0x55f21456581b]
31  /opt/conda/envs/gdf/bin/python(+0x12827a) [0x55f21456427a]
32  /opt/conda/envs/gdf/bin/python(_PyFunction_Vectorcall+0xd5) [0x55f214575c05]
33  /opt/conda/envs/gdf/bin/python(_PyEval_EvalFrameDefault+0x4e17) [0x55f214569fa7]
34  /opt/conda/envs/gdf/bin/python(+0x12827a) [0x55f21456427a]
35  /opt/conda/envs/gdf/bin/python(+0x147935) [0x55f214583935]
36  /opt/conda/envs/gdf/bin/python(PyObject_Call+0xb4) [0x55f214584104]
37  /opt/conda/envs/gdf/bin/python(+0x20efc8) [0x55f21464afc8]
38  /opt/conda/envs/gdf/bin/python(_PyObject_MakeTpCall+0x2fc) [0x55f21456e2bc]
39  /opt/conda/envs/gdf/bin/python(_PyEval_EvalFrameDefault+0x402b) [0x55f2145691bb]
40  /opt/conda/envs/gdf/bin/python(+0x139ef3) [0x55f214575ef3]
41  /opt/conda/envs/gdf/bin/python(+0x147c72) [0x55f214583c72]
42  /opt/conda/envs/gdf/bin/python(_PyEval_EvalFrameDefault+0x402b) [0x55f2145691bb]
43  /opt/conda/envs/gdf/bin/python(+0x139ef3) [0x55f214575ef3]
44  /opt/conda/envs/gdf/bin/python(_PyEval_EvalFrameDefault+0x68b) [0x55f21456581b]
45  /opt/conda/envs/gdf/bin/python(+0x12827a) [0x55f21456427a]
46  /opt/conda/envs/gdf/bin/python(_PyFunction_Vectorcall+0xd5) [0x55f214575c05]
47  /opt/conda/envs/gdf/bin/python(_PyEval_EvalFrameDefault+0x68b) [0x55f21456581b]
48  /opt/conda/envs/gdf/bin/python(+0x139ef3) [0x55f214575ef3]
49  /opt/conda/envs/gdf/bin/python(_PyEval_EvalFrameDefault+0x3d8) [0x55f214565568]
50  /opt/conda/envs/gdf/bin/python(+0x12827a) [0x55f21456427a]
51  /opt/conda/envs/gdf/bin/python(_PyFunction_Vectorcall+0xd5) [0x55f214575c05]
52  /opt/conda/envs/gdf/bin/python(_PyEval_EvalFrameDefault+0x123b) [0x55f2145663cb]
53  /opt/conda/envs/gdf/bin/python(+0x12827a) [0x55f21456427a]
54  /opt/conda/envs/gdf/bin/python(_PyEval_EvalCodeWithName+0x47) [0x55f214563f07]
55  /opt/conda/envs/gdf/bin/python(PyEval_EvalCodeEx+0x39) [0x55f214563eb9]
56  /opt/conda/envs/gdf/bin/python(PyEval_EvalCode+0x1b) [0x55f2146148bb]
57  /opt/conda/envs/gdf/bin/python(+0x206adc) [0x55f214642adc]
58  /opt/conda/envs/gdf/bin/python(+0x202c24) [0x55f21463ec24]
59  /opt/conda/envs/gdf/bin/python(PyRun_StringFlags+0x9d) [0x55f2146367ed]
60  /opt/conda/envs/gdf/bin/python(PyRun_SimpleStringFlags+0x3d) [0x55f2146366bd]
61  /opt/conda/envs/gdf/bin/python(Py_RunMain+0x262) [0x55f2146358a2]
=================================
2023-07-05 05:53:29,789 - distributed.worker - ERROR - Worker stream died during communication: ucx://127.0.0.1:48457
Traceback (most recent call last):
  File "/opt/conda/envs/gdf/lib/python3.9/site-packages/distributed/comm/ucx.py", line 349, in read
    await self.ep.recv(msg)
  File "/opt/conda/envs/gdf/lib/python3.9/site-packages/ucp/core.py", line 725, in recv
    ret = await comm.tag_recv(self._ep, buffer, nbytes, tag, name=log)
ucp._libs.exceptions.UCXCanceled: <[Recv #003] ep: 0x7f1c676fb100, tag: 0xe911a950d48e19ae, nbytes: 16, type: <class 'numpy.ndarray'>>: 

During handling of the above exception, another exception occurred:

Traceback (most recent call last):
  File "/opt/conda/envs/gdf/lib/python3.9/site-packages/distributed/worker.py", line 2066, in gather_dep
    response = await get_data_from_worker(
  File "/opt/conda/envs/gdf/lib/python3.9/site-packages/distributed/worker.py", line 2892, in get_data_from_worker
    response = await send_recv(
  File "/opt/conda/envs/gdf/lib/python3.9/site-packages/distributed/core.py", line 1024, in send_recv
    response = await comm.read(deserializers=deserializers)
  File "/opt/conda/envs/gdf/lib/python3.9/site-packages/distributed/utils.py", line 752, in wrapper
    return await func(*args, **kwargs)
  File "/opt/conda/envs/gdf/lib/python3.9/site-packages/distributed/comm/ucx.py", line 367, in read
    raise CommClosedError(
distributed.comm.core.CommClosedError: Connection closed by writer.
Inner exception: UCXCanceled("<[Recv #003] ep: 0x7f1c676fb100, tag: 0xe911a950d48e19ae, nbytes: 16, type: <class 'numpy.ndarray'>>: ")
2023-07-05 05:53:29,792 - distributed.worker - ERROR - Worker stream died during communication: ucx://127.0.0.1:52739
Traceback (most recent call last):
  File "/opt/conda/envs/gdf/lib/python3.9/site-packages/distributed/comm/ucx.py", line 391, in read
    await self.ep.recv(each_frame)
  File "/opt/conda/envs/gdf/lib/python3.9/site-packages/ucp/core.py", line 725, in recv
    ret = await comm.tag_recv(self._ep, buffer, nbytes, tag, name=log)
ucp._libs.exceptions.UCXCanceled: <[Recv #010] ep: 0x7f1c676fb1c0, tag: 0xfe6f073d95ab1cb9, nbytes: 50000000, type: <class 'rmm._lib.device_buffer.DeviceBuffer'>>: 

During handling of the above exception, another exception occurred:

Traceback (most recent call last):
  File "/opt/conda/envs/gdf/lib/python3.9/site-packages/distributed/worker.py", line 2066, in gather_dep
    response = await get_data_from_worker(
  File "/opt/conda/envs/gdf/lib/python3.9/site-packages/distributed/worker.py", line 2892, in get_data_from_worker
    response = await send_recv(
  File "/opt/conda/envs/gdf/lib/python3.9/site-packages/distributed/core.py", line 1024, in send_recv
    response = await comm.read(deserializers=deserializers)
  File "/opt/conda/envs/gdf/lib/python3.9/site-packages/distributed/utils.py", line 752, in wrapper
    return await func(*args, **kwargs)
  File "/opt/conda/envs/gdf/lib/python3.9/site-packages/distributed/comm/ucx.py", line 397, in read
    raise CommClosedError(
distributed.comm.core.CommClosedError: Connection closed by writer.
Inner exception: UCXCanceled("<[Recv #010] ep: 0x7f1c676fb1c0, tag: 0xfe6f073d95ab1cb9, nbytes: 50000000, type: <class 'rmm._lib.device_buffer.DeviceBuffer'>>: ")
2023-07-05 05:53:29,791 - distributed.worker - ERROR - Worker stream died during communication: ucx://127.0.0.1:52739
Traceback (most recent call last):
  File "/opt/conda/envs/gdf/lib/python3.9/site-packages/distributed/comm/ucx.py", line 349, in read
    await self.ep.recv(msg)
  File "/opt/conda/envs/gdf/lib/python3.9/site-packages/ucp/core.py", line 725, in recv
    ret = await comm.tag_recv(self._ep, buffer, nbytes, tag, name=log)
ucp._libs.exceptions.UCXCanceled: <[Recv #000] ep: 0x7efe705bb1c0, tag: 0x8ecc22202a774e20, nbytes: 16, type: <class 'numpy.ndarray'>>: 

During handling of the above exception, another exception occurred:

Traceback (most recent call last):
  File "/opt/conda/envs/gdf/lib/python3.9/site-packages/distributed/comm/core.py", line 329, in connect
    handshake = await wait_for(comm.read(), time_left())
  File "/opt/conda/envs/gdf/lib/python3.9/site-packages/distributed/utils.py", line 1849, in wait_for
    return await asyncio.wait_for(fut, timeout)
  File "/opt/conda/envs/gdf/lib/python3.9/asyncio/tasks.py", line 479, in wait_for
    return fut.result()
  File "/opt/conda/envs/gdf/lib/python3.9/site-packages/distributed/utils.py", line 752, in wrapper
    return await func(*args, **kwargs)
  File "/opt/conda/envs/gdf/lib/python3.9/site-packages/distributed/comm/ucx.py", line 367, in read
    raise CommClosedError(
distributed.comm.core.CommClosedError: Connection closed by writer.
Inner exception: UCXCanceled("<[Recv #000] ep: 0x7efe705bb1c0, tag: 0x8ecc22202a774e20, nbytes: 16, type: <class 'numpy.ndarray'>>: ")

The above exception was the direct cause of the following exception:

Traceback (most recent call last):
  File "/opt/conda/envs/gdf/lib/python3.9/site-packages/distributed/worker.py", line 2066, in gather_dep
    response = await get_data_from_worker(
  File "/opt/conda/envs/gdf/lib/python3.9/site-packages/distributed/worker.py", line 2889, in get_data_from_worker
    comm = await rpc.connect(worker)
  File "/opt/conda/envs/gdf/lib/python3.9/site-packages/distributed/core.py", line 1506, in connect
    return await connect_attempt
  File "/opt/conda/envs/gdf/lib/python3.9/site-packages/distributed/core.py", line 1427, in _connect
    comm = await connect(
  File "/opt/conda/envs/gdf/lib/python3.9/site-packages/distributed/comm/core.py", line 334, in connect
    raise OSError(
OSError: Timed out during handshake while connecting to ucx://127.0.0.1:52739 after 30 s
2023-07-05 05:53:29,793 - distributed.worker - ERROR - failed during get data with ucx://127.0.0.1:52501 -> ucx://127.0.0.1:52739
Traceback (most recent call last):
  File "/opt/conda/envs/gdf/lib/python3.9/site-packages/distributed/worker.py", line 1792, in get_data
    compressed = await comm.write(msg, serializers=serializers)
  File "/opt/conda/envs/gdf/lib/python3.9/site-packages/distributed/utils.py", line 752, in wrapper
    return await func(*args, **kwargs)
  File "/opt/conda/envs/gdf/lib/python3.9/site-packages/distributed/comm/ucx.py", line 289, in write
    raise CommClosedError("Endpoint is closed -- unable to send message")
distributed.comm.core.CommClosedError: Endpoint is closed -- unable to send message
2023-07-05 05:53:29,794 - distributed.worker - ERROR - Worker stream died during communication: ucx://127.0.0.1:52739
Traceback (most recent call last):
  File "/opt/conda/envs/gdf/lib/python3.9/site-packages/distributed/comm/ucx.py", line 391, in read
    await self.ep.recv(each_frame)
  File "/opt/conda/envs/gdf/lib/python3.9/site-packages/ucp/core.py", line 708, in recv
    self._ep.raise_on_error()
  File "ucp/_libs/ucx_endpoint.pyx", line 353, in ucp._libs.ucx_api.UCXEndpoint.raise_on_error
ucp._libs.exceptions.UCXConnectionReset: Endpoint 0x7fa641c521c0 error: Connection reset by remote peer

During handling of the above exception, another exception occurred:

Traceback (most recent call last):
  File "/opt/conda/envs/gdf/lib/python3.9/site-packages/distributed/worker.py", line 2066, in gather_dep
    response = await get_data_from_worker(
  File "/opt/conda/envs/gdf/lib/python3.9/site-packages/distributed/worker.py", line 2892, in get_data_from_worker
    response = await send_recv(
  File "/opt/conda/envs/gdf/lib/python3.9/site-packages/distributed/core.py", line 1024, in send_recv
    response = await comm.read(deserializers=deserializers)
  File "/opt/conda/envs/gdf/lib/python3.9/site-packages/distributed/utils.py", line 752, in wrapper
    return await func(*args, **kwargs)
  File "/opt/conda/envs/gdf/lib/python3.9/site-packages/distributed/comm/ucx.py", line 397, in read
    raise CommClosedError(
distributed.comm.core.CommClosedError: Connection closed by writer.
Inner exception: UCXConnectionReset('Endpoint 0x7fa641c521c0 error: Connection reset by remote peer')
2023-07-05 05:53:29,808 - distributed.worker - ERROR - failed during get data with ucx://127.0.0.1:52501 -> ucx://127.0.0.1:48457
Traceback (most recent call last):
  File "/opt/conda/envs/gdf/lib/python3.9/site-packages/distributed/worker.py", line 1792, in get_data
    compressed = await comm.write(msg, serializers=serializers)
  File "/opt/conda/envs/gdf/lib/python3.9/site-packages/distributed/utils.py", line 752, in wrapper
    return await func(*args, **kwargs)
  File "/opt/conda/envs/gdf/lib/python3.9/site-packages/distributed/comm/ucx.py", line 289, in write
    raise CommClosedError("Endpoint is closed -- unable to send message")
distributed.comm.core.CommClosedError: Endpoint is closed -- unable to send message
Task exception was never retrieved
future: <Task finished name='Task-925' coro=<_listener_handler_coroutine() done, defined at /opt/conda/envs/gdf/lib/python3.9/site-packages/ucp/core.py:128> exception=UCXError('<stream_send>: Connection reset by remote peer')>
Traceback (most recent call last):
  File "/opt/conda/envs/gdf/lib/python3.9/site-packages/ucp/core.py", line 143, in _listener_handler_coroutine
    peer_info = await exchange_peer_info(
  File "/opt/conda/envs/gdf/lib/python3.9/site-packages/ucp/core.py", line 51, in exchange_peer_info
    await comm.stream_send(endpoint, my_info_arr, my_info_arr.nbytes)
ucp._libs.exceptions.UCXError: <stream_send>: Connection reset by remote peer
2023-07-05 05:53:29,817 - distributed.worker - ERROR - failed during get data with ucx://127.0.0.1:36155 -> ucx://127.0.0.1:54063
Traceback (most recent call last):
  File "/opt/conda/envs/gdf/lib/python3.9/site-packages/distributed/comm/ucx.py", line 333, in write
    await self.ep.send(each_frame)
  File "/opt/conda/envs/gdf/lib/python3.9/site-packages/ucp/core.py", line 650, in send
    return await comm.tag_send(self._ep, buffer, nbytes, tag, name=log)
ucp._libs.exceptions.UCXError: <[Send #007] ep: 0x7f1c676fb340, tag: 0x11c4574a49932799, nbytes: 100000000, type: <class 'cudf.core.buffer.buffer.Buffer'>>: Connection reset by remote peer

During handling of the above exception, another exception occurred:

Traceback (most recent call last):
  File "/opt/conda/envs/gdf/lib/python3.9/site-packages/distributed/worker.py", line 1792, in get_data
    compressed = await comm.write(msg, serializers=serializers)
  File "/opt/conda/envs/gdf/lib/python3.9/site-packages/distributed/utils.py", line 752, in wrapper
    return await func(*args, **kwargs)
  File "/opt/conda/envs/gdf/lib/python3.9/site-packages/distributed/comm/ucx.py", line 337, in write
    raise CommClosedError("While writing, the connection was closed")
distributed.comm.core.CommClosedError: While writing, the connection was closed
2023-07-05 05:53:29,819 - distributed.worker - ERROR - Worker stream died during communication: ucx://127.0.0.1:55957
Traceback (most recent call last):
  File "/opt/conda/envs/gdf/lib/python3.9/site-packages/distributed/comm/ucx.py", line 349, in read
    await self.ep.recv(msg)
  File "/opt/conda/envs/gdf/lib/python3.9/site-packages/ucp/core.py", line 725, in recv
    ret = await comm.tag_recv(self._ep, buffer, nbytes, tag, name=log)
ucp._libs.exceptions.UCXCanceled: <[Recv #003] ep: 0x7f1c676fb180, tag: 0xd1559a214a85a8cc, nbytes: 16, type: <class 'numpy.ndarray'>>: 

During handling of the above exception, another exception occurred:

Traceback (most recent call last):
  File "/opt/conda/envs/gdf/lib/python3.9/site-packages/distributed/worker.py", line 2066, in gather_dep
    response = await get_data_from_worker(
  File "/opt/conda/envs/gdf/lib/python3.9/site-packages/distributed/worker.py", line 2892, in get_data_from_worker
    response = await send_recv(
  File "/opt/conda/envs/gdf/lib/python3.9/site-packages/distributed/core.py", line 1024, in send_recv
    response = await comm.read(deserializers=deserializers)
  File "/opt/conda/envs/gdf/lib/python3.9/site-packages/distributed/utils.py", line 752, in wrapper
    return await func(*args, **kwargs)
  File "/opt/conda/envs/gdf/lib/python3.9/site-packages/distributed/comm/ucx.py", line 367, in read
    raise CommClosedError(
distributed.comm.core.CommClosedError: Connection closed by writer.
Inner exception: UCXCanceled("<[Recv #003] ep: 0x7f1c676fb180, tag: 0xd1559a214a85a8cc, nbytes: 16, type: <class 'numpy.ndarray'>>: ")
2023-07-05 05:53:29,825 - distributed.worker - ERROR - Worker stream died during communication: ucx://127.0.0.1:54063
Traceback (most recent call last):
  File "/opt/conda/envs/gdf/lib/python3.9/site-packages/distributed/comm/ucx.py", line 349, in read
    await self.ep.recv(msg)
  File "/opt/conda/envs/gdf/lib/python3.9/site-packages/ucp/core.py", line 725, in recv
    ret = await comm.tag_recv(self._ep, buffer, nbytes, tag, name=log)
ucp._libs.exceptions.UCXCanceled: <[Recv #003] ep: 0x7f1c676fb200, tag: 0x60464d4e26f2c915, nbytes: 16, type: <class 'numpy.ndarray'>>: 

During handling of the above exception, another exception occurred:

Traceback (most recent call last):
  File "/opt/conda/envs/gdf/lib/python3.9/site-packages/distributed/worker.py", line 2066, in gather_dep
    response = await get_data_from_worker(
  File "/opt/conda/envs/gdf/lib/python3.9/site-packages/distributed/worker.py", line 2892, in get_data_from_worker
    response = await send_recv(
  File "/opt/conda/envs/gdf/lib/python3.9/site-packages/distributed/core.py", line 1024, in send_recv
    response = await comm.read(deserializers=deserializers)
  File "/opt/conda/envs/gdf/lib/python3.9/site-packages/distributed/utils.py", line 752, in wrapper
    return await func(*args, **kwargs)
  File "/opt/conda/envs/gdf/lib/python3.9/site-packages/distributed/comm/ucx.py", line 367, in read
    raise CommClosedError(
distributed.comm.core.CommClosedError: Connection closed by writer.
Inner exception: UCXCanceled("<[Recv #003] ep: 0x7f1c676fb200, tag: 0x60464d4e26f2c915, nbytes: 16, type: <class 'numpy.ndarray'>>: ")
2023-07-05 05:53:29,794 - distributed.worker - ERROR - Worker stream died during communication: ucx://127.0.0.1:48457
Traceback (most recent call last):
  File "/opt/conda/envs/gdf/lib/python3.9/site-packages/distributed/comm/ucx.py", line 466, in connect
    ep = await ucp.create_endpoint(ip, port)
  File "/opt/conda/envs/gdf/lib/python3.9/site-packages/ucp/core.py", line 1004, in create_endpoint
    return await _get_ctx().create_endpoint(
  File "/opt/conda/envs/gdf/lib/python3.9/site-packages/ucp/core.py", line 316, in create_endpoint
    peer_info = await exchange_peer_info(
  File "/opt/conda/envs/gdf/lib/python3.9/site-packages/ucp/core.py", line 54, in exchange_peer_info
    await comm.stream_recv(endpoint, peer_info_arr, peer_info_arr.nbytes)
ucp._libs.exceptions.UCXNotConnected: <stream_recv>: 

During handling of the above exception, another exception occurred:

Traceback (most recent call last):
  File "/opt/conda/envs/gdf/lib/python3.9/site-packages/distributed/comm/core.py", line 292, in connect
    comm = await wait_for(
  File "/opt/conda/envs/gdf/lib/python3.9/site-packages/distributed/utils.py", line 1849, in wait_for
    return await asyncio.wait_for(fut, timeout)
  File "/opt/conda/envs/gdf/lib/python3.9/asyncio/tasks.py", line 479, in wait_for
    return fut.result()
  File "/opt/conda/envs/gdf/lib/python3.9/site-packages/distributed/comm/ucx.py", line 468, in connect
    raise CommClosedError("Connection closed before handshake completed")
distributed.comm.core.CommClosedError: Connection closed before handshake completed

During handling of the above exception, another exception occurred:

Traceback (most recent call last):
  File "/opt/conda/envs/gdf/lib/python3.9/site-packages/distributed/core.py", line 1427, in _connect
    comm = await connect(
  File "/opt/conda/envs/gdf/lib/python3.9/site-packages/distributed/comm/core.py", line 316, in connect
    await asyncio.sleep(backoff)
  File "/opt/conda/envs/gdf/lib/python3.9/asyncio/tasks.py", line 652, in sleep
    return await future
asyncio.exceptions.CancelledError

During handling of the above exception, another exception occurred:

Traceback (most recent call last):
  File "/opt/conda/envs/gdf/lib/python3.9/site-packages/distributed/worker.py", line 2066, in gather_dep
    response = await get_data_from_worker(
  File "/opt/conda/envs/gdf/lib/python3.9/site-packages/distributed/worker.py", line 2889, in get_data_from_worker
    comm = await rpc.connect(worker)
  File "/opt/conda/envs/gdf/lib/python3.9/site-packages/distributed/core.py", line 1506, in connect
    return await connect_attempt
  File "/opt/conda/envs/gdf/lib/python3.9/site-packages/distributed/core.py", line 1450, in _connect
    raise CommClosedError(reason)
distributed.comm.core.CommClosedError: Address removed.
2023-07-05 05:53:29,810 - distributed.worker - ERROR - Worker stream died during communication: ucx://127.0.0.1:55957
Traceback (most recent call last):
  File "/opt/conda/envs/gdf/lib/python3.9/site-packages/distributed/comm/ucx.py", line 349, in read
    await self.ep.recv(msg)
  File "/opt/conda/envs/gdf/lib/python3.9/site-packages/ucp/core.py", line 725, in recv
    ret = await comm.tag_recv(self._ep, buffer, nbytes, tag, name=log)
ucp._libs.exceptions.UCXCanceled: <[Recv #003] ep: 0x7fa641c52240, tag: 0xb26dea6f51a6af97, nbytes: 16, type: <class 'numpy.ndarray'>>: 

During handling of the above exception, another exception occurred:

Traceback (most recent call last):
  File "/opt/conda/envs/gdf/lib/python3.9/site-packages/distributed/worker.py", line 2066, in gather_dep
    response = await get_data_from_worker(
  File "/opt/conda/envs/gdf/lib/python3.9/site-packages/distributed/worker.py", line 2892, in get_data_from_worker
    response = await send_recv(
  File "/opt/conda/envs/gdf/lib/python3.9/site-packages/distributed/core.py", line 1024, in send_recv
    response = await comm.read(deserializers=deserializers)
  File "/opt/conda/envs/gdf/lib/python3.9/site-packages/distributed/utils.py", line 752, in wrapper
    return await func(*args, **kwargs)
  File "/opt/conda/envs/gdf/lib/python3.9/site-packages/distributed/comm/ucx.py", line 367, in read
    raise CommClosedError(
distributed.comm.core.CommClosedError: Connection closed by writer.
Inner exception: UCXCanceled("<[Recv #003] ep: 0x7fa641c52240, tag: 0xb26dea6f51a6af97, nbytes: 16, type: <class 'numpy.ndarray'>>: ")
2023-07-05 05:53:29,875 - distributed.nanny - WARNING - Restarting worker
2023-07-05 05:53:29,926 - distributed.worker - ERROR - failed during get data with ucx://127.0.0.1:52501 -> ucx://127.0.0.1:55957
Traceback (most recent call last):
  File "/opt/conda/envs/gdf/lib/python3.9/site-packages/distributed/comm/ucx.py", line 315, in write
    await self.ep.send(struct.pack("?Q", False, nframes))
  File "/opt/conda/envs/gdf/lib/python3.9/site-packages/ucp/core.py", line 629, in send
    self._ep.raise_on_error()
  File "ucp/_libs/ucx_endpoint.pyx", line 353, in ucp._libs.ucx_api.UCXEndpoint.raise_on_error
ucp._libs.exceptions.UCXConnectionReset: Endpoint 0x7fa641c52300 error: Connection reset by remote peer

During handling of the above exception, another exception occurred:

Traceback (most recent call last):
  File "/opt/conda/envs/gdf/lib/python3.9/site-packages/distributed/worker.py", line 1792, in get_data
    compressed = await comm.write(msg, serializers=serializers)
  File "/opt/conda/envs/gdf/lib/python3.9/site-packages/distributed/utils.py", line 752, in wrapper
    return await func(*args, **kwargs)
  File "/opt/conda/envs/gdf/lib/python3.9/site-packages/distributed/comm/ucx.py", line 337, in write
    raise CommClosedError("While writing, the connection was closed")
distributed.comm.core.CommClosedError: While writing, the connection was closed
2023-07-05 05:53:29,928 - distributed.worker - ERROR - Worker stream died during communication: ucx://127.0.0.1:48457
Traceback (most recent call last):
  File "/opt/conda/envs/gdf/lib/python3.9/asyncio/tasks.py", line 466, in wait_for
    await waiter
asyncio.exceptions.CancelledError

During handling of the above exception, another exception occurred:

Traceback (most recent call last):
  File "/opt/conda/envs/gdf/lib/python3.9/site-packages/distributed/comm/core.py", line 330, in connect
    await wait_for(comm.write(local_info), time_left())
  File "/opt/conda/envs/gdf/lib/python3.9/site-packages/distributed/utils.py", line 1849, in wait_for
    return await asyncio.wait_for(fut, timeout)
  File "/opt/conda/envs/gdf/lib/python3.9/asyncio/tasks.py", line 469, in wait_for
    return fut.result()
  File "/opt/conda/envs/gdf/lib/python3.9/site-packages/distributed/utils.py", line 752, in wrapper
    return await func(*args, **kwargs)
  File "/opt/conda/envs/gdf/lib/python3.9/site-packages/distributed/comm/ucx.py", line 289, in write
    raise CommClosedError("Endpoint is closed -- unable to send message")
distributed.comm.core.CommClosedError: Endpoint is closed -- unable to send message

The above exception was the direct cause of the following exception:

Traceback (most recent call last):
  File "/opt/conda/envs/gdf/lib/python3.9/site-packages/distributed/worker.py", line 2066, in gather_dep
    response = await get_data_from_worker(
  File "/opt/conda/envs/gdf/lib/python3.9/site-packages/distributed/worker.py", line 2889, in get_data_from_worker
    comm = await rpc.connect(worker)
  File "/opt/conda/envs/gdf/lib/python3.9/site-packages/distributed/core.py", line 1506, in connect
    return await connect_attempt
  File "/opt/conda/envs/gdf/lib/python3.9/site-packages/distributed/core.py", line 1427, in _connect
    comm = await connect(
  File "/opt/conda/envs/gdf/lib/python3.9/site-packages/distributed/comm/core.py", line 334, in connect
    raise OSError(
OSError: Timed out during handshake while connecting to ucx://127.0.0.1:48457 after 30 s
2023-07-05 05:53:29,999 - distributed.worker - ERROR - Worker stream died during communication: ucx://127.0.0.1:54063
Traceback (most recent call last):
  File "/opt/conda/envs/gdf/lib/python3.9/site-packages/distributed/comm/core.py", line 330, in connect
    await wait_for(comm.write(local_info), time_left())
  File "/opt/conda/envs/gdf/lib/python3.9/site-packages/distributed/utils.py", line 1849, in wait_for
    return await asyncio.wait_for(fut, timeout)
  File "/opt/conda/envs/gdf/lib/python3.9/asyncio/tasks.py", line 479, in wait_for
    return fut.result()
  File "/opt/conda/envs/gdf/lib/python3.9/site-packages/distributed/utils.py", line 752, in wrapper
    return await func(*args, **kwargs)
  File "/opt/conda/envs/gdf/lib/python3.9/site-packages/distributed/comm/ucx.py", line 289, in write
    raise CommClosedError("Endpoint is closed -- unable to send message")
distributed.comm.core.CommClosedError: Endpoint is closed -- unable to send message

The above exception was the direct cause of the following exception:

Traceback (most recent call last):
  File "/opt/conda/envs/gdf/lib/python3.9/site-packages/distributed/worker.py", line 2066, in gather_dep
    response = await get_data_from_worker(
  File "/opt/conda/envs/gdf/lib/python3.9/site-packages/distributed/worker.py", line 2889, in get_data_from_worker
    comm = await rpc.connect(worker)
  File "/opt/conda/envs/gdf/lib/python3.9/site-packages/distributed/core.py", line 1506, in connect
    return await connect_attempt
  File "/opt/conda/envs/gdf/lib/python3.9/site-packages/distributed/core.py", line 1427, in _connect
    comm = await connect(
  File "/opt/conda/envs/gdf/lib/python3.9/site-packages/distributed/comm/core.py", line 334, in connect
    raise OSError(
OSError: Timed out during handshake while connecting to ucx://127.0.0.1:54063 after 30 s
2023-07-05 05:53:30,064 - distributed.nanny - WARNING - Restarting worker
2023-07-05 05:53:30,065 - distributed.nanny - WARNING - Restarting worker
2023-07-05 05:53:30,116 - distributed.worker - ERROR - Worker stream died during communication: ucx://127.0.0.1:54063
Traceback (most recent call last):
  File "/opt/conda/envs/gdf/lib/python3.9/asyncio/tasks.py", line 466, in wait_for
    await waiter
asyncio.exceptions.CancelledError

During handling of the above exception, another exception occurred:

Traceback (most recent call last):
  File "/opt/conda/envs/gdf/lib/python3.9/site-packages/distributed/comm/core.py", line 329, in connect
    handshake = await wait_for(comm.read(), time_left())
  File "/opt/conda/envs/gdf/lib/python3.9/site-packages/distributed/utils.py", line 1849, in wait_for
    return await asyncio.wait_for(fut, timeout)
  File "/opt/conda/envs/gdf/lib/python3.9/asyncio/tasks.py", line 469, in wait_for
    return fut.result()
  File "/opt/conda/envs/gdf/lib/python3.9/site-packages/distributed/utils.py", line 752, in wrapper
    return await func(*args, **kwargs)
  File "/opt/conda/envs/gdf/lib/python3.9/site-packages/distributed/comm/ucx.py", line 367, in read
    raise CommClosedError(
distributed.comm.core.CommClosedError: Connection closed by writer.
Inner exception: UCXCanceled("<[Recv #000] ep: 0x7efe705bb200, tag: 0x5a6fc99a24dcea8c, nbytes: 16, type: <class 'numpy.ndarray'>>: ")

The above exception was the direct cause of the following exception:

Traceback (most recent call last):
  File "/opt/conda/envs/gdf/lib/python3.9/site-packages/distributed/worker.py", line 2066, in gather_dep
    response = await get_data_from_worker(
  File "/opt/conda/envs/gdf/lib/python3.9/site-packages/distributed/worker.py", line 2889, in get_data_from_worker
    comm = await rpc.connect(worker)
  File "/opt/conda/envs/gdf/lib/python3.9/site-packages/distributed/core.py", line 1506, in connect
    return await connect_attempt
  File "/opt/conda/envs/gdf/lib/python3.9/site-packages/distributed/core.py", line 1427, in _connect
    comm = await connect(
  File "/opt/conda/envs/gdf/lib/python3.9/site-packages/distributed/comm/core.py", line 334, in connect
    raise OSError(
OSError: Timed out during handshake while connecting to ucx://127.0.0.1:54063 after 30 s
2023-07-05 05:53:30,118 - distributed.nanny - WARNING - Restarting worker
2023-07-05 05:53:30,419 - distributed.worker - ERROR - failed during get data with ucx://127.0.0.1:36155 -> ucx://127.0.0.1:52739
Traceback (most recent call last):
  File "/opt/conda/envs/gdf/lib/python3.9/site-packages/distributed/comm/ucx.py", line 333, in write
    await self.ep.send(each_frame)
  File "/opt/conda/envs/gdf/lib/python3.9/site-packages/ucp/core.py", line 650, in send
    return await comm.tag_send(self._ep, buffer, nbytes, tag, name=log)
ucp._libs.exceptions.UCXError: <[Send #007] ep: 0x7f1c676fb280, tag: 0xc58e6065a77cdd34, nbytes: 100000000, type: <class 'cudf.core.buffer.buffer.Buffer'>>: Connection reset by remote peer

During handling of the above exception, another exception occurred:

Traceback (most recent call last):
  File "/opt/conda/envs/gdf/lib/python3.9/site-packages/distributed/worker.py", line 1792, in get_data
    compressed = await comm.write(msg, serializers=serializers)
  File "/opt/conda/envs/gdf/lib/python3.9/site-packages/distributed/utils.py", line 752, in wrapper
    return await func(*args, **kwargs)
  File "/opt/conda/envs/gdf/lib/python3.9/site-packages/distributed/comm/ucx.py", line 337, in write
    raise CommClosedError("While writing, the connection was closed")
distributed.comm.core.CommClosedError: While writing, the connection was closed
2023-07-05 05:53:30,866 - distributed.preloading - INFO - Creating preload: dask_cuda.initialize
2023-07-05 05:53:30,866 - distributed.preloading - INFO - Import preload module: dask_cuda.initialize
2023-07-05 05:53:31,443 - distributed.preloading - INFO - Creating preload: dask_cuda.initialize
2023-07-05 05:53:31,443 - distributed.preloading - INFO - Import preload module: dask_cuda.initialize
2023-07-05 05:53:31,604 - distributed.preloading - INFO - Creating preload: dask_cuda.initialize
2023-07-05 05:53:31,604 - distributed.preloading - INFO - Import preload module: dask_cuda.initialize
2023-07-05 05:53:31,616 - distributed.preloading - INFO - Creating preload: dask_cuda.initialize
2023-07-05 05:53:31,616 - distributed.preloading - INFO - Import preload module: dask_cuda.initialize
2023-07-05 05:53:31,674 - distributed.preloading - INFO - Creating preload: dask_cuda.initialize
2023-07-05 05:53:31,674 - distributed.preloading - INFO - Import preload module: dask_cuda.initialize
2023-07-05 05:53:59,516 - distributed.worker - ERROR - Worker stream died during communication: ucx://127.0.0.1:55957
Traceback (most recent call last):
  File "/opt/conda/envs/gdf/lib/python3.9/site-packages/distributed/comm/ucx.py", line 466, in connect
    ep = await ucp.create_endpoint(ip, port)
  File "/opt/conda/envs/gdf/lib/python3.9/site-packages/ucp/core.py", line 1004, in create_endpoint
    return await _get_ctx().create_endpoint(
  File "/opt/conda/envs/gdf/lib/python3.9/site-packages/ucp/core.py", line 316, in create_endpoint
    peer_info = await exchange_peer_info(
  File "/opt/conda/envs/gdf/lib/python3.9/site-packages/ucp/core.py", line 54, in exchange_peer_info
    await comm.stream_recv(endpoint, peer_info_arr, peer_info_arr.nbytes)
asyncio.exceptions.CancelledError

During handling of the above exception, another exception occurred:

Traceback (most recent call last):
  File "/opt/conda/envs/gdf/lib/python3.9/asyncio/tasks.py", line 490, in wait_for
    return fut.result()
asyncio.exceptions.CancelledError

The above exception was the direct cause of the following exception:

Traceback (most recent call last):
  File "/opt/conda/envs/gdf/lib/python3.9/site-packages/distributed/comm/core.py", line 292, in connect
    comm = await wait_for(
  File "/opt/conda/envs/gdf/lib/python3.9/site-packages/distributed/utils.py", line 1849, in wait_for
    return await asyncio.wait_for(fut, timeout)
  File "/opt/conda/envs/gdf/lib/python3.9/asyncio/tasks.py", line 492, in wait_for
    raise exceptions.TimeoutError() from exc
asyncio.exceptions.TimeoutError

The above exception was the direct cause of the following exception:

Traceback (most recent call last):
  File "/opt/conda/envs/gdf/lib/python3.9/site-packages/distributed/worker.py", line 2066, in gather_dep
    response = await get_data_from_worker(
  File "/opt/conda/envs/gdf/lib/python3.9/site-packages/distributed/worker.py", line 2889, in get_data_from_worker
    comm = await rpc.connect(worker)
  File "/opt/conda/envs/gdf/lib/python3.9/site-packages/distributed/core.py", line 1506, in connect
    return await connect_attempt
  File "/opt/conda/envs/gdf/lib/python3.9/site-packages/distributed/core.py", line 1427, in _connect
    comm = await connect(
  File "/opt/conda/envs/gdf/lib/python3.9/site-packages/distributed/comm/core.py", line 318, in connect
    raise OSError(
OSError: Timed out trying to connect to ucx://127.0.0.1:55957 after 30 s
/opt/conda/envs/gdf/lib/python3.9/multiprocessing/resource_tracker.py:216: UserWarning: resource_tracker: There appear to be 48 leaked semaphore objects to clean up at shutdown
  warnings.warn('resource_tracker: There appear to be %d '
