2023-03-18 00:40:03,929 - distributed.preloading - INFO - Creating preload: dask_cuda.initialize
2023-03-18 00:40:03,929 - distributed.preloading - INFO - Import preload module: dask_cuda.initialize
2023-03-18 00:40:03,946 - distributed.preloading - INFO - Creating preload: dask_cuda.initialize
2023-03-18 00:40:03,946 - distributed.preloading - INFO - Import preload module: dask_cuda.initialize
2023-03-18 00:40:03,955 - distributed.preloading - INFO - Creating preload: dask_cuda.initialize
2023-03-18 00:40:03,955 - distributed.preloading - INFO - Import preload module: dask_cuda.initialize
2023-03-18 00:40:03,962 - distributed.preloading - INFO - Creating preload: dask_cuda.initialize
2023-03-18 00:40:03,962 - distributed.preloading - INFO - Import preload module: dask_cuda.initialize
2023-03-18 00:40:03,962 - distributed.preloading - INFO - Creating preload: dask_cuda.initialize
2023-03-18 00:40:03,962 - distributed.preloading - INFO - Import preload module: dask_cuda.initialize
2023-03-18 00:40:03,962 - distributed.preloading - INFO - Creating preload: dask_cuda.initialize
2023-03-18 00:40:03,963 - distributed.preloading - INFO - Import preload module: dask_cuda.initialize
2023-03-18 00:40:03,982 - distributed.preloading - INFO - Creating preload: dask_cuda.initialize
2023-03-18 00:40:03,982 - distributed.preloading - INFO - Import preload module: dask_cuda.initialize
2023-03-18 00:40:03,989 - distributed.preloading - INFO - Creating preload: dask_cuda.initialize
2023-03-18 00:40:03,989 - distributed.preloading - INFO - Import preload module: dask_cuda.initialize
[dgx13:22316:0:22316] Caught signal 11 (Segmentation fault: address not mapped to object at address 0x448)
==== backtrace (tid:  22316) ====
 0  /datasets/pentschev/miniconda3/envs/gdf/lib/libucs.so.0(ucs_handle_error+0x2d4) [0x7fe9994f14f4]
 1  /datasets/pentschev/miniconda3/envs/gdf/lib/libucs.so.0(+0x2e6cf) [0x7fe9994f16cf]
 2  /datasets/pentschev/miniconda3/envs/gdf/lib/libucs.so.0(+0x2e9f4) [0x7fe9994f19f4]
 3  /lib/x86_64-linux-gnu/libpthread.so.0(+0x12980) [0x7fea1cc1c980]
 4  /datasets/pentschev/miniconda3/envs/gdf/lib/libucp.so.0(ucp_mem_type_unpack+0x14) [0x7fe99977a574]
 5  /datasets/pentschev/miniconda3/envs/gdf/lib/libucp.so.0(ucp_rndv_data_handler+0x508) [0x7fe9997ae248]
 6  /datasets/pentschev/miniconda3/envs/gdf/lib/libuct.so.0(+0x20b6f) [0x7fe9992a5b6f]
 7  /datasets/pentschev/miniconda3/envs/gdf/lib/libuct.so.0(+0x21144) [0x7fe9992a6144]
 8  /datasets/pentschev/miniconda3/envs/gdf/lib/libuct.so.0(+0x235a8) [0x7fe9992a85a8]
 9  /datasets/pentschev/miniconda3/envs/gdf/lib/libucs.so.0(ucs_event_set_wait+0xb9) [0x7fe9994fbbc9]
10  /datasets/pentschev/miniconda3/envs/gdf/lib/libuct.so.0(uct_tcp_iface_progress+0x7b) [0x7fe9992a864b]
11  /datasets/pentschev/miniconda3/envs/gdf/lib/libucp.so.0(ucp_worker_progress+0x6a) [0x7fe999776b5a]
12  /datasets/pentschev/miniconda3/envs/gdf/lib/python3.8/site-packages/ucp/_libs/ucx_api.cpython-38-x86_64-linux-gnu.so(+0x272b9) [0x7fe999a352b9]
13  /datasets/pentschev/miniconda3/envs/gdf/bin/python(+0x12e343) [0x55987d5ac343]
14  /datasets/pentschev/miniconda3/envs/gdf/bin/python(PyObject_Call+0x24a) [0x55987d5b71fa]
15  /datasets/pentschev/miniconda3/envs/gdf/bin/python(_PyEval_EvalFrameDefault+0x680b) [0x55987d59db8b]
16  /datasets/pentschev/miniconda3/envs/gdf/bin/python(_PyEval_EvalCodeWithName+0x2f1) [0x55987d5962f1]
17  /datasets/pentschev/miniconda3/envs/gdf/bin/python(_PyFunction_Vectorcall+0x19c) [0x55987d5a793c]
18  /datasets/pentschev/miniconda3/envs/gdf/bin/python(_PyEval_EvalFrameDefault+0x6d5) [0x55987d597a55]
19  /datasets/pentschev/miniconda3/envs/gdf/bin/python(+0x13e1e8) [0x55987d5bc1e8]
20  /datasets/pentschev/miniconda3/envs/gdf/lib/python3.8/lib-dynload/_asyncio.cpython-38-x86_64-linux-gnu.so(+0x7003) [0x7fe9b73df003]
21  /datasets/pentschev/miniconda3/envs/gdf/bin/python(_PyObject_MakeTpCall+0x3db) [0x55987d5a030b]
22  /datasets/pentschev/miniconda3/envs/gdf/bin/python(+0xe0b07) [0x55987d55eb07]
23  /datasets/pentschev/miniconda3/envs/gdf/bin/python(+0x120f96) [0x55987d59ef96]
24  /datasets/pentschev/miniconda3/envs/gdf/bin/python(PyVectorcall_Call+0x7a) [0x55987d5b51ea]
25  /datasets/pentschev/miniconda3/envs/gdf/bin/python(_PyEval_EvalFrameDefault+0x5df8) [0x55987d59d178]
26  /datasets/pentschev/miniconda3/envs/gdf/bin/python(_PyFunction_Vectorcall+0x106) [0x55987d5a78a6]
27  /datasets/pentschev/miniconda3/envs/gdf/bin/python(_PyEval_EvalFrameDefault+0x6d5) [0x55987d597a55]
28  /datasets/pentschev/miniconda3/envs/gdf/bin/python(_PyFunction_Vectorcall+0x106) [0x55987d5a78a6]
29  /datasets/pentschev/miniconda3/envs/gdf/bin/python(_PyEval_EvalFrameDefault+0x6d5) [0x55987d597a55]
30  /datasets/pentschev/miniconda3/envs/gdf/bin/python(_PyFunction_Vectorcall+0x106) [0x55987d5a78a6]
31  /datasets/pentschev/miniconda3/envs/gdf/bin/python(_PyEval_EvalFrameDefault+0x6d5) [0x55987d597a55]
32  /datasets/pentschev/miniconda3/envs/gdf/bin/python(_PyFunction_Vectorcall+0x106) [0x55987d5a78a6]
33  /datasets/pentschev/miniconda3/envs/gdf/bin/python(_PyEval_EvalFrameDefault+0x6d5) [0x55987d597a55]
34  /datasets/pentschev/miniconda3/envs/gdf/bin/python(_PyEval_EvalCodeWithName+0x2f1) [0x55987d5962f1]
35  /datasets/pentschev/miniconda3/envs/gdf/bin/python(_PyFunction_Vectorcall+0x19c) [0x55987d5a793c]
36  /datasets/pentschev/miniconda3/envs/gdf/bin/python(_PyEval_EvalFrameDefault+0x4b7b) [0x55987d59befb]
37  /datasets/pentschev/miniconda3/envs/gdf/bin/python(_PyEval_EvalCodeWithName+0x2f1) [0x55987d5962f1]
38  /datasets/pentschev/miniconda3/envs/gdf/bin/python(_PyFunction_Vectorcall+0x19c) [0x55987d5a793c]
39  /datasets/pentschev/miniconda3/envs/gdf/bin/python(+0x136e8c) [0x55987d5b4e8c]
40  /datasets/pentschev/miniconda3/envs/gdf/bin/python(_PyObject_FastCallDict+0x282) [0x55987d59fa92]
41  /datasets/pentschev/miniconda3/envs/gdf/bin/python(+0x1ee049) [0x55987d66c049]
42  /datasets/pentschev/miniconda3/envs/gdf/bin/python(PyObject_Call+0x2d3) [0x55987d5b7283]
43  /datasets/pentschev/miniconda3/envs/gdf/bin/python(_PyEval_EvalFrameDefault+0x205e) [0x55987d5993de]
44  /datasets/pentschev/miniconda3/envs/gdf/bin/python(_PyFunction_Vectorcall+0x106) [0x55987d5a78a6]
45  /datasets/pentschev/miniconda3/envs/gdf/bin/python(+0x136e8c) [0x55987d5b4e8c]
46  /datasets/pentschev/miniconda3/envs/gdf/bin/python(PyObject_Call+0x24a) [0x55987d5b71fa]
47  /datasets/pentschev/miniconda3/envs/gdf/bin/python(_PyEval_EvalFrameDefault+0x205e) [0x55987d5993de]
48  /datasets/pentschev/miniconda3/envs/gdf/bin/python(_PyFunction_Vectorcall+0x106) [0x55987d5a78a6]
49  /datasets/pentschev/miniconda3/envs/gdf/bin/python(_PyEval_EvalFrameDefault+0x6d5) [0x55987d597a55]
50  /datasets/pentschev/miniconda3/envs/gdf/bin/python(_PyEval_EvalCodeWithName+0x2f1) [0x55987d5962f1]
51  /datasets/pentschev/miniconda3/envs/gdf/bin/python(_PyFunction_Vectorcall+0x19c) [0x55987d5a793c]
52  /datasets/pentschev/miniconda3/envs/gdf/bin/python(_PyEval_EvalFrameDefault+0x6d5) [0x55987d597a55]
53  /datasets/pentschev/miniconda3/envs/gdf/bin/python(_PyFunction_Vectorcall+0x106) [0x55987d5a78a6]
54  /datasets/pentschev/miniconda3/envs/gdf/bin/python(_PyEval_EvalFrameDefault+0x3a9) [0x55987d597729]
55  /datasets/pentschev/miniconda3/envs/gdf/bin/python(_PyEval_EvalCodeWithName+0x2f1) [0x55987d5962f1]
56  /datasets/pentschev/miniconda3/envs/gdf/bin/python(_PyFunction_Vectorcall+0x19c) [0x55987d5a793c]
57  /datasets/pentschev/miniconda3/envs/gdf/bin/python(_PyEval_EvalFrameDefault+0x11bf) [0x55987d59853f]
58  /datasets/pentschev/miniconda3/envs/gdf/bin/python(_PyEval_EvalCodeWithName+0x2f1) [0x55987d5962f1]
59  /datasets/pentschev/miniconda3/envs/gdf/bin/python(PyEval_EvalCodeEx+0x39) [0x55987d648e99]
60  /datasets/pentschev/miniconda3/envs/gdf/bin/python(PyEval_EvalCode+0x1b) [0x55987d648e5b]
61  /datasets/pentschev/miniconda3/envs/gdf/bin/python(+0x1eb7f9) [0x55987d6697f9]
=================================
2023-03-18 00:40:12,881 - distributed.worker - ERROR - failed during get data with ucx://127.0.0.1:40365 -> ucx://127.0.0.1:51451
Traceback (most recent call last):
  File "/datasets/pentschev/miniconda3/envs/gdf/lib/python3.8/site-packages/distributed/comm/ucx.py", line 333, in write
    await self.ep.send(each_frame)
  File "/datasets/pentschev/miniconda3/envs/gdf/lib/python3.8/site-packages/ucp/core.py", line 650, in send
    return await comm.tag_send(self._ep, buffer, nbytes, tag, name=log)
ucp._libs.exceptions.UCXError: <[Send #007] ep: 0x7fc9040cc100, tag: 0xcb386b7e931e44a6, nbytes: 800000000, type: <class 'cudf.core.buffer.buffer.Buffer'>>: Connection reset by remote peer

During handling of the above exception, another exception occurred:

Traceback (most recent call last):
  File "/datasets/pentschev/miniconda3/envs/gdf/lib/python3.8/site-packages/distributed/worker.py", line 1789, in get_data
    compressed = await comm.write(msg, serializers=serializers)
  File "/datasets/pentschev/miniconda3/envs/gdf/lib/python3.8/site-packages/distributed/utils.py", line 752, in wrapper
    return await func(*args, **kwargs)
  File "/datasets/pentschev/miniconda3/envs/gdf/lib/python3.8/site-packages/distributed/comm/ucx.py", line 337, in write
    raise CommClosedError("While writing, the connection was closed")
distributed.comm.core.CommClosedError: While writing, the connection was closed
Task exception was never retrieved
future: <Task finished name='Task-873' coro=<_listener_handler_coroutine() done, defined at /datasets/pentschev/miniconda3/envs/gdf/lib/python3.8/site-packages/ucp/core.py:128> exception=UCXError('<stream_send>: Endpoint timeout')>
Traceback (most recent call last):
  File "/datasets/pentschev/miniconda3/envs/gdf/lib/python3.8/site-packages/ucp/core.py", line 143, in _listener_handler_coroutine
    peer_info = await exchange_peer_info(
  File "/datasets/pentschev/miniconda3/envs/gdf/lib/python3.8/site-packages/ucp/core.py", line 51, in exchange_peer_info
    await comm.stream_send(endpoint, my_info_arr, my_info_arr.nbytes)
ucp._libs.exceptions.UCXError: <stream_send>: Endpoint timeout
Task exception was never retrieved
future: <Task finished name='Task-875' coro=<_listener_handler_coroutine() done, defined at /datasets/pentschev/miniconda3/envs/gdf/lib/python3.8/site-packages/ucp/core.py:128> exception=UCXError('<stream_send>: Connection reset by remote peer')>
Traceback (most recent call last):
  File "/datasets/pentschev/miniconda3/envs/gdf/lib/python3.8/site-packages/ucp/core.py", line 143, in _listener_handler_coroutine
    peer_info = await exchange_peer_info(
  File "/datasets/pentschev/miniconda3/envs/gdf/lib/python3.8/site-packages/ucp/core.py", line 51, in exchange_peer_info
    await comm.stream_send(endpoint, my_info_arr, my_info_arr.nbytes)
ucp._libs.exceptions.UCXError: <stream_send>: Connection reset by remote peer
2023-03-18 00:40:12,980 - distributed.nanny - WARNING - Restarting worker
2023-03-18 00:40:14,726 - distributed.preloading - INFO - Creating preload: dask_cuda.initialize
2023-03-18 00:40:14,726 - distributed.preloading - INFO - Import preload module: dask_cuda.initialize
/datasets/pentschev/miniconda3/envs/gdf/lib/python3.8/multiprocessing/resource_tracker.py:216: UserWarning: resource_tracker: There appear to be 48 leaked semaphore objects to clean up at shutdown
  warnings.warn('resource_tracker: There appear to be %d '
