/opt/conda/envs/gdf/lib/python3.9/site-packages/distributed/node.py:182: UserWarning: Port 8787 is already in use.
Perhaps you already have a cluster running?
Hosting the HTTP server on port 34731 instead
  warnings.warn(
[1702882486.427118] [dgx13:74287:0]    ib_mlx5dv_md.c:468  UCX  ERROR mlx5_2: LRU push returned Unsupported operation
[dgx13:74287:0:74287]        rndv.c:166  Fatal: failed to pack rendezvous remote key: Unsupported operation
==== backtrace (tid:  74287) ====
 0  /opt/conda/envs/gdf/lib/libucs.so.0(ucs_handle_error+0x2fd) [0x7fc0c020f06d]
 1  /opt/conda/envs/gdf/lib/libucs.so.0(ucs_fatal_error_message+0x51) [0x7fc0c020cc11]
 2  /opt/conda/envs/gdf/lib/libucs.so.0(+0x27dac) [0x7fc0c020cdac]
 3  /opt/conda/envs/gdf/lib/libucp.so.0(+0x739e8) [0x7fc0c02b69e8]
 4  /opt/conda/envs/gdf/lib/libucp.so.0(ucp_do_am_single+0xdf) [0x7fc0c028dd7f]
 5  /opt/conda/envs/gdf/lib/libucp.so.0(ucp_proto_progress_tag_rndv_rts+0x1d) [0x7fc0c02c9aed]
 6  /opt/conda/envs/gdf/lib/libucp.so.0(ucp_tag_send_nbx+0x6da) [0x7fc0c02ce9da]
 7  /opt/conda/envs/gdf/lib/libucp.so.0(ucp_tag_send_nb+0x4f) [0x7fc0c02cf71f]
 8  /opt/conda/envs/gdf/lib/python3.9/site-packages/ucp/_libs/ucx_api.cpython-39-x86_64-linux-gnu.so(+0x6c6f0) [0x7fc0c037d6f0]
 9  /opt/conda/envs/gdf/bin/python(PyObject_Call+0xbc) [0x55ddf950244c]
10  /opt/conda/envs/gdf/bin/python(_PyEval_EvalFrameDefault+0x37cb) [0x55ddf94e76fb]
11  /opt/conda/envs/gdf/bin/python(+0x12f094) [0x55ddf94e3094]
12  /opt/conda/envs/gdf/bin/python(_PyFunction_Vectorcall+0xd9) [0x55ddf94f4519]
13  /opt/conda/envs/gdf/bin/python(_PyEval_EvalFrameDefault+0x11f8) [0x55ddf94e5128]
14  /opt/conda/envs/gdf/bin/python(+0x12f094) [0x55ddf94e3094]
15  /opt/conda/envs/gdf/bin/python(_PyFunction_Vectorcall+0xd9) [0x55ddf94f4519]
16  /opt/conda/envs/gdf/bin/python(_PyEval_EvalFrameDefault+0x11f8) [0x55ddf94e5128]
17  /opt/conda/envs/gdf/bin/python(+0x1e3162) [0x55ddf9597162]
18  /opt/conda/envs/gdf/bin/python(_PyEval_EvalFrameDefault+0x5f34) [0x55ddf94e9e64]
19  /opt/conda/envs/gdf/bin/python(+0x1e3162) [0x55ddf9597162]
20  /opt/conda/envs/gdf/bin/python(_PyEval_EvalFrameDefault+0x5f34) [0x55ddf94e9e64]
21  /opt/conda/envs/gdf/bin/python(+0x1e3162) [0x55ddf9597162]
22  /opt/conda/envs/gdf/bin/python(_PyEval_EvalFrameDefault+0x5f34) [0x55ddf94e9e64]
23  /opt/conda/envs/gdf/bin/python(+0x1e3162) [0x55ddf9597162]
24  /opt/conda/envs/gdf/bin/python(_PyEval_EvalFrameDefault+0x5f34) [0x55ddf94e9e64]
25  /opt/conda/envs/gdf/bin/python(+0x1e3162) [0x55ddf9597162]
26  /opt/conda/envs/gdf/bin/python(_PyEval_EvalFrameDefault+0x5f34) [0x55ddf94e9e64]
27  /opt/conda/envs/gdf/bin/python(+0x1e3162) [0x55ddf9597162]
28  /opt/conda/envs/gdf/lib/python3.9/lib-dynload/_asyncio.cpython-39-x86_64-linux-gnu.so(+0x81e9) [0x7fc15785f1e9]
29  /opt/conda/envs/gdf/lib/python3.9/lib-dynload/_asyncio.cpython-39-x86_64-linux-gnu.so(+0x8aa6) [0x7fc15785faa6]
30  /opt/conda/envs/gdf/bin/python(_PyObject_MakeTpCall+0x2ec) [0x55ddf94ec77c]
31  /opt/conda/envs/gdf/bin/python(+0xead05) [0x55ddf949ed05]
32  /opt/conda/envs/gdf/bin/python(+0x1377f3) [0x55ddf94eb7f3]
33  /opt/conda/envs/gdf/bin/python(_PyEval_EvalFrameDefault+0x59f9) [0x55ddf94e9929]
34  /opt/conda/envs/gdf/bin/python(+0x1407c2) [0x55ddf94f47c2]
35  /opt/conda/envs/gdf/bin/python(_PyEval_EvalFrameDefault+0x696) [0x55ddf94e45c6]
36  /opt/conda/envs/gdf/bin/python(+0x1407c2) [0x55ddf94f47c2]
37  /opt/conda/envs/gdf/bin/python(_PyEval_EvalFrameDefault+0x696) [0x55ddf94e45c6]
38  /opt/conda/envs/gdf/bin/python(+0x1407c2) [0x55ddf94f47c2]
39  /opt/conda/envs/gdf/bin/python(_PyEval_EvalFrameDefault+0x696) [0x55ddf94e45c6]
40  /opt/conda/envs/gdf/bin/python(+0x1407c2) [0x55ddf94f47c2]
41  /opt/conda/envs/gdf/bin/python(_PyEval_EvalFrameDefault+0x696) [0x55ddf94e45c6]
42  /opt/conda/envs/gdf/bin/python(+0x12f094) [0x55ddf94e3094]
43  /opt/conda/envs/gdf/bin/python(_PyFunction_Vectorcall+0xd9) [0x55ddf94f4519]
44  /opt/conda/envs/gdf/bin/python(_PyEval_EvalFrameDefault+0x11f8) [0x55ddf94e5128]
45  /opt/conda/envs/gdf/bin/python(+0x12f094) [0x55ddf94e3094]
46  /opt/conda/envs/gdf/bin/python(+0x14dccb) [0x55ddf9501ccb]
47  /opt/conda/envs/gdf/bin/python(PyObject_Call+0xbc) [0x55ddf950244c]
48  /opt/conda/envs/gdf/bin/python(+0x21110e) [0x55ddf95c510e]
49  /opt/conda/envs/gdf/bin/python(_PyObject_MakeTpCall+0x2ec) [0x55ddf94ec77c]
50  /opt/conda/envs/gdf/bin/python(_PyEval_EvalFrameDefault+0x37cb) [0x55ddf94e76fb]
51  /opt/conda/envs/gdf/bin/python(+0x1407c2) [0x55ddf94f47c2]
52  /opt/conda/envs/gdf/bin/python(+0x14ddac) [0x55ddf9501dac]
53  /opt/conda/envs/gdf/bin/python(_PyEval_EvalFrameDefault+0x37cb) [0x55ddf94e76fb]
54  /opt/conda/envs/gdf/bin/python(+0x1407c2) [0x55ddf94f47c2]
55  /opt/conda/envs/gdf/bin/python(_PyEval_EvalFrameDefault+0x696) [0x55ddf94e45c6]
56  /opt/conda/envs/gdf/bin/python(+0x12f094) [0x55ddf94e3094]
57  /opt/conda/envs/gdf/bin/python(_PyFunction_Vectorcall+0xd9) [0x55ddf94f4519]
58  /opt/conda/envs/gdf/bin/python(_PyEval_EvalFrameDefault+0x696) [0x55ddf94e45c6]
59  /opt/conda/envs/gdf/bin/python(+0x1407c2) [0x55ddf94f47c2]
60  /opt/conda/envs/gdf/bin/python(_PyEval_EvalFrameDefault+0x3e2) [0x55ddf94e4312]
61  /opt/conda/envs/gdf/bin/python(+0x12f094) [0x55ddf94e3094]
=================================
2023-12-18 06:54:49,124 - distributed.worker - ERROR - Worker stream died during communication: ucx://127.0.0.1:52929
Traceback (most recent call last):
  File "/opt/conda/envs/gdf/lib/python3.9/site-packages/distributed/comm/ucx.py", line 354, in read
    await self.ep.recv(msg)
  File "/opt/conda/envs/gdf/lib/python3.9/site-packages/ucp/core.py", line 725, in recv
    ret = await comm.tag_recv(self._ep, buffer, nbytes, tag, name=log)
ucp._libs.exceptions.UCXCanceled: <[Recv #030] ep: 0x7fce9d0021c0, tag: 0x9bfb7ccd69c7e53f, nbytes: 16, type: <class 'numpy.ndarray'>>: 

During handling of the above exception, another exception occurred:

Traceback (most recent call last):
  File "/opt/conda/envs/gdf/lib/python3.9/site-packages/distributed/worker.py", line 2059, in gather_dep
    response = await get_data_from_worker(
  File "/opt/conda/envs/gdf/lib/python3.9/site-packages/distributed/worker.py", line 2852, in get_data_from_worker
    response = await send_recv(
  File "/opt/conda/envs/gdf/lib/python3.9/site-packages/distributed/core.py", line 1106, in send_recv
    response = await comm.read(deserializers=deserializers)
  File "/opt/conda/envs/gdf/lib/python3.9/site-packages/distributed/utils.py", line 803, in wrapper
    return await func(*args, **kwargs)
  File "/opt/conda/envs/gdf/lib/python3.9/site-packages/distributed/comm/ucx.py", line 372, in read
    raise CommClosedError(
distributed.comm.core.CommClosedError: Connection closed by writer.
Inner exception: UCXCanceled("<[Recv #030] ep: 0x7fce9d0021c0, tag: 0x9bfb7ccd69c7e53f, nbytes: 16, type: <class 'numpy.ndarray'>>: ")
2023-12-18 06:54:49,124 - distributed.worker - ERROR - Worker stream died during communication: ucx://127.0.0.1:52929
Traceback (most recent call last):
  File "/opt/conda/envs/gdf/lib/python3.9/site-packages/distributed/comm/ucx.py", line 396, in read
    await self.ep.recv(each_frame)
  File "/opt/conda/envs/gdf/lib/python3.9/site-packages/ucp/core.py", line 725, in recv
    ret = await comm.tag_recv(self._ep, buffer, nbytes, tag, name=log)
ucp._libs.exceptions.UCXCanceled: <[Recv #029] ep: 0x7fc0ccea7280, tag: 0x7a57f88a9e7ab4a3, nbytes: 799945328, type: <class 'rmm._lib.device_buffer.DeviceBuffer'>>: 

During handling of the above exception, another exception occurred:

Traceback (most recent call last):
  File "/opt/conda/envs/gdf/lib/python3.9/site-packages/distributed/worker.py", line 2059, in gather_dep
    response = await get_data_from_worker(
  File "/opt/conda/envs/gdf/lib/python3.9/site-packages/distributed/worker.py", line 2852, in get_data_from_worker
    response = await send_recv(
  File "/opt/conda/envs/gdf/lib/python3.9/site-packages/distributed/core.py", line 1106, in send_recv
    response = await comm.read(deserializers=deserializers)
  File "/opt/conda/envs/gdf/lib/python3.9/site-packages/distributed/utils.py", line 803, in wrapper
    return await func(*args, **kwargs)
  File "/opt/conda/envs/gdf/lib/python3.9/site-packages/distributed/comm/ucx.py", line 402, in read
    raise CommClosedError(
distributed.comm.core.CommClosedError: Connection closed by writer.
Inner exception: UCXCanceled("<[Recv #029] ep: 0x7fc0ccea7280, tag: 0x7a57f88a9e7ab4a3, nbytes: 799945328, type: <class 'rmm._lib.device_buffer.DeviceBuffer'>>: ")
2023-12-18 06:54:53,347 - distributed.core - ERROR - std::bad_alloc: out_of_memory: RMM failure at:/opt/conda/conda-bld/work/include/rmm/mr/device/pool_memory_resource.hpp:273: Maximum pool size exceeded
Traceback (most recent call last):
  File "/opt/conda/envs/gdf/lib/python3.9/site-packages/distributed/utils.py", line 803, in wrapper
    return await func(*args, **kwargs)
  File "/opt/conda/envs/gdf/lib/python3.9/site-packages/distributed/comm/ucx.py", line 377, in read
    frames = [
  File "/opt/conda/envs/gdf/lib/python3.9/site-packages/distributed/comm/ucx.py", line 378, in <listcomp>
    device_array(each_size) if is_cuda else host_array(each_size)
  File "/opt/conda/envs/gdf/lib/python3.9/site-packages/distributed/comm/ucx.py", line 171, in device_array
    return rmm.DeviceBuffer(size=n)
  File "device_buffer.pyx", line 85, in rmm._lib.device_buffer.DeviceBuffer.__cinit__
MemoryError: std::bad_alloc: out_of_memory: RMM failure at:/opt/conda/conda-bld/work/include/rmm/mr/device/pool_memory_resource.hpp:273: Maximum pool size exceeded
2023-12-18 06:54:53,347 - distributed.worker - ERROR - std::bad_alloc: out_of_memory: RMM failure at:/opt/conda/conda-bld/work/include/rmm/mr/device/pool_memory_resource.hpp:273: Maximum pool size exceeded
Traceback (most recent call last):
  File "/opt/conda/envs/gdf/lib/python3.9/site-packages/distributed/worker.py", line 2059, in gather_dep
    response = await get_data_from_worker(
  File "/opt/conda/envs/gdf/lib/python3.9/site-packages/distributed/worker.py", line 2852, in get_data_from_worker
    response = await send_recv(
  File "/opt/conda/envs/gdf/lib/python3.9/site-packages/distributed/core.py", line 1106, in send_recv
    response = await comm.read(deserializers=deserializers)
  File "/opt/conda/envs/gdf/lib/python3.9/site-packages/distributed/utils.py", line 803, in wrapper
    return await func(*args, **kwargs)
  File "/opt/conda/envs/gdf/lib/python3.9/site-packages/distributed/comm/ucx.py", line 377, in read
    frames = [
  File "/opt/conda/envs/gdf/lib/python3.9/site-packages/distributed/comm/ucx.py", line 378, in <listcomp>
    device_array(each_size) if is_cuda else host_array(each_size)
  File "/opt/conda/envs/gdf/lib/python3.9/site-packages/distributed/comm/ucx.py", line 171, in device_array
    return rmm.DeviceBuffer(size=n)
  File "device_buffer.pyx", line 85, in rmm._lib.device_buffer.DeviceBuffer.__cinit__
MemoryError: std::bad_alloc: out_of_memory: RMM failure at:/opt/conda/conda-bld/work/include/rmm/mr/device/pool_memory_resource.hpp:273: Maximum pool size exceeded
2023-12-18 06:54:54,671 - distributed.nanny - WARNING - Restarting worker
/opt/conda/envs/gdf/lib/python3.9/multiprocessing/resource_tracker.py:216: UserWarning: resource_tracker: There appear to be 48 leaked semaphore objects to clean up at shutdown
  warnings.warn('resource_tracker: There appear to be %d '
