[dgx13:74509:0:74509] Caught signal 11 (Segmentation fault: address not mapped to object at address 0x448)
==== backtrace (tid:  74509) ====
 0  /opt/conda/envs/gdf/lib/libucs.so.0(ucs_handle_error+0x2fd) [0x7f899392806d]
 1  /opt/conda/envs/gdf/lib/libucs.so.0(+0x2a264) [0x7f8993928264]
 2  /opt/conda/envs/gdf/lib/libucs.so.0(+0x2a42a) [0x7f899392842a]
 3  /usr/lib/x86_64-linux-gnu/libpthread.so.0(+0x14420) [0x7f8a3af68420]
 4  /opt/conda/envs/gdf/lib/libucp.so.0(ucp_mem_type_unpack+0x14) [0x7f89939a66a4]
 5  /opt/conda/envs/gdf/lib/libucp.so.0(ucp_rndv_data_handler+0x4e9) [0x7f89939cf829]
 6  /opt/conda/envs/gdf/lib/./libuct.so.0(+0x2146f) [0x7f89938e246f]
 7  /opt/conda/envs/gdf/lib/./libuct.so.0(+0x248c8) [0x7f89938e58c8]
 8  /opt/conda/envs/gdf/lib/libucs.so.0(ucs_event_set_wait+0xb9) [0x7f8993931499]
 9  /opt/conda/envs/gdf/lib/./libuct.so.0(uct_tcp_iface_progress+0x7d) [0x7f89938e466d]
10  /opt/conda/envs/gdf/lib/libucp.so.0(ucp_worker_progress+0x5a) [0x7f89939a38ca]
11  /opt/conda/envs/gdf/lib/python3.9/site-packages/ucp/_libs/ucx_api.cpython-39-x86_64-linux-gnu.so(+0x3206a) [0x7f8993a5c06a]
12  /opt/conda/envs/gdf/bin/python(_PyEval_EvalFrameDefault+0x37cb) [0x5577db89d6fb]
13  /opt/conda/envs/gdf/bin/python(+0x12f094) [0x5577db899094]
14  /opt/conda/envs/gdf/bin/python(_PyFunction_Vectorcall+0xd9) [0x5577db8aa519]
15  /opt/conda/envs/gdf/bin/python(_PyEval_EvalFrameDefault+0x696) [0x5577db89a5c6]
16  /opt/conda/envs/gdf/bin/python(+0x1e3162) [0x5577db94d162]
17  /opt/conda/envs/gdf/lib/python3.9/lib-dynload/_asyncio.cpython-39-x86_64-linux-gnu.so(+0x81e9) [0x7f8a30f501e9]
18  /opt/conda/envs/gdf/bin/python(_PyObject_MakeTpCall+0x2ec) [0x5577db8a277c]
19  /opt/conda/envs/gdf/bin/python(+0xead05) [0x5577db854d05]
20  /opt/conda/envs/gdf/bin/python(+0x1377f3) [0x5577db8a17f3]
21  /opt/conda/envs/gdf/bin/python(_PyEval_EvalFrameDefault+0x59f9) [0x5577db89f929]
22  /opt/conda/envs/gdf/bin/python(+0x1407c2) [0x5577db8aa7c2]
23  /opt/conda/envs/gdf/bin/python(_PyEval_EvalFrameDefault+0x696) [0x5577db89a5c6]
24  /opt/conda/envs/gdf/bin/python(+0x1407c2) [0x5577db8aa7c2]
25  /opt/conda/envs/gdf/bin/python(_PyEval_EvalFrameDefault+0x696) [0x5577db89a5c6]
26  /opt/conda/envs/gdf/bin/python(+0x1407c2) [0x5577db8aa7c2]
27  /opt/conda/envs/gdf/bin/python(_PyEval_EvalFrameDefault+0x696) [0x5577db89a5c6]
28  /opt/conda/envs/gdf/bin/python(+0x1407c2) [0x5577db8aa7c2]
29  /opt/conda/envs/gdf/bin/python(_PyEval_EvalFrameDefault+0x696) [0x5577db89a5c6]
30  /opt/conda/envs/gdf/bin/python(+0x12f094) [0x5577db899094]
31  /opt/conda/envs/gdf/bin/python(_PyFunction_Vectorcall+0xd9) [0x5577db8aa519]
32  /opt/conda/envs/gdf/bin/python(_PyEval_EvalFrameDefault+0x11f8) [0x5577db89b128]
33  /opt/conda/envs/gdf/bin/python(+0x12f094) [0x5577db899094]
34  /opt/conda/envs/gdf/bin/python(+0x14dccb) [0x5577db8b7ccb]
35  /opt/conda/envs/gdf/bin/python(PyObject_Call+0xbc) [0x5577db8b844c]
36  /opt/conda/envs/gdf/bin/python(+0x21110e) [0x5577db97b10e]
37  /opt/conda/envs/gdf/bin/python(_PyObject_MakeTpCall+0x2ec) [0x5577db8a277c]
38  /opt/conda/envs/gdf/bin/python(_PyEval_EvalFrameDefault+0x37cb) [0x5577db89d6fb]
39  /opt/conda/envs/gdf/bin/python(+0x1407c2) [0x5577db8aa7c2]
40  /opt/conda/envs/gdf/bin/python(+0x14ddac) [0x5577db8b7dac]
41  /opt/conda/envs/gdf/bin/python(_PyEval_EvalFrameDefault+0x37cb) [0x5577db89d6fb]
42  /opt/conda/envs/gdf/bin/python(+0x1407c2) [0x5577db8aa7c2]
43  /opt/conda/envs/gdf/bin/python(_PyEval_EvalFrameDefault+0x696) [0x5577db89a5c6]
44  /opt/conda/envs/gdf/bin/python(+0x12f094) [0x5577db899094]
45  /opt/conda/envs/gdf/bin/python(_PyFunction_Vectorcall+0xd9) [0x5577db8aa519]
46  /opt/conda/envs/gdf/bin/python(_PyEval_EvalFrameDefault+0x696) [0x5577db89a5c6]
47  /opt/conda/envs/gdf/bin/python(+0x1407c2) [0x5577db8aa7c2]
48  /opt/conda/envs/gdf/bin/python(_PyEval_EvalFrameDefault+0x3e2) [0x5577db89a312]
49  /opt/conda/envs/gdf/bin/python(+0x12f094) [0x5577db899094]
50  /opt/conda/envs/gdf/bin/python(_PyFunction_Vectorcall+0xd9) [0x5577db8aa519]
51  /opt/conda/envs/gdf/bin/python(_PyEval_EvalFrameDefault+0x11f8) [0x5577db89b128]
52  /opt/conda/envs/gdf/bin/python(+0x12f094) [0x5577db899094]
53  /opt/conda/envs/gdf/bin/python(_PyEval_EvalCodeWithName+0x48) [0x5577db898d68]
54  /opt/conda/envs/gdf/bin/python(PyEval_EvalCodeEx+0x39) [0x5577db898d19]
55  /opt/conda/envs/gdf/bin/python(PyEval_EvalCode+0x1b) [0x5577db94607b]
56  /opt/conda/envs/gdf/bin/python(+0x208fca) [0x5577db972fca]
57  /opt/conda/envs/gdf/bin/python(+0x205353) [0x5577db96f353]
58  /opt/conda/envs/gdf/bin/python(PyRun_StringFlags+0x9a) [0x5577db96716a]
59  /opt/conda/envs/gdf/bin/python(PyRun_SimpleStringFlags+0x3c) [0x5577db96705c]
60  /opt/conda/envs/gdf/bin/python(Py_RunMain+0x267) [0x5577db966297]
61  /opt/conda/envs/gdf/bin/python(Py_BytesMain+0x37) [0x5577db939f07]
=================================
[dgx13:74518:0:74518] Caught signal 11 (Segmentation fault: address not mapped to object at address 0x448)
==== backtrace (tid:  74518) ====
 0  /opt/conda/envs/gdf/lib/libucs.so.0(ucs_handle_error+0x2fd) [0x7fdf3c7b106d]
 1  /opt/conda/envs/gdf/lib/libucs.so.0(+0x2a264) [0x7fdf3c7b1264]
 2  /opt/conda/envs/gdf/lib/libucs.so.0(+0x2a42a) [0x7fdf3c7b142a]
 3  /usr/lib/x86_64-linux-gnu/libpthread.so.0(+0x14420) [0x7fdfddde4420]
 4  /opt/conda/envs/gdf/lib/libucp.so.0(ucp_mem_type_unpack+0x14) [0x7fdf3c82f6a4]
 5  /opt/conda/envs/gdf/lib/libucp.so.0(ucp_rndv_data_handler+0x4e9) [0x7fdf3c858829]
 6  /opt/conda/envs/gdf/lib/./libuct.so.0(+0x2146f) [0x7fdf3c76b46f]
 7  /opt/conda/envs/gdf/lib/./libuct.so.0(+0x248c8) [0x7fdf3c76e8c8]
 8  /opt/conda/envs/gdf/lib/libucs.so.0(ucs_event_set_wait+0xb9) [0x7fdf3c7ba499]
 9  /opt/conda/envs/gdf/lib/./libuct.so.0(uct_tcp_iface_progress+0x7d) [0x7fdf3c76d66d]
10  /opt/conda/envs/gdf/lib/libucp.so.0(ucp_worker_progress+0x5a) [0x7fdf3c82c8ca]
11  /opt/conda/envs/gdf/lib/python3.9/site-packages/ucp/_libs/ucx_api.cpython-39-x86_64-linux-gnu.so(+0x3206a) [0x7fdf3c8e506a]
12  /opt/conda/envs/gdf/bin/python(_PyEval_EvalFrameDefault+0x37cb) [0x55d2f10be6fb]
13  /opt/conda/envs/gdf/bin/python(+0x12f094) [0x55d2f10ba094]
14  /opt/conda/envs/gdf/bin/python(_PyFunction_Vectorcall+0xd9) [0x55d2f10cb519]
15  /opt/conda/envs/gdf/bin/python(_PyEval_EvalFrameDefault+0x696) [0x55d2f10bb5c6]
16  /opt/conda/envs/gdf/bin/python(+0x1e3162) [0x55d2f116e162]
17  /opt/conda/envs/gdf/lib/python3.9/lib-dynload/_asyncio.cpython-39-x86_64-linux-gnu.so(+0x81e9) [0x7fdfcfdc41e9]
18  /opt/conda/envs/gdf/bin/python(_PyObject_MakeTpCall+0x2ec) [0x55d2f10c377c]
19  /opt/conda/envs/gdf/bin/python(+0xead05) [0x55d2f1075d05]
20  /opt/conda/envs/gdf/bin/python(+0x1377f3) [0x55d2f10c27f3]
21  /opt/conda/envs/gdf/bin/python(_PyEval_EvalFrameDefault+0x59f9) [0x55d2f10c0929]
22  /opt/conda/envs/gdf/bin/python(+0x1407c2) [0x55d2f10cb7c2]
23  /opt/conda/envs/gdf/bin/python(_PyEval_EvalFrameDefault+0x696) [0x55d2f10bb5c6]
24  /opt/conda/envs/gdf/bin/python(+0x1407c2) [0x55d2f10cb7c2]
25  /opt/conda/envs/gdf/bin/python(_PyEval_EvalFrameDefault+0x696) [0x55d2f10bb5c6]
26  /opt/conda/envs/gdf/bin/python(+0x1407c2) [0x55d2f10cb7c2]
27  /opt/conda/envs/gdf/bin/python(_PyEval_EvalFrameDefault+0x696) [0x55d2f10bb5c6]
28  /opt/conda/envs/gdf/bin/python(+0x1407c2) [0x55d2f10cb7c2]
29  /opt/conda/envs/gdf/bin/python(_PyEval_EvalFrameDefault+0x696) [0x55d2f10bb5c6]
30  /opt/conda/envs/gdf/bin/python(+0x12f094) [0x55d2f10ba094]
31  /opt/conda/envs/gdf/bin/python(_PyFunction_Vectorcall+0xd9) [0x55d2f10cb519]
32  /opt/conda/envs/gdf/bin/python(_PyEval_EvalFrameDefault+0x11f8) [0x55d2f10bc128]
33  /opt/conda/envs/gdf/bin/python(+0x12f094) [0x55d2f10ba094]
34  /opt/conda/envs/gdf/bin/python(+0x14dccb) [0x55d2f10d8ccb]
35  /opt/conda/envs/gdf/bin/python(PyObject_Call+0xbc) [0x55d2f10d944c]
36  /opt/conda/envs/gdf/bin/python(+0x21110e) [0x55d2f119c10e]
37  /opt/conda/envs/gdf/bin/python(_PyObject_MakeTpCall+0x2ec) [0x55d2f10c377c]
38  /opt/conda/envs/gdf/bin/python(_PyEval_EvalFrameDefault+0x37cb) [0x55d2f10be6fb]
39  /opt/conda/envs/gdf/bin/python(+0x1407c2) [0x55d2f10cb7c2]
40  /opt/conda/envs/gdf/bin/python(+0x14ddac) [0x55d2f10d8dac]
41  /opt/conda/envs/gdf/bin/python(_PyEval_EvalFrameDefault+0x37cb) [0x55d2f10be6fb]
42  /opt/conda/envs/gdf/bin/python(+0x1407c2) [0x55d2f10cb7c2]
43  /opt/conda/envs/gdf/bin/python(_PyEval_EvalFrameDefault+0x696) [0x55d2f10bb5c6]
44  /opt/conda/envs/gdf/bin/python(+0x12f094) [0x55d2f10ba094]
45  /opt/conda/envs/gdf/bin/python(_PyFunction_Vectorcall+0xd9) [0x55d2f10cb519]
46  /opt/conda/envs/gdf/bin/python(_PyEval_EvalFrameDefault+0x696) [0x55d2f10bb5c6]
47  /opt/conda/envs/gdf/bin/python(+0x1407c2) [0x55d2f10cb7c2]
48  /opt/conda/envs/gdf/bin/python(_PyEval_EvalFrameDefault+0x3e2) [0x55d2f10bb312]
49  /opt/conda/envs/gdf/bin/python(+0x12f094) [0x55d2f10ba094]
50  /opt/conda/envs/gdf/bin/python(_PyFunction_Vectorcall+0xd9) [0x55d2f10cb519]
51  /opt/conda/envs/gdf/bin/python(_PyEval_EvalFrameDefault+0x11f8) [0x55d2f10bc128]
52  /opt/conda/envs/gdf/bin/python(+0x12f094) [0x55d2f10ba094]
53  /opt/conda/envs/gdf/bin/python(_PyEval_EvalCodeWithName+0x48) [0x55d2f10b9d68]
54  /opt/conda/envs/gdf/bin/python(PyEval_EvalCodeEx+0x39) [0x55d2f10b9d19]
55  /opt/conda/envs/gdf/bin/python(PyEval_EvalCode+0x1b) [0x55d2f116707b]
56  /opt/conda/envs/gdf/bin/python(+0x208fca) [0x55d2f1193fca]
57  /opt/conda/envs/gdf/bin/python(+0x205353) [0x55d2f1190353]
58  /opt/conda/envs/gdf/bin/python(PyRun_StringFlags+0x9a) [0x55d2f118816a]
59  /opt/conda/envs/gdf/bin/python(PyRun_SimpleStringFlags+0x3c) [0x55d2f118805c]
60  /opt/conda/envs/gdf/bin/python(Py_RunMain+0x267) [0x55d2f1187297]
61  /opt/conda/envs/gdf/bin/python(Py_BytesMain+0x37) [0x55d2f115af07]
=================================
[dgx13:74501:0:74501] Caught signal 11 (Segmentation fault: address not mapped to object at address 0x448)
==== backtrace (tid:  74501) ====
 0  /opt/conda/envs/gdf/lib/libucs.so.0(ucs_handle_error+0x2fd) [0x7efbaf06606d]
 1  /opt/conda/envs/gdf/lib/libucs.so.0(+0x2a264) [0x7efbaf066264]
 2  /opt/conda/envs/gdf/lib/libucs.so.0(+0x2a42a) [0x7efbaf06642a]
 3  /usr/lib/x86_64-linux-gnu/libpthread.so.0(+0x14420) [0x7efc60698420]
 4  /opt/conda/envs/gdf/lib/libucp.so.0(ucp_mem_type_unpack+0x14) [0x7efbaf0e46a4]
 5  /opt/conda/envs/gdf/lib/libucp.so.0(ucp_rndv_data_handler+0x4e9) [0x7efbaf10d829]
 6  /opt/conda/envs/gdf/lib/./libuct.so.0(+0x2146f) [0x7efbaf02046f]
 7  /opt/conda/envs/gdf/lib/./libuct.so.0(+0x248c8) [0x7efbaf0238c8]
 8  /opt/conda/envs/gdf/lib/libucs.so.0(ucs_event_set_wait+0xb9) [0x7efbaf06f499]
 9  /opt/conda/envs/gdf/lib/./libuct.so.0(uct_tcp_iface_progress+0x7d) [0x7efbaf02266d]
10  /opt/conda/envs/gdf/lib/libucp.so.0(ucp_worker_progress+0x5a) [0x7efbaf0e18ca]
11  /opt/conda/envs/gdf/lib/python3.9/site-packages/ucp/_libs/ucx_api.cpython-39-x86_64-linux-gnu.so(+0x3206a) [0x7efbaf19a06a]
12  /opt/conda/envs/gdf/bin/python(_PyEval_EvalFrameDefault+0x37cb) [0x56473ec946fb]
13  /opt/conda/envs/gdf/bin/python(+0x12f094) [0x56473ec90094]
14  /opt/conda/envs/gdf/bin/python(_PyFunction_Vectorcall+0xd9) [0x56473eca1519]
15  /opt/conda/envs/gdf/bin/python(_PyEval_EvalFrameDefault+0x696) [0x56473ec915c6]
16  /opt/conda/envs/gdf/bin/python(+0x1407c2) [0x56473eca17c2]
17  /opt/conda/envs/gdf/bin/python(+0x14de83) [0x56473ecaee83]
18  /opt/conda/envs/gdf/bin/python(+0x258b2c) [0x56473edb9b2c]
19  /opt/conda/envs/gdf/bin/python(+0xead05) [0x56473ec4bd05]
20  /opt/conda/envs/gdf/bin/python(+0x1377f3) [0x56473ec987f3]
21  /opt/conda/envs/gdf/bin/python(_PyEval_EvalFrameDefault+0x59f9) [0x56473ec96929]
22  /opt/conda/envs/gdf/bin/python(+0x1407c2) [0x56473eca17c2]
23  /opt/conda/envs/gdf/bin/python(_PyEval_EvalFrameDefault+0x696) [0x56473ec915c6]
24  /opt/conda/envs/gdf/bin/python(+0x1407c2) [0x56473eca17c2]
25  /opt/conda/envs/gdf/bin/python(_PyEval_EvalFrameDefault+0x696) [0x56473ec915c6]
26  /opt/conda/envs/gdf/bin/python(+0x1407c2) [0x56473eca17c2]
27  /opt/conda/envs/gdf/bin/python(_PyEval_EvalFrameDefault+0x696) [0x56473ec915c6]
28  /opt/conda/envs/gdf/bin/python(+0x1407c2) [0x56473eca17c2]
29  /opt/conda/envs/gdf/bin/python(_PyEval_EvalFrameDefault+0x696) [0x56473ec915c6]
30  /opt/conda/envs/gdf/bin/python(+0x12f094) [0x56473ec90094]
31  /opt/conda/envs/gdf/bin/python(_PyFunction_Vectorcall+0xd9) [0x56473eca1519]
32  /opt/conda/envs/gdf/bin/python(_PyEval_EvalFrameDefault+0x11f8) [0x56473ec92128]
33  /opt/conda/envs/gdf/bin/python(+0x12f094) [0x56473ec90094]
34  /opt/conda/envs/gdf/bin/python(+0x14dccb) [0x56473ecaeccb]
35  /opt/conda/envs/gdf/bin/python(PyObject_Call+0xbc) [0x56473ecaf44c]
36  /opt/conda/envs/gdf/bin/python(+0x21110e) [0x56473ed7210e]
37  /opt/conda/envs/gdf/bin/python(_PyObject_MakeTpCall+0x2ec) [0x56473ec9977c]
38  /opt/conda/envs/gdf/bin/python(_PyEval_EvalFrameDefault+0x37cb) [0x56473ec946fb]
39  /opt/conda/envs/gdf/bin/python(+0x1407c2) [0x56473eca17c2]
40  /opt/conda/envs/gdf/bin/python(+0x14ddac) [0x56473ecaedac]
41  /opt/conda/envs/gdf/bin/python(_PyEval_EvalFrameDefault+0x37cb) [0x56473ec946fb]
42  /opt/conda/envs/gdf/bin/python(+0x1407c2) [0x56473eca17c2]
43  /opt/conda/envs/gdf/bin/python(_PyEval_EvalFrameDefault+0x696) [0x56473ec915c6]
44  /opt/conda/envs/gdf/bin/python(+0x12f094) [0x56473ec90094]
45  /opt/conda/envs/gdf/bin/python(_PyFunction_Vectorcall+0xd9) [0x56473eca1519]
46  /opt/conda/envs/gdf/bin/python(_PyEval_EvalFrameDefault+0x696) [0x56473ec915c6]
47  /opt/conda/envs/gdf/bin/python(+0x1407c2) [0x56473eca17c2]
48  /opt/conda/envs/gdf/bin/python(_PyEval_EvalFrameDefault+0x3e2) [0x56473ec91312]
49  /opt/conda/envs/gdf/bin/python(+0x12f094) [0x56473ec90094]
50  /opt/conda/envs/gdf/bin/python(_PyFunction_Vectorcall+0xd9) [0x56473eca1519]
51  /opt/conda/envs/gdf/bin/python(_PyEval_EvalFrameDefault+0x11f8) [0x56473ec92128]
52  /opt/conda/envs/gdf/bin/python(+0x12f094) [0x56473ec90094]
53  /opt/conda/envs/gdf/bin/python(_PyEval_EvalCodeWithName+0x48) [0x56473ec8fd68]
54  /opt/conda/envs/gdf/bin/python(PyEval_EvalCodeEx+0x39) [0x56473ec8fd19]
55  /opt/conda/envs/gdf/bin/python(PyEval_EvalCode+0x1b) [0x56473ed3d07b]
56  /opt/conda/envs/gdf/bin/python(+0x208fca) [0x56473ed69fca]
57  /opt/conda/envs/gdf/bin/python(+0x205353) [0x56473ed66353]
58  /opt/conda/envs/gdf/bin/python(PyRun_StringFlags+0x9a) [0x56473ed5e16a]
59  /opt/conda/envs/gdf/bin/python(PyRun_SimpleStringFlags+0x3c) [0x56473ed5e05c]
60  /opt/conda/envs/gdf/bin/python(Py_RunMain+0x267) [0x56473ed5d297]
61  /opt/conda/envs/gdf/bin/python(Py_BytesMain+0x37) [0x56473ed30f07]
=================================
[dgx13:74512:0:74512] Caught signal 11 (Segmentation fault: address not mapped to object at address 0x448)
==== backtrace (tid:  74512) ====
 0  /opt/conda/envs/gdf/lib/libucs.so.0(ucs_handle_error+0x2fd) [0x7f6381c2806d]
 1  /opt/conda/envs/gdf/lib/libucs.so.0(+0x2a264) [0x7f6381c28264]
 2  /opt/conda/envs/gdf/lib/libucs.so.0(+0x2a42a) [0x7f6381c2842a]
 3  /usr/lib/x86_64-linux-gnu/libpthread.so.0(+0x14420) [0x7f6425294420]
 4  /opt/conda/envs/gdf/lib/libucp.so.0(ucp_mem_type_unpack+0x14) [0x7f6381ca66a4]
 5  /opt/conda/envs/gdf/lib/libucp.so.0(ucp_rndv_data_handler+0x4e9) [0x7f6381ccf829]
 6  /opt/conda/envs/gdf/lib/./libuct.so.0(+0x2146f) [0x7f6381be246f]
 7  /opt/conda/envs/gdf/lib/./libuct.so.0(+0x248c8) [0x7f6381be58c8]
 8  /opt/conda/envs/gdf/lib/libucs.so.0(ucs_event_set_wait+0xb9) [0x7f6381c31499]
 9  /opt/conda/envs/gdf/lib/./libuct.so.0(uct_tcp_iface_progress+0x7d) [0x7f6381be466d]
10  /opt/conda/envs/gdf/lib/libucp.so.0(ucp_worker_progress+0x5a) [0x7f6381ca38ca]
11  /opt/conda/envs/gdf/lib/python3.9/site-packages/ucp/_libs/ucx_api.cpython-39-x86_64-linux-gnu.so(+0x3206a) [0x7f6381d5c06a]
12  /opt/conda/envs/gdf/bin/python(_PyEval_EvalFrameDefault+0x37cb) [0x560a7f1726fb]
13  /opt/conda/envs/gdf/bin/python(+0x12f094) [0x560a7f16e094]
14  /opt/conda/envs/gdf/bin/python(_PyFunction_Vectorcall+0xd9) [0x560a7f17f519]
15  /opt/conda/envs/gdf/bin/python(_PyEval_EvalFrameDefault+0x696) [0x560a7f16f5c6]
16  /opt/conda/envs/gdf/bin/python(+0x1e3162) [0x560a7f222162]
17  /opt/conda/envs/gdf/lib/python3.9/lib-dynload/_asyncio.cpython-39-x86_64-linux-gnu.so(+0x81e9) [0x7f641b25f1e9]
18  /opt/conda/envs/gdf/bin/python(_PyObject_MakeTpCall+0x2ec) [0x560a7f17777c]
19  /opt/conda/envs/gdf/bin/python(+0xead05) [0x560a7f129d05]
20  /opt/conda/envs/gdf/bin/python(+0x1377f3) [0x560a7f1767f3]
21  /opt/conda/envs/gdf/bin/python(_PyEval_EvalFrameDefault+0x59f9) [0x560a7f174929]
22  /opt/conda/envs/gdf/bin/python(+0x1407c2) [0x560a7f17f7c2]
23  /opt/conda/envs/gdf/bin/python(_PyEval_EvalFrameDefault+0x696) [0x560a7f16f5c6]
24  /opt/conda/envs/gdf/bin/python(+0x1407c2) [0x560a7f17f7c2]
25  /opt/conda/envs/gdf/bin/python(_PyEval_EvalFrameDefault+0x696) [0x560a7f16f5c6]
26  /opt/conda/envs/gdf/bin/python(+0x1407c2) [0x560a7f17f7c2]
27  /opt/conda/envs/gdf/bin/python(_PyEval_EvalFrameDefault+0x696) [0x560a7f16f5c6]
28  /opt/conda/envs/gdf/bin/python(+0x1407c2) [0x560a7f17f7c2]
29  /opt/conda/envs/gdf/bin/python(_PyEval_EvalFrameDefault+0x696) [0x560a7f16f5c6]
30  /opt/conda/envs/gdf/bin/python(+0x12f094) [0x560a7f16e094]
31  /opt/conda/envs/gdf/bin/python(_PyFunction_Vectorcall+0xd9) [0x560a7f17f519]
32  /opt/conda/envs/gdf/bin/python(_PyEval_EvalFrameDefault+0x11f8) [0x560a7f170128]
33  /opt/conda/envs/gdf/bin/python(+0x12f094) [0x560a7f16e094]
34  /opt/conda/envs/gdf/bin/python(+0x14dccb) [0x560a7f18cccb]
35  /opt/conda/envs/gdf/bin/python(PyObject_Call+0xbc) [0x560a7f18d44c]
36  /opt/conda/envs/gdf/bin/python(+0x21110e) [0x560a7f25010e]
37  /opt/conda/envs/gdf/bin/python(_PyObject_MakeTpCall+0x2ec) [0x560a7f17777c]
38  /opt/conda/envs/gdf/bin/python(_PyEval_EvalFrameDefault+0x37cb) [0x560a7f1726fb]
39  /opt/conda/envs/gdf/bin/python(+0x1407c2) [0x560a7f17f7c2]
40  /opt/conda/envs/gdf/bin/python(+0x14ddac) [0x560a7f18cdac]
41  /opt/conda/envs/gdf/bin/python(_PyEval_EvalFrameDefault+0x37cb) [0x560a7f1726fb]
42  /opt/conda/envs/gdf/bin/python(+0x1407c2) [0x560a7f17f7c2]
43  /opt/conda/envs/gdf/bin/python(_PyEval_EvalFrameDefault+0x696) [0x560a7f16f5c6]
44  /opt/conda/envs/gdf/bin/python(+0x12f094) [0x560a7f16e094]
45  /opt/conda/envs/gdf/bin/python(_PyFunction_Vectorcall+0xd9) [0x560a7f17f519]
46  /opt/conda/envs/gdf/bin/python(_PyEval_EvalFrameDefault+0x696) [0x560a7f16f5c6]
47  /opt/conda/envs/gdf/bin/python(+0x1407c2) [0x560a7f17f7c2]
48  /opt/conda/envs/gdf/bin/python(_PyEval_EvalFrameDefault+0x3e2) [0x560a7f16f312]
49  /opt/conda/envs/gdf/bin/python(+0x12f094) [0x560a7f16e094]
50  /opt/conda/envs/gdf/bin/python(_PyFunction_Vectorcall+0xd9) [0x560a7f17f519]
51  /opt/conda/envs/gdf/bin/python(_PyEval_EvalFrameDefault+0x11f8) [0x560a7f170128]
52  /opt/conda/envs/gdf/bin/python(+0x12f094) [0x560a7f16e094]
53  /opt/conda/envs/gdf/bin/python(_PyEval_EvalCodeWithName+0x48) [0x560a7f16dd68]
54  /opt/conda/envs/gdf/bin/python(PyEval_EvalCodeEx+0x39) [0x560a7f16dd19]
55  /opt/conda/envs/gdf/bin/python(PyEval_EvalCode+0x1b) [0x560a7f21b07b]
56  /opt/conda/envs/gdf/bin/python(+0x208fca) [0x560a7f247fca]
57  /opt/conda/envs/gdf/bin/python(+0x205353) [0x560a7f244353]
58  /opt/conda/envs/gdf/bin/python(PyRun_StringFlags+0x9a) [0x560a7f23c16a]
59  /opt/conda/envs/gdf/bin/python(PyRun_SimpleStringFlags+0x3c) [0x560a7f23c05c]
60  /opt/conda/envs/gdf/bin/python(Py_RunMain+0x267) [0x560a7f23b297]
61  /opt/conda/envs/gdf/bin/python(Py_BytesMain+0x37) [0x560a7f20ef07]
=================================
[dgx13:74515:0:74515] Caught signal 11 (Segmentation fault: address not mapped to object at address 0x448)
==== backtrace (tid:  74515) ====
 0  /opt/conda/envs/gdf/lib/libucs.so.0(ucs_handle_error+0x2fd) [0x7f40f0eea06d]
 1  /opt/conda/envs/gdf/lib/libucs.so.0(+0x2a264) [0x7f40f0eea264]
 2  /opt/conda/envs/gdf/lib/libucs.so.0(+0x2a42a) [0x7f40f0eea42a]
 3  /usr/lib/x86_64-linux-gnu/libpthread.so.0(+0x14420) [0x7f4184519420]
 4  /opt/conda/envs/gdf/lib/libucp.so.0(ucp_mem_type_unpack+0x14) [0x7f40f0f686a4]
 5  /opt/conda/envs/gdf/lib/libucp.so.0(ucp_rndv_data_handler+0x4e9) [0x7f40f0f91829]
 6  /opt/conda/envs/gdf/lib/./libuct.so.0(+0x2146f) [0x7f40f0ea446f]
 7  /opt/conda/envs/gdf/lib/./libuct.so.0(+0x248c8) [0x7f40f0ea78c8]
 8  /opt/conda/envs/gdf/lib/libucs.so.0(ucs_event_set_wait+0xb9) [0x7f40f0ef3499]
 9  /opt/conda/envs/gdf/lib/./libuct.so.0(uct_tcp_iface_progress+0x7d) [0x7f40f0ea666d]
10  /opt/conda/envs/gdf/lib/libucp.so.0(ucp_worker_progress+0x5a) [0x7f40f0f658ca]
11  /opt/conda/envs/gdf/lib/python3.9/site-packages/ucp/_libs/ucx_api.cpython-39-x86_64-linux-gnu.so(+0x3206a) [0x7f40f101e06a]
12  /opt/conda/envs/gdf/bin/python(_PyEval_EvalFrameDefault+0x37cb) [0x55b177dee6fb]
13  /opt/conda/envs/gdf/bin/python(+0x12f094) [0x55b177dea094]
14  /opt/conda/envs/gdf/bin/python(_PyFunction_Vectorcall+0xd9) [0x55b177dfb519]
15  /opt/conda/envs/gdf/bin/python(_PyEval_EvalFrameDefault+0x696) [0x55b177deb5c6]
16  /opt/conda/envs/gdf/bin/python(+0x1e3162) [0x55b177e9e162]
17  /opt/conda/envs/gdf/lib/python3.9/lib-dynload/_asyncio.cpython-39-x86_64-linux-gnu.so(+0x81e9) [0x7f417a4df1e9]
18  /opt/conda/envs/gdf/bin/python(_PyObject_MakeTpCall+0x2ec) [0x55b177df377c]
19  /opt/conda/envs/gdf/bin/python(+0xead05) [0x55b177da5d05]
20  /opt/conda/envs/gdf/bin/python(+0x1377f3) [0x55b177df27f3]
21  /opt/conda/envs/gdf/bin/python(_PyEval_EvalFrameDefault+0x59f9) [0x55b177df0929]
22  /opt/conda/envs/gdf/bin/python(+0x1407c2) [0x55b177dfb7c2]
23  /opt/conda/envs/gdf/bin/python(_PyEval_EvalFrameDefault+0x696) [0x55b177deb5c6]
24  /opt/conda/envs/gdf/bin/python(+0x1407c2) [0x55b177dfb7c2]
25  /opt/conda/envs/gdf/bin/python(_PyEval_EvalFrameDefault+0x696) [0x55b177deb5c6]
26  /opt/conda/envs/gdf/bin/python(+0x1407c2) [0x55b177dfb7c2]
27  /opt/conda/envs/gdf/bin/python(_PyEval_EvalFrameDefault+0x696) [0x55b177deb5c6]
28  /opt/conda/envs/gdf/bin/python(+0x1407c2) [0x55b177dfb7c2]
29  /opt/conda/envs/gdf/bin/python(_PyEval_EvalFrameDefault+0x696) [0x55b177deb5c6]
30  /opt/conda/envs/gdf/bin/python(+0x12f094) [0x55b177dea094]
31  /opt/conda/envs/gdf/bin/python(_PyFunction_Vectorcall+0xd9) [0x55b177dfb519]
32  /opt/conda/envs/gdf/bin/python(_PyEval_EvalFrameDefault+0x11f8) [0x55b177dec128]
33  /opt/conda/envs/gdf/bin/python(+0x12f094) [0x55b177dea094]
34  /opt/conda/envs/gdf/bin/python(+0x14dccb) [0x55b177e08ccb]
35  /opt/conda/envs/gdf/bin/python(PyObject_Call+0xbc) [0x55b177e0944c]
36  /opt/conda/envs/gdf/bin/python(+0x21110e) [0x55b177ecc10e]
37  /opt/conda/envs/gdf/bin/python(_PyObject_MakeTpCall+0x2ec) [0x55b177df377c]
38  /opt/conda/envs/gdf/bin/python(_PyEval_EvalFrameDefault+0x37cb) [0x55b177dee6fb]
39  /opt/conda/envs/gdf/bin/python(+0x1407c2) [0x55b177dfb7c2]
40  /opt/conda/envs/gdf/bin/python(+0x14ddac) [0x55b177e08dac]
41  /opt/conda/envs/gdf/bin/python(_PyEval_EvalFrameDefault+0x37cb) [0x55b177dee6fb]
42  /opt/conda/envs/gdf/bin/python(+0x1407c2) [0x55b177dfb7c2]
43  /opt/conda/envs/gdf/bin/python(_PyEval_EvalFrameDefault+0x696) [0x55b177deb5c6]
44  /opt/conda/envs/gdf/bin/python(+0x12f094) [0x55b177dea094]
45  /opt/conda/envs/gdf/bin/python(_PyFunction_Vectorcall+0xd9) [0x55b177dfb519]
46  /opt/conda/envs/gdf/bin/python(_PyEval_EvalFrameDefault+0x696) [0x55b177deb5c6]
47  /opt/conda/envs/gdf/bin/python(+0x1407c2) [0x55b177dfb7c2]
48  /opt/conda/envs/gdf/bin/python(_PyEval_EvalFrameDefault+0x3e2) [0x55b177deb312]
49  /opt/conda/envs/gdf/bin/python(+0x12f094) [0x55b177dea094]
50  /opt/conda/envs/gdf/bin/python(_PyFunction_Vectorcall+0xd9) [0x55b177dfb519]
51  /opt/conda/envs/gdf/bin/python(_PyEval_EvalFrameDefault+0x11f8) [0x55b177dec128]
52  /opt/conda/envs/gdf/bin/python(+0x12f094) [0x55b177dea094]
53  /opt/conda/envs/gdf/bin/python(_PyEval_EvalCodeWithName+0x48) [0x55b177de9d68]
54  /opt/conda/envs/gdf/bin/python(PyEval_EvalCodeEx+0x39) [0x55b177de9d19]
55  /opt/conda/envs/gdf/bin/python(PyEval_EvalCode+0x1b) [0x55b177e9707b]
56  /opt/conda/envs/gdf/bin/python(+0x208fca) [0x55b177ec3fca]
57  /opt/conda/envs/gdf/bin/python(+0x205353) [0x55b177ec0353]
58  /opt/conda/envs/gdf/bin/python(PyRun_StringFlags+0x9a) [0x55b177eb816a]
59  /opt/conda/envs/gdf/bin/python(PyRun_SimpleStringFlags+0x3c) [0x55b177eb805c]
60  /opt/conda/envs/gdf/bin/python(Py_RunMain+0x267) [0x55b177eb7297]
61  /opt/conda/envs/gdf/bin/python(Py_BytesMain+0x37) [0x55b177e8af07]
=================================
2023-12-14 06:56:59,322 - distributed.worker - ERROR - failed during get data with ucx://127.0.0.1:47503 -> ucx://127.0.0.1:55579
Traceback (most recent call last):
  File "/opt/conda/envs/gdf/lib/python3.9/site-packages/distributed/comm/ucx.py", line 354, in read
    await self.ep.recv(msg)
  File "/opt/conda/envs/gdf/lib/python3.9/site-packages/ucp/core.py", line 725, in recv
    ret = await comm.tag_recv(self._ep, buffer, nbytes, tag, name=log)
ucp._libs.exceptions.UCXCanceled: <[Recv #006] ep: 0x7f01c462e200, tag: 0x1567516bbcf1de4d, nbytes: 16, type: <class 'numpy.ndarray'>>: 

During handling of the above exception, another exception occurred:

Traceback (most recent call last):
  File "/opt/conda/envs/gdf/lib/python3.9/site-packages/distributed/worker.py", line 1783, in get_data
    response = await comm.read(deserializers=serializers)
  File "/opt/conda/envs/gdf/lib/python3.9/site-packages/distributed/utils.py", line 803, in wrapper
    return await func(*args, **kwargs)
  File "/opt/conda/envs/gdf/lib/python3.9/site-packages/distributed/comm/ucx.py", line 372, in read
    raise CommClosedError(
distributed.comm.core.CommClosedError: Connection closed by writer.
Inner exception: UCXCanceled("<[Recv #006] ep: 0x7f01c462e200, tag: 0x1567516bbcf1de4d, nbytes: 16, type: <class 'numpy.ndarray'>>: ")
2023-12-14 06:56:59,323 - distributed.worker - ERROR - Worker stream died during communication: ucx://127.0.0.1:55579
Traceback (most recent call last):
  File "/opt/conda/envs/gdf/lib/python3.9/site-packages/distributed/comm/ucx.py", line 354, in read
    await self.ep.recv(msg)
  File "/opt/conda/envs/gdf/lib/python3.9/site-packages/ucp/core.py", line 725, in recv
    ret = await comm.tag_recv(self._ep, buffer, nbytes, tag, name=log)
ucp._libs.exceptions.UCXCanceled: <[Recv #008] ep: 0x7f01c462e100, tag: 0x3c8a7e5545696d77, nbytes: 16, type: <class 'numpy.ndarray'>>: 

During handling of the above exception, another exception occurred:

Traceback (most recent call last):
  File "/opt/conda/envs/gdf/lib/python3.9/site-packages/distributed/worker.py", line 2059, in gather_dep
    response = await get_data_from_worker(
  File "/opt/conda/envs/gdf/lib/python3.9/site-packages/distributed/worker.py", line 2852, in get_data_from_worker
    response = await send_recv(
  File "/opt/conda/envs/gdf/lib/python3.9/site-packages/distributed/core.py", line 1106, in send_recv
    response = await comm.read(deserializers=deserializers)
  File "/opt/conda/envs/gdf/lib/python3.9/site-packages/distributed/utils.py", line 803, in wrapper
    return await func(*args, **kwargs)
  File "/opt/conda/envs/gdf/lib/python3.9/site-packages/distributed/comm/ucx.py", line 372, in read
    raise CommClosedError(
distributed.comm.core.CommClosedError: Connection closed by writer.
Inner exception: UCXCanceled("<[Recv #008] ep: 0x7f01c462e100, tag: 0x3c8a7e5545696d77, nbytes: 16, type: <class 'numpy.ndarray'>>: ")
2023-12-14 06:56:59,329 - distributed.worker - ERROR - Worker stream died during communication: ucx://127.0.0.1:55579
Traceback (most recent call last):
  File "/opt/conda/envs/gdf/lib/python3.9/site-packages/distributed/core.py", line 1516, in _connect
    comm = await connect(
  File "/opt/conda/envs/gdf/lib/python3.9/site-packages/distributed/comm/core.py", line 342, in connect
    comm = await wait_for(
  File "/opt/conda/envs/gdf/lib/python3.9/site-packages/distributed/utils.py", line 1920, in wait_for
    return await asyncio.wait_for(fut, timeout)
  File "/opt/conda/envs/gdf/lib/python3.9/asyncio/tasks.py", line 466, in wait_for
    await waiter
asyncio.exceptions.CancelledError

During handling of the above exception, another exception occurred:

Traceback (most recent call last):
  File "/opt/conda/envs/gdf/lib/python3.9/site-packages/distributed/core.py", line 1626, in connect
    return connect_attempt.result()
asyncio.exceptions.CancelledError

During handling of the above exception, another exception occurred:

Traceback (most recent call last):
  File "/opt/conda/envs/gdf/lib/python3.9/site-packages/distributed/worker.py", line 2059, in gather_dep
    response = await get_data_from_worker(
  File "/opt/conda/envs/gdf/lib/python3.9/site-packages/distributed/worker.py", line 2849, in get_data_from_worker
    comm = await rpc.connect(worker)
  File "/opt/conda/envs/gdf/lib/python3.9/site-packages/distributed/core.py", line 1628, in connect
    raise CommClosedError(reason)
distributed.comm.core.CommClosedError: Address removed.
2023-12-14 06:56:59,380 - distributed.worker - ERROR - Worker stream died during communication: ucx://127.0.0.1:33445
Traceback (most recent call last):
  File "/opt/conda/envs/gdf/lib/python3.9/site-packages/distributed/comm/ucx.py", line 471, in connect
    ep = await ucp.create_endpoint(ip, port)
  File "/opt/conda/envs/gdf/lib/python3.9/site-packages/ucp/core.py", line 1004, in create_endpoint
    return await _get_ctx().create_endpoint(
  File "/opt/conda/envs/gdf/lib/python3.9/site-packages/ucp/core.py", line 316, in create_endpoint
    peer_info = await exchange_peer_info(
  File "/opt/conda/envs/gdf/lib/python3.9/site-packages/ucp/core.py", line 54, in exchange_peer_info
    await comm.stream_recv(endpoint, peer_info_arr, peer_info_arr.nbytes)
ucp._libs.exceptions.UCXError: <stream_recv>: Connection reset by remote peer

During handling of the above exception, another exception occurred:

Traceback (most recent call last):
  File "/opt/conda/envs/gdf/lib/python3.9/site-packages/distributed/comm/core.py", line 342, in connect
    comm = await wait_for(
  File "/opt/conda/envs/gdf/lib/python3.9/site-packages/distributed/utils.py", line 1920, in wait_for
    return await asyncio.wait_for(fut, timeout)
  File "/opt/conda/envs/gdf/lib/python3.9/asyncio/tasks.py", line 479, in wait_for
    return fut.result()
  File "/opt/conda/envs/gdf/lib/python3.9/site-packages/distributed/comm/ucx.py", line 473, in connect
    raise CommClosedError("Connection closed before handshake completed")
distributed.comm.core.CommClosedError: Connection closed before handshake completed

During handling of the above exception, another exception occurred:

Traceback (most recent call last):
  File "/opt/conda/envs/gdf/lib/python3.9/site-packages/distributed/core.py", line 1516, in _connect
    comm = await connect(
  File "/opt/conda/envs/gdf/lib/python3.9/site-packages/distributed/comm/core.py", line 366, in connect
    await asyncio.sleep(backoff)
  File "/opt/conda/envs/gdf/lib/python3.9/asyncio/tasks.py", line 652, in sleep
    return await future
asyncio.exceptions.CancelledError

During handling of the above exception, another exception occurred:

Traceback (most recent call last):
  File "/opt/conda/envs/gdf/lib/python3.9/site-packages/distributed/core.py", line 1626, in connect
    return connect_attempt.result()
asyncio.exceptions.CancelledError

During handling of the above exception, another exception occurred:

Traceback (most recent call last):
  File "/opt/conda/envs/gdf/lib/python3.9/site-packages/distributed/worker.py", line 2059, in gather_dep
    response = await get_data_from_worker(
  File "/opt/conda/envs/gdf/lib/python3.9/site-packages/distributed/worker.py", line 2849, in get_data_from_worker
    comm = await rpc.connect(worker)
  File "/opt/conda/envs/gdf/lib/python3.9/site-packages/distributed/core.py", line 1628, in connect
    raise CommClosedError(reason)
distributed.comm.core.CommClosedError: Address removed.
2023-12-14 06:56:59,416 - distributed.worker - ERROR - failed during get data with ucx://127.0.0.1:38163 -> ucx://127.0.0.1:58229
Traceback (most recent call last):
  File "/opt/conda/envs/gdf/lib/python3.9/site-packages/distributed/comm/ucx.py", line 338, in write
    await self.ep.send(each_frame)
  File "/opt/conda/envs/gdf/lib/python3.9/site-packages/ucp/core.py", line 650, in send
    return await comm.tag_send(self._ep, buffer, nbytes, tag, name=log)
ucp._libs.exceptions.UCXError: <[Send #007] ep: 0x7efc88dd2140, tag: 0xb6658a6df0da3a8f, nbytes: 50000000, type: <class 'cupy.ndarray'>>: Connection reset by remote peer

During handling of the above exception, another exception occurred:

Traceback (most recent call last):
  File "/opt/conda/envs/gdf/lib/python3.9/site-packages/distributed/worker.py", line 1782, in get_data
    compressed = await comm.write(msg, serializers=serializers)
  File "/opt/conda/envs/gdf/lib/python3.9/site-packages/distributed/utils.py", line 803, in wrapper
    return await func(*args, **kwargs)
  File "/opt/conda/envs/gdf/lib/python3.9/site-packages/distributed/comm/ucx.py", line 342, in write
    raise CommClosedError("While writing, the connection was closed")
distributed.comm.core.CommClosedError: While writing, the connection was closed
2023-12-14 06:56:59,416 - distributed.worker - ERROR - Worker stream died during communication: ucx://127.0.0.1:58229
Traceback (most recent call last):
  File "/opt/conda/envs/gdf/lib/python3.9/site-packages/distributed/comm/ucx.py", line 354, in read
    await self.ep.recv(msg)
  File "/opt/conda/envs/gdf/lib/python3.9/site-packages/ucp/core.py", line 725, in recv
    ret = await comm.tag_recv(self._ep, buffer, nbytes, tag, name=log)
ucp._libs.exceptions.UCXCanceled: <[Recv #008] ep: 0x7f01c462e180, tag: 0xc0c845a6ad0ace2d, nbytes: 16, type: <class 'numpy.ndarray'>>: 

During handling of the above exception, another exception occurred:

Traceback (most recent call last):
  File "/opt/conda/envs/gdf/lib/python3.9/site-packages/distributed/worker.py", line 2059, in gather_dep
    response = await get_data_from_worker(
  File "/opt/conda/envs/gdf/lib/python3.9/site-packages/distributed/worker.py", line 2852, in get_data_from_worker
    response = await send_recv(
  File "/opt/conda/envs/gdf/lib/python3.9/site-packages/distributed/core.py", line 1106, in send_recv
    response = await comm.read(deserializers=deserializers)
  File "/opt/conda/envs/gdf/lib/python3.9/site-packages/distributed/utils.py", line 803, in wrapper
    return await func(*args, **kwargs)
  File "/opt/conda/envs/gdf/lib/python3.9/site-packages/distributed/comm/ucx.py", line 372, in read
    raise CommClosedError(
distributed.comm.core.CommClosedError: Connection closed by writer.
Inner exception: UCXCanceled("<[Recv #008] ep: 0x7f01c462e180, tag: 0xc0c845a6ad0ace2d, nbytes: 16, type: <class 'numpy.ndarray'>>: ")
2023-12-14 06:56:59,416 - distributed.worker - ERROR - Worker stream died during communication: ucx://127.0.0.1:58229
Traceback (most recent call last):
  File "/opt/conda/envs/gdf/lib/python3.9/site-packages/distributed/comm/ucx.py", line 354, in read
    await self.ep.recv(msg)
  File "/opt/conda/envs/gdf/lib/python3.9/site-packages/ucp/core.py", line 725, in recv
    ret = await comm.tag_recv(self._ep, buffer, nbytes, tag, name=log)
ucp._libs.exceptions.UCXCanceled: <[Recv #008] ep: 0x7fc7683bf200, tag: 0x227c02be4bfbb464, nbytes: 16, type: <class 'numpy.ndarray'>>: 

During handling of the above exception, another exception occurred:

Traceback (most recent call last):
  File "/opt/conda/envs/gdf/lib/python3.9/site-packages/distributed/worker.py", line 2059, in gather_dep
    response = await get_data_from_worker(
  File "/opt/conda/envs/gdf/lib/python3.9/site-packages/distributed/worker.py", line 2852, in get_data_from_worker
    response = await send_recv(
  File "/opt/conda/envs/gdf/lib/python3.9/site-packages/distributed/core.py", line 1106, in send_recv
    response = await comm.read(deserializers=deserializers)
  File "/opt/conda/envs/gdf/lib/python3.9/site-packages/distributed/utils.py", line 803, in wrapper
    return await func(*args, **kwargs)
  File "/opt/conda/envs/gdf/lib/python3.9/site-packages/distributed/comm/ucx.py", line 372, in read
    raise CommClosedError(
distributed.comm.core.CommClosedError: Connection closed by writer.
Inner exception: UCXCanceled("<[Recv #008] ep: 0x7fc7683bf200, tag: 0x227c02be4bfbb464, nbytes: 16, type: <class 'numpy.ndarray'>>: ")
2023-12-14 06:56:59,417 - distributed.worker - ERROR - Worker stream died during communication: ucx://127.0.0.1:58229
Traceback (most recent call last):
  File "/opt/conda/envs/gdf/lib/python3.9/site-packages/distributed/comm/ucx.py", line 396, in read
    await self.ep.recv(each_frame)
  File "/opt/conda/envs/gdf/lib/python3.9/site-packages/ucp/core.py", line 725, in recv
    ret = await comm.tag_recv(self._ep, buffer, nbytes, tag, name=log)
ucp._libs.exceptions.UCXError: <[Recv #007] ep: 0x7efc88dd2240, tag: 0xe783585d6c1d01da, nbytes: 50000000, type: <class 'rmm._lib.device_buffer.DeviceBuffer'>>: Connection reset by remote peer

During handling of the above exception, another exception occurred:

Traceback (most recent call last):
  File "/opt/conda/envs/gdf/lib/python3.9/site-packages/distributed/worker.py", line 2059, in gather_dep
    response = await get_data_from_worker(
  File "/opt/conda/envs/gdf/lib/python3.9/site-packages/distributed/worker.py", line 2852, in get_data_from_worker
    response = await send_recv(
  File "/opt/conda/envs/gdf/lib/python3.9/site-packages/distributed/core.py", line 1106, in send_recv
    response = await comm.read(deserializers=deserializers)
  File "/opt/conda/envs/gdf/lib/python3.9/site-packages/distributed/utils.py", line 803, in wrapper
    return await func(*args, **kwargs)
  File "/opt/conda/envs/gdf/lib/python3.9/site-packages/distributed/comm/ucx.py", line 402, in read
    raise CommClosedError(
distributed.comm.core.CommClosedError: Connection closed by writer.
Inner exception: UCXError("<[Recv #007] ep: 0x7efc88dd2240, tag: 0xe783585d6c1d01da, nbytes: 50000000, type: <class 'rmm._lib.device_buffer.DeviceBuffer'>>: Connection reset by remote peer")
2023-12-14 06:56:59,442 - distributed.worker - ERROR - Worker stream died during communication: ucx://127.0.0.1:49521
Traceback (most recent call last):
  File "/opt/conda/envs/gdf/lib/python3.9/site-packages/distributed/comm/ucx.py", line 354, in read
    await self.ep.recv(msg)
  File "/opt/conda/envs/gdf/lib/python3.9/site-packages/ucp/core.py", line 725, in recv
    ret = await comm.tag_recv(self._ep, buffer, nbytes, tag, name=log)
ucp._libs.exceptions.UCXCanceled: <[Recv #017] ep: 0x7f01c462e140, tag: 0xff4b07e0599331fe, nbytes: 16, type: <class 'numpy.ndarray'>>: 

During handling of the above exception, another exception occurred:

Traceback (most recent call last):
  File "/opt/conda/envs/gdf/lib/python3.9/site-packages/distributed/worker.py", line 2059, in gather_dep
    response = await get_data_from_worker(
  File "/opt/conda/envs/gdf/lib/python3.9/site-packages/distributed/worker.py", line 2852, in get_data_from_worker
    response = await send_recv(
  File "/opt/conda/envs/gdf/lib/python3.9/site-packages/distributed/core.py", line 1106, in send_recv
    response = await comm.read(deserializers=deserializers)
  File "/opt/conda/envs/gdf/lib/python3.9/site-packages/distributed/utils.py", line 803, in wrapper
    return await func(*args, **kwargs)
  File "/opt/conda/envs/gdf/lib/python3.9/site-packages/distributed/comm/ucx.py", line 372, in read
    raise CommClosedError(
distributed.comm.core.CommClosedError: Connection closed by writer.
Inner exception: UCXCanceled("<[Recv #017] ep: 0x7f01c462e140, tag: 0xff4b07e0599331fe, nbytes: 16, type: <class 'numpy.ndarray'>>: ")
2023-12-14 06:56:59,442 - distributed.worker - ERROR - Worker stream died during communication: ucx://127.0.0.1:49521
Traceback (most recent call last):
  File "/opt/conda/envs/gdf/lib/python3.9/site-packages/distributed/comm/ucx.py", line 396, in read
    await self.ep.recv(each_frame)
  File "/opt/conda/envs/gdf/lib/python3.9/site-packages/ucp/core.py", line 725, in recv
    ret = await comm.tag_recv(self._ep, buffer, nbytes, tag, name=log)
ucp._libs.exceptions.UCXError: <[Recv #007] ep: 0x7efc88dd21c0, tag: 0x20a7490d2beaf2da, nbytes: 50000000, type: <class 'rmm._lib.device_buffer.DeviceBuffer'>>: Connection reset by remote peer

During handling of the above exception, another exception occurred:

Traceback (most recent call last):
  File "/opt/conda/envs/gdf/lib/python3.9/site-packages/distributed/worker.py", line 2059, in gather_dep
    response = await get_data_from_worker(
  File "/opt/conda/envs/gdf/lib/python3.9/site-packages/distributed/worker.py", line 2852, in get_data_from_worker
    response = await send_recv(
  File "/opt/conda/envs/gdf/lib/python3.9/site-packages/distributed/core.py", line 1106, in send_recv
    response = await comm.read(deserializers=deserializers)
  File "/opt/conda/envs/gdf/lib/python3.9/site-packages/distributed/utils.py", line 803, in wrapper
    return await func(*args, **kwargs)
  File "/opt/conda/envs/gdf/lib/python3.9/site-packages/distributed/comm/ucx.py", line 402, in read
    raise CommClosedError(
distributed.comm.core.CommClosedError: Connection closed by writer.
Inner exception: UCXError("<[Recv #007] ep: 0x7efc88dd21c0, tag: 0x20a7490d2beaf2da, nbytes: 50000000, type: <class 'rmm._lib.device_buffer.DeviceBuffer'>>: Connection reset by remote peer")
2023-12-14 06:56:59,443 - distributed.worker - ERROR - failed during get data with ucx://127.0.0.1:44821 -> ucx://127.0.0.1:49521
Traceback (most recent call last):
  File "/opt/conda/envs/gdf/lib/python3.9/site-packages/distributed/comm/ucx.py", line 338, in write
    await self.ep.send(each_frame)
  File "/opt/conda/envs/gdf/lib/python3.9/site-packages/ucp/core.py", line 650, in send
    return await comm.tag_send(self._ep, buffer, nbytes, tag, name=log)
ucp._libs.exceptions.UCXError: <[Send #007] ep: 0x7fc7683bf280, tag: 0x1507409e6513115, nbytes: 50000000, type: <class 'cupy.ndarray'>>: Connection reset by remote peer

During handling of the above exception, another exception occurred:

Traceback (most recent call last):
  File "/opt/conda/envs/gdf/lib/python3.9/site-packages/distributed/worker.py", line 1782, in get_data
    compressed = await comm.write(msg, serializers=serializers)
  File "/opt/conda/envs/gdf/lib/python3.9/site-packages/distributed/utils.py", line 803, in wrapper
    return await func(*args, **kwargs)
  File "/opt/conda/envs/gdf/lib/python3.9/site-packages/distributed/comm/ucx.py", line 342, in write
    raise CommClosedError("While writing, the connection was closed")
distributed.comm.core.CommClosedError: While writing, the connection was closed
2023-12-14 06:56:59,443 - distributed.worker - ERROR - failed during get data with ucx://127.0.0.1:38163 -> ucx://127.0.0.1:49521
Traceback (most recent call last):
  File "/opt/conda/envs/gdf/lib/python3.9/site-packages/distributed/comm/ucx.py", line 338, in write
    await self.ep.send(each_frame)
  File "/opt/conda/envs/gdf/lib/python3.9/site-packages/ucp/core.py", line 650, in send
    return await comm.tag_send(self._ep, buffer, nbytes, tag, name=log)
ucp._libs.exceptions.UCXError: <[Send #007] ep: 0x7efc88dd22c0, tag: 0xc4633c2321f3561a, nbytes: 50000000, type: <class 'cupy.ndarray'>>: Connection reset by remote peer

During handling of the above exception, another exception occurred:

Traceback (most recent call last):
  File "/opt/conda/envs/gdf/lib/python3.9/site-packages/distributed/worker.py", line 1782, in get_data
    compressed = await comm.write(msg, serializers=serializers)
  File "/opt/conda/envs/gdf/lib/python3.9/site-packages/distributed/utils.py", line 803, in wrapper
    return await func(*args, **kwargs)
  File "/opt/conda/envs/gdf/lib/python3.9/site-packages/distributed/comm/ucx.py", line 342, in write
    raise CommClosedError("While writing, the connection was closed")
distributed.comm.core.CommClosedError: While writing, the connection was closed
2023-12-14 06:56:59,443 - distributed.worker - ERROR - Worker stream died during communication: ucx://127.0.0.1:49521
Traceback (most recent call last):
  File "/opt/conda/envs/gdf/lib/python3.9/site-packages/distributed/comm/ucx.py", line 396, in read
    await self.ep.recv(each_frame)
  File "/opt/conda/envs/gdf/lib/python3.9/site-packages/ucp/core.py", line 725, in recv
    ret = await comm.tag_recv(self._ep, buffer, nbytes, tag, name=log)
ucp._libs.exceptions.UCXError: <[Recv #007] ep: 0x7fc7683bf1c0, tag: 0xdd5a7a5167d91430, nbytes: 50000000, type: <class 'rmm._lib.device_buffer.DeviceBuffer'>>: Connection reset by remote peer

During handling of the above exception, another exception occurred:

Traceback (most recent call last):
  File "/opt/conda/envs/gdf/lib/python3.9/site-packages/distributed/worker.py", line 2059, in gather_dep
    response = await get_data_from_worker(
  File "/opt/conda/envs/gdf/lib/python3.9/site-packages/distributed/worker.py", line 2852, in get_data_from_worker
    response = await send_recv(
  File "/opt/conda/envs/gdf/lib/python3.9/site-packages/distributed/core.py", line 1106, in send_recv
    response = await comm.read(deserializers=deserializers)
  File "/opt/conda/envs/gdf/lib/python3.9/site-packages/distributed/utils.py", line 803, in wrapper
    return await func(*args, **kwargs)
  File "/opt/conda/envs/gdf/lib/python3.9/site-packages/distributed/comm/ucx.py", line 402, in read
    raise CommClosedError(
distributed.comm.core.CommClosedError: Connection closed by writer.
Inner exception: UCXError("<[Recv #007] ep: 0x7fc7683bf1c0, tag: 0xdd5a7a5167d91430, nbytes: 50000000, type: <class 'rmm._lib.device_buffer.DeviceBuffer'>>: Connection reset by remote peer")
[dgx13:74497:0:74497] Caught signal 11 (Segmentation fault: address not mapped to object at address 0x448)
==== backtrace (tid:  74497) ====
 0  /opt/conda/envs/gdf/lib/libucs.so.0(ucs_handle_error+0x2fd) [0x7fc768ef106d]
 1  /opt/conda/envs/gdf/lib/libucs.so.0(+0x2a264) [0x7fc768ef1264]
 2  /opt/conda/envs/gdf/lib/libucs.so.0(+0x2a42a) [0x7fc768ef142a]
 3  /usr/lib/x86_64-linux-gnu/libpthread.so.0(+0x14420) [0x7fc80a53f420]
 4  /opt/conda/envs/gdf/lib/libucp.so.0(ucp_mem_type_unpack+0x14) [0x7fc768f6f6a4]
 5  /opt/conda/envs/gdf/lib/libucp.so.0(ucp_rndv_data_handler+0x4e9) [0x7fc768f98829]
 6  /opt/conda/envs/gdf/lib/./libuct.so.0(+0x2146f) [0x7fc768eab46f]
 7  /opt/conda/envs/gdf/lib/./libuct.so.0(+0x248c8) [0x7fc768eae8c8]
 8  /opt/conda/envs/gdf/lib/libucs.so.0(ucs_event_set_wait+0xb9) [0x7fc768efa499]
 9  /opt/conda/envs/gdf/lib/./libuct.so.0(uct_tcp_iface_progress+0x7d) [0x7fc768ead66d]
10  /opt/conda/envs/gdf/lib/libucp.so.0(ucp_worker_progress+0x5a) [0x7fc768f6c8ca]
11  /opt/conda/envs/gdf/lib/python3.9/site-packages/ucp/_libs/ucx_api.cpython-39-x86_64-linux-gnu.so(+0x3206a) [0x7fc76902506a]
12  /opt/conda/envs/gdf/bin/python(_PyEval_EvalFrameDefault+0x37cb) [0x563df627a6fb]
13  /opt/conda/envs/gdf/bin/python(+0x12f094) [0x563df6276094]
14  /opt/conda/envs/gdf/bin/python(_PyFunction_Vectorcall+0xd9) [0x563df6287519]
15  /opt/conda/envs/gdf/bin/python(_PyEval_EvalFrameDefault+0x696) [0x563df62775c6]
16  /opt/conda/envs/gdf/bin/python(+0x1407c2) [0x563df62877c2]
17  /opt/conda/envs/gdf/bin/python(+0x14de83) [0x563df6294e83]
18  /opt/conda/envs/gdf/bin/python(+0x258b2c) [0x563df639fb2c]
19  /opt/conda/envs/gdf/bin/python(+0xead05) [0x563df6231d05]
20  /opt/conda/envs/gdf/bin/python(+0x1377f3) [0x563df627e7f3]
21  /opt/conda/envs/gdf/bin/python(_PyEval_EvalFrameDefault+0x59f9) [0x563df627c929]
22  /opt/conda/envs/gdf/bin/python(+0x1407c2) [0x563df62877c2]
23  /opt/conda/envs/gdf/bin/python(_PyEval_EvalFrameDefault+0x696) [0x563df62775c6]
24  /opt/conda/envs/gdf/bin/python(+0x1407c2) [0x563df62877c2]
25  /opt/conda/envs/gdf/bin/python(_PyEval_EvalFrameDefault+0x696) [0x563df62775c6]
26  /opt/conda/envs/gdf/bin/python(+0x1407c2) [0x563df62877c2]
27  /opt/conda/envs/gdf/bin/python(_PyEval_EvalFrameDefault+0x696) [0x563df62775c6]
28  /opt/conda/envs/gdf/bin/python(+0x1407c2) [0x563df62877c2]
29  /opt/conda/envs/gdf/bin/python(_PyEval_EvalFrameDefault+0x696) [0x563df62775c6]
30  /opt/conda/envs/gdf/bin/python(+0x12f094) [0x563df6276094]
31  /opt/conda/envs/gdf/bin/python(_PyFunction_Vectorcall+0xd9) [0x563df6287519]
32  /opt/conda/envs/gdf/bin/python(_PyEval_EvalFrameDefault+0x11f8) [0x563df6278128]
33  /opt/conda/envs/gdf/bin/python(+0x12f094) [0x563df6276094]
34  /opt/conda/envs/gdf/bin/python(+0x14dccb) [0x563df6294ccb]
35  /opt/conda/envs/gdf/bin/python(PyObject_Call+0xbc) [0x563df629544c]
36  /opt/conda/envs/gdf/bin/python(+0x21110e) [0x563df635810e]
37  /opt/conda/envs/gdf/bin/python(_PyObject_MakeTpCall+0x2ec) [0x563df627f77c]
38  /opt/conda/envs/gdf/bin/python(_PyEval_EvalFrameDefault+0x37cb) [0x563df627a6fb]
39  /opt/conda/envs/gdf/bin/python(+0x1407c2) [0x563df62877c2]
40  /opt/conda/envs/gdf/bin/python(+0x14ddac) [0x563df6294dac]
41  /opt/conda/envs/gdf/bin/python(_PyEval_EvalFrameDefault+0x37cb) [0x563df627a6fb]
42  /opt/conda/envs/gdf/bin/python(+0x1407c2) [0x563df62877c2]
43  /opt/conda/envs/gdf/bin/python(_PyEval_EvalFrameDefault+0x696) [0x563df62775c6]
44  /opt/conda/envs/gdf/bin/python(+0x12f094) [0x563df6276094]
45  /opt/conda/envs/gdf/bin/python(_PyFunction_Vectorcall+0xd9) [0x563df6287519]
46  /opt/conda/envs/gdf/bin/python(_PyEval_EvalFrameDefault+0x696) [0x563df62775c6]
47  /opt/conda/envs/gdf/bin/python(+0x1407c2) [0x563df62877c2]
48  /opt/conda/envs/gdf/bin/python(_PyEval_EvalFrameDefault+0x3e2) [0x563df6277312]
49  /opt/conda/envs/gdf/bin/python(+0x12f094) [0x563df6276094]
50  /opt/conda/envs/gdf/bin/python(_PyFunction_Vectorcall+0xd9) [0x563df6287519]
51  /opt/conda/envs/gdf/bin/python(_PyEval_EvalFrameDefault+0x11f8) [0x563df6278128]
52  /opt/conda/envs/gdf/bin/python(+0x12f094) [0x563df6276094]
53  /opt/conda/envs/gdf/bin/python(_PyEval_EvalCodeWithName+0x48) [0x563df6275d68]
54  /opt/conda/envs/gdf/bin/python(PyEval_EvalCodeEx+0x39) [0x563df6275d19]
55  /opt/conda/envs/gdf/bin/python(PyEval_EvalCode+0x1b) [0x563df632307b]
56  /opt/conda/envs/gdf/bin/python(+0x208fca) [0x563df634ffca]
57  /opt/conda/envs/gdf/bin/python(+0x205353) [0x563df634c353]
58  /opt/conda/envs/gdf/bin/python(PyRun_StringFlags+0x9a) [0x563df634416a]
59  /opt/conda/envs/gdf/bin/python(PyRun_SimpleStringFlags+0x3c) [0x563df634405c]
60  /opt/conda/envs/gdf/bin/python(Py_RunMain+0x267) [0x563df6343297]
61  /opt/conda/envs/gdf/bin/python(Py_BytesMain+0x37) [0x563df6316f07]
=================================
2023-12-14 06:57:00,653 - distributed.worker - ERROR - failed during get data with ucx://127.0.0.1:47503 -> ucx://127.0.0.1:44821
Traceback (most recent call last):
  File "/opt/conda/envs/gdf/lib/python3.9/site-packages/distributed/comm/ucx.py", line 338, in write
    await self.ep.send(each_frame)
  File "/opt/conda/envs/gdf/lib/python3.9/site-packages/ucp/core.py", line 650, in send
    return await comm.tag_send(self._ep, buffer, nbytes, tag, name=log)
ucp._libs.exceptions.UCXError: <[Send #016] ep: 0x7f01c462e140, tag: 0xcfeab0ea60be1d96, nbytes: 50000000, type: <class 'cupy.ndarray'>>: Connection reset by remote peer

During handling of the above exception, another exception occurred:

Traceback (most recent call last):
  File "/opt/conda/envs/gdf/lib/python3.9/site-packages/distributed/worker.py", line 1782, in get_data
    compressed = await comm.write(msg, serializers=serializers)
  File "/opt/conda/envs/gdf/lib/python3.9/site-packages/distributed/utils.py", line 803, in wrapper
    return await func(*args, **kwargs)
  File "/opt/conda/envs/gdf/lib/python3.9/site-packages/distributed/comm/ucx.py", line 342, in write
    raise CommClosedError("While writing, the connection was closed")
distributed.comm.core.CommClosedError: While writing, the connection was closed
2023-12-14 06:57:06,161 - distributed.nanny - WARNING - Restarting worker
2023-12-14 06:57:06,345 - distributed.nanny - WARNING - Restarting worker
2023-12-14 06:57:06,484 - distributed.nanny - WARNING - Restarting worker
2023-12-14 06:57:06,549 - distributed.nanny - WARNING - Restarting worker
2023-12-14 06:57:06,590 - distributed.nanny - WARNING - Restarting worker
2023-12-14 06:57:06,793 - distributed.nanny - WARNING - Restarting worker
[dgx13:74661:0:74661] Caught signal 11 (Segmentation fault: address not mapped to object at address 0x448)
==== backtrace (tid:  74661) ====
 0  /opt/conda/envs/gdf/lib/libucs.so.0(ucs_handle_error+0x2fd) [0x7f5a63a3506d]
 1  /opt/conda/envs/gdf/lib/libucs.so.0(+0x2a264) [0x7f5a63a35264]
 2  /opt/conda/envs/gdf/lib/libucs.so.0(+0x2a42a) [0x7f5a63a3542a]
 3  /usr/lib/x86_64-linux-gnu/libpthread.so.0(+0x14420) [0x7f5b0b0a9420]
 4  /opt/conda/envs/gdf/lib/libucp.so.0(ucp_mem_type_unpack+0x14) [0x7f5a63ab36a4]
 5  /opt/conda/envs/gdf/lib/libucp.so.0(ucp_rndv_data_handler+0x4e9) [0x7f5a63adc829]
 6  /opt/conda/envs/gdf/lib/./libuct.so.0(+0x2146f) [0x7f5a639ef46f]
 7  /opt/conda/envs/gdf/lib/./libuct.so.0(+0x248c8) [0x7f5a639f28c8]
 8  /opt/conda/envs/gdf/lib/libucs.so.0(ucs_event_set_wait+0xb9) [0x7f5a63a3e499]
 9  /opt/conda/envs/gdf/lib/./libuct.so.0(uct_tcp_iface_progress+0x7d) [0x7f5a639f166d]
10  /opt/conda/envs/gdf/lib/libucp.so.0(ucp_worker_progress+0x5a) [0x7f5a63ab08ca]
11  /opt/conda/envs/gdf/lib/python3.9/site-packages/ucp/_libs/ucx_api.cpython-39-x86_64-linux-gnu.so(+0x3206a) [0x7f5a63b6906a]
12  /opt/conda/envs/gdf/bin/python(_PyEval_EvalFrameDefault+0x37cb) [0x562ed4d296fb]
13  /opt/conda/envs/gdf/bin/python(+0x12f094) [0x562ed4d25094]
14  /opt/conda/envs/gdf/bin/python(_PyFunction_Vectorcall+0xd9) [0x562ed4d36519]
15  /opt/conda/envs/gdf/bin/python(_PyEval_EvalFrameDefault+0x696) [0x562ed4d265c6]
16  /opt/conda/envs/gdf/bin/python(+0x1407c2) [0x562ed4d367c2]
17  /opt/conda/envs/gdf/bin/python(+0x14de83) [0x562ed4d43e83]
18  /opt/conda/envs/gdf/bin/python(+0x258b2c) [0x562ed4e4eb2c]
19  /opt/conda/envs/gdf/bin/python(+0xead05) [0x562ed4ce0d05]
20  /opt/conda/envs/gdf/bin/python(+0x1377f3) [0x562ed4d2d7f3]
21  /opt/conda/envs/gdf/bin/python(_PyEval_EvalFrameDefault+0x59f9) [0x562ed4d2b929]
22  /opt/conda/envs/gdf/bin/python(+0x1407c2) [0x562ed4d367c2]
23  /opt/conda/envs/gdf/bin/python(_PyEval_EvalFrameDefault+0x696) [0x562ed4d265c6]
24  /opt/conda/envs/gdf/bin/python(+0x1407c2) [0x562ed4d367c2]
25  /opt/conda/envs/gdf/bin/python(_PyEval_EvalFrameDefault+0x696) [0x562ed4d265c6]
26  /opt/conda/envs/gdf/bin/python(+0x1407c2) [0x562ed4d367c2]
27  /opt/conda/envs/gdf/bin/python(_PyEval_EvalFrameDefault+0x696) [0x562ed4d265c6]
28  /opt/conda/envs/gdf/bin/python(+0x1407c2) [0x562ed4d367c2]
29  /opt/conda/envs/gdf/bin/python(_PyEval_EvalFrameDefault+0x696) [0x562ed4d265c6]
30  /opt/conda/envs/gdf/bin/python(+0x12f094) [0x562ed4d25094]
31  /opt/conda/envs/gdf/bin/python(_PyFunction_Vectorcall+0xd9) [0x562ed4d36519]
32  /opt/conda/envs/gdf/bin/python(_PyEval_EvalFrameDefault+0x11f8) [0x562ed4d27128]
33  /opt/conda/envs/gdf/bin/python(+0x12f094) [0x562ed4d25094]
34  /opt/conda/envs/gdf/bin/python(+0x14dccb) [0x562ed4d43ccb]
35  /opt/conda/envs/gdf/bin/python(PyObject_Call+0xbc) [0x562ed4d4444c]
36  /opt/conda/envs/gdf/bin/python(+0x21110e) [0x562ed4e0710e]
37  /opt/conda/envs/gdf/bin/python(_PyObject_MakeTpCall+0x2ec) [0x562ed4d2e77c]
38  /opt/conda/envs/gdf/bin/python(_PyEval_EvalFrameDefault+0x37cb) [0x562ed4d296fb]
39  /opt/conda/envs/gdf/bin/python(+0x1407c2) [0x562ed4d367c2]
40  /opt/conda/envs/gdf/bin/python(+0x14ddac) [0x562ed4d43dac]
41  /opt/conda/envs/gdf/bin/python(_PyEval_EvalFrameDefault+0x37cb) [0x562ed4d296fb]
42  /opt/conda/envs/gdf/bin/python(+0x1407c2) [0x562ed4d367c2]
43  /opt/conda/envs/gdf/bin/python(_PyEval_EvalFrameDefault+0x696) [0x562ed4d265c6]
44  /opt/conda/envs/gdf/bin/python(+0x12f094) [0x562ed4d25094]
45  /opt/conda/envs/gdf/bin/python(_PyFunction_Vectorcall+0xd9) [0x562ed4d36519]
46  /opt/conda/envs/gdf/bin/python(_PyEval_EvalFrameDefault+0x696) [0x562ed4d265c6]
47  /opt/conda/envs/gdf/bin/python(+0x1407c2) [0x562ed4d367c2]
48  /opt/conda/envs/gdf/bin/python(_PyEval_EvalFrameDefault+0x3e2) [0x562ed4d26312]
49  /opt/conda/envs/gdf/bin/python(+0x12f094) [0x562ed4d25094]
50  /opt/conda/envs/gdf/bin/python(_PyFunction_Vectorcall+0xd9) [0x562ed4d36519]
51  /opt/conda/envs/gdf/bin/python(_PyEval_EvalFrameDefault+0x11f8) [0x562ed4d27128]
52  /opt/conda/envs/gdf/bin/python(+0x12f094) [0x562ed4d25094]
53  /opt/conda/envs/gdf/bin/python(_PyEval_EvalCodeWithName+0x48) [0x562ed4d24d68]
54  /opt/conda/envs/gdf/bin/python(PyEval_EvalCodeEx+0x39) [0x562ed4d24d19]
55  /opt/conda/envs/gdf/bin/python(PyEval_EvalCode+0x1b) [0x562ed4dd207b]
56  /opt/conda/envs/gdf/bin/python(+0x208fca) [0x562ed4dfefca]
57  /opt/conda/envs/gdf/bin/python(+0x205353) [0x562ed4dfb353]
58  /opt/conda/envs/gdf/bin/python(PyRun_StringFlags+0x9a) [0x562ed4df316a]
59  /opt/conda/envs/gdf/bin/python(PyRun_SimpleStringFlags+0x3c) [0x562ed4df305c]
60  /opt/conda/envs/gdf/bin/python(Py_RunMain+0x267) [0x562ed4df2297]
61  /opt/conda/envs/gdf/bin/python(Py_BytesMain+0x37) [0x562ed4dc5f07]
=================================
[dgx13:74651:0:74651] Caught signal 11 (Segmentation fault: address not mapped to object at address 0x448)
==== backtrace (tid:  74651) ====
 0  /opt/conda/envs/gdf/lib/libucs.so.0(ucs_handle_error+0x2fd) [0x7fd91852406d]
 1  /opt/conda/envs/gdf/lib/libucs.so.0(+0x2a264) [0x7fd918524264]
 2  /opt/conda/envs/gdf/lib/libucs.so.0(+0x2a42a) [0x7fd91852442a]
 3  /usr/lib/x86_64-linux-gnu/libpthread.so.0(+0x14420) [0x7fd9b9a2d420]
 4  /opt/conda/envs/gdf/lib/libucp.so.0(ucp_mem_type_unpack+0x14) [0x7fd9185a26a4]
 5  /opt/conda/envs/gdf/lib/libucp.so.0(ucp_rndv_data_handler+0x4e9) [0x7fd9185cb829]
 6  /opt/conda/envs/gdf/lib/./libuct.so.0(+0x2146f) [0x7fd9184de46f]
 7  /opt/conda/envs/gdf/lib/./libuct.so.0(+0x248c8) [0x7fd9184e18c8]
 8  /opt/conda/envs/gdf/lib/libucs.so.0(ucs_event_set_wait+0xb9) [0x7fd91852d499]
 9  /opt/conda/envs/gdf/lib/./libuct.so.0(uct_tcp_iface_progress+0x7d) [0x7fd9184e066d]
10  /opt/conda/envs/gdf/lib/libucp.so.0(ucp_worker_progress+0x5a) [0x7fd91859f8ca]
11  /opt/conda/envs/gdf/lib/python3.9/site-packages/ucp/_libs/ucx_api.cpython-39-x86_64-linux-gnu.so(+0x3206a) [0x7fd91865806a]
12  /opt/conda/envs/gdf/bin/python(_PyEval_EvalFrameDefault+0x37cb) [0x55bf9d1386fb]
13  /opt/conda/envs/gdf/bin/python(+0x12f094) [0x55bf9d134094]
14  /opt/conda/envs/gdf/bin/python(_PyFunction_Vectorcall+0xd9) [0x55bf9d145519]
15  /opt/conda/envs/gdf/bin/python(_PyEval_EvalFrameDefault+0x696) [0x55bf9d1355c6]
16  /opt/conda/envs/gdf/bin/python(+0x1407c2) [0x55bf9d1457c2]
17  /opt/conda/envs/gdf/bin/python(+0x14de83) [0x55bf9d152e83]
18  /opt/conda/envs/gdf/bin/python(+0x258b2c) [0x55bf9d25db2c]
19  /opt/conda/envs/gdf/bin/python(+0xead05) [0x55bf9d0efd05]
20  /opt/conda/envs/gdf/bin/python(+0x1377f3) [0x55bf9d13c7f3]
21  /opt/conda/envs/gdf/bin/python(_PyEval_EvalFrameDefault+0x59f9) [0x55bf9d13a929]
22  /opt/conda/envs/gdf/bin/python(+0x1407c2) [0x55bf9d1457c2]
23  /opt/conda/envs/gdf/bin/python(_PyEval_EvalFrameDefault+0x696) [0x55bf9d1355c6]
24  /opt/conda/envs/gdf/bin/python(+0x1407c2) [0x55bf9d1457c2]
25  /opt/conda/envs/gdf/bin/python(_PyEval_EvalFrameDefault+0x696) [0x55bf9d1355c6]
26  /opt/conda/envs/gdf/bin/python(+0x1407c2) [0x55bf9d1457c2]
27  /opt/conda/envs/gdf/bin/python(_PyEval_EvalFrameDefault+0x696) [0x55bf9d1355c6]
28  /opt/conda/envs/gdf/bin/python(+0x1407c2) [0x55bf9d1457c2]
29  /opt/conda/envs/gdf/bin/python(_PyEval_EvalFrameDefault+0x696) [0x55bf9d1355c6]
30  /opt/conda/envs/gdf/bin/python(+0x12f094) [0x55bf9d134094]
31  /opt/conda/envs/gdf/bin/python(_PyFunction_Vectorcall+0xd9) [0x55bf9d145519]
32  /opt/conda/envs/gdf/bin/python(_PyEval_EvalFrameDefault+0x11f8) [0x55bf9d136128]
33  /opt/conda/envs/gdf/bin/python(+0x12f094) [0x55bf9d134094]
34  /opt/conda/envs/gdf/bin/python(+0x14dccb) [0x55bf9d152ccb]
35  /opt/conda/envs/gdf/bin/python(PyObject_Call+0xbc) [0x55bf9d15344c]
36  /opt/conda/envs/gdf/bin/python(+0x21110e) [0x55bf9d21610e]
37  /opt/conda/envs/gdf/bin/python(_PyObject_MakeTpCall+0x2ec) [0x55bf9d13d77c]
38  /opt/conda/envs/gdf/bin/python(_PyEval_EvalFrameDefault+0x37cb) [0x55bf9d1386fb]
39  /opt/conda/envs/gdf/bin/python(+0x1407c2) [0x55bf9d1457c2]
40  /opt/conda/envs/gdf/bin/python(+0x14ddac) [0x55bf9d152dac]
41  /opt/conda/envs/gdf/bin/python(_PyEval_EvalFrameDefault+0x37cb) [0x55bf9d1386fb]
42  /opt/conda/envs/gdf/bin/python(+0x1407c2) [0x55bf9d1457c2]
43  /opt/conda/envs/gdf/bin/python(_PyEval_EvalFrameDefault+0x696) [0x55bf9d1355c6]
44  /opt/conda/envs/gdf/bin/python(+0x12f094) [0x55bf9d134094]
45  /opt/conda/envs/gdf/bin/python(_PyFunction_Vectorcall+0xd9) [0x55bf9d145519]
46  /opt/conda/envs/gdf/bin/python(_PyEval_EvalFrameDefault+0x696) [0x55bf9d1355c6]
47  /opt/conda/envs/gdf/bin/python(+0x1407c2) [0x55bf9d1457c2]
48  /opt/conda/envs/gdf/bin/python(_PyEval_EvalFrameDefault+0x3e2) [0x55bf9d135312]
49  /opt/conda/envs/gdf/bin/python(+0x12f094) [0x55bf9d134094]
50  /opt/conda/envs/gdf/bin/python(_PyFunction_Vectorcall+0xd9) [0x55bf9d145519]
51  /opt/conda/envs/gdf/bin/python(_PyEval_EvalFrameDefault+0x11f8) [0x55bf9d136128]
52  /opt/conda/envs/gdf/bin/python(+0x12f094) [0x55bf9d134094]
53  /opt/conda/envs/gdf/bin/python(_PyEval_EvalCodeWithName+0x48) [0x55bf9d133d68]
54  /opt/conda/envs/gdf/bin/python(PyEval_EvalCodeEx+0x39) [0x55bf9d133d19]
55  /opt/conda/envs/gdf/bin/python(PyEval_EvalCode+0x1b) [0x55bf9d1e107b]
56  /opt/conda/envs/gdf/bin/python(+0x208fca) [0x55bf9d20dfca]
57  /opt/conda/envs/gdf/bin/python(+0x205353) [0x55bf9d20a353]
58  /opt/conda/envs/gdf/bin/python(PyRun_StringFlags+0x9a) [0x55bf9d20216a]
59  /opt/conda/envs/gdf/bin/python(PyRun_SimpleStringFlags+0x3c) [0x55bf9d20205c]
60  /opt/conda/envs/gdf/bin/python(Py_RunMain+0x267) [0x55bf9d201297]
61  /opt/conda/envs/gdf/bin/python(Py_BytesMain+0x37) [0x55bf9d1d4f07]
=================================
[dgx13:74658:0:74658] Caught signal 11 (Segmentation fault: address not mapped to object at address 0x448)
==== backtrace (tid:  74658) ====
 0  /opt/conda/envs/gdf/lib/libucs.so.0(ucs_handle_error+0x2fd) [0x7f61ec52606d]
 1  /opt/conda/envs/gdf/lib/libucs.so.0(+0x2a264) [0x7f61ec526264]
 2  /opt/conda/envs/gdf/lib/libucs.so.0(+0x2a42a) [0x7f61ec52642a]
 3  /usr/lib/x86_64-linux-gnu/libpthread.so.0(+0x14420) [0x7f627fa1f420]
 4  /opt/conda/envs/gdf/lib/libucp.so.0(ucp_mem_type_unpack+0x14) [0x7f61ec5a46a4]
 5  /opt/conda/envs/gdf/lib/libucp.so.0(ucp_rndv_data_handler+0x4e9) [0x7f61ec5cd829]
 6  /opt/conda/envs/gdf/lib/./libuct.so.0(+0x2146f) [0x7f61ec4e046f]
 7  /opt/conda/envs/gdf/lib/./libuct.so.0(+0x248c8) [0x7f61ec4e38c8]
 8  /opt/conda/envs/gdf/lib/libucs.so.0(ucs_event_set_wait+0xb9) [0x7f61ec52f499]
 9  /opt/conda/envs/gdf/lib/./libuct.so.0(uct_tcp_iface_progress+0x7d) [0x7f61ec4e266d]
10  /opt/conda/envs/gdf/lib/libucp.so.0(ucp_worker_progress+0x5a) [0x7f61ec5a18ca]
11  /opt/conda/envs/gdf/lib/python3.9/site-packages/ucp/_libs/ucx_api.cpython-39-x86_64-linux-gnu.so(+0x3206a) [0x7f61ec65a06a]
12  /opt/conda/envs/gdf/bin/python(_PyEval_EvalFrameDefault+0x37cb) [0x55c0b3aed6fb]
13  /opt/conda/envs/gdf/bin/python(+0x12f094) [0x55c0b3ae9094]
14  /opt/conda/envs/gdf/bin/python(_PyFunction_Vectorcall+0xd9) [0x55c0b3afa519]
15  /opt/conda/envs/gdf/bin/python(_PyEval_EvalFrameDefault+0x696) [0x55c0b3aea5c6]
16  /opt/conda/envs/gdf/bin/python(+0x1407c2) [0x55c0b3afa7c2]
17  /opt/conda/envs/gdf/bin/python(+0x14de83) [0x55c0b3b07e83]
18  /opt/conda/envs/gdf/bin/python(+0x258b2c) [0x55c0b3c12b2c]
19  /opt/conda/envs/gdf/bin/python(+0xead05) [0x55c0b3aa4d05]
20  /opt/conda/envs/gdf/bin/python(+0x1377f3) [0x55c0b3af17f3]
21  /opt/conda/envs/gdf/bin/python(_PyEval_EvalFrameDefault+0x59f9) [0x55c0b3aef929]
22  /opt/conda/envs/gdf/bin/python(+0x1407c2) [0x55c0b3afa7c2]
23  /opt/conda/envs/gdf/bin/python(_PyEval_EvalFrameDefault+0x696) [0x55c0b3aea5c6]
24  /opt/conda/envs/gdf/bin/python(+0x1407c2) [0x55c0b3afa7c2]
25  /opt/conda/envs/gdf/bin/python(_PyEval_EvalFrameDefault+0x696) [0x55c0b3aea5c6]
26  /opt/conda/envs/gdf/bin/python(+0x1407c2) [0x55c0b3afa7c2]
27  /opt/conda/envs/gdf/bin/python(_PyEval_EvalFrameDefault+0x696) [0x55c0b3aea5c6]
28  /opt/conda/envs/gdf/bin/python(+0x1407c2) [0x55c0b3afa7c2]
29  /opt/conda/envs/gdf/bin/python(_PyEval_EvalFrameDefault+0x696) [0x55c0b3aea5c6]
30  /opt/conda/envs/gdf/bin/python(+0x12f094) [0x55c0b3ae9094]
31  /opt/conda/envs/gdf/bin/python(_PyFunction_Vectorcall+0xd9) [0x55c0b3afa519]
32  /opt/conda/envs/gdf/bin/python(_PyEval_EvalFrameDefault+0x11f8) [0x55c0b3aeb128]
33  /opt/conda/envs/gdf/bin/python(+0x12f094) [0x55c0b3ae9094]
34  /opt/conda/envs/gdf/bin/python(+0x14dccb) [0x55c0b3b07ccb]
35  /opt/conda/envs/gdf/bin/python(PyObject_Call+0xbc) [0x55c0b3b0844c]
36  /opt/conda/envs/gdf/bin/python(+0x21110e) [0x55c0b3bcb10e]
37  /opt/conda/envs/gdf/bin/python(_PyObject_MakeTpCall+0x2ec) [0x55c0b3af277c]
38  /opt/conda/envs/gdf/bin/python(_PyEval_EvalFrameDefault+0x37cb) [0x55c0b3aed6fb]
39  /opt/conda/envs/gdf/bin/python(+0x1407c2) [0x55c0b3afa7c2]
40  /opt/conda/envs/gdf/bin/python(+0x14ddac) [0x55c0b3b07dac]
41  /opt/conda/envs/gdf/bin/python(_PyEval_EvalFrameDefault+0x37cb) [0x55c0b3aed6fb]
42  /opt/conda/envs/gdf/bin/python(+0x1407c2) [0x55c0b3afa7c2]
43  /opt/conda/envs/gdf/bin/python(_PyEval_EvalFrameDefault+0x696) [0x55c0b3aea5c6]
44  /opt/conda/envs/gdf/bin/python(+0x12f094) [0x55c0b3ae9094]
45  /opt/conda/envs/gdf/bin/python(_PyFunction_Vectorcall+0xd9) [0x55c0b3afa519]
46  /opt/conda/envs/gdf/bin/python(_PyEval_EvalFrameDefault+0x696) [0x55c0b3aea5c6]
47  /opt/conda/envs/gdf/bin/python(+0x1407c2) [0x55c0b3afa7c2]
48  /opt/conda/envs/gdf/bin/python(_PyEval_EvalFrameDefault+0x3e2) [0x55c0b3aea312]
49  /opt/conda/envs/gdf/bin/python(+0x12f094) [0x55c0b3ae9094]
50  /opt/conda/envs/gdf/bin/python(_PyFunction_Vectorcall+0xd9) [0x55c0b3afa519]
51  /opt/conda/envs/gdf/bin/python(_PyEval_EvalFrameDefault+0x11f8) [0x55c0b3aeb128]
52  /opt/conda/envs/gdf/bin/python(+0x12f094) [0x55c0b3ae9094]
53  /opt/conda/envs/gdf/bin/python(_PyEval_EvalCodeWithName+0x48) [0x55c0b3ae8d68]
54  /opt/conda/envs/gdf/bin/python(PyEval_EvalCodeEx+0x39) [0x55c0b3ae8d19]
55  /opt/conda/envs/gdf/bin/python(PyEval_EvalCode+0x1b) [0x55c0b3b9607b]
56  /opt/conda/envs/gdf/bin/python(+0x208fca) [0x55c0b3bc2fca]
57  /opt/conda/envs/gdf/bin/python(+0x205353) [0x55c0b3bbf353]
58  /opt/conda/envs/gdf/bin/python(PyRun_StringFlags+0x9a) [0x55c0b3bb716a]
59  /opt/conda/envs/gdf/bin/python(PyRun_SimpleStringFlags+0x3c) [0x55c0b3bb705c]
60  /opt/conda/envs/gdf/bin/python(Py_RunMain+0x267) [0x55c0b3bb6297]
61  /opt/conda/envs/gdf/bin/python(Py_BytesMain+0x37) [0x55c0b3b89f07]
=================================
[dgx13:74665:0:74665] Caught signal 11 (Segmentation fault: address not mapped to object at address 0x448)
==== backtrace (tid:  74665) ====
 0  /opt/conda/envs/gdf/lib/libucs.so.0(ucs_handle_error+0x2fd) [0x7f0c419b506d]
 1  /opt/conda/envs/gdf/lib/libucs.so.0(+0x2a264) [0x7f0c419b5264]
 2  /opt/conda/envs/gdf/lib/libucs.so.0(+0x2a42a) [0x7f0c419b542a]
 3  /usr/lib/x86_64-linux-gnu/libpthread.so.0(+0x14420) [0x7f0ce703a420]
 4  /opt/conda/envs/gdf/lib/libucp.so.0(ucp_mem_type_unpack+0x14) [0x7f0c41a336a4]
 5  /opt/conda/envs/gdf/lib/libucp.so.0(ucp_rndv_data_handler+0x4e9) [0x7f0c41a5c829]
 6  /opt/conda/envs/gdf/lib/./libuct.so.0(+0x2146f) [0x7f0c4196f46f]
 7  /opt/conda/envs/gdf/lib/./libuct.so.0(+0x248c8) [0x7f0c419728c8]
 8  /opt/conda/envs/gdf/lib/libucs.so.0(ucs_event_set_wait+0xb9) [0x7f0c419be499]
 9  /opt/conda/envs/gdf/lib/./libuct.so.0(uct_tcp_iface_progress+0x7d) [0x7f0c4197166d]
10  /opt/conda/envs/gdf/lib/libucp.so.0(ucp_worker_progress+0x5a) [0x7f0c41a308ca]
11  /opt/conda/envs/gdf/lib/python3.9/site-packages/ucp/_libs/ucx_api.cpython-39-x86_64-linux-gnu.so(+0x3206a) [0x7f0c41ae906a]
12  /opt/conda/envs/gdf/bin/python(_PyEval_EvalFrameDefault+0x37cb) [0x5569f20256fb]
13  /opt/conda/envs/gdf/bin/python(+0x12f094) [0x5569f2021094]
14  /opt/conda/envs/gdf/bin/python(_PyFunction_Vectorcall+0xd9) [0x5569f2032519]
15  /opt/conda/envs/gdf/bin/python(_PyEval_EvalFrameDefault+0x696) [0x5569f20225c6]
16  /opt/conda/envs/gdf/bin/python(+0x1407c2) [0x5569f20327c2]
17  /opt/conda/envs/gdf/bin/python(+0x14de83) [0x5569f203fe83]
18  /opt/conda/envs/gdf/bin/python(+0x258b2c) [0x5569f214ab2c]
19  /opt/conda/envs/gdf/bin/python(+0xead05) [0x5569f1fdcd05]
20  /opt/conda/envs/gdf/bin/python(+0x1377f3) [0x5569f20297f3]
21  /opt/conda/envs/gdf/bin/python(_PyEval_EvalFrameDefault+0x59f9) [0x5569f2027929]
22  /opt/conda/envs/gdf/bin/python(+0x1407c2) [0x5569f20327c2]
23  /opt/conda/envs/gdf/bin/python(_PyEval_EvalFrameDefault+0x696) [0x5569f20225c6]
24  /opt/conda/envs/gdf/bin/python(+0x1407c2) [0x5569f20327c2]
25  /opt/conda/envs/gdf/bin/python(_PyEval_EvalFrameDefault+0x696) [0x5569f20225c6]
26  /opt/conda/envs/gdf/bin/python(+0x1407c2) [0x5569f20327c2]
27  /opt/conda/envs/gdf/bin/python(_PyEval_EvalFrameDefault+0x696) [0x5569f20225c6]
28  /opt/conda/envs/gdf/bin/python(+0x1407c2) [0x5569f20327c2]
29  /opt/conda/envs/gdf/bin/python(_PyEval_EvalFrameDefault+0x696) [0x5569f20225c6]
30  /opt/conda/envs/gdf/bin/python(+0x12f094) [0x5569f2021094]
31  /opt/conda/envs/gdf/bin/python(_PyFunction_Vectorcall+0xd9) [0x5569f2032519]
32  /opt/conda/envs/gdf/bin/python(_PyEval_EvalFrameDefault+0x11f8) [0x5569f2023128]
33  /opt/conda/envs/gdf/bin/python(+0x12f094) [0x5569f2021094]
34  /opt/conda/envs/gdf/bin/python(+0x14dccb) [0x5569f203fccb]
35  /opt/conda/envs/gdf/bin/python(PyObject_Call+0xbc) [0x5569f204044c]
36  /opt/conda/envs/gdf/bin/python(+0x21110e) [0x5569f210310e]
37  /opt/conda/envs/gdf/bin/python(_PyObject_MakeTpCall+0x2ec) [0x5569f202a77c]
38  /opt/conda/envs/gdf/bin/python(_PyEval_EvalFrameDefault+0x37cb) [0x5569f20256fb]
39  /opt/conda/envs/gdf/bin/python(+0x1407c2) [0x5569f20327c2]
40  /opt/conda/envs/gdf/bin/python(+0x14ddac) [0x5569f203fdac]
41  /opt/conda/envs/gdf/bin/python(_PyEval_EvalFrameDefault+0x37cb) [0x5569f20256fb]
42  /opt/conda/envs/gdf/bin/python(+0x1407c2) [0x5569f20327c2]
43  /opt/conda/envs/gdf/bin/python(_PyEval_EvalFrameDefault+0x696) [0x5569f20225c6]
44  /opt/conda/envs/gdf/bin/python(+0x12f094) [0x5569f2021094]
45  /opt/conda/envs/gdf/bin/python(_PyFunction_Vectorcall+0xd9) [0x5569f2032519]
46  /opt/conda/envs/gdf/bin/python(_PyEval_EvalFrameDefault+0x696) [0x5569f20225c6]
47  /opt/conda/envs/gdf/bin/python(+0x1407c2) [0x5569f20327c2]
48  /opt/conda/envs/gdf/bin/python(_PyEval_EvalFrameDefault+0x3e2) [0x5569f2022312]
49  /opt/conda/envs/gdf/bin/python(+0x12f094) [0x5569f2021094]
50  /opt/conda/envs/gdf/bin/python(_PyFunction_Vectorcall+0xd9) [0x5569f2032519]
51  /opt/conda/envs/gdf/bin/python(_PyEval_EvalFrameDefault+0x11f8) [0x5569f2023128]
52  /opt/conda/envs/gdf/bin/python(+0x12f094) [0x5569f2021094]
53  /opt/conda/envs/gdf/bin/python(_PyEval_EvalCodeWithName+0x48) [0x5569f2020d68]
54  /opt/conda/envs/gdf/bin/python(PyEval_EvalCodeEx+0x39) [0x5569f2020d19]
55  /opt/conda/envs/gdf/bin/python(PyEval_EvalCode+0x1b) [0x5569f20ce07b]
56  /opt/conda/envs/gdf/bin/python(+0x208fca) [0x5569f20fafca]
57  /opt/conda/envs/gdf/bin/python(+0x205353) [0x5569f20f7353]
58  /opt/conda/envs/gdf/bin/python(PyRun_StringFlags+0x9a) [0x5569f20ef16a]
59  /opt/conda/envs/gdf/bin/python(PyRun_SimpleStringFlags+0x3c) [0x5569f20ef05c]
60  /opt/conda/envs/gdf/bin/python(Py_RunMain+0x267) [0x5569f20ee297]
61  /opt/conda/envs/gdf/bin/python(Py_BytesMain+0x37) [0x5569f20c1f07]
=================================
2023-12-14 06:57:11,125 - distributed.worker - ERROR - failed during get data with ucx://127.0.0.1:38163 -> ucx://127.0.0.1:60139
Traceback (most recent call last):
  File "/opt/conda/envs/gdf/lib/python3.9/site-packages/distributed/comm/ucx.py", line 338, in write
    await self.ep.send(each_frame)
  File "/opt/conda/envs/gdf/lib/python3.9/site-packages/ucp/core.py", line 650, in send
    return await comm.tag_send(self._ep, buffer, nbytes, tag, name=log)
ucp._libs.exceptions.UCXError: <[Send #007] ep: 0x7efc88dd21c0, tag: 0x756e410c5b2e6314, nbytes: 50000000, type: <class 'cupy.ndarray'>>: Connection reset by remote peer

During handling of the above exception, another exception occurred:

Traceback (most recent call last):
  File "/opt/conda/envs/gdf/lib/python3.9/site-packages/distributed/worker.py", line 1782, in get_data
    compressed = await comm.write(msg, serializers=serializers)
  File "/opt/conda/envs/gdf/lib/python3.9/site-packages/distributed/utils.py", line 803, in wrapper
    return await func(*args, **kwargs)
  File "/opt/conda/envs/gdf/lib/python3.9/site-packages/distributed/comm/ucx.py", line 342, in write
    raise CommClosedError("While writing, the connection was closed")
distributed.comm.core.CommClosedError: While writing, the connection was closed
2023-12-14 06:57:11,223 - distributed.worker - ERROR - Worker stream died during communication: ucx://127.0.0.1:51959
Traceback (most recent call last):
  File "/opt/conda/envs/gdf/lib/python3.9/site-packages/distributed/core.py", line 1516, in _connect
    comm = await connect(
  File "/opt/conda/envs/gdf/lib/python3.9/site-packages/distributed/comm/core.py", line 342, in connect
    comm = await wait_for(
  File "/opt/conda/envs/gdf/lib/python3.9/site-packages/distributed/utils.py", line 1920, in wait_for
    return await asyncio.wait_for(fut, timeout)
  File "/opt/conda/envs/gdf/lib/python3.9/asyncio/tasks.py", line 466, in wait_for
    await waiter
asyncio.exceptions.CancelledError

During handling of the above exception, another exception occurred:

Traceback (most recent call last):
  File "/opt/conda/envs/gdf/lib/python3.9/site-packages/distributed/core.py", line 1626, in connect
    return connect_attempt.result()
asyncio.exceptions.CancelledError

During handling of the above exception, another exception occurred:

Traceback (most recent call last):
  File "/opt/conda/envs/gdf/lib/python3.9/site-packages/distributed/worker.py", line 2059, in gather_dep
    response = await get_data_from_worker(
  File "/opt/conda/envs/gdf/lib/python3.9/site-packages/distributed/worker.py", line 2849, in get_data_from_worker
    comm = await rpc.connect(worker)
  File "/opt/conda/envs/gdf/lib/python3.9/site-packages/distributed/core.py", line 1628, in connect
    raise CommClosedError(reason)
distributed.comm.core.CommClosedError: Address removed.
2023-12-14 06:57:11,223 - distributed.worker - ERROR - Worker stream died during communication: ucx://127.0.0.1:51959
Traceback (most recent call last):
  File "/opt/conda/envs/gdf/lib/python3.9/site-packages/distributed/core.py", line 1516, in _connect
    comm = await connect(
  File "/opt/conda/envs/gdf/lib/python3.9/site-packages/distributed/comm/core.py", line 342, in connect
    comm = await wait_for(
  File "/opt/conda/envs/gdf/lib/python3.9/site-packages/distributed/utils.py", line 1920, in wait_for
    return await asyncio.wait_for(fut, timeout)
  File "/opt/conda/envs/gdf/lib/python3.9/asyncio/tasks.py", line 466, in wait_for
    await waiter
asyncio.exceptions.CancelledError

During handling of the above exception, another exception occurred:

Traceback (most recent call last):
  File "/opt/conda/envs/gdf/lib/python3.9/site-packages/distributed/core.py", line 1626, in connect
    return connect_attempt.result()
asyncio.exceptions.CancelledError

During handling of the above exception, another exception occurred:

Traceback (most recent call last):
  File "/opt/conda/envs/gdf/lib/python3.9/site-packages/distributed/worker.py", line 2059, in gather_dep
    response = await get_data_from_worker(
  File "/opt/conda/envs/gdf/lib/python3.9/site-packages/distributed/worker.py", line 2849, in get_data_from_worker
    comm = await rpc.connect(worker)
  File "/opt/conda/envs/gdf/lib/python3.9/site-packages/distributed/core.py", line 1628, in connect
    raise CommClosedError(reason)
distributed.comm.core.CommClosedError: Address removed.
2023-12-14 06:57:11,341 - distributed.worker - ERROR - failed during get data with ucx://127.0.0.1:47503 -> ucx://127.0.0.1:58211
Traceback (most recent call last):
  File "/opt/conda/envs/gdf/lib/python3.9/site-packages/distributed/comm/ucx.py", line 338, in write
    await self.ep.send(each_frame)
  File "/opt/conda/envs/gdf/lib/python3.9/site-packages/ucp/core.py", line 650, in send
    return await comm.tag_send(self._ep, buffer, nbytes, tag, name=log)
ucp._libs.exceptions.UCXError: <[Send #007] ep: 0x7f01c462e200, tag: 0x63a28fab880df2e2, nbytes: 50000000, type: <class 'cupy.ndarray'>>: Connection reset by remote peer

During handling of the above exception, another exception occurred:

Traceback (most recent call last):
  File "/opt/conda/envs/gdf/lib/python3.9/site-packages/distributed/worker.py", line 1782, in get_data
    compressed = await comm.write(msg, serializers=serializers)
  File "/opt/conda/envs/gdf/lib/python3.9/site-packages/distributed/utils.py", line 803, in wrapper
    return await func(*args, **kwargs)
  File "/opt/conda/envs/gdf/lib/python3.9/site-packages/distributed/comm/ucx.py", line 342, in write
    raise CommClosedError("While writing, the connection was closed")
distributed.comm.core.CommClosedError: While writing, the connection was closed
2023-12-14 06:57:11,369 - distributed.worker - ERROR - failed during get data with ucx://127.0.0.1:38163 -> ucx://127.0.0.1:54653
Traceback (most recent call last):
  File "/opt/conda/envs/gdf/lib/python3.9/site-packages/distributed/comm/ucx.py", line 338, in write
    await self.ep.send(each_frame)
  File "/opt/conda/envs/gdf/lib/python3.9/site-packages/ucp/core.py", line 650, in send
    return await comm.tag_send(self._ep, buffer, nbytes, tag, name=log)
ucp._libs.exceptions.UCXError: <[Send #007] ep: 0x7efc88dd2240, tag: 0x5121b4e0ae34a0bd, nbytes: 50000000, type: <class 'cupy.ndarray'>>: Connection reset by remote peer

During handling of the above exception, another exception occurred:

Traceback (most recent call last):
  File "/opt/conda/envs/gdf/lib/python3.9/site-packages/distributed/worker.py", line 1782, in get_data
    compressed = await comm.write(msg, serializers=serializers)
  File "/opt/conda/envs/gdf/lib/python3.9/site-packages/distributed/utils.py", line 803, in wrapper
    return await func(*args, **kwargs)
  File "/opt/conda/envs/gdf/lib/python3.9/site-packages/distributed/comm/ucx.py", line 342, in write
    raise CommClosedError("While writing, the connection was closed")
distributed.comm.core.CommClosedError: While writing, the connection was closed
[dgx13:74670:0:74670] Caught signal 11 (Segmentation fault: address not mapped to object at address 0x448)
==== backtrace (tid:  74670) ====
 0  /opt/conda/envs/gdf/lib/libucs.so.0(ucs_handle_error+0x2fd) [0x7f8d704a306d]
 1  /opt/conda/envs/gdf/lib/libucs.so.0(+0x2a264) [0x7f8d704a3264]
 2  /opt/conda/envs/gdf/lib/libucs.so.0(+0x2a42a) [0x7f8d704a342a]
 3  /usr/lib/x86_64-linux-gnu/libpthread.so.0(+0x14420) [0x7f8e119a8420]
 4  /opt/conda/envs/gdf/lib/libucp.so.0(ucp_mem_type_unpack+0x14) [0x7f8d705216a4]
 5  /opt/conda/envs/gdf/lib/libucp.so.0(ucp_rndv_data_handler+0x4e9) [0x7f8d7054a829]
 6  /opt/conda/envs/gdf/lib/./libuct.so.0(+0x2146f) [0x7f8d7045d46f]
 7  /opt/conda/envs/gdf/lib/./libuct.so.0(+0x248c8) [0x7f8d704608c8]
 8  /opt/conda/envs/gdf/lib/libucs.so.0(ucs_event_set_wait+0xb9) [0x7f8d704ac499]
 9  /opt/conda/envs/gdf/lib/./libuct.so.0(uct_tcp_iface_progress+0x7d) [0x7f8d7045f66d]
10  /opt/conda/envs/gdf/lib/libucp.so.0(ucp_worker_progress+0x5a) [0x7f8d7051e8ca]
11  /opt/conda/envs/gdf/lib/python3.9/site-packages/ucp/_libs/ucx_api.cpython-39-x86_64-linux-gnu.so(+0x3206a) [0x7f8d705d706a]
12  /opt/conda/envs/gdf/bin/python(_PyEval_EvalFrameDefault+0x37cb) [0x55bec20586fb]
13  /opt/conda/envs/gdf/bin/python(+0x12f094) [0x55bec2054094]
14  /opt/conda/envs/gdf/bin/python(_PyFunction_Vectorcall+0xd9) [0x55bec2065519]
15  /opt/conda/envs/gdf/bin/python(_PyEval_EvalFrameDefault+0x696) [0x55bec20555c6]
16  /opt/conda/envs/gdf/bin/python(+0x1407c2) [0x55bec20657c2]
17  /opt/conda/envs/gdf/bin/python(+0x14de83) [0x55bec2072e83]
18  /opt/conda/envs/gdf/bin/python(+0x258b2c) [0x55bec217db2c]
19  /opt/conda/envs/gdf/bin/python(+0xead05) [0x55bec200fd05]
20  /opt/conda/envs/gdf/bin/python(+0x1377f3) [0x55bec205c7f3]
21  /opt/conda/envs/gdf/bin/python(_PyEval_EvalFrameDefault+0x59f9) [0x55bec205a929]
22  /opt/conda/envs/gdf/bin/python(+0x1407c2) [0x55bec20657c2]
23  /opt/conda/envs/gdf/bin/python(_PyEval_EvalFrameDefault+0x696) [0x55bec20555c6]
24  /opt/conda/envs/gdf/bin/python(+0x1407c2) [0x55bec20657c2]
25  /opt/conda/envs/gdf/bin/python(_PyEval_EvalFrameDefault+0x696) [0x55bec20555c6]
26  /opt/conda/envs/gdf/bin/python(+0x1407c2) [0x55bec20657c2]
27  /opt/conda/envs/gdf/bin/python(_PyEval_EvalFrameDefault+0x696) [0x55bec20555c6]
28  /opt/conda/envs/gdf/bin/python(+0x1407c2) [0x55bec20657c2]
29  /opt/conda/envs/gdf/bin/python(_PyEval_EvalFrameDefault+0x696) [0x55bec20555c6]
30  /opt/conda/envs/gdf/bin/python(+0x12f094) [0x55bec2054094]
31  /opt/conda/envs/gdf/bin/python(_PyFunction_Vectorcall+0xd9) [0x55bec2065519]
32  /opt/conda/envs/gdf/bin/python(_PyEval_EvalFrameDefault+0x11f8) [0x55bec2056128]
33  /opt/conda/envs/gdf/bin/python(+0x12f094) [0x55bec2054094]
34  /opt/conda/envs/gdf/bin/python(+0x14dccb) [0x55bec2072ccb]
35  /opt/conda/envs/gdf/bin/python(PyObject_Call+0xbc) [0x55bec207344c]
36  /opt/conda/envs/gdf/bin/python(+0x21110e) [0x55bec213610e]
37  /opt/conda/envs/gdf/bin/python(_PyObject_MakeTpCall+0x2ec) [0x55bec205d77c]
38  /opt/conda/envs/gdf/bin/python(_PyEval_EvalFrameDefault+0x37cb) [0x55bec20586fb]
39  /opt/conda/envs/gdf/bin/python(+0x1407c2) [0x55bec20657c2]
40  /opt/conda/envs/gdf/bin/python(+0x14ddac) [0x55bec2072dac]
41  /opt/conda/envs/gdf/bin/python(_PyEval_EvalFrameDefault+0x37cb) [0x55bec20586fb]
42  /opt/conda/envs/gdf/bin/python(+0x1407c2) [0x55bec20657c2]
43  /opt/conda/envs/gdf/bin/python(_PyEval_EvalFrameDefault+0x696) [0x55bec20555c6]
44  /opt/conda/envs/gdf/bin/python(+0x12f094) [0x55bec2054094]
45  /opt/conda/envs/gdf/bin/python(_PyFunction_Vectorcall+0xd9) [0x55bec2065519]
46  /opt/conda/envs/gdf/bin/python(_PyEval_EvalFrameDefault+0x696) [0x55bec20555c6]
47  /opt/conda/envs/gdf/bin/python(+0x1407c2) [0x55bec20657c2]
48  /opt/conda/envs/gdf/bin/python(_PyEval_EvalFrameDefault+0x3e2) [0x55bec2055312]
49  /opt/conda/envs/gdf/bin/python(+0x12f094) [0x55bec2054094]
50  /opt/conda/envs/gdf/bin/python(_PyFunction_Vectorcall+0xd9) [0x55bec2065519]
51  /opt/conda/envs/gdf/bin/python(_PyEval_EvalFrameDefault+0x11f8) [0x55bec2056128]
52  /opt/conda/envs/gdf/bin/python(+0x12f094) [0x55bec2054094]
53  /opt/conda/envs/gdf/bin/python(_PyEval_EvalCodeWithName+0x48) [0x55bec2053d68]
54  /opt/conda/envs/gdf/bin/python(PyEval_EvalCodeEx+0x39) [0x55bec2053d19]
55  /opt/conda/envs/gdf/bin/python(PyEval_EvalCode+0x1b) [0x55bec210107b]
56  /opt/conda/envs/gdf/bin/python(+0x208fca) [0x55bec212dfca]
57  /opt/conda/envs/gdf/bin/python(+0x205353) [0x55bec212a353]
58  /opt/conda/envs/gdf/bin/python(PyRun_StringFlags+0x9a) [0x55bec212216a]
59  /opt/conda/envs/gdf/bin/python(PyRun_SimpleStringFlags+0x3c) [0x55bec212205c]
60  /opt/conda/envs/gdf/bin/python(Py_RunMain+0x267) [0x55bec2121297]
61  /opt/conda/envs/gdf/bin/python(Py_BytesMain+0x37) [0x55bec20f4f07]
=================================
2023-12-14 06:57:12,262 - distributed.worker - ERROR - failed during get data with ucx://127.0.0.1:47503 -> ucx://127.0.0.1:35651
Traceback (most recent call last):
  File "/opt/conda/envs/gdf/lib/python3.9/site-packages/distributed/comm/ucx.py", line 338, in write
    await self.ep.send(each_frame)
  File "/opt/conda/envs/gdf/lib/python3.9/site-packages/ucp/core.py", line 650, in send
    return await comm.tag_send(self._ep, buffer, nbytes, tag, name=log)
ucp._libs.exceptions.UCXError: <[Send #031] ep: 0x7f01c462e140, tag: 0x35fb2ba35f63b400, nbytes: 50000000, type: <class 'cupy.ndarray'>>: Connection reset by remote peer

During handling of the above exception, another exception occurred:

Traceback (most recent call last):
  File "/opt/conda/envs/gdf/lib/python3.9/site-packages/distributed/worker.py", line 1782, in get_data
    compressed = await comm.write(msg, serializers=serializers)
  File "/opt/conda/envs/gdf/lib/python3.9/site-packages/distributed/utils.py", line 803, in wrapper
    return await func(*args, **kwargs)
  File "/opt/conda/envs/gdf/lib/python3.9/site-packages/distributed/comm/ucx.py", line 342, in write
    raise CommClosedError("While writing, the connection was closed")
distributed.comm.core.CommClosedError: While writing, the connection was closed
2023-12-14 06:57:12,262 - distributed.worker - ERROR - Worker stream died during communication: ucx://127.0.0.1:35651
Traceback (most recent call last):
  File "/opt/conda/envs/gdf/lib/python3.9/site-packages/distributed/comm/ucx.py", line 354, in read
    await self.ep.recv(msg)
  File "/opt/conda/envs/gdf/lib/python3.9/site-packages/ucp/core.py", line 725, in recv
    ret = await comm.tag_recv(self._ep, buffer, nbytes, tag, name=log)
ucp._libs.exceptions.UCXCanceled: <[Recv #008] ep: 0x7efc4d44a240, tag: 0x1c79548a70014dfd, nbytes: 16, type: <class 'numpy.ndarray'>>: 

During handling of the above exception, another exception occurred:

Traceback (most recent call last):
  File "/opt/conda/envs/gdf/lib/python3.9/site-packages/distributed/worker.py", line 2059, in gather_dep
    response = await get_data_from_worker(
  File "/opt/conda/envs/gdf/lib/python3.9/site-packages/distributed/worker.py", line 2852, in get_data_from_worker
    response = await send_recv(
  File "/opt/conda/envs/gdf/lib/python3.9/site-packages/distributed/core.py", line 1106, in send_recv
    response = await comm.read(deserializers=deserializers)
  File "/opt/conda/envs/gdf/lib/python3.9/site-packages/distributed/utils.py", line 803, in wrapper
    return await func(*args, **kwargs)
  File "/opt/conda/envs/gdf/lib/python3.9/site-packages/distributed/comm/ucx.py", line 372, in read
    raise CommClosedError(
distributed.comm.core.CommClosedError: Connection closed by writer.
Inner exception: UCXCanceled("<[Recv #008] ep: 0x7efc4d44a240, tag: 0x1c79548a70014dfd, nbytes: 16, type: <class 'numpy.ndarray'>>: ")
/opt/conda/envs/gdf/lib/python3.9/multiprocessing/resource_tracker.py:216: UserWarning: resource_tracker: There appear to be 18 leaked semaphore objects to clean up at shutdown
  warnings.warn('resource_tracker: There appear to be %d '
