/opt/conda/envs/gdf/lib/python3.9/site-packages/distributed/node.py:182: UserWarning: Port 8787 is already in use.
Perhaps you already have a cluster running?
Hosting the HTTP server on port 41069 instead
  warnings.warn(
[dgx13:94943:0:94943] Caught signal 11 (Segmentation fault: address not mapped to object at address 0x450)
==== backtrace (tid:  94943) ====
 0  /opt/conda/envs/gdf/lib/libucs.so.0(ucs_handle_error+0x2fd) [0x7f4a5977c6fd]
 1  /opt/conda/envs/gdf/lib/libucs.so.0(+0x2d8f4) [0x7f4a5977c8f4]
 2  /opt/conda/envs/gdf/lib/libucs.so.0(+0x2daba) [0x7f4a5977caba]
 3  /usr/lib/x86_64-linux-gnu/libpthread.so.0(+0x14420) [0x7f4afedfd420]
 4  /opt/conda/envs/gdf/lib/libucp.so.0(ucp_mem_type_unpack+0x17) [0x7f4a597ff8b7]
 5  /opt/conda/envs/gdf/lib/libucp.so.0(ucp_rndv_data_handler+0x65d) [0x7f4a598283ed]
 6  /opt/conda/envs/gdf/lib/libuct.so.0(+0x2193f) [0x7f4a5973393f]
 7  /opt/conda/envs/gdf/lib/libuct.so.0(+0x24b18) [0x7f4a59736b18]
 8  /opt/conda/envs/gdf/lib/libucs.so.0(ucs_event_set_wait+0xb9) [0x7f4a59785ff9]
 9  /opt/conda/envs/gdf/lib/libuct.so.0(uct_tcp_iface_progress+0x7d) [0x7f4a59735c2d]
10  /opt/conda/envs/gdf/lib/libucp.so.0(ucp_worker_progress+0x5a) [0x7f4a597fc7aa]
11  /opt/conda/envs/gdf/lib/python3.9/site-packages/ucp/_libs/ucx_api.cpython-39-x86_64-linux-gnu.so(+0x3206a) [0x7f4a598bb06a]
12  /opt/conda/envs/gdf/bin/python(_PyEval_EvalFrameDefault+0x45a6) [0x562e6415b3f6]
13  /opt/conda/envs/gdf/bin/python(+0x12dfb4) [0x562e64155fb4]
14  /opt/conda/envs/gdf/bin/python(_PyFunction_Vectorcall+0xd9) [0x562e64167469]
15  /opt/conda/envs/gdf/bin/python(_PyEval_EvalFrameDefault+0x696) [0x562e641574e6]
16  /opt/conda/envs/gdf/bin/python(+0x13f712) [0x562e64167712]
17  /opt/conda/envs/gdf/bin/python(+0x14ca83) [0x562e64174a83]
18  /opt/conda/envs/gdf/bin/python(+0x25819c) [0x562e6428019c]
19  /opt/conda/envs/gdf/bin/python(+0xf23ff) [0x562e6411a3ff]
20  /opt/conda/envs/gdf/bin/python(+0x136723) [0x562e6415e723]
21  /opt/conda/envs/gdf/bin/python(_PyEval_EvalFrameDefault+0x5ad9) [0x562e6415c929]
22  /opt/conda/envs/gdf/bin/python(+0x13f712) [0x562e64167712]
23  /opt/conda/envs/gdf/bin/python(_PyEval_EvalFrameDefault+0x696) [0x562e641574e6]
24  /opt/conda/envs/gdf/bin/python(+0x13f712) [0x562e64167712]
25  /opt/conda/envs/gdf/bin/python(_PyEval_EvalFrameDefault+0x696) [0x562e641574e6]
26  /opt/conda/envs/gdf/bin/python(+0x13f712) [0x562e64167712]
27  /opt/conda/envs/gdf/bin/python(_PyEval_EvalFrameDefault+0x696) [0x562e641574e6]
28  /opt/conda/envs/gdf/bin/python(+0x13f712) [0x562e64167712]
29  /opt/conda/envs/gdf/bin/python(_PyEval_EvalFrameDefault+0x696) [0x562e641574e6]
30  /opt/conda/envs/gdf/bin/python(+0x12dfb4) [0x562e64155fb4]
31  /opt/conda/envs/gdf/bin/python(_PyFunction_Vectorcall+0xd9) [0x562e64167469]
32  /opt/conda/envs/gdf/bin/python(_PyEval_EvalFrameDefault+0x11f2) [0x562e64158042]
33  /opt/conda/envs/gdf/bin/python(+0x12dfb4) [0x562e64155fb4]
34  /opt/conda/envs/gdf/bin/python(+0x14c8cb) [0x562e641748cb]
35  /opt/conda/envs/gdf/bin/python(PyObject_Call+0xbc) [0x562e6417504c]
36  /opt/conda/envs/gdf/bin/python(+0x21080e) [0x562e6423880e]
37  /opt/conda/envs/gdf/bin/python(_PyObject_MakeTpCall+0x2ec) [0x562e6415f6ac]
38  /opt/conda/envs/gdf/bin/python(_PyEval_EvalFrameDefault+0x45a6) [0x562e6415b3f6]
39  /opt/conda/envs/gdf/bin/python(+0x13f712) [0x562e64167712]
40  /opt/conda/envs/gdf/bin/python(+0x14c9ac) [0x562e641749ac]
41  /opt/conda/envs/gdf/bin/python(_PyEval_EvalFrameDefault+0x45a6) [0x562e6415b3f6]
42  /opt/conda/envs/gdf/bin/python(+0x13f712) [0x562e64167712]
43  /opt/conda/envs/gdf/bin/python(_PyEval_EvalFrameDefault+0x696) [0x562e641574e6]
44  /opt/conda/envs/gdf/bin/python(+0x12dfb4) [0x562e64155fb4]
45  /opt/conda/envs/gdf/bin/python(_PyFunction_Vectorcall+0xd9) [0x562e64167469]
46  /opt/conda/envs/gdf/bin/python(_PyEval_EvalFrameDefault+0x696) [0x562e641574e6]
47  /opt/conda/envs/gdf/bin/python(+0x13f712) [0x562e64167712]
48  /opt/conda/envs/gdf/bin/python(_PyEval_EvalFrameDefault+0x3e2) [0x562e64157232]
49  /opt/conda/envs/gdf/bin/python(+0x12dfb4) [0x562e64155fb4]
50  /opt/conda/envs/gdf/bin/python(_PyFunction_Vectorcall+0xd9) [0x562e64167469]
51  /opt/conda/envs/gdf/bin/python(_PyEval_EvalFrameDefault+0x11f2) [0x562e64158042]
52  /opt/conda/envs/gdf/bin/python(+0x12dfb4) [0x562e64155fb4]
53  /opt/conda/envs/gdf/bin/python(_PyEval_EvalCodeWithName+0x48) [0x562e64155c88]
54  /opt/conda/envs/gdf/bin/python(PyEval_EvalCodeEx+0x39) [0x562e64155c39]
55  /opt/conda/envs/gdf/bin/python(PyEval_EvalCode+0x1b) [0x562e642032cb]
56  /opt/conda/envs/gdf/bin/python(+0x2086ca) [0x562e642306ca]
57  /opt/conda/envs/gdf/bin/python(+0x204a63) [0x562e6422ca63]
58  /opt/conda/envs/gdf/bin/python(PyRun_StringFlags+0x9a) [0x562e6422487a]
59  /opt/conda/envs/gdf/bin/python(PyRun_SimpleStringFlags+0x3c) [0x562e6422476c]
60  /opt/conda/envs/gdf/bin/python(Py_RunMain+0x267) [0x562e642239a7]
61  /opt/conda/envs/gdf/bin/python(Py_BytesMain+0x37) [0x562e641f7107]
=================================
[dgx13:94947:0:94947] Caught signal 11 (Segmentation fault: address not mapped to object at address 0x450)
==== backtrace (tid:  94947) ====
 0  /opt/conda/envs/gdf/lib/libucs.so.0(ucs_handle_error+0x2fd) [0x7f4c74c4f6fd]
 1  /opt/conda/envs/gdf/lib/libucs.so.0(+0x2d8f4) [0x7f4c74c4f8f4]
 2  /opt/conda/envs/gdf/lib/libucs.so.0(+0x2daba) [0x7f4c74c4faba]
 3  /usr/lib/x86_64-linux-gnu/libpthread.so.0(+0x14420) [0x7f4d082c8420]
 4  /opt/conda/envs/gdf/lib/libucp.so.0(ucp_mem_type_unpack+0x17) [0x7f4c74cd28b7]
 5  /opt/conda/envs/gdf/lib/libucp.so.0(ucp_rndv_data_handler+0x65d) [0x7f4c74cfb3ed]
 6  /opt/conda/envs/gdf/lib/libuct.so.0(+0x2193f) [0x7f4c74c0693f]
 7  /opt/conda/envs/gdf/lib/libuct.so.0(+0x24b18) [0x7f4c74c09b18]
 8  /opt/conda/envs/gdf/lib/libucs.so.0(ucs_event_set_wait+0xb9) [0x7f4c74c58ff9]
 9  /opt/conda/envs/gdf/lib/libuct.so.0(uct_tcp_iface_progress+0x7d) [0x7f4c74c08c2d]
10  /opt/conda/envs/gdf/lib/libucp.so.0(ucp_worker_progress+0x5a) [0x7f4c74ccf7aa]
11  /opt/conda/envs/gdf/lib/python3.9/site-packages/ucp/_libs/ucx_api.cpython-39-x86_64-linux-gnu.so(+0x3206a) [0x7f4c74d8e06a]
12  /opt/conda/envs/gdf/bin/python(_PyEval_EvalFrameDefault+0x45a6) [0x5564bddb53f6]
13  /opt/conda/envs/gdf/bin/python(+0x12dfb4) [0x5564bddaffb4]
14  /opt/conda/envs/gdf/bin/python(_PyFunction_Vectorcall+0xd9) [0x5564bddc1469]
15  /opt/conda/envs/gdf/bin/python(_PyEval_EvalFrameDefault+0x696) [0x5564bddb14e6]
16  /opt/conda/envs/gdf/bin/python(+0x1e26d2) [0x5564bde646d2]
17  /opt/conda/envs/gdf/lib/python3.9/lib-dynload/_asyncio.cpython-39-x86_64-linux-gnu.so(+0x81e9) [0x7f4cfe29f1e9]
18  /opt/conda/envs/gdf/bin/python(_PyObject_MakeTpCall+0x2ec) [0x5564bddb96ac]
19  /opt/conda/envs/gdf/bin/python(+0xf23ff) [0x5564bdd743ff]
20  /opt/conda/envs/gdf/bin/python(+0x136723) [0x5564bddb8723]
21  /opt/conda/envs/gdf/bin/python(_PyEval_EvalFrameDefault+0x5ad9) [0x5564bddb6929]
22  /opt/conda/envs/gdf/bin/python(+0x13f712) [0x5564bddc1712]
23  /opt/conda/envs/gdf/bin/python(_PyEval_EvalFrameDefault+0x696) [0x5564bddb14e6]
24  /opt/conda/envs/gdf/bin/python(+0x13f712) [0x5564bddc1712]
25  /opt/conda/envs/gdf/bin/python(_PyEval_EvalFrameDefault+0x696) [0x5564bddb14e6]
26  /opt/conda/envs/gdf/bin/python(+0x13f712) [0x5564bddc1712]
27  /opt/conda/envs/gdf/bin/python(_PyEval_EvalFrameDefault+0x696) [0x5564bddb14e6]
28  /opt/conda/envs/gdf/bin/python(+0x13f712) [0x5564bddc1712]
29  /opt/conda/envs/gdf/bin/python(_PyEval_EvalFrameDefault+0x696) [0x5564bddb14e6]
30  /opt/conda/envs/gdf/bin/python(+0x12dfb4) [0x5564bddaffb4]
31  /opt/conda/envs/gdf/bin/python(_PyFunction_Vectorcall+0xd9) [0x5564bddc1469]
32  /opt/conda/envs/gdf/bin/python(_PyEval_EvalFrameDefault+0x11f2) [0x5564bddb2042]
33  /opt/conda/envs/gdf/bin/python(+0x12dfb4) [0x5564bddaffb4]
34  /opt/conda/envs/gdf/bin/python(+0x14c8cb) [0x5564bddce8cb]
35  /opt/conda/envs/gdf/bin/python(PyObject_Call+0xbc) [0x5564bddcf04c]
36  /opt/conda/envs/gdf/bin/python(+0x21080e) [0x5564bde9280e]
37  /opt/conda/envs/gdf/bin/python(_PyObject_MakeTpCall+0x2ec) [0x5564bddb96ac]
38  /opt/conda/envs/gdf/bin/python(_PyEval_EvalFrameDefault+0x45a6) [0x5564bddb53f6]
39  /opt/conda/envs/gdf/bin/python(+0x13f712) [0x5564bddc1712]
40  /opt/conda/envs/gdf/bin/python(+0x14c9ac) [0x5564bddce9ac]
41  /opt/conda/envs/gdf/bin/python(_PyEval_EvalFrameDefault+0x45a6) [0x5564bddb53f6]
42  /opt/conda/envs/gdf/bin/python(+0x13f712) [0x5564bddc1712]
43  /opt/conda/envs/gdf/bin/python(_PyEval_EvalFrameDefault+0x696) [0x5564bddb14e6]
44  /opt/conda/envs/gdf/bin/python(+0x12dfb4) [0x5564bddaffb4]
45  /opt/conda/envs/gdf/bin/python(_PyFunction_Vectorcall+0xd9) [0x5564bddc1469]
46  /opt/conda/envs/gdf/bin/python(_PyEval_EvalFrameDefault+0x696) [0x5564bddb14e6]
47  /opt/conda/envs/gdf/bin/python(+0x13f712) [0x5564bddc1712]
48  /opt/conda/envs/gdf/bin/python(_PyEval_EvalFrameDefault+0x3e2) [0x5564bddb1232]
49  /opt/conda/envs/gdf/bin/python(+0x12dfb4) [0x5564bddaffb4]
50  /opt/conda/envs/gdf/bin/python(_PyFunction_Vectorcall+0xd9) [0x5564bddc1469]
51  /opt/conda/envs/gdf/bin/python(_PyEval_EvalFrameDefault+0x11f2) [0x5564bddb2042]
52  /opt/conda/envs/gdf/bin/python(+0x12dfb4) [0x5564bddaffb4]
53  /opt/conda/envs/gdf/bin/python(_PyEval_EvalCodeWithName+0x48) [0x5564bddafc88]
54  /opt/conda/envs/gdf/bin/python(PyEval_EvalCodeEx+0x39) [0x5564bddafc39]
55  /opt/conda/envs/gdf/bin/python(PyEval_EvalCode+0x1b) [0x5564bde5d2cb]
56  /opt/conda/envs/gdf/bin/python(+0x2086ca) [0x5564bde8a6ca]
57  /opt/conda/envs/gdf/bin/python(+0x204a63) [0x5564bde86a63]
58  /opt/conda/envs/gdf/bin/python(PyRun_StringFlags+0x9a) [0x5564bde7e87a]
59  /opt/conda/envs/gdf/bin/python(PyRun_SimpleStringFlags+0x3c) [0x5564bde7e76c]
60  /opt/conda/envs/gdf/bin/python(Py_RunMain+0x267) [0x5564bde7d9a7]
61  /opt/conda/envs/gdf/bin/python(Py_BytesMain+0x37) [0x5564bde51107]
=================================
[dgx13:94917:0:94917] Caught signal 11 (Segmentation fault: address not mapped to object at address 0x450)
==== backtrace (tid:  94917) ====
 0  /opt/conda/envs/gdf/lib/libucs.so.0(ucs_handle_error+0x2fd) [0x7f51d519b6fd]
 1  /opt/conda/envs/gdf/lib/libucs.so.0(+0x2d8f4) [0x7f51d519b8f4]
 2  /opt/conda/envs/gdf/lib/libucs.so.0(+0x2daba) [0x7f51d519baba]
 3  /usr/lib/x86_64-linux-gnu/libpthread.so.0(+0x14420) [0x7f527a853420]
 4  /opt/conda/envs/gdf/lib/libucp.so.0(ucp_mem_type_unpack+0x17) [0x7f51d521e8b7]
 5  /opt/conda/envs/gdf/lib/libucp.so.0(ucp_rndv_data_handler+0x65d) [0x7f51d52473ed]
 6  /opt/conda/envs/gdf/lib/libuct.so.0(+0x2193f) [0x7f51d515293f]
 7  /opt/conda/envs/gdf/lib/libuct.so.0(+0x24b18) [0x7f51d5155b18]
 8  /opt/conda/envs/gdf/lib/libucs.so.0(ucs_event_set_wait+0xb9) [0x7f51d51a4ff9]
 9  /opt/conda/envs/gdf/lib/libuct.so.0(uct_tcp_iface_progress+0x7d) [0x7f51d5154c2d]
10  /opt/conda/envs/gdf/lib/libucp.so.0(ucp_worker_progress+0x5a) [0x7f51d521b7aa]
11  /opt/conda/envs/gdf/lib/python3.9/site-packages/ucp/_libs/ucx_api.cpython-39-x86_64-linux-gnu.so(+0x3206a) [0x7f51d52da06a]
12  /opt/conda/envs/gdf/bin/python(_PyEval_EvalFrameDefault+0x45a6) [0x55c52971a3f6]
13  /opt/conda/envs/gdf/bin/python(+0x12dfb4) [0x55c529714fb4]
14  /opt/conda/envs/gdf/bin/python(_PyFunction_Vectorcall+0xd9) [0x55c529726469]
15  /opt/conda/envs/gdf/bin/python(_PyEval_EvalFrameDefault+0x696) [0x55c5297164e6]
16  /opt/conda/envs/gdf/bin/python(+0x1e26d2) [0x55c5297c96d2]
17  /opt/conda/envs/gdf/lib/python3.9/lib-dynload/_asyncio.cpython-39-x86_64-linux-gnu.so(+0x81e9) [0x7f527081f1e9]
18  /opt/conda/envs/gdf/bin/python(_PyObject_MakeTpCall+0x2ec) [0x55c52971e6ac]
19  /opt/conda/envs/gdf/bin/python(+0xf23ff) [0x55c5296d93ff]
20  /opt/conda/envs/gdf/bin/python(+0x136723) [0x55c52971d723]
21  /opt/conda/envs/gdf/bin/python(_PyEval_EvalFrameDefault+0x5ad9) [0x55c52971b929]
22  /opt/conda/envs/gdf/bin/python(+0x13f712) [0x55c529726712]
23  /opt/conda/envs/gdf/bin/python(_PyEval_EvalFrameDefault+0x696) [0x55c5297164e6]
24  /opt/conda/envs/gdf/bin/python(+0x13f712) [0x55c529726712]
25  /opt/conda/envs/gdf/bin/python(_PyEval_EvalFrameDefault+0x696) [0x55c5297164e6]
26  /opt/conda/envs/gdf/bin/python(+0x13f712) [0x55c529726712]
27  /opt/conda/envs/gdf/bin/python(_PyEval_EvalFrameDefault+0x696) [0x55c5297164e6]
28  /opt/conda/envs/gdf/bin/python(+0x13f712) [0x55c529726712]
29  /opt/conda/envs/gdf/bin/python(_PyEval_EvalFrameDefault+0x696) [0x55c5297164e6]
30  /opt/conda/envs/gdf/bin/python(+0x12dfb4) [0x55c529714fb4]
31  /opt/conda/envs/gdf/bin/python(_PyFunction_Vectorcall+0xd9) [0x55c529726469]
32  /opt/conda/envs/gdf/bin/python(_PyEval_EvalFrameDefault+0x11f2) [0x55c529717042]
33  /opt/conda/envs/gdf/bin/python(+0x12dfb4) [0x55c529714fb4]
34  /opt/conda/envs/gdf/bin/python(+0x14c8cb) [0x55c5297338cb]
35  /opt/conda/envs/gdf/bin/python(PyObject_Call+0xbc) [0x55c52973404c]
36  /opt/conda/envs/gdf/bin/python(+0x21080e) [0x55c5297f780e]
37  /opt/conda/envs/gdf/bin/python(_PyObject_MakeTpCall+0x2ec) [0x55c52971e6ac]
38  /opt/conda/envs/gdf/bin/python(_PyEval_EvalFrameDefault+0x45a6) [0x55c52971a3f6]
39  /opt/conda/envs/gdf/bin/python(+0x13f712) [0x55c529726712]
40  /opt/conda/envs/gdf/bin/python(+0x14c9ac) [0x55c5297339ac]
41  /opt/conda/envs/gdf/bin/python(_PyEval_EvalFrameDefault+0x45a6) [0x55c52971a3f6]
42  /opt/conda/envs/gdf/bin/python(+0x13f712) [0x55c529726712]
43  /opt/conda/envs/gdf/bin/python(_PyEval_EvalFrameDefault+0x696) [0x55c5297164e6]
44  /opt/conda/envs/gdf/bin/python(+0x12dfb4) [0x55c529714fb4]
45  /opt/conda/envs/gdf/bin/python(_PyFunction_Vectorcall+0xd9) [0x55c529726469]
46  /opt/conda/envs/gdf/bin/python(_PyEval_EvalFrameDefault+0x696) [0x55c5297164e6]
47  /opt/conda/envs/gdf/bin/python(+0x13f712) [0x55c529726712]
48  /opt/conda/envs/gdf/bin/python(_PyEval_EvalFrameDefault+0x3e2) [0x55c529716232]
49  /opt/conda/envs/gdf/bin/python(+0x12dfb4) [0x55c529714fb4]
50  /opt/conda/envs/gdf/bin/python(_PyFunction_Vectorcall+0xd9) [0x55c529726469]
51  /opt/conda/envs/gdf/bin/python(_PyEval_EvalFrameDefault+0x11f2) [0x55c529717042]
52  /opt/conda/envs/gdf/bin/python(+0x12dfb4) [0x55c529714fb4]
53  /opt/conda/envs/gdf/bin/python(_PyEval_EvalCodeWithName+0x48) [0x55c529714c88]
54  /opt/conda/envs/gdf/bin/python(PyEval_EvalCodeEx+0x39) [0x55c529714c39]
55  /opt/conda/envs/gdf/bin/python(PyEval_EvalCode+0x1b) [0x55c5297c22cb]
56  /opt/conda/envs/gdf/bin/python(+0x2086ca) [0x55c5297ef6ca]
57  /opt/conda/envs/gdf/bin/python(+0x204a63) [0x55c5297eba63]
58  /opt/conda/envs/gdf/bin/python(PyRun_StringFlags+0x9a) [0x55c5297e387a]
59  /opt/conda/envs/gdf/bin/python(PyRun_SimpleStringFlags+0x3c) [0x55c5297e376c]
60  /opt/conda/envs/gdf/bin/python(Py_RunMain+0x267) [0x55c5297e29a7]
61  /opt/conda/envs/gdf/bin/python(Py_BytesMain+0x37) [0x55c5297b6107]
=================================
[dgx13:94935:0:94935] Caught signal 11 (Segmentation fault: address not mapped to object at address 0x450)
==== backtrace (tid:  94935) ====
 0  /opt/conda/envs/gdf/lib/libucs.so.0(ucs_handle_error+0x2fd) [0x7ff02c0676fd]
 1  /opt/conda/envs/gdf/lib/libucs.so.0(+0x2d8f4) [0x7ff02c0678f4]
 2  /opt/conda/envs/gdf/lib/libucs.so.0(+0x2daba) [0x7ff02c067aba]
 3  /usr/lib/x86_64-linux-gnu/libpthread.so.0(+0x14420) [0x7ff0be888420]
 4  /opt/conda/envs/gdf/lib/libucp.so.0(ucp_mem_type_unpack+0x17) [0x7ff01935c8b7]
 5  /opt/conda/envs/gdf/lib/libucp.so.0(ucp_rndv_data_handler+0x65d) [0x7ff0193853ed]
 6  /opt/conda/envs/gdf/lib/libuct.so.0(+0x2193f) [0x7ff0192f493f]
 7  /opt/conda/envs/gdf/lib/libuct.so.0(+0x24b18) [0x7ff0192f7b18]
 8  /opt/conda/envs/gdf/lib/libucs.so.0(ucs_event_set_wait+0xb9) [0x7ff02c070ff9]
 9  /opt/conda/envs/gdf/lib/libuct.so.0(uct_tcp_iface_progress+0x7d) [0x7ff0192f6c2d]
10  /opt/conda/envs/gdf/lib/libucp.so.0(ucp_worker_progress+0x5a) [0x7ff0193597aa]
11  /opt/conda/envs/gdf/lib/python3.9/site-packages/ucp/_libs/ucx_api.cpython-39-x86_64-linux-gnu.so(+0x3206a) [0x7ff01941806a]
12  /opt/conda/envs/gdf/bin/python(_PyEval_EvalFrameDefault+0x45a6) [0x55b0af2403f6]
13  /opt/conda/envs/gdf/bin/python(+0x12dfb4) [0x55b0af23afb4]
14  /opt/conda/envs/gdf/bin/python(_PyFunction_Vectorcall+0xd9) [0x55b0af24c469]
15  /opt/conda/envs/gdf/bin/python(_PyEval_EvalFrameDefault+0x696) [0x55b0af23c4e6]
16  /opt/conda/envs/gdf/bin/python(+0x1e26d2) [0x55b0af2ef6d2]
17  /opt/conda/envs/gdf/lib/python3.9/lib-dynload/_asyncio.cpython-39-x86_64-linux-gnu.so(+0x81e9) [0x7ff0b485f1e9]
18  /opt/conda/envs/gdf/bin/python(_PyObject_MakeTpCall+0x2ec) [0x55b0af2446ac]
19  /opt/conda/envs/gdf/bin/python(+0xf23ff) [0x55b0af1ff3ff]
20  /opt/conda/envs/gdf/bin/python(+0x136723) [0x55b0af243723]
21  /opt/conda/envs/gdf/bin/python(_PyEval_EvalFrameDefault+0x5ad9) [0x55b0af241929]
22  /opt/conda/envs/gdf/bin/python(+0x13f712) [0x55b0af24c712]
23  /opt/conda/envs/gdf/bin/python(_PyEval_EvalFrameDefault+0x696) [0x55b0af23c4e6]
24  /opt/conda/envs/gdf/bin/python(+0x13f712) [0x55b0af24c712]
25  /opt/conda/envs/gdf/bin/python(_PyEval_EvalFrameDefault+0x696) [0x55b0af23c4e6]
26  /opt/conda/envs/gdf/bin/python(+0x13f712) [0x55b0af24c712]
27  /opt/conda/envs/gdf/bin/python(_PyEval_EvalFrameDefault+0x696) [0x55b0af23c4e6]
28  /opt/conda/envs/gdf/bin/python(+0x13f712) [0x55b0af24c712]
29  /opt/conda/envs/gdf/bin/python(_PyEval_EvalFrameDefault+0x696) [0x55b0af23c4e6]
30  /opt/conda/envs/gdf/bin/python(+0x12dfb4) [0x55b0af23afb4]
31  /opt/conda/envs/gdf/bin/python(_PyFunction_Vectorcall+0xd9) [0x55b0af24c469]
32  /opt/conda/envs/gdf/bin/python(_PyEval_EvalFrameDefault+0x11f2) [0x55b0af23d042]
33  /opt/conda/envs/gdf/bin/python(+0x12dfb4) [0x55b0af23afb4]
34  /opt/conda/envs/gdf/bin/python(+0x14c8cb) [0x55b0af2598cb]
35  /opt/conda/envs/gdf/bin/python(PyObject_Call+0xbc) [0x55b0af25a04c]
36  /opt/conda/envs/gdf/bin/python(+0x21080e) [0x55b0af31d80e]
37  /opt/conda/envs/gdf/bin/python(_PyObject_MakeTpCall+0x2ec) [0x55b0af2446ac]
38  /opt/conda/envs/gdf/bin/python(_PyEval_EvalFrameDefault+0x45a6) [0x55b0af2403f6]
39  /opt/conda/envs/gdf/bin/python(+0x13f712) [0x55b0af24c712]
40  /opt/conda/envs/gdf/bin/python(+0x14c9ac) [0x55b0af2599ac]
41  /opt/conda/envs/gdf/bin/python(_PyEval_EvalFrameDefault+0x45a6) [0x55b0af2403f6]
42  /opt/conda/envs/gdf/bin/python(+0x13f712) [0x55b0af24c712]
43  /opt/conda/envs/gdf/bin/python(_PyEval_EvalFrameDefault+0x696) [0x55b0af23c4e6]
44  /opt/conda/envs/gdf/bin/python(+0x12dfb4) [0x55b0af23afb4]
45  /opt/conda/envs/gdf/bin/python(_PyFunction_Vectorcall+0xd9) [0x55b0af24c469]
46  /opt/conda/envs/gdf/bin/python(_PyEval_EvalFrameDefault+0x696) [0x55b0af23c4e6]
47  /opt/conda/envs/gdf/bin/python(+0x13f712) [0x55b0af24c712]
48  /opt/conda/envs/gdf/bin/python(_PyEval_EvalFrameDefault+0x3e2) [0x55b0af23c232]
49  /opt/conda/envs/gdf/bin/python(+0x12dfb4) [0x55b0af23afb4]
50  /opt/conda/envs/gdf/bin/python(_PyFunction_Vectorcall+0xd9) [0x55b0af24c469]
51  /opt/conda/envs/gdf/bin/python(_PyEval_EvalFrameDefault+0x11f2) [0x55b0af23d042]
52  /opt/conda/envs/gdf/bin/python(+0x12dfb4) [0x55b0af23afb4]
53  /opt/conda/envs/gdf/bin/python(_PyEval_EvalCodeWithName+0x48) [0x55b0af23ac88]
54  /opt/conda/envs/gdf/bin/python(PyEval_EvalCodeEx+0x39) [0x55b0af23ac39]
55  /opt/conda/envs/gdf/bin/python(PyEval_EvalCode+0x1b) [0x55b0af2e82cb]
56  /opt/conda/envs/gdf/bin/python(+0x2086ca) [0x55b0af3156ca]
57  /opt/conda/envs/gdf/bin/python(+0x204a63) [0x55b0af311a63]
58  /opt/conda/envs/gdf/bin/python(PyRun_StringFlags+0x9a) [0x55b0af30987a]
59  /opt/conda/envs/gdf/bin/python(PyRun_SimpleStringFlags+0x3c) [0x55b0af30976c]
60  /opt/conda/envs/gdf/bin/python(Py_RunMain+0x267) [0x55b0af3089a7]
61  /opt/conda/envs/gdf/bin/python(Py_BytesMain+0x37) [0x55b0af2dc107]
=================================
[dgx13:94931:0:94931] Caught signal 11 (Segmentation fault: address not mapped to object at address 0x450)
==== backtrace (tid:  94931) ====
 0  /opt/conda/envs/gdf/lib/libucs.so.0(ucs_handle_error+0x2fd) [0x7f5a69a7d6fd]
 1  /opt/conda/envs/gdf/lib/libucs.so.0(+0x2d8f4) [0x7f5a69a7d8f4]
 2  /opt/conda/envs/gdf/lib/libucs.so.0(+0x2daba) [0x7f5a69a7daba]
 3  /usr/lib/x86_64-linux-gnu/libpthread.so.0(+0x14420) [0x7f5b0ef8c420]
 4  /opt/conda/envs/gdf/lib/libucp.so.0(ucp_mem_type_unpack+0x17) [0x7f5a69b008b7]
 5  /opt/conda/envs/gdf/lib/libucp.so.0(ucp_rndv_data_handler+0x65d) [0x7f5a69b293ed]
 6  /opt/conda/envs/gdf/lib/libuct.so.0(+0x2193f) [0x7f5a69a3493f]
 7  /opt/conda/envs/gdf/lib/libuct.so.0(+0x24b18) [0x7f5a69a37b18]
 8  /opt/conda/envs/gdf/lib/libucs.so.0(ucs_event_set_wait+0xb9) [0x7f5a69a86ff9]
 9  /opt/conda/envs/gdf/lib/libuct.so.0(uct_tcp_iface_progress+0x7d) [0x7f5a69a36c2d]
10  /opt/conda/envs/gdf/lib/libucp.so.0(ucp_worker_progress+0x5a) [0x7f5a69afd7aa]
11  /opt/conda/envs/gdf/lib/python3.9/site-packages/ucp/_libs/ucx_api.cpython-39-x86_64-linux-gnu.so(+0x3206a) [0x7f5a69bbc06a]
12  /opt/conda/envs/gdf/bin/python(_PyEval_EvalFrameDefault+0x45a6) [0x55a8383243f6]
13  /opt/conda/envs/gdf/bin/python(+0x12dfb4) [0x55a83831efb4]
14  /opt/conda/envs/gdf/bin/python(_PyFunction_Vectorcall+0xd9) [0x55a838330469]
15  /opt/conda/envs/gdf/bin/python(_PyEval_EvalFrameDefault+0x696) [0x55a8383204e6]
16  /opt/conda/envs/gdf/bin/python(+0x1e26d2) [0x55a8383d36d2]
17  /opt/conda/envs/gdf/lib/python3.9/lib-dynload/_asyncio.cpython-39-x86_64-linux-gnu.so(+0x81e9) [0x7f5b04f501e9]
18  /opt/conda/envs/gdf/bin/python(_PyObject_MakeTpCall+0x2ec) [0x55a8383286ac]
19  /opt/conda/envs/gdf/bin/python(+0xf23ff) [0x55a8382e33ff]
20  /opt/conda/envs/gdf/bin/python(+0x136723) [0x55a838327723]
21  /opt/conda/envs/gdf/bin/python(_PyEval_EvalFrameDefault+0x5ad9) [0x55a838325929]
22  /opt/conda/envs/gdf/bin/python(+0x13f712) [0x55a838330712]
23  /opt/conda/envs/gdf/bin/python(_PyEval_EvalFrameDefault+0x696) [0x55a8383204e6]
24  /opt/conda/envs/gdf/bin/python(+0x13f712) [0x55a838330712]
25  /opt/conda/envs/gdf/bin/python(_PyEval_EvalFrameDefault+0x696) [0x55a8383204e6]
26  /opt/conda/envs/gdf/bin/python(+0x13f712) [0x55a838330712]
27  /opt/conda/envs/gdf/bin/python(_PyEval_EvalFrameDefault+0x696) [0x55a8383204e6]
28  /opt/conda/envs/gdf/bin/python(+0x13f712) [0x55a838330712]
29  /opt/conda/envs/gdf/bin/python(_PyEval_EvalFrameDefault+0x696) [0x55a8383204e6]
30  /opt/conda/envs/gdf/bin/python(+0x12dfb4) [0x55a83831efb4]
31  /opt/conda/envs/gdf/bin/python(_PyFunction_Vectorcall+0xd9) [0x55a838330469]
32  /opt/conda/envs/gdf/bin/python(_PyEval_EvalFrameDefault+0x11f2) [0x55a838321042]
33  /opt/conda/envs/gdf/bin/python(+0x12dfb4) [0x55a83831efb4]
34  /opt/conda/envs/gdf/bin/python(+0x14c8cb) [0x55a83833d8cb]
35  /opt/conda/envs/gdf/bin/python(PyObject_Call+0xbc) [0x55a83833e04c]
36  /opt/conda/envs/gdf/bin/python(+0x21080e) [0x55a83840180e]
37  /opt/conda/envs/gdf/bin/python(_PyObject_MakeTpCall+0x2ec) [0x55a8383286ac]
38  /opt/conda/envs/gdf/bin/python(_PyEval_EvalFrameDefault+0x45a6) [0x55a8383243f6]
39  /opt/conda/envs/gdf/bin/python(+0x13f712) [0x55a838330712]
40  /opt/conda/envs/gdf/bin/python(+0x14c9ac) [0x55a83833d9ac]
41  /opt/conda/envs/gdf/bin/python(_PyEval_EvalFrameDefault+0x45a6) [0x55a8383243f6]
42  /opt/conda/envs/gdf/bin/python(+0x13f712) [0x55a838330712]
43  /opt/conda/envs/gdf/bin/python(_PyEval_EvalFrameDefault+0x696) [0x55a8383204e6]
44  /opt/conda/envs/gdf/bin/python(+0x12dfb4) [0x55a83831efb4]
45  /opt/conda/envs/gdf/bin/python(_PyFunction_Vectorcall+0xd9) [0x55a838330469]
46  /opt/conda/envs/gdf/bin/python(_PyEval_EvalFrameDefault+0x696) [0x55a8383204e6]
47  /opt/conda/envs/gdf/bin/python(+0x13f712) [0x55a838330712]
48  /opt/conda/envs/gdf/bin/python(_PyEval_EvalFrameDefault+0x3e2) [0x55a838320232]
49  /opt/conda/envs/gdf/bin/python(+0x12dfb4) [0x55a83831efb4]
50  /opt/conda/envs/gdf/bin/python(_PyFunction_Vectorcall+0xd9) [0x55a838330469]
51  /opt/conda/envs/gdf/bin/python(_PyEval_EvalFrameDefault+0x11f2) [0x55a838321042]
52  /opt/conda/envs/gdf/bin/python(+0x12dfb4) [0x55a83831efb4]
53  /opt/conda/envs/gdf/bin/python(_PyEval_EvalCodeWithName+0x48) [0x55a83831ec88]
54  /opt/conda/envs/gdf/bin/python(PyEval_EvalCodeEx+0x39) [0x55a83831ec39]
55  /opt/conda/envs/gdf/bin/python(PyEval_EvalCode+0x1b) [0x55a8383cc2cb]
56  /opt/conda/envs/gdf/bin/python(+0x2086ca) [0x55a8383f96ca]
57  /opt/conda/envs/gdf/bin/python(+0x204a63) [0x55a8383f5a63]
58  /opt/conda/envs/gdf/bin/python(PyRun_StringFlags+0x9a) [0x55a8383ed87a]
59  /opt/conda/envs/gdf/bin/python(PyRun_SimpleStringFlags+0x3c) [0x55a8383ed76c]
60  /opt/conda/envs/gdf/bin/python(Py_RunMain+0x267) [0x55a8383ec9a7]
61  /opt/conda/envs/gdf/bin/python(Py_BytesMain+0x37) [0x55a8383c0107]
=================================
2024-01-17 07:11:51,771 - distributed.worker - ERROR - failed during get data with ucx://127.0.0.1:35705 -> ucx://127.0.0.1:55823
Traceback (most recent call last):
  File "/opt/conda/envs/gdf/lib/python3.9/site-packages/distributed/comm/ucx.py", line 350, in read
    await self.ep.recv(msg)
  File "/opt/conda/envs/gdf/lib/python3.9/site-packages/ucp/core.py", line 737, in recv
    ret = await comm.tag_recv(self._ep, buffer, nbytes, tag, name=log)
ucp._libs.exceptions.UCXCanceled: <[Recv #006] ep: 0x7f8d72a23300, tag: 0x53bd36911b2fc770, nbytes: 16, type: <class 'numpy.ndarray'>>: 

During handling of the above exception, another exception occurred:

Traceback (most recent call last):
  File "/opt/conda/envs/gdf/lib/python3.9/site-packages/distributed/worker.py", line 1780, in get_data
    response = await comm.read(deserializers=serializers)
  File "/opt/conda/envs/gdf/lib/python3.9/site-packages/distributed/utils.py", line 832, in wrapper
    return await func(*args, **kwargs)
  File "/opt/conda/envs/gdf/lib/python3.9/site-packages/distributed/comm/ucx.py", line 368, in read
    raise CommClosedError(
distributed.comm.core.CommClosedError: Connection closed by writer.
Inner exception: UCXCanceled("<[Recv #006] ep: 0x7f8d72a23300, tag: 0x53bd36911b2fc770, nbytes: 16, type: <class 'numpy.ndarray'>>: ")
Task exception was never retrieved
future: <Task finished name='Task-324' coro=<_listener_handler_coroutine() done, defined at /opt/conda/envs/gdf/lib/python3.9/site-packages/ucp/core.py:140> exception=UCXError('<stream_recv>: Connection reset by remote peer')>
Traceback (most recent call last):
  File "/opt/conda/envs/gdf/lib/python3.9/site-packages/ucp/core.py", line 155, in _listener_handler_coroutine
    peer_info = await exchange_peer_info(
  File "/opt/conda/envs/gdf/lib/python3.9/site-packages/ucp/core.py", line 55, in exchange_peer_info
    await asyncio.wait_for(
  File "/opt/conda/envs/gdf/lib/python3.9/asyncio/tasks.py", line 479, in wait_for
    return fut.result()
ucp._libs.exceptions.UCXError: <stream_recv>: Connection reset by remote peer
2024-01-17 07:11:51,772 - distributed.worker - ERROR - failed during get data with ucx://127.0.0.1:48753 -> ucx://127.0.0.1:55823
Traceback (most recent call last):
  File "/opt/conda/envs/gdf/lib/python3.9/site-packages/distributed/comm/ucx.py", line 334, in write
    await self.ep.send(each_frame)
  File "/opt/conda/envs/gdf/lib/python3.9/site-packages/ucp/core.py", line 662, in send
    return await comm.tag_send(self._ep, buffer, nbytes, tag, name=log)
ucp._libs.exceptions.UCXError: <[Send #007] ep: 0x7f773cfe4300, tag: 0x7af2d37b83feab73, nbytes: 50000000, type: <class 'cupy.ndarray'>>: Connection reset by remote peer

During handling of the above exception, another exception occurred:

Traceback (most recent call last):
  File "/opt/conda/envs/gdf/lib/python3.9/site-packages/distributed/worker.py", line 1779, in get_data
    compressed = await comm.write(msg, serializers=serializers)
  File "/opt/conda/envs/gdf/lib/python3.9/site-packages/distributed/utils.py", line 832, in wrapper
    return await func(*args, **kwargs)
  File "/opt/conda/envs/gdf/lib/python3.9/site-packages/distributed/comm/ucx.py", line 338, in write
    raise CommClosedError("While writing, the connection was closed")
distributed.comm.core.CommClosedError: While writing, the connection was closed
2024-01-17 07:11:51,776 - distributed.worker - ERROR - Worker stream died during communication: ucx://127.0.0.1:55823
Traceback (most recent call last):
  File "/opt/conda/envs/gdf/lib/python3.9/site-packages/distributed/comm/ucx.py", line 350, in read
    await self.ep.recv(msg)
  File "/opt/conda/envs/gdf/lib/python3.9/site-packages/ucp/core.py", line 737, in recv
    ret = await comm.tag_recv(self._ep, buffer, nbytes, tag, name=log)
ucp._libs.exceptions.UCXCanceled: <[Recv #000] ep: 0x7f773cfe41c0, tag: 0x44f8a3f58889d46a, nbytes: 16, type: <class 'numpy.ndarray'>>: 

During handling of the above exception, another exception occurred:

Traceback (most recent call last):
  File "/opt/conda/envs/gdf/lib/python3.9/site-packages/distributed/worker.py", line 2056, in gather_dep
    response = await get_data_from_worker(
  File "/opt/conda/envs/gdf/lib/python3.9/site-packages/distributed/worker.py", line 2857, in get_data_from_worker
    comm = await rpc.connect(worker)
  File "/opt/conda/envs/gdf/lib/python3.9/site-packages/distributed/core.py", line 1674, in connect
    return connect_attempt.result()
  File "/opt/conda/envs/gdf/lib/python3.9/site-packages/distributed/core.py", line 1564, in _connect
    comm = await connect(
  File "/opt/conda/envs/gdf/lib/python3.9/site-packages/distributed/comm/core.py", line 377, in connect
    handshake = await comm.read()
  File "/opt/conda/envs/gdf/lib/python3.9/site-packages/distributed/utils.py", line 832, in wrapper
    return await func(*args, **kwargs)
  File "/opt/conda/envs/gdf/lib/python3.9/site-packages/distributed/comm/ucx.py", line 368, in read
    raise CommClosedError(
distributed.comm.core.CommClosedError: Connection closed by writer.
Inner exception: UCXCanceled("<[Recv #000] ep: 0x7f773cfe41c0, tag: 0x44f8a3f58889d46a, nbytes: 16, type: <class 'numpy.ndarray'>>: ")
2024-01-17 07:11:51,777 - distributed.worker - ERROR - Worker stream died during communication: ucx://127.0.0.1:55823
Traceback (most recent call last):
  File "/opt/conda/envs/gdf/lib/python3.9/site-packages/distributed/core.py", line 1564, in _connect
    comm = await connect(
  File "/opt/conda/envs/gdf/lib/python3.9/site-packages/distributed/comm/core.py", line 342, in connect
    comm = await wait_for(
  File "/opt/conda/envs/gdf/lib/python3.9/site-packages/distributed/utils.py", line 1940, in wait_for
    return await asyncio.wait_for(fut, timeout)
  File "/opt/conda/envs/gdf/lib/python3.9/asyncio/tasks.py", line 466, in wait_for
    await waiter
asyncio.exceptions.CancelledError

During handling of the above exception, another exception occurred:

Traceback (most recent call last):
  File "/opt/conda/envs/gdf/lib/python3.9/site-packages/distributed/core.py", line 1674, in connect
    return connect_attempt.result()
asyncio.exceptions.CancelledError

During handling of the above exception, another exception occurred:

Traceback (most recent call last):
  File "/opt/conda/envs/gdf/lib/python3.9/site-packages/distributed/worker.py", line 2056, in gather_dep
    response = await get_data_from_worker(
  File "/opt/conda/envs/gdf/lib/python3.9/site-packages/distributed/worker.py", line 2857, in get_data_from_worker
    comm = await rpc.connect(worker)
  File "/opt/conda/envs/gdf/lib/python3.9/site-packages/distributed/core.py", line 1676, in connect
    raise CommClosedError(reason)
distributed.comm.core.CommClosedError: Address removed.
2024-01-17 07:11:51,777 - distributed.worker - ERROR - Worker stream died during communication: ucx://127.0.0.1:55823
Traceback (most recent call last):
  File "/opt/conda/envs/gdf/lib/python3.9/site-packages/distributed/comm/ucx.py", line 467, in connect
    ep = await ucp.create_endpoint(ip, port)
  File "/opt/conda/envs/gdf/lib/python3.9/site-packages/ucp/core.py", line 1016, in create_endpoint
    return await _get_ctx().create_endpoint(
  File "/opt/conda/envs/gdf/lib/python3.9/site-packages/ucp/core.py", line 328, in create_endpoint
    peer_info = await exchange_peer_info(
  File "/opt/conda/envs/gdf/lib/python3.9/site-packages/ucp/core.py", line 60, in exchange_peer_info
    await asyncio.wait_for(
  File "/opt/conda/envs/gdf/lib/python3.9/asyncio/tasks.py", line 479, in wait_for
    return fut.result()
ucp._libs.exceptions.UCXError: <stream_recv>: Connection reset by remote peer

During handling of the above exception, another exception occurred:

Traceback (most recent call last):
  File "/opt/conda/envs/gdf/lib/python3.9/site-packages/distributed/comm/core.py", line 342, in connect
    comm = await wait_for(
  File "/opt/conda/envs/gdf/lib/python3.9/site-packages/distributed/utils.py", line 1940, in wait_for
    return await asyncio.wait_for(fut, timeout)
  File "/opt/conda/envs/gdf/lib/python3.9/asyncio/tasks.py", line 479, in wait_for
    return fut.result()
  File "/opt/conda/envs/gdf/lib/python3.9/site-packages/distributed/comm/ucx.py", line 469, in connect
    raise CommClosedError("Connection closed before handshake completed")
distributed.comm.core.CommClosedError: Connection closed before handshake completed

During handling of the above exception, another exception occurred:

Traceback (most recent call last):
  File "/opt/conda/envs/gdf/lib/python3.9/site-packages/distributed/core.py", line 1564, in _connect
    comm = await connect(
  File "/opt/conda/envs/gdf/lib/python3.9/site-packages/distributed/comm/core.py", line 366, in connect
    await asyncio.sleep(backoff)
  File "/opt/conda/envs/gdf/lib/python3.9/asyncio/tasks.py", line 652, in sleep
    return await future
asyncio.exceptions.CancelledError

During handling of the above exception, another exception occurred:

Traceback (most recent call last):
  File "/opt/conda/envs/gdf/lib/python3.9/site-packages/distributed/core.py", line 1674, in connect
    return connect_attempt.result()
asyncio.exceptions.CancelledError

During handling of the above exception, another exception occurred:

Traceback (most recent call last):
  File "/opt/conda/envs/gdf/lib/python3.9/site-packages/distributed/worker.py", line 2056, in gather_dep
    response = await get_data_from_worker(
  File "/opt/conda/envs/gdf/lib/python3.9/site-packages/distributed/worker.py", line 2857, in get_data_from_worker
    comm = await rpc.connect(worker)
  File "/opt/conda/envs/gdf/lib/python3.9/site-packages/distributed/core.py", line 1676, in connect
    raise CommClosedError(reason)
distributed.comm.core.CommClosedError: Address removed.
2024-01-17 07:11:51,784 - distributed.worker - ERROR - Worker stream died during communication: ucx://127.0.0.1:45955
Traceback (most recent call last):
  File "/opt/conda/envs/gdf/lib/python3.9/site-packages/distributed/core.py", line 1564, in _connect
    comm = await connect(
  File "/opt/conda/envs/gdf/lib/python3.9/site-packages/distributed/comm/core.py", line 342, in connect
    comm = await wait_for(
  File "/opt/conda/envs/gdf/lib/python3.9/site-packages/distributed/utils.py", line 1940, in wait_for
    return await asyncio.wait_for(fut, timeout)
  File "/opt/conda/envs/gdf/lib/python3.9/asyncio/tasks.py", line 466, in wait_for
    await waiter
asyncio.exceptions.CancelledError

During handling of the above exception, another exception occurred:

Traceback (most recent call last):
  File "/opt/conda/envs/gdf/lib/python3.9/site-packages/distributed/core.py", line 1674, in connect
    return connect_attempt.result()
asyncio.exceptions.CancelledError

During handling of the above exception, another exception occurred:

Traceback (most recent call last):
  File "/opt/conda/envs/gdf/lib/python3.9/site-packages/distributed/worker.py", line 2056, in gather_dep
    response = await get_data_from_worker(
  File "/opt/conda/envs/gdf/lib/python3.9/site-packages/distributed/worker.py", line 2857, in get_data_from_worker
    comm = await rpc.connect(worker)
  File "/opt/conda/envs/gdf/lib/python3.9/site-packages/distributed/core.py", line 1676, in connect
    raise CommClosedError(reason)
distributed.comm.core.CommClosedError: Address removed.
2024-01-17 07:11:51,784 - distributed.worker - ERROR - Worker stream died during communication: ucx://127.0.0.1:45955
Traceback (most recent call last):
  File "/opt/conda/envs/gdf/lib/python3.9/site-packages/distributed/core.py", line 1564, in _connect
    comm = await connect(
  File "/opt/conda/envs/gdf/lib/python3.9/site-packages/distributed/comm/core.py", line 342, in connect
    comm = await wait_for(
  File "/opt/conda/envs/gdf/lib/python3.9/site-packages/distributed/utils.py", line 1940, in wait_for
    return await asyncio.wait_for(fut, timeout)
  File "/opt/conda/envs/gdf/lib/python3.9/asyncio/tasks.py", line 466, in wait_for
    await waiter
asyncio.exceptions.CancelledError

During handling of the above exception, another exception occurred:

Traceback (most recent call last):
  File "/opt/conda/envs/gdf/lib/python3.9/site-packages/distributed/core.py", line 1674, in connect
    return connect_attempt.result()
asyncio.exceptions.CancelledError

During handling of the above exception, another exception occurred:

Traceback (most recent call last):
  File "/opt/conda/envs/gdf/lib/python3.9/site-packages/distributed/worker.py", line 2056, in gather_dep
    response = await get_data_from_worker(
  File "/opt/conda/envs/gdf/lib/python3.9/site-packages/distributed/worker.py", line 2857, in get_data_from_worker
    comm = await rpc.connect(worker)
  File "/opt/conda/envs/gdf/lib/python3.9/site-packages/distributed/core.py", line 1676, in connect
    raise CommClosedError(reason)
distributed.comm.core.CommClosedError: Address removed.
2024-01-17 07:11:51,784 - distributed.worker - ERROR - Worker stream died during communication: ucx://127.0.0.1:45955
Traceback (most recent call last):
  File "/opt/conda/envs/gdf/lib/python3.9/site-packages/distributed/comm/ucx.py", line 467, in connect
    ep = await ucp.create_endpoint(ip, port)
  File "/opt/conda/envs/gdf/lib/python3.9/site-packages/ucp/core.py", line 1016, in create_endpoint
    return await _get_ctx().create_endpoint(
  File "/opt/conda/envs/gdf/lib/python3.9/site-packages/ucp/core.py", line 328, in create_endpoint
    peer_info = await exchange_peer_info(
  File "/opt/conda/envs/gdf/lib/python3.9/site-packages/ucp/core.py", line 60, in exchange_peer_info
    await asyncio.wait_for(
  File "/opt/conda/envs/gdf/lib/python3.9/asyncio/tasks.py", line 479, in wait_for
    return fut.result()
ucp._libs.exceptions.UCXError: <stream_recv>: Connection reset by remote peer

During handling of the above exception, another exception occurred:

Traceback (most recent call last):
  File "/opt/conda/envs/gdf/lib/python3.9/site-packages/distributed/comm/core.py", line 342, in connect
    comm = await wait_for(
  File "/opt/conda/envs/gdf/lib/python3.9/site-packages/distributed/utils.py", line 1940, in wait_for
    return await asyncio.wait_for(fut, timeout)
  File "/opt/conda/envs/gdf/lib/python3.9/asyncio/tasks.py", line 479, in wait_for
    return fut.result()
  File "/opt/conda/envs/gdf/lib/python3.9/site-packages/distributed/comm/ucx.py", line 469, in connect
    raise CommClosedError("Connection closed before handshake completed")
distributed.comm.core.CommClosedError: Connection closed before handshake completed

During handling of the above exception, another exception occurred:

Traceback (most recent call last):
  File "/opt/conda/envs/gdf/lib/python3.9/site-packages/distributed/core.py", line 1564, in _connect
    comm = await connect(
  File "/opt/conda/envs/gdf/lib/python3.9/site-packages/distributed/comm/core.py", line 366, in connect
    await asyncio.sleep(backoff)
  File "/opt/conda/envs/gdf/lib/python3.9/asyncio/tasks.py", line 652, in sleep
    return await future
asyncio.exceptions.CancelledError

During handling of the above exception, another exception occurred:

Traceback (most recent call last):
  File "/opt/conda/envs/gdf/lib/python3.9/site-packages/distributed/core.py", line 1674, in connect
    return connect_attempt.result()
asyncio.exceptions.CancelledError

During handling of the above exception, another exception occurred:

Traceback (most recent call last):
  File "/opt/conda/envs/gdf/lib/python3.9/site-packages/distributed/worker.py", line 2056, in gather_dep
    response = await get_data_from_worker(
  File "/opt/conda/envs/gdf/lib/python3.9/site-packages/distributed/worker.py", line 2857, in get_data_from_worker
    comm = await rpc.connect(worker)
  File "/opt/conda/envs/gdf/lib/python3.9/site-packages/distributed/core.py", line 1676, in connect
    raise CommClosedError(reason)
distributed.comm.core.CommClosedError: Address removed.
2024-01-17 07:11:51,909 - distributed.worker - ERROR - failed during get data with ucx://127.0.0.1:35705 -> ucx://127.0.0.1:54715
Traceback (most recent call last):
  File "/opt/conda/envs/gdf/lib/python3.9/site-packages/distributed/comm/ucx.py", line 334, in write
    await self.ep.send(each_frame)
  File "/opt/conda/envs/gdf/lib/python3.9/site-packages/ucp/core.py", line 662, in send
    return await comm.tag_send(self._ep, buffer, nbytes, tag, name=log)
ucp._libs.exceptions.UCXError: <[Send #007] ep: 0x7f8d72a23340, tag: 0x25d668d233f4a176, nbytes: 50000000, type: <class 'cupy.ndarray'>>: Connection reset by remote peer

During handling of the above exception, another exception occurred:

Traceback (most recent call last):
  File "/opt/conda/envs/gdf/lib/python3.9/site-packages/distributed/worker.py", line 1779, in get_data
    compressed = await comm.write(msg, serializers=serializers)
  File "/opt/conda/envs/gdf/lib/python3.9/site-packages/distributed/utils.py", line 832, in wrapper
    return await func(*args, **kwargs)
  File "/opt/conda/envs/gdf/lib/python3.9/site-packages/distributed/comm/ucx.py", line 338, in write
    raise CommClosedError("While writing, the connection was closed")
distributed.comm.core.CommClosedError: While writing, the connection was closed
2024-01-17 07:11:51,909 - distributed.worker - ERROR - Worker stream died during communication: ucx://127.0.0.1:54715
Traceback (most recent call last):
  File "/opt/conda/envs/gdf/lib/python3.9/site-packages/distributed/comm/ucx.py", line 350, in read
    await self.ep.recv(msg)
  File "/opt/conda/envs/gdf/lib/python3.9/site-packages/ucp/core.py", line 737, in recv
    ret = await comm.tag_recv(self._ep, buffer, nbytes, tag, name=log)
ucp._libs.exceptions.UCXCanceled: <[Recv #008] ep: 0x7f773cfe4180, tag: 0x2263304acec70a1c, nbytes: 16, type: <class 'numpy.ndarray'>>: 

During handling of the above exception, another exception occurred:

Traceback (most recent call last):
  File "/opt/conda/envs/gdf/lib/python3.9/site-packages/distributed/worker.py", line 2056, in gather_dep
    response = await get_data_from_worker(
  File "/opt/conda/envs/gdf/lib/python3.9/site-packages/distributed/worker.py", line 2860, in get_data_from_worker
    response = await send_recv(
  File "/opt/conda/envs/gdf/lib/python3.9/site-packages/distributed/core.py", line 1154, in send_recv
    response = await comm.read(deserializers=deserializers)
  File "/opt/conda/envs/gdf/lib/python3.9/site-packages/distributed/utils.py", line 832, in wrapper
    return await func(*args, **kwargs)
  File "/opt/conda/envs/gdf/lib/python3.9/site-packages/distributed/comm/ucx.py", line 368, in read
    raise CommClosedError(
distributed.comm.core.CommClosedError: Connection closed by writer.
Inner exception: UCXCanceled("<[Recv #008] ep: 0x7f773cfe4180, tag: 0x2263304acec70a1c, nbytes: 16, type: <class 'numpy.ndarray'>>: ")
2024-01-17 07:11:51,910 - distributed.worker - ERROR - Worker stream died during communication: ucx://127.0.0.1:54715
Traceback (most recent call last):
  File "/opt/conda/envs/gdf/lib/python3.9/site-packages/distributed/comm/ucx.py", line 392, in read
    await self.ep.recv(each_frame)
  File "/opt/conda/envs/gdf/lib/python3.9/site-packages/ucp/core.py", line 737, in recv
    ret = await comm.tag_recv(self._ep, buffer, nbytes, tag, name=log)
ucp._libs.exceptions.UCXError: <[Recv #007] ep: 0x7f8d72a23140, tag: 0x229b4fe7c43b12fa, nbytes: 50000000, type: <class 'rmm._lib.device_buffer.DeviceBuffer'>>: Connection reset by remote peer

During handling of the above exception, another exception occurred:

Traceback (most recent call last):
  File "/opt/conda/envs/gdf/lib/python3.9/site-packages/distributed/worker.py", line 2056, in gather_dep
    response = await get_data_from_worker(
  File "/opt/conda/envs/gdf/lib/python3.9/site-packages/distributed/worker.py", line 2860, in get_data_from_worker
    response = await send_recv(
  File "/opt/conda/envs/gdf/lib/python3.9/site-packages/distributed/core.py", line 1154, in send_recv
    response = await comm.read(deserializers=deserializers)
  File "/opt/conda/envs/gdf/lib/python3.9/site-packages/distributed/utils.py", line 832, in wrapper
    return await func(*args, **kwargs)
  File "/opt/conda/envs/gdf/lib/python3.9/site-packages/distributed/comm/ucx.py", line 398, in read
    raise CommClosedError(
distributed.comm.core.CommClosedError: Connection closed by writer.
Inner exception: UCXError("<[Recv #007] ep: 0x7f8d72a23140, tag: 0x229b4fe7c43b12fa, nbytes: 50000000, type: <class 'rmm._lib.device_buffer.DeviceBuffer'>>: Connection reset by remote peer")
2024-01-17 07:11:51,910 - distributed.worker - ERROR - failed during get data with ucx://127.0.0.1:48753 -> ucx://127.0.0.1:54715
Traceback (most recent call last):
  File "/opt/conda/envs/gdf/lib/python3.9/site-packages/distributed/comm/ucx.py", line 350, in read
    await self.ep.recv(msg)
  File "/opt/conda/envs/gdf/lib/python3.9/site-packages/ucp/core.py", line 737, in recv
    ret = await comm.tag_recv(self._ep, buffer, nbytes, tag, name=log)
ucp._libs.exceptions.UCXCanceled: <[Recv #006] ep: 0x7f773cfe4280, tag: 0x3d5537f05ff93eff, nbytes: 16, type: <class 'numpy.ndarray'>>: 

During handling of the above exception, another exception occurred:

Traceback (most recent call last):
  File "/opt/conda/envs/gdf/lib/python3.9/site-packages/distributed/worker.py", line 1780, in get_data
    response = await comm.read(deserializers=serializers)
  File "/opt/conda/envs/gdf/lib/python3.9/site-packages/distributed/utils.py", line 832, in wrapper
    return await func(*args, **kwargs)
  File "/opt/conda/envs/gdf/lib/python3.9/site-packages/distributed/comm/ucx.py", line 368, in read
    raise CommClosedError(
distributed.comm.core.CommClosedError: Connection closed by writer.
Inner exception: UCXCanceled("<[Recv #006] ep: 0x7f773cfe4280, tag: 0x3d5537f05ff93eff, nbytes: 16, type: <class 'numpy.ndarray'>>: ")
2024-01-17 07:11:51,952 - distributed.worker - ERROR - failed during get data with ucx://127.0.0.1:35705 -> ucx://127.0.0.1:57497
Traceback (most recent call last):
  File "/opt/conda/envs/gdf/lib/python3.9/site-packages/distributed/comm/ucx.py", line 334, in write
    await self.ep.send(each_frame)
  File "/opt/conda/envs/gdf/lib/python3.9/site-packages/ucp/core.py", line 662, in send
    return await comm.tag_send(self._ep, buffer, nbytes, tag, name=log)
ucp._libs.exceptions.UCXError: <[Send #007] ep: 0x7f8d72a233c0, tag: 0x8955bf7a7e2644c7, nbytes: 50000000, type: <class 'cupy.ndarray'>>: Connection reset by remote peer

During handling of the above exception, another exception occurred:

Traceback (most recent call last):
  File "/opt/conda/envs/gdf/lib/python3.9/site-packages/distributed/worker.py", line 1779, in get_data
    compressed = await comm.write(msg, serializers=serializers)
  File "/opt/conda/envs/gdf/lib/python3.9/site-packages/distributed/utils.py", line 832, in wrapper
    return await func(*args, **kwargs)
  File "/opt/conda/envs/gdf/lib/python3.9/site-packages/distributed/comm/ucx.py", line 338, in write
    raise CommClosedError("While writing, the connection was closed")
distributed.comm.core.CommClosedError: While writing, the connection was closed
2024-01-17 07:11:51,953 - distributed.worker - ERROR - failed during get data with ucx://127.0.0.1:42005 -> ucx://127.0.0.1:57497
Traceback (most recent call last):
  File "/opt/conda/envs/gdf/lib/python3.9/site-packages/distributed/comm/ucx.py", line 334, in write
    await self.ep.send(each_frame)
  File "/opt/conda/envs/gdf/lib/python3.9/site-packages/ucp/core.py", line 662, in send
    return await comm.tag_send(self._ep, buffer, nbytes, tag, name=log)
ucp._libs.exceptions.UCXError: <[Send #007] ep: 0x7f1cd83ee3c0, tag: 0xdc3fdfa825e2e750, nbytes: 50000000, type: <class 'cupy.ndarray'>>: Connection reset by remote peer

During handling of the above exception, another exception occurred:

Traceback (most recent call last):
  File "/opt/conda/envs/gdf/lib/python3.9/site-packages/distributed/worker.py", line 1779, in get_data
    compressed = await comm.write(msg, serializers=serializers)
  File "/opt/conda/envs/gdf/lib/python3.9/site-packages/distributed/utils.py", line 832, in wrapper
    return await func(*args, **kwargs)
  File "/opt/conda/envs/gdf/lib/python3.9/site-packages/distributed/comm/ucx.py", line 338, in write
    raise CommClosedError("While writing, the connection was closed")
distributed.comm.core.CommClosedError: While writing, the connection was closed
2024-01-17 07:11:51,953 - distributed.worker - ERROR - failed during get data with ucx://127.0.0.1:48753 -> ucx://127.0.0.1:45955
Traceback (most recent call last):
  File "/opt/conda/envs/gdf/lib/python3.9/site-packages/distributed/comm/ucx.py", line 334, in write
    await self.ep.send(each_frame)
  File "/opt/conda/envs/gdf/lib/python3.9/site-packages/ucp/core.py", line 662, in send
    return await comm.tag_send(self._ep, buffer, nbytes, tag, name=log)
ucp._libs.exceptions.UCXError: <[Send #007] ep: 0x7f773cfe4240, tag: 0x9db0681d70965225, nbytes: 50000000, type: <class 'cupy.ndarray'>>: Connection reset by remote peer

During handling of the above exception, another exception occurred:

Traceback (most recent call last):
  File "/opt/conda/envs/gdf/lib/python3.9/site-packages/distributed/worker.py", line 1779, in get_data
    compressed = await comm.write(msg, serializers=serializers)
  File "/opt/conda/envs/gdf/lib/python3.9/site-packages/distributed/utils.py", line 832, in wrapper
    return await func(*args, **kwargs)
  File "/opt/conda/envs/gdf/lib/python3.9/site-packages/distributed/comm/ucx.py", line 338, in write
    raise CommClosedError("While writing, the connection was closed")
distributed.comm.core.CommClosedError: While writing, the connection was closed
2024-01-17 07:11:51,953 - distributed.worker - ERROR - Worker stream died during communication: ucx://127.0.0.1:57497
Traceback (most recent call last):
  File "/opt/conda/envs/gdf/lib/python3.9/site-packages/distributed/comm/ucx.py", line 392, in read
    await self.ep.recv(each_frame)
  File "/opt/conda/envs/gdf/lib/python3.9/site-packages/ucp/core.py", line 737, in recv
    ret = await comm.tag_recv(self._ep, buffer, nbytes, tag, name=log)
ucp._libs.exceptions.UCXError: <[Recv #007] ep: 0x7f1cd83ee180, tag: 0x70d20e3a3778731e, nbytes: 50000000, type: <class 'rmm._lib.device_buffer.DeviceBuffer'>>: Connection reset by remote peer

During handling of the above exception, another exception occurred:

Traceback (most recent call last):
  File "/opt/conda/envs/gdf/lib/python3.9/site-packages/distributed/worker.py", line 2056, in gather_dep
    response = await get_data_from_worker(
  File "/opt/conda/envs/gdf/lib/python3.9/site-packages/distributed/worker.py", line 2860, in get_data_from_worker
    response = await send_recv(
  File "/opt/conda/envs/gdf/lib/python3.9/site-packages/distributed/core.py", line 1154, in send_recv
    response = await comm.read(deserializers=deserializers)
  File "/opt/conda/envs/gdf/lib/python3.9/site-packages/distributed/utils.py", line 832, in wrapper
    return await func(*args, **kwargs)
  File "/opt/conda/envs/gdf/lib/python3.9/site-packages/distributed/comm/ucx.py", line 398, in read
    raise CommClosedError(
distributed.comm.core.CommClosedError: Connection closed by writer.
Inner exception: UCXError("<[Recv #007] ep: 0x7f1cd83ee180, tag: 0x70d20e3a3778731e, nbytes: 50000000, type: <class 'rmm._lib.device_buffer.DeviceBuffer'>>: Connection reset by remote peer")
2024-01-17 07:11:51,953 - distributed.worker - ERROR - failed during get data with ucx://127.0.0.1:48753 -> ucx://127.0.0.1:57497
Traceback (most recent call last):
  File "/opt/conda/envs/gdf/lib/python3.9/site-packages/distributed/comm/ucx.py", line 334, in write
    await self.ep.send(each_frame)
  File "/opt/conda/envs/gdf/lib/python3.9/site-packages/ucp/core.py", line 662, in send
    return await comm.tag_send(self._ep, buffer, nbytes, tag, name=log)
ucp._libs.exceptions.UCXError: <[Send #012] ep: 0x7f773cfe42c0, tag: 0x8d0739904676b5b6, nbytes: 50000000, type: <class 'cupy.ndarray'>>: Connection reset by remote peer

During handling of the above exception, another exception occurred:

Traceback (most recent call last):
  File "/opt/conda/envs/gdf/lib/python3.9/site-packages/distributed/worker.py", line 1779, in get_data
    compressed = await comm.write(msg, serializers=serializers)
  File "/opt/conda/envs/gdf/lib/python3.9/site-packages/distributed/utils.py", line 832, in wrapper
    return await func(*args, **kwargs)
  File "/opt/conda/envs/gdf/lib/python3.9/site-packages/distributed/comm/ucx.py", line 338, in write
    raise CommClosedError("While writing, the connection was closed")
distributed.comm.core.CommClosedError: While writing, the connection was closed
2024-01-17 07:11:51,954 - distributed.worker - ERROR - Worker stream died during communication: ucx://127.0.0.1:57497
Traceback (most recent call last):
  File "/opt/conda/envs/gdf/lib/python3.9/site-packages/distributed/comm/ucx.py", line 350, in read
    await self.ep.recv(msg)
  File "/opt/conda/envs/gdf/lib/python3.9/site-packages/ucp/core.py", line 737, in recv
    ret = await comm.tag_recv(self._ep, buffer, nbytes, tag, name=log)
ucp._libs.exceptions.UCXCanceled: <[Recv #008] ep: 0x7f773cfe4140, tag: 0xd585477bb3673789, nbytes: 16, type: <class 'numpy.ndarray'>>: 

During handling of the above exception, another exception occurred:

Traceback (most recent call last):
  File "/opt/conda/envs/gdf/lib/python3.9/site-packages/distributed/worker.py", line 2056, in gather_dep
    response = await get_data_from_worker(
  File "/opt/conda/envs/gdf/lib/python3.9/site-packages/distributed/worker.py", line 2860, in get_data_from_worker
    response = await send_recv(
  File "/opt/conda/envs/gdf/lib/python3.9/site-packages/distributed/core.py", line 1154, in send_recv
    response = await comm.read(deserializers=deserializers)
  File "/opt/conda/envs/gdf/lib/python3.9/site-packages/distributed/utils.py", line 832, in wrapper
    return await func(*args, **kwargs)
  File "/opt/conda/envs/gdf/lib/python3.9/site-packages/distributed/comm/ucx.py", line 368, in read
    raise CommClosedError(
distributed.comm.core.CommClosedError: Connection closed by writer.
Inner exception: UCXCanceled("<[Recv #008] ep: 0x7f773cfe4140, tag: 0xd585477bb3673789, nbytes: 16, type: <class 'numpy.ndarray'>>: ")
2024-01-17 07:11:51,958 - distributed.worker - ERROR - Worker stream died during communication: ucx://127.0.0.1:57497
Traceback (most recent call last):
  File "/opt/conda/envs/gdf/lib/python3.9/site-packages/distributed/comm/ucx.py", line 467, in connect
    ep = await ucp.create_endpoint(ip, port)
  File "/opt/conda/envs/gdf/lib/python3.9/site-packages/ucp/core.py", line 1016, in create_endpoint
    return await _get_ctx().create_endpoint(
  File "/opt/conda/envs/gdf/lib/python3.9/site-packages/ucp/core.py", line 328, in create_endpoint
    peer_info = await exchange_peer_info(
  File "/opt/conda/envs/gdf/lib/python3.9/site-packages/ucp/core.py", line 60, in exchange_peer_info
    await asyncio.wait_for(
  File "/opt/conda/envs/gdf/lib/python3.9/asyncio/tasks.py", line 479, in wait_for
    return fut.result()
ucp._libs.exceptions.UCXError: <stream_recv>: Connection reset by remote peer

During handling of the above exception, another exception occurred:

Traceback (most recent call last):
  File "/opt/conda/envs/gdf/lib/python3.9/site-packages/distributed/comm/core.py", line 342, in connect
    comm = await wait_for(
  File "/opt/conda/envs/gdf/lib/python3.9/site-packages/distributed/utils.py", line 1940, in wait_for
    return await asyncio.wait_for(fut, timeout)
  File "/opt/conda/envs/gdf/lib/python3.9/asyncio/tasks.py", line 479, in wait_for
    return fut.result()
  File "/opt/conda/envs/gdf/lib/python3.9/site-packages/distributed/comm/ucx.py", line 469, in connect
    raise CommClosedError("Connection closed before handshake completed")
distributed.comm.core.CommClosedError: Connection closed before handshake completed

During handling of the above exception, another exception occurred:

Traceback (most recent call last):
  File "/opt/conda/envs/gdf/lib/python3.9/site-packages/distributed/core.py", line 1564, in _connect
    comm = await connect(
  File "/opt/conda/envs/gdf/lib/python3.9/site-packages/distributed/comm/core.py", line 366, in connect
    await asyncio.sleep(backoff)
  File "/opt/conda/envs/gdf/lib/python3.9/asyncio/tasks.py", line 652, in sleep
    return await future
asyncio.exceptions.CancelledError

During handling of the above exception, another exception occurred:

Traceback (most recent call last):
  File "/opt/conda/envs/gdf/lib/python3.9/site-packages/distributed/core.py", line 1674, in connect
    return connect_attempt.result()
asyncio.exceptions.CancelledError

During handling of the above exception, another exception occurred:

Traceback (most recent call last):
  File "/opt/conda/envs/gdf/lib/python3.9/site-packages/distributed/worker.py", line 2056, in gather_dep
    response = await get_data_from_worker(
  File "/opt/conda/envs/gdf/lib/python3.9/site-packages/distributed/worker.py", line 2857, in get_data_from_worker
    comm = await rpc.connect(worker)
  File "/opt/conda/envs/gdf/lib/python3.9/site-packages/distributed/core.py", line 1676, in connect
    raise CommClosedError(reason)
distributed.comm.core.CommClosedError: Address removed.
2024-01-17 07:11:52,084 - distributed.worker - ERROR - Worker stream died during communication: ucx://127.0.0.1:58643
Traceback (most recent call last):
  File "/opt/conda/envs/gdf/lib/python3.9/site-packages/distributed/comm/ucx.py", line 392, in read
    await self.ep.recv(each_frame)
  File "/opt/conda/envs/gdf/lib/python3.9/site-packages/ucp/core.py", line 737, in recv
    ret = await comm.tag_recv(self._ep, buffer, nbytes, tag, name=log)
ucp._libs.exceptions.UCXError: <[Recv #007] ep: 0x7f8d72a23180, tag: 0xb399acc1fedcbcab, nbytes: 50000000, type: <class 'rmm._lib.device_buffer.DeviceBuffer'>>: Connection reset by remote peer

During handling of the above exception, another exception occurred:

Traceback (most recent call last):
  File "/opt/conda/envs/gdf/lib/python3.9/site-packages/distributed/worker.py", line 2056, in gather_dep
    response = await get_data_from_worker(
  File "/opt/conda/envs/gdf/lib/python3.9/site-packages/distributed/worker.py", line 2860, in get_data_from_worker
    response = await send_recv(
  File "/opt/conda/envs/gdf/lib/python3.9/site-packages/distributed/core.py", line 1154, in send_recv
    response = await comm.read(deserializers=deserializers)
  File "/opt/conda/envs/gdf/lib/python3.9/site-packages/distributed/utils.py", line 832, in wrapper
    return await func(*args, **kwargs)
  File "/opt/conda/envs/gdf/lib/python3.9/site-packages/distributed/comm/ucx.py", line 398, in read
    raise CommClosedError(
distributed.comm.core.CommClosedError: Connection closed by writer.
Inner exception: UCXError("<[Recv #007] ep: 0x7f8d72a23180, tag: 0xb399acc1fedcbcab, nbytes: 50000000, type: <class 'rmm._lib.device_buffer.DeviceBuffer'>>: Connection reset by remote peer")
2024-01-17 07:11:52,084 - distributed.worker - ERROR - Worker stream died during communication: ucx://127.0.0.1:58643
Traceback (most recent call last):
  File "/opt/conda/envs/gdf/lib/python3.9/site-packages/distributed/comm/ucx.py", line 392, in read
    await self.ep.recv(each_frame)
  File "/opt/conda/envs/gdf/lib/python3.9/site-packages/ucp/core.py", line 737, in recv
    ret = await comm.tag_recv(self._ep, buffer, nbytes, tag, name=log)
ucp._libs.exceptions.UCXError: <[Recv #007] ep: 0x7f1cd83ee140, tag: 0xd10add859a407749, nbytes: 50000000, type: <class 'rmm._lib.device_buffer.DeviceBuffer'>>: Connection reset by remote peer

During handling of the above exception, another exception occurred:

Traceback (most recent call last):
  File "/opt/conda/envs/gdf/lib/python3.9/site-packages/distributed/worker.py", line 2056, in gather_dep
    response = await get_data_from_worker(
  File "/opt/conda/envs/gdf/lib/python3.9/site-packages/distributed/worker.py", line 2860, in get_data_from_worker
    response = await send_recv(
  File "/opt/conda/envs/gdf/lib/python3.9/site-packages/distributed/core.py", line 1154, in send_recv
    response = await comm.read(deserializers=deserializers)
  File "/opt/conda/envs/gdf/lib/python3.9/site-packages/distributed/utils.py", line 832, in wrapper
    return await func(*args, **kwargs)
  File "/opt/conda/envs/gdf/lib/python3.9/site-packages/distributed/comm/ucx.py", line 398, in read
    raise CommClosedError(
distributed.comm.core.CommClosedError: Connection closed by writer.
Inner exception: UCXError("<[Recv #007] ep: 0x7f1cd83ee140, tag: 0xd10add859a407749, nbytes: 50000000, type: <class 'rmm._lib.device_buffer.DeviceBuffer'>>: Connection reset by remote peer")
2024-01-17 07:11:52,085 - distributed.worker - ERROR - failed during get data with ucx://127.0.0.1:42005 -> ucx://127.0.0.1:58643
Traceback (most recent call last):
  File "/opt/conda/envs/gdf/lib/python3.9/site-packages/distributed/comm/ucx.py", line 334, in write
    await self.ep.send(each_frame)
  File "/opt/conda/envs/gdf/lib/python3.9/site-packages/ucp/core.py", line 662, in send
    return await comm.tag_send(self._ep, buffer, nbytes, tag, name=log)
ucp._libs.exceptions.UCXError: <[Send #007] ep: 0x7f1cd83ee300, tag: 0x3b932a0d6ddfbd5d, nbytes: 50000000, type: <class 'cupy.ndarray'>>: Connection reset by remote peer

During handling of the above exception, another exception occurred:

Traceback (most recent call last):
  File "/opt/conda/envs/gdf/lib/python3.9/site-packages/distributed/worker.py", line 1779, in get_data
    compressed = await comm.write(msg, serializers=serializers)
  File "/opt/conda/envs/gdf/lib/python3.9/site-packages/distributed/utils.py", line 832, in wrapper
    return await func(*args, **kwargs)
  File "/opt/conda/envs/gdf/lib/python3.9/site-packages/distributed/comm/ucx.py", line 338, in write
    raise CommClosedError("While writing, the connection was closed")
distributed.comm.core.CommClosedError: While writing, the connection was closed
2024-01-17 07:11:52,085 - distributed.worker - ERROR - failed during get data with ucx://127.0.0.1:35705 -> ucx://127.0.0.1:58643
Traceback (most recent call last):
  File "/opt/conda/envs/gdf/lib/python3.9/site-packages/distributed/comm/ucx.py", line 334, in write
    await self.ep.send(each_frame)
  File "/opt/conda/envs/gdf/lib/python3.9/site-packages/ucp/core.py", line 662, in send
    return await comm.tag_send(self._ep, buffer, nbytes, tag, name=log)
ucp._libs.exceptions.UCXError: <[Send #007] ep: 0x7f8d72a232c0, tag: 0x45dceaf66b856a9f, nbytes: 50000000, type: <class 'cupy.ndarray'>>: Connection reset by remote peer

During handling of the above exception, another exception occurred:

Traceback (most recent call last):
  File "/opt/conda/envs/gdf/lib/python3.9/site-packages/distributed/worker.py", line 1779, in get_data
    compressed = await comm.write(msg, serializers=serializers)
  File "/opt/conda/envs/gdf/lib/python3.9/site-packages/distributed/utils.py", line 832, in wrapper
    return await func(*args, **kwargs)
  File "/opt/conda/envs/gdf/lib/python3.9/site-packages/distributed/comm/ucx.py", line 338, in write
    raise CommClosedError("While writing, the connection was closed")
distributed.comm.core.CommClosedError: While writing, the connection was closed
2024-01-17 07:11:52,090 - distributed.worker - ERROR - Worker stream died during communication: ucx://127.0.0.1:58643
Traceback (most recent call last):
  File "/opt/conda/envs/gdf/lib/python3.9/site-packages/distributed/comm/ucx.py", line 467, in connect
    ep = await ucp.create_endpoint(ip, port)
  File "/opt/conda/envs/gdf/lib/python3.9/site-packages/ucp/core.py", line 1016, in create_endpoint
    return await _get_ctx().create_endpoint(
  File "/opt/conda/envs/gdf/lib/python3.9/site-packages/ucp/core.py", line 328, in create_endpoint
    peer_info = await exchange_peer_info(
  File "/opt/conda/envs/gdf/lib/python3.9/site-packages/ucp/core.py", line 60, in exchange_peer_info
    await asyncio.wait_for(
  File "/opt/conda/envs/gdf/lib/python3.9/asyncio/tasks.py", line 479, in wait_for
    return fut.result()
ucp._libs.exceptions.UCXError: <stream_recv>: Connection reset by remote peer

During handling of the above exception, another exception occurred:

Traceback (most recent call last):
  File "/opt/conda/envs/gdf/lib/python3.9/site-packages/distributed/comm/core.py", line 342, in connect
    comm = await wait_for(
  File "/opt/conda/envs/gdf/lib/python3.9/site-packages/distributed/utils.py", line 1940, in wait_for
    return await asyncio.wait_for(fut, timeout)
  File "/opt/conda/envs/gdf/lib/python3.9/asyncio/tasks.py", line 479, in wait_for
    return fut.result()
  File "/opt/conda/envs/gdf/lib/python3.9/site-packages/distributed/comm/ucx.py", line 469, in connect
    raise CommClosedError("Connection closed before handshake completed")
distributed.comm.core.CommClosedError: Connection closed before handshake completed

During handling of the above exception, another exception occurred:

Traceback (most recent call last):
  File "/opt/conda/envs/gdf/lib/python3.9/site-packages/distributed/core.py", line 1564, in _connect
    comm = await connect(
  File "/opt/conda/envs/gdf/lib/python3.9/site-packages/distributed/comm/core.py", line 366, in connect
    await asyncio.sleep(backoff)
  File "/opt/conda/envs/gdf/lib/python3.9/asyncio/tasks.py", line 652, in sleep
    return await future
asyncio.exceptions.CancelledError

During handling of the above exception, another exception occurred:

Traceback (most recent call last):
  File "/opt/conda/envs/gdf/lib/python3.9/site-packages/distributed/core.py", line 1674, in connect
    return connect_attempt.result()
asyncio.exceptions.CancelledError

During handling of the above exception, another exception occurred:

Traceback (most recent call last):
  File "/opt/conda/envs/gdf/lib/python3.9/site-packages/distributed/worker.py", line 2056, in gather_dep
    response = await get_data_from_worker(
  File "/opt/conda/envs/gdf/lib/python3.9/site-packages/distributed/worker.py", line 2857, in get_data_from_worker
    comm = await rpc.connect(worker)
  File "/opt/conda/envs/gdf/lib/python3.9/site-packages/distributed/core.py", line 1676, in connect
    raise CommClosedError(reason)
distributed.comm.core.CommClosedError: Address removed.
2024-01-17 07:11:57,302 - distributed.nanny - WARNING - Restarting worker
2024-01-17 07:11:57,351 - distributed.nanny - WARNING - Restarting worker
2024-01-17 07:11:57,838 - distributed.nanny - WARNING - Restarting worker
2024-01-17 07:11:58,023 - distributed.nanny - WARNING - Restarting worker
2024-01-17 07:11:58,056 - distributed.nanny - WARNING - Restarting worker
/opt/conda/envs/gdf/lib/python3.9/multiprocessing/resource_tracker.py:216: UserWarning: resource_tracker: There appear to be 48 leaked semaphore objects to clean up at shutdown
  warnings.warn('resource_tracker: There appear to be %d '
