[dgx13:83968:0:83968] Caught signal 11 (Segmentation fault: address not mapped to object at address 0x448)
==== backtrace (tid:  83968) ====
 0  /opt/conda/envs/gdf/lib/libucs.so.0(ucs_handle_error+0x2fd) [0x7f6c453bc07d]
 1  /opt/conda/envs/gdf/lib/libucs.so.0(+0x2a274) [0x7f6c453bc274]
 2  /opt/conda/envs/gdf/lib/libucs.so.0(+0x2a43a) [0x7f6c453bc43a]
 3  /usr/lib/x86_64-linux-gnu/libpthread.so.0(+0x14420) [0x7f6c820d3420]
 4  /opt/conda/envs/gdf/lib/libucp.so.0(ucp_mem_type_unpack+0x14) [0x7f6c4543b6b4]
 5  /opt/conda/envs/gdf/lib/libucp.so.0(ucp_rndv_data_handler+0x4e9) [0x7f6c45464839]
 6  /opt/conda/envs/gdf/lib/libuct.so.0(+0x203df) [0x7f6c453763df]
 7  /opt/conda/envs/gdf/lib/libuct.so.0(+0x23838) [0x7f6c45379838]
 8  /opt/conda/envs/gdf/lib/libucs.so.0(ucs_event_set_wait+0xb9) [0x7f6c453c54a9]
 9  /opt/conda/envs/gdf/lib/libuct.so.0(uct_tcp_iface_progress+0x7d) [0x7f6c453785dd]
10  /opt/conda/envs/gdf/lib/libucp.so.0(ucp_worker_progress+0x5a) [0x7f6c454388da]
11  /opt/conda/envs/gdf/lib/python3.9/site-packages/ucp/_libs/ucx_api.cpython-39-x86_64-linux-gnu.so(+0x3206a) [0x7f6c454f106a]
12  /opt/conda/envs/gdf/bin/python(_PyEval_EvalFrameDefault+0x45a6) [0x558461a8a3f6]
13  /opt/conda/envs/gdf/bin/python(+0x12dfb4) [0x558461a84fb4]
14  /opt/conda/envs/gdf/bin/python(_PyFunction_Vectorcall+0xd9) [0x558461a96469]
15  /opt/conda/envs/gdf/bin/python(_PyEval_EvalFrameDefault+0x696) [0x558461a864e6]
16  /opt/conda/envs/gdf/bin/python(+0x1e26d2) [0x558461b396d2]
17  /opt/conda/envs/gdf/lib/python3.9/lib-dynload/_asyncio.cpython-39-x86_64-linux-gnu.so(+0x81e9) [0x7f6c6c6791e9]
18  /opt/conda/envs/gdf/bin/python(_PyObject_MakeTpCall+0x2ec) [0x558461a8e6ac]
19  /opt/conda/envs/gdf/bin/python(+0xf23ff) [0x558461a493ff]
20  /opt/conda/envs/gdf/bin/python(+0x136723) [0x558461a8d723]
21  /opt/conda/envs/gdf/bin/python(_PyEval_EvalFrameDefault+0x5ad9) [0x558461a8b929]
22  /opt/conda/envs/gdf/bin/python(+0x13f712) [0x558461a96712]
23  /opt/conda/envs/gdf/bin/python(_PyEval_EvalFrameDefault+0x696) [0x558461a864e6]
24  /opt/conda/envs/gdf/bin/python(+0x13f712) [0x558461a96712]
25  /opt/conda/envs/gdf/bin/python(_PyEval_EvalFrameDefault+0x696) [0x558461a864e6]
26  /opt/conda/envs/gdf/bin/python(+0x13f712) [0x558461a96712]
27  /opt/conda/envs/gdf/bin/python(_PyEval_EvalFrameDefault+0x696) [0x558461a864e6]
28  /opt/conda/envs/gdf/bin/python(+0x13f712) [0x558461a96712]
29  /opt/conda/envs/gdf/bin/python(_PyEval_EvalFrameDefault+0x696) [0x558461a864e6]
30  /opt/conda/envs/gdf/bin/python(+0x12dfb4) [0x558461a84fb4]
31  /opt/conda/envs/gdf/bin/python(_PyFunction_Vectorcall+0xd9) [0x558461a96469]
32  /opt/conda/envs/gdf/bin/python(_PyEval_EvalFrameDefault+0x11f2) [0x558461a87042]
33  /opt/conda/envs/gdf/bin/python(+0x12dfb4) [0x558461a84fb4]
34  /opt/conda/envs/gdf/bin/python(+0x14c8cb) [0x558461aa38cb]
35  /opt/conda/envs/gdf/bin/python(PyObject_Call+0xbc) [0x558461aa404c]
36  /opt/conda/envs/gdf/bin/python(+0x21080e) [0x558461b6780e]
37  /opt/conda/envs/gdf/bin/python(_PyObject_MakeTpCall+0x2ec) [0x558461a8e6ac]
38  /opt/conda/envs/gdf/bin/python(_PyEval_EvalFrameDefault+0x45a6) [0x558461a8a3f6]
39  /opt/conda/envs/gdf/bin/python(+0x13f712) [0x558461a96712]
40  /opt/conda/envs/gdf/bin/python(+0x14c9ac) [0x558461aa39ac]
41  /opt/conda/envs/gdf/bin/python(_PyEval_EvalFrameDefault+0x45a6) [0x558461a8a3f6]
42  /opt/conda/envs/gdf/bin/python(+0x13f712) [0x558461a96712]
43  /opt/conda/envs/gdf/bin/python(_PyEval_EvalFrameDefault+0x696) [0x558461a864e6]
44  /opt/conda/envs/gdf/bin/python(+0x12dfb4) [0x558461a84fb4]
45  /opt/conda/envs/gdf/bin/python(_PyFunction_Vectorcall+0xd9) [0x558461a96469]
46  /opt/conda/envs/gdf/bin/python(_PyEval_EvalFrameDefault+0x696) [0x558461a864e6]
47  /opt/conda/envs/gdf/bin/python(+0x13f712) [0x558461a96712]
48  /opt/conda/envs/gdf/bin/python(_PyEval_EvalFrameDefault+0x3e2) [0x558461a86232]
49  /opt/conda/envs/gdf/bin/python(+0x12dfb4) [0x558461a84fb4]
50  /opt/conda/envs/gdf/bin/python(_PyFunction_Vectorcall+0xd9) [0x558461a96469]
51  /opt/conda/envs/gdf/bin/python(_PyEval_EvalFrameDefault+0x11f2) [0x558461a87042]
52  /opt/conda/envs/gdf/bin/python(+0x12dfb4) [0x558461a84fb4]
53  /opt/conda/envs/gdf/bin/python(_PyEval_EvalCodeWithName+0x48) [0x558461a84c88]
54  /opt/conda/envs/gdf/bin/python(PyEval_EvalCodeEx+0x39) [0x558461a84c39]
55  /opt/conda/envs/gdf/bin/python(PyEval_EvalCode+0x1b) [0x558461b322cb]
56  /opt/conda/envs/gdf/bin/python(+0x2086ca) [0x558461b5f6ca]
57  /opt/conda/envs/gdf/bin/python(+0x204a63) [0x558461b5ba63]
58  /opt/conda/envs/gdf/bin/python(PyRun_StringFlags+0x9a) [0x558461b5387a]
59  /opt/conda/envs/gdf/bin/python(PyRun_SimpleStringFlags+0x3c) [0x558461b5376c]
60  /opt/conda/envs/gdf/bin/python(Py_RunMain+0x267) [0x558461b529a7]
61  /opt/conda/envs/gdf/bin/python(Py_BytesMain+0x37) [0x558461b26107]
=================================
[dgx13:83963:0:83963] Caught signal 11 (Segmentation fault: address not mapped to object at address 0x448)
==== backtrace (tid:  83963) ====
 0  /opt/conda/envs/gdf/lib/libucs.so.0(ucs_handle_error+0x2fd) [0x7f648c03c07d]
 1  /opt/conda/envs/gdf/lib/libucs.so.0(+0x2a274) [0x7f648c03c274]
 2  /opt/conda/envs/gdf/lib/libucs.so.0(+0x2a43a) [0x7f648c03c43a]
 3  /usr/lib/x86_64-linux-gnu/libpthread.so.0(+0x14420) [0x7f64c4c54420]
 4  /opt/conda/envs/gdf/lib/libucp.so.0(ucp_mem_type_unpack+0x14) [0x7f6485f7c6b4]
 5  /opt/conda/envs/gdf/lib/libucp.so.0(ucp_rndv_data_handler+0x4e9) [0x7f6485fa5839]
 6  /opt/conda/envs/gdf/lib/libuct.so.0(+0x203df) [0x7f6485f163df]
 7  /opt/conda/envs/gdf/lib/libuct.so.0(+0x23838) [0x7f6485f19838]
 8  /opt/conda/envs/gdf/lib/libucs.so.0(ucs_event_set_wait+0xb9) [0x7f648c0454a9]
 9  /opt/conda/envs/gdf/lib/libuct.so.0(uct_tcp_iface_progress+0x7d) [0x7f6485f185dd]
10  /opt/conda/envs/gdf/lib/libucp.so.0(ucp_worker_progress+0x5a) [0x7f6485f798da]
11  /opt/conda/envs/gdf/lib/python3.9/site-packages/ucp/_libs/ucx_api.cpython-39-x86_64-linux-gnu.so(+0x3206a) [0x7f648c0a306a]
12  /opt/conda/envs/gdf/bin/python(_PyEval_EvalFrameDefault+0x45a6) [0x55baefa6e3f6]
13  /opt/conda/envs/gdf/bin/python(+0x12dfb4) [0x55baefa68fb4]
14  /opt/conda/envs/gdf/bin/python(_PyFunction_Vectorcall+0xd9) [0x55baefa7a469]
15  /opt/conda/envs/gdf/bin/python(_PyEval_EvalFrameDefault+0x696) [0x55baefa6a4e6]
16  /opt/conda/envs/gdf/bin/python(+0x1e26d2) [0x55baefb1d6d2]
17  /opt/conda/envs/gdf/lib/python3.9/lib-dynload/_asyncio.cpython-39-x86_64-linux-gnu.so(+0x81e9) [0x7f64b823d1e9]
18  /opt/conda/envs/gdf/bin/python(_PyObject_MakeTpCall+0x2ec) [0x55baefa726ac]
19  /opt/conda/envs/gdf/bin/python(+0xf23ff) [0x55baefa2d3ff]
20  /opt/conda/envs/gdf/bin/python(+0x136723) [0x55baefa71723]
21  /opt/conda/envs/gdf/bin/python(_PyEval_EvalFrameDefault+0x5ad9) [0x55baefa6f929]
22  /opt/conda/envs/gdf/bin/python(+0x13f712) [0x55baefa7a712]
23  /opt/conda/envs/gdf/bin/python(_PyEval_EvalFrameDefault+0x696) [0x55baefa6a4e6]
24  /opt/conda/envs/gdf/bin/python(+0x13f712) [0x55baefa7a712]
25  /opt/conda/envs/gdf/bin/python(_PyEval_EvalFrameDefault+0x696) [0x55baefa6a4e6]
26  /opt/conda/envs/gdf/bin/python(+0x13f712) [0x55baefa7a712]
27  /opt/conda/envs/gdf/bin/python(_PyEval_EvalFrameDefault+0x696) [0x55baefa6a4e6]
28  /opt/conda/envs/gdf/bin/python(+0x13f712) [0x55baefa7a712]
29  /opt/conda/envs/gdf/bin/python(_PyEval_EvalFrameDefault+0x696) [0x55baefa6a4e6]
30  /opt/conda/envs/gdf/bin/python(+0x12dfb4) [0x55baefa68fb4]
31  /opt/conda/envs/gdf/bin/python(_PyFunction_Vectorcall+0xd9) [0x55baefa7a469]
32  /opt/conda/envs/gdf/bin/python(_PyEval_EvalFrameDefault+0x11f2) [0x55baefa6b042]
33  /opt/conda/envs/gdf/bin/python(+0x12dfb4) [0x55baefa68fb4]
34  /opt/conda/envs/gdf/bin/python(+0x14c8cb) [0x55baefa878cb]
35  /opt/conda/envs/gdf/bin/python(PyObject_Call+0xbc) [0x55baefa8804c]
36  /opt/conda/envs/gdf/bin/python(+0x21080e) [0x55baefb4b80e]
37  /opt/conda/envs/gdf/bin/python(_PyObject_MakeTpCall+0x2ec) [0x55baefa726ac]
38  /opt/conda/envs/gdf/bin/python(_PyEval_EvalFrameDefault+0x45a6) [0x55baefa6e3f6]
39  /opt/conda/envs/gdf/bin/python(+0x13f712) [0x55baefa7a712]
40  /opt/conda/envs/gdf/bin/python(+0x14c9ac) [0x55baefa879ac]
41  /opt/conda/envs/gdf/bin/python(_PyEval_EvalFrameDefault+0x45a6) [0x55baefa6e3f6]
42  /opt/conda/envs/gdf/bin/python(+0x13f712) [0x55baefa7a712]
43  /opt/conda/envs/gdf/bin/python(_PyEval_EvalFrameDefault+0x696) [0x55baefa6a4e6]
44  /opt/conda/envs/gdf/bin/python(+0x12dfb4) [0x55baefa68fb4]
45  /opt/conda/envs/gdf/bin/python(_PyFunction_Vectorcall+0xd9) [0x55baefa7a469]
46  /opt/conda/envs/gdf/bin/python(_PyEval_EvalFrameDefault+0x696) [0x55baefa6a4e6]
47  /opt/conda/envs/gdf/bin/python(+0x13f712) [0x55baefa7a712]
48  /opt/conda/envs/gdf/bin/python(_PyEval_EvalFrameDefault+0x3e2) [0x55baefa6a232]
49  /opt/conda/envs/gdf/bin/python(+0x12dfb4) [0x55baefa68fb4]
50  /opt/conda/envs/gdf/bin/python(_PyFunction_Vectorcall+0xd9) [0x55baefa7a469]
51  /opt/conda/envs/gdf/bin/python(_PyEval_EvalFrameDefault+0x11f2) [0x55baefa6b042]
52  /opt/conda/envs/gdf/bin/python(+0x12dfb4) [0x55baefa68fb4]
53  /opt/conda/envs/gdf/bin/python(_PyEval_EvalCodeWithName+0x48) [0x55baefa68c88]
54  /opt/conda/envs/gdf/bin/python(PyEval_EvalCodeEx+0x39) [0x55baefa68c39]
55  /opt/conda/envs/gdf/bin/python(PyEval_EvalCode+0x1b) [0x55baefb162cb]
56  /opt/conda/envs/gdf/bin/python(+0x2086ca) [0x55baefb436ca]
57  /opt/conda/envs/gdf/bin/python(+0x204a63) [0x55baefb3fa63]
58  /opt/conda/envs/gdf/bin/python(PyRun_StringFlags+0x9a) [0x55baefb3787a]
59  /opt/conda/envs/gdf/bin/python(PyRun_SimpleStringFlags+0x3c) [0x55baefb3776c]
60  /opt/conda/envs/gdf/bin/python(Py_RunMain+0x267) [0x55baefb369a7]
61  /opt/conda/envs/gdf/bin/python(Py_BytesMain+0x37) [0x55baefb0a107]
=================================
[dgx13:83978:0:83978] Caught signal 11 (Segmentation fault: address not mapped to object at address 0x448)
==== backtrace (tid:  83978) ====
 0  /opt/conda/envs/gdf/lib/libucs.so.0(ucs_handle_error+0x2fd) [0x7f9ef438707d]
 1  /opt/conda/envs/gdf/lib/libucs.so.0(+0x2a274) [0x7f9ef4387274]
 2  /opt/conda/envs/gdf/lib/libucs.so.0(+0x2a43a) [0x7f9ef438743a]
 3  /usr/lib/x86_64-linux-gnu/libpthread.so.0(+0x14420) [0x7f9f1f058420]
 4  /opt/conda/envs/gdf/lib/libucp.so.0(ucp_mem_type_unpack+0x14) [0x7f9ef44066b4]
 5  /opt/conda/envs/gdf/lib/libucp.so.0(ucp_rndv_data_handler+0x4e9) [0x7f9ef442f839]
 6  /opt/conda/envs/gdf/lib/libuct.so.0(+0x203df) [0x7f9ef43413df]
 7  /opt/conda/envs/gdf/lib/libuct.so.0(+0x23838) [0x7f9ef4344838]
 8  /opt/conda/envs/gdf/lib/libucs.so.0(ucs_event_set_wait+0xb9) [0x7f9ef43904a9]
 9  /opt/conda/envs/gdf/lib/libuct.so.0(uct_tcp_iface_progress+0x7d) [0x7f9ef43435dd]
10  /opt/conda/envs/gdf/lib/libucp.so.0(ucp_worker_progress+0x5a) [0x7f9ef44038da]
11  /opt/conda/envs/gdf/lib/python3.9/site-packages/ucp/_libs/ucx_api.cpython-39-x86_64-linux-gnu.so(+0x3206a) [0x7f9ef44bc06a]
12  /opt/conda/envs/gdf/bin/python(_PyEval_EvalFrameDefault+0x45a6) [0x55a9a919b3f6]
13  /opt/conda/envs/gdf/bin/python(+0x12dfb4) [0x55a9a9195fb4]
14  /opt/conda/envs/gdf/bin/python(_PyFunction_Vectorcall+0xd9) [0x55a9a91a7469]
15  /opt/conda/envs/gdf/bin/python(_PyEval_EvalFrameDefault+0x696) [0x55a9a91974e6]
16  /opt/conda/envs/gdf/bin/python(+0x13f712) [0x55a9a91a7712]
17  /opt/conda/envs/gdf/bin/python(+0x14ca83) [0x55a9a91b4a83]
18  /opt/conda/envs/gdf/bin/python(+0x25819c) [0x55a9a92c019c]
19  /opt/conda/envs/gdf/bin/python(+0xf23ff) [0x55a9a915a3ff]
20  /opt/conda/envs/gdf/bin/python(+0x136723) [0x55a9a919e723]
21  /opt/conda/envs/gdf/bin/python(_PyEval_EvalFrameDefault+0x5ad9) [0x55a9a919c929]
22  /opt/conda/envs/gdf/bin/python(+0x13f712) [0x55a9a91a7712]
23  /opt/conda/envs/gdf/bin/python(_PyEval_EvalFrameDefault+0x696) [0x55a9a91974e6]
24  /opt/conda/envs/gdf/bin/python(+0x13f712) [0x55a9a91a7712]
25  /opt/conda/envs/gdf/bin/python(_PyEval_EvalFrameDefault+0x696) [0x55a9a91974e6]
26  /opt/conda/envs/gdf/bin/python(+0x13f712) [0x55a9a91a7712]
27  /opt/conda/envs/gdf/bin/python(_PyEval_EvalFrameDefault+0x696) [0x55a9a91974e6]
28  /opt/conda/envs/gdf/bin/python(+0x13f712) [0x55a9a91a7712]
29  /opt/conda/envs/gdf/bin/python(_PyEval_EvalFrameDefault+0x696) [0x55a9a91974e6]
30  /opt/conda/envs/gdf/bin/python(+0x12dfb4) [0x55a9a9195fb4]
31  /opt/conda/envs/gdf/bin/python(_PyFunction_Vectorcall+0xd9) [0x55a9a91a7469]
32  /opt/conda/envs/gdf/bin/python(_PyEval_EvalFrameDefault+0x11f2) [0x55a9a9198042]
33  /opt/conda/envs/gdf/bin/python(+0x12dfb4) [0x55a9a9195fb4]
34  /opt/conda/envs/gdf/bin/python(+0x14c8cb) [0x55a9a91b48cb]
35  /opt/conda/envs/gdf/bin/python(PyObject_Call+0xbc) [0x55a9a91b504c]
36  /opt/conda/envs/gdf/bin/python(+0x21080e) [0x55a9a927880e]
37  /opt/conda/envs/gdf/bin/python(_PyObject_MakeTpCall+0x2ec) [0x55a9a919f6ac]
38  /opt/conda/envs/gdf/bin/python(_PyEval_EvalFrameDefault+0x45a6) [0x55a9a919b3f6]
39  /opt/conda/envs/gdf/bin/python(+0x13f712) [0x55a9a91a7712]
40  /opt/conda/envs/gdf/bin/python(+0x14c9ac) [0x55a9a91b49ac]
41  /opt/conda/envs/gdf/bin/python(_PyEval_EvalFrameDefault+0x45a6) [0x55a9a919b3f6]
42  /opt/conda/envs/gdf/bin/python(+0x13f712) [0x55a9a91a7712]
43  /opt/conda/envs/gdf/bin/python(_PyEval_EvalFrameDefault+0x696) [0x55a9a91974e6]
44  /opt/conda/envs/gdf/bin/python(+0x12dfb4) [0x55a9a9195fb4]
45  /opt/conda/envs/gdf/bin/python(_PyFunction_Vectorcall+0xd9) [0x55a9a91a7469]
46  /opt/conda/envs/gdf/bin/python(_PyEval_EvalFrameDefault+0x696) [0x55a9a91974e6]
47  /opt/conda/envs/gdf/bin/python(+0x13f712) [0x55a9a91a7712]
48  /opt/conda/envs/gdf/bin/python(_PyEval_EvalFrameDefault+0x3e2) [0x55a9a9197232]
49  /opt/conda/envs/gdf/bin/python(+0x12dfb4) [0x55a9a9195fb4]
50  /opt/conda/envs/gdf/bin/python(_PyFunction_Vectorcall+0xd9) [0x55a9a91a7469]
51  /opt/conda/envs/gdf/bin/python(_PyEval_EvalFrameDefault+0x11f2) [0x55a9a9198042]
52  /opt/conda/envs/gdf/bin/python(+0x12dfb4) [0x55a9a9195fb4]
53  /opt/conda/envs/gdf/bin/python(_PyEval_EvalCodeWithName+0x48) [0x55a9a9195c88]
54  /opt/conda/envs/gdf/bin/python(PyEval_EvalCodeEx+0x39) [0x55a9a9195c39]
55  /opt/conda/envs/gdf/bin/python(PyEval_EvalCode+0x1b) [0x55a9a92432cb]
56  /opt/conda/envs/gdf/bin/python(+0x2086ca) [0x55a9a92706ca]
57  /opt/conda/envs/gdf/bin/python(+0x204a63) [0x55a9a926ca63]
58  /opt/conda/envs/gdf/bin/python(PyRun_StringFlags+0x9a) [0x55a9a926487a]
59  /opt/conda/envs/gdf/bin/python(PyRun_SimpleStringFlags+0x3c) [0x55a9a926476c]
60  /opt/conda/envs/gdf/bin/python(Py_RunMain+0x267) [0x55a9a92639a7]
61  /opt/conda/envs/gdf/bin/python(Py_BytesMain+0x37) [0x55a9a9237107]
=================================
[dgx13:83958:0:83958] Caught signal 11 (Segmentation fault: address not mapped to object at address 0x448)
==== backtrace (tid:  83958) ====
 0  /opt/conda/envs/gdf/lib/libucs.so.0(ucs_handle_error+0x2fd) [0x7fda9319a07d]
 1  /opt/conda/envs/gdf/lib/libucs.so.0(+0x2a274) [0x7fda9319a274]
 2  /opt/conda/envs/gdf/lib/libucs.so.0(+0x2a43a) [0x7fda9319a43a]
 3  /usr/lib/x86_64-linux-gnu/libpthread.so.0(+0x14420) [0x7fdacbcf9420]
 4  /opt/conda/envs/gdf/lib/libucp.so.0(ucp_mem_type_unpack+0x14) [0x7fda932196b4]
 5  /opt/conda/envs/gdf/lib/libucp.so.0(ucp_rndv_data_handler+0x4e9) [0x7fda93242839]
 6  /opt/conda/envs/gdf/lib/libuct.so.0(+0x203df) [0x7fda931543df]
 7  /opt/conda/envs/gdf/lib/libuct.so.0(+0x23838) [0x7fda93157838]
 8  /opt/conda/envs/gdf/lib/libucs.so.0(ucs_event_set_wait+0xb9) [0x7fda931a34a9]
 9  /opt/conda/envs/gdf/lib/libuct.so.0(uct_tcp_iface_progress+0x7d) [0x7fda931565dd]
10  /opt/conda/envs/gdf/lib/libucp.so.0(ucp_worker_progress+0x5a) [0x7fda932168da]
11  /opt/conda/envs/gdf/lib/python3.9/site-packages/ucp/_libs/ucx_api.cpython-39-x86_64-linux-gnu.so(+0x3206a) [0x7fda932cf06a]
12  /opt/conda/envs/gdf/bin/python(_PyEval_EvalFrameDefault+0x45a6) [0x55c36d3663f6]
13  /opt/conda/envs/gdf/bin/python(+0x12dfb4) [0x55c36d360fb4]
14  /opt/conda/envs/gdf/bin/python(_PyFunction_Vectorcall+0xd9) [0x55c36d372469]
15  /opt/conda/envs/gdf/bin/python(_PyEval_EvalFrameDefault+0x696) [0x55c36d3624e6]
16  /opt/conda/envs/gdf/bin/python(+0x1e26d2) [0x55c36d4156d2]
17  /opt/conda/envs/gdf/lib/python3.9/lib-dynload/_asyncio.cpython-39-x86_64-linux-gnu.so(+0x81e9) [0x7fdab62911e9]
18  /opt/conda/envs/gdf/bin/python(_PyObject_MakeTpCall+0x2ec) [0x55c36d36a6ac]
19  /opt/conda/envs/gdf/bin/python(+0xf23ff) [0x55c36d3253ff]
20  /opt/conda/envs/gdf/bin/python(+0x136723) [0x55c36d369723]
21  /opt/conda/envs/gdf/bin/python(_PyEval_EvalFrameDefault+0x5ad9) [0x55c36d367929]
22  /opt/conda/envs/gdf/bin/python(+0x13f712) [0x55c36d372712]
23  /opt/conda/envs/gdf/bin/python(_PyEval_EvalFrameDefault+0x696) [0x55c36d3624e6]
24  /opt/conda/envs/gdf/bin/python(+0x13f712) [0x55c36d372712]
25  /opt/conda/envs/gdf/bin/python(_PyEval_EvalFrameDefault+0x696) [0x55c36d3624e6]
26  /opt/conda/envs/gdf/bin/python(+0x13f712) [0x55c36d372712]
27  /opt/conda/envs/gdf/bin/python(_PyEval_EvalFrameDefault+0x696) [0x55c36d3624e6]
28  /opt/conda/envs/gdf/bin/python(+0x13f712) [0x55c36d372712]
29  /opt/conda/envs/gdf/bin/python(_PyEval_EvalFrameDefault+0x696) [0x55c36d3624e6]
30  /opt/conda/envs/gdf/bin/python(+0x12dfb4) [0x55c36d360fb4]
31  /opt/conda/envs/gdf/bin/python(_PyFunction_Vectorcall+0xd9) [0x55c36d372469]
32  /opt/conda/envs/gdf/bin/python(_PyEval_EvalFrameDefault+0x11f2) [0x55c36d363042]
33  /opt/conda/envs/gdf/bin/python(+0x12dfb4) [0x55c36d360fb4]
34  /opt/conda/envs/gdf/bin/python(+0x14c8cb) [0x55c36d37f8cb]
35  /opt/conda/envs/gdf/bin/python(PyObject_Call+0xbc) [0x55c36d38004c]
36  /opt/conda/envs/gdf/bin/python(+0x21080e) [0x55c36d44380e]
37  /opt/conda/envs/gdf/bin/python(_PyObject_MakeTpCall+0x2ec) [0x55c36d36a6ac]
38  /opt/conda/envs/gdf/bin/python(_PyEval_EvalFrameDefault+0x45a6) [0x55c36d3663f6]
39  /opt/conda/envs/gdf/bin/python(+0x13f712) [0x55c36d372712]
40  /opt/conda/envs/gdf/bin/python(+0x14c9ac) [0x55c36d37f9ac]
41  /opt/conda/envs/gdf/bin/python(_PyEval_EvalFrameDefault+0x45a6) [0x55c36d3663f6]
42  /opt/conda/envs/gdf/bin/python(+0x13f712) [0x55c36d372712]
43  /opt/conda/envs/gdf/bin/python(_PyEval_EvalFrameDefault+0x696) [0x55c36d3624e6]
44  /opt/conda/envs/gdf/bin/python(+0x12dfb4) [0x55c36d360fb4]
45  /opt/conda/envs/gdf/bin/python(_PyFunction_Vectorcall+0xd9) [0x55c36d372469]
46  /opt/conda/envs/gdf/bin/python(_PyEval_EvalFrameDefault+0x696) [0x55c36d3624e6]
47  /opt/conda/envs/gdf/bin/python(+0x13f712) [0x55c36d372712]
48  /opt/conda/envs/gdf/bin/python(_PyEval_EvalFrameDefault+0x3e2) [0x55c36d362232]
49  /opt/conda/envs/gdf/bin/python(+0x12dfb4) [0x55c36d360fb4]
50  /opt/conda/envs/gdf/bin/python(_PyFunction_Vectorcall+0xd9) [0x55c36d372469]
51  /opt/conda/envs/gdf/bin/python(_PyEval_EvalFrameDefault+0x11f2) [0x55c36d363042]
52  /opt/conda/envs/gdf/bin/python(+0x12dfb4) [0x55c36d360fb4]
53  /opt/conda/envs/gdf/bin/python(_PyEval_EvalCodeWithName+0x48) [0x55c36d360c88]
54  /opt/conda/envs/gdf/bin/python(PyEval_EvalCodeEx+0x39) [0x55c36d360c39]
55  /opt/conda/envs/gdf/bin/python(PyEval_EvalCode+0x1b) [0x55c36d40e2cb]
56  /opt/conda/envs/gdf/bin/python(+0x2086ca) [0x55c36d43b6ca]
57  /opt/conda/envs/gdf/bin/python(+0x204a63) [0x55c36d437a63]
58  /opt/conda/envs/gdf/bin/python(PyRun_StringFlags+0x9a) [0x55c36d42f87a]
59  /opt/conda/envs/gdf/bin/python(PyRun_SimpleStringFlags+0x3c) [0x55c36d42f76c]
60  /opt/conda/envs/gdf/bin/python(Py_RunMain+0x267) [0x55c36d42e9a7]
61  /opt/conda/envs/gdf/bin/python(Py_BytesMain+0x37) [0x55c36d402107]
=================================
[dgx13:83973:0:83973] Caught signal 11 (Segmentation fault: address not mapped to object at address 0x448)
==== backtrace (tid:  83973) ====
 0  /opt/conda/envs/gdf/lib/libucs.so.0(ucs_handle_error+0x2fd) [0x7f324576f07d]
 1  /opt/conda/envs/gdf/lib/libucs.so.0(+0x2a274) [0x7f324576f274]
 2  /opt/conda/envs/gdf/lib/libucs.so.0(+0x2a43a) [0x7f324576f43a]
 3  /usr/lib/x86_64-linux-gnu/libpthread.so.0(+0x14420) [0x7f3282452420]
 4  /opt/conda/envs/gdf/lib/libucp.so.0(ucp_mem_type_unpack+0x14) [0x7f32457ee6b4]
 5  /opt/conda/envs/gdf/lib/libucp.so.0(ucp_rndv_data_handler+0x4e9) [0x7f3245817839]
 6  /opt/conda/envs/gdf/lib/libuct.so.0(+0x203df) [0x7f32457293df]
 7  /opt/conda/envs/gdf/lib/libuct.so.0(+0x23838) [0x7f324572c838]
 8  /opt/conda/envs/gdf/lib/libucs.so.0(ucs_event_set_wait+0xb9) [0x7f32457784a9]
 9  /opt/conda/envs/gdf/lib/libuct.so.0(uct_tcp_iface_progress+0x7d) [0x7f324572b5dd]
10  /opt/conda/envs/gdf/lib/libucp.so.0(ucp_worker_progress+0x5a) [0x7f32457eb8da]
11  /opt/conda/envs/gdf/lib/python3.9/site-packages/ucp/_libs/ucx_api.cpython-39-x86_64-linux-gnu.so(+0x3206a) [0x7f32458a406a]
12  /opt/conda/envs/gdf/bin/python(_PyEval_EvalFrameDefault+0x45a6) [0x5605ef3093f6]
13  /opt/conda/envs/gdf/bin/python(+0x12dfb4) [0x5605ef303fb4]
14  /opt/conda/envs/gdf/bin/python(_PyFunction_Vectorcall+0xd9) [0x5605ef315469]
15  /opt/conda/envs/gdf/bin/python(_PyEval_EvalFrameDefault+0x696) [0x5605ef3054e6]
16  /opt/conda/envs/gdf/bin/python(+0x1e26d2) [0x5605ef3b86d2]
17  /opt/conda/envs/gdf/lib/python3.9/lib-dynload/_asyncio.cpython-39-x86_64-linux-gnu.so(+0x81e9) [0x7f326c9f31e9]
18  /opt/conda/envs/gdf/bin/python(_PyObject_MakeTpCall+0x2ec) [0x5605ef30d6ac]
19  /opt/conda/envs/gdf/bin/python(+0xf23ff) [0x5605ef2c83ff]
20  /opt/conda/envs/gdf/bin/python(+0x136723) [0x5605ef30c723]
21  /opt/conda/envs/gdf/bin/python(_PyEval_EvalFrameDefault+0x5ad9) [0x5605ef30a929]
22  /opt/conda/envs/gdf/bin/python(+0x13f712) [0x5605ef315712]
23  /opt/conda/envs/gdf/bin/python(_PyEval_EvalFrameDefault+0x696) [0x5605ef3054e6]
24  /opt/conda/envs/gdf/bin/python(+0x13f712) [0x5605ef315712]
25  /opt/conda/envs/gdf/bin/python(_PyEval_EvalFrameDefault+0x696) [0x5605ef3054e6]
26  /opt/conda/envs/gdf/bin/python(+0x13f712) [0x5605ef315712]
27  /opt/conda/envs/gdf/bin/python(_PyEval_EvalFrameDefault+0x696) [0x5605ef3054e6]
28  /opt/conda/envs/gdf/bin/python(+0x13f712) [0x5605ef315712]
29  /opt/conda/envs/gdf/bin/python(_PyEval_EvalFrameDefault+0x696) [0x5605ef3054e6]
30  /opt/conda/envs/gdf/bin/python(+0x12dfb4) [0x5605ef303fb4]
31  /opt/conda/envs/gdf/bin/python(_PyFunction_Vectorcall+0xd9) [0x5605ef315469]
32  /opt/conda/envs/gdf/bin/python(_PyEval_EvalFrameDefault+0x11f2) [0x5605ef306042]
33  /opt/conda/envs/gdf/bin/python(+0x12dfb4) [0x5605ef303fb4]
34  /opt/conda/envs/gdf/bin/python(+0x14c8cb) [0x5605ef3228cb]
35  /opt/conda/envs/gdf/bin/python(PyObject_Call+0xbc) [0x5605ef32304c]
36  /opt/conda/envs/gdf/bin/python(+0x21080e) [0x5605ef3e680e]
37  /opt/conda/envs/gdf/bin/python(_PyObject_MakeTpCall+0x2ec) [0x5605ef30d6ac]
38  /opt/conda/envs/gdf/bin/python(_PyEval_EvalFrameDefault+0x45a6) [0x5605ef3093f6]
39  /opt/conda/envs/gdf/bin/python(+0x13f712) [0x5605ef315712]
40  /opt/conda/envs/gdf/bin/python(+0x14c9ac) [0x5605ef3229ac]
41  /opt/conda/envs/gdf/bin/python(_PyEval_EvalFrameDefault+0x45a6) [0x5605ef3093f6]
42  /opt/conda/envs/gdf/bin/python(+0x13f712) [0x5605ef315712]
43  /opt/conda/envs/gdf/bin/python(_PyEval_EvalFrameDefault+0x696) [0x5605ef3054e6]
44  /opt/conda/envs/gdf/bin/python(+0x12dfb4) [0x5605ef303fb4]
45  /opt/conda/envs/gdf/bin/python(_PyFunction_Vectorcall+0xd9) [0x5605ef315469]
46  /opt/conda/envs/gdf/bin/python(_PyEval_EvalFrameDefault+0x696) [0x5605ef3054e6]
47  /opt/conda/envs/gdf/bin/python(+0x13f712) [0x5605ef315712]
48  /opt/conda/envs/gdf/bin/python(_PyEval_EvalFrameDefault+0x3e2) [0x5605ef305232]
49  /opt/conda/envs/gdf/bin/python(+0x12dfb4) [0x5605ef303fb4]
50  /opt/conda/envs/gdf/bin/python(_PyFunction_Vectorcall+0xd9) [0x5605ef315469]
51  /opt/conda/envs/gdf/bin/python(_PyEval_EvalFrameDefault+0x11f2) [0x5605ef306042]
52  /opt/conda/envs/gdf/bin/python(+0x12dfb4) [0x5605ef303fb4]
53  /opt/conda/envs/gdf/bin/python(_PyEval_EvalCodeWithName+0x48) [0x5605ef303c88]
54  /opt/conda/envs/gdf/bin/python(PyEval_EvalCodeEx+0x39) [0x5605ef303c39]
55  /opt/conda/envs/gdf/bin/python(PyEval_EvalCode+0x1b) [0x5605ef3b12cb]
56  /opt/conda/envs/gdf/bin/python(+0x2086ca) [0x5605ef3de6ca]
57  /opt/conda/envs/gdf/bin/python(+0x204a63) [0x5605ef3daa63]
58  /opt/conda/envs/gdf/bin/python(PyRun_StringFlags+0x9a) [0x5605ef3d287a]
59  /opt/conda/envs/gdf/bin/python(PyRun_SimpleStringFlags+0x3c) [0x5605ef3d276c]
60  /opt/conda/envs/gdf/bin/python(Py_RunMain+0x267) [0x5605ef3d19a7]
61  /opt/conda/envs/gdf/bin/python(Py_BytesMain+0x37) [0x5605ef3a5107]
=================================
2024-02-07 07:55:07,507 - distributed.worker - ERROR - failed during get data with ucx://127.0.0.1:41713 -> ucx://127.0.0.1:56001
Traceback (most recent call last):
  File "/opt/conda/envs/gdf/lib/python3.9/site-packages/distributed/comm/ucx.py", line 334, in write
    await self.ep.send(each_frame)
  File "/opt/conda/envs/gdf/lib/python3.9/site-packages/ucp/core.py", line 662, in send
    return await comm.tag_send(self._ep, buffer, nbytes, tag, name=log)
ucp._libs.exceptions.UCXError: <[Send #007] ep: 0x7f7f52d1e280, tag: 0x1c446c9499c8b4a7, nbytes: 50000000, type: <class 'cupy.ndarray'>>: Connection reset by remote peer

During handling of the above exception, another exception occurred:

Traceback (most recent call last):
  File "/opt/conda/envs/gdf/lib/python3.9/site-packages/distributed/worker.py", line 1779, in get_data
    compressed = await comm.write(msg, serializers=serializers)
  File "/opt/conda/envs/gdf/lib/python3.9/site-packages/distributed/utils.py", line 832, in wrapper
    return await func(*args, **kwargs)
  File "/opt/conda/envs/gdf/lib/python3.9/site-packages/distributed/comm/ucx.py", line 338, in write
    raise CommClosedError("While writing, the connection was closed")
distributed.comm.core.CommClosedError: While writing, the connection was closed
Task exception was never retrieved
future: <Task finished name='Task-270' coro=<_listener_handler_coroutine() done, defined at /opt/conda/envs/gdf/lib/python3.9/site-packages/ucp/core.py:140> exception=UCXError('<stream_send>: Connection reset by remote peer')>
Traceback (most recent call last):
  File "/opt/conda/envs/gdf/lib/python3.9/site-packages/ucp/core.py", line 155, in _listener_handler_coroutine
    peer_info = await exchange_peer_info(
  File "/opt/conda/envs/gdf/lib/python3.9/site-packages/ucp/core.py", line 51, in exchange_peer_info
    await asyncio.wait_for(
  File "/opt/conda/envs/gdf/lib/python3.9/asyncio/tasks.py", line 479, in wait_for
    return fut.result()
ucp._libs.exceptions.UCXError: <stream_send>: Connection reset by remote peer
2024-02-07 07:55:07,513 - distributed.worker - ERROR - Worker stream died during communication: ucx://127.0.0.1:56001
Traceback (most recent call last):
  File "/opt/conda/envs/gdf/lib/python3.9/site-packages/distributed/comm/ucx.py", line 467, in connect
    ep = await ucp.create_endpoint(ip, port)
  File "/opt/conda/envs/gdf/lib/python3.9/site-packages/ucp/core.py", line 1016, in create_endpoint
    return await _get_ctx().create_endpoint(
  File "/opt/conda/envs/gdf/lib/python3.9/site-packages/ucp/core.py", line 328, in create_endpoint
    peer_info = await exchange_peer_info(
  File "/opt/conda/envs/gdf/lib/python3.9/site-packages/ucp/core.py", line 60, in exchange_peer_info
    await asyncio.wait_for(
  File "/opt/conda/envs/gdf/lib/python3.9/asyncio/tasks.py", line 479, in wait_for
    return fut.result()
ucp._libs.exceptions.UCXError: <stream_recv>: Connection reset by remote peer

During handling of the above exception, another exception occurred:

Traceback (most recent call last):
  File "/opt/conda/envs/gdf/lib/python3.9/site-packages/distributed/comm/core.py", line 342, in connect
    comm = await wait_for(
  File "/opt/conda/envs/gdf/lib/python3.9/site-packages/distributed/utils.py", line 1940, in wait_for
    return await asyncio.wait_for(fut, timeout)
  File "/opt/conda/envs/gdf/lib/python3.9/asyncio/tasks.py", line 479, in wait_for
    return fut.result()
  File "/opt/conda/envs/gdf/lib/python3.9/site-packages/distributed/comm/ucx.py", line 469, in connect
    raise CommClosedError("Connection closed before handshake completed")
distributed.comm.core.CommClosedError: Connection closed before handshake completed

During handling of the above exception, another exception occurred:

Traceback (most recent call last):
  File "/opt/conda/envs/gdf/lib/python3.9/site-packages/distributed/core.py", line 1564, in _connect
    comm = await connect(
  File "/opt/conda/envs/gdf/lib/python3.9/site-packages/distributed/comm/core.py", line 366, in connect
    await asyncio.sleep(backoff)
  File "/opt/conda/envs/gdf/lib/python3.9/asyncio/tasks.py", line 652, in sleep
    return await future
asyncio.exceptions.CancelledError

During handling of the above exception, another exception occurred:

Traceback (most recent call last):
  File "/opt/conda/envs/gdf/lib/python3.9/site-packages/distributed/core.py", line 1674, in connect
    return connect_attempt.result()
asyncio.exceptions.CancelledError

During handling of the above exception, another exception occurred:

Traceback (most recent call last):
  File "/opt/conda/envs/gdf/lib/python3.9/site-packages/distributed/worker.py", line 2056, in gather_dep
    response = await get_data_from_worker(
  File "/opt/conda/envs/gdf/lib/python3.9/site-packages/distributed/worker.py", line 2857, in get_data_from_worker
    comm = await rpc.connect(worker)
  File "/opt/conda/envs/gdf/lib/python3.9/site-packages/distributed/core.py", line 1676, in connect
    raise CommClosedError(reason)
distributed.comm.core.CommClosedError: Address removed.
Task exception was never retrieved
future: <Task finished name='Task-292' coro=<_listener_handler_coroutine() done, defined at /opt/conda/envs/gdf/lib/python3.9/site-packages/ucp/core.py:140> exception=UCXError('<stream_recv>: Connection reset by remote peer')>
Traceback (most recent call last):
  File "/opt/conda/envs/gdf/lib/python3.9/site-packages/ucp/core.py", line 155, in _listener_handler_coroutine
    peer_info = await exchange_peer_info(
  File "/opt/conda/envs/gdf/lib/python3.9/site-packages/ucp/core.py", line 55, in exchange_peer_info
    await asyncio.wait_for(
  File "/opt/conda/envs/gdf/lib/python3.9/asyncio/tasks.py", line 479, in wait_for
    return fut.result()
ucp._libs.exceptions.UCXError: <stream_recv>: Connection reset by remote peer
2024-02-07 07:55:07,583 - distributed.worker - ERROR - failed during get data with ucx://127.0.0.1:53983 -> ucx://127.0.0.1:52755
Traceback (most recent call last):
  File "/opt/conda/envs/gdf/lib/python3.9/site-packages/distributed/comm/ucx.py", line 334, in write
    await self.ep.send(each_frame)
  File "/opt/conda/envs/gdf/lib/python3.9/site-packages/ucp/core.py", line 662, in send
    return await comm.tag_send(self._ep, buffer, nbytes, tag, name=log)
ucp._libs.exceptions.UCXError: <[Send #007] ep: 0x7fe686209100, tag: 0x7129a31d252167b7, nbytes: 50000000, type: <class 'cupy.ndarray'>>: Connection reset by remote peer

During handling of the above exception, another exception occurred:

Traceback (most recent call last):
  File "/opt/conda/envs/gdf/lib/python3.9/site-packages/distributed/worker.py", line 1779, in get_data
    compressed = await comm.write(msg, serializers=serializers)
  File "/opt/conda/envs/gdf/lib/python3.9/site-packages/distributed/utils.py", line 832, in wrapper
    return await func(*args, **kwargs)
  File "/opt/conda/envs/gdf/lib/python3.9/site-packages/distributed/comm/ucx.py", line 338, in write
    raise CommClosedError("While writing, the connection was closed")
distributed.comm.core.CommClosedError: While writing, the connection was closed
2024-02-07 07:55:07,584 - distributed.worker - ERROR - Worker stream died during communication: ucx://127.0.0.1:52755
Traceback (most recent call last):
  File "/opt/conda/envs/gdf/lib/python3.9/site-packages/distributed/comm/ucx.py", line 350, in read
    await self.ep.recv(msg)
  File "/opt/conda/envs/gdf/lib/python3.9/site-packages/ucp/core.py", line 737, in recv
    ret = await comm.tag_recv(self._ep, buffer, nbytes, tag, name=log)
ucp._libs.exceptions.UCXCanceled: <[Recv #003] ep: 0x7fe686209280, tag: 0xba8e50b16099a531, nbytes: 16, type: <class 'numpy.ndarray'>>: 

During handling of the above exception, another exception occurred:

Traceback (most recent call last):
  File "/opt/conda/envs/gdf/lib/python3.9/site-packages/distributed/worker.py", line 2056, in gather_dep
    response = await get_data_from_worker(
  File "/opt/conda/envs/gdf/lib/python3.9/site-packages/distributed/worker.py", line 2860, in get_data_from_worker
    response = await send_recv(
  File "/opt/conda/envs/gdf/lib/python3.9/site-packages/distributed/core.py", line 1154, in send_recv
    response = await comm.read(deserializers=deserializers)
  File "/opt/conda/envs/gdf/lib/python3.9/site-packages/distributed/utils.py", line 832, in wrapper
    return await func(*args, **kwargs)
  File "/opt/conda/envs/gdf/lib/python3.9/site-packages/distributed/comm/ucx.py", line 368, in read
    raise CommClosedError(
distributed.comm.core.CommClosedError: Connection closed by writer.
Inner exception: UCXCanceled("<[Recv #003] ep: 0x7fe686209280, tag: 0xba8e50b16099a531, nbytes: 16, type: <class 'numpy.ndarray'>>: ")
2024-02-07 07:55:07,584 - distributed.worker - ERROR - Worker stream died during communication: ucx://127.0.0.1:52755
Traceback (most recent call last):
  File "/opt/conda/envs/gdf/lib/python3.9/site-packages/distributed/comm/ucx.py", line 350, in read
    await self.ep.recv(msg)
  File "/opt/conda/envs/gdf/lib/python3.9/site-packages/ucp/core.py", line 737, in recv
    ret = await comm.tag_recv(self._ep, buffer, nbytes, tag, name=log)
ucp._libs.exceptions.UCXCanceled: <[Recv #000] ep: 0x7f7f52d1e180, tag: 0x1cd1eba1bcf31a85, nbytes: 16, type: <class 'numpy.ndarray'>>: 

During handling of the above exception, another exception occurred:

Traceback (most recent call last):
  File "/opt/conda/envs/gdf/lib/python3.9/site-packages/distributed/worker.py", line 2056, in gather_dep
    response = await get_data_from_worker(
  File "/opt/conda/envs/gdf/lib/python3.9/site-packages/distributed/worker.py", line 2857, in get_data_from_worker
    comm = await rpc.connect(worker)
  File "/opt/conda/envs/gdf/lib/python3.9/site-packages/distributed/core.py", line 1674, in connect
    return connect_attempt.result()
  File "/opt/conda/envs/gdf/lib/python3.9/site-packages/distributed/core.py", line 1564, in _connect
    comm = await connect(
  File "/opt/conda/envs/gdf/lib/python3.9/site-packages/distributed/comm/core.py", line 377, in connect
    handshake = await comm.read()
  File "/opt/conda/envs/gdf/lib/python3.9/site-packages/distributed/utils.py", line 832, in wrapper
    return await func(*args, **kwargs)
  File "/opt/conda/envs/gdf/lib/python3.9/site-packages/distributed/comm/ucx.py", line 368, in read
    raise CommClosedError(
distributed.comm.core.CommClosedError: Connection closed by writer.
Inner exception: UCXCanceled("<[Recv #000] ep: 0x7f7f52d1e180, tag: 0x1cd1eba1bcf31a85, nbytes: 16, type: <class 'numpy.ndarray'>>: ")
2024-02-07 07:55:07,583 - distributed.worker - ERROR - Worker stream died during communication: ucx://127.0.0.1:52755
Traceback (most recent call last):
  File "/opt/conda/envs/gdf/lib/python3.9/site-packages/distributed/comm/ucx.py", line 350, in read
    await self.ep.recv(msg)
  File "/opt/conda/envs/gdf/lib/python3.9/site-packages/ucp/core.py", line 737, in recv
    ret = await comm.tag_recv(self._ep, buffer, nbytes, tag, name=log)
ucp._libs.exceptions.UCXCanceled: <[Recv #000] ep: 0x7f47e47eb180, tag: 0xf134a3cf4349bb57, nbytes: 16, type: <class 'numpy.ndarray'>>: 

During handling of the above exception, another exception occurred:

Traceback (most recent call last):
  File "/opt/conda/envs/gdf/lib/python3.9/site-packages/distributed/worker.py", line 2056, in gather_dep
    response = await get_data_from_worker(
  File "/opt/conda/envs/gdf/lib/python3.9/site-packages/distributed/worker.py", line 2857, in get_data_from_worker
    comm = await rpc.connect(worker)
  File "/opt/conda/envs/gdf/lib/python3.9/site-packages/distributed/core.py", line 1674, in connect
    return connect_attempt.result()
  File "/opt/conda/envs/gdf/lib/python3.9/site-packages/distributed/core.py", line 1564, in _connect
    comm = await connect(
  File "/opt/conda/envs/gdf/lib/python3.9/site-packages/distributed/comm/core.py", line 377, in connect
    handshake = await comm.read()
  File "/opt/conda/envs/gdf/lib/python3.9/site-packages/distributed/utils.py", line 832, in wrapper
    return await func(*args, **kwargs)
  File "/opt/conda/envs/gdf/lib/python3.9/site-packages/distributed/comm/ucx.py", line 368, in read
    raise CommClosedError(
distributed.comm.core.CommClosedError: Connection closed by writer.
Inner exception: UCXCanceled("<[Recv #000] ep: 0x7f47e47eb180, tag: 0xf134a3cf4349bb57, nbytes: 16, type: <class 'numpy.ndarray'>>: ")
2024-02-07 07:55:07,630 - distributed.worker - ERROR - Worker stream died during communication: ucx://127.0.0.1:58689
Traceback (most recent call last):
  File "/opt/conda/envs/gdf/lib/python3.9/site-packages/distributed/comm/ucx.py", line 392, in read
    await self.ep.recv(each_frame)
  File "/opt/conda/envs/gdf/lib/python3.9/site-packages/ucp/core.py", line 737, in recv
    ret = await comm.tag_recv(self._ep, buffer, nbytes, tag, name=log)
ucp._libs.exceptions.UCXError: <[Recv #007] ep: 0x7f7f52d1e200, tag: 0xf73a31607b51fb0e, nbytes: 50000000, type: <class 'rmm._lib.device_buffer.DeviceBuffer'>>: Connection reset by remote peer

During handling of the above exception, another exception occurred:

Traceback (most recent call last):
  File "/opt/conda/envs/gdf/lib/python3.9/site-packages/distributed/worker.py", line 2056, in gather_dep
    response = await get_data_from_worker(
  File "/opt/conda/envs/gdf/lib/python3.9/site-packages/distributed/worker.py", line 2860, in get_data_from_worker
    response = await send_recv(
  File "/opt/conda/envs/gdf/lib/python3.9/site-packages/distributed/core.py", line 1154, in send_recv
    response = await comm.read(deserializers=deserializers)
  File "/opt/conda/envs/gdf/lib/python3.9/site-packages/distributed/utils.py", line 832, in wrapper
    return await func(*args, **kwargs)
  File "/opt/conda/envs/gdf/lib/python3.9/site-packages/distributed/comm/ucx.py", line 398, in read
    raise CommClosedError(
distributed.comm.core.CommClosedError: Connection closed by writer.
Inner exception: UCXError("<[Recv #007] ep: 0x7f7f52d1e200, tag: 0xf73a31607b51fb0e, nbytes: 50000000, type: <class 'rmm._lib.device_buffer.DeviceBuffer'>>: Connection reset by remote peer")
2024-02-07 07:55:07,630 - distributed.worker - ERROR - failed during get data with ucx://127.0.0.1:53983 -> ucx://127.0.0.1:58689
Traceback (most recent call last):
  File "/opt/conda/envs/gdf/lib/python3.9/site-packages/distributed/comm/ucx.py", line 334, in write
    await self.ep.send(each_frame)
  File "/opt/conda/envs/gdf/lib/python3.9/site-packages/ucp/core.py", line 662, in send
    return await comm.tag_send(self._ep, buffer, nbytes, tag, name=log)
ucp._libs.exceptions.UCXError: <[Send #007] ep: 0x7fe686209300, tag: 0x938740b045aa49e2, nbytes: 50000000, type: <class 'cupy.ndarray'>>: Connection reset by remote peer

During handling of the above exception, another exception occurred:

Traceback (most recent call last):
  File "/opt/conda/envs/gdf/lib/python3.9/site-packages/distributed/worker.py", line 1779, in get_data
    compressed = await comm.write(msg, serializers=serializers)
  File "/opt/conda/envs/gdf/lib/python3.9/site-packages/distributed/utils.py", line 832, in wrapper
    return await func(*args, **kwargs)
  File "/opt/conda/envs/gdf/lib/python3.9/site-packages/distributed/comm/ucx.py", line 338, in write
    raise CommClosedError("While writing, the connection was closed")
distributed.comm.core.CommClosedError: While writing, the connection was closed
2024-02-07 07:55:07,630 - distributed.worker - ERROR - Worker stream died during communication: ucx://127.0.0.1:58689
Traceback (most recent call last):
  File "/opt/conda/envs/gdf/lib/python3.9/site-packages/distributed/comm/ucx.py", line 350, in read
    await self.ep.recv(msg)
  File "/opt/conda/envs/gdf/lib/python3.9/site-packages/ucp/core.py", line 737, in recv
    ret = await comm.tag_recv(self._ep, buffer, nbytes, tag, name=log)
ucp._libs.exceptions.UCXCanceled: <[Recv #008] ep: 0x7f47e47eb100, tag: 0xae30178ec50ff421, nbytes: 16, type: <class 'numpy.ndarray'>>: 

During handling of the above exception, another exception occurred:

Traceback (most recent call last):
  File "/opt/conda/envs/gdf/lib/python3.9/site-packages/distributed/worker.py", line 2056, in gather_dep
    response = await get_data_from_worker(
  File "/opt/conda/envs/gdf/lib/python3.9/site-packages/distributed/worker.py", line 2860, in get_data_from_worker
    response = await send_recv(
  File "/opt/conda/envs/gdf/lib/python3.9/site-packages/distributed/core.py", line 1154, in send_recv
    response = await comm.read(deserializers=deserializers)
  File "/opt/conda/envs/gdf/lib/python3.9/site-packages/distributed/utils.py", line 832, in wrapper
    return await func(*args, **kwargs)
  File "/opt/conda/envs/gdf/lib/python3.9/site-packages/distributed/comm/ucx.py", line 368, in read
    raise CommClosedError(
distributed.comm.core.CommClosedError: Connection closed by writer.
Inner exception: UCXCanceled("<[Recv #008] ep: 0x7f47e47eb100, tag: 0xae30178ec50ff421, nbytes: 16, type: <class 'numpy.ndarray'>>: ")
2024-02-07 07:55:07,631 - distributed.worker - ERROR - failed during get data with ucx://127.0.0.1:41713 -> ucx://127.0.0.1:58689
Traceback (most recent call last):
  File "/opt/conda/envs/gdf/lib/python3.9/site-packages/distributed/comm/ucx.py", line 334, in write
    await self.ep.send(each_frame)
  File "/opt/conda/envs/gdf/lib/python3.9/site-packages/ucp/core.py", line 662, in send
    return await comm.tag_send(self._ep, buffer, nbytes, tag, name=log)
ucp._libs.exceptions.UCXError: <[Send #007] ep: 0x7f7f52d1e2c0, tag: 0xa8d86fb5dfde5e03, nbytes: 50000000, type: <class 'cupy.ndarray'>>: Connection reset by remote peer

During handling of the above exception, another exception occurred:

Traceback (most recent call last):
  File "/opt/conda/envs/gdf/lib/python3.9/site-packages/distributed/worker.py", line 1779, in get_data
    compressed = await comm.write(msg, serializers=serializers)
  File "/opt/conda/envs/gdf/lib/python3.9/site-packages/distributed/utils.py", line 832, in wrapper
    return await func(*args, **kwargs)
  File "/opt/conda/envs/gdf/lib/python3.9/site-packages/distributed/comm/ucx.py", line 338, in write
    raise CommClosedError("While writing, the connection was closed")
distributed.comm.core.CommClosedError: While writing, the connection was closed
2024-02-07 07:55:07,631 - distributed.worker - ERROR - Worker stream died during communication: ucx://127.0.0.1:58689
Traceback (most recent call last):
  File "/opt/conda/envs/gdf/lib/python3.9/site-packages/distributed/comm/ucx.py", line 392, in read
    await self.ep.recv(each_frame)
  File "/opt/conda/envs/gdf/lib/python3.9/site-packages/ucp/core.py", line 737, in recv
    ret = await comm.tag_recv(self._ep, buffer, nbytes, tag, name=log)
ucp._libs.exceptions.UCXError: <[Recv #007] ep: 0x7fe6862092c0, tag: 0x8b83aabb25ff75df, nbytes: 50000000, type: <class 'rmm._lib.device_buffer.DeviceBuffer'>>: Connection reset by remote peer

During handling of the above exception, another exception occurred:

Traceback (most recent call last):
  File "/opt/conda/envs/gdf/lib/python3.9/site-packages/distributed/worker.py", line 2056, in gather_dep
    response = await get_data_from_worker(
  File "/opt/conda/envs/gdf/lib/python3.9/site-packages/distributed/worker.py", line 2860, in get_data_from_worker
    response = await send_recv(
  File "/opt/conda/envs/gdf/lib/python3.9/site-packages/distributed/core.py", line 1154, in send_recv
    response = await comm.read(deserializers=deserializers)
  File "/opt/conda/envs/gdf/lib/python3.9/site-packages/distributed/utils.py", line 832, in wrapper
    return await func(*args, **kwargs)
  File "/opt/conda/envs/gdf/lib/python3.9/site-packages/distributed/comm/ucx.py", line 398, in read
    raise CommClosedError(
distributed.comm.core.CommClosedError: Connection closed by writer.
Inner exception: UCXError("<[Recv #007] ep: 0x7fe6862092c0, tag: 0x8b83aabb25ff75df, nbytes: 50000000, type: <class 'rmm._lib.device_buffer.DeviceBuffer'>>: Connection reset by remote peer")
2024-02-07 07:55:07,690 - distributed.worker - ERROR - Worker stream died during communication: ucx://127.0.0.1:47223
Traceback (most recent call last):
  File "/opt/conda/envs/gdf/lib/python3.9/site-packages/distributed/comm/ucx.py", line 350, in read
    await self.ep.recv(msg)
  File "/opt/conda/envs/gdf/lib/python3.9/site-packages/ucp/core.py", line 737, in recv
    ret = await comm.tag_recv(self._ep, buffer, nbytes, tag, name=log)
ucp._libs.exceptions.UCXCanceled: <[Recv #008] ep: 0x7fe6862091c0, tag: 0xf74331c406074f77, nbytes: 16, type: <class 'numpy.ndarray'>>: 

During handling of the above exception, another exception occurred:

Traceback (most recent call last):
  File "/opt/conda/envs/gdf/lib/python3.9/site-packages/distributed/worker.py", line 2056, in gather_dep
    response = await get_data_from_worker(
  File "/opt/conda/envs/gdf/lib/python3.9/site-packages/distributed/worker.py", line 2860, in get_data_from_worker
    response = await send_recv(
  File "/opt/conda/envs/gdf/lib/python3.9/site-packages/distributed/core.py", line 1154, in send_recv
    response = await comm.read(deserializers=deserializers)
  File "/opt/conda/envs/gdf/lib/python3.9/site-packages/distributed/utils.py", line 832, in wrapper
    return await func(*args, **kwargs)
  File "/opt/conda/envs/gdf/lib/python3.9/site-packages/distributed/comm/ucx.py", line 368, in read
    raise CommClosedError(
distributed.comm.core.CommClosedError: Connection closed by writer.
Inner exception: UCXCanceled("<[Recv #008] ep: 0x7fe6862091c0, tag: 0xf74331c406074f77, nbytes: 16, type: <class 'numpy.ndarray'>>: ")
2024-02-07 07:55:07,692 - distributed.worker - ERROR - Worker stream died during communication: ucx://127.0.0.1:56519
Traceback (most recent call last):
  File "/opt/conda/envs/gdf/lib/python3.9/site-packages/distributed/comm/ucx.py", line 392, in read
    await self.ep.recv(each_frame)
  File "/opt/conda/envs/gdf/lib/python3.9/site-packages/ucp/core.py", line 737, in recv
    ret = await comm.tag_recv(self._ep, buffer, nbytes, tag, name=log)
ucp._libs.exceptions.UCXError: <[Recv #007] ep: 0x7f7f52d1e140, tag: 0x6a34492ae2b3449e, nbytes: 50000000, type: <class 'rmm._lib.device_buffer.DeviceBuffer'>>: Connection reset by remote peer

During handling of the above exception, another exception occurred:

Traceback (most recent call last):
  File "/opt/conda/envs/gdf/lib/python3.9/site-packages/distributed/worker.py", line 2056, in gather_dep
    response = await get_data_from_worker(
  File "/opt/conda/envs/gdf/lib/python3.9/site-packages/distributed/worker.py", line 2860, in get_data_from_worker
    response = await send_recv(
  File "/opt/conda/envs/gdf/lib/python3.9/site-packages/distributed/core.py", line 1154, in send_recv
    response = await comm.read(deserializers=deserializers)
  File "/opt/conda/envs/gdf/lib/python3.9/site-packages/distributed/utils.py", line 832, in wrapper
    return await func(*args, **kwargs)
  File "/opt/conda/envs/gdf/lib/python3.9/site-packages/distributed/comm/ucx.py", line 398, in read
    raise CommClosedError(
distributed.comm.core.CommClosedError: Connection closed by writer.
Inner exception: UCXError("<[Recv #007] ep: 0x7f7f52d1e140, tag: 0x6a34492ae2b3449e, nbytes: 50000000, type: <class 'rmm._lib.device_buffer.DeviceBuffer'>>: Connection reset by remote peer")
2024-02-07 07:55:07,692 - distributed.worker - ERROR - Worker stream died during communication: ucx://127.0.0.1:56519
Traceback (most recent call last):
  File "/opt/conda/envs/gdf/lib/python3.9/site-packages/distributed/comm/ucx.py", line 392, in read
    await self.ep.recv(each_frame)
  File "/opt/conda/envs/gdf/lib/python3.9/site-packages/ucp/core.py", line 737, in recv
    ret = await comm.tag_recv(self._ep, buffer, nbytes, tag, name=log)
ucp._libs.exceptions.UCXError: <[Recv #007] ep: 0x7f47e47eb1c0, tag: 0x9bfbdc4d5d5958c1, nbytes: 50000000, type: <class 'rmm._lib.device_buffer.DeviceBuffer'>>: Connection reset by remote peer

During handling of the above exception, another exception occurred:

Traceback (most recent call last):
  File "/opt/conda/envs/gdf/lib/python3.9/site-packages/distributed/worker.py", line 2056, in gather_dep
    response = await get_data_from_worker(
  File "/opt/conda/envs/gdf/lib/python3.9/site-packages/distributed/worker.py", line 2860, in get_data_from_worker
    response = await send_recv(
  File "/opt/conda/envs/gdf/lib/python3.9/site-packages/distributed/core.py", line 1154, in send_recv
    response = await comm.read(deserializers=deserializers)
  File "/opt/conda/envs/gdf/lib/python3.9/site-packages/distributed/utils.py", line 832, in wrapper
    return await func(*args, **kwargs)
  File "/opt/conda/envs/gdf/lib/python3.9/site-packages/distributed/comm/ucx.py", line 398, in read
    raise CommClosedError(
distributed.comm.core.CommClosedError: Connection closed by writer.
Inner exception: UCXError("<[Recv #007] ep: 0x7f47e47eb1c0, tag: 0x9bfbdc4d5d5958c1, nbytes: 50000000, type: <class 'rmm._lib.device_buffer.DeviceBuffer'>>: Connection reset by remote peer")
2024-02-07 07:55:07,692 - distributed.worker - ERROR - Worker stream died during communication: ucx://127.0.0.1:56519
Traceback (most recent call last):
  File "/opt/conda/envs/gdf/lib/python3.9/site-packages/distributed/comm/ucx.py", line 350, in read
    await self.ep.recv(msg)
  File "/opt/conda/envs/gdf/lib/python3.9/site-packages/ucp/core.py", line 737, in recv
    ret = await comm.tag_recv(self._ep, buffer, nbytes, tag, name=log)
ucp._libs.exceptions.UCXCanceled: <[Recv #003] ep: 0x7fe686209200, tag: 0xb07b171a958deefa, nbytes: 16, type: <class 'numpy.ndarray'>>: 

During handling of the above exception, another exception occurred:

Traceback (most recent call last):
  File "/opt/conda/envs/gdf/lib/python3.9/site-packages/distributed/worker.py", line 2056, in gather_dep
    response = await get_data_from_worker(
  File "/opt/conda/envs/gdf/lib/python3.9/site-packages/distributed/worker.py", line 2860, in get_data_from_worker
    response = await send_recv(
  File "/opt/conda/envs/gdf/lib/python3.9/site-packages/distributed/core.py", line 1154, in send_recv
    response = await comm.read(deserializers=deserializers)
  File "/opt/conda/envs/gdf/lib/python3.9/site-packages/distributed/utils.py", line 832, in wrapper
    return await func(*args, **kwargs)
  File "/opt/conda/envs/gdf/lib/python3.9/site-packages/distributed/comm/ucx.py", line 368, in read
    raise CommClosedError(
distributed.comm.core.CommClosedError: Connection closed by writer.
Inner exception: UCXCanceled("<[Recv #003] ep: 0x7fe686209200, tag: 0xb07b171a958deefa, nbytes: 16, type: <class 'numpy.ndarray'>>: ")
2024-02-07 07:55:07,693 - distributed.worker - ERROR - failed during get data with ucx://127.0.0.1:41713 -> ucx://127.0.0.1:56519
Traceback (most recent call last):
  File "/opt/conda/envs/gdf/lib/python3.9/site-packages/distributed/comm/ucx.py", line 334, in write
    await self.ep.send(each_frame)
  File "/opt/conda/envs/gdf/lib/python3.9/site-packages/ucp/core.py", line 662, in send
    return await comm.tag_send(self._ep, buffer, nbytes, tag, name=log)
ucp._libs.exceptions.UCXError: <[Send #007] ep: 0x7f7f52d1e240, tag: 0x52653331a0f6d02b, nbytes: 50000000, type: <class 'cupy.ndarray'>>: Connection reset by remote peer

During handling of the above exception, another exception occurred:

Traceback (most recent call last):
  File "/opt/conda/envs/gdf/lib/python3.9/site-packages/distributed/worker.py", line 1779, in get_data
    compressed = await comm.write(msg, serializers=serializers)
  File "/opt/conda/envs/gdf/lib/python3.9/site-packages/distributed/utils.py", line 832, in wrapper
    return await func(*args, **kwargs)
  File "/opt/conda/envs/gdf/lib/python3.9/site-packages/distributed/comm/ucx.py", line 338, in write
    raise CommClosedError("While writing, the connection was closed")
distributed.comm.core.CommClosedError: While writing, the connection was closed
2024-02-07 07:55:07,693 - distributed.worker - ERROR - failed during get data with ucx://127.0.0.1:41331 -> ucx://127.0.0.1:56519
Traceback (most recent call last):
  File "/opt/conda/envs/gdf/lib/python3.9/site-packages/distributed/comm/ucx.py", line 334, in write
    await self.ep.send(each_frame)
  File "/opt/conda/envs/gdf/lib/python3.9/site-packages/ucp/core.py", line 662, in send
    return await comm.tag_send(self._ep, buffer, nbytes, tag, name=log)
ucp._libs.exceptions.UCXError: <[Send #007] ep: 0x7f47e47eb240, tag: 0x8f092ff790a80235, nbytes: 50000000, type: <class 'cupy.ndarray'>>: Connection reset by remote peer

During handling of the above exception, another exception occurred:

Traceback (most recent call last):
  File "/opt/conda/envs/gdf/lib/python3.9/site-packages/distributed/worker.py", line 1779, in get_data
    compressed = await comm.write(msg, serializers=serializers)
  File "/opt/conda/envs/gdf/lib/python3.9/site-packages/distributed/utils.py", line 832, in wrapper
    return await func(*args, **kwargs)
  File "/opt/conda/envs/gdf/lib/python3.9/site-packages/distributed/comm/ucx.py", line 338, in write
    raise CommClosedError("While writing, the connection was closed")
distributed.comm.core.CommClosedError: While writing, the connection was closed
2024-02-07 07:55:09,999 - distributed.nanny - WARNING - Restarting worker
2024-02-07 07:55:10,046 - distributed.nanny - WARNING - Restarting worker
2024-02-07 07:55:10,250 - distributed.nanny - WARNING - Restarting worker
2024-02-07 07:55:10,289 - distributed.nanny - WARNING - Restarting worker
2024-02-07 07:55:10,336 - distributed.nanny - WARNING - Restarting worker
[dgx13:84121:0:84121] Caught signal 11 (Segmentation fault: address not mapped to object at address 0x448)
==== backtrace (tid:  84121) ====
 0  /opt/conda/envs/gdf/lib/libucs.so.0(ucs_handle_error+0x2fd) [0x7fe2844ba07d]
 1  /opt/conda/envs/gdf/lib/libucs.so.0(+0x2a274) [0x7fe2844ba274]
 2  /opt/conda/envs/gdf/lib/libucs.so.0(+0x2a43a) [0x7fe2844ba43a]
 3  /usr/lib/x86_64-linux-gnu/libpthread.so.0(+0x14420) [0x7fe2af013420]
 4  /opt/conda/envs/gdf/lib/libucp.so.0(ucp_mem_type_unpack+0x14) [0x7fe2845396b4]
 5  /opt/conda/envs/gdf/lib/libucp.so.0(ucp_rndv_data_handler+0x4e9) [0x7fe284562839]
 6  /opt/conda/envs/gdf/lib/libuct.so.0(+0x203df) [0x7fe2844743df]
 7  /opt/conda/envs/gdf/lib/libuct.so.0(+0x23838) [0x7fe284477838]
 8  /opt/conda/envs/gdf/lib/libucs.so.0(ucs_event_set_wait+0xb9) [0x7fe2844c34a9]
 9  /opt/conda/envs/gdf/lib/libuct.so.0(uct_tcp_iface_progress+0x7d) [0x7fe2844765dd]
10  /opt/conda/envs/gdf/lib/libucp.so.0(ucp_worker_progress+0x5a) [0x7fe2845368da]
11  /opt/conda/envs/gdf/lib/python3.9/site-packages/ucp/_libs/ucx_api.cpython-39-x86_64-linux-gnu.so(+0x3206a) [0x7fe2845ef06a]
12  /opt/conda/envs/gdf/bin/python(_PyEval_EvalFrameDefault+0x45a6) [0x558e8fa883f6]
13  /opt/conda/envs/gdf/bin/python(+0x12dfb4) [0x558e8fa82fb4]
14  /opt/conda/envs/gdf/bin/python(_PyFunction_Vectorcall+0xd9) [0x558e8fa94469]
15  /opt/conda/envs/gdf/bin/python(_PyEval_EvalFrameDefault+0x696) [0x558e8fa844e6]
16  /opt/conda/envs/gdf/bin/python(+0x13f712) [0x558e8fa94712]
17  /opt/conda/envs/gdf/bin/python(+0x14ca83) [0x558e8faa1a83]
18  /opt/conda/envs/gdf/bin/python(+0x25819c) [0x558e8fbad19c]
19  /opt/conda/envs/gdf/bin/python(+0xf23ff) [0x558e8fa473ff]
20  /opt/conda/envs/gdf/bin/python(+0x136723) [0x558e8fa8b723]
21  /opt/conda/envs/gdf/bin/python(_PyEval_EvalFrameDefault+0x5ad9) [0x558e8fa89929]
22  /opt/conda/envs/gdf/bin/python(+0x13f712) [0x558e8fa94712]
23  /opt/conda/envs/gdf/bin/python(_PyEval_EvalFrameDefault+0x696) [0x558e8fa844e6]
24  /opt/conda/envs/gdf/bin/python(+0x13f712) [0x558e8fa94712]
25  /opt/conda/envs/gdf/bin/python(_PyEval_EvalFrameDefault+0x696) [0x558e8fa844e6]
26  /opt/conda/envs/gdf/bin/python(+0x13f712) [0x558e8fa94712]
27  /opt/conda/envs/gdf/bin/python(_PyEval_EvalFrameDefault+0x696) [0x558e8fa844e6]
28  /opt/conda/envs/gdf/bin/python(+0x13f712) [0x558e8fa94712]
29  /opt/conda/envs/gdf/bin/python(_PyEval_EvalFrameDefault+0x696) [0x558e8fa844e6]
30  /opt/conda/envs/gdf/bin/python(+0x12dfb4) [0x558e8fa82fb4]
31  /opt/conda/envs/gdf/bin/python(_PyFunction_Vectorcall+0xd9) [0x558e8fa94469]
32  /opt/conda/envs/gdf/bin/python(_PyEval_EvalFrameDefault+0x11f2) [0x558e8fa85042]
33  /opt/conda/envs/gdf/bin/python(+0x12dfb4) [0x558e8fa82fb4]
34  /opt/conda/envs/gdf/bin/python(+0x14c8cb) [0x558e8faa18cb]
35  /opt/conda/envs/gdf/bin/python(PyObject_Call+0xbc) [0x558e8faa204c]
36  /opt/conda/envs/gdf/bin/python(+0x21080e) [0x558e8fb6580e]
37  /opt/conda/envs/gdf/bin/python(_PyObject_MakeTpCall+0x2ec) [0x558e8fa8c6ac]
38  /opt/conda/envs/gdf/bin/python(_PyEval_EvalFrameDefault+0x45a6) [0x558e8fa883f6]
39  /opt/conda/envs/gdf/bin/python(+0x13f712) [0x558e8fa94712]
40  /opt/conda/envs/gdf/bin/python(+0x14c9ac) [0x558e8faa19ac]
41  /opt/conda/envs/gdf/bin/python(_PyEval_EvalFrameDefault+0x45a6) [0x558e8fa883f6]
42  /opt/conda/envs/gdf/bin/python(+0x13f712) [0x558e8fa94712]
43  /opt/conda/envs/gdf/bin/python(_PyEval_EvalFrameDefault+0x696) [0x558e8fa844e6]
44  /opt/conda/envs/gdf/bin/python(+0x12dfb4) [0x558e8fa82fb4]
45  /opt/conda/envs/gdf/bin/python(_PyFunction_Vectorcall+0xd9) [0x558e8fa94469]
46  /opt/conda/envs/gdf/bin/python(_PyEval_EvalFrameDefault+0x696) [0x558e8fa844e6]
47  /opt/conda/envs/gdf/bin/python(+0x13f712) [0x558e8fa94712]
48  /opt/conda/envs/gdf/bin/python(_PyEval_EvalFrameDefault+0x3e2) [0x558e8fa84232]
49  /opt/conda/envs/gdf/bin/python(+0x12dfb4) [0x558e8fa82fb4]
50  /opt/conda/envs/gdf/bin/python(_PyFunction_Vectorcall+0xd9) [0x558e8fa94469]
51  /opt/conda/envs/gdf/bin/python(_PyEval_EvalFrameDefault+0x11f2) [0x558e8fa85042]
52  /opt/conda/envs/gdf/bin/python(+0x12dfb4) [0x558e8fa82fb4]
53  /opt/conda/envs/gdf/bin/python(_PyEval_EvalCodeWithName+0x48) [0x558e8fa82c88]
54  /opt/conda/envs/gdf/bin/python(PyEval_EvalCodeEx+0x39) [0x558e8fa82c39]
55  /opt/conda/envs/gdf/bin/python(PyEval_EvalCode+0x1b) [0x558e8fb302cb]
56  /opt/conda/envs/gdf/bin/python(+0x2086ca) [0x558e8fb5d6ca]
57  /opt/conda/envs/gdf/bin/python(+0x204a63) [0x558e8fb59a63]
58  /opt/conda/envs/gdf/bin/python(PyRun_StringFlags+0x9a) [0x558e8fb5187a]
59  /opt/conda/envs/gdf/bin/python(PyRun_SimpleStringFlags+0x3c) [0x558e8fb5176c]
60  /opt/conda/envs/gdf/bin/python(Py_RunMain+0x267) [0x558e8fb509a7]
61  /opt/conda/envs/gdf/bin/python(Py_BytesMain+0x37) [0x558e8fb24107]
=================================
[dgx13:84135:0:84135] Caught signal 11 (Segmentation fault: address not mapped to object at address 0x448)
==== backtrace (tid:  84135) ====
 0  /opt/conda/envs/gdf/lib/libucs.so.0(ucs_handle_error+0x2fd) [0x7f434978607d]
 1  /opt/conda/envs/gdf/lib/libucs.so.0(+0x2a274) [0x7f4349786274]
 2  /opt/conda/envs/gdf/lib/libucs.so.0(+0x2a43a) [0x7f434978643a]
 3  /usr/lib/x86_64-linux-gnu/libpthread.so.0(+0x14420) [0x7f438646e420]
 4  /opt/conda/envs/gdf/lib/libucp.so.0(ucp_mem_type_unpack+0x14) [0x7f43498056b4]
 5  /opt/conda/envs/gdf/lib/libucp.so.0(ucp_rndv_data_handler+0x4e9) [0x7f434982e839]
 6  /opt/conda/envs/gdf/lib/libuct.so.0(+0x203df) [0x7f43497403df]
 7  /opt/conda/envs/gdf/lib/libuct.so.0(+0x23838) [0x7f4349743838]
 8  /opt/conda/envs/gdf/lib/libucs.so.0(ucs_event_set_wait+0xb9) [0x7f434978f4a9]
 9  /opt/conda/envs/gdf/lib/libuct.so.0(uct_tcp_iface_progress+0x7d) [0x7f43497425dd]
10  /opt/conda/envs/gdf/lib/libucp.so.0(ucp_worker_progress+0x5a) [0x7f43498028da]
11  /opt/conda/envs/gdf/lib/python3.9/site-packages/ucp/_libs/ucx_api.cpython-39-x86_64-linux-gnu.so(+0x3206a) [0x7f43498bb06a]
12  /opt/conda/envs/gdf/bin/python(_PyEval_EvalFrameDefault+0x45a6) [0x55e84f5f73f6]
13  /opt/conda/envs/gdf/bin/python(+0x12dfb4) [0x55e84f5f1fb4]
14  /opt/conda/envs/gdf/bin/python(_PyFunction_Vectorcall+0xd9) [0x55e84f603469]
15  /opt/conda/envs/gdf/bin/python(_PyEval_EvalFrameDefault+0x696) [0x55e84f5f34e6]
16  /opt/conda/envs/gdf/bin/python(+0x13f712) [0x55e84f603712]
17  /opt/conda/envs/gdf/bin/python(+0x14ca83) [0x55e84f610a83]
18  /opt/conda/envs/gdf/bin/python(+0x25819c) [0x55e84f71c19c]
19  /opt/conda/envs/gdf/bin/python(+0xf23ff) [0x55e84f5b63ff]
20  /opt/conda/envs/gdf/bin/python(+0x136723) [0x55e84f5fa723]
21  /opt/conda/envs/gdf/bin/python(_PyEval_EvalFrameDefault+0x5ad9) [0x55e84f5f8929]
22  /opt/conda/envs/gdf/bin/python(+0x13f712) [0x55e84f603712]
23  /opt/conda/envs/gdf/bin/python(_PyEval_EvalFrameDefault+0x696) [0x55e84f5f34e6]
24  /opt/conda/envs/gdf/bin/python(+0x13f712) [0x55e84f603712]
25  /opt/conda/envs/gdf/bin/python(_PyEval_EvalFrameDefault+0x696) [0x55e84f5f34e6]
26  /opt/conda/envs/gdf/bin/python(+0x13f712) [0x55e84f603712]
27  /opt/conda/envs/gdf/bin/python(_PyEval_EvalFrameDefault+0x696) [0x55e84f5f34e6]
28  /opt/conda/envs/gdf/bin/python(+0x13f712) [0x55e84f603712]
29  /opt/conda/envs/gdf/bin/python(_PyEval_EvalFrameDefault+0x696) [0x55e84f5f34e6]
30  /opt/conda/envs/gdf/bin/python(+0x12dfb4) [0x55e84f5f1fb4]
31  /opt/conda/envs/gdf/bin/python(_PyFunction_Vectorcall+0xd9) [0x55e84f603469]
32  /opt/conda/envs/gdf/bin/python(_PyEval_EvalFrameDefault+0x11f2) [0x55e84f5f4042]
33  /opt/conda/envs/gdf/bin/python(+0x12dfb4) [0x55e84f5f1fb4]
34  /opt/conda/envs/gdf/bin/python(+0x14c8cb) [0x55e84f6108cb]
35  /opt/conda/envs/gdf/bin/python(PyObject_Call+0xbc) [0x55e84f61104c]
36  /opt/conda/envs/gdf/bin/python(+0x21080e) [0x55e84f6d480e]
37  /opt/conda/envs/gdf/bin/python(_PyObject_MakeTpCall+0x2ec) [0x55e84f5fb6ac]
38  /opt/conda/envs/gdf/bin/python(_PyEval_EvalFrameDefault+0x45a6) [0x55e84f5f73f6]
39  /opt/conda/envs/gdf/bin/python(+0x13f712) [0x55e84f603712]
40  /opt/conda/envs/gdf/bin/python(+0x14c9ac) [0x55e84f6109ac]
41  /opt/conda/envs/gdf/bin/python(_PyEval_EvalFrameDefault+0x45a6) [0x55e84f5f73f6]
42  /opt/conda/envs/gdf/bin/python(+0x13f712) [0x55e84f603712]
43  /opt/conda/envs/gdf/bin/python(_PyEval_EvalFrameDefault+0x696) [0x55e84f5f34e6]
44  /opt/conda/envs/gdf/bin/python(+0x12dfb4) [0x55e84f5f1fb4]
45  /opt/conda/envs/gdf/bin/python(_PyFunction_Vectorcall+0xd9) [0x55e84f603469]
46  /opt/conda/envs/gdf/bin/python(_PyEval_EvalFrameDefault+0x696) [0x55e84f5f34e6]
47  /opt/conda/envs/gdf/bin/python(+0x13f712) [0x55e84f603712]
48  /opt/conda/envs/gdf/bin/python(_PyEval_EvalFrameDefault+0x3e2) [0x55e84f5f3232]
49  /opt/conda/envs/gdf/bin/python(+0x12dfb4) [0x55e84f5f1fb4]
50  /opt/conda/envs/gdf/bin/python(_PyFunction_Vectorcall+0xd9) [0x55e84f603469]
51  /opt/conda/envs/gdf/bin/python(_PyEval_EvalFrameDefault+0x11f2) [0x55e84f5f4042]
52  /opt/conda/envs/gdf/bin/python(+0x12dfb4) [0x55e84f5f1fb4]
53  /opt/conda/envs/gdf/bin/python(_PyEval_EvalCodeWithName+0x48) [0x55e84f5f1c88]
54  /opt/conda/envs/gdf/bin/python(PyEval_EvalCodeEx+0x39) [0x55e84f5f1c39]
55  /opt/conda/envs/gdf/bin/python(PyEval_EvalCode+0x1b) [0x55e84f69f2cb]
56  /opt/conda/envs/gdf/bin/python(+0x2086ca) [0x55e84f6cc6ca]
57  /opt/conda/envs/gdf/bin/python(+0x204a63) [0x55e84f6c8a63]
58  /opt/conda/envs/gdf/bin/python(PyRun_StringFlags+0x9a) [0x55e84f6c087a]
59  /opt/conda/envs/gdf/bin/python(PyRun_SimpleStringFlags+0x3c) [0x55e84f6c076c]
60  /opt/conda/envs/gdf/bin/python(Py_RunMain+0x267) [0x55e84f6bf9a7]
61  /opt/conda/envs/gdf/bin/python(Py_BytesMain+0x37) [0x55e84f693107]
=================================
[dgx13:84139:0:84139] Caught signal 11 (Segmentation fault: address not mapped to object at address 0x448)
==== backtrace (tid:  84139) ====
 0  /opt/conda/envs/gdf/lib/libucs.so.0(ucs_handle_error+0x2fd) [0x7fc93c5d007d]
 1  /opt/conda/envs/gdf/lib/libucs.so.0(+0x2a274) [0x7fc93c5d0274]
 2  /opt/conda/envs/gdf/lib/libucs.so.0(+0x2a43a) [0x7fc93c5d043a]
 3  /usr/lib/x86_64-linux-gnu/libpthread.so.0(+0x14420) [0x7fc9752a7420]
 4  /opt/conda/envs/gdf/lib/libucp.so.0(ucp_mem_type_unpack+0x14) [0x7fc93c64f6b4]
 5  /opt/conda/envs/gdf/lib/libucp.so.0(ucp_rndv_data_handler+0x4e9) [0x7fc93c678839]
 6  /opt/conda/envs/gdf/lib/libuct.so.0(+0x203df) [0x7fc93c58a3df]
 7  /opt/conda/envs/gdf/lib/libuct.so.0(+0x23838) [0x7fc93c58d838]
 8  /opt/conda/envs/gdf/lib/libucs.so.0(ucs_event_set_wait+0xb9) [0x7fc93c5d94a9]
 9  /opt/conda/envs/gdf/lib/libuct.so.0(uct_tcp_iface_progress+0x7d) [0x7fc93c58c5dd]
10  /opt/conda/envs/gdf/lib/libucp.so.0(ucp_worker_progress+0x5a) [0x7fc93c64c8da]
11  /opt/conda/envs/gdf/lib/python3.9/site-packages/ucp/_libs/ucx_api.cpython-39-x86_64-linux-gnu.so(+0x3206a) [0x7fc93c70506a]
12  /opt/conda/envs/gdf/bin/python(_PyEval_EvalFrameDefault+0x45a6) [0x559ab5b5b3f6]
13  /opt/conda/envs/gdf/bin/python(+0x12dfb4) [0x559ab5b55fb4]
14  /opt/conda/envs/gdf/bin/python(_PyFunction_Vectorcall+0xd9) [0x559ab5b67469]
15  /opt/conda/envs/gdf/bin/python(_PyEval_EvalFrameDefault+0x696) [0x559ab5b574e6]
16  /opt/conda/envs/gdf/bin/python(+0x13f712) [0x559ab5b67712]
17  /opt/conda/envs/gdf/bin/python(+0x14ca83) [0x559ab5b74a83]
18  /opt/conda/envs/gdf/bin/python(+0x25819c) [0x559ab5c8019c]
19  /opt/conda/envs/gdf/bin/python(+0xf23ff) [0x559ab5b1a3ff]
20  /opt/conda/envs/gdf/bin/python(+0x136723) [0x559ab5b5e723]
21  /opt/conda/envs/gdf/bin/python(_PyEval_EvalFrameDefault+0x5ad9) [0x559ab5b5c929]
22  /opt/conda/envs/gdf/bin/python(+0x13f712) [0x559ab5b67712]
23  /opt/conda/envs/gdf/bin/python(_PyEval_EvalFrameDefault+0x696) [0x559ab5b574e6]
24  /opt/conda/envs/gdf/bin/python(+0x13f712) [0x559ab5b67712]
25  /opt/conda/envs/gdf/bin/python(_PyEval_EvalFrameDefault+0x696) [0x559ab5b574e6]
26  /opt/conda/envs/gdf/bin/python(+0x13f712) [0x559ab5b67712]
27  /opt/conda/envs/gdf/bin/python(_PyEval_EvalFrameDefault+0x696) [0x559ab5b574e6]
28  /opt/conda/envs/gdf/bin/python(+0x13f712) [0x559ab5b67712]
29  /opt/conda/envs/gdf/bin/python(_PyEval_EvalFrameDefault+0x696) [0x559ab5b574e6]
30  /opt/conda/envs/gdf/bin/python(+0x12dfb4) [0x559ab5b55fb4]
31  /opt/conda/envs/gdf/bin/python(_PyFunction_Vectorcall+0xd9) [0x559ab5b67469]
32  /opt/conda/envs/gdf/bin/python(_PyEval_EvalFrameDefault+0x11f2) [0x559ab5b58042]
33  /opt/conda/envs/gdf/bin/python(+0x12dfb4) [0x559ab5b55fb4]
34  /opt/conda/envs/gdf/bin/python(+0x14c8cb) [0x559ab5b748cb]
35  /opt/conda/envs/gdf/bin/python(PyObject_Call+0xbc) [0x559ab5b7504c]
36  /opt/conda/envs/gdf/bin/python(+0x21080e) [0x559ab5c3880e]
37  /opt/conda/envs/gdf/bin/python(_PyObject_MakeTpCall+0x2ec) [0x559ab5b5f6ac]
38  /opt/conda/envs/gdf/bin/python(_PyEval_EvalFrameDefault+0x45a6) [0x559ab5b5b3f6]
39  /opt/conda/envs/gdf/bin/python(+0x13f712) [0x559ab5b67712]
40  /opt/conda/envs/gdf/bin/python(+0x14c9ac) [0x559ab5b749ac]
41  /opt/conda/envs/gdf/bin/python(_PyEval_EvalFrameDefault+0x45a6) [0x559ab5b5b3f6]
42  /opt/conda/envs/gdf/bin/python(+0x13f712) [0x559ab5b67712]
43  /opt/conda/envs/gdf/bin/python(_PyEval_EvalFrameDefault+0x696) [0x559ab5b574e6]
44  /opt/conda/envs/gdf/bin/python(+0x12dfb4) [0x559ab5b55fb4]
45  /opt/conda/envs/gdf/bin/python(_PyFunction_Vectorcall+0xd9) [0x559ab5b67469]
46  /opt/conda/envs/gdf/bin/python(_PyEval_EvalFrameDefault+0x696) [0x559ab5b574e6]
47  /opt/conda/envs/gdf/bin/python(+0x13f712) [0x559ab5b67712]
48  /opt/conda/envs/gdf/bin/python(_PyEval_EvalFrameDefault+0x3e2) [0x559ab5b57232]
49  /opt/conda/envs/gdf/bin/python(+0x12dfb4) [0x559ab5b55fb4]
50  /opt/conda/envs/gdf/bin/python(_PyFunction_Vectorcall+0xd9) [0x559ab5b67469]
51  /opt/conda/envs/gdf/bin/python(_PyEval_EvalFrameDefault+0x11f2) [0x559ab5b58042]
52  /opt/conda/envs/gdf/bin/python(+0x12dfb4) [0x559ab5b55fb4]
53  /opt/conda/envs/gdf/bin/python(_PyEval_EvalCodeWithName+0x48) [0x559ab5b55c88]
54  /opt/conda/envs/gdf/bin/python(PyEval_EvalCodeEx+0x39) [0x559ab5b55c39]
55  /opt/conda/envs/gdf/bin/python(PyEval_EvalCode+0x1b) [0x559ab5c032cb]
56  /opt/conda/envs/gdf/bin/python(+0x2086ca) [0x559ab5c306ca]
57  /opt/conda/envs/gdf/bin/python(+0x204a63) [0x559ab5c2ca63]
58  /opt/conda/envs/gdf/bin/python(PyRun_StringFlags+0x9a) [0x559ab5c2487a]
59  /opt/conda/envs/gdf/bin/python(PyRun_SimpleStringFlags+0x3c) [0x559ab5c2476c]
60  /opt/conda/envs/gdf/bin/python(Py_RunMain+0x267) [0x559ab5c239a7]
61  /opt/conda/envs/gdf/bin/python(Py_BytesMain+0x37) [0x559ab5bf7107]
=================================
2024-02-07 07:55:13,659 - distributed.worker - ERROR - Worker stream died during communication: ucx://127.0.0.1:52931
Traceback (most recent call last):
  File "/opt/conda/envs/gdf/lib/python3.9/site-packages/distributed/comm/ucx.py", line 392, in read
    await self.ep.recv(each_frame)
  File "/opt/conda/envs/gdf/lib/python3.9/site-packages/ucp/core.py", line 737, in recv
    ret = await comm.tag_recv(self._ep, buffer, nbytes, tag, name=log)
ucp._libs.exceptions.UCXError: <[Recv #007] ep: 0x7f7f52d1e200, tag: 0xc89b974ded874ac0, nbytes: 50000000, type: <class 'rmm._lib.device_buffer.DeviceBuffer'>>: Connection reset by remote peer

During handling of the above exception, another exception occurred:

Traceback (most recent call last):
  File "/opt/conda/envs/gdf/lib/python3.9/site-packages/distributed/worker.py", line 2056, in gather_dep
    response = await get_data_from_worker(
  File "/opt/conda/envs/gdf/lib/python3.9/site-packages/distributed/worker.py", line 2860, in get_data_from_worker
    response = await send_recv(
  File "/opt/conda/envs/gdf/lib/python3.9/site-packages/distributed/core.py", line 1154, in send_recv
    response = await comm.read(deserializers=deserializers)
  File "/opt/conda/envs/gdf/lib/python3.9/site-packages/distributed/utils.py", line 832, in wrapper
    return await func(*args, **kwargs)
  File "/opt/conda/envs/gdf/lib/python3.9/site-packages/distributed/comm/ucx.py", line 398, in read
    raise CommClosedError(
distributed.comm.core.CommClosedError: Connection closed by writer.
Inner exception: UCXError("<[Recv #007] ep: 0x7f7f52d1e200, tag: 0xc89b974ded874ac0, nbytes: 50000000, type: <class 'rmm._lib.device_buffer.DeviceBuffer'>>: Connection reset by remote peer")
2024-02-07 07:55:13,659 - distributed.worker - ERROR - failed during get data with ucx://127.0.0.1:41331 -> ucx://127.0.0.1:52931
Traceback (most recent call last):
  File "/opt/conda/envs/gdf/lib/python3.9/site-packages/distributed/comm/ucx.py", line 334, in write
    await self.ep.send(each_frame)
  File "/opt/conda/envs/gdf/lib/python3.9/site-packages/ucp/core.py", line 662, in send
    return await comm.tag_send(self._ep, buffer, nbytes, tag, name=log)
ucp._libs.exceptions.UCXError: <[Send #007] ep: 0x7f47e47eb2c0, tag: 0xfa65b95f7bce3e73, nbytes: 50000000, type: <class 'cupy.ndarray'>>: Connection reset by remote peer

During handling of the above exception, another exception occurred:

Traceback (most recent call last):
  File "/opt/conda/envs/gdf/lib/python3.9/site-packages/distributed/worker.py", line 1779, in get_data
    compressed = await comm.write(msg, serializers=serializers)
  File "/opt/conda/envs/gdf/lib/python3.9/site-packages/distributed/utils.py", line 832, in wrapper
    return await func(*args, **kwargs)
  File "/opt/conda/envs/gdf/lib/python3.9/site-packages/distributed/comm/ucx.py", line 338, in write
    raise CommClosedError("While writing, the connection was closed")
distributed.comm.core.CommClosedError: While writing, the connection was closed
2024-02-07 07:55:13,693 - distributed.worker - ERROR - failed during get data with ucx://127.0.0.1:41713 -> ucx://127.0.0.1:45915
Traceback (most recent call last):
  File "/opt/conda/envs/gdf/lib/python3.9/site-packages/distributed/comm/ucx.py", line 334, in write
    await self.ep.send(each_frame)
  File "/opt/conda/envs/gdf/lib/python3.9/site-packages/ucp/core.py", line 662, in send
    return await comm.tag_send(self._ep, buffer, nbytes, tag, name=log)
ucp._libs.exceptions.UCXError: <[Send #007] ep: 0x7f7f52d1e180, tag: 0x51e5d579750f6877, nbytes: 50000000, type: <class 'cupy.ndarray'>>: Connection reset by remote peer

During handling of the above exception, another exception occurred:

Traceback (most recent call last):
  File "/opt/conda/envs/gdf/lib/python3.9/site-packages/distributed/worker.py", line 1779, in get_data
    compressed = await comm.write(msg, serializers=serializers)
  File "/opt/conda/envs/gdf/lib/python3.9/site-packages/distributed/utils.py", line 832, in wrapper
    return await func(*args, **kwargs)
  File "/opt/conda/envs/gdf/lib/python3.9/site-packages/distributed/comm/ucx.py", line 338, in write
    raise CommClosedError("While writing, the connection was closed")
distributed.comm.core.CommClosedError: While writing, the connection was closed
2024-02-07 07:55:13,861 - distributed.worker - ERROR - failed during get data with ucx://127.0.0.1:41331 -> ucx://127.0.0.1:43411
Traceback (most recent call last):
  File "/opt/conda/envs/gdf/lib/python3.9/site-packages/distributed/comm/ucx.py", line 334, in write
    await self.ep.send(each_frame)
  File "/opt/conda/envs/gdf/lib/python3.9/site-packages/ucp/core.py", line 662, in send
    return await comm.tag_send(self._ep, buffer, nbytes, tag, name=log)
ucp._libs.exceptions.UCXError: <[Send #007] ep: 0x7f47e47eb180, tag: 0xa52a12cbda5bf2dd, nbytes: 50000000, type: <class 'cupy.ndarray'>>: Connection reset by remote peer

During handling of the above exception, another exception occurred:

Traceback (most recent call last):
  File "/opt/conda/envs/gdf/lib/python3.9/site-packages/distributed/worker.py", line 1779, in get_data
    compressed = await comm.write(msg, serializers=serializers)
  File "/opt/conda/envs/gdf/lib/python3.9/site-packages/distributed/utils.py", line 832, in wrapper
    return await func(*args, **kwargs)
  File "/opt/conda/envs/gdf/lib/python3.9/site-packages/distributed/comm/ucx.py", line 338, in write
    raise CommClosedError("While writing, the connection was closed")
distributed.comm.core.CommClosedError: While writing, the connection was closed
2024-02-07 07:55:13,861 - distributed.worker - ERROR - Worker stream died during communication: ucx://127.0.0.1:43411
Traceback (most recent call last):
  File "/opt/conda/envs/gdf/lib/python3.9/site-packages/distributed/comm/ucx.py", line 392, in read
    await self.ep.recv(each_frame)
  File "/opt/conda/envs/gdf/lib/python3.9/site-packages/ucp/core.py", line 737, in recv
    ret = await comm.tag_recv(self._ep, buffer, nbytes, tag, name=log)
ucp._libs.exceptions.UCXError: <[Recv #007] ep: 0x7f47e47eb100, tag: 0x49aab5dd297bb467, nbytes: 50000000, type: <class 'rmm._lib.device_buffer.DeviceBuffer'>>: Connection reset by remote peer

During handling of the above exception, another exception occurred:

Traceback (most recent call last):
  File "/opt/conda/envs/gdf/lib/python3.9/site-packages/distributed/worker.py", line 2056, in gather_dep
    response = await get_data_from_worker(
  File "/opt/conda/envs/gdf/lib/python3.9/site-packages/distributed/worker.py", line 2860, in get_data_from_worker
    response = await send_recv(
  File "/opt/conda/envs/gdf/lib/python3.9/site-packages/distributed/core.py", line 1154, in send_recv
    response = await comm.read(deserializers=deserializers)
  File "/opt/conda/envs/gdf/lib/python3.9/site-packages/distributed/utils.py", line 832, in wrapper
    return await func(*args, **kwargs)
  File "/opt/conda/envs/gdf/lib/python3.9/site-packages/distributed/comm/ucx.py", line 398, in read
    raise CommClosedError(
distributed.comm.core.CommClosedError: Connection closed by writer.
Inner exception: UCXError("<[Recv #007] ep: 0x7f47e47eb100, tag: 0x49aab5dd297bb467, nbytes: 50000000, type: <class 'rmm._lib.device_buffer.DeviceBuffer'>>: Connection reset by remote peer")
[dgx13:84131:0:84131] Caught signal 11 (Segmentation fault: address not mapped to object at address 0x448)
==== backtrace (tid:  84131) ====
 0  /opt/conda/envs/gdf/lib/libucs.so.0(ucs_handle_error+0x2fd) [0x7f25f8cda07d]
 1  /opt/conda/envs/gdf/lib/libucs.so.0(+0x2a274) [0x7f25f8cda274]
 2  /opt/conda/envs/gdf/lib/libucs.so.0(+0x2a43a) [0x7f25f8cda43a]
 3  /usr/lib/x86_64-linux-gnu/libpthread.so.0(+0x14420) [0x7f26239b6420]
 4  /opt/conda/envs/gdf/lib/libucp.so.0(ucp_mem_type_unpack+0x14) [0x7f25f8d596b4]
 5  /opt/conda/envs/gdf/lib/libucp.so.0(ucp_rndv_data_handler+0x4e9) [0x7f25f8d82839]
 6  /opt/conda/envs/gdf/lib/libuct.so.0(+0x203df) [0x7f25f8c943df]
 7  /opt/conda/envs/gdf/lib/libuct.so.0(+0x23838) [0x7f25f8c97838]
 8  /opt/conda/envs/gdf/lib/libucs.so.0(ucs_event_set_wait+0xb9) [0x7f25f8ce34a9]
 9  /opt/conda/envs/gdf/lib/libuct.so.0(uct_tcp_iface_progress+0x7d) [0x7f25f8c965dd]
10  /opt/conda/envs/gdf/lib/libucp.so.0(ucp_worker_progress+0x5a) [0x7f25f8d568da]
11  /opt/conda/envs/gdf/lib/python3.9/site-packages/ucp/_libs/ucx_api.cpython-39-x86_64-linux-gnu.so(+0x3206a) [0x7f25f8e0f06a]
12  /opt/conda/envs/gdf/bin/python(_PyEval_EvalFrameDefault+0x45a6) [0x55a5bb1963f6]
13  /opt/conda/envs/gdf/bin/python(+0x12dfb4) [0x55a5bb190fb4]
14  /opt/conda/envs/gdf/bin/python(_PyFunction_Vectorcall+0xd9) [0x55a5bb1a2469]
15  /opt/conda/envs/gdf/bin/python(_PyEval_EvalFrameDefault+0x696) [0x55a5bb1924e6]
16  /opt/conda/envs/gdf/bin/python(+0x1e26d2) [0x55a5bb2456d2]
17  /opt/conda/envs/gdf/lib/python3.9/lib-dynload/_asyncio.cpython-39-x86_64-linux-gnu.so(+0x81e9) [0x7f260df571e9]
18  /opt/conda/envs/gdf/bin/python(_PyObject_MakeTpCall+0x2ec) [0x55a5bb19a6ac]
19  /opt/conda/envs/gdf/bin/python(+0xf23ff) [0x55a5bb1553ff]
20  /opt/conda/envs/gdf/bin/python(+0x136723) [0x55a5bb199723]
21  /opt/conda/envs/gdf/bin/python(_PyEval_EvalFrameDefault+0x5ad9) [0x55a5bb197929]
22  /opt/conda/envs/gdf/bin/python(+0x13f712) [0x55a5bb1a2712]
23  /opt/conda/envs/gdf/bin/python(_PyEval_EvalFrameDefault+0x696) [0x55a5bb1924e6]
24  /opt/conda/envs/gdf/bin/python(+0x13f712) [0x55a5bb1a2712]
25  /opt/conda/envs/gdf/bin/python(_PyEval_EvalFrameDefault+0x696) [0x55a5bb1924e6]
26  /opt/conda/envs/gdf/bin/python(+0x13f712) [0x55a5bb1a2712]
27  /opt/conda/envs/gdf/bin/python(_PyEval_EvalFrameDefault+0x696) [0x55a5bb1924e6]
28  /opt/conda/envs/gdf/bin/python(+0x13f712) [0x55a5bb1a2712]
29  /opt/conda/envs/gdf/bin/python(_PyEval_EvalFrameDefault+0x696) [0x55a5bb1924e6]
30  /opt/conda/envs/gdf/bin/python(+0x12dfb4) [0x55a5bb190fb4]
31  /opt/conda/envs/gdf/bin/python(_PyFunction_Vectorcall+0xd9) [0x55a5bb1a2469]
32  /opt/conda/envs/gdf/bin/python(_PyEval_EvalFrameDefault+0x11f2) [0x55a5bb193042]
33  /opt/conda/envs/gdf/bin/python(+0x12dfb4) [0x55a5bb190fb4]
34  /opt/conda/envs/gdf/bin/python(+0x14c8cb) [0x55a5bb1af8cb]
35  /opt/conda/envs/gdf/bin/python(PyObject_Call+0xbc) [0x55a5bb1b004c]
36  /opt/conda/envs/gdf/bin/python(+0x21080e) [0x55a5bb27380e]
37  /opt/conda/envs/gdf/bin/python(_PyObject_MakeTpCall+0x2ec) [0x55a5bb19a6ac]
38  /opt/conda/envs/gdf/bin/python(_PyEval_EvalFrameDefault+0x45a6) [0x55a5bb1963f6]
39  /opt/conda/envs/gdf/bin/python(+0x13f712) [0x55a5bb1a2712]
40  /opt/conda/envs/gdf/bin/python(+0x14c9ac) [0x55a5bb1af9ac]
41  /opt/conda/envs/gdf/bin/python(_PyEval_EvalFrameDefault+0x45a6) [0x55a5bb1963f6]
42  /opt/conda/envs/gdf/bin/python(+0x13f712) [0x55a5bb1a2712]
43  /opt/conda/envs/gdf/bin/python(_PyEval_EvalFrameDefault+0x696) [0x55a5bb1924e6]
44  /opt/conda/envs/gdf/bin/python(+0x12dfb4) [0x55a5bb190fb4]
45  /opt/conda/envs/gdf/bin/python(_PyFunction_Vectorcall+0xd9) [0x55a5bb1a2469]
46  /opt/conda/envs/gdf/bin/python(_PyEval_EvalFrameDefault+0x696) [0x55a5bb1924e6]
47  /opt/conda/envs/gdf/bin/python(+0x13f712) [0x55a5bb1a2712]
48  /opt/conda/envs/gdf/bin/python(_PyEval_EvalFrameDefault+0x3e2) [0x55a5bb192232]
49  /opt/conda/envs/gdf/bin/python(+0x12dfb4) [0x55a5bb190fb4]
50  /opt/conda/envs/gdf/bin/python(_PyFunction_Vectorcall+0xd9) [0x55a5bb1a2469]
51  /opt/conda/envs/gdf/bin/python(_PyEval_EvalFrameDefault+0x11f2) [0x55a5bb193042]
52  /opt/conda/envs/gdf/bin/python(+0x12dfb4) [0x55a5bb190fb4]
53  /opt/conda/envs/gdf/bin/python(_PyEval_EvalCodeWithName+0x48) [0x55a5bb190c88]
54  /opt/conda/envs/gdf/bin/python(PyEval_EvalCodeEx+0x39) [0x55a5bb190c39]
55  /opt/conda/envs/gdf/bin/python(PyEval_EvalCode+0x1b) [0x55a5bb23e2cb]
56  /opt/conda/envs/gdf/bin/python(+0x2086ca) [0x55a5bb26b6ca]
57  /opt/conda/envs/gdf/bin/python(+0x204a63) [0x55a5bb267a63]
58  /opt/conda/envs/gdf/bin/python(PyRun_StringFlags+0x9a) [0x55a5bb25f87a]
59  /opt/conda/envs/gdf/bin/python(PyRun_SimpleStringFlags+0x3c) [0x55a5bb25f76c]
60  /opt/conda/envs/gdf/bin/python(Py_RunMain+0x267) [0x55a5bb25e9a7]
61  /opt/conda/envs/gdf/bin/python(Py_BytesMain+0x37) [0x55a5bb232107]
=================================
2024-02-07 07:55:14,207 - distributed.worker - ERROR - failed during get data with ucx://127.0.0.1:41331 -> ucx://127.0.0.1:54813
Traceback (most recent call last):
  File "/opt/conda/envs/gdf/lib/python3.9/site-packages/distributed/comm/ucx.py", line 334, in write
    await self.ep.send(each_frame)
  File "/opt/conda/envs/gdf/lib/python3.9/site-packages/ucp/core.py", line 662, in send
    return await comm.tag_send(self._ep, buffer, nbytes, tag, name=log)
ucp._libs.exceptions.UCXError: <[Send #007] ep: 0x7f47e47eb340, tag: 0xc52d6f084e7ffa4b, nbytes: 50000000, type: <class 'cupy.ndarray'>>: Connection reset by remote peer

During handling of the above exception, another exception occurred:

Traceback (most recent call last):
  File "/opt/conda/envs/gdf/lib/python3.9/site-packages/distributed/worker.py", line 1779, in get_data
    compressed = await comm.write(msg, serializers=serializers)
  File "/opt/conda/envs/gdf/lib/python3.9/site-packages/distributed/utils.py", line 832, in wrapper
    return await func(*args, **kwargs)
  File "/opt/conda/envs/gdf/lib/python3.9/site-packages/distributed/comm/ucx.py", line 338, in write
    raise CommClosedError("While writing, the connection was closed")
distributed.comm.core.CommClosedError: While writing, the connection was closed
2024-02-07 07:55:14,207 - distributed.worker - ERROR - Worker stream died during communication: ucx://127.0.0.1:54813
Traceback (most recent call last):
  File "/opt/conda/envs/gdf/lib/python3.9/site-packages/distributed/comm/ucx.py", line 350, in read
    await self.ep.recv(msg)
  File "/opt/conda/envs/gdf/lib/python3.9/site-packages/ucp/core.py", line 737, in recv
    ret = await comm.tag_recv(self._ep, buffer, nbytes, tag, name=log)
ucp._libs.exceptions.UCXCanceled: <[Recv #003] ep: 0x7f7f52d1e180, tag: 0xb06987de8b74d050, nbytes: 16, type: <class 'numpy.ndarray'>>: 

During handling of the above exception, another exception occurred:

Traceback (most recent call last):
  File "/opt/conda/envs/gdf/lib/python3.9/site-packages/distributed/worker.py", line 2056, in gather_dep
    response = await get_data_from_worker(
  File "/opt/conda/envs/gdf/lib/python3.9/site-packages/distributed/worker.py", line 2860, in get_data_from_worker
    response = await send_recv(
  File "/opt/conda/envs/gdf/lib/python3.9/site-packages/distributed/core.py", line 1154, in send_recv
    response = await comm.read(deserializers=deserializers)
  File "/opt/conda/envs/gdf/lib/python3.9/site-packages/distributed/utils.py", line 832, in wrapper
    return await func(*args, **kwargs)
  File "/opt/conda/envs/gdf/lib/python3.9/site-packages/distributed/comm/ucx.py", line 368, in read
    raise CommClosedError(
distributed.comm.core.CommClosedError: Connection closed by writer.
Inner exception: UCXCanceled("<[Recv #003] ep: 0x7f7f52d1e180, tag: 0xb06987de8b74d050, nbytes: 16, type: <class 'numpy.ndarray'>>: ")
2024-02-07 07:55:14,208 - distributed.worker - ERROR - Worker stream died during communication: ucx://127.0.0.1:54813
Traceback (most recent call last):
  File "/opt/conda/envs/gdf/lib/python3.9/site-packages/distributed/comm/ucx.py", line 350, in read
    await self.ep.recv(msg)
  File "/opt/conda/envs/gdf/lib/python3.9/site-packages/ucp/core.py", line 737, in recv
    ret = await comm.tag_recv(self._ep, buffer, nbytes, tag, name=log)
ucp._libs.exceptions.UCXCanceled: <[Recv #003] ep: 0x7f47e47eb2c0, tag: 0x30a903b4d34946d5, nbytes: 16, type: <class 'numpy.ndarray'>>: 

During handling of the above exception, another exception occurred:

Traceback (most recent call last):
  File "/opt/conda/envs/gdf/lib/python3.9/site-packages/distributed/worker.py", line 2056, in gather_dep
    response = await get_data_from_worker(
  File "/opt/conda/envs/gdf/lib/python3.9/site-packages/distributed/worker.py", line 2860, in get_data_from_worker
    response = await send_recv(
  File "/opt/conda/envs/gdf/lib/python3.9/site-packages/distributed/core.py", line 1154, in send_recv
    response = await comm.read(deserializers=deserializers)
  File "/opt/conda/envs/gdf/lib/python3.9/site-packages/distributed/utils.py", line 832, in wrapper
    return await func(*args, **kwargs)
  File "/opt/conda/envs/gdf/lib/python3.9/site-packages/distributed/comm/ucx.py", line 368, in read
    raise CommClosedError(
distributed.comm.core.CommClosedError: Connection closed by writer.
Inner exception: UCXCanceled("<[Recv #003] ep: 0x7f47e47eb2c0, tag: 0x30a903b4d34946d5, nbytes: 16, type: <class 'numpy.ndarray'>>: ")
2024-02-07 07:55:16,468 - distributed.nanny - WARNING - Restarting worker
2024-02-07 07:55:16,500 - distributed.nanny - WARNING - Restarting worker
2024-02-07 07:55:16,543 - distributed.nanny - WARNING - Restarting worker
2024-02-07 07:55:16,611 - distributed.nanny - WARNING - Restarting worker
[dgx13:84216:0:84216] Caught signal 11 (Segmentation fault: address not mapped to object at address 0x448)
==== backtrace (tid:  84216) ====
 0  /opt/conda/envs/gdf/lib/libucs.so.0(ucs_handle_error+0x2fd) [0x7f4b6804a07d]
 1  /opt/conda/envs/gdf/lib/libucs.so.0(+0x2a274) [0x7f4b6804a274]
 2  /opt/conda/envs/gdf/lib/libucs.so.0(+0x2a43a) [0x7f4b6804a43a]
 3  /usr/lib/x86_64-linux-gnu/libpthread.so.0(+0x14420) [0x7f4b9fec6420]
 4  /opt/conda/envs/gdf/lib/libucp.so.0(ucp_mem_type_unpack+0x14) [0x7f4b633626b4]
 5  /opt/conda/envs/gdf/lib/libucp.so.0(ucp_rndv_data_handler+0x4e9) [0x7f4b6338b839]
 6  /opt/conda/envs/gdf/lib/libuct.so.0(+0x203df) [0x7f4b632fc3df]
 7  /opt/conda/envs/gdf/lib/libuct.so.0(+0x23838) [0x7f4b632ff838]
 8  /opt/conda/envs/gdf/lib/libucs.so.0(ucs_event_set_wait+0xb9) [0x7f4b680534a9]
 9  /opt/conda/envs/gdf/lib/libuct.so.0(uct_tcp_iface_progress+0x7d) [0x7f4b632fe5dd]
10  /opt/conda/envs/gdf/lib/libucp.so.0(ucp_worker_progress+0x5a) [0x7f4b6335f8da]
11  /opt/conda/envs/gdf/lib/python3.9/site-packages/ucp/_libs/ucx_api.cpython-39-x86_64-linux-gnu.so(+0x3206a) [0x7f4b6341806a]
12  /opt/conda/envs/gdf/bin/python(_PyEval_EvalFrameDefault+0x45a6) [0x560b3652a3f6]
13  /opt/conda/envs/gdf/bin/python(+0x12dfb4) [0x560b36524fb4]
14  /opt/conda/envs/gdf/bin/python(_PyFunction_Vectorcall+0xd9) [0x560b36536469]
15  /opt/conda/envs/gdf/bin/python(_PyEval_EvalFrameDefault+0x696) [0x560b365264e6]
16  /opt/conda/envs/gdf/bin/python(+0x13f712) [0x560b36536712]
17  /opt/conda/envs/gdf/bin/python(+0x14ca83) [0x560b36543a83]
18  /opt/conda/envs/gdf/bin/python(+0x25819c) [0x560b3664f19c]
19  /opt/conda/envs/gdf/bin/python(+0xf23ff) [0x560b364e93ff]
20  /opt/conda/envs/gdf/bin/python(+0x136723) [0x560b3652d723]
21  /opt/conda/envs/gdf/bin/python(_PyEval_EvalFrameDefault+0x5ad9) [0x560b3652b929]
22  /opt/conda/envs/gdf/bin/python(+0x13f712) [0x560b36536712]
23  /opt/conda/envs/gdf/bin/python(_PyEval_EvalFrameDefault+0x696) [0x560b365264e6]
24  /opt/conda/envs/gdf/bin/python(+0x13f712) [0x560b36536712]
25  /opt/conda/envs/gdf/bin/python(_PyEval_EvalFrameDefault+0x696) [0x560b365264e6]
26  /opt/conda/envs/gdf/bin/python(+0x13f712) [0x560b36536712]
27  /opt/conda/envs/gdf/bin/python(_PyEval_EvalFrameDefault+0x696) [0x560b365264e6]
28  /opt/conda/envs/gdf/bin/python(+0x13f712) [0x560b36536712]
29  /opt/conda/envs/gdf/bin/python(_PyEval_EvalFrameDefault+0x696) [0x560b365264e6]
30  /opt/conda/envs/gdf/bin/python(+0x12dfb4) [0x560b36524fb4]
31  /opt/conda/envs/gdf/bin/python(_PyFunction_Vectorcall+0xd9) [0x560b36536469]
32  /opt/conda/envs/gdf/bin/python(_PyEval_EvalFrameDefault+0x11f2) [0x560b36527042]
33  /opt/conda/envs/gdf/bin/python(+0x12dfb4) [0x560b36524fb4]
34  /opt/conda/envs/gdf/bin/python(+0x14c8cb) [0x560b365438cb]
35  /opt/conda/envs/gdf/bin/python(PyObject_Call+0xbc) [0x560b3654404c]
36  /opt/conda/envs/gdf/bin/python(+0x21080e) [0x560b3660780e]
37  /opt/conda/envs/gdf/bin/python(_PyObject_MakeTpCall+0x2ec) [0x560b3652e6ac]
38  /opt/conda/envs/gdf/bin/python(_PyEval_EvalFrameDefault+0x45a6) [0x560b3652a3f6]
39  /opt/conda/envs/gdf/bin/python(+0x13f712) [0x560b36536712]
40  /opt/conda/envs/gdf/bin/python(+0x14c9ac) [0x560b365439ac]
41  /opt/conda/envs/gdf/bin/python(_PyEval_EvalFrameDefault+0x45a6) [0x560b3652a3f6]
42  /opt/conda/envs/gdf/bin/python(+0x13f712) [0x560b36536712]
43  /opt/conda/envs/gdf/bin/python(_PyEval_EvalFrameDefault+0x696) [0x560b365264e6]
44  /opt/conda/envs/gdf/bin/python(+0x12dfb4) [0x560b36524fb4]
45  /opt/conda/envs/gdf/bin/python(_PyFunction_Vectorcall+0xd9) [0x560b36536469]
46  /opt/conda/envs/gdf/bin/python(_PyEval_EvalFrameDefault+0x696) [0x560b365264e6]
47  /opt/conda/envs/gdf/bin/python(+0x13f712) [0x560b36536712]
48  /opt/conda/envs/gdf/bin/python(_PyEval_EvalFrameDefault+0x3e2) [0x560b36526232]
49  /opt/conda/envs/gdf/bin/python(+0x12dfb4) [0x560b36524fb4]
50  /opt/conda/envs/gdf/bin/python(_PyFunction_Vectorcall+0xd9) [0x560b36536469]
51  /opt/conda/envs/gdf/bin/python(_PyEval_EvalFrameDefault+0x11f2) [0x560b36527042]
52  /opt/conda/envs/gdf/bin/python(+0x12dfb4) [0x560b36524fb4]
53  /opt/conda/envs/gdf/bin/python(_PyEval_EvalCodeWithName+0x48) [0x560b36524c88]
54  /opt/conda/envs/gdf/bin/python(PyEval_EvalCodeEx+0x39) [0x560b36524c39]
55  /opt/conda/envs/gdf/bin/python(PyEval_EvalCode+0x1b) [0x560b365d22cb]
56  /opt/conda/envs/gdf/bin/python(+0x2086ca) [0x560b365ff6ca]
57  /opt/conda/envs/gdf/bin/python(+0x204a63) [0x560b365fba63]
58  /opt/conda/envs/gdf/bin/python(PyRun_StringFlags+0x9a) [0x560b365f387a]
59  /opt/conda/envs/gdf/bin/python(PyRun_SimpleStringFlags+0x3c) [0x560b365f376c]
60  /opt/conda/envs/gdf/bin/python(Py_RunMain+0x267) [0x560b365f29a7]
61  /opt/conda/envs/gdf/bin/python(Py_BytesMain+0x37) [0x560b365c6107]
=================================
[dgx13:84228:0:84228] Caught signal 11 (Segmentation fault: address not mapped to object at address 0x448)
==== backtrace (tid:  84228) ====
 0  /opt/conda/envs/gdf/lib/libucs.so.0(ucs_handle_error+0x2fd) [0x7f069417f07d]
 1  /opt/conda/envs/gdf/lib/libucs.so.0(+0x2a274) [0x7f069417f274]
 2  /opt/conda/envs/gdf/lib/libucs.so.0(+0x2a43a) [0x7f069417f43a]
 3  /usr/lib/x86_64-linux-gnu/libpthread.so.0(+0x14420) [0x7f06cccec420]
 4  /opt/conda/envs/gdf/lib/libucp.so.0(ucp_mem_type_unpack+0x14) [0x7f06941fe6b4]
 5  /opt/conda/envs/gdf/lib/libucp.so.0(ucp_rndv_data_handler+0x4e9) [0x7f0694227839]
 6  /opt/conda/envs/gdf/lib/libuct.so.0(+0x203df) [0x7f06941393df]
 7  /opt/conda/envs/gdf/lib/libuct.so.0(+0x23838) [0x7f069413c838]
 8  /opt/conda/envs/gdf/lib/libucs.so.0(ucs_event_set_wait+0xb9) [0x7f06941884a9]
 9  /opt/conda/envs/gdf/lib/libuct.so.0(uct_tcp_iface_progress+0x7d) [0x7f069413b5dd]
10  /opt/conda/envs/gdf/lib/libucp.so.0(ucp_worker_progress+0x5a) [0x7f06941fb8da]
11  /opt/conda/envs/gdf/lib/python3.9/site-packages/ucp/_libs/ucx_api.cpython-39-x86_64-linux-gnu.so(+0x3206a) [0x7f06942b406a]
12  /opt/conda/envs/gdf/bin/python(_PyEval_EvalFrameDefault+0x45a6) [0x564c426023f6]
13  /opt/conda/envs/gdf/bin/python(+0x12dfb4) [0x564c425fcfb4]
14  /opt/conda/envs/gdf/bin/python(_PyFunction_Vectorcall+0xd9) [0x564c4260e469]
15  /opt/conda/envs/gdf/bin/python(_PyEval_EvalFrameDefault+0x696) [0x564c425fe4e6]
16  /opt/conda/envs/gdf/bin/python(+0x13f712) [0x564c4260e712]
17  /opt/conda/envs/gdf/bin/python(+0x14ca83) [0x564c4261ba83]
18  /opt/conda/envs/gdf/bin/python(+0x25819c) [0x564c4272719c]
19  /opt/conda/envs/gdf/bin/python(+0xf23ff) [0x564c425c13ff]
20  /opt/conda/envs/gdf/bin/python(+0x136723) [0x564c42605723]
21  /opt/conda/envs/gdf/bin/python(_PyEval_EvalFrameDefault+0x5ad9) [0x564c42603929]
22  /opt/conda/envs/gdf/bin/python(+0x13f712) [0x564c4260e712]
23  /opt/conda/envs/gdf/bin/python(_PyEval_EvalFrameDefault+0x696) [0x564c425fe4e6]
24  /opt/conda/envs/gdf/bin/python(+0x13f712) [0x564c4260e712]
25  /opt/conda/envs/gdf/bin/python(_PyEval_EvalFrameDefault+0x696) [0x564c425fe4e6]
26  /opt/conda/envs/gdf/bin/python(+0x13f712) [0x564c4260e712]
27  /opt/conda/envs/gdf/bin/python(_PyEval_EvalFrameDefault+0x696) [0x564c425fe4e6]
28  /opt/conda/envs/gdf/bin/python(+0x13f712) [0x564c4260e712]
29  /opt/conda/envs/gdf/bin/python(_PyEval_EvalFrameDefault+0x696) [0x564c425fe4e6]
30  /opt/conda/envs/gdf/bin/python(+0x12dfb4) [0x564c425fcfb4]
31  /opt/conda/envs/gdf/bin/python(_PyFunction_Vectorcall+0xd9) [0x564c4260e469]
32  /opt/conda/envs/gdf/bin/python(_PyEval_EvalFrameDefault+0x11f2) [0x564c425ff042]
33  /opt/conda/envs/gdf/bin/python(+0x12dfb4) [0x564c425fcfb4]
34  /opt/conda/envs/gdf/bin/python(+0x14c8cb) [0x564c4261b8cb]
35  /opt/conda/envs/gdf/bin/python(PyObject_Call+0xbc) [0x564c4261c04c]
36  /opt/conda/envs/gdf/bin/python(+0x21080e) [0x564c426df80e]
37  /opt/conda/envs/gdf/bin/python(_PyObject_MakeTpCall+0x2ec) [0x564c426066ac]
38  /opt/conda/envs/gdf/bin/python(_PyEval_EvalFrameDefault+0x45a6) [0x564c426023f6]
39  /opt/conda/envs/gdf/bin/python(+0x13f712) [0x564c4260e712]
40  /opt/conda/envs/gdf/bin/python(+0x14c9ac) [0x564c4261b9ac]
41  /opt/conda/envs/gdf/bin/python(_PyEval_EvalFrameDefault+0x45a6) [0x564c426023f6]
42  /opt/conda/envs/gdf/bin/python(+0x13f712) [0x564c4260e712]
43  /opt/conda/envs/gdf/bin/python(_PyEval_EvalFrameDefault+0x696) [0x564c425fe4e6]
44  /opt/conda/envs/gdf/bin/python(+0x12dfb4) [0x564c425fcfb4]
45  /opt/conda/envs/gdf/bin/python(_PyFunction_Vectorcall+0xd9) [0x564c4260e469]
46  /opt/conda/envs/gdf/bin/python(_PyEval_EvalFrameDefault+0x696) [0x564c425fe4e6]
47  /opt/conda/envs/gdf/bin/python(+0x13f712) [0x564c4260e712]
48  /opt/conda/envs/gdf/bin/python(_PyEval_EvalFrameDefault+0x3e2) [0x564c425fe232]
49  /opt/conda/envs/gdf/bin/python(+0x12dfb4) [0x564c425fcfb4]
50  /opt/conda/envs/gdf/bin/python(_PyFunction_Vectorcall+0xd9) [0x564c4260e469]
51  /opt/conda/envs/gdf/bin/python(_PyEval_EvalFrameDefault+0x11f2) [0x564c425ff042]
52  /opt/conda/envs/gdf/bin/python(+0x12dfb4) [0x564c425fcfb4]
53  /opt/conda/envs/gdf/bin/python(_PyEval_EvalCodeWithName+0x48) [0x564c425fcc88]
54  /opt/conda/envs/gdf/bin/python(PyEval_EvalCodeEx+0x39) [0x564c425fcc39]
55  /opt/conda/envs/gdf/bin/python(PyEval_EvalCode+0x1b) [0x564c426aa2cb]
56  /opt/conda/envs/gdf/bin/python(+0x2086ca) [0x564c426d76ca]
57  /opt/conda/envs/gdf/bin/python(+0x204a63) [0x564c426d3a63]
58  /opt/conda/envs/gdf/bin/python(PyRun_StringFlags+0x9a) [0x564c426cb87a]
59  /opt/conda/envs/gdf/bin/python(PyRun_SimpleStringFlags+0x3c) [0x564c426cb76c]
60  /opt/conda/envs/gdf/bin/python(Py_RunMain+0x267) [0x564c426ca9a7]
61  /opt/conda/envs/gdf/bin/python(Py_BytesMain+0x37) [0x564c4269e107]
=================================
2024-02-07 07:55:19,603 - distributed.worker - ERROR - Worker stream died during communication: ucx://127.0.0.1:36681
Traceback (most recent call last):
  File "/opt/conda/envs/gdf/lib/python3.9/site-packages/distributed/comm/ucx.py", line 392, in read
    await self.ep.recv(each_frame)
  File "/opt/conda/envs/gdf/lib/python3.9/site-packages/ucp/core.py", line 737, in recv
    ret = await comm.tag_recv(self._ep, buffer, nbytes, tag, name=log)
ucp._libs.exceptions.UCXError: <[Recv #007] ep: 0x7f7f52d1e180, tag: 0xd4732bb46cd6dad7, nbytes: 50000000, type: <class 'rmm._lib.device_buffer.DeviceBuffer'>>: Connection reset by remote peer

During handling of the above exception, another exception occurred:

Traceback (most recent call last):
  File "/opt/conda/envs/gdf/lib/python3.9/site-packages/distributed/worker.py", line 2056, in gather_dep
    response = await get_data_from_worker(
  File "/opt/conda/envs/gdf/lib/python3.9/site-packages/distributed/worker.py", line 2860, in get_data_from_worker
    response = await send_recv(
  File "/opt/conda/envs/gdf/lib/python3.9/site-packages/distributed/core.py", line 1154, in send_recv
    response = await comm.read(deserializers=deserializers)
  File "/opt/conda/envs/gdf/lib/python3.9/site-packages/distributed/utils.py", line 832, in wrapper
    return await func(*args, **kwargs)
  File "/opt/conda/envs/gdf/lib/python3.9/site-packages/distributed/comm/ucx.py", line 398, in read
    raise CommClosedError(
distributed.comm.core.CommClosedError: Connection closed by writer.
Inner exception: UCXError("<[Recv #007] ep: 0x7f7f52d1e180, tag: 0xd4732bb46cd6dad7, nbytes: 50000000, type: <class 'rmm._lib.device_buffer.DeviceBuffer'>>: Connection reset by remote peer")
2024-02-07 07:55:19,603 - distributed.worker - ERROR - Worker stream died during communication: ucx://127.0.0.1:36681
Traceback (most recent call last):
  File "/opt/conda/envs/gdf/lib/python3.9/site-packages/distributed/comm/ucx.py", line 392, in read
    await self.ep.recv(each_frame)
  File "/opt/conda/envs/gdf/lib/python3.9/site-packages/ucp/core.py", line 737, in recv
    ret = await comm.tag_recv(self._ep, buffer, nbytes, tag, name=log)
ucp._libs.exceptions.UCXError: <[Recv #007] ep: 0x7f47e47eb2c0, tag: 0xb13f3148a4a2b12a, nbytes: 50000000, type: <class 'rmm._lib.device_buffer.DeviceBuffer'>>: Connection reset by remote peer

During handling of the above exception, another exception occurred:

Traceback (most recent call last):
  File "/opt/conda/envs/gdf/lib/python3.9/site-packages/distributed/worker.py", line 2056, in gather_dep
    response = await get_data_from_worker(
  File "/opt/conda/envs/gdf/lib/python3.9/site-packages/distributed/worker.py", line 2860, in get_data_from_worker
    response = await send_recv(
  File "/opt/conda/envs/gdf/lib/python3.9/site-packages/distributed/core.py", line 1154, in send_recv
    response = await comm.read(deserializers=deserializers)
  File "/opt/conda/envs/gdf/lib/python3.9/site-packages/distributed/utils.py", line 832, in wrapper
    return await func(*args, **kwargs)
  File "/opt/conda/envs/gdf/lib/python3.9/site-packages/distributed/comm/ucx.py", line 398, in read
    raise CommClosedError(
distributed.comm.core.CommClosedError: Connection closed by writer.
Inner exception: UCXError("<[Recv #007] ep: 0x7f47e47eb2c0, tag: 0xb13f3148a4a2b12a, nbytes: 50000000, type: <class 'rmm._lib.device_buffer.DeviceBuffer'>>: Connection reset by remote peer")
2024-02-07 07:55:19,604 - distributed.worker - ERROR - failed during get data with ucx://127.0.0.1:41331 -> ucx://127.0.0.1:36681
Traceback (most recent call last):
  File "/opt/conda/envs/gdf/lib/python3.9/site-packages/distributed/comm/ucx.py", line 334, in write
    await self.ep.send(each_frame)
  File "/opt/conda/envs/gdf/lib/python3.9/site-packages/ucp/core.py", line 662, in send
    return await comm.tag_send(self._ep, buffer, nbytes, tag, name=log)
ucp._libs.exceptions.UCXError: <[Send #007] ep: 0x7f47e47eb340, tag: 0x4422e57ca71738ab, nbytes: 50000000, type: <class 'cupy.ndarray'>>: Connection reset by remote peer

During handling of the above exception, another exception occurred:

Traceback (most recent call last):
  File "/opt/conda/envs/gdf/lib/python3.9/site-packages/distributed/worker.py", line 1779, in get_data
    compressed = await comm.write(msg, serializers=serializers)
  File "/opt/conda/envs/gdf/lib/python3.9/site-packages/distributed/utils.py", line 832, in wrapper
    return await func(*args, **kwargs)
  File "/opt/conda/envs/gdf/lib/python3.9/site-packages/distributed/comm/ucx.py", line 338, in write
    raise CommClosedError("While writing, the connection was closed")
distributed.comm.core.CommClosedError: While writing, the connection was closed
2024-02-07 07:55:19,799 - distributed.worker - ERROR - failed during get data with ucx://127.0.0.1:41331 -> ucx://127.0.0.1:52315
Traceback (most recent call last):
  File "/opt/conda/envs/gdf/lib/python3.9/site-packages/distributed/comm/ucx.py", line 334, in write
    await self.ep.send(each_frame)
  File "/opt/conda/envs/gdf/lib/python3.9/site-packages/ucp/core.py", line 662, in send
    return await comm.tag_send(self._ep, buffer, nbytes, tag, name=log)
ucp._libs.exceptions.UCXError: <[Send #007] ep: 0x7f47e47eb100, tag: 0x53a49f6c4140944, nbytes: 50000000, type: <class 'cupy.ndarray'>>: Connection reset by remote peer

During handling of the above exception, another exception occurred:

Traceback (most recent call last):
  File "/opt/conda/envs/gdf/lib/python3.9/site-packages/distributed/worker.py", line 1779, in get_data
    compressed = await comm.write(msg, serializers=serializers)
  File "/opt/conda/envs/gdf/lib/python3.9/site-packages/distributed/utils.py", line 832, in wrapper
    return await func(*args, **kwargs)
  File "/opt/conda/envs/gdf/lib/python3.9/site-packages/distributed/comm/ucx.py", line 338, in write
    raise CommClosedError("While writing, the connection was closed")
distributed.comm.core.CommClosedError: While writing, the connection was closed
[dgx13:84224:0:84224] Caught signal 11 (Segmentation fault: address not mapped to object at address 0x448)
==== backtrace (tid:  84224) ====
 0  /opt/conda/envs/gdf/lib/libucs.so.0(ucs_handle_error+0x2fd) [0x7f5a4c0c507d]
 1  /opt/conda/envs/gdf/lib/libucs.so.0(+0x2a274) [0x7f5a4c0c5274]
 2  /opt/conda/envs/gdf/lib/libucs.so.0(+0x2a43a) [0x7f5a4c0c543a]
 3  /usr/lib/x86_64-linux-gnu/libpthread.so.0(+0x14420) [0x7f5a76c17420]
 4  /opt/conda/envs/gdf/lib/libucp.so.0(ucp_mem_type_unpack+0x14) [0x7f5a4c1446b4]
 5  /opt/conda/envs/gdf/lib/libucp.so.0(ucp_rndv_data_handler+0x4e9) [0x7f5a4c16d839]
 6  /opt/conda/envs/gdf/lib/libuct.so.0(+0x203df) [0x7f5a4c07f3df]
 7  /opt/conda/envs/gdf/lib/libuct.so.0(+0x23838) [0x7f5a4c082838]
 8  /opt/conda/envs/gdf/lib/libucs.so.0(ucs_event_set_wait+0xb9) [0x7f5a4c0ce4a9]
 9  /opt/conda/envs/gdf/lib/libuct.so.0(uct_tcp_iface_progress+0x7d) [0x7f5a4c0815dd]
10  /opt/conda/envs/gdf/lib/libucp.so.0(ucp_worker_progress+0x5a) [0x7f5a4c1418da]
11  /opt/conda/envs/gdf/lib/python3.9/site-packages/ucp/_libs/ucx_api.cpython-39-x86_64-linux-gnu.so(+0x3206a) [0x7f5a4c1fa06a]
12  /opt/conda/envs/gdf/bin/python(_PyEval_EvalFrameDefault+0x45a6) [0x5582e67693f6]
13  /opt/conda/envs/gdf/bin/python(+0x12dfb4) [0x5582e6763fb4]
14  /opt/conda/envs/gdf/bin/python(_PyFunction_Vectorcall+0xd9) [0x5582e6775469]
15  /opt/conda/envs/gdf/bin/python(_PyEval_EvalFrameDefault+0x696) [0x5582e67654e6]
16  /opt/conda/envs/gdf/bin/python(+0x13f712) [0x5582e6775712]
17  /opt/conda/envs/gdf/bin/python(+0x14ca83) [0x5582e6782a83]
18  /opt/conda/envs/gdf/bin/python(+0x25819c) [0x5582e688e19c]
19  /opt/conda/envs/gdf/bin/python(+0xf23ff) [0x5582e67283ff]
20  /opt/conda/envs/gdf/bin/python(+0x136723) [0x5582e676c723]
21  /opt/conda/envs/gdf/bin/python(_PyEval_EvalFrameDefault+0x5ad9) [0x5582e676a929]
22  /opt/conda/envs/gdf/bin/python(+0x13f712) [0x5582e6775712]
23  /opt/conda/envs/gdf/bin/python(_PyEval_EvalFrameDefault+0x696) [0x5582e67654e6]
24  /opt/conda/envs/gdf/bin/python(+0x13f712) [0x5582e6775712]
25  /opt/conda/envs/gdf/bin/python(_PyEval_EvalFrameDefault+0x696) [0x5582e67654e6]
26  /opt/conda/envs/gdf/bin/python(+0x13f712) [0x5582e6775712]
27  /opt/conda/envs/gdf/bin/python(_PyEval_EvalFrameDefault+0x696) [0x5582e67654e6]
28  /opt/conda/envs/gdf/bin/python(+0x13f712) [0x5582e6775712]
29  /opt/conda/envs/gdf/bin/python(_PyEval_EvalFrameDefault+0x696) [0x5582e67654e6]
30  /opt/conda/envs/gdf/bin/python(+0x12dfb4) [0x5582e6763fb4]
31  /opt/conda/envs/gdf/bin/python(_PyFunction_Vectorcall+0xd9) [0x5582e6775469]
32  /opt/conda/envs/gdf/bin/python(_PyEval_EvalFrameDefault+0x11f2) [0x5582e6766042]
33  /opt/conda/envs/gdf/bin/python(+0x12dfb4) [0x5582e6763fb4]
34  /opt/conda/envs/gdf/bin/python(+0x14c8cb) [0x5582e67828cb]
35  /opt/conda/envs/gdf/bin/python(PyObject_Call+0xbc) [0x5582e678304c]
36  /opt/conda/envs/gdf/bin/python(+0x21080e) [0x5582e684680e]
37  /opt/conda/envs/gdf/bin/python(_PyObject_MakeTpCall+0x2ec) [0x5582e676d6ac]
38  /opt/conda/envs/gdf/bin/python(_PyEval_EvalFrameDefault+0x45a6) [0x5582e67693f6]
39  /opt/conda/envs/gdf/bin/python(+0x13f712) [0x5582e6775712]
40  /opt/conda/envs/gdf/bin/python(+0x14c9ac) [0x5582e67829ac]
41  /opt/conda/envs/gdf/bin/python(_PyEval_EvalFrameDefault+0x45a6) [0x5582e67693f6]
42  /opt/conda/envs/gdf/bin/python(+0x13f712) [0x5582e6775712]
43  /opt/conda/envs/gdf/bin/python(_PyEval_EvalFrameDefault+0x696) [0x5582e67654e6]
44  /opt/conda/envs/gdf/bin/python(+0x12dfb4) [0x5582e6763fb4]
45  /opt/conda/envs/gdf/bin/python(_PyFunction_Vectorcall+0xd9) [0x5582e6775469]
46  /opt/conda/envs/gdf/bin/python(_PyEval_EvalFrameDefault+0x696) [0x5582e67654e6]
47  /opt/conda/envs/gdf/bin/python(+0x13f712) [0x5582e6775712]
48  /opt/conda/envs/gdf/bin/python(_PyEval_EvalFrameDefault+0x3e2) [0x5582e6765232]
49  /opt/conda/envs/gdf/bin/python(+0x12dfb4) [0x5582e6763fb4]
50  /opt/conda/envs/gdf/bin/python(_PyFunction_Vectorcall+0xd9) [0x5582e6775469]
51  /opt/conda/envs/gdf/bin/python(_PyEval_EvalFrameDefault+0x11f2) [0x5582e6766042]
52  /opt/conda/envs/gdf/bin/python(+0x12dfb4) [0x5582e6763fb4]
53  /opt/conda/envs/gdf/bin/python(_PyEval_EvalCodeWithName+0x48) [0x5582e6763c88]
54  /opt/conda/envs/gdf/bin/python(PyEval_EvalCodeEx+0x39) [0x5582e6763c39]
55  /opt/conda/envs/gdf/bin/python(PyEval_EvalCode+0x1b) [0x5582e68112cb]
56  /opt/conda/envs/gdf/bin/python(+0x2086ca) [0x5582e683e6ca]
57  /opt/conda/envs/gdf/bin/python(+0x204a63) [0x5582e683aa63]
58  /opt/conda/envs/gdf/bin/python(PyRun_StringFlags+0x9a) [0x5582e683287a]
59  /opt/conda/envs/gdf/bin/python(PyRun_SimpleStringFlags+0x3c) [0x5582e683276c]
60  /opt/conda/envs/gdf/bin/python(Py_RunMain+0x267) [0x5582e68319a7]
61  /opt/conda/envs/gdf/bin/python(Py_BytesMain+0x37) [0x5582e6805107]
=================================
2024-02-07 07:55:20,429 - distributed.worker - ERROR - failed during get data with ucx://127.0.0.1:41331 -> ucx://127.0.0.1:35915
Traceback (most recent call last):
  File "/opt/conda/envs/gdf/lib/python3.9/site-packages/distributed/comm/ucx.py", line 334, in write
    await self.ep.send(each_frame)
  File "/opt/conda/envs/gdf/lib/python3.9/site-packages/ucp/core.py", line 662, in send
    return await comm.tag_send(self._ep, buffer, nbytes, tag, name=log)
ucp._libs.exceptions.UCXError: <[Send #007] ep: 0x7f47e47eb2c0, tag: 0xf62fe6cf394f6000, nbytes: 50000000, type: <class 'cupy.ndarray'>>: Connection reset by remote peer

During handling of the above exception, another exception occurred:

Traceback (most recent call last):
  File "/opt/conda/envs/gdf/lib/python3.9/site-packages/distributed/worker.py", line 1779, in get_data
    compressed = await comm.write(msg, serializers=serializers)
  File "/opt/conda/envs/gdf/lib/python3.9/site-packages/distributed/utils.py", line 832, in wrapper
    return await func(*args, **kwargs)
  File "/opt/conda/envs/gdf/lib/python3.9/site-packages/distributed/comm/ucx.py", line 338, in write
    raise CommClosedError("While writing, the connection was closed")
distributed.comm.core.CommClosedError: While writing, the connection was closed
2024-02-07 07:55:20,429 - distributed.worker - ERROR - Worker stream died during communication: ucx://127.0.0.1:35915
Traceback (most recent call last):
  File "/opt/conda/envs/gdf/lib/python3.9/site-packages/distributed/comm/ucx.py", line 392, in read
    await self.ep.recv(each_frame)
  File "/opt/conda/envs/gdf/lib/python3.9/site-packages/ucp/core.py", line 737, in recv
    ret = await comm.tag_recv(self._ep, buffer, nbytes, tag, name=log)
ucp._libs.exceptions.UCXError: <[Recv #007] ep: 0x7f47e47eb340, tag: 0x2f6e0e62b82d4c59, nbytes: 50000000, type: <class 'rmm._lib.device_buffer.DeviceBuffer'>>: Connection reset by remote peer

During handling of the above exception, another exception occurred:

Traceback (most recent call last):
  File "/opt/conda/envs/gdf/lib/python3.9/site-packages/distributed/worker.py", line 2056, in gather_dep
    response = await get_data_from_worker(
  File "/opt/conda/envs/gdf/lib/python3.9/site-packages/distributed/worker.py", line 2860, in get_data_from_worker
    response = await send_recv(
  File "/opt/conda/envs/gdf/lib/python3.9/site-packages/distributed/core.py", line 1154, in send_recv
    response = await comm.read(deserializers=deserializers)
  File "/opt/conda/envs/gdf/lib/python3.9/site-packages/distributed/utils.py", line 832, in wrapper
    return await func(*args, **kwargs)
  File "/opt/conda/envs/gdf/lib/python3.9/site-packages/distributed/comm/ucx.py", line 398, in read
    raise CommClosedError(
distributed.comm.core.CommClosedError: Connection closed by writer.
Inner exception: UCXError("<[Recv #007] ep: 0x7f47e47eb340, tag: 0x2f6e0e62b82d4c59, nbytes: 50000000, type: <class 'rmm._lib.device_buffer.DeviceBuffer'>>: Connection reset by remote peer")
2024-02-07 07:55:20,946 - distributed.nanny - WARNING - Restarting worker
2024-02-07 07:55:20,992 - distributed.nanny - WARNING - Restarting worker
2024-02-07 07:55:21,452 - distributed.nanny - WARNING - Restarting worker
2024-02-07 07:55:43,477 - distributed.worker - ERROR - Worker stream died during communication: ucx://127.0.0.1:53983
Traceback (most recent call last):
  File "/opt/conda/envs/gdf/lib/python3.9/site-packages/distributed/comm/ucx.py", line 467, in connect
    ep = await ucp.create_endpoint(ip, port)
  File "/opt/conda/envs/gdf/lib/python3.9/site-packages/ucp/core.py", line 1016, in create_endpoint
    return await _get_ctx().create_endpoint(
  File "/opt/conda/envs/gdf/lib/python3.9/site-packages/ucp/core.py", line 328, in create_endpoint
    peer_info = await exchange_peer_info(
  File "/opt/conda/envs/gdf/lib/python3.9/site-packages/ucp/core.py", line 60, in exchange_peer_info
    await asyncio.wait_for(
  File "/opt/conda/envs/gdf/lib/python3.9/asyncio/tasks.py", line 466, in wait_for
    await waiter
asyncio.exceptions.CancelledError

During handling of the above exception, another exception occurred:

Traceback (most recent call last):
  File "/opt/conda/envs/gdf/lib/python3.9/asyncio/tasks.py", line 490, in wait_for
    return fut.result()
asyncio.exceptions.CancelledError

The above exception was the direct cause of the following exception:

Traceback (most recent call last):
  File "/opt/conda/envs/gdf/lib/python3.9/site-packages/distributed/comm/core.py", line 342, in connect
    comm = await wait_for(
  File "/opt/conda/envs/gdf/lib/python3.9/site-packages/distributed/utils.py", line 1940, in wait_for
    return await asyncio.wait_for(fut, timeout)
  File "/opt/conda/envs/gdf/lib/python3.9/asyncio/tasks.py", line 492, in wait_for
    raise exceptions.TimeoutError() from exc
asyncio.exceptions.TimeoutError

The above exception was the direct cause of the following exception:

Traceback (most recent call last):
  File "/opt/conda/envs/gdf/lib/python3.9/site-packages/distributed/worker.py", line 2056, in gather_dep
    response = await get_data_from_worker(
  File "/opt/conda/envs/gdf/lib/python3.9/site-packages/distributed/worker.py", line 2857, in get_data_from_worker
    comm = await rpc.connect(worker)
  File "/opt/conda/envs/gdf/lib/python3.9/site-packages/distributed/core.py", line 1674, in connect
    return connect_attempt.result()
  File "/opt/conda/envs/gdf/lib/python3.9/site-packages/distributed/core.py", line 1564, in _connect
    comm = await connect(
  File "/opt/conda/envs/gdf/lib/python3.9/site-packages/distributed/comm/core.py", line 368, in connect
    raise OSError(
OSError: Timed out trying to connect to ucx://127.0.0.1:53983 after 30 s
/opt/conda/envs/gdf/lib/python3.9/multiprocessing/resource_tracker.py:216: UserWarning: resource_tracker: There appear to be 30 leaked semaphore objects to clean up at shutdown
  warnings.warn('resource_tracker: There appear to be %d '
