2023-05-24 05:45:34,589 - distributed.preloading - INFO - Creating preload: dask_cuda.initialize
2023-05-24 05:45:34,589 - distributed.preloading - INFO - Creating preload: dask_cuda.initialize
2023-05-24 05:45:34,589 - distributed.preloading - INFO - Import preload module: dask_cuda.initialize
2023-05-24 05:45:34,589 - distributed.preloading - INFO - Import preload module: dask_cuda.initialize
2023-05-24 05:45:34,589 - distributed.preloading - INFO - Creating preload: dask_cuda.initialize
2023-05-24 05:45:34,589 - distributed.preloading - INFO - Import preload module: dask_cuda.initialize
2023-05-24 05:45:34,592 - distributed.preloading - INFO - Creating preload: dask_cuda.initialize
2023-05-24 05:45:34,592 - distributed.preloading - INFO - Import preload module: dask_cuda.initialize
2023-05-24 05:45:34,603 - distributed.preloading - INFO - Creating preload: dask_cuda.initialize
2023-05-24 05:45:34,604 - distributed.preloading - INFO - Import preload module: dask_cuda.initialize
2023-05-24 05:45:34,605 - distributed.preloading - INFO - Creating preload: dask_cuda.initialize
2023-05-24 05:45:34,605 - distributed.preloading - INFO - Import preload module: dask_cuda.initialize
2023-05-24 05:45:34,608 - distributed.preloading - INFO - Creating preload: dask_cuda.initialize
2023-05-24 05:45:34,608 - distributed.preloading - INFO - Import preload module: dask_cuda.initialize
2023-05-24 05:45:34,650 - distributed.preloading - INFO - Creating preload: dask_cuda.initialize
2023-05-24 05:45:34,650 - distributed.preloading - INFO - Import preload module: dask_cuda.initialize
[dgx13:80069:0:80069] Caught signal 11 (Segmentation fault: address not mapped to object at address 0x448)
==== backtrace (tid:  80069) ====
 0  /opt/conda/envs/gdf/lib/libucs.so.0(ucs_handle_error+0x2dc) [0x7f637cadc11c]
 1  /opt/conda/envs/gdf/lib/libucs.so.0(+0x302ff) [0x7f637cadc2ff]
 2  /opt/conda/envs/gdf/lib/libucs.so.0(+0x30634) [0x7f637cadc634]
 3  /usr/lib/x86_64-linux-gnu/libpthread.so.0(+0x14420) [0x7f641d456420]
 4  /opt/conda/envs/gdf/lib/libucp.so.0(ucp_mem_type_unpack+0x1b) [0x7f637cb5d28b]
 5  /opt/conda/envs/gdf/lib/libucp.so.0(ucp_rndv_data_handler+0x508) [0x7f637cb870b8]
 6  /opt/conda/envs/gdf/lib/libuct.so.0(+0x216a7) [0x7f637ca8e6a7]
 7  /opt/conda/envs/gdf/lib/libuct.so.0(+0x21c28) [0x7f637ca8ec28]
 8  /opt/conda/envs/gdf/lib/libuct.so.0(+0x240fc) [0x7f637ca910fc]
 9  /opt/conda/envs/gdf/lib/libucs.so.0(ucs_event_set_wait+0xf9) [0x7f637cae6639]
10  /opt/conda/envs/gdf/lib/libuct.so.0(uct_tcp_iface_progress+0x7b) [0x7f637ca911ab]
11  /opt/conda/envs/gdf/lib/libucp.so.0(ucp_worker_progress+0x6a) [0x7f637cb59f1a]
12  /opt/conda/envs/gdf/lib/python3.9/site-packages/ucp/_libs/ucx_api.cpython-39-x86_64-linux-gnu.so(+0x286e1) [0x7f637cc096e1]
13  /opt/conda/envs/gdf/bin/python(+0x13eb08) [0x560405bd1b08]
14  /opt/conda/envs/gdf/bin/python(_PyEval_EvalFrameDefault+0x5f82) [0x560405bc2112]
15  /opt/conda/envs/gdf/bin/python(+0x12827a) [0x560405bbb27a]
16  /opt/conda/envs/gdf/bin/python(_PyFunction_Vectorcall+0xd5) [0x560405bccc05]
17  /opt/conda/envs/gdf/bin/python(_PyEval_EvalFrameDefault+0x68b) [0x560405bbc81b]
18  /opt/conda/envs/gdf/bin/python(+0x139ef3) [0x560405bccef3]
19  /opt/conda/envs/gdf/bin/python(+0x147a16) [0x560405bdaa16]
20  /opt/conda/envs/gdf/bin/python(+0x2579b1) [0x560405cea9b1]
21  /opt/conda/envs/gdf/bin/python(+0xe5817) [0x560405b78817]
22  /opt/conda/envs/gdf/bin/python(+0x130f83) [0x560405bc3f83]
23  /opt/conda/envs/gdf/bin/python(_PyEval_EvalFrameDefault+0x5ba6) [0x560405bc1d36]
24  /opt/conda/envs/gdf/bin/python(+0x139ef3) [0x560405bccef3]
25  /opt/conda/envs/gdf/bin/python(_PyEval_EvalFrameDefault+0x68b) [0x560405bbc81b]
26  /opt/conda/envs/gdf/bin/python(+0x139ef3) [0x560405bccef3]
27  /opt/conda/envs/gdf/bin/python(_PyEval_EvalFrameDefault+0x68b) [0x560405bbc81b]
28  /opt/conda/envs/gdf/bin/python(+0x139ef3) [0x560405bccef3]
29  /opt/conda/envs/gdf/bin/python(_PyEval_EvalFrameDefault+0x68b) [0x560405bbc81b]
30  /opt/conda/envs/gdf/bin/python(+0x139ef3) [0x560405bccef3]
31  /opt/conda/envs/gdf/bin/python(_PyEval_EvalFrameDefault+0x68b) [0x560405bbc81b]
32  /opt/conda/envs/gdf/bin/python(+0x12827a) [0x560405bbb27a]
33  /opt/conda/envs/gdf/bin/python(_PyFunction_Vectorcall+0xd5) [0x560405bccc05]
34  /opt/conda/envs/gdf/bin/python(_PyEval_EvalFrameDefault+0x4e17) [0x560405bc0fa7]
35  /opt/conda/envs/gdf/bin/python(+0x12827a) [0x560405bbb27a]
36  /opt/conda/envs/gdf/bin/python(+0x147935) [0x560405bda935]
37  /opt/conda/envs/gdf/bin/python(PyObject_Call+0xb4) [0x560405bdb104]
38  /opt/conda/envs/gdf/bin/python(+0x20efc8) [0x560405ca1fc8]
39  /opt/conda/envs/gdf/bin/python(_PyObject_MakeTpCall+0x2fc) [0x560405bc52bc]
40  /opt/conda/envs/gdf/bin/python(_PyEval_EvalFrameDefault+0x402b) [0x560405bc01bb]
41  /opt/conda/envs/gdf/bin/python(+0x139ef3) [0x560405bccef3]
42  /opt/conda/envs/gdf/bin/python(+0x147c72) [0x560405bdac72]
43  /opt/conda/envs/gdf/bin/python(_PyEval_EvalFrameDefault+0x402b) [0x560405bc01bb]
44  /opt/conda/envs/gdf/bin/python(+0x139ef3) [0x560405bccef3]
45  /opt/conda/envs/gdf/bin/python(_PyEval_EvalFrameDefault+0x68b) [0x560405bbc81b]
46  /opt/conda/envs/gdf/bin/python(+0x12827a) [0x560405bbb27a]
47  /opt/conda/envs/gdf/bin/python(_PyFunction_Vectorcall+0xd5) [0x560405bccc05]
48  /opt/conda/envs/gdf/bin/python(_PyEval_EvalFrameDefault+0x68b) [0x560405bbc81b]
49  /opt/conda/envs/gdf/bin/python(+0x139ef3) [0x560405bccef3]
50  /opt/conda/envs/gdf/bin/python(_PyEval_EvalFrameDefault+0x3d8) [0x560405bbc568]
51  /opt/conda/envs/gdf/bin/python(+0x12827a) [0x560405bbb27a]
52  /opt/conda/envs/gdf/bin/python(_PyFunction_Vectorcall+0xd5) [0x560405bccc05]
53  /opt/conda/envs/gdf/bin/python(_PyEval_EvalFrameDefault+0x123b) [0x560405bbd3cb]
54  /opt/conda/envs/gdf/bin/python(+0x12827a) [0x560405bbb27a]
55  /opt/conda/envs/gdf/bin/python(_PyEval_EvalCodeWithName+0x47) [0x560405bbaf07]
56  /opt/conda/envs/gdf/bin/python(PyEval_EvalCodeEx+0x39) [0x560405bbaeb9]
57  /opt/conda/envs/gdf/bin/python(PyEval_EvalCode+0x1b) [0x560405c6b8bb]
58  /opt/conda/envs/gdf/bin/python(+0x206adc) [0x560405c99adc]
59  /opt/conda/envs/gdf/bin/python(+0x202c24) [0x560405c95c24]
60  /opt/conda/envs/gdf/bin/python(PyRun_StringFlags+0x9d) [0x560405c8d7ed]
61  /opt/conda/envs/gdf/bin/python(PyRun_SimpleStringFlags+0x3d) [0x560405c8d6bd]
=================================
[dgx13:80082:0:80082] Caught signal 11 (Segmentation fault: address not mapped to object at address 0x448)
==== backtrace (tid:  80082) ====
 0  /opt/conda/envs/gdf/lib/libucs.so.0(ucs_handle_error+0x2dc) [0x7fa36405e11c]
 1  /opt/conda/envs/gdf/lib/libucs.so.0(+0x302ff) [0x7fa36405e2ff]
 2  /opt/conda/envs/gdf/lib/libucs.so.0(+0x30634) [0x7fa36405e634]
 3  /usr/lib/x86_64-linux-gnu/libpthread.so.0(+0x14420) [0x7fa3f5ec8420]
 4  /opt/conda/envs/gdf/lib/libucp.so.0(ucp_mem_type_unpack+0x1b) [0x7fa35155e28b]
 5  /opt/conda/envs/gdf/lib/libucp.so.0(ucp_rndv_data_handler+0x508) [0x7fa3515880b8]
 6  /opt/conda/envs/gdf/lib/libuct.so.0(+0x216a7) [0x7fa3514f46a7]
 7  /opt/conda/envs/gdf/lib/libuct.so.0(+0x21c28) [0x7fa3514f4c28]
 8  /opt/conda/envs/gdf/lib/libuct.so.0(+0x240fc) [0x7fa3514f70fc]
 9  /opt/conda/envs/gdf/lib/libucs.so.0(ucs_event_set_wait+0xf9) [0x7fa364068639]
10  /opt/conda/envs/gdf/lib/libuct.so.0(uct_tcp_iface_progress+0x7b) [0x7fa3514f71ab]
11  /opt/conda/envs/gdf/lib/libucp.so.0(ucp_worker_progress+0x6a) [0x7fa35155af1a]
12  /opt/conda/envs/gdf/lib/python3.9/site-packages/ucp/_libs/ucx_api.cpython-39-x86_64-linux-gnu.so(+0x286e1) [0x7fa35160a6e1]
13  /opt/conda/envs/gdf/bin/python(+0x13eb08) [0x55c3593c3b08]
14  /opt/conda/envs/gdf/bin/python(_PyEval_EvalFrameDefault+0x5f82) [0x55c3593b4112]
15  /opt/conda/envs/gdf/bin/python(+0x12827a) [0x55c3593ad27a]
16  /opt/conda/envs/gdf/bin/python(_PyFunction_Vectorcall+0xd5) [0x55c3593bec05]
17  /opt/conda/envs/gdf/bin/python(_PyEval_EvalFrameDefault+0x68b) [0x55c3593ae81b]
18  /opt/conda/envs/gdf/bin/python(+0x139ef3) [0x55c3593beef3]
19  /opt/conda/envs/gdf/bin/python(+0x147a16) [0x55c3593cca16]
20  /opt/conda/envs/gdf/bin/python(+0x2579b1) [0x55c3594dc9b1]
21  /opt/conda/envs/gdf/bin/python(+0xe5817) [0x55c35936a817]
22  /opt/conda/envs/gdf/bin/python(+0x130f83) [0x55c3593b5f83]
23  /opt/conda/envs/gdf/bin/python(_PyEval_EvalFrameDefault+0x5ba6) [0x55c3593b3d36]
24  /opt/conda/envs/gdf/bin/python(+0x139ef3) [0x55c3593beef3]
25  /opt/conda/envs/gdf/bin/python(_PyEval_EvalFrameDefault+0x68b) [0x55c3593ae81b]
26  /opt/conda/envs/gdf/bin/python(+0x139ef3) [0x55c3593beef3]
27  /opt/conda/envs/gdf/bin/python(_PyEval_EvalFrameDefault+0x68b) [0x55c3593ae81b]
28  /opt/conda/envs/gdf/bin/python(+0x139ef3) [0x55c3593beef3]
29  /opt/conda/envs/gdf/bin/python(_PyEval_EvalFrameDefault+0x68b) [0x55c3593ae81b]
30  /opt/conda/envs/gdf/bin/python(+0x139ef3) [0x55c3593beef3]
31  /opt/conda/envs/gdf/bin/python(_PyEval_EvalFrameDefault+0x68b) [0x55c3593ae81b]
32  /opt/conda/envs/gdf/bin/python(+0x12827a) [0x55c3593ad27a]
33  /opt/conda/envs/gdf/bin/python(_PyFunction_Vectorcall+0xd5) [0x55c3593bec05]
34  /opt/conda/envs/gdf/bin/python(_PyEval_EvalFrameDefault+0x4e17) [0x55c3593b2fa7]
35  /opt/conda/envs/gdf/bin/python(+0x12827a) [0x55c3593ad27a]
36  /opt/conda/envs/gdf/bin/python(+0x147935) [0x55c3593cc935]
37  /opt/conda/envs/gdf/bin/python(PyObject_Call+0xb4) [0x55c3593cd104]
38  /opt/conda/envs/gdf/bin/python(+0x20efc8) [0x55c359493fc8]
39  /opt/conda/envs/gdf/bin/python(_PyObject_MakeTpCall+0x2fc) [0x55c3593b72bc]
40  /opt/conda/envs/gdf/bin/python(_PyEval_EvalFrameDefault+0x402b) [0x55c3593b21bb]
41  /opt/conda/envs/gdf/bin/python(+0x139ef3) [0x55c3593beef3]
42  /opt/conda/envs/gdf/bin/python(+0x147c72) [0x55c3593ccc72]
43  /opt/conda/envs/gdf/bin/python(_PyEval_EvalFrameDefault+0x402b) [0x55c3593b21bb]
44  /opt/conda/envs/gdf/bin/python(+0x139ef3) [0x55c3593beef3]
45  /opt/conda/envs/gdf/bin/python(_PyEval_EvalFrameDefault+0x68b) [0x55c3593ae81b]
46  /opt/conda/envs/gdf/bin/python(+0x12827a) [0x55c3593ad27a]
47  /opt/conda/envs/gdf/bin/python(_PyFunction_Vectorcall+0xd5) [0x55c3593bec05]
48  /opt/conda/envs/gdf/bin/python(_PyEval_EvalFrameDefault+0x68b) [0x55c3593ae81b]
49  /opt/conda/envs/gdf/bin/python(+0x139ef3) [0x55c3593beef3]
50  /opt/conda/envs/gdf/bin/python(_PyEval_EvalFrameDefault+0x3d8) [0x55c3593ae568]
51  /opt/conda/envs/gdf/bin/python(+0x12827a) [0x55c3593ad27a]
52  /opt/conda/envs/gdf/bin/python(_PyFunction_Vectorcall+0xd5) [0x55c3593bec05]
53  /opt/conda/envs/gdf/bin/python(_PyEval_EvalFrameDefault+0x123b) [0x55c3593af3cb]
54  /opt/conda/envs/gdf/bin/python(+0x12827a) [0x55c3593ad27a]
55  /opt/conda/envs/gdf/bin/python(_PyEval_EvalCodeWithName+0x47) [0x55c3593acf07]
56  /opt/conda/envs/gdf/bin/python(PyEval_EvalCodeEx+0x39) [0x55c3593aceb9]
57  /opt/conda/envs/gdf/bin/python(PyEval_EvalCode+0x1b) [0x55c35945d8bb]
58  /opt/conda/envs/gdf/bin/python(+0x206adc) [0x55c35948badc]
59  /opt/conda/envs/gdf/bin/python(+0x202c24) [0x55c359487c24]
60  /opt/conda/envs/gdf/bin/python(PyRun_StringFlags+0x9d) [0x55c35947f7ed]
61  /opt/conda/envs/gdf/bin/python(PyRun_SimpleStringFlags+0x3d) [0x55c35947f6bd]
=================================
[dgx13:80074:0:80074] Caught signal 11 (Segmentation fault: address not mapped to object at address 0x448)
==== backtrace (tid:  80074) ====
 0  /opt/conda/envs/gdf/lib/libucs.so.0(ucs_handle_error+0x2dc) [0x7f406007a11c]
 1  /opt/conda/envs/gdf/lib/libucs.so.0(+0x302ff) [0x7f406007a2ff]
 2  /opt/conda/envs/gdf/lib/libucs.so.0(+0x30634) [0x7f406007a634]
 3  /usr/lib/x86_64-linux-gnu/libpthread.so.0(+0x14420) [0x7f41009e3420]
 4  /opt/conda/envs/gdf/lib/libucp.so.0(ucp_mem_type_unpack+0x1b) [0x7f40600fb28b]
 5  /opt/conda/envs/gdf/lib/libucp.so.0(ucp_rndv_data_handler+0x508) [0x7f40601250b8]
 6  /opt/conda/envs/gdf/lib/libuct.so.0(+0x216a7) [0x7f406002c6a7]
 7  /opt/conda/envs/gdf/lib/libuct.so.0(+0x21c28) [0x7f406002cc28]
 8  /opt/conda/envs/gdf/lib/libuct.so.0(+0x240fc) [0x7f406002f0fc]
 9  /opt/conda/envs/gdf/lib/libucs.so.0(ucs_event_set_wait+0xf9) [0x7f4060084639]
10  /opt/conda/envs/gdf/lib/libuct.so.0(uct_tcp_iface_progress+0x7b) [0x7f406002f1ab]
11  /opt/conda/envs/gdf/lib/libucp.so.0(ucp_worker_progress+0x6a) [0x7f40600f7f1a]
12  /opt/conda/envs/gdf/lib/python3.9/site-packages/ucp/_libs/ucx_api.cpython-39-x86_64-linux-gnu.so(+0x286e1) [0x7f40601a76e1]
13  /opt/conda/envs/gdf/bin/python(+0x13eb08) [0x558fc7696b08]
14  /opt/conda/envs/gdf/bin/python(_PyEval_EvalFrameDefault+0x5f82) [0x558fc7687112]
15  /opt/conda/envs/gdf/bin/python(+0x12827a) [0x558fc768027a]
16  /opt/conda/envs/gdf/bin/python(_PyFunction_Vectorcall+0xd5) [0x558fc7691c05]
17  /opt/conda/envs/gdf/bin/python(_PyEval_EvalFrameDefault+0x68b) [0x558fc768181b]
18  /opt/conda/envs/gdf/bin/python(+0x14e70e) [0x558fc76a670e]
19  /opt/conda/envs/gdf/lib/python3.9/lib-dynload/_asyncio.cpython-39-x86_64-linux-gnu.so(+0x82fe) [0x7f40804062fe]
20  /opt/conda/envs/gdf/bin/python(_PyObject_MakeTpCall+0x2fc) [0x558fc768a2bc]
21  /opt/conda/envs/gdf/bin/python(+0xe5817) [0x558fc763d817]
22  /opt/conda/envs/gdf/bin/python(+0x130f83) [0x558fc7688f83]
23  /opt/conda/envs/gdf/bin/python(_PyEval_EvalFrameDefault+0x5ba6) [0x558fc7686d36]
24  /opt/conda/envs/gdf/bin/python(+0x139ef3) [0x558fc7691ef3]
25  /opt/conda/envs/gdf/bin/python(_PyEval_EvalFrameDefault+0x68b) [0x558fc768181b]
26  /opt/conda/envs/gdf/bin/python(+0x139ef3) [0x558fc7691ef3]
27  /opt/conda/envs/gdf/bin/python(_PyEval_EvalFrameDefault+0x68b) [0x558fc768181b]
28  /opt/conda/envs/gdf/bin/python(+0x139ef3) [0x558fc7691ef3]
29  /opt/conda/envs/gdf/bin/python(_PyEval_EvalFrameDefault+0x68b) [0x558fc768181b]
30  /opt/conda/envs/gdf/bin/python(+0x139ef3) [0x558fc7691ef3]
31  /opt/conda/envs/gdf/bin/python(_PyEval_EvalFrameDefault+0x68b) [0x558fc768181b]
32  /opt/conda/envs/gdf/bin/python(+0x12827a) [0x558fc768027a]
33  /opt/conda/envs/gdf/bin/python(_PyFunction_Vectorcall+0xd5) [0x558fc7691c05]
34  /opt/conda/envs/gdf/bin/python(_PyEval_EvalFrameDefault+0x4e17) [0x558fc7685fa7]
35  /opt/conda/envs/gdf/bin/python(+0x12827a) [0x558fc768027a]
36  /opt/conda/envs/gdf/bin/python(+0x147935) [0x558fc769f935]
37  /opt/conda/envs/gdf/bin/python(PyObject_Call+0xb4) [0x558fc76a0104]
38  /opt/conda/envs/gdf/bin/python(+0x20efc8) [0x558fc7766fc8]
39  /opt/conda/envs/gdf/bin/python(_PyObject_MakeTpCall+0x2fc) [0x558fc768a2bc]
40  /opt/conda/envs/gdf/bin/python(_PyEval_EvalFrameDefault+0x402b) [0x558fc76851bb]
41  /opt/conda/envs/gdf/bin/python(+0x139ef3) [0x558fc7691ef3]
42  /opt/conda/envs/gdf/bin/python(+0x147c72) [0x558fc769fc72]
43  /opt/conda/envs/gdf/bin/python(_PyEval_EvalFrameDefault+0x402b) [0x558fc76851bb]
44  /opt/conda/envs/gdf/bin/python(+0x139ef3) [0x558fc7691ef3]
45  /opt/conda/envs/gdf/bin/python(_PyEval_EvalFrameDefault+0x68b) [0x558fc768181b]
46  /opt/conda/envs/gdf/bin/python(+0x12827a) [0x558fc768027a]
47  /opt/conda/envs/gdf/bin/python(_PyFunction_Vectorcall+0xd5) [0x558fc7691c05]
48  /opt/conda/envs/gdf/bin/python(_PyEval_EvalFrameDefault+0x68b) [0x558fc768181b]
49  /opt/conda/envs/gdf/bin/python(+0x139ef3) [0x558fc7691ef3]
50  /opt/conda/envs/gdf/bin/python(_PyEval_EvalFrameDefault+0x3d8) [0x558fc7681568]
51  /opt/conda/envs/gdf/bin/python(+0x12827a) [0x558fc768027a]
52  /opt/conda/envs/gdf/bin/python(_PyFunction_Vectorcall+0xd5) [0x558fc7691c05]
53  /opt/conda/envs/gdf/bin/python(_PyEval_EvalFrameDefault+0x123b) [0x558fc76823cb]
54  /opt/conda/envs/gdf/bin/python(+0x12827a) [0x558fc768027a]
55  /opt/conda/envs/gdf/bin/python(_PyEval_EvalCodeWithName+0x47) [0x558fc767ff07]
56  /opt/conda/envs/gdf/bin/python(PyEval_EvalCodeEx+0x39) [0x558fc767feb9]
57  /opt/conda/envs/gdf/bin/python(PyEval_EvalCode+0x1b) [0x558fc77308bb]
58  /opt/conda/envs/gdf/bin/python(+0x206adc) [0x558fc775eadc]
59  /opt/conda/envs/gdf/bin/python(+0x202c24) [0x558fc775ac24]
60  /opt/conda/envs/gdf/bin/python(PyRun_StringFlags+0x9d) [0x558fc77527ed]
61  /opt/conda/envs/gdf/bin/python(PyRun_SimpleStringFlags+0x3d) [0x558fc77526bd]
=================================
2023-05-24 05:45:43,617 - distributed.worker - ERROR - failed during get data with ucx://127.0.0.1:53989 -> ucx://127.0.0.1:48031
Traceback (most recent call last):
  File "/opt/conda/envs/gdf/lib/python3.9/site-packages/distributed/comm/ucx.py", line 333, in write
    await self.ep.send(each_frame)
  File "/opt/conda/envs/gdf/lib/python3.9/site-packages/ucp/core.py", line 650, in send
    return await comm.tag_send(self._ep, buffer, nbytes, tag, name=log)
ucp._libs.exceptions.UCXError: <[Send #007] ep: 0x7f3d8465a400, tag: 0xa40e333097826604, nbytes: 100000000, type: <class 'cudf.core.buffer.buffer.Buffer'>>: Endpoint timeout

During handling of the above exception, another exception occurred:

Traceback (most recent call last):
  File "/opt/conda/envs/gdf/lib/python3.9/site-packages/distributed/worker.py", line 1792, in get_data
    compressed = await comm.write(msg, serializers=serializers)
  File "/opt/conda/envs/gdf/lib/python3.9/site-packages/distributed/utils.py", line 752, in wrapper
    return await func(*args, **kwargs)
  File "/opt/conda/envs/gdf/lib/python3.9/site-packages/distributed/comm/ucx.py", line 337, in write
    raise CommClosedError("While writing, the connection was closed")
distributed.comm.core.CommClosedError: While writing, the connection was closed
2023-05-24 05:45:43,619 - distributed.worker - ERROR - Worker stream died during communication: ucx://127.0.0.1:48031
Traceback (most recent call last):
  File "/opt/conda/envs/gdf/lib/python3.9/site-packages/distributed/comm/ucx.py", line 349, in read
    await self.ep.recv(msg)
  File "/opt/conda/envs/gdf/lib/python3.9/site-packages/ucp/core.py", line 725, in recv
    ret = await comm.tag_recv(self._ep, buffer, nbytes, tag, name=log)
ucp._libs.exceptions.UCXCanceled: <[Recv #003] ep: 0x7f3d8465a240, tag: 0x6e6f64396df35757, nbytes: 16, type: <class 'numpy.ndarray'>>: 

During handling of the above exception, another exception occurred:

Traceback (most recent call last):
  File "/opt/conda/envs/gdf/lib/python3.9/site-packages/distributed/worker.py", line 2066, in gather_dep
    response = await get_data_from_worker(
  File "/opt/conda/envs/gdf/lib/python3.9/site-packages/distributed/worker.py", line 2892, in get_data_from_worker
    response = await send_recv(
  File "/opt/conda/envs/gdf/lib/python3.9/site-packages/distributed/core.py", line 1024, in send_recv
    response = await comm.read(deserializers=deserializers)
  File "/opt/conda/envs/gdf/lib/python3.9/site-packages/distributed/utils.py", line 752, in wrapper
    return await func(*args, **kwargs)
  File "/opt/conda/envs/gdf/lib/python3.9/site-packages/distributed/comm/ucx.py", line 367, in read
    raise CommClosedError(
distributed.comm.core.CommClosedError: Connection closed by writer.
Inner exception: UCXCanceled("<[Recv #003] ep: 0x7f3d8465a240, tag: 0x6e6f64396df35757, nbytes: 16, type: <class 'numpy.ndarray'>>: ")
2023-05-24 05:45:43,619 - distributed.worker - ERROR - Worker stream died during communication: ucx://127.0.0.1:48031
Traceback (most recent call last):
  File "/opt/conda/envs/gdf/lib/python3.9/site-packages/distributed/comm/ucx.py", line 391, in read
    await self.ep.recv(each_frame)
  File "/opt/conda/envs/gdf/lib/python3.9/site-packages/ucp/core.py", line 725, in recv
    ret = await comm.tag_recv(self._ep, buffer, nbytes, tag, name=log)
ucp._libs.exceptions.UCXCanceled: <[Recv #009] ep: 0x7f53b0a35280, tag: 0xbbb1d8981f4bfc7d, nbytes: 100000000, type: <class 'rmm._lib.device_buffer.DeviceBuffer'>>: 

During handling of the above exception, another exception occurred:

Traceback (most recent call last):
  File "/opt/conda/envs/gdf/lib/python3.9/site-packages/distributed/worker.py", line 2066, in gather_dep
    response = await get_data_from_worker(
  File "/opt/conda/envs/gdf/lib/python3.9/site-packages/distributed/worker.py", line 2892, in get_data_from_worker
    response = await send_recv(
  File "/opt/conda/envs/gdf/lib/python3.9/site-packages/distributed/core.py", line 1024, in send_recv
    response = await comm.read(deserializers=deserializers)
  File "/opt/conda/envs/gdf/lib/python3.9/site-packages/distributed/utils.py", line 752, in wrapper
    return await func(*args, **kwargs)
  File "/opt/conda/envs/gdf/lib/python3.9/site-packages/distributed/comm/ucx.py", line 397, in read
    raise CommClosedError(
distributed.comm.core.CommClosedError: Connection closed by writer.
Inner exception: UCXCanceled("<[Recv #009] ep: 0x7f53b0a35280, tag: 0xbbb1d8981f4bfc7d, nbytes: 100000000, type: <class 'rmm._lib.device_buffer.DeviceBuffer'>>: ")
2023-05-24 05:45:43,620 - distributed.worker - ERROR - Worker stream died during communication: ucx://127.0.0.1:57205
Traceback (most recent call last):
  File "/opt/conda/envs/gdf/lib/python3.9/site-packages/distributed/comm/ucx.py", line 349, in read
    await self.ep.recv(msg)
  File "/opt/conda/envs/gdf/lib/python3.9/site-packages/ucp/core.py", line 725, in recv
    ret = await comm.tag_recv(self._ep, buffer, nbytes, tag, name=log)
ucp._libs.exceptions.UCXCanceled: <[Recv #003] ep: 0x7f3d8465a2c0, tag: 0xd86b626a7e9c6cbf, nbytes: 16, type: <class 'numpy.ndarray'>>: 

During handling of the above exception, another exception occurred:

Traceback (most recent call last):
  File "/opt/conda/envs/gdf/lib/python3.9/site-packages/distributed/worker.py", line 2066, in gather_dep
    response = await get_data_from_worker(
  File "/opt/conda/envs/gdf/lib/python3.9/site-packages/distributed/worker.py", line 2892, in get_data_from_worker
    response = await send_recv(
  File "/opt/conda/envs/gdf/lib/python3.9/site-packages/distributed/core.py", line 1024, in send_recv
    response = await comm.read(deserializers=deserializers)
  File "/opt/conda/envs/gdf/lib/python3.9/site-packages/distributed/utils.py", line 752, in wrapper
    return await func(*args, **kwargs)
  File "/opt/conda/envs/gdf/lib/python3.9/site-packages/distributed/comm/ucx.py", line 367, in read
    raise CommClosedError(
distributed.comm.core.CommClosedError: Connection closed by writer.
Inner exception: UCXCanceled("<[Recv #003] ep: 0x7f3d8465a2c0, tag: 0xd86b626a7e9c6cbf, nbytes: 16, type: <class 'numpy.ndarray'>>: ")
2023-05-24 05:45:43,620 - distributed.worker - ERROR - Worker stream died during communication: ucx://127.0.0.1:57205
Traceback (most recent call last):
  File "/opt/conda/envs/gdf/lib/python3.9/site-packages/distributed/comm/ucx.py", line 391, in read
    await self.ep.recv(each_frame)
  File "/opt/conda/envs/gdf/lib/python3.9/site-packages/ucp/core.py", line 725, in recv
    ret = await comm.tag_recv(self._ep, buffer, nbytes, tag, name=log)
ucp._libs.exceptions.UCXCanceled: <[Recv #008] ep: 0x7f53b0a35180, tag: 0x20bcbb4f49236da8, nbytes: 100000000, type: <class 'rmm._lib.device_buffer.DeviceBuffer'>>: 

During handling of the above exception, another exception occurred:

Traceback (most recent call last):
  File "/opt/conda/envs/gdf/lib/python3.9/site-packages/distributed/worker.py", line 2066, in gather_dep
    response = await get_data_from_worker(
  File "/opt/conda/envs/gdf/lib/python3.9/site-packages/distributed/worker.py", line 2892, in get_data_from_worker
    response = await send_recv(
  File "/opt/conda/envs/gdf/lib/python3.9/site-packages/distributed/core.py", line 1024, in send_recv
    response = await comm.read(deserializers=deserializers)
  File "/opt/conda/envs/gdf/lib/python3.9/site-packages/distributed/utils.py", line 752, in wrapper
    return await func(*args, **kwargs)
  File "/opt/conda/envs/gdf/lib/python3.9/site-packages/distributed/comm/ucx.py", line 397, in read
    raise CommClosedError(
distributed.comm.core.CommClosedError: Connection closed by writer.
Inner exception: UCXCanceled("<[Recv #008] ep: 0x7f53b0a35180, tag: 0x20bcbb4f49236da8, nbytes: 100000000, type: <class 'rmm._lib.device_buffer.DeviceBuffer'>>: ")
2023-05-24 05:45:43,643 - distributed.worker - ERROR - Worker stream died during communication: ucx://127.0.0.1:48031
Traceback (most recent call last):
  File "/opt/conda/envs/gdf/lib/python3.9/site-packages/distributed/comm/ucx.py", line 391, in read
    await self.ep.recv(each_frame)
  File "/opt/conda/envs/gdf/lib/python3.9/site-packages/ucp/core.py", line 708, in recv
    self._ep.raise_on_error()
  File "ucp/_libs/ucx_endpoint.pyx", line 355, in ucp._libs.ucx_api.UCXEndpoint.raise_on_error
ucp._libs.exceptions.UCXError: Endpoint 0x7ff6cc629280 error: Endpoint timeout

During handling of the above exception, another exception occurred:

Traceback (most recent call last):
  File "/opt/conda/envs/gdf/lib/python3.9/site-packages/distributed/worker.py", line 2066, in gather_dep
    response = await get_data_from_worker(
  File "/opt/conda/envs/gdf/lib/python3.9/site-packages/distributed/worker.py", line 2892, in get_data_from_worker
    response = await send_recv(
  File "/opt/conda/envs/gdf/lib/python3.9/site-packages/distributed/core.py", line 1024, in send_recv
    response = await comm.read(deserializers=deserializers)
  File "/opt/conda/envs/gdf/lib/python3.9/site-packages/distributed/utils.py", line 752, in wrapper
    return await func(*args, **kwargs)
  File "/opt/conda/envs/gdf/lib/python3.9/site-packages/distributed/comm/ucx.py", line 397, in read
    raise CommClosedError(
distributed.comm.core.CommClosedError: Connection closed by writer.
Inner exception: UCXError('Endpoint 0x7ff6cc629280 error: Endpoint timeout')
2023-05-24 05:45:43,649 - distributed.worker - ERROR - failed during get data with ucx://127.0.0.1:56207 -> ucx://127.0.0.1:48031
Traceback (most recent call last):
  File "/opt/conda/envs/gdf/lib/python3.9/site-packages/distributed/comm/ucx.py", line 333, in write
    await self.ep.send(each_frame)
  File "/opt/conda/envs/gdf/lib/python3.9/site-packages/ucp/core.py", line 629, in send
    self._ep.raise_on_error()
  File "ucp/_libs/ucx_endpoint.pyx", line 355, in ucp._libs.ucx_api.UCXEndpoint.raise_on_error
ucp._libs.exceptions.UCXError: Endpoint 0x7ff6cc629400 error: Endpoint timeout

During handling of the above exception, another exception occurred:

Traceback (most recent call last):
  File "/opt/conda/envs/gdf/lib/python3.9/site-packages/distributed/worker.py", line 1792, in get_data
    compressed = await comm.write(msg, serializers=serializers)
  File "/opt/conda/envs/gdf/lib/python3.9/site-packages/distributed/utils.py", line 752, in wrapper
    return await func(*args, **kwargs)
  File "/opt/conda/envs/gdf/lib/python3.9/site-packages/distributed/comm/ucx.py", line 337, in write
    raise CommClosedError("While writing, the connection was closed")
distributed.comm.core.CommClosedError: While writing, the connection was closed
2023-05-24 05:45:43,649 - distributed.worker - ERROR - failed during get data with ucx://127.0.0.1:56207 -> ucx://127.0.0.1:57205
Traceback (most recent call last):
  File "/opt/conda/envs/gdf/lib/python3.9/site-packages/distributed/comm/ucx.py", line 333, in write
    await self.ep.send(each_frame)
  File "/opt/conda/envs/gdf/lib/python3.9/site-packages/ucp/core.py", line 650, in send
    return await comm.tag_send(self._ep, buffer, nbytes, tag, name=log)
ucp._libs.exceptions.UCXError: <[Send #007] ep: 0x7ff6cc629380, tag: 0xc94f310f0b0f4b7f, nbytes: 100000000, type: <class 'cudf.core.buffer.buffer.Buffer'>>: Endpoint timeout

During handling of the above exception, another exception occurred:

Traceback (most recent call last):
  File "/opt/conda/envs/gdf/lib/python3.9/site-packages/distributed/worker.py", line 1792, in get_data
    compressed = await comm.write(msg, serializers=serializers)
  File "/opt/conda/envs/gdf/lib/python3.9/site-packages/distributed/utils.py", line 752, in wrapper
    return await func(*args, **kwargs)
  File "/opt/conda/envs/gdf/lib/python3.9/site-packages/distributed/comm/ucx.py", line 337, in write
    raise CommClosedError("While writing, the connection was closed")
distributed.comm.core.CommClosedError: While writing, the connection was closed
2023-05-24 05:45:43,651 - distributed.worker - ERROR - Worker stream died during communication: ucx://127.0.0.1:57205
Traceback (most recent call last):
  File "/opt/conda/envs/gdf/lib/python3.9/site-packages/distributed/comm/ucx.py", line 349, in read
    await self.ep.recv(msg)
  File "/opt/conda/envs/gdf/lib/python3.9/site-packages/ucp/core.py", line 725, in recv
    ret = await comm.tag_recv(self._ep, buffer, nbytes, tag, name=log)
ucp._libs.exceptions.UCXCanceled: <[Recv #003] ep: 0x7ff6cc629100, tag: 0xee034ff4e7346429, nbytes: 16, type: <class 'numpy.ndarray'>>: 

During handling of the above exception, another exception occurred:

Traceback (most recent call last):
  File "/opt/conda/envs/gdf/lib/python3.9/site-packages/distributed/worker.py", line 2066, in gather_dep
    response = await get_data_from_worker(
  File "/opt/conda/envs/gdf/lib/python3.9/site-packages/distributed/worker.py", line 2892, in get_data_from_worker
    response = await send_recv(
  File "/opt/conda/envs/gdf/lib/python3.9/site-packages/distributed/core.py", line 1024, in send_recv
    response = await comm.read(deserializers=deserializers)
  File "/opt/conda/envs/gdf/lib/python3.9/site-packages/distributed/utils.py", line 752, in wrapper
    return await func(*args, **kwargs)
  File "/opt/conda/envs/gdf/lib/python3.9/site-packages/distributed/comm/ucx.py", line 367, in read
    raise CommClosedError(
distributed.comm.core.CommClosedError: Connection closed by writer.
Inner exception: UCXCanceled("<[Recv #003] ep: 0x7ff6cc629100, tag: 0xee034ff4e7346429, nbytes: 16, type: <class 'numpy.ndarray'>>: ")
2023-05-24 05:45:43,657 - distributed.worker - ERROR - failed during get data with ucx://127.0.0.1:39305 -> ucx://127.0.0.1:57205
Traceback (most recent call last):
  File "/opt/conda/envs/gdf/lib/python3.9/site-packages/distributed/comm/ucx.py", line 333, in write
    await self.ep.send(each_frame)
  File "/opt/conda/envs/gdf/lib/python3.9/site-packages/ucp/core.py", line 650, in send
    return await comm.tag_send(self._ep, buffer, nbytes, tag, name=log)
ucp._libs.exceptions.UCXError: <[Send #007] ep: 0x7f55f44f6400, tag: 0x653049a8e0785f38, nbytes: 100000000, type: <class 'cudf.core.buffer.buffer.Buffer'>>: Endpoint timeout

During handling of the above exception, another exception occurred:

Traceback (most recent call last):
  File "/opt/conda/envs/gdf/lib/python3.9/site-packages/distributed/worker.py", line 1792, in get_data
    compressed = await comm.write(msg, serializers=serializers)
  File "/opt/conda/envs/gdf/lib/python3.9/site-packages/distributed/utils.py", line 752, in wrapper
    return await func(*args, **kwargs)
  File "/opt/conda/envs/gdf/lib/python3.9/site-packages/distributed/comm/ucx.py", line 337, in write
    raise CommClosedError("While writing, the connection was closed")
distributed.comm.core.CommClosedError: While writing, the connection was closed
2023-05-24 05:45:43,659 - distributed.worker - ERROR - failed during get data with ucx://127.0.0.1:39305 -> ucx://127.0.0.1:48031
Traceback (most recent call last):
  File "/opt/conda/envs/gdf/lib/python3.9/site-packages/distributed/comm/ucx.py", line 333, in write
    await self.ep.send(each_frame)
  File "/opt/conda/envs/gdf/lib/python3.9/site-packages/ucp/core.py", line 650, in send
    return await comm.tag_send(self._ep, buffer, nbytes, tag, name=log)
ucp._libs.exceptions.UCXError: <[Send #007] ep: 0x7f55f44f6440, tag: 0x9b957a7e5827ca42, nbytes: 100000000, type: <class 'cudf.core.buffer.buffer.Buffer'>>: Endpoint timeout

During handling of the above exception, another exception occurred:

Traceback (most recent call last):
  File "/opt/conda/envs/gdf/lib/python3.9/site-packages/distributed/worker.py", line 1792, in get_data
    compressed = await comm.write(msg, serializers=serializers)
  File "/opt/conda/envs/gdf/lib/python3.9/site-packages/distributed/utils.py", line 752, in wrapper
    return await func(*args, **kwargs)
  File "/opt/conda/envs/gdf/lib/python3.9/site-packages/distributed/comm/ucx.py", line 337, in write
    raise CommClosedError("While writing, the connection was closed")
distributed.comm.core.CommClosedError: While writing, the connection was closed
[dgx13:80084:0:80084] Caught signal 11 (Segmentation fault: address not mapped to object at address 0x448)
==== backtrace (tid:  80084) ====
 0  /opt/conda/envs/gdf/lib/libucs.so.0(ucs_handle_error+0x2dc) [0x7fc64089d11c]
 1  /opt/conda/envs/gdf/lib/libucs.so.0(+0x302ff) [0x7fc64089d2ff]
 2  /opt/conda/envs/gdf/lib/libucs.so.0(+0x30634) [0x7fc64089d634]
 3  /usr/lib/x86_64-linux-gnu/libpthread.so.0(+0x14420) [0x7fc6d321c420]
 4  /opt/conda/envs/gdf/lib/libucp.so.0(ucp_mem_type_unpack+0x1b) [0x7fc64091e28b]
 5  /opt/conda/envs/gdf/lib/libucp.so.0(ucp_rndv_data_handler+0x508) [0x7fc6409480b8]
 6  /opt/conda/envs/gdf/lib/libuct.so.0(+0x216a7) [0x7fc64084f6a7]
 7  /opt/conda/envs/gdf/lib/libuct.so.0(+0x21c28) [0x7fc64084fc28]
 8  /opt/conda/envs/gdf/lib/libuct.so.0(+0x240fc) [0x7fc6408520fc]
 9  /opt/conda/envs/gdf/lib/libucs.so.0(ucs_event_set_wait+0xf9) [0x7fc6408a7639]
10  /opt/conda/envs/gdf/lib/libuct.so.0(uct_tcp_iface_progress+0x7b) [0x7fc6408521ab]
11  /opt/conda/envs/gdf/lib/libucp.so.0(ucp_worker_progress+0x6a) [0x7fc64091af1a]
12  /opt/conda/envs/gdf/lib/python3.9/site-packages/ucp/_libs/ucx_api.cpython-39-x86_64-linux-gnu.so(+0x286e1) [0x7fc6409ca6e1]
13  /opt/conda/envs/gdf/bin/python(+0x13eb08) [0x556593177b08]
14  /opt/conda/envs/gdf/bin/python(_PyEval_EvalFrameDefault+0x5f82) [0x556593168112]
15  /opt/conda/envs/gdf/bin/python(+0x12827a) [0x55659316127a]
16  /opt/conda/envs/gdf/bin/python(_PyFunction_Vectorcall+0xd5) [0x556593172c05]
17  /opt/conda/envs/gdf/bin/python(_PyEval_EvalFrameDefault+0x68b) [0x55659316281b]
18  /opt/conda/envs/gdf/bin/python(+0x14e70e) [0x55659318770e]
19  /opt/conda/envs/gdf/lib/python3.9/lib-dynload/_asyncio.cpython-39-x86_64-linux-gnu.so(+0x82fe) [0x7fc652c4e2fe]
20  /opt/conda/envs/gdf/bin/python(_PyObject_MakeTpCall+0x2fc) [0x55659316b2bc]
21  /opt/conda/envs/gdf/bin/python(+0xe5817) [0x55659311e817]
22  /opt/conda/envs/gdf/bin/python(+0x130f83) [0x556593169f83]
23  /opt/conda/envs/gdf/bin/python(_PyEval_EvalFrameDefault+0x5ba6) [0x556593167d36]
24  /opt/conda/envs/gdf/bin/python(+0x139ef3) [0x556593172ef3]
25  /opt/conda/envs/gdf/bin/python(_PyEval_EvalFrameDefault+0x68b) [0x55659316281b]
26  /opt/conda/envs/gdf/bin/python(+0x139ef3) [0x556593172ef3]
27  /opt/conda/envs/gdf/bin/python(_PyEval_EvalFrameDefault+0x68b) [0x55659316281b]
28  /opt/conda/envs/gdf/bin/python(+0x139ef3) [0x556593172ef3]
29  /opt/conda/envs/gdf/bin/python(_PyEval_EvalFrameDefault+0x68b) [0x55659316281b]
30  /opt/conda/envs/gdf/bin/python(+0x139ef3) [0x556593172ef3]
31  /opt/conda/envs/gdf/bin/python(_PyEval_EvalFrameDefault+0x68b) [0x55659316281b]
32  /opt/conda/envs/gdf/bin/python(+0x12827a) [0x55659316127a]
33  /opt/conda/envs/gdf/bin/python(_PyFunction_Vectorcall+0xd5) [0x556593172c05]
34  /opt/conda/envs/gdf/bin/python(_PyEval_EvalFrameDefault+0x4e17) [0x556593166fa7]
35  /opt/conda/envs/gdf/bin/python(+0x12827a) [0x55659316127a]
36  /opt/conda/envs/gdf/bin/python(+0x147935) [0x556593180935]
37  /opt/conda/envs/gdf/bin/python(PyObject_Call+0xb4) [0x556593181104]
38  /opt/conda/envs/gdf/bin/python(+0x20efc8) [0x556593247fc8]
39  /opt/conda/envs/gdf/bin/python(_PyObject_MakeTpCall+0x2fc) [0x55659316b2bc]
40  /opt/conda/envs/gdf/bin/python(_PyEval_EvalFrameDefault+0x402b) [0x5565931661bb]
41  /opt/conda/envs/gdf/bin/python(+0x139ef3) [0x556593172ef3]
42  /opt/conda/envs/gdf/bin/python(+0x147c72) [0x556593180c72]
43  /opt/conda/envs/gdf/bin/python(_PyEval_EvalFrameDefault+0x402b) [0x5565931661bb]
44  /opt/conda/envs/gdf/bin/python(+0x139ef3) [0x556593172ef3]
45  /opt/conda/envs/gdf/bin/python(_PyEval_EvalFrameDefault+0x68b) [0x55659316281b]
46  /opt/conda/envs/gdf/bin/python(+0x12827a) [0x55659316127a]
47  /opt/conda/envs/gdf/bin/python(_PyFunction_Vectorcall+0xd5) [0x556593172c05]
48  /opt/conda/envs/gdf/bin/python(_PyEval_EvalFrameDefault+0x68b) [0x55659316281b]
49  /opt/conda/envs/gdf/bin/python(+0x139ef3) [0x556593172ef3]
50  /opt/conda/envs/gdf/bin/python(_PyEval_EvalFrameDefault+0x3d8) [0x556593162568]
51  /opt/conda/envs/gdf/bin/python(+0x12827a) [0x55659316127a]
52  /opt/conda/envs/gdf/bin/python(_PyFunction_Vectorcall+0xd5) [0x556593172c05]
53  /opt/conda/envs/gdf/bin/python(_PyEval_EvalFrameDefault+0x123b) [0x5565931633cb]
54  /opt/conda/envs/gdf/bin/python(+0x12827a) [0x55659316127a]
55  /opt/conda/envs/gdf/bin/python(_PyEval_EvalCodeWithName+0x47) [0x556593160f07]
56  /opt/conda/envs/gdf/bin/python(PyEval_EvalCodeEx+0x39) [0x556593160eb9]
57  /opt/conda/envs/gdf/bin/python(PyEval_EvalCode+0x1b) [0x5565932118bb]
58  /opt/conda/envs/gdf/bin/python(+0x206adc) [0x55659323fadc]
59  /opt/conda/envs/gdf/bin/python(+0x202c24) [0x55659323bc24]
60  /opt/conda/envs/gdf/bin/python(PyRun_StringFlags+0x9d) [0x5565932337ed]
61  /opt/conda/envs/gdf/bin/python(PyRun_SimpleStringFlags+0x3d) [0x5565932336bd]
=================================
2023-05-24 05:45:43,684 - distributed.worker - ERROR - Worker stream died during communication: ucx://127.0.0.1:50535
Traceback (most recent call last):
  File "/opt/conda/envs/gdf/lib/python3.9/site-packages/distributed/comm/ucx.py", line 349, in read
    await self.ep.recv(msg)
  File "/opt/conda/envs/gdf/lib/python3.9/site-packages/ucp/core.py", line 725, in recv
    ret = await comm.tag_recv(self._ep, buffer, nbytes, tag, name=log)
ucp._libs.exceptions.UCXCanceled: <[Recv #003] ep: 0x7f53b0a35140, tag: 0xb42e0f0e79b3075c, nbytes: 16, type: <class 'numpy.ndarray'>>: 

During handling of the above exception, another exception occurred:

Traceback (most recent call last):
  File "/opt/conda/envs/gdf/lib/python3.9/site-packages/distributed/worker.py", line 2066, in gather_dep
    response = await get_data_from_worker(
  File "/opt/conda/envs/gdf/lib/python3.9/site-packages/distributed/worker.py", line 2892, in get_data_from_worker
    response = await send_recv(
  File "/opt/conda/envs/gdf/lib/python3.9/site-packages/distributed/core.py", line 1024, in send_recv
    response = await comm.read(deserializers=deserializers)
  File "/opt/conda/envs/gdf/lib/python3.9/site-packages/distributed/utils.py", line 752, in wrapper
    return await func(*args, **kwargs)
  File "/opt/conda/envs/gdf/lib/python3.9/site-packages/distributed/comm/ucx.py", line 367, in read
    raise CommClosedError(
distributed.comm.core.CommClosedError: Connection closed by writer.
Inner exception: UCXCanceled("<[Recv #003] ep: 0x7f53b0a35140, tag: 0xb42e0f0e79b3075c, nbytes: 16, type: <class 'numpy.ndarray'>>: ")
2023-05-24 05:45:43,735 - distributed.nanny - WARNING - Restarting worker
2023-05-24 05:45:43,736 - distributed.nanny - WARNING - Restarting worker
2023-05-24 05:45:43,737 - distributed.worker - ERROR - Worker stream died during communication: ucx://127.0.0.1:50535
Traceback (most recent call last):
  File "/opt/conda/envs/gdf/lib/python3.9/site-packages/distributed/comm/ucx.py", line 391, in read
    await self.ep.recv(each_frame)
  File "/opt/conda/envs/gdf/lib/python3.9/site-packages/ucp/core.py", line 708, in recv
    self._ep.raise_on_error()
  File "ucp/_libs/ucx_endpoint.pyx", line 353, in ucp._libs.ucx_api.UCXEndpoint.raise_on_error
ucp._libs.exceptions.UCXConnectionReset: Endpoint 0x7f55f44f6240 error: Connection reset by remote peer

During handling of the above exception, another exception occurred:

Traceback (most recent call last):
  File "/opt/conda/envs/gdf/lib/python3.9/site-packages/distributed/worker.py", line 2066, in gather_dep
    response = await get_data_from_worker(
  File "/opt/conda/envs/gdf/lib/python3.9/site-packages/distributed/worker.py", line 2892, in get_data_from_worker
    response = await send_recv(
  File "/opt/conda/envs/gdf/lib/python3.9/site-packages/distributed/core.py", line 1024, in send_recv
    response = await comm.read(deserializers=deserializers)
  File "/opt/conda/envs/gdf/lib/python3.9/site-packages/distributed/utils.py", line 752, in wrapper
    return await func(*args, **kwargs)
  File "/opt/conda/envs/gdf/lib/python3.9/site-packages/distributed/comm/ucx.py", line 397, in read
    raise CommClosedError(
distributed.comm.core.CommClosedError: Connection closed by writer.
Inner exception: UCXConnectionReset('Endpoint 0x7f55f44f6240 error: Connection reset by remote peer')
2023-05-24 05:45:43,738 - distributed.worker - ERROR - Worker stream died during communication: ucx://127.0.0.1:57205
Traceback (most recent call last):
  File "/opt/conda/envs/gdf/lib/python3.9/site-packages/distributed/comm/ucx.py", line 349, in read
    await self.ep.recv(msg)
  File "/opt/conda/envs/gdf/lib/python3.9/site-packages/ucp/core.py", line 725, in recv
    ret = await comm.tag_recv(self._ep, buffer, nbytes, tag, name=log)
ucp._libs.exceptions.UCXCanceled: <[Recv #003] ep: 0x7f55f44f6140, tag: 0x98d3bb3c4e119539, nbytes: 16, type: <class 'numpy.ndarray'>>: 

During handling of the above exception, another exception occurred:

Traceback (most recent call last):
  File "/opt/conda/envs/gdf/lib/python3.9/site-packages/distributed/worker.py", line 2066, in gather_dep
    response = await get_data_from_worker(
  File "/opt/conda/envs/gdf/lib/python3.9/site-packages/distributed/worker.py", line 2892, in get_data_from_worker
    response = await send_recv(
  File "/opt/conda/envs/gdf/lib/python3.9/site-packages/distributed/core.py", line 1024, in send_recv
    response = await comm.read(deserializers=deserializers)
  File "/opt/conda/envs/gdf/lib/python3.9/site-packages/distributed/utils.py", line 752, in wrapper
    return await func(*args, **kwargs)
  File "/opt/conda/envs/gdf/lib/python3.9/site-packages/distributed/comm/ucx.py", line 367, in read
    raise CommClosedError(
distributed.comm.core.CommClosedError: Connection closed by writer.
Inner exception: UCXCanceled("<[Recv #003] ep: 0x7f55f44f6140, tag: 0x98d3bb3c4e119539, nbytes: 16, type: <class 'numpy.ndarray'>>: ")
2023-05-24 05:45:43,739 - distributed.worker - ERROR - Worker stream died during communication: ucx://127.0.0.1:48031
Traceback (most recent call last):
  File "/opt/conda/envs/gdf/lib/python3.9/site-packages/distributed/comm/ucx.py", line 349, in read
    await self.ep.recv(msg)
  File "/opt/conda/envs/gdf/lib/python3.9/site-packages/ucp/core.py", line 725, in recv
    ret = await comm.tag_recv(self._ep, buffer, nbytes, tag, name=log)
ucp._libs.exceptions.UCXCanceled: <[Recv #003] ep: 0x7f55f44f61c0, tag: 0xc2a742012c6b196d, nbytes: 16, type: <class 'numpy.ndarray'>>: 

During handling of the above exception, another exception occurred:

Traceback (most recent call last):
  File "/opt/conda/envs/gdf/lib/python3.9/site-packages/distributed/worker.py", line 2066, in gather_dep
    response = await get_data_from_worker(
  File "/opt/conda/envs/gdf/lib/python3.9/site-packages/distributed/worker.py", line 2892, in get_data_from_worker
    response = await send_recv(
  File "/opt/conda/envs/gdf/lib/python3.9/site-packages/distributed/core.py", line 1024, in send_recv
    response = await comm.read(deserializers=deserializers)
  File "/opt/conda/envs/gdf/lib/python3.9/site-packages/distributed/utils.py", line 752, in wrapper
    return await func(*args, **kwargs)
  File "/opt/conda/envs/gdf/lib/python3.9/site-packages/distributed/comm/ucx.py", line 367, in read
    raise CommClosedError(
distributed.comm.core.CommClosedError: Connection closed by writer.
Inner exception: UCXCanceled("<[Recv #003] ep: 0x7f55f44f61c0, tag: 0xc2a742012c6b196d, nbytes: 16, type: <class 'numpy.ndarray'>>: ")
2023-05-24 05:45:43,697 - distributed.worker - ERROR - failed during get data with ucx://127.0.0.1:53989 -> ucx://127.0.0.1:50535
Traceback (most recent call last):
  File "/opt/conda/envs/gdf/lib/python3.9/site-packages/distributed/comm/ucx.py", line 333, in write
    await self.ep.send(each_frame)
  File "/opt/conda/envs/gdf/lib/python3.9/site-packages/ucp/core.py", line 650, in send
    return await comm.tag_send(self._ep, buffer, nbytes, tag, name=log)
ucp._libs.exceptions.UCXError: <[Send #007] ep: 0x7f3d8465a140, tag: 0x205b79f6e530d706, nbytes: 100000000, type: <class 'cudf.core.buffer.buffer.Buffer'>>: Endpoint timeout

During handling of the above exception, another exception occurred:

Traceback (most recent call last):
  File "/opt/conda/envs/gdf/lib/python3.9/site-packages/distributed/worker.py", line 1792, in get_data
    compressed = await comm.write(msg, serializers=serializers)
  File "/opt/conda/envs/gdf/lib/python3.9/site-packages/distributed/utils.py", line 752, in wrapper
    return await func(*args, **kwargs)
  File "/opt/conda/envs/gdf/lib/python3.9/site-packages/distributed/comm/ucx.py", line 337, in write
    raise CommClosedError("While writing, the connection was closed")
distributed.comm.core.CommClosedError: While writing, the connection was closed
2023-05-24 05:45:43,741 - distributed.worker - ERROR - Worker stream died during communication: ucx://127.0.0.1:50535
Traceback (most recent call last):
  File "/opt/conda/envs/gdf/lib/python3.9/site-packages/distributed/comm/ucx.py", line 349, in read
    await self.ep.recv(msg)
  File "/opt/conda/envs/gdf/lib/python3.9/site-packages/ucp/core.py", line 725, in recv
    ret = await comm.tag_recv(self._ep, buffer, nbytes, tag, name=log)
ucp._libs.exceptions.UCXCanceled: <[Recv #003] ep: 0x7f3d8465a1c0, tag: 0x157d5f4dfc8d0551, nbytes: 16, type: <class 'numpy.ndarray'>>: 

During handling of the above exception, another exception occurred:

Traceback (most recent call last):
  File "/opt/conda/envs/gdf/lib/python3.9/site-packages/distributed/worker.py", line 2066, in gather_dep
    response = await get_data_from_worker(
  File "/opt/conda/envs/gdf/lib/python3.9/site-packages/distributed/worker.py", line 2892, in get_data_from_worker
    response = await send_recv(
  File "/opt/conda/envs/gdf/lib/python3.9/site-packages/distributed/core.py", line 1024, in send_recv
    response = await comm.read(deserializers=deserializers)
  File "/opt/conda/envs/gdf/lib/python3.9/site-packages/distributed/utils.py", line 752, in wrapper
    return await func(*args, **kwargs)
  File "/opt/conda/envs/gdf/lib/python3.9/site-packages/distributed/comm/ucx.py", line 367, in read
    raise CommClosedError(
distributed.comm.core.CommClosedError: Connection closed by writer.
Inner exception: UCXCanceled("<[Recv #003] ep: 0x7f3d8465a1c0, tag: 0x157d5f4dfc8d0551, nbytes: 16, type: <class 'numpy.ndarray'>>: ")
2023-05-24 05:45:43,771 - distributed.worker - ERROR - Worker stream died during communication: ucx://127.0.0.1:50535
Traceback (most recent call last):
  File "/opt/conda/envs/gdf/lib/python3.9/site-packages/distributed/comm/ucx.py", line 349, in read
    await self.ep.recv(msg)
  File "/opt/conda/envs/gdf/lib/python3.9/site-packages/ucp/core.py", line 725, in recv
    ret = await comm.tag_recv(self._ep, buffer, nbytes, tag, name=log)
ucp._libs.exceptions.UCXCanceled: <[Recv #003] ep: 0x7ff6cc629180, tag: 0xe8a722e2e40b41e5, nbytes: 16, type: <class 'numpy.ndarray'>>: 

During handling of the above exception, another exception occurred:

Traceback (most recent call last):
  File "/opt/conda/envs/gdf/lib/python3.9/site-packages/distributed/worker.py", line 2066, in gather_dep
    response = await get_data_from_worker(
  File "/opt/conda/envs/gdf/lib/python3.9/site-packages/distributed/worker.py", line 2892, in get_data_from_worker
    response = await send_recv(
  File "/opt/conda/envs/gdf/lib/python3.9/site-packages/distributed/core.py", line 1024, in send_recv
    response = await comm.read(deserializers=deserializers)
  File "/opt/conda/envs/gdf/lib/python3.9/site-packages/distributed/utils.py", line 752, in wrapper
    return await func(*args, **kwargs)
  File "/opt/conda/envs/gdf/lib/python3.9/site-packages/distributed/comm/ucx.py", line 367, in read
    raise CommClosedError(
distributed.comm.core.CommClosedError: Connection closed by writer.
Inner exception: UCXCanceled("<[Recv #003] ep: 0x7ff6cc629180, tag: 0xe8a722e2e40b41e5, nbytes: 16, type: <class 'numpy.ndarray'>>: ")
2023-05-24 05:45:43,821 - distributed.nanny - WARNING - Restarting worker
2023-05-24 05:45:43,906 - distributed.worker - ERROR - Worker stream died during communication: ucx://127.0.0.1:36959
Traceback (most recent call last):
  File "/opt/conda/envs/gdf/lib/python3.9/site-packages/distributed/comm/ucx.py", line 391, in read
    await self.ep.recv(each_frame)
  File "/opt/conda/envs/gdf/lib/python3.9/site-packages/ucp/core.py", line 725, in recv
    ret = await comm.tag_recv(self._ep, buffer, nbytes, tag, name=log)
ucp._libs.exceptions.UCXCanceled: <[Recv #008] ep: 0x7f3d8465a280, tag: 0x72504a389d3aec98, nbytes: 100000000, type: <class 'rmm._lib.device_buffer.DeviceBuffer'>>: 

During handling of the above exception, another exception occurred:

Traceback (most recent call last):
  File "/opt/conda/envs/gdf/lib/python3.9/site-packages/distributed/worker.py", line 2066, in gather_dep
    response = await get_data_from_worker(
  File "/opt/conda/envs/gdf/lib/python3.9/site-packages/distributed/worker.py", line 2892, in get_data_from_worker
    response = await send_recv(
  File "/opt/conda/envs/gdf/lib/python3.9/site-packages/distributed/core.py", line 1024, in send_recv
    response = await comm.read(deserializers=deserializers)
  File "/opt/conda/envs/gdf/lib/python3.9/site-packages/distributed/utils.py", line 752, in wrapper
    return await func(*args, **kwargs)
  File "/opt/conda/envs/gdf/lib/python3.9/site-packages/distributed/comm/ucx.py", line 397, in read
    raise CommClosedError(
distributed.comm.core.CommClosedError: Connection closed by writer.
Inner exception: UCXCanceled("<[Recv #008] ep: 0x7f3d8465a280, tag: 0x72504a389d3aec98, nbytes: 100000000, type: <class 'rmm._lib.device_buffer.DeviceBuffer'>>: ")
2023-05-24 05:45:43,922 - distributed.worker - ERROR - Worker stream died during communication: ucx://127.0.0.1:36959
Traceback (most recent call last):
  File "/opt/conda/envs/gdf/lib/python3.9/site-packages/distributed/comm/ucx.py", line 391, in read
    await self.ep.recv(each_frame)
  File "/opt/conda/envs/gdf/lib/python3.9/site-packages/ucp/core.py", line 725, in recv
    ret = await comm.tag_recv(self._ep, buffer, nbytes, tag, name=log)
ucp._libs.exceptions.UCXCanceled: <[Recv #008] ep: 0x7ff6cc629140, tag: 0x2f73bd8c514a73d5, nbytes: 100000000, type: <class 'rmm._lib.device_buffer.DeviceBuffer'>>: 

During handling of the above exception, another exception occurred:

Traceback (most recent call last):
  File "/opt/conda/envs/gdf/lib/python3.9/site-packages/distributed/worker.py", line 2066, in gather_dep
    response = await get_data_from_worker(
  File "/opt/conda/envs/gdf/lib/python3.9/site-packages/distributed/worker.py", line 2892, in get_data_from_worker
    response = await send_recv(
  File "/opt/conda/envs/gdf/lib/python3.9/site-packages/distributed/core.py", line 1024, in send_recv
    response = await comm.read(deserializers=deserializers)
  File "/opt/conda/envs/gdf/lib/python3.9/site-packages/distributed/utils.py", line 752, in wrapper
    return await func(*args, **kwargs)
  File "/opt/conda/envs/gdf/lib/python3.9/site-packages/distributed/comm/ucx.py", line 397, in read
    raise CommClosedError(
distributed.comm.core.CommClosedError: Connection closed by writer.
Inner exception: UCXCanceled("<[Recv #008] ep: 0x7ff6cc629140, tag: 0x2f73bd8c514a73d5, nbytes: 100000000, type: <class 'rmm._lib.device_buffer.DeviceBuffer'>>: ")
2023-05-24 05:45:43,963 - distributed.nanny - WARNING - Restarting worker
2023-05-24 05:45:44,040 - distributed.worker - ERROR - failed during get data with ucx://127.0.0.1:44315 -> ucx://127.0.0.1:36959
Traceback (most recent call last):
  File "/opt/conda/envs/gdf/lib/python3.9/site-packages/distributed/comm/ucx.py", line 333, in write
    await self.ep.send(each_frame)
  File "/opt/conda/envs/gdf/lib/python3.9/site-packages/ucp/core.py", line 650, in send
    return await comm.tag_send(self._ep, buffer, nbytes, tag, name=log)
ucp._libs.exceptions.UCXError: <[Send #007] ep: 0x7f53b0a352c0, tag: 0x6cbeeedcffc19e44, nbytes: 100000000, type: <class 'cudf.core.buffer.buffer.Buffer'>>: Endpoint timeout

During handling of the above exception, another exception occurred:

Traceback (most recent call last):
  File "/opt/conda/envs/gdf/lib/python3.9/site-packages/distributed/worker.py", line 1792, in get_data
    compressed = await comm.write(msg, serializers=serializers)
  File "/opt/conda/envs/gdf/lib/python3.9/site-packages/distributed/utils.py", line 752, in wrapper
    return await func(*args, **kwargs)
  File "/opt/conda/envs/gdf/lib/python3.9/site-packages/distributed/comm/ucx.py", line 337, in write
    raise CommClosedError("While writing, the connection was closed")
distributed.comm.core.CommClosedError: While writing, the connection was closed
2023-05-24 05:45:44,041 - distributed.worker - ERROR - Worker stream died during communication: ucx://127.0.0.1:36959
Traceback (most recent call last):
  File "/opt/conda/envs/gdf/lib/python3.9/site-packages/distributed/comm/ucx.py", line 391, in read
    await self.ep.recv(each_frame)
  File "/opt/conda/envs/gdf/lib/python3.9/site-packages/ucp/core.py", line 725, in recv
    ret = await comm.tag_recv(self._ep, buffer, nbytes, tag, name=log)
ucp._libs.exceptions.UCXError: <[Recv #007] ep: 0x7f53b0a35240, tag: 0x66fe79b4706c461f, nbytes: 100000000, type: <class 'rmm._lib.device_buffer.DeviceBuffer'>>: Endpoint timeout

During handling of the above exception, another exception occurred:

Traceback (most recent call last):
  File "/opt/conda/envs/gdf/lib/python3.9/site-packages/distributed/worker.py", line 2066, in gather_dep
    response = await get_data_from_worker(
  File "/opt/conda/envs/gdf/lib/python3.9/site-packages/distributed/worker.py", line 2892, in get_data_from_worker
    response = await send_recv(
  File "/opt/conda/envs/gdf/lib/python3.9/site-packages/distributed/core.py", line 1024, in send_recv
    response = await comm.read(deserializers=deserializers)
  File "/opt/conda/envs/gdf/lib/python3.9/site-packages/distributed/utils.py", line 752, in wrapper
    return await func(*args, **kwargs)
  File "/opt/conda/envs/gdf/lib/python3.9/site-packages/distributed/comm/ucx.py", line 397, in read
    raise CommClosedError(
distributed.comm.core.CommClosedError: Connection closed by writer.
Inner exception: UCXError("<[Recv #007] ep: 0x7f53b0a35240, tag: 0x66fe79b4706c461f, nbytes: 100000000, type: <class 'rmm._lib.device_buffer.DeviceBuffer'>>: Endpoint timeout")
2023-05-24 05:45:45,362 - distributed.preloading - INFO - Creating preload: dask_cuda.initialize
2023-05-24 05:45:45,362 - distributed.preloading - INFO - Import preload module: dask_cuda.initialize
2023-05-24 05:45:45,392 - distributed.preloading - INFO - Creating preload: dask_cuda.initialize
2023-05-24 05:45:45,392 - distributed.preloading - INFO - Import preload module: dask_cuda.initialize
2023-05-24 05:45:45,429 - distributed.preloading - INFO - Creating preload: dask_cuda.initialize
2023-05-24 05:45:45,430 - distributed.preloading - INFO - Import preload module: dask_cuda.initialize
2023-05-24 05:45:45,609 - distributed.preloading - INFO - Creating preload: dask_cuda.initialize
2023-05-24 05:45:45,609 - distributed.preloading - INFO - Import preload module: dask_cuda.initialize
/opt/conda/envs/gdf/lib/python3.9/multiprocessing/resource_tracker.py:216: UserWarning: resource_tracker: There appear to be 48 leaked semaphore objects to clean up at shutdown
  warnings.warn('resource_tracker: There appear to be %d '
