[dgx13:71451:0:71451] Caught signal 11 (Segmentation fault: address not mapped to object at address 0x448)
==== backtrace (tid:  71451) ====
 0  /opt/conda/envs/gdf/lib/libucs.so.0(ucs_handle_error+0x2fd) [0x7fb0e426d06d]
 1  /opt/conda/envs/gdf/lib/libucs.so.0(+0x2a264) [0x7fb0e426d264]
 2  /opt/conda/envs/gdf/lib/libucs.so.0(+0x2a42a) [0x7fb0e426d42a]
 3  /usr/lib/x86_64-linux-gnu/libpthread.so.0(+0x14420) [0x7fb1853e3420]
 4  /opt/conda/envs/gdf/lib/libucp.so.0(ucp_mem_type_unpack+0x14) [0x7fb0e42eb6a4]
 5  /opt/conda/envs/gdf/lib/libucp.so.0(ucp_rndv_data_handler+0x4e9) [0x7fb0e4314829]
 6  /opt/conda/envs/gdf/lib/./libuct.so.0(+0x2146f) [0x7fb0e422746f]
 7  /opt/conda/envs/gdf/lib/./libuct.so.0(+0x248c8) [0x7fb0e422a8c8]
 8  /opt/conda/envs/gdf/lib/libucs.so.0(ucs_event_set_wait+0xb9) [0x7fb0e4276499]
 9  /opt/conda/envs/gdf/lib/./libuct.so.0(uct_tcp_iface_progress+0x7d) [0x7fb0e422966d]
10  /opt/conda/envs/gdf/lib/libucp.so.0(ucp_worker_progress+0x5a) [0x7fb0e42e88ca]
11  /opt/conda/envs/gdf/lib/python3.9/site-packages/ucp/_libs/ucx_api.cpython-39-x86_64-linux-gnu.so(+0x3206a) [0x7fb0e43a106a]
12  /opt/conda/envs/gdf/bin/python(_PyEval_EvalFrameDefault+0x37cb) [0x5567b99626fb]
13  /opt/conda/envs/gdf/bin/python(+0x12f094) [0x5567b995e094]
14  /opt/conda/envs/gdf/bin/python(_PyFunction_Vectorcall+0xd9) [0x5567b996f519]
15  /opt/conda/envs/gdf/bin/python(_PyEval_EvalFrameDefault+0x696) [0x5567b995f5c6]
16  /opt/conda/envs/gdf/bin/python(+0x1407c2) [0x5567b996f7c2]
17  /opt/conda/envs/gdf/bin/python(+0x14de83) [0x5567b997ce83]
18  /opt/conda/envs/gdf/bin/python(+0x258b2c) [0x5567b9a87b2c]
19  /opt/conda/envs/gdf/bin/python(+0xead05) [0x5567b9919d05]
20  /opt/conda/envs/gdf/bin/python(+0x1377f3) [0x5567b99667f3]
21  /opt/conda/envs/gdf/bin/python(_PyEval_EvalFrameDefault+0x59f9) [0x5567b9964929]
22  /opt/conda/envs/gdf/bin/python(+0x1407c2) [0x5567b996f7c2]
23  /opt/conda/envs/gdf/bin/python(_PyEval_EvalFrameDefault+0x696) [0x5567b995f5c6]
24  /opt/conda/envs/gdf/bin/python(+0x1407c2) [0x5567b996f7c2]
25  /opt/conda/envs/gdf/bin/python(_PyEval_EvalFrameDefault+0x696) [0x5567b995f5c6]
26  /opt/conda/envs/gdf/bin/python(+0x1407c2) [0x5567b996f7c2]
27  /opt/conda/envs/gdf/bin/python(_PyEval_EvalFrameDefault+0x696) [0x5567b995f5c6]
28  /opt/conda/envs/gdf/bin/python(+0x1407c2) [0x5567b996f7c2]
29  /opt/conda/envs/gdf/bin/python(_PyEval_EvalFrameDefault+0x696) [0x5567b995f5c6]
30  /opt/conda/envs/gdf/bin/python(+0x12f094) [0x5567b995e094]
31  /opt/conda/envs/gdf/bin/python(_PyFunction_Vectorcall+0xd9) [0x5567b996f519]
32  /opt/conda/envs/gdf/bin/python(_PyEval_EvalFrameDefault+0x11f8) [0x5567b9960128]
33  /opt/conda/envs/gdf/bin/python(+0x12f094) [0x5567b995e094]
34  /opt/conda/envs/gdf/bin/python(+0x14dccb) [0x5567b997cccb]
35  /opt/conda/envs/gdf/bin/python(PyObject_Call+0xbc) [0x5567b997d44c]
36  /opt/conda/envs/gdf/bin/python(+0x21110e) [0x5567b9a4010e]
37  /opt/conda/envs/gdf/bin/python(_PyObject_MakeTpCall+0x2ec) [0x5567b996777c]
38  /opt/conda/envs/gdf/bin/python(_PyEval_EvalFrameDefault+0x37cb) [0x5567b99626fb]
39  /opt/conda/envs/gdf/bin/python(+0x1407c2) [0x5567b996f7c2]
40  /opt/conda/envs/gdf/bin/python(+0x14ddac) [0x5567b997cdac]
41  /opt/conda/envs/gdf/bin/python(_PyEval_EvalFrameDefault+0x37cb) [0x5567b99626fb]
42  /opt/conda/envs/gdf/bin/python(+0x1407c2) [0x5567b996f7c2]
43  /opt/conda/envs/gdf/bin/python(_PyEval_EvalFrameDefault+0x696) [0x5567b995f5c6]
44  /opt/conda/envs/gdf/bin/python(+0x12f094) [0x5567b995e094]
45  /opt/conda/envs/gdf/bin/python(_PyFunction_Vectorcall+0xd9) [0x5567b996f519]
46  /opt/conda/envs/gdf/bin/python(_PyEval_EvalFrameDefault+0x696) [0x5567b995f5c6]
47  /opt/conda/envs/gdf/bin/python(+0x1407c2) [0x5567b996f7c2]
48  /opt/conda/envs/gdf/bin/python(_PyEval_EvalFrameDefault+0x3e2) [0x5567b995f312]
49  /opt/conda/envs/gdf/bin/python(+0x12f094) [0x5567b995e094]
50  /opt/conda/envs/gdf/bin/python(_PyFunction_Vectorcall+0xd9) [0x5567b996f519]
51  /opt/conda/envs/gdf/bin/python(_PyEval_EvalFrameDefault+0x11f8) [0x5567b9960128]
52  /opt/conda/envs/gdf/bin/python(+0x12f094) [0x5567b995e094]
53  /opt/conda/envs/gdf/bin/python(_PyEval_EvalCodeWithName+0x48) [0x5567b995dd68]
54  /opt/conda/envs/gdf/bin/python(PyEval_EvalCodeEx+0x39) [0x5567b995dd19]
55  /opt/conda/envs/gdf/bin/python(PyEval_EvalCode+0x1b) [0x5567b9a0b07b]
56  /opt/conda/envs/gdf/bin/python(+0x208fca) [0x5567b9a37fca]
57  /opt/conda/envs/gdf/bin/python(+0x205353) [0x5567b9a34353]
58  /opt/conda/envs/gdf/bin/python(PyRun_StringFlags+0x9a) [0x5567b9a2c16a]
59  /opt/conda/envs/gdf/bin/python(PyRun_SimpleStringFlags+0x3c) [0x5567b9a2c05c]
60  /opt/conda/envs/gdf/bin/python(Py_RunMain+0x267) [0x5567b9a2b297]
61  /opt/conda/envs/gdf/bin/python(Py_BytesMain+0x37) [0x5567b99fef07]
=================================
[dgx13:71448:0:71448] Caught signal 11 (Segmentation fault: address not mapped to object at address 0x448)
==== backtrace (tid:  71448) ====
 0  /opt/conda/envs/gdf/lib/libucs.so.0(ucs_handle_error+0x2fd) [0x7f14a8b7c06d]
 1  /opt/conda/envs/gdf/lib/libucs.so.0(+0x2a264) [0x7f14a8b7c264]
 2  /opt/conda/envs/gdf/lib/libucs.so.0(+0x2a42a) [0x7f14a8b7c42a]
 3  /usr/lib/x86_64-linux-gnu/libpthread.so.0(+0x14420) [0x7f153bcf1420]
 4  /opt/conda/envs/gdf/lib/libucp.so.0(ucp_mem_type_unpack+0x14) [0x7f14a8bfa6a4]
 5  /opt/conda/envs/gdf/lib/libucp.so.0(ucp_rndv_data_handler+0x4e9) [0x7f14a8c23829]
 6  /opt/conda/envs/gdf/lib/./libuct.so.0(+0x2146f) [0x7f14a8b3646f]
 7  /opt/conda/envs/gdf/lib/./libuct.so.0(+0x248c8) [0x7f14a8b398c8]
 8  /opt/conda/envs/gdf/lib/libucs.so.0(ucs_event_set_wait+0xb9) [0x7f14a8b85499]
 9  /opt/conda/envs/gdf/lib/./libuct.so.0(uct_tcp_iface_progress+0x7d) [0x7f14a8b3866d]
10  /opt/conda/envs/gdf/lib/libucp.so.0(ucp_worker_progress+0x5a) [0x7f14a8bf78ca]
11  /opt/conda/envs/gdf/lib/python3.9/site-packages/ucp/_libs/ucx_api.cpython-39-x86_64-linux-gnu.so(+0x3206a) [0x7f14a8cb006a]
12  /opt/conda/envs/gdf/bin/python(_PyEval_EvalFrameDefault+0x37cb) [0x5643cd4eb6fb]
13  /opt/conda/envs/gdf/bin/python(+0x12f094) [0x5643cd4e7094]
14  /opt/conda/envs/gdf/bin/python(_PyFunction_Vectorcall+0xd9) [0x5643cd4f8519]
15  /opt/conda/envs/gdf/bin/python(_PyEval_EvalFrameDefault+0x696) [0x5643cd4e85c6]
16  /opt/conda/envs/gdf/bin/python(+0x1407c2) [0x5643cd4f87c2]
17  /opt/conda/envs/gdf/bin/python(+0x14de83) [0x5643cd505e83]
18  /opt/conda/envs/gdf/bin/python(+0x258b2c) [0x5643cd610b2c]
19  /opt/conda/envs/gdf/bin/python(+0xead05) [0x5643cd4a2d05]
20  /opt/conda/envs/gdf/bin/python(+0x1377f3) [0x5643cd4ef7f3]
21  /opt/conda/envs/gdf/bin/python(_PyEval_EvalFrameDefault+0x59f9) [0x5643cd4ed929]
22  /opt/conda/envs/gdf/bin/python(+0x1407c2) [0x5643cd4f87c2]
23  /opt/conda/envs/gdf/bin/python(_PyEval_EvalFrameDefault+0x696) [0x5643cd4e85c6]
24  /opt/conda/envs/gdf/bin/python(+0x1407c2) [0x5643cd4f87c2]
25  /opt/conda/envs/gdf/bin/python(_PyEval_EvalFrameDefault+0x696) [0x5643cd4e85c6]
26  /opt/conda/envs/gdf/bin/python(+0x1407c2) [0x5643cd4f87c2]
27  /opt/conda/envs/gdf/bin/python(_PyEval_EvalFrameDefault+0x696) [0x5643cd4e85c6]
28  /opt/conda/envs/gdf/bin/python(+0x1407c2) [0x5643cd4f87c2]
29  /opt/conda/envs/gdf/bin/python(_PyEval_EvalFrameDefault+0x696) [0x5643cd4e85c6]
30  /opt/conda/envs/gdf/bin/python(+0x12f094) [0x5643cd4e7094]
31  /opt/conda/envs/gdf/bin/python(_PyFunction_Vectorcall+0xd9) [0x5643cd4f8519]
32  /opt/conda/envs/gdf/bin/python(_PyEval_EvalFrameDefault+0x11f8) [0x5643cd4e9128]
33  /opt/conda/envs/gdf/bin/python(+0x12f094) [0x5643cd4e7094]
34  /opt/conda/envs/gdf/bin/python(+0x14dccb) [0x5643cd505ccb]
35  /opt/conda/envs/gdf/bin/python(PyObject_Call+0xbc) [0x5643cd50644c]
36  /opt/conda/envs/gdf/bin/python(+0x21110e) [0x5643cd5c910e]
37  /opt/conda/envs/gdf/bin/python(_PyObject_MakeTpCall+0x2ec) [0x5643cd4f077c]
38  /opt/conda/envs/gdf/bin/python(_PyEval_EvalFrameDefault+0x37cb) [0x5643cd4eb6fb]
39  /opt/conda/envs/gdf/bin/python(+0x1407c2) [0x5643cd4f87c2]
40  /opt/conda/envs/gdf/bin/python(+0x14ddac) [0x5643cd505dac]
41  /opt/conda/envs/gdf/bin/python(_PyEval_EvalFrameDefault+0x37cb) [0x5643cd4eb6fb]
42  /opt/conda/envs/gdf/bin/python(+0x1407c2) [0x5643cd4f87c2]
43  /opt/conda/envs/gdf/bin/python(_PyEval_EvalFrameDefault+0x696) [0x5643cd4e85c6]
44  /opt/conda/envs/gdf/bin/python(+0x12f094) [0x5643cd4e7094]
45  /opt/conda/envs/gdf/bin/python(_PyFunction_Vectorcall+0xd9) [0x5643cd4f8519]
46  /opt/conda/envs/gdf/bin/python(_PyEval_EvalFrameDefault+0x696) [0x5643cd4e85c6]
47  /opt/conda/envs/gdf/bin/python(+0x1407c2) [0x5643cd4f87c2]
48  /opt/conda/envs/gdf/bin/python(_PyEval_EvalFrameDefault+0x3e2) [0x5643cd4e8312]
49  /opt/conda/envs/gdf/bin/python(+0x12f094) [0x5643cd4e7094]
50  /opt/conda/envs/gdf/bin/python(_PyFunction_Vectorcall+0xd9) [0x5643cd4f8519]
51  /opt/conda/envs/gdf/bin/python(_PyEval_EvalFrameDefault+0x11f8) [0x5643cd4e9128]
52  /opt/conda/envs/gdf/bin/python(+0x12f094) [0x5643cd4e7094]
53  /opt/conda/envs/gdf/bin/python(_PyEval_EvalCodeWithName+0x48) [0x5643cd4e6d68]
54  /opt/conda/envs/gdf/bin/python(PyEval_EvalCodeEx+0x39) [0x5643cd4e6d19]
55  /opt/conda/envs/gdf/bin/python(PyEval_EvalCode+0x1b) [0x5643cd59407b]
56  /opt/conda/envs/gdf/bin/python(+0x208fca) [0x5643cd5c0fca]
57  /opt/conda/envs/gdf/bin/python(+0x205353) [0x5643cd5bd353]
58  /opt/conda/envs/gdf/bin/python(PyRun_StringFlags+0x9a) [0x5643cd5b516a]
59  /opt/conda/envs/gdf/bin/python(PyRun_SimpleStringFlags+0x3c) [0x5643cd5b505c]
60  /opt/conda/envs/gdf/bin/python(Py_RunMain+0x267) [0x5643cd5b4297]
61  /opt/conda/envs/gdf/bin/python(Py_BytesMain+0x37) [0x5643cd587f07]
=================================
[dgx13:71460:0:71460] Caught signal 11 (Segmentation fault: address not mapped to object at address 0x448)
==== backtrace (tid:  71460) ====
 0  /opt/conda/envs/gdf/lib/libucs.so.0(ucs_handle_error+0x2fd) [0x7fef647ee06d]
 1  /opt/conda/envs/gdf/lib/libucs.so.0(+0x2a264) [0x7fef647ee264]
 2  /opt/conda/envs/gdf/lib/libucs.so.0(+0x2a42a) [0x7fef647ee42a]
 3  /usr/lib/x86_64-linux-gnu/libpthread.so.0(+0x14420) [0x7ff0057f0420]
 4  /opt/conda/envs/gdf/lib/libucp.so.0(ucp_mem_type_unpack+0x14) [0x7fef6486c6a4]
 5  /opt/conda/envs/gdf/lib/libucp.so.0(ucp_rndv_data_handler+0x4e9) [0x7fef64895829]
 6  /opt/conda/envs/gdf/lib/./libuct.so.0(+0x2146f) [0x7fef647a846f]
 7  /opt/conda/envs/gdf/lib/./libuct.so.0(+0x248c8) [0x7fef647ab8c8]
 8  /opt/conda/envs/gdf/lib/libucs.so.0(ucs_event_set_wait+0xb9) [0x7fef647f7499]
 9  /opt/conda/envs/gdf/lib/./libuct.so.0(uct_tcp_iface_progress+0x7d) [0x7fef647aa66d]
10  /opt/conda/envs/gdf/lib/libucp.so.0(ucp_worker_progress+0x5a) [0x7fef648698ca]
11  /opt/conda/envs/gdf/lib/python3.9/site-packages/ucp/_libs/ucx_api.cpython-39-x86_64-linux-gnu.so(+0x3206a) [0x7fef6492206a]
12  /opt/conda/envs/gdf/bin/python(_PyEval_EvalFrameDefault+0x37cb) [0x55a5b3d9f6fb]
13  /opt/conda/envs/gdf/bin/python(+0x12f094) [0x55a5b3d9b094]
14  /opt/conda/envs/gdf/bin/python(_PyFunction_Vectorcall+0xd9) [0x55a5b3dac519]
15  /opt/conda/envs/gdf/bin/python(_PyEval_EvalFrameDefault+0x696) [0x55a5b3d9c5c6]
16  /opt/conda/envs/gdf/bin/python(+0x1e3162) [0x55a5b3e4f162]
17  /opt/conda/envs/gdf/lib/python3.9/lib-dynload/_asyncio.cpython-39-x86_64-linux-gnu.so(+0x81e9) [0x7feff83a81e9]
18  /opt/conda/envs/gdf/bin/python(_PyObject_MakeTpCall+0x2ec) [0x55a5b3da477c]
19  /opt/conda/envs/gdf/bin/python(+0xead05) [0x55a5b3d56d05]
20  /opt/conda/envs/gdf/bin/python(+0x1377f3) [0x55a5b3da37f3]
21  /opt/conda/envs/gdf/bin/python(_PyEval_EvalFrameDefault+0x59f9) [0x55a5b3da1929]
22  /opt/conda/envs/gdf/bin/python(+0x1407c2) [0x55a5b3dac7c2]
23  /opt/conda/envs/gdf/bin/python(_PyEval_EvalFrameDefault+0x696) [0x55a5b3d9c5c6]
24  /opt/conda/envs/gdf/bin/python(+0x1407c2) [0x55a5b3dac7c2]
25  /opt/conda/envs/gdf/bin/python(_PyEval_EvalFrameDefault+0x696) [0x55a5b3d9c5c6]
26  /opt/conda/envs/gdf/bin/python(+0x1407c2) [0x55a5b3dac7c2]
27  /opt/conda/envs/gdf/bin/python(_PyEval_EvalFrameDefault+0x696) [0x55a5b3d9c5c6]
28  /opt/conda/envs/gdf/bin/python(+0x1407c2) [0x55a5b3dac7c2]
29  /opt/conda/envs/gdf/bin/python(_PyEval_EvalFrameDefault+0x696) [0x55a5b3d9c5c6]
30  /opt/conda/envs/gdf/bin/python(+0x12f094) [0x55a5b3d9b094]
31  /opt/conda/envs/gdf/bin/python(_PyFunction_Vectorcall+0xd9) [0x55a5b3dac519]
32  /opt/conda/envs/gdf/bin/python(_PyEval_EvalFrameDefault+0x11f8) [0x55a5b3d9d128]
33  /opt/conda/envs/gdf/bin/python(+0x12f094) [0x55a5b3d9b094]
34  /opt/conda/envs/gdf/bin/python(+0x14dccb) [0x55a5b3db9ccb]
35  /opt/conda/envs/gdf/bin/python(PyObject_Call+0xbc) [0x55a5b3dba44c]
36  /opt/conda/envs/gdf/bin/python(+0x21110e) [0x55a5b3e7d10e]
37  /opt/conda/envs/gdf/bin/python(_PyObject_MakeTpCall+0x2ec) [0x55a5b3da477c]
38  /opt/conda/envs/gdf/bin/python(_PyEval_EvalFrameDefault+0x37cb) [0x55a5b3d9f6fb]
39  /opt/conda/envs/gdf/bin/python(+0x1407c2) [0x55a5b3dac7c2]
40  /opt/conda/envs/gdf/bin/python(+0x14ddac) [0x55a5b3db9dac]
41  /opt/conda/envs/gdf/bin/python(_PyEval_EvalFrameDefault+0x37cb) [0x55a5b3d9f6fb]
42  /opt/conda/envs/gdf/bin/python(+0x1407c2) [0x55a5b3dac7c2]
43  /opt/conda/envs/gdf/bin/python(_PyEval_EvalFrameDefault+0x696) [0x55a5b3d9c5c6]
44  /opt/conda/envs/gdf/bin/python(+0x12f094) [0x55a5b3d9b094]
45  /opt/conda/envs/gdf/bin/python(_PyFunction_Vectorcall+0xd9) [0x55a5b3dac519]
46  /opt/conda/envs/gdf/bin/python(_PyEval_EvalFrameDefault+0x696) [0x55a5b3d9c5c6]
47  /opt/conda/envs/gdf/bin/python(+0x1407c2) [0x55a5b3dac7c2]
48  /opt/conda/envs/gdf/bin/python(_PyEval_EvalFrameDefault+0x3e2) [0x55a5b3d9c312]
49  /opt/conda/envs/gdf/bin/python(+0x12f094) [0x55a5b3d9b094]
50  /opt/conda/envs/gdf/bin/python(_PyFunction_Vectorcall+0xd9) [0x55a5b3dac519]
51  /opt/conda/envs/gdf/bin/python(_PyEval_EvalFrameDefault+0x11f8) [0x55a5b3d9d128]
52  /opt/conda/envs/gdf/bin/python(+0x12f094) [0x55a5b3d9b094]
53  /opt/conda/envs/gdf/bin/python(_PyEval_EvalCodeWithName+0x48) [0x55a5b3d9ad68]
54  /opt/conda/envs/gdf/bin/python(PyEval_EvalCodeEx+0x39) [0x55a5b3d9ad19]
55  /opt/conda/envs/gdf/bin/python(PyEval_EvalCode+0x1b) [0x55a5b3e4807b]
56  /opt/conda/envs/gdf/bin/python(+0x208fca) [0x55a5b3e74fca]
57  /opt/conda/envs/gdf/bin/python(+0x205353) [0x55a5b3e71353]
58  /opt/conda/envs/gdf/bin/python(PyRun_StringFlags+0x9a) [0x55a5b3e6916a]
59  /opt/conda/envs/gdf/bin/python(PyRun_SimpleStringFlags+0x3c) [0x55a5b3e6905c]
60  /opt/conda/envs/gdf/bin/python(Py_RunMain+0x267) [0x55a5b3e68297]
61  /opt/conda/envs/gdf/bin/python(Py_BytesMain+0x37) [0x55a5b3e3bf07]
=================================
2023-10-31 06:29:17,843 - distributed.worker - ERROR - Worker stream died during communication: ucx://127.0.0.1:57687
Traceback (most recent call last):
  File "/opt/conda/envs/gdf/lib/python3.9/site-packages/distributed/comm/ucx.py", line 354, in read
    await self.ep.recv(msg)
  File "/opt/conda/envs/gdf/lib/python3.9/site-packages/ucp/core.py", line 725, in recv
    ret = await comm.tag_recv(self._ep, buffer, nbytes, tag, name=log)
ucp._libs.exceptions.UCXCanceled: <[Recv #003] ep: 0x7f6ddc01b1c0, tag: 0x3b24614e9d049a2, nbytes: 16, type: <class 'numpy.ndarray'>>: 

During handling of the above exception, another exception occurred:

Traceback (most recent call last):
  File "/opt/conda/envs/gdf/lib/python3.9/site-packages/distributed/worker.py", line 2059, in gather_dep
    response = await get_data_from_worker(
  File "/opt/conda/envs/gdf/lib/python3.9/site-packages/distributed/worker.py", line 2852, in get_data_from_worker
    response = await send_recv(
  File "/opt/conda/envs/gdf/lib/python3.9/site-packages/distributed/core.py", line 1106, in send_recv
    response = await comm.read(deserializers=deserializers)
  File "/opt/conda/envs/gdf/lib/python3.9/site-packages/distributed/utils.py", line 803, in wrapper
    return await func(*args, **kwargs)
  File "/opt/conda/envs/gdf/lib/python3.9/site-packages/distributed/comm/ucx.py", line 372, in read
    raise CommClosedError(
distributed.comm.core.CommClosedError: Connection closed by writer.
Inner exception: UCXCanceled("<[Recv #003] ep: 0x7f6ddc01b1c0, tag: 0x3b24614e9d049a2, nbytes: 16, type: <class 'numpy.ndarray'>>: ")
2023-10-31 06:29:17,843 - distributed.worker - ERROR - failed during get data with ucx://127.0.0.1:51215 -> ucx://127.0.0.1:57687
Traceback (most recent call last):
  File "/opt/conda/envs/gdf/lib/python3.9/site-packages/distributed/comm/ucx.py", line 338, in write
    await self.ep.send(each_frame)
  File "/opt/conda/envs/gdf/lib/python3.9/site-packages/ucp/core.py", line 650, in send
    return await comm.tag_send(self._ep, buffer, nbytes, tag, name=log)
ucp._libs.exceptions.UCXError: <[Send #007] ep: 0x7fe598ef2240, tag: 0x7e600b35d869fe4f, nbytes: 50000000, type: <class 'cupy.ndarray'>>: Connection reset by remote peer

During handling of the above exception, another exception occurred:

Traceback (most recent call last):
  File "/opt/conda/envs/gdf/lib/python3.9/site-packages/distributed/worker.py", line 1782, in get_data
    compressed = await comm.write(msg, serializers=serializers)
  File "/opt/conda/envs/gdf/lib/python3.9/site-packages/distributed/utils.py", line 803, in wrapper
    return await func(*args, **kwargs)
  File "/opt/conda/envs/gdf/lib/python3.9/site-packages/distributed/comm/ucx.py", line 342, in write
    raise CommClosedError("While writing, the connection was closed")
distributed.comm.core.CommClosedError: While writing, the connection was closed
2023-10-31 06:29:17,845 - distributed.worker - ERROR - Worker stream died during communication: ucx://127.0.0.1:57687
Traceback (most recent call last):
  File "/opt/conda/envs/gdf/lib/python3.9/site-packages/distributed/comm/ucx.py", line 354, in read
    await self.ep.recv(msg)
  File "/opt/conda/envs/gdf/lib/python3.9/site-packages/ucp/core.py", line 725, in recv
    ret = await comm.tag_recv(self._ep, buffer, nbytes, tag, name=log)
ucp._libs.exceptions.UCXCanceled: <[Recv #003] ep: 0x7fe598ef2140, tag: 0xfadade41ea3d3cf, nbytes: 16, type: <class 'numpy.ndarray'>>: 

During handling of the above exception, another exception occurred:

Traceback (most recent call last):
  File "/opt/conda/envs/gdf/lib/python3.9/site-packages/distributed/worker.py", line 2059, in gather_dep
    response = await get_data_from_worker(
  File "/opt/conda/envs/gdf/lib/python3.9/site-packages/distributed/worker.py", line 2852, in get_data_from_worker
    response = await send_recv(
  File "/opt/conda/envs/gdf/lib/python3.9/site-packages/distributed/core.py", line 1106, in send_recv
    response = await comm.read(deserializers=deserializers)
  File "/opt/conda/envs/gdf/lib/python3.9/site-packages/distributed/utils.py", line 803, in wrapper
    return await func(*args, **kwargs)
  File "/opt/conda/envs/gdf/lib/python3.9/site-packages/distributed/comm/ucx.py", line 372, in read
    raise CommClosedError(
distributed.comm.core.CommClosedError: Connection closed by writer.
Inner exception: UCXCanceled("<[Recv #003] ep: 0x7fe598ef2140, tag: 0xfadade41ea3d3cf, nbytes: 16, type: <class 'numpy.ndarray'>>: ")
2023-10-31 06:29:17,907 - distributed.worker - ERROR - Worker stream died during communication: ucx://127.0.0.1:36841
Traceback (most recent call last):
  File "/opt/conda/envs/gdf/lib/python3.9/site-packages/distributed/comm/ucx.py", line 396, in read
    await self.ep.recv(each_frame)
  File "/opt/conda/envs/gdf/lib/python3.9/site-packages/ucp/core.py", line 725, in recv
    ret = await comm.tag_recv(self._ep, buffer, nbytes, tag, name=log)
ucp._libs.exceptions.UCXError: <[Recv #007] ep: 0x7f6ddc01b180, tag: 0x9f8279c74ae7054f, nbytes: 50000000, type: <class 'rmm._lib.device_buffer.DeviceBuffer'>>: Connection reset by remote peer

During handling of the above exception, another exception occurred:

Traceback (most recent call last):
  File "/opt/conda/envs/gdf/lib/python3.9/site-packages/distributed/worker.py", line 2059, in gather_dep
    response = await get_data_from_worker(
  File "/opt/conda/envs/gdf/lib/python3.9/site-packages/distributed/worker.py", line 2852, in get_data_from_worker
    response = await send_recv(
  File "/opt/conda/envs/gdf/lib/python3.9/site-packages/distributed/core.py", line 1106, in send_recv
    response = await comm.read(deserializers=deserializers)
  File "/opt/conda/envs/gdf/lib/python3.9/site-packages/distributed/utils.py", line 803, in wrapper
    return await func(*args, **kwargs)
  File "/opt/conda/envs/gdf/lib/python3.9/site-packages/distributed/comm/ucx.py", line 402, in read
    raise CommClosedError(
distributed.comm.core.CommClosedError: Connection closed by writer.
Inner exception: UCXError("<[Recv #007] ep: 0x7f6ddc01b180, tag: 0x9f8279c74ae7054f, nbytes: 50000000, type: <class 'rmm._lib.device_buffer.DeviceBuffer'>>: Connection reset by remote peer")
2023-10-31 06:29:17,912 - distributed.worker - ERROR - Worker stream died during communication: ucx://127.0.0.1:36841
Traceback (most recent call last):
  File "/opt/conda/envs/gdf/lib/python3.9/site-packages/distributed/comm/ucx.py", line 471, in connect
    ep = await ucp.create_endpoint(ip, port)
  File "/opt/conda/envs/gdf/lib/python3.9/site-packages/ucp/core.py", line 1004, in create_endpoint
    return await _get_ctx().create_endpoint(
  File "/opt/conda/envs/gdf/lib/python3.9/site-packages/ucp/core.py", line 316, in create_endpoint
    peer_info = await exchange_peer_info(
  File "/opt/conda/envs/gdf/lib/python3.9/site-packages/ucp/core.py", line 54, in exchange_peer_info
    await comm.stream_recv(endpoint, peer_info_arr, peer_info_arr.nbytes)
ucp._libs.exceptions.UCXError: <stream_recv>: Connection reset by remote peer

During handling of the above exception, another exception occurred:

Traceback (most recent call last):
  File "/opt/conda/envs/gdf/lib/python3.9/site-packages/distributed/comm/core.py", line 342, in connect
    comm = await wait_for(
  File "/opt/conda/envs/gdf/lib/python3.9/site-packages/distributed/utils.py", line 1920, in wait_for
    return await asyncio.wait_for(fut, timeout)
  File "/opt/conda/envs/gdf/lib/python3.9/asyncio/tasks.py", line 479, in wait_for
    return fut.result()
  File "/opt/conda/envs/gdf/lib/python3.9/site-packages/distributed/comm/ucx.py", line 473, in connect
    raise CommClosedError("Connection closed before handshake completed")
distributed.comm.core.CommClosedError: Connection closed before handshake completed

During handling of the above exception, another exception occurred:

Traceback (most recent call last):
  File "/opt/conda/envs/gdf/lib/python3.9/site-packages/distributed/core.py", line 1516, in _connect
    comm = await connect(
  File "/opt/conda/envs/gdf/lib/python3.9/site-packages/distributed/comm/core.py", line 366, in connect
    await asyncio.sleep(backoff)
  File "/opt/conda/envs/gdf/lib/python3.9/asyncio/tasks.py", line 652, in sleep
    return await future
asyncio.exceptions.CancelledError

During handling of the above exception, another exception occurred:

Traceback (most recent call last):
  File "/opt/conda/envs/gdf/lib/python3.9/site-packages/distributed/core.py", line 1626, in connect
    return connect_attempt.result()
asyncio.exceptions.CancelledError

During handling of the above exception, another exception occurred:

Traceback (most recent call last):
  File "/opt/conda/envs/gdf/lib/python3.9/site-packages/distributed/worker.py", line 2059, in gather_dep
    response = await get_data_from_worker(
  File "/opt/conda/envs/gdf/lib/python3.9/site-packages/distributed/worker.py", line 2849, in get_data_from_worker
    comm = await rpc.connect(worker)
  File "/opt/conda/envs/gdf/lib/python3.9/site-packages/distributed/core.py", line 1628, in connect
    raise CommClosedError(reason)
distributed.comm.core.CommClosedError: Address removed.
2023-10-31 06:29:17,940 - distributed.worker - ERROR - Worker stream died during communication: ucx://127.0.0.1:40945
Traceback (most recent call last):
  File "/opt/conda/envs/gdf/lib/python3.9/site-packages/distributed/comm/ucx.py", line 396, in read
    await self.ep.recv(each_frame)
  File "/opt/conda/envs/gdf/lib/python3.9/site-packages/ucp/core.py", line 725, in recv
    ret = await comm.tag_recv(self._ep, buffer, nbytes, tag, name=log)
ucp._libs.exceptions.UCXError: <[Recv #007] ep: 0x7f36628ba140, tag: 0x3ca3a061dbcfd1f0, nbytes: 50000000, type: <class 'rmm._lib.device_buffer.DeviceBuffer'>>: Connection reset by remote peer

During handling of the above exception, another exception occurred:

Traceback (most recent call last):
  File "/opt/conda/envs/gdf/lib/python3.9/site-packages/distributed/worker.py", line 2059, in gather_dep
    response = await get_data_from_worker(
  File "/opt/conda/envs/gdf/lib/python3.9/site-packages/distributed/worker.py", line 2852, in get_data_from_worker
    response = await send_recv(
  File "/opt/conda/envs/gdf/lib/python3.9/site-packages/distributed/core.py", line 1106, in send_recv
    response = await comm.read(deserializers=deserializers)
  File "/opt/conda/envs/gdf/lib/python3.9/site-packages/distributed/utils.py", line 803, in wrapper
    return await func(*args, **kwargs)
  File "/opt/conda/envs/gdf/lib/python3.9/site-packages/distributed/comm/ucx.py", line 402, in read
    raise CommClosedError(
distributed.comm.core.CommClosedError: Connection closed by writer.
Inner exception: UCXError("<[Recv #007] ep: 0x7f36628ba140, tag: 0x3ca3a061dbcfd1f0, nbytes: 50000000, type: <class 'rmm._lib.device_buffer.DeviceBuffer'>>: Connection reset by remote peer")
2023-10-31 06:29:17,940 - distributed.worker - ERROR - failed during get data with ucx://127.0.0.1:47235 -> ucx://127.0.0.1:40945
Traceback (most recent call last):
  File "/opt/conda/envs/gdf/lib/python3.9/site-packages/distributed/comm/ucx.py", line 354, in read
    await self.ep.recv(msg)
  File "/opt/conda/envs/gdf/lib/python3.9/site-packages/ucp/core.py", line 725, in recv
    ret = await comm.tag_recv(self._ep, buffer, nbytes, tag, name=log)
ucp._libs.exceptions.UCXCanceled: <[Recv #006] ep: 0x7fdf912be200, tag: 0xb6cec84fc10fd8e6, nbytes: 16, type: <class 'numpy.ndarray'>>: 

During handling of the above exception, another exception occurred:

Traceback (most recent call last):
  File "/opt/conda/envs/gdf/lib/python3.9/site-packages/distributed/worker.py", line 1783, in get_data
    response = await comm.read(deserializers=serializers)
  File "/opt/conda/envs/gdf/lib/python3.9/site-packages/distributed/utils.py", line 803, in wrapper
    return await func(*args, **kwargs)
  File "/opt/conda/envs/gdf/lib/python3.9/site-packages/distributed/comm/ucx.py", line 372, in read
    raise CommClosedError(
distributed.comm.core.CommClosedError: Connection closed by writer.
Inner exception: UCXCanceled("<[Recv #006] ep: 0x7fdf912be200, tag: 0xb6cec84fc10fd8e6, nbytes: 16, type: <class 'numpy.ndarray'>>: ")
2023-10-31 06:29:17,941 - distributed.worker - ERROR - failed during get data with ucx://127.0.0.1:54263 -> ucx://127.0.0.1:40945
Traceback (most recent call last):
  File "/opt/conda/envs/gdf/lib/python3.9/site-packages/distributed/comm/ucx.py", line 338, in write
    await self.ep.send(each_frame)
  File "/opt/conda/envs/gdf/lib/python3.9/site-packages/ucp/core.py", line 650, in send
    return await comm.tag_send(self._ep, buffer, nbytes, tag, name=log)
ucp._libs.exceptions.UCXError: <[Send #007] ep: 0x7f36628ba200, tag: 0xa54d21d22476313c, nbytes: 50000000, type: <class 'cupy.ndarray'>>: Connection reset by remote peer

During handling of the above exception, another exception occurred:

Traceback (most recent call last):
  File "/opt/conda/envs/gdf/lib/python3.9/site-packages/distributed/worker.py", line 1782, in get_data
    compressed = await comm.write(msg, serializers=serializers)
  File "/opt/conda/envs/gdf/lib/python3.9/site-packages/distributed/utils.py", line 803, in wrapper
    return await func(*args, **kwargs)
  File "/opt/conda/envs/gdf/lib/python3.9/site-packages/distributed/comm/ucx.py", line 342, in write
    raise CommClosedError("While writing, the connection was closed")
distributed.comm.core.CommClosedError: While writing, the connection was closed
2023-10-31 06:29:17,941 - distributed.worker - ERROR - Worker stream died during communication: ucx://127.0.0.1:40945
Traceback (most recent call last):
  File "/opt/conda/envs/gdf/lib/python3.9/site-packages/distributed/comm/ucx.py", line 354, in read
    await self.ep.recv(msg)
  File "/opt/conda/envs/gdf/lib/python3.9/site-packages/ucp/core.py", line 725, in recv
    ret = await comm.tag_recv(self._ep, buffer, nbytes, tag, name=log)
ucp._libs.exceptions.UCXCanceled: <[Recv #003] ep: 0x7fe598ef2100, tag: 0x35ecec021ccd1048, nbytes: 16, type: <class 'numpy.ndarray'>>: 

During handling of the above exception, another exception occurred:

Traceback (most recent call last):
  File "/opt/conda/envs/gdf/lib/python3.9/site-packages/distributed/worker.py", line 2059, in gather_dep
    response = await get_data_from_worker(
  File "/opt/conda/envs/gdf/lib/python3.9/site-packages/distributed/worker.py", line 2852, in get_data_from_worker
    response = await send_recv(
  File "/opt/conda/envs/gdf/lib/python3.9/site-packages/distributed/core.py", line 1106, in send_recv
    response = await comm.read(deserializers=deserializers)
  File "/opt/conda/envs/gdf/lib/python3.9/site-packages/distributed/utils.py", line 803, in wrapper
    return await func(*args, **kwargs)
  File "/opt/conda/envs/gdf/lib/python3.9/site-packages/distributed/comm/ucx.py", line 372, in read
    raise CommClosedError(
distributed.comm.core.CommClosedError: Connection closed by writer.
Inner exception: UCXCanceled("<[Recv #003] ep: 0x7fe598ef2100, tag: 0x35ecec021ccd1048, nbytes: 16, type: <class 'numpy.ndarray'>>: ")
2023-10-31 06:29:17,942 - distributed.worker - ERROR - Worker stream died during communication: ucx://127.0.0.1:40945
Traceback (most recent call last):
  File "/opt/conda/envs/gdf/lib/python3.9/site-packages/distributed/comm/ucx.py", line 354, in read
    await self.ep.recv(msg)
  File "/opt/conda/envs/gdf/lib/python3.9/site-packages/ucp/core.py", line 725, in recv
    ret = await comm.tag_recv(self._ep, buffer, nbytes, tag, name=log)
ucp._libs.exceptions.UCXCanceled: <[Recv #003] ep: 0x7fdf912be140, tag: 0xd5cda9deadd19112, nbytes: 16, type: <class 'numpy.ndarray'>>: 

During handling of the above exception, another exception occurred:

Traceback (most recent call last):
  File "/opt/conda/envs/gdf/lib/python3.9/site-packages/distributed/worker.py", line 2059, in gather_dep
    response = await get_data_from_worker(
  File "/opt/conda/envs/gdf/lib/python3.9/site-packages/distributed/worker.py", line 2852, in get_data_from_worker
    response = await send_recv(
  File "/opt/conda/envs/gdf/lib/python3.9/site-packages/distributed/core.py", line 1106, in send_recv
    response = await comm.read(deserializers=deserializers)
  File "/opt/conda/envs/gdf/lib/python3.9/site-packages/distributed/utils.py", line 803, in wrapper
    return await func(*args, **kwargs)
  File "/opt/conda/envs/gdf/lib/python3.9/site-packages/distributed/comm/ucx.py", line 372, in read
    raise CommClosedError(
distributed.comm.core.CommClosedError: Connection closed by writer.
Inner exception: UCXCanceled("<[Recv #003] ep: 0x7fdf912be140, tag: 0xd5cda9deadd19112, nbytes: 16, type: <class 'numpy.ndarray'>>: ")
2023-10-31 06:29:17,947 - distributed.worker - ERROR - Worker stream died during communication: ucx://127.0.0.1:40945
Traceback (most recent call last):
  File "/opt/conda/envs/gdf/lib/python3.9/site-packages/distributed/comm/ucx.py", line 471, in connect
    ep = await ucp.create_endpoint(ip, port)
  File "/opt/conda/envs/gdf/lib/python3.9/site-packages/ucp/core.py", line 1004, in create_endpoint
    return await _get_ctx().create_endpoint(
  File "/opt/conda/envs/gdf/lib/python3.9/site-packages/ucp/core.py", line 316, in create_endpoint
    peer_info = await exchange_peer_info(
  File "/opt/conda/envs/gdf/lib/python3.9/site-packages/ucp/core.py", line 54, in exchange_peer_info
    await comm.stream_recv(endpoint, peer_info_arr, peer_info_arr.nbytes)
ucp._libs.exceptions.UCXNotConnected: <stream_recv>: 

During handling of the above exception, another exception occurred:

Traceback (most recent call last):
  File "/opt/conda/envs/gdf/lib/python3.9/site-packages/distributed/comm/core.py", line 342, in connect
    comm = await wait_for(
  File "/opt/conda/envs/gdf/lib/python3.9/site-packages/distributed/utils.py", line 1920, in wait_for
    return await asyncio.wait_for(fut, timeout)
  File "/opt/conda/envs/gdf/lib/python3.9/asyncio/tasks.py", line 479, in wait_for
    return fut.result()
  File "/opt/conda/envs/gdf/lib/python3.9/site-packages/distributed/comm/ucx.py", line 473, in connect
    raise CommClosedError("Connection closed before handshake completed")
distributed.comm.core.CommClosedError: Connection closed before handshake completed

During handling of the above exception, another exception occurred:

Traceback (most recent call last):
  File "/opt/conda/envs/gdf/lib/python3.9/site-packages/distributed/core.py", line 1516, in _connect
    comm = await connect(
  File "/opt/conda/envs/gdf/lib/python3.9/site-packages/distributed/comm/core.py", line 366, in connect
    await asyncio.sleep(backoff)
  File "/opt/conda/envs/gdf/lib/python3.9/asyncio/tasks.py", line 652, in sleep
    return await future
asyncio.exceptions.CancelledError

During handling of the above exception, another exception occurred:

Traceback (most recent call last):
  File "/opt/conda/envs/gdf/lib/python3.9/site-packages/distributed/core.py", line 1626, in connect
    return connect_attempt.result()
asyncio.exceptions.CancelledError

During handling of the above exception, another exception occurred:

Traceback (most recent call last):
  File "/opt/conda/envs/gdf/lib/python3.9/site-packages/distributed/worker.py", line 2059, in gather_dep
    response = await get_data_from_worker(
  File "/opt/conda/envs/gdf/lib/python3.9/site-packages/distributed/worker.py", line 2849, in get_data_from_worker
    comm = await rpc.connect(worker)
  File "/opt/conda/envs/gdf/lib/python3.9/site-packages/distributed/core.py", line 1628, in connect
    raise CommClosedError(reason)
distributed.comm.core.CommClosedError: Address removed.
2023-10-31 06:29:21,608 - distributed.nanny - WARNING - Restarting worker
2023-10-31 06:29:21,840 - distributed.nanny - WARNING - Restarting worker
2023-10-31 06:29:21,879 - distributed.nanny - WARNING - Restarting worker
[dgx13:71590:0:71590] Caught signal 11 (Segmentation fault: address not mapped to object at address 0x448)
[dgx13:71454:0:71454] Caught signal 11 (Segmentation fault: address not mapped to object at address 0x448)
==== backtrace (tid:  71590) ====
 0  /opt/conda/envs/gdf/lib/libucs.so.0(ucs_handle_error+0x2fd) [0x7f03151a606d]
 1  /opt/conda/envs/gdf/lib/libucs.so.0(+0x2a264) [0x7f03151a6264]
 2  /opt/conda/envs/gdf/lib/libucs.so.0(+0x2a42a) [0x7f03151a642a]
 3  /usr/lib/x86_64-linux-gnu/libpthread.so.0(+0x14420) [0x7f03ba194420]
 4  /opt/conda/envs/gdf/lib/libucp.so.0(ucp_mem_type_unpack+0x14) [0x7f03152246a4]
 5  /opt/conda/envs/gdf/lib/libucp.so.0(ucp_rndv_data_handler+0x4e9) [0x7f031524d829]
 6  /opt/conda/envs/gdf/lib/./libuct.so.0(+0x2146f) [0x7f031516046f]
 7  /opt/conda/envs/gdf/lib/./libuct.so.0(+0x248c8) [0x7f03151638c8]
 8  /opt/conda/envs/gdf/lib/libucs.so.0(ucs_event_set_wait+0xb9) [0x7f03151af499]
 9  /opt/conda/envs/gdf/lib/./libuct.so.0(uct_tcp_iface_progress+0x7d) [0x7f031516266d]
10  /opt/conda/envs/gdf/lib/libucp.so.0(ucp_worker_progress+0x5a) [0x7f03152218ca]
11  /opt/conda/envs/gdf/lib/python3.9/site-packages/ucp/_libs/ucx_api.cpython-39-x86_64-linux-gnu.so(+0x3206a) [0x7f03152da06a]
12  /opt/conda/envs/gdf/bin/python(_PyEval_EvalFrameDefault+0x37cb) [0x55f58d9ef6fb]
13  /opt/conda/envs/gdf/bin/python(+0x12f094) [0x55f58d9eb094]
14  /opt/conda/envs/gdf/bin/python(_PyFunction_Vectorcall+0xd9) [0x55f58d9fc519]
15  /opt/conda/envs/gdf/bin/python(_PyEval_EvalFrameDefault+0x696) [0x55f58d9ec5c6]
16  /opt/conda/envs/gdf/bin/python(+0x1e3162) [0x55f58da9f162]
17  /opt/conda/envs/gdf/lib/python3.9/lib-dynload/_asyncio.cpython-39-x86_64-linux-gnu.so(+0x81e9) [0x7f033a31b1e9]
18  /opt/conda/envs/gdf/bin/python(_PyObject_MakeTpCall+0x2ec) [0x55f58d9f477c]
19  /opt/conda/envs/gdf/bin/python(+0xead05) [0x55f58d9a6d05]
20  /opt/conda/envs/gdf/bin/python(+0x1377f3) [0x55f58d9f37f3]
21  /opt/conda/envs/gdf/bin/python(_PyEval_EvalFrameDefault+0x59f9) [0x55f58d9f1929]
22  /opt/conda/envs/gdf/bin/python(+0x1407c2) [0x55f58d9fc7c2]
23  /opt/conda/envs/gdf/bin/python(_PyEval_EvalFrameDefault+0x696) [0x55f58d9ec5c6]
24  /opt/conda/envs/gdf/bin/python(+0x1407c2) [0x55f58d9fc7c2]
25  /opt/conda/envs/gdf/bin/python(_PyEval_EvalFrameDefault+0x696) [0x55f58d9ec5c6]
26  /opt/conda/envs/gdf/bin/python(+0x1407c2) [0x55f58d9fc7c2]
27  /opt/conda/envs/gdf/bin/python(_PyEval_EvalFrameDefault+0x696) [0x55f58d9ec5c6]
28  /opt/conda/envs/gdf/bin/python(+0x1407c2) [0x55f58d9fc7c2]
29  /opt/conda/envs/gdf/bin/python(_PyEval_EvalFrameDefault+0x696) [0x55f58d9ec5c6]
30  /opt/conda/envs/gdf/bin/python(+0x12f094) [0x55f58d9eb094]
31  /opt/conda/envs/gdf/bin/python(_PyFunction_Vectorcall+0xd9) [0x55f58d9fc519]
32  /opt/conda/envs/gdf/bin/python(_PyEval_EvalFrameDefault+0x11f8) [0x55f58d9ed128]
33  /opt/conda/envs/gdf/bin/python(+0x12f094) [0x55f58d9eb094]
34  /opt/conda/envs/gdf/bin/python(+0x14dccb) [0x55f58da09ccb]
35  /opt/conda/envs/gdf/bin/python(PyObject_Call+0xbc) [0x55f58da0a44c]
36  /opt/conda/envs/gdf/bin/python(+0x21110e) [0x55f58dacd10e]
37  /opt/conda/envs/gdf/bin/python(_PyObject_MakeTpCall+0x2ec) [0x55f58d9f477c]
38  /opt/conda/envs/gdf/bin/python(_PyEval_EvalFrameDefault+0x37cb) [0x55f58d9ef6fb]
39  /opt/conda/envs/gdf/bin/python(+0x1407c2) [0x55f58d9fc7c2]
40  /opt/conda/envs/gdf/bin/python(+0x14ddac) [0x55f58da09dac]
41  /opt/conda/envs/gdf/bin/python(_PyEval_EvalFrameDefault+0x37cb) [0x55f58d9ef6fb]
42  /opt/conda/envs/gdf/bin/python(+0x1407c2) [0x55f58d9fc7c2]
43  /opt/conda/envs/gdf/bin/python(_PyEval_EvalFrameDefault+0x696) [0x55f58d9ec5c6]
44  /opt/conda/envs/gdf/bin/python(+0x12f094) [0x55f58d9eb094]
45  /opt/conda/envs/gdf/bin/python(_PyFunction_Vectorcall+0xd9) [0x55f58d9fc519]
46  /opt/conda/envs/gdf/bin/python(_PyEval_EvalFrameDefault+0x696) [0x55f58d9ec5c6]
47  /opt/conda/envs/gdf/bin/python(+0x1407c2) [0x55f58d9fc7c2]
48  /opt/conda/envs/gdf/bin/python(_PyEval_EvalFrameDefault+0x3e2) [0x55f58d9ec312]
49  /opt/conda/envs/gdf/bin/python(+0x12f094) [0x55f58d9eb094]
50  /opt/conda/envs/gdf/bin/python(_PyFunction_Vectorcall+0xd9) [0x55f58d9fc519]
51  /opt/conda/envs/gdf/bin/python(_PyEval_EvalFrameDefault+0x11f8) [0x55f58d9ed128]
52  /opt/conda/envs/gdf/bin/python(+0x12f094) [0x55f58d9eb094]
53  /opt/conda/envs/gdf/bin/python(_PyEval_EvalCodeWithName+0x48) [0x55f58d9ead68]
54  /opt/conda/envs/gdf/bin/python(PyEval_EvalCodeEx+0x39) [0x55f58d9ead19]
55  /opt/conda/envs/gdf/bin/python(PyEval_EvalCode+0x1b) [0x55f58da9807b]
56  /opt/conda/envs/gdf/bin/python(+0x208fca) [0x55f58dac4fca]
57  /opt/conda/envs/gdf/bin/python(+0x205353) [0x55f58dac1353]
58  /opt/conda/envs/gdf/bin/python(PyRun_StringFlags+0x9a) [0x55f58dab916a]
59  /opt/conda/envs/gdf/bin/python(PyRun_SimpleStringFlags+0x3c) [0x55f58dab905c]
60  /opt/conda/envs/gdf/bin/python(Py_RunMain+0x267) [0x55f58dab8297]
61  /opt/conda/envs/gdf/bin/python(Py_BytesMain+0x37) [0x55f58da8bf07]
=================================
==== backtrace (tid:  71454) ====
 0  /opt/conda/envs/gdf/lib/libucs.so.0(ucs_handle_error+0x2fd) [0x7fe5999e806d]
 1  /opt/conda/envs/gdf/lib/libucs.so.0(+0x2a264) [0x7fe5999e8264]
 2  /opt/conda/envs/gdf/lib/libucs.so.0(+0x2a42a) [0x7fe5999e842a]
 3  /usr/lib/x86_64-linux-gnu/libpthread.so.0(+0x14420) [0x7fe63eb53420]
 4  /opt/conda/envs/gdf/lib/libucp.so.0(ucp_mem_type_unpack+0x14) [0x7fe599a666a4]
 5  /opt/conda/envs/gdf/lib/libucp.so.0(ucp_rndv_data_handler+0x4e9) [0x7fe599a8f829]
 6  /opt/conda/envs/gdf/lib/./libuct.so.0(+0x2146f) [0x7fe5999a246f]
 7  /opt/conda/envs/gdf/lib/./libuct.so.0(+0x248c8) [0x7fe5999a58c8]
 8  /opt/conda/envs/gdf/lib/libucs.so.0(ucs_event_set_wait+0xb9) [0x7fe5999f1499]
 9  /opt/conda/envs/gdf/lib/./libuct.so.0(uct_tcp_iface_progress+0x7d) [0x7fe5999a466d]
10  /opt/conda/envs/gdf/lib/libucp.so.0(ucp_worker_progress+0x5a) [0x7fe599a638ca]
11  /opt/conda/envs/gdf/lib/python3.9/site-packages/ucp/_libs/ucx_api.cpython-39-x86_64-linux-gnu.so(+0x3206a) [0x7fe599b1c06a]
12  /opt/conda/envs/gdf/bin/python(_PyEval_EvalFrameDefault+0x37cb) [0x563f9ed0d6fb]
13  /opt/conda/envs/gdf/bin/python(+0x12f094) [0x563f9ed09094]
14  /opt/conda/envs/gdf/bin/python(_PyFunction_Vectorcall+0xd9) [0x563f9ed1a519]
15  /opt/conda/envs/gdf/bin/python(_PyEval_EvalFrameDefault+0x696) [0x563f9ed0a5c6]
16  /opt/conda/envs/gdf/bin/python(+0x1407c2) [0x563f9ed1a7c2]
17  /opt/conda/envs/gdf/bin/python(+0x14de83) [0x563f9ed27e83]
18  /opt/conda/envs/gdf/bin/python(+0x258b2c) [0x563f9ee32b2c]
19  /opt/conda/envs/gdf/bin/python(+0xead05) [0x563f9ecc4d05]
20  /opt/conda/envs/gdf/bin/python(+0x1377f3) [0x563f9ed117f3]
21  /opt/conda/envs/gdf/bin/python(_PyEval_EvalFrameDefault+0x59f9) [0x563f9ed0f929]
22  /opt/conda/envs/gdf/bin/python(+0x1407c2) [0x563f9ed1a7c2]
23  /opt/conda/envs/gdf/bin/python(_PyEval_EvalFrameDefault+0x696) [0x563f9ed0a5c6]
24  /opt/conda/envs/gdf/bin/python(+0x1407c2) [0x563f9ed1a7c2]
25  /opt/conda/envs/gdf/bin/python(_PyEval_EvalFrameDefault+0x696) [0x563f9ed0a5c6]
26  /opt/conda/envs/gdf/bin/python(+0x1407c2) [0x563f9ed1a7c2]
27  /opt/conda/envs/gdf/bin/python(_PyEval_EvalFrameDefault+0x696) [0x563f9ed0a5c6]
28  /opt/conda/envs/gdf/bin/python(+0x1407c2) [0x563f9ed1a7c2]
29  /opt/conda/envs/gdf/bin/python(_PyEval_EvalFrameDefault+0x696) [0x563f9ed0a5c6]
30  /opt/conda/envs/gdf/bin/python(+0x12f094) [0x563f9ed09094]
31  /opt/conda/envs/gdf/bin/python(_PyFunction_Vectorcall+0xd9) [0x563f9ed1a519]
32  /opt/conda/envs/gdf/bin/python(_PyEval_EvalFrameDefault+0x11f8) [0x563f9ed0b128]
33  /opt/conda/envs/gdf/bin/python(+0x12f094) [0x563f9ed09094]
34  /opt/conda/envs/gdf/bin/python(+0x14dccb) [0x563f9ed27ccb]
35  /opt/conda/envs/gdf/bin/python(PyObject_Call+0xbc) [0x563f9ed2844c]
36  /opt/conda/envs/gdf/bin/python(+0x21110e) [0x563f9edeb10e]
37  /opt/conda/envs/gdf/bin/python(_PyObject_MakeTpCall+0x2ec) [0x563f9ed1277c]
38  /opt/conda/envs/gdf/bin/python(_PyEval_EvalFrameDefault+0x37cb) [0x563f9ed0d6fb]
39  /opt/conda/envs/gdf/bin/python(+0x1407c2) [0x563f9ed1a7c2]
40  /opt/conda/envs/gdf/bin/python(+0x14ddac) [0x563f9ed27dac]
41  /opt/conda/envs/gdf/bin/python(_PyEval_EvalFrameDefault+0x37cb) [0x563f9ed0d6fb]
42  /opt/conda/envs/gdf/bin/python(+0x1407c2) [0x563f9ed1a7c2]
43  /opt/conda/envs/gdf/bin/python(_PyEval_EvalFrameDefault+0x696) [0x563f9ed0a5c6]
44  /opt/conda/envs/gdf/bin/python(+0x12f094) [0x563f9ed09094]
45  /opt/conda/envs/gdf/bin/python(_PyFunction_Vectorcall+0xd9) [0x563f9ed1a519]
46  /opt/conda/envs/gdf/bin/python(_PyEval_EvalFrameDefault+0x696) [0x563f9ed0a5c6]
47  /opt/conda/envs/gdf/bin/python(+0x1407c2) [0x563f9ed1a7c2]
48  /opt/conda/envs/gdf/bin/python(_PyEval_EvalFrameDefault+0x3e2) [0x563f9ed0a312]
49  /opt/conda/envs/gdf/bin/python(+0x12f094) [0x563f9ed09094]
50  /opt/conda/envs/gdf/bin/python(_PyFunction_Vectorcall+0xd9) [0x563f9ed1a519]
51  /opt/conda/envs/gdf/bin/python(_PyEval_EvalFrameDefault+0x11f8) [0x563f9ed0b128]
52  /opt/conda/envs/gdf/bin/python(+0x12f094) [0x563f9ed09094]
53  /opt/conda/envs/gdf/bin/python(_PyEval_EvalCodeWithName+0x48) [0x563f9ed08d68]
54  /opt/conda/envs/gdf/bin/python(PyEval_EvalCodeEx+0x39) [0x563f9ed08d19]
55  /opt/conda/envs/gdf/bin/python(PyEval_EvalCode+0x1b) [0x563f9edb607b]
56  /opt/conda/envs/gdf/bin/python(+0x208fca) [0x563f9ede2fca]
57  /opt/conda/envs/gdf/bin/python(+0x205353) [0x563f9eddf353]
58  /opt/conda/envs/gdf/bin/python(PyRun_StringFlags+0x9a) [0x563f9edd716a]
59  /opt/conda/envs/gdf/bin/python(PyRun_SimpleStringFlags+0x3c) [0x563f9edd705c]
60  /opt/conda/envs/gdf/bin/python(Py_RunMain+0x267) [0x563f9edd6297]
61  /opt/conda/envs/gdf/bin/python(Py_BytesMain+0x37) [0x563f9eda9f07]
=================================
[dgx13:71594:0:71594] Caught signal 11 (Segmentation fault: address not mapped to object at address 0x448)
==== backtrace (tid:  71594) ====
 0  /opt/conda/envs/gdf/lib/libucs.so.0(ucs_handle_error+0x2fd) [0x7f5a0c1f906d]
 1  /opt/conda/envs/gdf/lib/libucs.so.0(+0x2a264) [0x7f5a0c1f9264]
 2  /opt/conda/envs/gdf/lib/libucs.so.0(+0x2a42a) [0x7f5a0c1f942a]
 3  /usr/lib/x86_64-linux-gnu/libpthread.so.0(+0x14420) [0x7f5a9f200420]
 4  /opt/conda/envs/gdf/lib/libucp.so.0(ucp_mem_type_unpack+0x14) [0x7f5a0c2776a4]
 5  /opt/conda/envs/gdf/lib/libucp.so.0(ucp_rndv_data_handler+0x4e9) [0x7f5a0c2a0829]
 6  /opt/conda/envs/gdf/lib/./libuct.so.0(+0x2146f) [0x7f5a0c1b346f]
 7  /opt/conda/envs/gdf/lib/./libuct.so.0(+0x248c8) [0x7f5a0c1b68c8]
 8  /opt/conda/envs/gdf/lib/libucs.so.0(ucs_event_set_wait+0xb9) [0x7f5a0c202499]
 9  /opt/conda/envs/gdf/lib/./libuct.so.0(uct_tcp_iface_progress+0x7d) [0x7f5a0c1b566d]
10  /opt/conda/envs/gdf/lib/libucp.so.0(ucp_worker_progress+0x5a) [0x7f5a0c2748ca]
11  /opt/conda/envs/gdf/lib/python3.9/site-packages/ucp/_libs/ucx_api.cpython-39-x86_64-linux-gnu.so(+0x3206a) [0x7f5a0c32d06a]
12  /opt/conda/envs/gdf/bin/python(_PyEval_EvalFrameDefault+0x37cb) [0x55bb298716fb]
13  /opt/conda/envs/gdf/bin/python(+0x12f094) [0x55bb2986d094]
14  /opt/conda/envs/gdf/bin/python(_PyFunction_Vectorcall+0xd9) [0x55bb2987e519]
15  /opt/conda/envs/gdf/bin/python(_PyEval_EvalFrameDefault+0x696) [0x55bb2986e5c6]
16  /opt/conda/envs/gdf/bin/python(+0x1407c2) [0x55bb2987e7c2]
17  /opt/conda/envs/gdf/bin/python(+0x14de83) [0x55bb2988be83]
18  /opt/conda/envs/gdf/bin/python(+0x258b2c) [0x55bb29996b2c]
19  /opt/conda/envs/gdf/bin/python(+0xead05) [0x55bb29828d05]
20  /opt/conda/envs/gdf/bin/python(+0x1377f3) [0x55bb298757f3]
21  /opt/conda/envs/gdf/bin/python(_PyEval_EvalFrameDefault+0x59f9) [0x55bb29873929]
22  /opt/conda/envs/gdf/bin/python(+0x1407c2) [0x55bb2987e7c2]
23  /opt/conda/envs/gdf/bin/python(_PyEval_EvalFrameDefault+0x696) [0x55bb2986e5c6]
24  /opt/conda/envs/gdf/bin/python(+0x1407c2) [0x55bb2987e7c2]
25  /opt/conda/envs/gdf/bin/python(_PyEval_EvalFrameDefault+0x696) [0x55bb2986e5c6]
26  /opt/conda/envs/gdf/bin/python(+0x1407c2) [0x55bb2987e7c2]
27  /opt/conda/envs/gdf/bin/python(_PyEval_EvalFrameDefault+0x696) [0x55bb2986e5c6]
28  /opt/conda/envs/gdf/bin/python(+0x1407c2) [0x55bb2987e7c2]
29  /opt/conda/envs/gdf/bin/python(_PyEval_EvalFrameDefault+0x696) [0x55bb2986e5c6]
30  /opt/conda/envs/gdf/bin/python(+0x12f094) [0x55bb2986d094]
31  /opt/conda/envs/gdf/bin/python(_PyFunction_Vectorcall+0xd9) [0x55bb2987e519]
32  /opt/conda/envs/gdf/bin/python(_PyEval_EvalFrameDefault+0x11f8) [0x55bb2986f128]
33  /opt/conda/envs/gdf/bin/python(+0x12f094) [0x55bb2986d094]
34  /opt/conda/envs/gdf/bin/python(+0x14dccb) [0x55bb2988bccb]
35  /opt/conda/envs/gdf/bin/python(PyObject_Call+0xbc) [0x55bb2988c44c]
36  /opt/conda/envs/gdf/bin/python(+0x21110e) [0x55bb2994f10e]
37  /opt/conda/envs/gdf/bin/python(_PyObject_MakeTpCall+0x2ec) [0x55bb2987677c]
38  /opt/conda/envs/gdf/bin/python(_PyEval_EvalFrameDefault+0x37cb) [0x55bb298716fb]
39  /opt/conda/envs/gdf/bin/python(+0x1407c2) [0x55bb2987e7c2]
40  /opt/conda/envs/gdf/bin/python(+0x14ddac) [0x55bb2988bdac]
41  /opt/conda/envs/gdf/bin/python(_PyEval_EvalFrameDefault+0x37cb) [0x55bb298716fb]
42  /opt/conda/envs/gdf/bin/python(+0x1407c2) [0x55bb2987e7c2]
43  /opt/conda/envs/gdf/bin/python(_PyEval_EvalFrameDefault+0x696) [0x55bb2986e5c6]
44  /opt/conda/envs/gdf/bin/python(+0x12f094) [0x55bb2986d094]
45  /opt/conda/envs/gdf/bin/python(_PyFunction_Vectorcall+0xd9) [0x55bb2987e519]
46  /opt/conda/envs/gdf/bin/python(_PyEval_EvalFrameDefault+0x696) [0x55bb2986e5c6]
47  /opt/conda/envs/gdf/bin/python(+0x1407c2) [0x55bb2987e7c2]
48  /opt/conda/envs/gdf/bin/python(_PyEval_EvalFrameDefault+0x3e2) [0x55bb2986e312]
49  /opt/conda/envs/gdf/bin/python(+0x12f094) [0x55bb2986d094]
50  /opt/conda/envs/gdf/bin/python(_PyFunction_Vectorcall+0xd9) [0x55bb2987e519]
51  /opt/conda/envs/gdf/bin/python(_PyEval_EvalFrameDefault+0x11f8) [0x55bb2986f128]
52  /opt/conda/envs/gdf/bin/python(+0x12f094) [0x55bb2986d094]
53  /opt/conda/envs/gdf/bin/python(_PyEval_EvalCodeWithName+0x48) [0x55bb2986cd68]
54  /opt/conda/envs/gdf/bin/python(PyEval_EvalCodeEx+0x39) [0x55bb2986cd19]
55  /opt/conda/envs/gdf/bin/python(PyEval_EvalCode+0x1b) [0x55bb2991a07b]
56  /opt/conda/envs/gdf/bin/python(+0x208fca) [0x55bb29946fca]
57  /opt/conda/envs/gdf/bin/python(+0x205353) [0x55bb29943353]
58  /opt/conda/envs/gdf/bin/python(PyRun_StringFlags+0x9a) [0x55bb2993b16a]
59  /opt/conda/envs/gdf/bin/python(PyRun_SimpleStringFlags+0x3c) [0x55bb2993b05c]
60  /opt/conda/envs/gdf/bin/python(Py_RunMain+0x267) [0x55bb2993a297]
61  /opt/conda/envs/gdf/bin/python(Py_BytesMain+0x37) [0x55bb2990df07]
=================================
2023-10-31 06:29:25,306 - distributed.worker - ERROR - failed during get data with ucx://127.0.0.1:54263 -> ucx://127.0.0.1:51215
Traceback (most recent call last):
  File "/opt/conda/envs/gdf/lib/python3.9/site-packages/distributed/comm/ucx.py", line 354, in read
    await self.ep.recv(msg)
  File "/opt/conda/envs/gdf/lib/python3.9/site-packages/ucp/core.py", line 725, in recv
    ret = await comm.tag_recv(self._ep, buffer, nbytes, tag, name=log)
ucp._libs.exceptions.UCXCanceled: <[Recv #030] ep: 0x7f36628ba340, tag: 0x191888c36c672a94, nbytes: 16, type: <class 'numpy.ndarray'>>: 

During handling of the above exception, another exception occurred:

Traceback (most recent call last):
  File "/opt/conda/envs/gdf/lib/python3.9/site-packages/distributed/worker.py", line 1783, in get_data
    response = await comm.read(deserializers=serializers)
  File "/opt/conda/envs/gdf/lib/python3.9/site-packages/distributed/utils.py", line 803, in wrapper
    return await func(*args, **kwargs)
  File "/opt/conda/envs/gdf/lib/python3.9/site-packages/distributed/comm/ucx.py", line 372, in read
    raise CommClosedError(
distributed.comm.core.CommClosedError: Connection closed by writer.
Inner exception: UCXCanceled("<[Recv #030] ep: 0x7f36628ba340, tag: 0x191888c36c672a94, nbytes: 16, type: <class 'numpy.ndarray'>>: ")
2023-10-31 06:29:25,306 - distributed.worker - ERROR - Worker stream died during communication: ucx://127.0.0.1:51215
Traceback (most recent call last):
  File "/opt/conda/envs/gdf/lib/python3.9/site-packages/distributed/comm/ucx.py", line 396, in read
    await self.ep.recv(each_frame)
  File "/opt/conda/envs/gdf/lib/python3.9/site-packages/ucp/core.py", line 725, in recv
    ret = await comm.tag_recv(self._ep, buffer, nbytes, tag, name=log)
ucp._libs.exceptions.UCXError: <[Recv #007] ep: 0x7f2c1818c200, tag: 0x7d320e9db51261e6, nbytes: 50000000, type: <class 'rmm._lib.device_buffer.DeviceBuffer'>>: Connection reset by remote peer

During handling of the above exception, another exception occurred:

Traceback (most recent call last):
  File "/opt/conda/envs/gdf/lib/python3.9/site-packages/distributed/worker.py", line 2059, in gather_dep
    response = await get_data_from_worker(
  File "/opt/conda/envs/gdf/lib/python3.9/site-packages/distributed/worker.py", line 2852, in get_data_from_worker
    response = await send_recv(
  File "/opt/conda/envs/gdf/lib/python3.9/site-packages/distributed/core.py", line 1106, in send_recv
    response = await comm.read(deserializers=deserializers)
  File "/opt/conda/envs/gdf/lib/python3.9/site-packages/distributed/utils.py", line 803, in wrapper
    return await func(*args, **kwargs)
  File "/opt/conda/envs/gdf/lib/python3.9/site-packages/distributed/comm/ucx.py", line 402, in read
    raise CommClosedError(
distributed.comm.core.CommClosedError: Connection closed by writer.
Inner exception: UCXError("<[Recv #007] ep: 0x7f2c1818c200, tag: 0x7d320e9db51261e6, nbytes: 50000000, type: <class 'rmm._lib.device_buffer.DeviceBuffer'>>: Connection reset by remote peer")
2023-10-31 06:29:25,307 - distributed.worker - ERROR - Worker stream died during communication: ucx://127.0.0.1:51215
Traceback (most recent call last):
  File "/opt/conda/envs/gdf/lib/python3.9/site-packages/distributed/comm/ucx.py", line 396, in read
    await self.ep.recv(each_frame)
  File "/opt/conda/envs/gdf/lib/python3.9/site-packages/ucp/core.py", line 725, in recv
    ret = await comm.tag_recv(self._ep, buffer, nbytes, tag, name=log)
ucp._libs.exceptions.UCXError: <[Recv #014] ep: 0x7f36628ba200, tag: 0xd6781abca645a036, nbytes: 50000000, type: <class 'rmm._lib.device_buffer.DeviceBuffer'>>: Connection reset by remote peer

During handling of the above exception, another exception occurred:

Traceback (most recent call last):
  File "/opt/conda/envs/gdf/lib/python3.9/site-packages/distributed/worker.py", line 2059, in gather_dep
    response = await get_data_from_worker(
  File "/opt/conda/envs/gdf/lib/python3.9/site-packages/distributed/worker.py", line 2852, in get_data_from_worker
    response = await send_recv(
  File "/opt/conda/envs/gdf/lib/python3.9/site-packages/distributed/core.py", line 1106, in send_recv
    response = await comm.read(deserializers=deserializers)
  File "/opt/conda/envs/gdf/lib/python3.9/site-packages/distributed/utils.py", line 803, in wrapper
    return await func(*args, **kwargs)
  File "/opt/conda/envs/gdf/lib/python3.9/site-packages/distributed/comm/ucx.py", line 402, in read
    raise CommClosedError(
distributed.comm.core.CommClosedError: Connection closed by writer.
Inner exception: UCXError("<[Recv #014] ep: 0x7f36628ba200, tag: 0xd6781abca645a036, nbytes: 50000000, type: <class 'rmm._lib.device_buffer.DeviceBuffer'>>: Connection reset by remote peer")
2023-10-31 06:29:25,317 - distributed.worker - ERROR - Worker stream died during communication: ucx://127.0.0.1:51215
Traceback (most recent call last):
  File "/opt/conda/envs/gdf/lib/python3.9/site-packages/distributed/core.py", line 1516, in _connect
    comm = await connect(
  File "/opt/conda/envs/gdf/lib/python3.9/site-packages/distributed/comm/core.py", line 342, in connect
    comm = await wait_for(
  File "/opt/conda/envs/gdf/lib/python3.9/site-packages/distributed/utils.py", line 1920, in wait_for
    return await asyncio.wait_for(fut, timeout)
  File "/opt/conda/envs/gdf/lib/python3.9/asyncio/tasks.py", line 466, in wait_for
    await waiter
asyncio.exceptions.CancelledError

During handling of the above exception, another exception occurred:

Traceback (most recent call last):
  File "/opt/conda/envs/gdf/lib/python3.9/site-packages/distributed/core.py", line 1626, in connect
    return connect_attempt.result()
asyncio.exceptions.CancelledError

During handling of the above exception, another exception occurred:

Traceback (most recent call last):
  File "/opt/conda/envs/gdf/lib/python3.9/site-packages/distributed/worker.py", line 2059, in gather_dep
    response = await get_data_from_worker(
  File "/opt/conda/envs/gdf/lib/python3.9/site-packages/distributed/worker.py", line 2849, in get_data_from_worker
    comm = await rpc.connect(worker)
  File "/opt/conda/envs/gdf/lib/python3.9/site-packages/distributed/core.py", line 1628, in connect
    raise CommClosedError(reason)
distributed.comm.core.CommClosedError: Address removed.
[dgx13:71444:0:71444] Caught signal 11 (Segmentation fault: address not mapped to object at address 0x448)
==== backtrace (tid:  71444) ====
 0  /opt/conda/envs/gdf/lib/libucs.so.0(ucs_handle_error+0x2fd) [0x7f36633a706d]
 1  /opt/conda/envs/gdf/lib/libucs.so.0(+0x2a264) [0x7f36633a7264]
 2  /opt/conda/envs/gdf/lib/libucs.so.0(+0x2a42a) [0x7f36633a742a]
 3  /usr/lib/x86_64-linux-gnu/libpthread.so.0(+0x14420) [0x7f3704519420]
 4  /opt/conda/envs/gdf/lib/libucp.so.0(ucp_mem_type_unpack+0x14) [0x7f36634256a4]
 5  /opt/conda/envs/gdf/lib/libucp.so.0(ucp_rndv_data_handler+0x4e9) [0x7f366344e829]
 6  /opt/conda/envs/gdf/lib/./libuct.so.0(+0x2146f) [0x7f366336146f]
 7  /opt/conda/envs/gdf/lib/./libuct.so.0(+0x248c8) [0x7f36633648c8]
 8  /opt/conda/envs/gdf/lib/libucs.so.0(ucs_event_set_wait+0xb9) [0x7f36633b0499]
 9  /opt/conda/envs/gdf/lib/./libuct.so.0(uct_tcp_iface_progress+0x7d) [0x7f366336366d]
10  /opt/conda/envs/gdf/lib/libucp.so.0(ucp_worker_progress+0x5a) [0x7f36634228ca]
11  /opt/conda/envs/gdf/lib/python3.9/site-packages/ucp/_libs/ucx_api.cpython-39-x86_64-linux-gnu.so(+0x3206a) [0x7f36634db06a]
12  /opt/conda/envs/gdf/bin/python(_PyEval_EvalFrameDefault+0x37cb) [0x561d87f266fb]
13  /opt/conda/envs/gdf/bin/python(+0x12f094) [0x561d87f22094]
14  /opt/conda/envs/gdf/bin/python(_PyFunction_Vectorcall+0xd9) [0x561d87f33519]
15  /opt/conda/envs/gdf/bin/python(_PyEval_EvalFrameDefault+0x696) [0x561d87f235c6]
16  /opt/conda/envs/gdf/bin/python(+0x1407c2) [0x561d87f337c2]
17  /opt/conda/envs/gdf/bin/python(+0x14de83) [0x561d87f40e83]
18  /opt/conda/envs/gdf/bin/python(+0x258b2c) [0x561d8804bb2c]
19  /opt/conda/envs/gdf/bin/python(+0xead05) [0x561d87eddd05]
20  /opt/conda/envs/gdf/bin/python(+0x1377f3) [0x561d87f2a7f3]
21  /opt/conda/envs/gdf/bin/python(_PyEval_EvalFrameDefault+0x59f9) [0x561d87f28929]
22  /opt/conda/envs/gdf/bin/python(+0x1407c2) [0x561d87f337c2]
23  /opt/conda/envs/gdf/bin/python(_PyEval_EvalFrameDefault+0x696) [0x561d87f235c6]
24  /opt/conda/envs/gdf/bin/python(+0x1407c2) [0x561d87f337c2]
25  /opt/conda/envs/gdf/bin/python(_PyEval_EvalFrameDefault+0x696) [0x561d87f235c6]
26  /opt/conda/envs/gdf/bin/python(+0x1407c2) [0x561d87f337c2]
27  /opt/conda/envs/gdf/bin/python(_PyEval_EvalFrameDefault+0x696) [0x561d87f235c6]
28  /opt/conda/envs/gdf/bin/python(+0x1407c2) [0x561d87f337c2]
29  /opt/conda/envs/gdf/bin/python(_PyEval_EvalFrameDefault+0x696) [0x561d87f235c6]
30  /opt/conda/envs/gdf/bin/python(+0x12f094) [0x561d87f22094]
31  /opt/conda/envs/gdf/bin/python(_PyFunction_Vectorcall+0xd9) [0x561d87f33519]
32  /opt/conda/envs/gdf/bin/python(_PyEval_EvalFrameDefault+0x11f8) [0x561d87f24128]
33  /opt/conda/envs/gdf/bin/python(+0x12f094) [0x561d87f22094]
34  /opt/conda/envs/gdf/bin/python(+0x14dccb) [0x561d87f40ccb]
35  /opt/conda/envs/gdf/bin/python(PyObject_Call+0xbc) [0x561d87f4144c]
36  /opt/conda/envs/gdf/bin/python(+0x21110e) [0x561d8800410e]
37  /opt/conda/envs/gdf/bin/python(_PyObject_MakeTpCall+0x2ec) [0x561d87f2b77c]
38  /opt/conda/envs/gdf/bin/python(_PyEval_EvalFrameDefault+0x37cb) [0x561d87f266fb]
39  /opt/conda/envs/gdf/bin/python(+0x1407c2) [0x561d87f337c2]
40  /opt/conda/envs/gdf/bin/python(+0x14ddac) [0x561d87f40dac]
41  /opt/conda/envs/gdf/bin/python(_PyEval_EvalFrameDefault+0x37cb) [0x561d87f266fb]
42  /opt/conda/envs/gdf/bin/python(+0x1407c2) [0x561d87f337c2]
43  /opt/conda/envs/gdf/bin/python(_PyEval_EvalFrameDefault+0x696) [0x561d87f235c6]
44  /opt/conda/envs/gdf/bin/python(+0x12f094) [0x561d87f22094]
45  /opt/conda/envs/gdf/bin/python(_PyFunction_Vectorcall+0xd9) [0x561d87f33519]
46  /opt/conda/envs/gdf/bin/python(_PyEval_EvalFrameDefault+0x696) [0x561d87f235c6]
47  /opt/conda/envs/gdf/bin/python(+0x1407c2) [0x561d87f337c2]
48  /opt/conda/envs/gdf/bin/python(_PyEval_EvalFrameDefault+0x3e2) [0x561d87f23312]
49  /opt/conda/envs/gdf/bin/python(+0x12f094) [0x561d87f22094]
50  /opt/conda/envs/gdf/bin/python(_PyFunction_Vectorcall+0xd9) [0x561d87f33519]
51  /opt/conda/envs/gdf/bin/python(_PyEval_EvalFrameDefault+0x11f8) [0x561d87f24128]
52  /opt/conda/envs/gdf/bin/python(+0x12f094) [0x561d87f22094]
53  /opt/conda/envs/gdf/bin/python(_PyEval_EvalCodeWithName+0x48) [0x561d87f21d68]
54  /opt/conda/envs/gdf/bin/python(PyEval_EvalCodeEx+0x39) [0x561d87f21d19]
55  /opt/conda/envs/gdf/bin/python(PyEval_EvalCode+0x1b) [0x561d87fcf07b]
56  /opt/conda/envs/gdf/bin/python(+0x208fca) [0x561d87ffbfca]
57  /opt/conda/envs/gdf/bin/python(+0x205353) [0x561d87ff8353]
58  /opt/conda/envs/gdf/bin/python(PyRun_StringFlags+0x9a) [0x561d87ff016a]
59  /opt/conda/envs/gdf/bin/python(PyRun_SimpleStringFlags+0x3c) [0x561d87ff005c]
60  /opt/conda/envs/gdf/bin/python(Py_RunMain+0x267) [0x561d87fef297]
61  /opt/conda/envs/gdf/bin/python(Py_BytesMain+0x37) [0x561d87fc2f07]
=================================
2023-10-31 06:29:25,524 - distributed.worker - ERROR - Worker stream died during communication: ucx://127.0.0.1:33619
Traceback (most recent call last):
  File "/opt/conda/envs/gdf/lib/python3.9/site-packages/distributed/comm/ucx.py", line 354, in read
    await self.ep.recv(msg)
  File "/opt/conda/envs/gdf/lib/python3.9/site-packages/ucp/core.py", line 725, in recv
    ret = await comm.tag_recv(self._ep, buffer, nbytes, tag, name=log)
ucp._libs.exceptions.UCXCanceled: <[Recv #008] ep: 0x7fdf912be300, tag: 0xe3bbee46c3e1260b, nbytes: 16, type: <class 'numpy.ndarray'>>: 

During handling of the above exception, another exception occurred:

Traceback (most recent call last):
  File "/opt/conda/envs/gdf/lib/python3.9/site-packages/distributed/worker.py", line 2059, in gather_dep
    response = await get_data_from_worker(
  File "/opt/conda/envs/gdf/lib/python3.9/site-packages/distributed/worker.py", line 2852, in get_data_from_worker
    response = await send_recv(
  File "/opt/conda/envs/gdf/lib/python3.9/site-packages/distributed/core.py", line 1106, in send_recv
    response = await comm.read(deserializers=deserializers)
  File "/opt/conda/envs/gdf/lib/python3.9/site-packages/distributed/utils.py", line 803, in wrapper
    return await func(*args, **kwargs)
  File "/opt/conda/envs/gdf/lib/python3.9/site-packages/distributed/comm/ucx.py", line 372, in read
    raise CommClosedError(
distributed.comm.core.CommClosedError: Connection closed by writer.
Inner exception: UCXCanceled("<[Recv #008] ep: 0x7fdf912be300, tag: 0xe3bbee46c3e1260b, nbytes: 16, type: <class 'numpy.ndarray'>>: ")
2023-10-31 06:29:26,131 - distributed.worker - ERROR - failed during get data with ucx://127.0.0.1:60655 -> ucx://127.0.0.1:54263
Traceback (most recent call last):
  File "/opt/conda/envs/gdf/lib/python3.9/site-packages/distributed/comm/ucx.py", line 338, in write
    await self.ep.send(each_frame)
  File "/opt/conda/envs/gdf/lib/python3.9/site-packages/ucp/core.py", line 650, in send
    return await comm.tag_send(self._ep, buffer, nbytes, tag, name=log)
ucp._libs.exceptions.UCXError: <[Send #007] ep: 0x7f1f414c02c0, tag: 0xad9b892a168010fe, nbytes: 50000000, type: <class 'cupy.ndarray'>>: Connection reset by remote peer

During handling of the above exception, another exception occurred:

Traceback (most recent call last):
  File "/opt/conda/envs/gdf/lib/python3.9/site-packages/distributed/worker.py", line 1782, in get_data
    compressed = await comm.write(msg, serializers=serializers)
  File "/opt/conda/envs/gdf/lib/python3.9/site-packages/distributed/utils.py", line 803, in wrapper
    return await func(*args, **kwargs)
  File "/opt/conda/envs/gdf/lib/python3.9/site-packages/distributed/comm/ucx.py", line 342, in write
    raise CommClosedError("While writing, the connection was closed")
distributed.comm.core.CommClosedError: While writing, the connection was closed
2023-10-31 06:29:26,132 - distributed.worker - ERROR - Worker stream died during communication: ucx://127.0.0.1:54263
Traceback (most recent call last):
  File "/opt/conda/envs/gdf/lib/python3.9/site-packages/distributed/comm/ucx.py", line 354, in read
    await self.ep.recv(msg)
  File "/opt/conda/envs/gdf/lib/python3.9/site-packages/ucp/core.py", line 725, in recv
    ret = await comm.tag_recv(self._ep, buffer, nbytes, tag, name=log)
ucp._libs.exceptions.UCXCanceled: <[Recv #013] ep: 0x7f1f414c01c0, tag: 0x3b66a437cee70e0f, nbytes: 16, type: <class 'numpy.ndarray'>>: 

During handling of the above exception, another exception occurred:

Traceback (most recent call last):
  File "/opt/conda/envs/gdf/lib/python3.9/site-packages/distributed/worker.py", line 2059, in gather_dep
    response = await get_data_from_worker(
  File "/opt/conda/envs/gdf/lib/python3.9/site-packages/distributed/worker.py", line 2852, in get_data_from_worker
    response = await send_recv(
  File "/opt/conda/envs/gdf/lib/python3.9/site-packages/distributed/core.py", line 1106, in send_recv
    response = await comm.read(deserializers=deserializers)
  File "/opt/conda/envs/gdf/lib/python3.9/site-packages/distributed/utils.py", line 803, in wrapper
    return await func(*args, **kwargs)
  File "/opt/conda/envs/gdf/lib/python3.9/site-packages/distributed/comm/ucx.py", line 372, in read
    raise CommClosedError(
distributed.comm.core.CommClosedError: Connection closed by writer.
Inner exception: UCXCanceled("<[Recv #013] ep: 0x7f1f414c01c0, tag: 0x3b66a437cee70e0f, nbytes: 16, type: <class 'numpy.ndarray'>>: ")
2023-10-31 06:29:29,445 - distributed.nanny - WARNING - Restarting worker
2023-10-31 06:29:29,815 - distributed.nanny - WARNING - Restarting worker
2023-10-31 06:29:29,999 - distributed.nanny - WARNING - Restarting worker
2023-10-31 06:29:30,214 - distributed.nanny - WARNING - Restarting worker
[dgx13:71597:0:71597] Caught signal 11 (Segmentation fault: address not mapped to object at address 0x448)
==== backtrace (tid:  71597) ====
 0  /opt/conda/envs/gdf/lib/libucs.so.0(ucs_handle_error+0x2fd) [0x7f1f4409706d]
 1  /opt/conda/envs/gdf/lib/libucs.so.0(+0x2a264) [0x7f1f44097264]
 2  /opt/conda/envs/gdf/lib/libucs.so.0(+0x2a42a) [0x7f1f4409742a]
 3  /usr/lib/x86_64-linux-gnu/libpthread.so.0(+0x14420) [0x7f1fe4fbb420]
 4  /opt/conda/envs/gdf/lib/libucp.so.0(ucp_mem_type_unpack+0x14) [0x7f1f41f7c6a4]
 5  /opt/conda/envs/gdf/lib/libucp.so.0(ucp_rndv_data_handler+0x4e9) [0x7f1f41fa5829]
 6  /opt/conda/envs/gdf/lib/./libuct.so.0(+0x2146f) [0x7f1f4405146f]
 7  /opt/conda/envs/gdf/lib/./libuct.so.0(+0x248c8) [0x7f1f440548c8]
 8  /opt/conda/envs/gdf/lib/libucs.so.0(ucs_event_set_wait+0xb9) [0x7f1f440a0499]
 9  /opt/conda/envs/gdf/lib/./libuct.so.0(uct_tcp_iface_progress+0x7d) [0x7f1f4405366d]
10  /opt/conda/envs/gdf/lib/libucp.so.0(ucp_worker_progress+0x5a) [0x7f1f41f798ca]
11  /opt/conda/envs/gdf/lib/python3.9/site-packages/ucp/_libs/ucx_api.cpython-39-x86_64-linux-gnu.so(+0x3206a) [0x7f1f440fd06a]
12  /opt/conda/envs/gdf/bin/python(_PyEval_EvalFrameDefault+0x37cb) [0x55981268f6fb]
13  /opt/conda/envs/gdf/bin/python(+0x12f094) [0x55981268b094]
14  /opt/conda/envs/gdf/bin/python(_PyFunction_Vectorcall+0xd9) [0x55981269c519]
15  /opt/conda/envs/gdf/bin/python(_PyEval_EvalFrameDefault+0x696) [0x55981268c5c6]
16  /opt/conda/envs/gdf/bin/python(+0x1407c2) [0x55981269c7c2]
17  /opt/conda/envs/gdf/bin/python(+0x14de83) [0x5598126a9e83]
18  /opt/conda/envs/gdf/bin/python(+0x258b2c) [0x5598127b4b2c]
19  /opt/conda/envs/gdf/bin/python(+0xead05) [0x559812646d05]
20  /opt/conda/envs/gdf/bin/python(+0x1377f3) [0x5598126937f3]
21  /opt/conda/envs/gdf/bin/python(_PyEval_EvalFrameDefault+0x59f9) [0x559812691929]
22  /opt/conda/envs/gdf/bin/python(+0x1407c2) [0x55981269c7c2]
23  /opt/conda/envs/gdf/bin/python(_PyEval_EvalFrameDefault+0x696) [0x55981268c5c6]
24  /opt/conda/envs/gdf/bin/python(+0x1407c2) [0x55981269c7c2]
25  /opt/conda/envs/gdf/bin/python(_PyEval_EvalFrameDefault+0x696) [0x55981268c5c6]
26  /opt/conda/envs/gdf/bin/python(+0x1407c2) [0x55981269c7c2]
27  /opt/conda/envs/gdf/bin/python(_PyEval_EvalFrameDefault+0x696) [0x55981268c5c6]
28  /opt/conda/envs/gdf/bin/python(+0x1407c2) [0x55981269c7c2]
29  /opt/conda/envs/gdf/bin/python(_PyEval_EvalFrameDefault+0x696) [0x55981268c5c6]
30  /opt/conda/envs/gdf/bin/python(+0x12f094) [0x55981268b094]
31  /opt/conda/envs/gdf/bin/python(_PyFunction_Vectorcall+0xd9) [0x55981269c519]
32  /opt/conda/envs/gdf/bin/python(_PyEval_EvalFrameDefault+0x11f8) [0x55981268d128]
33  /opt/conda/envs/gdf/bin/python(+0x12f094) [0x55981268b094]
34  /opt/conda/envs/gdf/bin/python(+0x14dccb) [0x5598126a9ccb]
35  /opt/conda/envs/gdf/bin/python(PyObject_Call+0xbc) [0x5598126aa44c]
36  /opt/conda/envs/gdf/bin/python(+0x21110e) [0x55981276d10e]
37  /opt/conda/envs/gdf/bin/python(_PyObject_MakeTpCall+0x2ec) [0x55981269477c]
38  /opt/conda/envs/gdf/bin/python(_PyEval_EvalFrameDefault+0x37cb) [0x55981268f6fb]
39  /opt/conda/envs/gdf/bin/python(+0x1407c2) [0x55981269c7c2]
40  /opt/conda/envs/gdf/bin/python(+0x14ddac) [0x5598126a9dac]
41  /opt/conda/envs/gdf/bin/python(_PyEval_EvalFrameDefault+0x37cb) [0x55981268f6fb]
42  /opt/conda/envs/gdf/bin/python(+0x1407c2) [0x55981269c7c2]
43  /opt/conda/envs/gdf/bin/python(_PyEval_EvalFrameDefault+0x696) [0x55981268c5c6]
44  /opt/conda/envs/gdf/bin/python(+0x12f094) [0x55981268b094]
45  /opt/conda/envs/gdf/bin/python(_PyFunction_Vectorcall+0xd9) [0x55981269c519]
46  /opt/conda/envs/gdf/bin/python(_PyEval_EvalFrameDefault+0x696) [0x55981268c5c6]
47  /opt/conda/envs/gdf/bin/python(+0x1407c2) [0x55981269c7c2]
48  /opt/conda/envs/gdf/bin/python(_PyEval_EvalFrameDefault+0x3e2) [0x55981268c312]
49  /opt/conda/envs/gdf/bin/python(+0x12f094) [0x55981268b094]
50  /opt/conda/envs/gdf/bin/python(_PyFunction_Vectorcall+0xd9) [0x55981269c519]
51  /opt/conda/envs/gdf/bin/python(_PyEval_EvalFrameDefault+0x11f8) [0x55981268d128]
52  /opt/conda/envs/gdf/bin/python(+0x12f094) [0x55981268b094]
53  /opt/conda/envs/gdf/bin/python(_PyEval_EvalCodeWithName+0x48) [0x55981268ad68]
54  /opt/conda/envs/gdf/bin/python(PyEval_EvalCodeEx+0x39) [0x55981268ad19]
55  /opt/conda/envs/gdf/bin/python(PyEval_EvalCode+0x1b) [0x55981273807b]
56  /opt/conda/envs/gdf/bin/python(+0x208fca) [0x559812764fca]
57  /opt/conda/envs/gdf/bin/python(+0x205353) [0x559812761353]
58  /opt/conda/envs/gdf/bin/python(PyRun_StringFlags+0x9a) [0x55981275916a]
59  /opt/conda/envs/gdf/bin/python(PyRun_SimpleStringFlags+0x3c) [0x55981275905c]
60  /opt/conda/envs/gdf/bin/python(Py_RunMain+0x267) [0x559812758297]
61  /opt/conda/envs/gdf/bin/python(Py_BytesMain+0x37) [0x55981272bf07]
=================================
2023-10-31 06:29:32,823 - distributed.worker - ERROR - failed during get data with ucx://127.0.0.1:59585 -> ucx://127.0.0.1:60655
Traceback (most recent call last):
  File "/opt/conda/envs/gdf/lib/python3.9/site-packages/distributed/comm/ucx.py", line 354, in read
    await self.ep.recv(msg)
  File "/opt/conda/envs/gdf/lib/python3.9/site-packages/ucp/core.py", line 725, in recv
    ret = await comm.tag_recv(self._ep, buffer, nbytes, tag, name=log)
ucp._libs.exceptions.UCXCanceled: <[Recv #006] ep: 0x7f6ddc01b240, tag: 0x3a91cbc4f65d7d5a, nbytes: 16, type: <class 'numpy.ndarray'>>: 

During handling of the above exception, another exception occurred:

Traceback (most recent call last):
  File "/opt/conda/envs/gdf/lib/python3.9/site-packages/distributed/worker.py", line 1783, in get_data
    response = await comm.read(deserializers=serializers)
  File "/opt/conda/envs/gdf/lib/python3.9/site-packages/distributed/utils.py", line 803, in wrapper
    return await func(*args, **kwargs)
  File "/opt/conda/envs/gdf/lib/python3.9/site-packages/distributed/comm/ucx.py", line 372, in read
    raise CommClosedError(
distributed.comm.core.CommClosedError: Connection closed by writer.
Inner exception: UCXCanceled("<[Recv #006] ep: 0x7f6ddc01b240, tag: 0x3a91cbc4f65d7d5a, nbytes: 16, type: <class 'numpy.ndarray'>>: ")
2023-10-31 06:29:32,824 - distributed.worker - ERROR - failed during get data with ucx://127.0.0.1:36759 -> ucx://127.0.0.1:60655
Traceback (most recent call last):
  File "/opt/conda/envs/gdf/lib/python3.9/site-packages/distributed/comm/ucx.py", line 338, in write
    await self.ep.send(each_frame)
  File "/opt/conda/envs/gdf/lib/python3.9/site-packages/ucp/core.py", line 650, in send
    return await comm.tag_send(self._ep, buffer, nbytes, tag, name=log)
ucp._libs.exceptions.UCXError: <[Send #007] ep: 0x7f64603cc0c0, tag: 0xe09dd91de87ba68, nbytes: 50000000, type: <class 'cupy.ndarray'>>: Connection reset by remote peer

During handling of the above exception, another exception occurred:

Traceback (most recent call last):
  File "/opt/conda/envs/gdf/lib/python3.9/site-packages/distributed/worker.py", line 1782, in get_data
    compressed = await comm.write(msg, serializers=serializers)
  File "/opt/conda/envs/gdf/lib/python3.9/site-packages/distributed/utils.py", line 803, in wrapper
    return await func(*args, **kwargs)
  File "/opt/conda/envs/gdf/lib/python3.9/site-packages/distributed/comm/ucx.py", line 342, in write
    raise CommClosedError("While writing, the connection was closed")
distributed.comm.core.CommClosedError: While writing, the connection was closed
2023-10-31 06:29:32,832 - distributed.worker - ERROR - Worker stream died during communication: ucx://127.0.0.1:60655
Traceback (most recent call last):
  File "/opt/conda/envs/gdf/lib/python3.9/site-packages/distributed/comm/ucx.py", line 471, in connect
    ep = await ucp.create_endpoint(ip, port)
  File "/opt/conda/envs/gdf/lib/python3.9/site-packages/ucp/core.py", line 1004, in create_endpoint
    return await _get_ctx().create_endpoint(
  File "/opt/conda/envs/gdf/lib/python3.9/site-packages/ucp/core.py", line 316, in create_endpoint
    peer_info = await exchange_peer_info(
  File "/opt/conda/envs/gdf/lib/python3.9/site-packages/ucp/core.py", line 54, in exchange_peer_info
    await comm.stream_recv(endpoint, peer_info_arr, peer_info_arr.nbytes)
ucp._libs.exceptions.UCXError: <stream_recv>: Connection reset by remote peer

During handling of the above exception, another exception occurred:

Traceback (most recent call last):
  File "/opt/conda/envs/gdf/lib/python3.9/site-packages/distributed/comm/core.py", line 342, in connect
    comm = await wait_for(
  File "/opt/conda/envs/gdf/lib/python3.9/site-packages/distributed/utils.py", line 1920, in wait_for
    return await asyncio.wait_for(fut, timeout)
  File "/opt/conda/envs/gdf/lib/python3.9/asyncio/tasks.py", line 479, in wait_for
    return fut.result()
  File "/opt/conda/envs/gdf/lib/python3.9/site-packages/distributed/comm/ucx.py", line 473, in connect
    raise CommClosedError("Connection closed before handshake completed")
distributed.comm.core.CommClosedError: Connection closed before handshake completed

During handling of the above exception, another exception occurred:

Traceback (most recent call last):
  File "/opt/conda/envs/gdf/lib/python3.9/site-packages/distributed/core.py", line 1516, in _connect
    comm = await connect(
  File "/opt/conda/envs/gdf/lib/python3.9/site-packages/distributed/comm/core.py", line 366, in connect
    await asyncio.sleep(backoff)
  File "/opt/conda/envs/gdf/lib/python3.9/asyncio/tasks.py", line 652, in sleep
    return await future
asyncio.exceptions.CancelledError

During handling of the above exception, another exception occurred:

Traceback (most recent call last):
  File "/opt/conda/envs/gdf/lib/python3.9/site-packages/distributed/core.py", line 1626, in connect
    return connect_attempt.result()
asyncio.exceptions.CancelledError

During handling of the above exception, another exception occurred:

Traceback (most recent call last):
  File "/opt/conda/envs/gdf/lib/python3.9/site-packages/distributed/worker.py", line 2059, in gather_dep
    response = await get_data_from_worker(
  File "/opt/conda/envs/gdf/lib/python3.9/site-packages/distributed/worker.py", line 2849, in get_data_from_worker
    comm = await rpc.connect(worker)
  File "/opt/conda/envs/gdf/lib/python3.9/site-packages/distributed/core.py", line 1628, in connect
    raise CommClosedError(reason)
distributed.comm.core.CommClosedError: Address removed.
2023-10-31 06:29:32,835 - distributed.worker - ERROR - Worker stream died during communication: ucx://127.0.0.1:60655
Traceback (most recent call last):
  File "/opt/conda/envs/gdf/lib/python3.9/site-packages/distributed/core.py", line 1516, in _connect
    comm = await connect(
  File "/opt/conda/envs/gdf/lib/python3.9/site-packages/distributed/comm/core.py", line 342, in connect
    comm = await wait_for(
  File "/opt/conda/envs/gdf/lib/python3.9/site-packages/distributed/utils.py", line 1920, in wait_for
    return await asyncio.wait_for(fut, timeout)
  File "/opt/conda/envs/gdf/lib/python3.9/asyncio/tasks.py", line 466, in wait_for
    await waiter
asyncio.exceptions.CancelledError

During handling of the above exception, another exception occurred:

Traceback (most recent call last):
  File "/opt/conda/envs/gdf/lib/python3.9/site-packages/distributed/core.py", line 1626, in connect
    return connect_attempt.result()
asyncio.exceptions.CancelledError

During handling of the above exception, another exception occurred:

Traceback (most recent call last):
  File "/opt/conda/envs/gdf/lib/python3.9/site-packages/distributed/worker.py", line 2059, in gather_dep
    response = await get_data_from_worker(
  File "/opt/conda/envs/gdf/lib/python3.9/site-packages/distributed/worker.py", line 2849, in get_data_from_worker
    comm = await rpc.connect(worker)
  File "/opt/conda/envs/gdf/lib/python3.9/site-packages/distributed/core.py", line 1628, in connect
    raise CommClosedError(reason)
distributed.comm.core.CommClosedError: Address removed.
2023-10-31 06:29:32,834 - distributed.worker - ERROR - Worker stream died during communication: ucx://127.0.0.1:60655
Traceback (most recent call last):
  File "/opt/conda/envs/gdf/lib/python3.9/site-packages/distributed/comm/ucx.py", line 471, in connect
    ep = await ucp.create_endpoint(ip, port)
  File "/opt/conda/envs/gdf/lib/python3.9/site-packages/ucp/core.py", line 1004, in create_endpoint
    return await _get_ctx().create_endpoint(
  File "/opt/conda/envs/gdf/lib/python3.9/site-packages/ucp/core.py", line 316, in create_endpoint
    peer_info = await exchange_peer_info(
  File "/opt/conda/envs/gdf/lib/python3.9/site-packages/ucp/core.py", line 54, in exchange_peer_info
    await comm.stream_recv(endpoint, peer_info_arr, peer_info_arr.nbytes)
ucp._libs.exceptions.UCXNotConnected: <stream_recv>: 

During handling of the above exception, another exception occurred:

Traceback (most recent call last):
  File "/opt/conda/envs/gdf/lib/python3.9/site-packages/distributed/comm/core.py", line 342, in connect
    comm = await wait_for(
  File "/opt/conda/envs/gdf/lib/python3.9/site-packages/distributed/utils.py", line 1920, in wait_for
    return await asyncio.wait_for(fut, timeout)
  File "/opt/conda/envs/gdf/lib/python3.9/asyncio/tasks.py", line 479, in wait_for
    return fut.result()
  File "/opt/conda/envs/gdf/lib/python3.9/site-packages/distributed/comm/ucx.py", line 473, in connect
    raise CommClosedError("Connection closed before handshake completed")
distributed.comm.core.CommClosedError: Connection closed before handshake completed

During handling of the above exception, another exception occurred:

Traceback (most recent call last):
  File "/opt/conda/envs/gdf/lib/python3.9/site-packages/distributed/core.py", line 1516, in _connect
    comm = await connect(
  File "/opt/conda/envs/gdf/lib/python3.9/site-packages/distributed/comm/core.py", line 366, in connect
    await asyncio.sleep(backoff)
  File "/opt/conda/envs/gdf/lib/python3.9/asyncio/tasks.py", line 652, in sleep
    return await future
asyncio.exceptions.CancelledError

During handling of the above exception, another exception occurred:

Traceback (most recent call last):
  File "/opt/conda/envs/gdf/lib/python3.9/site-packages/distributed/core.py", line 1626, in connect
    return connect_attempt.result()
asyncio.exceptions.CancelledError

During handling of the above exception, another exception occurred:

Traceback (most recent call last):
  File "/opt/conda/envs/gdf/lib/python3.9/site-packages/distributed/worker.py", line 2059, in gather_dep
    response = await get_data_from_worker(
  File "/opt/conda/envs/gdf/lib/python3.9/site-packages/distributed/worker.py", line 2849, in get_data_from_worker
    comm = await rpc.connect(worker)
  File "/opt/conda/envs/gdf/lib/python3.9/site-packages/distributed/core.py", line 1628, in connect
    raise CommClosedError(reason)
distributed.comm.core.CommClosedError: Address removed.
[dgx13:71649:0:71649] Caught signal 11 (Segmentation fault: address not mapped to object at address 0x448)
==== backtrace (tid:  71649) ====
 0  /opt/conda/envs/gdf/lib/libucs.so.0(ucs_handle_error+0x2fd) [0x7f5875c8806d]
 1  /opt/conda/envs/gdf/lib/libucs.so.0(+0x2a264) [0x7f5875c88264]
 2  /opt/conda/envs/gdf/lib/libucs.so.0(+0x2a42a) [0x7f5875c8842a]
 3  /usr/lib/x86_64-linux-gnu/libpthread.so.0(+0x14420) [0x7f5930c82420]
 4  /opt/conda/envs/gdf/lib/libucp.so.0(ucp_mem_type_unpack+0x14) [0x7f5875d066a4]
 5  /opt/conda/envs/gdf/lib/libucp.so.0(ucp_rndv_data_handler+0x4e9) [0x7f5875d2f829]
 6  /opt/conda/envs/gdf/lib/./libuct.so.0(+0x2146f) [0x7f5875c4246f]
 7  /opt/conda/envs/gdf/lib/./libuct.so.0(+0x248c8) [0x7f5875c458c8]
 8  /opt/conda/envs/gdf/lib/libucs.so.0(ucs_event_set_wait+0xb9) [0x7f5875c91499]
 9  /opt/conda/envs/gdf/lib/./libuct.so.0(uct_tcp_iface_progress+0x7d) [0x7f5875c4466d]
10  /opt/conda/envs/gdf/lib/libucp.so.0(ucp_worker_progress+0x5a) [0x7f5875d038ca]
11  /opt/conda/envs/gdf/lib/python3.9/site-packages/ucp/_libs/ucx_api.cpython-39-x86_64-linux-gnu.so(+0x3206a) [0x7f5875dbc06a]
12  /opt/conda/envs/gdf/bin/python(_PyEval_EvalFrameDefault+0x37cb) [0x5606349a36fb]
13  /opt/conda/envs/gdf/bin/python(+0x12f094) [0x56063499f094]
14  /opt/conda/envs/gdf/bin/python(_PyFunction_Vectorcall+0xd9) [0x5606349b0519]
15  /opt/conda/envs/gdf/bin/python(_PyEval_EvalFrameDefault+0x696) [0x5606349a05c6]
16  /opt/conda/envs/gdf/bin/python(+0x1e3162) [0x560634a53162]
17  /opt/conda/envs/gdf/lib/python3.9/lib-dynload/_asyncio.cpython-39-x86_64-linux-gnu.so(+0x81e9) [0x7f592401c1e9]
18  /opt/conda/envs/gdf/bin/python(_PyObject_MakeTpCall+0x2ec) [0x5606349a877c]
19  /opt/conda/envs/gdf/bin/python(+0xead05) [0x56063495ad05]
20  /opt/conda/envs/gdf/bin/python(+0x1377f3) [0x5606349a77f3]
21  /opt/conda/envs/gdf/bin/python(_PyEval_EvalFrameDefault+0x59f9) [0x5606349a5929]
22  /opt/conda/envs/gdf/bin/python(+0x1407c2) [0x5606349b07c2]
23  /opt/conda/envs/gdf/bin/python(_PyEval_EvalFrameDefault+0x696) [0x5606349a05c6]
24  /opt/conda/envs/gdf/bin/python(+0x1407c2) [0x5606349b07c2]
25  /opt/conda/envs/gdf/bin/python(_PyEval_EvalFrameDefault+0x696) [0x5606349a05c6]
26  /opt/conda/envs/gdf/bin/python(+0x1407c2) [0x5606349b07c2]
27  /opt/conda/envs/gdf/bin/python(_PyEval_EvalFrameDefault+0x696) [0x5606349a05c6]
28  /opt/conda/envs/gdf/bin/python(+0x1407c2) [0x5606349b07c2]
29  /opt/conda/envs/gdf/bin/python(_PyEval_EvalFrameDefault+0x696) [0x5606349a05c6]
30  /opt/conda/envs/gdf/bin/python(+0x12f094) [0x56063499f094]
31  /opt/conda/envs/gdf/bin/python(_PyFunction_Vectorcall+0xd9) [0x5606349b0519]
32  /opt/conda/envs/gdf/bin/python(_PyEval_EvalFrameDefault+0x11f8) [0x5606349a1128]
33  /opt/conda/envs/gdf/bin/python(+0x12f094) [0x56063499f094]
34  /opt/conda/envs/gdf/bin/python(+0x14dccb) [0x5606349bdccb]
35  /opt/conda/envs/gdf/bin/python(PyObject_Call+0xbc) [0x5606349be44c]
36  /opt/conda/envs/gdf/bin/python(+0x21110e) [0x560634a8110e]
37  /opt/conda/envs/gdf/bin/python(_PyObject_MakeTpCall+0x2ec) [0x5606349a877c]
38  /opt/conda/envs/gdf/bin/python(_PyEval_EvalFrameDefault+0x37cb) [0x5606349a36fb]
39  /opt/conda/envs/gdf/bin/python(+0x1407c2) [0x5606349b07c2]
40  /opt/conda/envs/gdf/bin/python(+0x14ddac) [0x5606349bddac]
41  /opt/conda/envs/gdf/bin/python(_PyEval_EvalFrameDefault+0x37cb) [0x5606349a36fb]
42  /opt/conda/envs/gdf/bin/python(+0x1407c2) [0x5606349b07c2]
43  /opt/conda/envs/gdf/bin/python(_PyEval_EvalFrameDefault+0x696) [0x5606349a05c6]
44  /opt/conda/envs/gdf/bin/python(+0x12f094) [0x56063499f094]
45  /opt/conda/envs/gdf/bin/python(_PyFunction_Vectorcall+0xd9) [0x5606349b0519]
46  /opt/conda/envs/gdf/bin/python(_PyEval_EvalFrameDefault+0x696) [0x5606349a05c6]
47  /opt/conda/envs/gdf/bin/python(+0x1407c2) [0x5606349b07c2]
48  /opt/conda/envs/gdf/bin/python(_PyEval_EvalFrameDefault+0x3e2) [0x5606349a0312]
49  /opt/conda/envs/gdf/bin/python(+0x12f094) [0x56063499f094]
50  /opt/conda/envs/gdf/bin/python(_PyFunction_Vectorcall+0xd9) [0x5606349b0519]
51  /opt/conda/envs/gdf/bin/python(_PyEval_EvalFrameDefault+0x11f8) [0x5606349a1128]
52  /opt/conda/envs/gdf/bin/python(+0x12f094) [0x56063499f094]
53  /opt/conda/envs/gdf/bin/python(_PyEval_EvalCodeWithName+0x48) [0x56063499ed68]
54  /opt/conda/envs/gdf/bin/python(PyEval_EvalCodeEx+0x39) [0x56063499ed19]
55  /opt/conda/envs/gdf/bin/python(PyEval_EvalCode+0x1b) [0x560634a4c07b]
56  /opt/conda/envs/gdf/bin/python(+0x208fca) [0x560634a78fca]
57  /opt/conda/envs/gdf/bin/python(+0x205353) [0x560634a75353]
58  /opt/conda/envs/gdf/bin/python(PyRun_StringFlags+0x9a) [0x560634a6d16a]
59  /opt/conda/envs/gdf/bin/python(PyRun_SimpleStringFlags+0x3c) [0x560634a6d05c]
60  /opt/conda/envs/gdf/bin/python(Py_RunMain+0x267) [0x560634a6c297]
61  /opt/conda/envs/gdf/bin/python(Py_BytesMain+0x37) [0x560634a3ff07]
=================================
[dgx13:71652:0:71652] Caught signal 11 (Segmentation fault: address not mapped to object at address 0x448)
==== backtrace (tid:  71652) ====
 0  /opt/conda/envs/gdf/lib/libucs.so.0(ucs_handle_error+0x2fd) [0x7f093c17906d]
 1  /opt/conda/envs/gdf/lib/libucs.so.0(+0x2a264) [0x7f093c179264]
 2  /opt/conda/envs/gdf/lib/libucs.so.0(+0x2a42a) [0x7f093c17942a]
 3  /usr/lib/x86_64-linux-gnu/libpthread.so.0(+0x14420) [0x7f09cf169420]
 4  /opt/conda/envs/gdf/lib/libucp.so.0(ucp_mem_type_unpack+0x14) [0x7f093c1f76a4]
 5  /opt/conda/envs/gdf/lib/libucp.so.0(ucp_rndv_data_handler+0x4e9) [0x7f093c220829]
 6  /opt/conda/envs/gdf/lib/./libuct.so.0(+0x2146f) [0x7f093c13346f]
 7  /opt/conda/envs/gdf/lib/./libuct.so.0(+0x248c8) [0x7f093c1368c8]
 8  /opt/conda/envs/gdf/lib/libucs.so.0(ucs_event_set_wait+0xb9) [0x7f093c182499]
 9  /opt/conda/envs/gdf/lib/./libuct.so.0(uct_tcp_iface_progress+0x7d) [0x7f093c13566d]
10  /opt/conda/envs/gdf/lib/libucp.so.0(ucp_worker_progress+0x5a) [0x7f093c1f48ca]
11  /opt/conda/envs/gdf/lib/python3.9/site-packages/ucp/_libs/ucx_api.cpython-39-x86_64-linux-gnu.so(+0x3206a) [0x7f093c2ad06a]
12  /opt/conda/envs/gdf/bin/python(_PyEval_EvalFrameDefault+0x37cb) [0x55936cd016fb]
13  /opt/conda/envs/gdf/bin/python(+0x12f094) [0x55936ccfd094]
14  /opt/conda/envs/gdf/bin/python(_PyFunction_Vectorcall+0xd9) [0x55936cd0e519]
15  /opt/conda/envs/gdf/bin/python(_PyEval_EvalFrameDefault+0x696) [0x55936ccfe5c6]
16  /opt/conda/envs/gdf/bin/python(+0x1407c2) [0x55936cd0e7c2]
17  /opt/conda/envs/gdf/bin/python(+0x14de83) [0x55936cd1be83]
18  /opt/conda/envs/gdf/bin/python(+0x258b2c) [0x55936ce26b2c]
19  /opt/conda/envs/gdf/bin/python(+0xead05) [0x55936ccb8d05]
20  /opt/conda/envs/gdf/bin/python(+0x1377f3) [0x55936cd057f3]
21  /opt/conda/envs/gdf/bin/python(_PyEval_EvalFrameDefault+0x59f9) [0x55936cd03929]
22  /opt/conda/envs/gdf/bin/python(+0x1407c2) [0x55936cd0e7c2]
23  /opt/conda/envs/gdf/bin/python(_PyEval_EvalFrameDefault+0x696) [0x55936ccfe5c6]
24  /opt/conda/envs/gdf/bin/python(+0x1407c2) [0x55936cd0e7c2]
25  /opt/conda/envs/gdf/bin/python(_PyEval_EvalFrameDefault+0x696) [0x55936ccfe5c6]
26  /opt/conda/envs/gdf/bin/python(+0x1407c2) [0x55936cd0e7c2]
27  /opt/conda/envs/gdf/bin/python(_PyEval_EvalFrameDefault+0x696) [0x55936ccfe5c6]
28  /opt/conda/envs/gdf/bin/python(+0x1407c2) [0x55936cd0e7c2]
29  /opt/conda/envs/gdf/bin/python(_PyEval_EvalFrameDefault+0x696) [0x55936ccfe5c6]
30  /opt/conda/envs/gdf/bin/python(+0x12f094) [0x55936ccfd094]
31  /opt/conda/envs/gdf/bin/python(_PyFunction_Vectorcall+0xd9) [0x55936cd0e519]
32  /opt/conda/envs/gdf/bin/python(_PyEval_EvalFrameDefault+0x11f8) [0x55936ccff128]
33  /opt/conda/envs/gdf/bin/python(+0x12f094) [0x55936ccfd094]
34  /opt/conda/envs/gdf/bin/python(+0x14dccb) [0x55936cd1bccb]
35  /opt/conda/envs/gdf/bin/python(PyObject_Call+0xbc) [0x55936cd1c44c]
36  /opt/conda/envs/gdf/bin/python(+0x21110e) [0x55936cddf10e]
37  /opt/conda/envs/gdf/bin/python(_PyObject_MakeTpCall+0x2ec) [0x55936cd0677c]
38  /opt/conda/envs/gdf/bin/python(_PyEval_EvalFrameDefault+0x37cb) [0x55936cd016fb]
39  /opt/conda/envs/gdf/bin/python(+0x1407c2) [0x55936cd0e7c2]
40  /opt/conda/envs/gdf/bin/python(+0x14ddac) [0x55936cd1bdac]
41  /opt/conda/envs/gdf/bin/python(_PyEval_EvalFrameDefault+0x37cb) [0x55936cd016fb]
42  /opt/conda/envs/gdf/bin/python(+0x1407c2) [0x55936cd0e7c2]
43  /opt/conda/envs/gdf/bin/python(_PyEval_EvalFrameDefault+0x696) [0x55936ccfe5c6]
44  /opt/conda/envs/gdf/bin/python(+0x12f094) [0x55936ccfd094]
45  /opt/conda/envs/gdf/bin/python(_PyFunction_Vectorcall+0xd9) [0x55936cd0e519]
46  /opt/conda/envs/gdf/bin/python(_PyEval_EvalFrameDefault+0x696) [0x55936ccfe5c6]
47  /opt/conda/envs/gdf/bin/python(+0x1407c2) [0x55936cd0e7c2]
48  /opt/conda/envs/gdf/bin/python(_PyEval_EvalFrameDefault+0x3e2) [0x55936ccfe312]
49  /opt/conda/envs/gdf/bin/python(+0x12f094) [0x55936ccfd094]
50  /opt/conda/envs/gdf/bin/python(_PyFunction_Vectorcall+0xd9) [0x55936cd0e519]
51  /opt/conda/envs/gdf/bin/python(_PyEval_EvalFrameDefault+0x11f8) [0x55936ccff128]
52  /opt/conda/envs/gdf/bin/python(+0x12f094) [0x55936ccfd094]
53  /opt/conda/envs/gdf/bin/python(_PyEval_EvalCodeWithName+0x48) [0x55936ccfcd68]
54  /opt/conda/envs/gdf/bin/python(PyEval_EvalCodeEx+0x39) [0x55936ccfcd19]
55  /opt/conda/envs/gdf/bin/python(PyEval_EvalCode+0x1b) [0x55936cdaa07b]
56  /opt/conda/envs/gdf/bin/python(+0x208fca) [0x55936cdd6fca]
57  /opt/conda/envs/gdf/bin/python(+0x205353) [0x55936cdd3353]
58  /opt/conda/envs/gdf/bin/python(PyRun_StringFlags+0x9a) [0x55936cdcb16a]
59  /opt/conda/envs/gdf/bin/python(PyRun_SimpleStringFlags+0x3c) [0x55936cdcb05c]
60  /opt/conda/envs/gdf/bin/python(Py_RunMain+0x267) [0x55936cdca297]
61  /opt/conda/envs/gdf/bin/python(Py_BytesMain+0x37) [0x55936cd9df07]
=================================
2023-10-31 06:29:33,795 - distributed.worker - ERROR - Worker stream died during communication: ucx://127.0.0.1:46149
Traceback (most recent call last):
  File "/opt/conda/envs/gdf/lib/python3.9/site-packages/distributed/comm/ucx.py", line 354, in read
    await self.ep.recv(msg)
  File "/opt/conda/envs/gdf/lib/python3.9/site-packages/ucp/core.py", line 725, in recv
    ret = await comm.tag_recv(self._ep, buffer, nbytes, tag, name=log)
ucp._libs.exceptions.UCXCanceled: <[Recv #015] ep: 0x7f64603cc0c0, tag: 0x4f20e328be93b527, nbytes: 16, type: <class 'numpy.ndarray'>>: 

During handling of the above exception, another exception occurred:

Traceback (most recent call last):
  File "/opt/conda/envs/gdf/lib/python3.9/site-packages/distributed/worker.py", line 2059, in gather_dep
    response = await get_data_from_worker(
  File "/opt/conda/envs/gdf/lib/python3.9/site-packages/distributed/worker.py", line 2852, in get_data_from_worker
    response = await send_recv(
  File "/opt/conda/envs/gdf/lib/python3.9/site-packages/distributed/core.py", line 1106, in send_recv
    response = await comm.read(deserializers=deserializers)
  File "/opt/conda/envs/gdf/lib/python3.9/site-packages/distributed/utils.py", line 803, in wrapper
    return await func(*args, **kwargs)
  File "/opt/conda/envs/gdf/lib/python3.9/site-packages/distributed/comm/ucx.py", line 372, in read
    raise CommClosedError(
distributed.comm.core.CommClosedError: Connection closed by writer.
Inner exception: UCXCanceled("<[Recv #015] ep: 0x7f64603cc0c0, tag: 0x4f20e328be93b527, nbytes: 16, type: <class 'numpy.ndarray'>>: ")
2023-10-31 06:29:33,795 - distributed.worker - ERROR - failed during get data with ucx://127.0.0.1:56709 -> ucx://127.0.0.1:46149
Traceback (most recent call last):
  File "/opt/conda/envs/gdf/lib/python3.9/site-packages/distributed/comm/ucx.py", line 338, in write
    await self.ep.send(each_frame)
  File "/opt/conda/envs/gdf/lib/python3.9/site-packages/ucp/core.py", line 650, in send
    return await comm.tag_send(self._ep, buffer, nbytes, tag, name=log)
ucp._libs.exceptions.UCXError: <[Send #007] ep: 0x7f2c1818c3c0, tag: 0xa9b512971d5d07e2, nbytes: 50000000, type: <class 'cupy.ndarray'>>: Connection reset by remote peer

During handling of the above exception, another exception occurred:

Traceback (most recent call last):
  File "/opt/conda/envs/gdf/lib/python3.9/site-packages/distributed/worker.py", line 1782, in get_data
    compressed = await comm.write(msg, serializers=serializers)
  File "/opt/conda/envs/gdf/lib/python3.9/site-packages/distributed/utils.py", line 803, in wrapper
    return await func(*args, **kwargs)
  File "/opt/conda/envs/gdf/lib/python3.9/site-packages/distributed/comm/ucx.py", line 342, in write
    raise CommClosedError("While writing, the connection was closed")
distributed.comm.core.CommClosedError: While writing, the connection was closed
2023-10-31 06:29:33,800 - distributed.worker - ERROR - failed during get data with ucx://127.0.0.1:36759 -> ucx://127.0.0.1:37765
Traceback (most recent call last):
  File "/opt/conda/envs/gdf/lib/python3.9/site-packages/distributed/comm/ucx.py", line 338, in write
    await self.ep.send(each_frame)
  File "/opt/conda/envs/gdf/lib/python3.9/site-packages/ucp/core.py", line 650, in send
    return await comm.tag_send(self._ep, buffer, nbytes, tag, name=log)
ucp._libs.exceptions.UCXError: <[Send #007] ep: 0x7f64603cc240, tag: 0xf1f78c2c540f8ccb, nbytes: 50000000, type: <class 'cupy.ndarray'>>: Connection reset by remote peer

During handling of the above exception, another exception occurred:

Traceback (most recent call last):
  File "/opt/conda/envs/gdf/lib/python3.9/site-packages/distributed/worker.py", line 1782, in get_data
    compressed = await comm.write(msg, serializers=serializers)
  File "/opt/conda/envs/gdf/lib/python3.9/site-packages/distributed/utils.py", line 803, in wrapper
    return await func(*args, **kwargs)
  File "/opt/conda/envs/gdf/lib/python3.9/site-packages/distributed/comm/ucx.py", line 342, in write
    raise CommClosedError("While writing, the connection was closed")
distributed.comm.core.CommClosedError: While writing, the connection was closed
2023-10-31 06:29:33,800 - distributed.worker - ERROR - Worker stream died during communication: ucx://127.0.0.1:46149
Traceback (most recent call last):
  File "/opt/conda/envs/gdf/lib/python3.9/site-packages/distributed/core.py", line 1516, in _connect
    comm = await connect(
  File "/opt/conda/envs/gdf/lib/python3.9/site-packages/distributed/comm/core.py", line 342, in connect
    comm = await wait_for(
  File "/opt/conda/envs/gdf/lib/python3.9/site-packages/distributed/utils.py", line 1920, in wait_for
    return await asyncio.wait_for(fut, timeout)
  File "/opt/conda/envs/gdf/lib/python3.9/asyncio/tasks.py", line 466, in wait_for
    await waiter
asyncio.exceptions.CancelledError

During handling of the above exception, another exception occurred:

Traceback (most recent call last):
  File "/opt/conda/envs/gdf/lib/python3.9/site-packages/distributed/core.py", line 1626, in connect
    return connect_attempt.result()
asyncio.exceptions.CancelledError

During handling of the above exception, another exception occurred:

Traceback (most recent call last):
  File "/opt/conda/envs/gdf/lib/python3.9/site-packages/distributed/worker.py", line 2059, in gather_dep
    response = await get_data_from_worker(
  File "/opt/conda/envs/gdf/lib/python3.9/site-packages/distributed/worker.py", line 2849, in get_data_from_worker
    comm = await rpc.connect(worker)
  File "/opt/conda/envs/gdf/lib/python3.9/site-packages/distributed/core.py", line 1628, in connect
    raise CommClosedError(reason)
distributed.comm.core.CommClosedError: Address removed.
2023-10-31 06:29:36,521 - distributed.nanny - WARNING - Restarting worker
2023-10-31 06:29:36,580 - distributed.nanny - WARNING - Restarting worker
/opt/conda/envs/gdf/lib/python3.9/multiprocessing/resource_tracker.py:216: UserWarning: resource_tracker: There appear to be 42 leaked semaphore objects to clean up at shutdown
  warnings.warn('resource_tracker: There appear to be %d '
