2023-08-11 06:19:42,390 - distributed.preloading - INFO - Creating preload: dask_cuda.initialize
2023-08-11 06:19:42,390 - distributed.preloading - INFO - Import preload module: dask_cuda.initialize
2023-08-11 06:19:42,501 - distributed.preloading - INFO - Creating preload: dask_cuda.initialize
2023-08-11 06:19:42,501 - distributed.preloading - INFO - Import preload module: dask_cuda.initialize
2023-08-11 06:19:42,533 - distributed.preloading - INFO - Creating preload: dask_cuda.initialize
2023-08-11 06:19:42,533 - distributed.preloading - INFO - Import preload module: dask_cuda.initialize
2023-08-11 06:19:42,556 - distributed.preloading - INFO - Creating preload: dask_cuda.initialize
2023-08-11 06:19:42,556 - distributed.preloading - INFO - Import preload module: dask_cuda.initialize
2023-08-11 06:19:42,556 - distributed.preloading - INFO - Creating preload: dask_cuda.initialize
2023-08-11 06:19:42,557 - distributed.preloading - INFO - Import preload module: dask_cuda.initialize
2023-08-11 06:19:42,567 - distributed.preloading - INFO - Creating preload: dask_cuda.initialize
2023-08-11 06:19:42,567 - distributed.preloading - INFO - Import preload module: dask_cuda.initialize
2023-08-11 06:19:42,568 - distributed.preloading - INFO - Creating preload: dask_cuda.initialize
2023-08-11 06:19:42,568 - distributed.preloading - INFO - Import preload module: dask_cuda.initialize
2023-08-11 06:19:42,576 - distributed.preloading - INFO - Creating preload: dask_cuda.initialize
2023-08-11 06:19:42,576 - distributed.preloading - INFO - Import preload module: dask_cuda.initialize
[dgx13:70758:0:70758] Caught signal 11 (Segmentation fault: address not mapped to object at address 0x448)
==== backtrace (tid:  70758) ====
 0  /opt/conda/envs/gdf/lib/libucs.so.0(ucs_handle_error+0x2fd) [0x7f2f246e7f1d]
 1  /opt/conda/envs/gdf/lib/libucs.so.0(+0x29114) [0x7f2f246e8114]
 2  /opt/conda/envs/gdf/lib/libucs.so.0(+0x292da) [0x7f2f246e82da]
 3  /usr/lib/x86_64-linux-gnu/libpthread.so.0(+0x14420) [0x7f2fb5dd4420]
 4  /opt/conda/envs/gdf/lib/libucp.so.0(ucp_mem_type_unpack+0x14) [0x7f2f247615d4]
 5  /opt/conda/envs/gdf/lib/libucp.so.0(ucp_rndv_data_handler+0x4e9) [0x7f2f24786859]
 6  /opt/conda/envs/gdf/lib/libuct.so.0(+0x2042f) [0x7f2f246a342f]
 7  /opt/conda/envs/gdf/lib/libuct.so.0(+0x23798) [0x7f2f246a6798]
 8  /opt/conda/envs/gdf/lib/libucs.so.0(ucs_event_set_wait+0xb9) [0x7f2f246f0989]
 9  /opt/conda/envs/gdf/lib/libuct.so.0(uct_tcp_iface_progress+0x7d) [0x7f2f246a562d]
10  /opt/conda/envs/gdf/lib/libucp.so.0(ucp_worker_progress+0x5a) [0x7f2f2475ec4a]
11  /opt/conda/envs/gdf/lib/python3.9/site-packages/ucp/_libs/ucx_api.cpython-39-x86_64-linux-gnu.so(+0x2b17a) [0x7f2f2480917a]
12  /opt/conda/envs/gdf/bin/python(+0x14420c) [0x5619ee7d720c]
13  /opt/conda/envs/gdf/bin/python(_PyEval_EvalFrameDefault+0x5dc5) [0x5619ee7c7bf5]
14  /opt/conda/envs/gdf/bin/python(+0x12df94) [0x5619ee7c0f94]
15  /opt/conda/envs/gdf/bin/python(_PyFunction_Vectorcall+0xd9) [0x5619ee7d23f9]
16  /opt/conda/envs/gdf/bin/python(_PyEval_EvalFrameDefault+0x696) [0x5619ee7c24c6]
17  /opt/conda/envs/gdf/bin/python(+0x13f6a2) [0x5619ee7d26a2]
18  /opt/conda/envs/gdf/bin/python(+0x14ca43) [0x5619ee7dfa43]
19  /opt/conda/envs/gdf/bin/python(+0x2580fc) [0x5619ee8eb0fc]
20  /opt/conda/envs/gdf/bin/python(+0xf248b) [0x5619ee78548b]
21  /opt/conda/envs/gdf/bin/python(+0x1366f3) [0x5619ee7c96f3]
22  /opt/conda/envs/gdf/bin/python(_PyEval_EvalFrameDefault+0x58b4) [0x5619ee7c76e4]
23  /opt/conda/envs/gdf/bin/python(+0x13f6a2) [0x5619ee7d26a2]
24  /opt/conda/envs/gdf/bin/python(_PyEval_EvalFrameDefault+0x696) [0x5619ee7c24c6]
25  /opt/conda/envs/gdf/bin/python(+0x13f6a2) [0x5619ee7d26a2]
26  /opt/conda/envs/gdf/bin/python(_PyEval_EvalFrameDefault+0x696) [0x5619ee7c24c6]
27  /opt/conda/envs/gdf/bin/python(+0x13f6a2) [0x5619ee7d26a2]
28  /opt/conda/envs/gdf/bin/python(_PyEval_EvalFrameDefault+0x696) [0x5619ee7c24c6]
29  /opt/conda/envs/gdf/bin/python(+0x13f6a2) [0x5619ee7d26a2]
30  /opt/conda/envs/gdf/bin/python(_PyEval_EvalFrameDefault+0x696) [0x5619ee7c24c6]
31  /opt/conda/envs/gdf/bin/python(+0x12df94) [0x5619ee7c0f94]
32  /opt/conda/envs/gdf/bin/python(_PyFunction_Vectorcall+0xd9) [0x5619ee7d23f9]
33  /opt/conda/envs/gdf/bin/python(_PyEval_EvalFrameDefault+0x4abe) [0x5619ee7c68ee]
34  /opt/conda/envs/gdf/bin/python(+0x12df94) [0x5619ee7c0f94]
35  /opt/conda/envs/gdf/bin/python(+0x14c88b) [0x5619ee7df88b]
36  /opt/conda/envs/gdf/bin/python(PyObject_Call+0xbc) [0x5619ee7e000c]
37  /opt/conda/envs/gdf/bin/python(+0x21073e) [0x5619ee8a373e]
38  /opt/conda/envs/gdf/bin/python(_PyObject_MakeTpCall+0x2ec) [0x5619ee7ca67c]
39  /opt/conda/envs/gdf/bin/python(_PyEval_EvalFrameDefault+0x45a6) [0x5619ee7c63d6]
40  /opt/conda/envs/gdf/bin/python(+0x13f6a2) [0x5619ee7d26a2]
41  /opt/conda/envs/gdf/bin/python(+0x14c96c) [0x5619ee7df96c]
42  /opt/conda/envs/gdf/bin/python(_PyEval_EvalFrameDefault+0x45a6) [0x5619ee7c63d6]
43  /opt/conda/envs/gdf/bin/python(+0x13f6a2) [0x5619ee7d26a2]
44  /opt/conda/envs/gdf/bin/python(_PyEval_EvalFrameDefault+0x696) [0x5619ee7c24c6]
45  /opt/conda/envs/gdf/bin/python(+0x12df94) [0x5619ee7c0f94]
46  /opt/conda/envs/gdf/bin/python(_PyFunction_Vectorcall+0xd9) [0x5619ee7d23f9]
47  /opt/conda/envs/gdf/bin/python(_PyEval_EvalFrameDefault+0x696) [0x5619ee7c24c6]
48  /opt/conda/envs/gdf/bin/python(+0x13f6a2) [0x5619ee7d26a2]
49  /opt/conda/envs/gdf/bin/python(_PyEval_EvalFrameDefault+0x3e2) [0x5619ee7c2212]
50  /opt/conda/envs/gdf/bin/python(+0x12df94) [0x5619ee7c0f94]
51  /opt/conda/envs/gdf/bin/python(_PyFunction_Vectorcall+0xd9) [0x5619ee7d23f9]
52  /opt/conda/envs/gdf/bin/python(_PyEval_EvalFrameDefault+0x11f2) [0x5619ee7c3022]
53  /opt/conda/envs/gdf/bin/python(+0x12df94) [0x5619ee7c0f94]
54  /opt/conda/envs/gdf/bin/python(_PyEval_EvalCodeWithName+0x48) [0x5619ee7c0c68]
55  /opt/conda/envs/gdf/bin/python(PyEval_EvalCodeEx+0x39) [0x5619ee7c0c19]
56  /opt/conda/envs/gdf/bin/python(PyEval_EvalCode+0x1b) [0x5619ee86e20b]
57  /opt/conda/envs/gdf/bin/python(+0x2085fa) [0x5619ee89b5fa]
58  /opt/conda/envs/gdf/bin/python(+0x204983) [0x5619ee897983]
59  /opt/conda/envs/gdf/bin/python(PyRun_StringFlags+0x9a) [0x5619ee88f79a]
60  /opt/conda/envs/gdf/bin/python(PyRun_SimpleStringFlags+0x3c) [0x5619ee88f68c]
61  /opt/conda/envs/gdf/bin/python(Py_RunMain+0x267) [0x5619ee88e8c7]
=================================
[dgx13:70767:0:70767] Caught signal 11 (Segmentation fault: address not mapped to object at address 0x448)
==== backtrace (tid:  70767) ====
 0  /opt/conda/envs/gdf/lib/libucs.so.0(ucs_handle_error+0x2fd) [0x7f91458f4f1d]
 1  /opt/conda/envs/gdf/lib/libucs.so.0(+0x29114) [0x7f91458f5114]
 2  /opt/conda/envs/gdf/lib/libucs.so.0(+0x292da) [0x7f91458f52da]
 3  /usr/lib/x86_64-linux-gnu/libpthread.so.0(+0x14420) [0x7f91ff15b420]
 4  /opt/conda/envs/gdf/lib/libucp.so.0(ucp_mem_type_unpack+0x14) [0x7f914596e5d4]
 5  /opt/conda/envs/gdf/lib/libucp.so.0(ucp_rndv_data_handler+0x4e9) [0x7f9145993859]
 6  /opt/conda/envs/gdf/lib/libuct.so.0(+0x2042f) [0x7f91458b042f]
 7  /opt/conda/envs/gdf/lib/libuct.so.0(+0x23798) [0x7f91458b3798]
 8  /opt/conda/envs/gdf/lib/libucs.so.0(ucs_event_set_wait+0xb9) [0x7f91458fd989]
 9  /opt/conda/envs/gdf/lib/libuct.so.0(uct_tcp_iface_progress+0x7d) [0x7f91458b262d]
10  /opt/conda/envs/gdf/lib/libucp.so.0(ucp_worker_progress+0x5a) [0x7f914596bc4a]
11  /opt/conda/envs/gdf/lib/python3.9/site-packages/ucp/_libs/ucx_api.cpython-39-x86_64-linux-gnu.so(+0x2b17a) [0x7f9145a1617a]
12  /opt/conda/envs/gdf/bin/python(+0x14420c) [0x55947234120c]
13  /opt/conda/envs/gdf/bin/python(_PyEval_EvalFrameDefault+0x5dc5) [0x559472331bf5]
14  /opt/conda/envs/gdf/bin/python(+0x12df94) [0x55947232af94]
15  /opt/conda/envs/gdf/bin/python(_PyFunction_Vectorcall+0xd9) [0x55947233c3f9]
16  /opt/conda/envs/gdf/bin/python(_PyEval_EvalFrameDefault+0x696) [0x55947232c4c6]
17  /opt/conda/envs/gdf/bin/python(+0x1e2612) [0x5594723df612]
18  /opt/conda/envs/gdf/lib/python3.9/lib-dynload/_asyncio.cpython-39-x86_64-linux-gnu.so(+0x81e9) [0x7f917fcaf1e9]
19  /opt/conda/envs/gdf/bin/python(_PyObject_MakeTpCall+0x2ec) [0x55947233467c]
20  /opt/conda/envs/gdf/bin/python(+0xf248b) [0x5594722ef48b]
21  /opt/conda/envs/gdf/bin/python(+0x1366f3) [0x5594723336f3]
22  /opt/conda/envs/gdf/bin/python(_PyEval_EvalFrameDefault+0x58b4) [0x5594723316e4]
23  /opt/conda/envs/gdf/bin/python(+0x13f6a2) [0x55947233c6a2]
24  /opt/conda/envs/gdf/bin/python(_PyEval_EvalFrameDefault+0x696) [0x55947232c4c6]
25  /opt/conda/envs/gdf/bin/python(+0x13f6a2) [0x55947233c6a2]
26  /opt/conda/envs/gdf/bin/python(_PyEval_EvalFrameDefault+0x696) [0x55947232c4c6]
27  /opt/conda/envs/gdf/bin/python(+0x13f6a2) [0x55947233c6a2]
28  /opt/conda/envs/gdf/bin/python(_PyEval_EvalFrameDefault+0x696) [0x55947232c4c6]
29  /opt/conda/envs/gdf/bin/python(+0x13f6a2) [0x55947233c6a2]
30  /opt/conda/envs/gdf/bin/python(_PyEval_EvalFrameDefault+0x696) [0x55947232c4c6]
31  /opt/conda/envs/gdf/bin/python(+0x12df94) [0x55947232af94]
32  /opt/conda/envs/gdf/bin/python(_PyFunction_Vectorcall+0xd9) [0x55947233c3f9]
33  /opt/conda/envs/gdf/bin/python(_PyEval_EvalFrameDefault+0x4abe) [0x5594723308ee]
34  /opt/conda/envs/gdf/bin/python(+0x12df94) [0x55947232af94]
35  /opt/conda/envs/gdf/bin/python(+0x14c88b) [0x55947234988b]
36  /opt/conda/envs/gdf/bin/python(PyObject_Call+0xbc) [0x55947234a00c]
37  /opt/conda/envs/gdf/bin/python(+0x21073e) [0x55947240d73e]
38  /opt/conda/envs/gdf/bin/python(_PyObject_MakeTpCall+0x2ec) [0x55947233467c]
39  /opt/conda/envs/gdf/bin/python(_PyEval_EvalFrameDefault+0x45a6) [0x5594723303d6]
40  /opt/conda/envs/gdf/bin/python(+0x13f6a2) [0x55947233c6a2]
41  /opt/conda/envs/gdf/bin/python(+0x14c96c) [0x55947234996c]
42  /opt/conda/envs/gdf/bin/python(_PyEval_EvalFrameDefault+0x45a6) [0x5594723303d6]
43  /opt/conda/envs/gdf/bin/python(+0x13f6a2) [0x55947233c6a2]
44  /opt/conda/envs/gdf/bin/python(_PyEval_EvalFrameDefault+0x696) [0x55947232c4c6]
45  /opt/conda/envs/gdf/bin/python(+0x12df94) [0x55947232af94]
46  /opt/conda/envs/gdf/bin/python(_PyFunction_Vectorcall+0xd9) [0x55947233c3f9]
47  /opt/conda/envs/gdf/bin/python(_PyEval_EvalFrameDefault+0x696) [0x55947232c4c6]
48  /opt/conda/envs/gdf/bin/python(+0x13f6a2) [0x55947233c6a2]
49  /opt/conda/envs/gdf/bin/python(_PyEval_EvalFrameDefault+0x3e2) [0x55947232c212]
50  /opt/conda/envs/gdf/bin/python(+0x12df94) [0x55947232af94]
51  /opt/conda/envs/gdf/bin/python(_PyFunction_Vectorcall+0xd9) [0x55947233c3f9]
52  /opt/conda/envs/gdf/bin/python(_PyEval_EvalFrameDefault+0x11f2) [0x55947232d022]
53  /opt/conda/envs/gdf/bin/python(+0x12df94) [0x55947232af94]
54  /opt/conda/envs/gdf/bin/python(_PyEval_EvalCodeWithName+0x48) [0x55947232ac68]
55  /opt/conda/envs/gdf/bin/python(PyEval_EvalCodeEx+0x39) [0x55947232ac19]
56  /opt/conda/envs/gdf/bin/python(PyEval_EvalCode+0x1b) [0x5594723d820b]
57  /opt/conda/envs/gdf/bin/python(+0x2085fa) [0x5594724055fa]
58  /opt/conda/envs/gdf/bin/python(+0x204983) [0x559472401983]
59  /opt/conda/envs/gdf/bin/python(PyRun_StringFlags+0x9a) [0x5594723f979a]
60  /opt/conda/envs/gdf/bin/python(PyRun_SimpleStringFlags+0x3c) [0x5594723f968c]
61  /opt/conda/envs/gdf/bin/python(Py_RunMain+0x267) [0x5594723f88c7]
=================================
[dgx13:70743:0:70743] Caught signal 11 (Segmentation fault: address not mapped to object at address 0x448)
==== backtrace (tid:  70743) ====
 0  /opt/conda/envs/gdf/lib/libucs.so.0(ucs_handle_error+0x2fd) [0x7f3cf4c16f1d]
 1  /opt/conda/envs/gdf/lib/libucs.so.0(+0x29114) [0x7f3cf4c17114]
 2  /opt/conda/envs/gdf/lib/libucs.so.0(+0x292da) [0x7f3cf4c172da]
 3  /usr/lib/x86_64-linux-gnu/libpthread.so.0(+0x14420) [0x7f3d94489420]
 4  /opt/conda/envs/gdf/lib/libucp.so.0(ucp_mem_type_unpack+0x14) [0x7f3cf4c905d4]
 5  /opt/conda/envs/gdf/lib/libucp.so.0(ucp_rndv_data_handler+0x4e9) [0x7f3cf4cb5859]
 6  /opt/conda/envs/gdf/lib/libuct.so.0(+0x2042f) [0x7f3cf4bd242f]
 7  /opt/conda/envs/gdf/lib/libuct.so.0(+0x23798) [0x7f3cf4bd5798]
 8  /opt/conda/envs/gdf/lib/libucs.so.0(ucs_event_set_wait+0xb9) [0x7f3cf4c1f989]
 9  /opt/conda/envs/gdf/lib/libuct.so.0(uct_tcp_iface_progress+0x7d) [0x7f3cf4bd462d]
10  /opt/conda/envs/gdf/lib/libucp.so.0(ucp_worker_progress+0x5a) [0x7f3cf4c8dc4a]
11  /opt/conda/envs/gdf/lib/python3.9/site-packages/ucp/_libs/ucx_api.cpython-39-x86_64-linux-gnu.so(+0x2b17a) [0x7f3cf4d3817a]
12  /opt/conda/envs/gdf/bin/python(+0x14420c) [0x55d88f92320c]
13  /opt/conda/envs/gdf/bin/python(_PyEval_EvalFrameDefault+0x5dc5) [0x55d88f913bf5]
14  /opt/conda/envs/gdf/bin/python(+0x12df94) [0x55d88f90cf94]
15  /opt/conda/envs/gdf/bin/python(_PyFunction_Vectorcall+0xd9) [0x55d88f91e3f9]
16  /opt/conda/envs/gdf/bin/python(_PyEval_EvalFrameDefault+0x696) [0x55d88f90e4c6]
17  /opt/conda/envs/gdf/bin/python(+0x13f6a2) [0x55d88f91e6a2]
18  /opt/conda/envs/gdf/bin/python(+0x14ca43) [0x55d88f92ba43]
19  /opt/conda/envs/gdf/bin/python(+0x2580fc) [0x55d88fa370fc]
20  /opt/conda/envs/gdf/bin/python(+0xf248b) [0x55d88f8d148b]
21  /opt/conda/envs/gdf/bin/python(+0x1366f3) [0x55d88f9156f3]
22  /opt/conda/envs/gdf/bin/python(_PyEval_EvalFrameDefault+0x58b4) [0x55d88f9136e4]
23  /opt/conda/envs/gdf/bin/python(+0x13f6a2) [0x55d88f91e6a2]
24  /opt/conda/envs/gdf/bin/python(_PyEval_EvalFrameDefault+0x696) [0x55d88f90e4c6]
25  /opt/conda/envs/gdf/bin/python(+0x13f6a2) [0x55d88f91e6a2]
26  /opt/conda/envs/gdf/bin/python(_PyEval_EvalFrameDefault+0x696) [0x55d88f90e4c6]
27  /opt/conda/envs/gdf/bin/python(+0x13f6a2) [0x55d88f91e6a2]
28  /opt/conda/envs/gdf/bin/python(_PyEval_EvalFrameDefault+0x696) [0x55d88f90e4c6]
29  /opt/conda/envs/gdf/bin/python(+0x13f6a2) [0x55d88f91e6a2]
30  /opt/conda/envs/gdf/bin/python(_PyEval_EvalFrameDefault+0x696) [0x55d88f90e4c6]
31  /opt/conda/envs/gdf/bin/python(+0x12df94) [0x55d88f90cf94]
32  /opt/conda/envs/gdf/bin/python(_PyFunction_Vectorcall+0xd9) [0x55d88f91e3f9]
33  /opt/conda/envs/gdf/bin/python(_PyEval_EvalFrameDefault+0x4abe) [0x55d88f9128ee]
34  /opt/conda/envs/gdf/bin/python(+0x12df94) [0x55d88f90cf94]
35  /opt/conda/envs/gdf/bin/python(+0x14c88b) [0x55d88f92b88b]
36  /opt/conda/envs/gdf/bin/python(PyObject_Call+0xbc) [0x55d88f92c00c]
37  /opt/conda/envs/gdf/bin/python(+0x21073e) [0x55d88f9ef73e]
38  /opt/conda/envs/gdf/bin/python(_PyObject_MakeTpCall+0x2ec) [0x55d88f91667c]
39  /opt/conda/envs/gdf/bin/python(_PyEval_EvalFrameDefault+0x45a6) [0x55d88f9123d6]
40  /opt/conda/envs/gdf/bin/python(+0x13f6a2) [0x55d88f91e6a2]
41  /opt/conda/envs/gdf/bin/python(+0x14c96c) [0x55d88f92b96c]
42  /opt/conda/envs/gdf/bin/python(_PyEval_EvalFrameDefault+0x45a6) [0x55d88f9123d6]
43  /opt/conda/envs/gdf/bin/python(+0x13f6a2) [0x55d88f91e6a2]
44  /opt/conda/envs/gdf/bin/python(_PyEval_EvalFrameDefault+0x696) [0x55d88f90e4c6]
45  /opt/conda/envs/gdf/bin/python(+0x12df94) [0x55d88f90cf94]
46  /opt/conda/envs/gdf/bin/python(_PyFunction_Vectorcall+0xd9) [0x55d88f91e3f9]
47  /opt/conda/envs/gdf/bin/python(_PyEval_EvalFrameDefault+0x696) [0x55d88f90e4c6]
48  /opt/conda/envs/gdf/bin/python(+0x13f6a2) [0x55d88f91e6a2]
49  /opt/conda/envs/gdf/bin/python(_PyEval_EvalFrameDefault+0x3e2) [0x55d88f90e212]
50  /opt/conda/envs/gdf/bin/python(+0x12df94) [0x55d88f90cf94]
51  /opt/conda/envs/gdf/bin/python(_PyFunction_Vectorcall+0xd9) [0x55d88f91e3f9]
52  /opt/conda/envs/gdf/bin/python(_PyEval_EvalFrameDefault+0x11f2) [0x55d88f90f022]
53  /opt/conda/envs/gdf/bin/python(+0x12df94) [0x55d88f90cf94]
54  /opt/conda/envs/gdf/bin/python(_PyEval_EvalCodeWithName+0x48) [0x55d88f90cc68]
55  /opt/conda/envs/gdf/bin/python(PyEval_EvalCodeEx+0x39) [0x55d88f90cc19]
56  /opt/conda/envs/gdf/bin/python(PyEval_EvalCode+0x1b) [0x55d88f9ba20b]
57  /opt/conda/envs/gdf/bin/python(+0x2085fa) [0x55d88f9e75fa]
58  /opt/conda/envs/gdf/bin/python(+0x204983) [0x55d88f9e3983]
59  /opt/conda/envs/gdf/bin/python(PyRun_StringFlags+0x9a) [0x55d88f9db79a]
60  /opt/conda/envs/gdf/bin/python(PyRun_SimpleStringFlags+0x3c) [0x55d88f9db68c]
61  /opt/conda/envs/gdf/bin/python(Py_RunMain+0x267) [0x55d88f9da8c7]
=================================
[dgx13:70748:0:70748] Caught signal 11 (Segmentation fault: address not mapped to object at address 0x448)
==== backtrace (tid:  70748) ====
 0  /opt/conda/envs/gdf/lib/libucs.so.0(ucs_handle_error+0x2fd) [0x7f8d332ecf1d]
 1  /opt/conda/envs/gdf/lib/libucs.so.0(+0x29114) [0x7f8d332ed114]
 2  /opt/conda/envs/gdf/lib/libucs.so.0(+0x292da) [0x7f8d332ed2da]
 3  /usr/lib/x86_64-linux-gnu/libpthread.so.0(+0x14420) [0x7f8dd2b6a420]
 4  /opt/conda/envs/gdf/lib/libucp.so.0(ucp_mem_type_unpack+0x14) [0x7f8d333665d4]
 5  /opt/conda/envs/gdf/lib/libucp.so.0(ucp_rndv_data_handler+0x4e9) [0x7f8d3338b859]
 6  /opt/conda/envs/gdf/lib/libuct.so.0(+0x2042f) [0x7f8d332a842f]
 7  /opt/conda/envs/gdf/lib/libuct.so.0(+0x23798) [0x7f8d332ab798]
 8  /opt/conda/envs/gdf/lib/libucs.so.0(ucs_event_set_wait+0xb9) [0x7f8d332f5989]
 9  /opt/conda/envs/gdf/lib/libuct.so.0(uct_tcp_iface_progress+0x7d) [0x7f8d332aa62d]
10  /opt/conda/envs/gdf/lib/libucp.so.0(ucp_worker_progress+0x5a) [0x7f8d33363c4a]
11  /opt/conda/envs/gdf/lib/python3.9/site-packages/ucp/_libs/ucx_api.cpython-39-x86_64-linux-gnu.so(+0x2b17a) [0x7f8d3340e17a]
12  /opt/conda/envs/gdf/bin/python(+0x14420c) [0x561736b3420c]
13  /opt/conda/envs/gdf/bin/python(_PyEval_EvalFrameDefault+0x5dc5) [0x561736b24bf5]
14  /opt/conda/envs/gdf/bin/python(+0x12df94) [0x561736b1df94]
15  /opt/conda/envs/gdf/bin/python(_PyFunction_Vectorcall+0xd9) [0x561736b2f3f9]
16  /opt/conda/envs/gdf/bin/python(_PyEval_EvalFrameDefault+0x696) [0x561736b1f4c6]
17  /opt/conda/envs/gdf/bin/python(+0x13f6a2) [0x561736b2f6a2]
18  /opt/conda/envs/gdf/bin/python(+0x14ca43) [0x561736b3ca43]
19  /opt/conda/envs/gdf/bin/python(+0x2580fc) [0x561736c480fc]
20  /opt/conda/envs/gdf/bin/python(+0xf248b) [0x561736ae248b]
21  /opt/conda/envs/gdf/bin/python(+0x1366f3) [0x561736b266f3]
22  /opt/conda/envs/gdf/bin/python(_PyEval_EvalFrameDefault+0x58b4) [0x561736b246e4]
23  /opt/conda/envs/gdf/bin/python(+0x13f6a2) [0x561736b2f6a2]
24  /opt/conda/envs/gdf/bin/python(_PyEval_EvalFrameDefault+0x696) [0x561736b1f4c6]
25  /opt/conda/envs/gdf/bin/python(+0x13f6a2) [0x561736b2f6a2]
26  /opt/conda/envs/gdf/bin/python(_PyEval_EvalFrameDefault+0x696) [0x561736b1f4c6]
27  /opt/conda/envs/gdf/bin/python(+0x13f6a2) [0x561736b2f6a2]
28  /opt/conda/envs/gdf/bin/python(_PyEval_EvalFrameDefault+0x696) [0x561736b1f4c6]
29  /opt/conda/envs/gdf/bin/python(+0x13f6a2) [0x561736b2f6a2]
30  /opt/conda/envs/gdf/bin/python(_PyEval_EvalFrameDefault+0x696) [0x561736b1f4c6]
31  /opt/conda/envs/gdf/bin/python(+0x12df94) [0x561736b1df94]
32  /opt/conda/envs/gdf/bin/python(_PyFunction_Vectorcall+0xd9) [0x561736b2f3f9]
33  /opt/conda/envs/gdf/bin/python(_PyEval_EvalFrameDefault+0x4abe) [0x561736b238ee]
34  /opt/conda/envs/gdf/bin/python(+0x12df94) [0x561736b1df94]
35  /opt/conda/envs/gdf/bin/python(+0x14c88b) [0x561736b3c88b]
36  /opt/conda/envs/gdf/bin/python(PyObject_Call+0xbc) [0x561736b3d00c]
37  /opt/conda/envs/gdf/bin/python(+0x21073e) [0x561736c0073e]
38  /opt/conda/envs/gdf/bin/python(_PyObject_MakeTpCall+0x2ec) [0x561736b2767c]
39  /opt/conda/envs/gdf/bin/python(_PyEval_EvalFrameDefault+0x45a6) [0x561736b233d6]
40  /opt/conda/envs/gdf/bin/python(+0x13f6a2) [0x561736b2f6a2]
41  /opt/conda/envs/gdf/bin/python(+0x14c96c) [0x561736b3c96c]
42  /opt/conda/envs/gdf/bin/python(_PyEval_EvalFrameDefault+0x45a6) [0x561736b233d6]
43  /opt/conda/envs/gdf/bin/python(+0x13f6a2) [0x561736b2f6a2]
44  /opt/conda/envs/gdf/bin/python(_PyEval_EvalFrameDefault+0x696) [0x561736b1f4c6]
45  /opt/conda/envs/gdf/bin/python(+0x12df94) [0x561736b1df94]
46  /opt/conda/envs/gdf/bin/python(_PyFunction_Vectorcall+0xd9) [0x561736b2f3f9]
47  /opt/conda/envs/gdf/bin/python(_PyEval_EvalFrameDefault+0x696) [0x561736b1f4c6]
48  /opt/conda/envs/gdf/bin/python(+0x13f6a2) [0x561736b2f6a2]
49  /opt/conda/envs/gdf/bin/python(_PyEval_EvalFrameDefault+0x3e2) [0x561736b1f212]
50  /opt/conda/envs/gdf/bin/python(+0x12df94) [0x561736b1df94]
51  /opt/conda/envs/gdf/bin/python(_PyFunction_Vectorcall+0xd9) [0x561736b2f3f9]
52  /opt/conda/envs/gdf/bin/python(_PyEval_EvalFrameDefault+0x11f2) [0x561736b20022]
53  /opt/conda/envs/gdf/bin/python(+0x12df94) [0x561736b1df94]
54  /opt/conda/envs/gdf/bin/python(_PyEval_EvalCodeWithName+0x48) [0x561736b1dc68]
55  /opt/conda/envs/gdf/bin/python(PyEval_EvalCodeEx+0x39) [0x561736b1dc19]
56  /opt/conda/envs/gdf/bin/python(PyEval_EvalCode+0x1b) [0x561736bcb20b]
57  /opt/conda/envs/gdf/bin/python(+0x2085fa) [0x561736bf85fa]
58  /opt/conda/envs/gdf/bin/python(+0x204983) [0x561736bf4983]
59  /opt/conda/envs/gdf/bin/python(PyRun_StringFlags+0x9a) [0x561736bec79a]
60  /opt/conda/envs/gdf/bin/python(PyRun_SimpleStringFlags+0x3c) [0x561736bec68c]
61  /opt/conda/envs/gdf/bin/python(Py_RunMain+0x267) [0x561736beb8c7]
=================================
[dgx13:70756:0:70756] Caught signal 11 (Segmentation fault: address not mapped to object at address 0x448)
==== backtrace (tid:  70756) ====
 0  /opt/conda/envs/gdf/lib/libucs.so.0(ucs_handle_error+0x2fd) [0x7f885009cf1d]
 1  /opt/conda/envs/gdf/lib/libucs.so.0(+0x29114) [0x7f885009d114]
 2  /opt/conda/envs/gdf/lib/libucs.so.0(+0x292da) [0x7f885009d2da]
 3  /usr/lib/x86_64-linux-gnu/libpthread.so.0(+0x14420) [0x7f88e1914420]
 4  /opt/conda/envs/gdf/lib/libucp.so.0(ucp_mem_type_unpack+0x14) [0x7f88501165d4]
 5  /opt/conda/envs/gdf/lib/libucp.so.0(ucp_rndv_data_handler+0x4e9) [0x7f885013b859]
 6  /opt/conda/envs/gdf/lib/libuct.so.0(+0x2042f) [0x7f885005842f]
 7  /opt/conda/envs/gdf/lib/libuct.so.0(+0x23798) [0x7f885005b798]
 8  /opt/conda/envs/gdf/lib/libucs.so.0(ucs_event_set_wait+0xb9) [0x7f88500a5989]
 9  /opt/conda/envs/gdf/lib/libuct.so.0(uct_tcp_iface_progress+0x7d) [0x7f885005a62d]
10  /opt/conda/envs/gdf/lib/libucp.so.0(ucp_worker_progress+0x5a) [0x7f8850113c4a]
11  /opt/conda/envs/gdf/lib/python3.9/site-packages/ucp/_libs/ucx_api.cpython-39-x86_64-linux-gnu.so(+0x2b17a) [0x7f88501be17a]
12  /opt/conda/envs/gdf/bin/python(+0x14420c) [0x559917ac020c]
13  /opt/conda/envs/gdf/bin/python(_PyEval_EvalFrameDefault+0x5dc5) [0x559917ab0bf5]
14  /opt/conda/envs/gdf/bin/python(+0x12df94) [0x559917aa9f94]
15  /opt/conda/envs/gdf/bin/python(_PyFunction_Vectorcall+0xd9) [0x559917abb3f9]
16  /opt/conda/envs/gdf/bin/python(_PyEval_EvalFrameDefault+0x696) [0x559917aab4c6]
17  /opt/conda/envs/gdf/bin/python(+0x13f6a2) [0x559917abb6a2]
18  /opt/conda/envs/gdf/bin/python(+0x14ca43) [0x559917ac8a43]
19  /opt/conda/envs/gdf/bin/python(+0x2580fc) [0x559917bd40fc]
20  /opt/conda/envs/gdf/bin/python(+0xf248b) [0x559917a6e48b]
21  /opt/conda/envs/gdf/bin/python(+0x1366f3) [0x559917ab26f3]
22  /opt/conda/envs/gdf/bin/python(_PyEval_EvalFrameDefault+0x58b4) [0x559917ab06e4]
23  /opt/conda/envs/gdf/bin/python(+0x13f6a2) [0x559917abb6a2]
24  /opt/conda/envs/gdf/bin/python(_PyEval_EvalFrameDefault+0x696) [0x559917aab4c6]
25  /opt/conda/envs/gdf/bin/python(+0x13f6a2) [0x559917abb6a2]
26  /opt/conda/envs/gdf/bin/python(_PyEval_EvalFrameDefault+0x696) [0x559917aab4c6]
27  /opt/conda/envs/gdf/bin/python(+0x13f6a2) [0x559917abb6a2]
28  /opt/conda/envs/gdf/bin/python(_PyEval_EvalFrameDefault+0x696) [0x559917aab4c6]
29  /opt/conda/envs/gdf/bin/python(+0x13f6a2) [0x559917abb6a2]
30  /opt/conda/envs/gdf/bin/python(_PyEval_EvalFrameDefault+0x696) [0x559917aab4c6]
31  /opt/conda/envs/gdf/bin/python(+0x12df94) [0x559917aa9f94]
32  /opt/conda/envs/gdf/bin/python(_PyFunction_Vectorcall+0xd9) [0x559917abb3f9]
33  /opt/conda/envs/gdf/bin/python(_PyEval_EvalFrameDefault+0x4abe) [0x559917aaf8ee]
34  /opt/conda/envs/gdf/bin/python(+0x12df94) [0x559917aa9f94]
35  /opt/conda/envs/gdf/bin/python(+0x14c88b) [0x559917ac888b]
36  /opt/conda/envs/gdf/bin/python(PyObject_Call+0xbc) [0x559917ac900c]
37  /opt/conda/envs/gdf/bin/python(+0x21073e) [0x559917b8c73e]
38  /opt/conda/envs/gdf/bin/python(_PyObject_MakeTpCall+0x2ec) [0x559917ab367c]
39  /opt/conda/envs/gdf/bin/python(_PyEval_EvalFrameDefault+0x45a6) [0x559917aaf3d6]
40  /opt/conda/envs/gdf/bin/python(+0x13f6a2) [0x559917abb6a2]
41  /opt/conda/envs/gdf/bin/python(+0x14c96c) [0x559917ac896c]
42  /opt/conda/envs/gdf/bin/python(_PyEval_EvalFrameDefault+0x45a6) [0x559917aaf3d6]
43  /opt/conda/envs/gdf/bin/python(+0x13f6a2) [0x559917abb6a2]
44  /opt/conda/envs/gdf/bin/python(_PyEval_EvalFrameDefault+0x696) [0x559917aab4c6]
45  /opt/conda/envs/gdf/bin/python(+0x12df94) [0x559917aa9f94]
46  /opt/conda/envs/gdf/bin/python(_PyFunction_Vectorcall+0xd9) [0x559917abb3f9]
47  /opt/conda/envs/gdf/bin/python(_PyEval_EvalFrameDefault+0x696) [0x559917aab4c6]
48  /opt/conda/envs/gdf/bin/python(+0x13f6a2) [0x559917abb6a2]
49  /opt/conda/envs/gdf/bin/python(_PyEval_EvalFrameDefault+0x3e2) [0x559917aab212]
50  /opt/conda/envs/gdf/bin/python(+0x12df94) [0x559917aa9f94]
51  /opt/conda/envs/gdf/bin/python(_PyFunction_Vectorcall+0xd9) [0x559917abb3f9]
52  /opt/conda/envs/gdf/bin/python(_PyEval_EvalFrameDefault+0x11f2) [0x559917aac022]
53  /opt/conda/envs/gdf/bin/python(+0x12df94) [0x559917aa9f94]
54  /opt/conda/envs/gdf/bin/python(_PyEval_EvalCodeWithName+0x48) [0x559917aa9c68]
55  /opt/conda/envs/gdf/bin/python(PyEval_EvalCodeEx+0x39) [0x559917aa9c19]
56  /opt/conda/envs/gdf/bin/python(PyEval_EvalCode+0x1b) [0x559917b5720b]
57  /opt/conda/envs/gdf/bin/python(+0x2085fa) [0x559917b845fa]
58  /opt/conda/envs/gdf/bin/python(+0x204983) [0x559917b80983]
59  /opt/conda/envs/gdf/bin/python(PyRun_StringFlags+0x9a) [0x559917b7879a]
60  /opt/conda/envs/gdf/bin/python(PyRun_SimpleStringFlags+0x3c) [0x559917b7868c]
61  /opt/conda/envs/gdf/bin/python(Py_RunMain+0x267) [0x559917b778c7]
=================================
2023-08-11 06:19:46,314 - distributed.worker - ERROR - Worker stream died during communication: ucx://127.0.0.1:56933
Traceback (most recent call last):
  File "/opt/conda/envs/gdf/lib/python3.9/site-packages/distributed/comm/ucx.py", line 349, in read
    await self.ep.recv(msg)
  File "/opt/conda/envs/gdf/lib/python3.9/site-packages/ucp/core.py", line 725, in recv
    ret = await comm.tag_recv(self._ep, buffer, nbytes, tag, name=log)
ucp._libs.exceptions.UCXCanceled: <[Recv #003] ep: 0x7f3a1c790100, tag: 0x4857a623e666de80, nbytes: 16, type: <class 'numpy.ndarray'>>: 

During handling of the above exception, another exception occurred:

Traceback (most recent call last):
  File "/opt/conda/envs/gdf/lib/python3.9/site-packages/distributed/worker.py", line 2066, in gather_dep
    response = await get_data_from_worker(
  File "/opt/conda/envs/gdf/lib/python3.9/site-packages/distributed/worker.py", line 2892, in get_data_from_worker
    response = await send_recv(
  File "/opt/conda/envs/gdf/lib/python3.9/site-packages/distributed/core.py", line 1024, in send_recv
    response = await comm.read(deserializers=deserializers)
  File "/opt/conda/envs/gdf/lib/python3.9/site-packages/distributed/utils.py", line 752, in wrapper
    return await func(*args, **kwargs)
  File "/opt/conda/envs/gdf/lib/python3.9/site-packages/distributed/comm/ucx.py", line 367, in read
    raise CommClosedError(
distributed.comm.core.CommClosedError: Connection closed by writer.
Inner exception: UCXCanceled("<[Recv #003] ep: 0x7f3a1c790100, tag: 0x4857a623e666de80, nbytes: 16, type: <class 'numpy.ndarray'>>: ")
2023-08-11 06:19:46,314 - distributed.worker - ERROR - failed during get data with ucx://127.0.0.1:55709 -> ucx://127.0.0.1:56933
Traceback (most recent call last):
  File "/opt/conda/envs/gdf/lib/python3.9/site-packages/distributed/comm/ucx.py", line 333, in write
    await self.ep.send(each_frame)
  File "/opt/conda/envs/gdf/lib/python3.9/site-packages/ucp/core.py", line 650, in send
    return await comm.tag_send(self._ep, buffer, nbytes, tag, name=log)
ucp._libs.exceptions.UCXError: <[Send #007] ep: 0x7f20c4500280, tag: 0x51aad322e71a14b7, nbytes: 50000000, type: <class 'cupy.ndarray'>>: Connection reset by remote peer

During handling of the above exception, another exception occurred:

Traceback (most recent call last):
  File "/opt/conda/envs/gdf/lib/python3.9/site-packages/distributed/worker.py", line 1792, in get_data
    compressed = await comm.write(msg, serializers=serializers)
  File "/opt/conda/envs/gdf/lib/python3.9/site-packages/distributed/utils.py", line 752, in wrapper
    return await func(*args, **kwargs)
  File "/opt/conda/envs/gdf/lib/python3.9/site-packages/distributed/comm/ucx.py", line 337, in write
    raise CommClosedError("While writing, the connection was closed")
distributed.comm.core.CommClosedError: While writing, the connection was closed
2023-08-11 06:19:46,316 - distributed.worker - ERROR - Worker stream died during communication: ucx://127.0.0.1:56933
Traceback (most recent call last):
  File "/opt/conda/envs/gdf/lib/python3.9/site-packages/distributed/comm/ucx.py", line 391, in read
    await self.ep.recv(each_frame)
  File "/opt/conda/envs/gdf/lib/python3.9/site-packages/ucp/core.py", line 725, in recv
    ret = await comm.tag_recv(self._ep, buffer, nbytes, tag, name=log)
ucp._libs.exceptions.UCXError: <[Recv #007] ep: 0x7f20c4500180, tag: 0x700115814b00cb53, nbytes: 50000000, type: <class 'rmm._lib.device_buffer.DeviceBuffer'>>: Connection reset by remote peer

During handling of the above exception, another exception occurred:

Traceback (most recent call last):
  File "/opt/conda/envs/gdf/lib/python3.9/site-packages/distributed/worker.py", line 2066, in gather_dep
    response = await get_data_from_worker(
  File "/opt/conda/envs/gdf/lib/python3.9/site-packages/distributed/worker.py", line 2892, in get_data_from_worker
    response = await send_recv(
  File "/opt/conda/envs/gdf/lib/python3.9/site-packages/distributed/core.py", line 1024, in send_recv
    response = await comm.read(deserializers=deserializers)
  File "/opt/conda/envs/gdf/lib/python3.9/site-packages/distributed/utils.py", line 752, in wrapper
    return await func(*args, **kwargs)
  File "/opt/conda/envs/gdf/lib/python3.9/site-packages/distributed/comm/ucx.py", line 397, in read
    raise CommClosedError(
distributed.comm.core.CommClosedError: Connection closed by writer.
Inner exception: UCXError("<[Recv #007] ep: 0x7f20c4500180, tag: 0x700115814b00cb53, nbytes: 50000000, type: <class 'rmm._lib.device_buffer.DeviceBuffer'>>: Connection reset by remote peer")
2023-08-11 06:19:46,324 - distributed.worker - ERROR - Worker stream died during communication: ucx://127.0.0.1:45947
Traceback (most recent call last):
  File "/opt/conda/envs/gdf/lib/python3.9/site-packages/distributed/comm/ucx.py", line 391, in read
    await self.ep.recv(each_frame)
  File "/opt/conda/envs/gdf/lib/python3.9/site-packages/ucp/core.py", line 725, in recv
    ret = await comm.tag_recv(self._ep, buffer, nbytes, tag, name=log)
ucp._libs.exceptions.UCXError: <[Recv #007] ep: 0x7f20c4500140, tag: 0xc6569518a4e1f834, nbytes: 50000000, type: <class 'rmm._lib.device_buffer.DeviceBuffer'>>: Connection reset by remote peer

During handling of the above exception, another exception occurred:

Traceback (most recent call last):
  File "/opt/conda/envs/gdf/lib/python3.9/site-packages/distributed/worker.py", line 2066, in gather_dep
    response = await get_data_from_worker(
  File "/opt/conda/envs/gdf/lib/python3.9/site-packages/distributed/worker.py", line 2892, in get_data_from_worker
    response = await send_recv(
  File "/opt/conda/envs/gdf/lib/python3.9/site-packages/distributed/core.py", line 1024, in send_recv
    response = await comm.read(deserializers=deserializers)
  File "/opt/conda/envs/gdf/lib/python3.9/site-packages/distributed/utils.py", line 752, in wrapper
    return await func(*args, **kwargs)
  File "/opt/conda/envs/gdf/lib/python3.9/site-packages/distributed/comm/ucx.py", line 397, in read
    raise CommClosedError(
distributed.comm.core.CommClosedError: Connection closed by writer.
Inner exception: UCXError("<[Recv #007] ep: 0x7f20c4500140, tag: 0xc6569518a4e1f834, nbytes: 50000000, type: <class 'rmm._lib.device_buffer.DeviceBuffer'>>: Connection reset by remote peer")
2023-08-11 06:19:46,324 - distributed.worker - ERROR - Worker stream died during communication: ucx://127.0.0.1:45947
Traceback (most recent call last):
  File "/opt/conda/envs/gdf/lib/python3.9/site-packages/distributed/comm/ucx.py", line 349, in read
    await self.ep.recv(msg)
  File "/opt/conda/envs/gdf/lib/python3.9/site-packages/ucp/core.py", line 725, in recv
    ret = await comm.tag_recv(self._ep, buffer, nbytes, tag, name=log)
ucp._libs.exceptions.UCXCanceled: <[Recv #008] ep: 0x7f64f15a0140, tag: 0xac8c83c03f321451, nbytes: 16, type: <class 'numpy.ndarray'>>: 

During handling of the above exception, another exception occurred:

Traceback (most recent call last):
  File "/opt/conda/envs/gdf/lib/python3.9/site-packages/distributed/worker.py", line 2066, in gather_dep
    response = await get_data_from_worker(
  File "/opt/conda/envs/gdf/lib/python3.9/site-packages/distributed/worker.py", line 2892, in get_data_from_worker
    response = await send_recv(
  File "/opt/conda/envs/gdf/lib/python3.9/site-packages/distributed/core.py", line 1024, in send_recv
    response = await comm.read(deserializers=deserializers)
  File "/opt/conda/envs/gdf/lib/python3.9/site-packages/distributed/utils.py", line 752, in wrapper
    return await func(*args, **kwargs)
  File "/opt/conda/envs/gdf/lib/python3.9/site-packages/distributed/comm/ucx.py", line 367, in read
    raise CommClosedError(
distributed.comm.core.CommClosedError: Connection closed by writer.
Inner exception: UCXCanceled("<[Recv #008] ep: 0x7f64f15a0140, tag: 0xac8c83c03f321451, nbytes: 16, type: <class 'numpy.ndarray'>>: ")
2023-08-11 06:19:46,344 - distributed.worker - ERROR - Worker stream died during communication: ucx://127.0.0.1:53621
Traceback (most recent call last):
  File "/opt/conda/envs/gdf/lib/python3.9/site-packages/distributed/comm/ucx.py", line 391, in read
    await self.ep.recv(each_frame)
  File "/opt/conda/envs/gdf/lib/python3.9/site-packages/ucp/core.py", line 725, in recv
    ret = await comm.tag_recv(self._ep, buffer, nbytes, tag, name=log)
ucp._libs.exceptions.UCXError: <[Recv #007] ep: 0x7f3a1c790180, tag: 0x71f42f0546d26c81, nbytes: 50000000, type: <class 'rmm._lib.device_buffer.DeviceBuffer'>>: Connection reset by remote peer

During handling of the above exception, another exception occurred:

Traceback (most recent call last):
  File "/opt/conda/envs/gdf/lib/python3.9/site-packages/distributed/worker.py", line 2066, in gather_dep
    response = await get_data_from_worker(
  File "/opt/conda/envs/gdf/lib/python3.9/site-packages/distributed/worker.py", line 2892, in get_data_from_worker
    response = await send_recv(
  File "/opt/conda/envs/gdf/lib/python3.9/site-packages/distributed/core.py", line 1024, in send_recv
    response = await comm.read(deserializers=deserializers)
  File "/opt/conda/envs/gdf/lib/python3.9/site-packages/distributed/utils.py", line 752, in wrapper
    return await func(*args, **kwargs)
  File "/opt/conda/envs/gdf/lib/python3.9/site-packages/distributed/comm/ucx.py", line 397, in read
    raise CommClosedError(
distributed.comm.core.CommClosedError: Connection closed by writer.
Inner exception: UCXError("<[Recv #007] ep: 0x7f3a1c790180, tag: 0x71f42f0546d26c81, nbytes: 50000000, type: <class 'rmm._lib.device_buffer.DeviceBuffer'>>: Connection reset by remote peer")
2023-08-11 06:19:46,344 - distributed.worker - ERROR - Worker stream died during communication: ucx://127.0.0.1:53621
Traceback (most recent call last):
  File "/opt/conda/envs/gdf/lib/python3.9/site-packages/distributed/comm/ucx.py", line 349, in read
    await self.ep.recv(msg)
  File "/opt/conda/envs/gdf/lib/python3.9/site-packages/ucp/core.py", line 725, in recv
    ret = await comm.tag_recv(self._ep, buffer, nbytes, tag, name=log)
ucp._libs.exceptions.UCXCanceled: <[Recv #003] ep: 0x7f20c45001c0, tag: 0xdafb95a0f7f3f530, nbytes: 16, type: <class 'numpy.ndarray'>>: 

During handling of the above exception, another exception occurred:

Traceback (most recent call last):
  File "/opt/conda/envs/gdf/lib/python3.9/site-packages/distributed/worker.py", line 2066, in gather_dep
    response = await get_data_from_worker(
  File "/opt/conda/envs/gdf/lib/python3.9/site-packages/distributed/worker.py", line 2892, in get_data_from_worker
    response = await send_recv(
  File "/opt/conda/envs/gdf/lib/python3.9/site-packages/distributed/core.py", line 1024, in send_recv
    response = await comm.read(deserializers=deserializers)
  File "/opt/conda/envs/gdf/lib/python3.9/site-packages/distributed/utils.py", line 752, in wrapper
    return await func(*args, **kwargs)
  File "/opt/conda/envs/gdf/lib/python3.9/site-packages/distributed/comm/ucx.py", line 367, in read
    raise CommClosedError(
distributed.comm.core.CommClosedError: Connection closed by writer.
Inner exception: UCXCanceled("<[Recv #003] ep: 0x7f20c45001c0, tag: 0xdafb95a0f7f3f530, nbytes: 16, type: <class 'numpy.ndarray'>>: ")
2023-08-11 06:19:46,344 - distributed.worker - ERROR - failed during get data with ucx://127.0.0.1:42581 -> ucx://127.0.0.1:53621
Traceback (most recent call last):
  File "/opt/conda/envs/gdf/lib/python3.9/site-packages/distributed/comm/ucx.py", line 333, in write
    await self.ep.send(each_frame)
  File "/opt/conda/envs/gdf/lib/python3.9/site-packages/ucp/core.py", line 650, in send
    return await comm.tag_send(self._ep, buffer, nbytes, tag, name=log)
ucp._libs.exceptions.UCXError: <[Send #007] ep: 0x7f64f15a0240, tag: 0x6266837fe6fe547c, nbytes: 50000000, type: <class 'cupy.ndarray'>>: Connection reset by remote peer

During handling of the above exception, another exception occurred:

Traceback (most recent call last):
  File "/opt/conda/envs/gdf/lib/python3.9/site-packages/distributed/worker.py", line 1792, in get_data
    compressed = await comm.write(msg, serializers=serializers)
  File "/opt/conda/envs/gdf/lib/python3.9/site-packages/distributed/utils.py", line 752, in wrapper
    return await func(*args, **kwargs)
  File "/opt/conda/envs/gdf/lib/python3.9/site-packages/distributed/comm/ucx.py", line 337, in write
    raise CommClosedError("While writing, the connection was closed")
distributed.comm.core.CommClosedError: While writing, the connection was closed
2023-08-11 06:19:46,345 - distributed.worker - ERROR - failed during get data with ucx://127.0.0.1:51723 -> ucx://127.0.0.1:53621
Traceback (most recent call last):
  File "/opt/conda/envs/gdf/lib/python3.9/site-packages/distributed/comm/ucx.py", line 333, in write
    await self.ep.send(each_frame)
  File "/opt/conda/envs/gdf/lib/python3.9/site-packages/ucp/core.py", line 650, in send
    return await comm.tag_send(self._ep, buffer, nbytes, tag, name=log)
ucp._libs.exceptions.UCXError: <[Send #007] ep: 0x7f3a1c790380, tag: 0x4302e87e51a06025, nbytes: 50000000, type: <class 'cupy.ndarray'>>: Connection reset by remote peer

During handling of the above exception, another exception occurred:

Traceback (most recent call last):
  File "/opt/conda/envs/gdf/lib/python3.9/site-packages/distributed/worker.py", line 1792, in get_data
    compressed = await comm.write(msg, serializers=serializers)
  File "/opt/conda/envs/gdf/lib/python3.9/site-packages/distributed/utils.py", line 752, in wrapper
    return await func(*args, **kwargs)
  File "/opt/conda/envs/gdf/lib/python3.9/site-packages/distributed/comm/ucx.py", line 337, in write
    raise CommClosedError("While writing, the connection was closed")
distributed.comm.core.CommClosedError: While writing, the connection was closed
2023-08-11 06:19:46,345 - distributed.worker - ERROR - Worker stream died during communication: ucx://127.0.0.1:53621
Traceback (most recent call last):
  File "/opt/conda/envs/gdf/lib/python3.9/site-packages/distributed/comm/ucx.py", line 349, in read
    await self.ep.recv(msg)
  File "/opt/conda/envs/gdf/lib/python3.9/site-packages/ucp/core.py", line 725, in recv
    ret = await comm.tag_recv(self._ep, buffer, nbytes, tag, name=log)
ucp._libs.exceptions.UCXCanceled: <[Recv #003] ep: 0x7f64f15a0100, tag: 0xe904af95e1a683df, nbytes: 16, type: <class 'numpy.ndarray'>>: 

During handling of the above exception, another exception occurred:

Traceback (most recent call last):
  File "/opt/conda/envs/gdf/lib/python3.9/site-packages/distributed/worker.py", line 2066, in gather_dep
    response = await get_data_from_worker(
  File "/opt/conda/envs/gdf/lib/python3.9/site-packages/distributed/worker.py", line 2892, in get_data_from_worker
    response = await send_recv(
  File "/opt/conda/envs/gdf/lib/python3.9/site-packages/distributed/core.py", line 1024, in send_recv
    response = await comm.read(deserializers=deserializers)
  File "/opt/conda/envs/gdf/lib/python3.9/site-packages/distributed/utils.py", line 752, in wrapper
    return await func(*args, **kwargs)
  File "/opt/conda/envs/gdf/lib/python3.9/site-packages/distributed/comm/ucx.py", line 367, in read
    raise CommClosedError(
distributed.comm.core.CommClosedError: Connection closed by writer.
Inner exception: UCXCanceled("<[Recv #003] ep: 0x7f64f15a0100, tag: 0xe904af95e1a683df, nbytes: 16, type: <class 'numpy.ndarray'>>: ")
2023-08-11 06:19:46,355 - distributed.worker - ERROR - Worker stream died during communication: ucx://127.0.0.1:37365
Traceback (most recent call last):
  File "/opt/conda/envs/gdf/lib/python3.9/site-packages/distributed/comm/ucx.py", line 349, in read
    await self.ep.recv(msg)
  File "/opt/conda/envs/gdf/lib/python3.9/site-packages/ucp/core.py", line 725, in recv
    ret = await comm.tag_recv(self._ep, buffer, nbytes, tag, name=log)
ucp._libs.exceptions.UCXCanceled: <[Recv #003] ep: 0x7f20c4500100, tag: 0x8b92ad2faeab1362, nbytes: 16, type: <class 'numpy.ndarray'>>: 

During handling of the above exception, another exception occurred:

Traceback (most recent call last):
  File "/opt/conda/envs/gdf/lib/python3.9/site-packages/distributed/worker.py", line 2066, in gather_dep
    response = await get_data_from_worker(
  File "/opt/conda/envs/gdf/lib/python3.9/site-packages/distributed/worker.py", line 2892, in get_data_from_worker
    response = await send_recv(
  File "/opt/conda/envs/gdf/lib/python3.9/site-packages/distributed/core.py", line 1024, in send_recv
    response = await comm.read(deserializers=deserializers)
  File "/opt/conda/envs/gdf/lib/python3.9/site-packages/distributed/utils.py", line 752, in wrapper
    return await func(*args, **kwargs)
  File "/opt/conda/envs/gdf/lib/python3.9/site-packages/distributed/comm/ucx.py", line 367, in read
    raise CommClosedError(
distributed.comm.core.CommClosedError: Connection closed by writer.
Inner exception: UCXCanceled("<[Recv #003] ep: 0x7f20c4500100, tag: 0x8b92ad2faeab1362, nbytes: 16, type: <class 'numpy.ndarray'>>: ")
2023-08-11 06:19:46,371 - distributed.nanny - WARNING - Restarting worker
2023-08-11 06:19:46,349 - distributed.worker - ERROR - failed during get data with ucx://127.0.0.1:51723 -> ucx://127.0.0.1:54597
Traceback (most recent call last):
  File "/opt/conda/envs/gdf/lib/python3.9/site-packages/distributed/comm/ucx.py", line 333, in write
    await self.ep.send(each_frame)
  File "/opt/conda/envs/gdf/lib/python3.9/site-packages/ucp/core.py", line 650, in send
    return await comm.tag_send(self._ep, buffer, nbytes, tag, name=log)
ucp._libs.exceptions.UCXError: <[Send #007] ep: 0x7f3a1c790340, tag: 0xa25051c4fa1a376a, nbytes: 50000000, type: <class 'cupy.ndarray'>>: Connection reset by remote peer

During handling of the above exception, another exception occurred:

Traceback (most recent call last):
  File "/opt/conda/envs/gdf/lib/python3.9/site-packages/distributed/worker.py", line 1792, in get_data
    compressed = await comm.write(msg, serializers=serializers)
  File "/opt/conda/envs/gdf/lib/python3.9/site-packages/distributed/utils.py", line 752, in wrapper
    return await func(*args, **kwargs)
  File "/opt/conda/envs/gdf/lib/python3.9/site-packages/distributed/comm/ucx.py", line 337, in write
    raise CommClosedError("While writing, the connection was closed")
distributed.comm.core.CommClosedError: While writing, the connection was closed
2023-08-11 06:19:46,375 - distributed.worker - ERROR - failed during get data with ucx://127.0.0.1:51723 -> ucx://127.0.0.1:37365
Traceback (most recent call last):
  File "/opt/conda/envs/gdf/lib/python3.9/site-packages/distributed/comm/ucx.py", line 333, in write
    await self.ep.send(each_frame)
  File "/opt/conda/envs/gdf/lib/python3.9/site-packages/ucp/core.py", line 650, in send
    return await comm.tag_send(self._ep, buffer, nbytes, tag, name=log)
ucp._libs.exceptions.UCXError: <[Send #007] ep: 0x7f3a1c790400, tag: 0xaa7a4e01c103c4c9, nbytes: 50000000, type: <class 'cupy.ndarray'>>: Connection reset by remote peer

During handling of the above exception, another exception occurred:

Traceback (most recent call last):
  File "/opt/conda/envs/gdf/lib/python3.9/site-packages/distributed/worker.py", line 1792, in get_data
    compressed = await comm.write(msg, serializers=serializers)
  File "/opt/conda/envs/gdf/lib/python3.9/site-packages/distributed/utils.py", line 752, in wrapper
    return await func(*args, **kwargs)
  File "/opt/conda/envs/gdf/lib/python3.9/site-packages/distributed/comm/ucx.py", line 337, in write
    raise CommClosedError("While writing, the connection was closed")
distributed.comm.core.CommClosedError: While writing, the connection was closed
2023-08-11 06:19:46,375 - distributed.worker - ERROR - Worker stream died during communication: ucx://127.0.0.1:37365
Traceback (most recent call last):
  File "/opt/conda/envs/gdf/lib/python3.9/site-packages/distributed/comm/ucx.py", line 391, in read
    await self.ep.recv(each_frame)
  File "/opt/conda/envs/gdf/lib/python3.9/site-packages/ucp/core.py", line 725, in recv
    ret = await comm.tag_recv(self._ep, buffer, nbytes, tag, name=log)
ucp._libs.exceptions.UCXError: <[Recv #007] ep: 0x7f3a1c7901c0, tag: 0x77eea1e9ca13fa81, nbytes: 50000000, type: <class 'rmm._lib.device_buffer.DeviceBuffer'>>: Connection reset by remote peer

During handling of the above exception, another exception occurred:

Traceback (most recent call last):
  File "/opt/conda/envs/gdf/lib/python3.9/site-packages/distributed/worker.py", line 2066, in gather_dep
    response = await get_data_from_worker(
  File "/opt/conda/envs/gdf/lib/python3.9/site-packages/distributed/worker.py", line 2892, in get_data_from_worker
    response = await send_recv(
  File "/opt/conda/envs/gdf/lib/python3.9/site-packages/distributed/core.py", line 1024, in send_recv
    response = await comm.read(deserializers=deserializers)
  File "/opt/conda/envs/gdf/lib/python3.9/site-packages/distributed/utils.py", line 752, in wrapper
    return await func(*args, **kwargs)
  File "/opt/conda/envs/gdf/lib/python3.9/site-packages/distributed/comm/ucx.py", line 397, in read
    raise CommClosedError(
distributed.comm.core.CommClosedError: Connection closed by writer.
Inner exception: UCXError("<[Recv #007] ep: 0x7f3a1c7901c0, tag: 0x77eea1e9ca13fa81, nbytes: 50000000, type: <class 'rmm._lib.device_buffer.DeviceBuffer'>>: Connection reset by remote peer")
2023-08-11 06:19:46,375 - distributed.worker - ERROR - Worker stream died during communication: ucx://127.0.0.1:37365
Traceback (most recent call last):
  File "/opt/conda/envs/gdf/lib/python3.9/site-packages/distributed/comm/ucx.py", line 349, in read
    await self.ep.recv(msg)
  File "/opt/conda/envs/gdf/lib/python3.9/site-packages/ucp/core.py", line 725, in recv
    ret = await comm.tag_recv(self._ep, buffer, nbytes, tag, name=log)
ucp._libs.exceptions.UCXCanceled: <[Recv #003] ep: 0x7f64f15a0200, tag: 0x6c2ea561ae1a7af0, nbytes: 16, type: <class 'numpy.ndarray'>>: 

During handling of the above exception, another exception occurred:

Traceback (most recent call last):
  File "/opt/conda/envs/gdf/lib/python3.9/site-packages/distributed/worker.py", line 2066, in gather_dep
    response = await get_data_from_worker(
  File "/opt/conda/envs/gdf/lib/python3.9/site-packages/distributed/worker.py", line 2892, in get_data_from_worker
    response = await send_recv(
  File "/opt/conda/envs/gdf/lib/python3.9/site-packages/distributed/core.py", line 1024, in send_recv
    response = await comm.read(deserializers=deserializers)
  File "/opt/conda/envs/gdf/lib/python3.9/site-packages/distributed/utils.py", line 752, in wrapper
    return await func(*args, **kwargs)
  File "/opt/conda/envs/gdf/lib/python3.9/site-packages/distributed/comm/ucx.py", line 367, in read
    raise CommClosedError(
distributed.comm.core.CommClosedError: Connection closed by writer.
Inner exception: UCXCanceled("<[Recv #003] ep: 0x7f64f15a0200, tag: 0x6c2ea561ae1a7af0, nbytes: 16, type: <class 'numpy.ndarray'>>: ")
2023-08-11 06:19:46,425 - distributed.nanny - WARNING - Restarting worker
2023-08-11 06:19:46,461 - distributed.nanny - WARNING - Restarting worker
2023-08-11 06:19:46,490 - distributed.nanny - WARNING - Restarting worker
2023-08-11 06:19:46,558 - distributed.nanny - WARNING - Restarting worker
[dgx13:70761:0:70761] Caught signal 11 (Segmentation fault: address not mapped to object at address 0x448)
==== backtrace (tid:  70761) ====
 0  /opt/conda/envs/gdf/lib/libucs.so.0(ucs_handle_error+0x2fd) [0x7f64f1817f1d]
 1  /opt/conda/envs/gdf/lib/libucs.so.0(+0x29114) [0x7f64f1818114]
 2  /opt/conda/envs/gdf/lib/libucs.so.0(+0x292da) [0x7f64f18182da]
 3  /usr/lib/x86_64-linux-gnu/libpthread.so.0(+0x14420) [0x7f659508d420]
 4  /opt/conda/envs/gdf/lib/libucp.so.0(ucp_mem_type_unpack+0x14) [0x7f64f18915d4]
 5  /opt/conda/envs/gdf/lib/libucp.so.0(ucp_rndv_data_handler+0x4e9) [0x7f64f18b6859]
 6  /opt/conda/envs/gdf/lib/libuct.so.0(+0x2042f) [0x7f64f17d342f]
 7  /opt/conda/envs/gdf/lib/libuct.so.0(+0x23798) [0x7f64f17d6798]
 8  /opt/conda/envs/gdf/lib/libucs.so.0(ucs_event_set_wait+0xb9) [0x7f64f1820989]
 9  /opt/conda/envs/gdf/lib/libuct.so.0(uct_tcp_iface_progress+0x7d) [0x7f64f17d562d]
10  /opt/conda/envs/gdf/lib/libucp.so.0(ucp_worker_progress+0x5a) [0x7f64f188ec4a]
11  /opt/conda/envs/gdf/lib/python3.9/site-packages/ucp/_libs/ucx_api.cpython-39-x86_64-linux-gnu.so(+0x2b17a) [0x7f64f193917a]
12  /opt/conda/envs/gdf/bin/python(+0x14420c) [0x5650aafd320c]
13  /opt/conda/envs/gdf/bin/python(_PyEval_EvalFrameDefault+0x5dc5) [0x5650aafc3bf5]
14  /opt/conda/envs/gdf/bin/python(+0x12df94) [0x5650aafbcf94]
15  /opt/conda/envs/gdf/bin/python(_PyFunction_Vectorcall+0xd9) [0x5650aafce3f9]
16  /opt/conda/envs/gdf/bin/python(_PyEval_EvalFrameDefault+0x696) [0x5650aafbe4c6]
17  /opt/conda/envs/gdf/bin/python(+0x13f6a2) [0x5650aafce6a2]
18  /opt/conda/envs/gdf/bin/python(+0x14ca43) [0x5650aafdba43]
19  /opt/conda/envs/gdf/bin/python(+0x2580fc) [0x5650ab0e70fc]
20  /opt/conda/envs/gdf/bin/python(+0xf248b) [0x5650aaf8148b]
21  /opt/conda/envs/gdf/bin/python(+0x1366f3) [0x5650aafc56f3]
22  /opt/conda/envs/gdf/bin/python(_PyEval_EvalFrameDefault+0x58b4) [0x5650aafc36e4]
23  /opt/conda/envs/gdf/bin/python(+0x13f6a2) [0x5650aafce6a2]
24  /opt/conda/envs/gdf/bin/python(_PyEval_EvalFrameDefault+0x696) [0x5650aafbe4c6]
25  /opt/conda/envs/gdf/bin/python(+0x13f6a2) [0x5650aafce6a2]
26  /opt/conda/envs/gdf/bin/python(_PyEval_EvalFrameDefault+0x696) [0x5650aafbe4c6]
27  /opt/conda/envs/gdf/bin/python(+0x13f6a2) [0x5650aafce6a2]
28  /opt/conda/envs/gdf/bin/python(_PyEval_EvalFrameDefault+0x696) [0x5650aafbe4c6]
29  /opt/conda/envs/gdf/bin/python(+0x13f6a2) [0x5650aafce6a2]
30  /opt/conda/envs/gdf/bin/python(_PyEval_EvalFrameDefault+0x696) [0x5650aafbe4c6]
31  /opt/conda/envs/gdf/bin/python(+0x12df94) [0x5650aafbcf94]
32  /opt/conda/envs/gdf/bin/python(_PyFunction_Vectorcall+0xd9) [0x5650aafce3f9]
33  /opt/conda/envs/gdf/bin/python(_PyEval_EvalFrameDefault+0x4abe) [0x5650aafc28ee]
34  /opt/conda/envs/gdf/bin/python(+0x12df94) [0x5650aafbcf94]
35  /opt/conda/envs/gdf/bin/python(+0x14c88b) [0x5650aafdb88b]
36  /opt/conda/envs/gdf/bin/python(PyObject_Call+0xbc) [0x5650aafdc00c]
37  /opt/conda/envs/gdf/bin/python(+0x21073e) [0x5650ab09f73e]
38  /opt/conda/envs/gdf/bin/python(_PyObject_MakeTpCall+0x2ec) [0x5650aafc667c]
39  /opt/conda/envs/gdf/bin/python(_PyEval_EvalFrameDefault+0x45a6) [0x5650aafc23d6]
40  /opt/conda/envs/gdf/bin/python(+0x13f6a2) [0x5650aafce6a2]
41  /opt/conda/envs/gdf/bin/python(+0x14c96c) [0x5650aafdb96c]
42  /opt/conda/envs/gdf/bin/python(_PyEval_EvalFrameDefault+0x45a6) [0x5650aafc23d6]
43  /opt/conda/envs/gdf/bin/python(+0x13f6a2) [0x5650aafce6a2]
44  /opt/conda/envs/gdf/bin/python(_PyEval_EvalFrameDefault+0x696) [0x5650aafbe4c6]
45  /opt/conda/envs/gdf/bin/python(+0x12df94) [0x5650aafbcf94]
46  /opt/conda/envs/gdf/bin/python(_PyFunction_Vectorcall+0xd9) [0x5650aafce3f9]
47  /opt/conda/envs/gdf/bin/python(_PyEval_EvalFrameDefault+0x696) [0x5650aafbe4c6]
48  /opt/conda/envs/gdf/bin/python(+0x13f6a2) [0x5650aafce6a2]
49  /opt/conda/envs/gdf/bin/python(_PyEval_EvalFrameDefault+0x3e2) [0x5650aafbe212]
50  /opt/conda/envs/gdf/bin/python(+0x12df94) [0x5650aafbcf94]
51  /opt/conda/envs/gdf/bin/python(_PyFunction_Vectorcall+0xd9) [0x5650aafce3f9]
52  /opt/conda/envs/gdf/bin/python(_PyEval_EvalFrameDefault+0x11f2) [0x5650aafbf022]
53  /opt/conda/envs/gdf/bin/python(+0x12df94) [0x5650aafbcf94]
54  /opt/conda/envs/gdf/bin/python(_PyEval_EvalCodeWithName+0x48) [0x5650aafbcc68]
55  /opt/conda/envs/gdf/bin/python(PyEval_EvalCodeEx+0x39) [0x5650aafbcc19]
56  /opt/conda/envs/gdf/bin/python(PyEval_EvalCode+0x1b) [0x5650ab06a20b]
57  /opt/conda/envs/gdf/bin/python(+0x2085fa) [0x5650ab0975fa]
58  /opt/conda/envs/gdf/bin/python(+0x204983) [0x5650ab093983]
59  /opt/conda/envs/gdf/bin/python(PyRun_StringFlags+0x9a) [0x5650ab08b79a]
60  /opt/conda/envs/gdf/bin/python(PyRun_SimpleStringFlags+0x3c) [0x5650ab08b68c]
61  /opt/conda/envs/gdf/bin/python(Py_RunMain+0x267) [0x5650ab08a8c7]
=================================
2023-08-11 06:19:46,906 - distributed.worker - ERROR - Worker stream died during communication: ucx://127.0.0.1:42581
Traceback (most recent call last):
  File "/opt/conda/envs/gdf/lib/python3.9/site-packages/distributed/comm/ucx.py", line 349, in read
    await self.ep.recv(msg)
  File "/opt/conda/envs/gdf/lib/python3.9/site-packages/ucp/core.py", line 725, in recv
    ret = await comm.tag_recv(self._ep, buffer, nbytes, tag, name=log)
ucp._libs.exceptions.UCXCanceled: <[Recv #008] ep: 0x7f3a1c790240, tag: 0x4be804060a74a437, nbytes: 16, type: <class 'numpy.ndarray'>>: 

During handling of the above exception, another exception occurred:

Traceback (most recent call last):
  File "/opt/conda/envs/gdf/lib/python3.9/site-packages/distributed/worker.py", line 2066, in gather_dep
    response = await get_data_from_worker(
  File "/opt/conda/envs/gdf/lib/python3.9/site-packages/distributed/worker.py", line 2892, in get_data_from_worker
    response = await send_recv(
  File "/opt/conda/envs/gdf/lib/python3.9/site-packages/distributed/core.py", line 1024, in send_recv
    response = await comm.read(deserializers=deserializers)
  File "/opt/conda/envs/gdf/lib/python3.9/site-packages/distributed/utils.py", line 752, in wrapper
    return await func(*args, **kwargs)
  File "/opt/conda/envs/gdf/lib/python3.9/site-packages/distributed/comm/ucx.py", line 367, in read
    raise CommClosedError(
distributed.comm.core.CommClosedError: Connection closed by writer.
Inner exception: UCXCanceled("<[Recv #008] ep: 0x7f3a1c790240, tag: 0x4be804060a74a437, nbytes: 16, type: <class 'numpy.ndarray'>>: ")
2023-08-11 06:19:46,906 - distributed.worker - ERROR - Worker stream died during communication: ucx://127.0.0.1:42581
Traceback (most recent call last):
  File "/opt/conda/envs/gdf/lib/python3.9/site-packages/distributed/comm/ucx.py", line 391, in read
    await self.ep.recv(each_frame)
  File "/opt/conda/envs/gdf/lib/python3.9/site-packages/ucp/core.py", line 725, in recv
    ret = await comm.tag_recv(self._ep, buffer, nbytes, tag, name=log)
ucp._libs.exceptions.UCXError: <[Recv #007] ep: 0x7f20c4500100, tag: 0x7873dcd588b4db40, nbytes: 50000000, type: <class 'rmm._lib.device_buffer.DeviceBuffer'>>: Connection reset by remote peer

During handling of the above exception, another exception occurred:

Traceback (most recent call last):
  File "/opt/conda/envs/gdf/lib/python3.9/site-packages/distributed/worker.py", line 2066, in gather_dep
    response = await get_data_from_worker(
  File "/opt/conda/envs/gdf/lib/python3.9/site-packages/distributed/worker.py", line 2892, in get_data_from_worker
    response = await send_recv(
  File "/opt/conda/envs/gdf/lib/python3.9/site-packages/distributed/core.py", line 1024, in send_recv
    response = await comm.read(deserializers=deserializers)
  File "/opt/conda/envs/gdf/lib/python3.9/site-packages/distributed/utils.py", line 752, in wrapper
    return await func(*args, **kwargs)
  File "/opt/conda/envs/gdf/lib/python3.9/site-packages/distributed/comm/ucx.py", line 397, in read
    raise CommClosedError(
distributed.comm.core.CommClosedError: Connection closed by writer.
Inner exception: UCXError("<[Recv #007] ep: 0x7f20c4500100, tag: 0x7873dcd588b4db40, nbytes: 50000000, type: <class 'rmm._lib.device_buffer.DeviceBuffer'>>: Connection reset by remote peer")
2023-08-11 06:19:46,906 - distributed.worker - ERROR - failed during get data with ucx://127.0.0.1:55709 -> ucx://127.0.0.1:42581
Traceback (most recent call last):
  File "/opt/conda/envs/gdf/lib/python3.9/site-packages/distributed/comm/ucx.py", line 333, in write
    await self.ep.send(each_frame)
  File "/opt/conda/envs/gdf/lib/python3.9/site-packages/ucp/core.py", line 650, in send
    return await comm.tag_send(self._ep, buffer, nbytes, tag, name=log)
ucp._libs.exceptions.UCXError: <[Send #007] ep: 0x7f20c4500380, tag: 0x552683a281b6d667, nbytes: 50000000, type: <class 'cupy.ndarray'>>: Connection reset by remote peer

During handling of the above exception, another exception occurred:

Traceback (most recent call last):
  File "/opt/conda/envs/gdf/lib/python3.9/site-packages/distributed/worker.py", line 1792, in get_data
    compressed = await comm.write(msg, serializers=serializers)
  File "/opt/conda/envs/gdf/lib/python3.9/site-packages/distributed/utils.py", line 752, in wrapper
    return await func(*args, **kwargs)
  File "/opt/conda/envs/gdf/lib/python3.9/site-packages/distributed/comm/ucx.py", line 337, in write
    raise CommClosedError("While writing, the connection was closed")
distributed.comm.core.CommClosedError: While writing, the connection was closed
2023-08-11 06:19:46,969 - distributed.nanny - WARNING - Restarting worker
2023-08-11 06:19:48,011 - distributed.preloading - INFO - Creating preload: dask_cuda.initialize
2023-08-11 06:19:48,011 - distributed.preloading - INFO - Import preload module: dask_cuda.initialize
2023-08-11 06:19:48,069 - distributed.preloading - INFO - Creating preload: dask_cuda.initialize
2023-08-11 06:19:48,069 - distributed.preloading - INFO - Import preload module: dask_cuda.initialize
2023-08-11 06:19:48,099 - distributed.preloading - INFO - Creating preload: dask_cuda.initialize
2023-08-11 06:19:48,099 - distributed.preloading - INFO - Import preload module: dask_cuda.initialize
2023-08-11 06:19:48,143 - distributed.preloading - INFO - Creating preload: dask_cuda.initialize
2023-08-11 06:19:48,144 - distributed.preloading - INFO - Import preload module: dask_cuda.initialize
2023-08-11 06:19:48,149 - distributed.preloading - INFO - Creating preload: dask_cuda.initialize
2023-08-11 06:19:48,149 - distributed.preloading - INFO - Import preload module: dask_cuda.initialize
2023-08-11 06:19:48,617 - distributed.preloading - INFO - Creating preload: dask_cuda.initialize
2023-08-11 06:19:48,617 - distributed.preloading - INFO - Import preload module: dask_cuda.initialize
[dgx13:70902:0:70902] Caught signal 11 (Segmentation fault: address not mapped to object at address 0x448)
==== backtrace (tid:  70902) ====
 0  /opt/conda/envs/gdf/lib/libucs.so.0(ucs_handle_error+0x2fd) [0x7f7553149f1d]
 1  /opt/conda/envs/gdf/lib/libucs.so.0(+0x29114) [0x7f755314a114]
 2  /opt/conda/envs/gdf/lib/libucs.so.0(+0x292da) [0x7f755314a2da]
 3  /usr/lib/x86_64-linux-gnu/libpthread.so.0(+0x14420) [0x7f75f29a7420]
 4  /opt/conda/envs/gdf/lib/libucp.so.0(ucp_mem_type_unpack+0x14) [0x7f75531c35d4]
 5  /opt/conda/envs/gdf/lib/libucp.so.0(ucp_rndv_data_handler+0x4e9) [0x7f75531e8859]
 6  /opt/conda/envs/gdf/lib/libuct.so.0(+0x2042f) [0x7f755310542f]
 7  /opt/conda/envs/gdf/lib/libuct.so.0(+0x23798) [0x7f7553108798]
 8  /opt/conda/envs/gdf/lib/libucs.so.0(ucs_event_set_wait+0xb9) [0x7f7553152989]
 9  /opt/conda/envs/gdf/lib/libuct.so.0(uct_tcp_iface_progress+0x7d) [0x7f755310762d]
10  /opt/conda/envs/gdf/lib/libucp.so.0(ucp_worker_progress+0x5a) [0x7f75531c0c4a]
11  /opt/conda/envs/gdf/lib/python3.9/site-packages/ucp/_libs/ucx_api.cpython-39-x86_64-linux-gnu.so(+0x2b17a) [0x7f755326b17a]
12  /opt/conda/envs/gdf/bin/python(+0x14420c) [0x563fce6e120c]
13  /opt/conda/envs/gdf/bin/python(_PyEval_EvalFrameDefault+0x5dc5) [0x563fce6d1bf5]
14  /opt/conda/envs/gdf/bin/python(+0x12df94) [0x563fce6caf94]
15  /opt/conda/envs/gdf/bin/python(_PyFunction_Vectorcall+0xd9) [0x563fce6dc3f9]
16  /opt/conda/envs/gdf/bin/python(_PyEval_EvalFrameDefault+0x696) [0x563fce6cc4c6]
17  /opt/conda/envs/gdf/bin/python(+0x13f6a2) [0x563fce6dc6a2]
18  /opt/conda/envs/gdf/bin/python(+0x14ca43) [0x563fce6e9a43]
19  /opt/conda/envs/gdf/bin/python(+0x2580fc) [0x563fce7f50fc]
20  /opt/conda/envs/gdf/bin/python(+0xf248b) [0x563fce68f48b]
21  /opt/conda/envs/gdf/bin/python(+0x1366f3) [0x563fce6d36f3]
22  /opt/conda/envs/gdf/bin/python(_PyEval_EvalFrameDefault+0x58b4) [0x563fce6d16e4]
23  /opt/conda/envs/gdf/bin/python(+0x13f6a2) [0x563fce6dc6a2]
24  /opt/conda/envs/gdf/bin/python(_PyEval_EvalFrameDefault+0x696) [0x563fce6cc4c6]
25  /opt/conda/envs/gdf/bin/python(+0x13f6a2) [0x563fce6dc6a2]
26  /opt/conda/envs/gdf/bin/python(_PyEval_EvalFrameDefault+0x696) [0x563fce6cc4c6]
27  /opt/conda/envs/gdf/bin/python(+0x13f6a2) [0x563fce6dc6a2]
28  /opt/conda/envs/gdf/bin/python(_PyEval_EvalFrameDefault+0x696) [0x563fce6cc4c6]
29  /opt/conda/envs/gdf/bin/python(+0x13f6a2) [0x563fce6dc6a2]
30  /opt/conda/envs/gdf/bin/python(_PyEval_EvalFrameDefault+0x696) [0x563fce6cc4c6]
31  /opt/conda/envs/gdf/bin/python(+0x12df94) [0x563fce6caf94]
32  /opt/conda/envs/gdf/bin/python(_PyFunction_Vectorcall+0xd9) [0x563fce6dc3f9]
33  /opt/conda/envs/gdf/bin/python(_PyEval_EvalFrameDefault+0x4abe) [0x563fce6d08ee]
34  /opt/conda/envs/gdf/bin/python(+0x12df94) [0x563fce6caf94]
35  /opt/conda/envs/gdf/bin/python(+0x14c88b) [0x563fce6e988b]
36  /opt/conda/envs/gdf/bin/python(PyObject_Call+0xbc) [0x563fce6ea00c]
37  /opt/conda/envs/gdf/bin/python(+0x21073e) [0x563fce7ad73e]
38  /opt/conda/envs/gdf/bin/python(_PyObject_MakeTpCall+0x2ec) [0x563fce6d467c]
39  /opt/conda/envs/gdf/bin/python(_PyEval_EvalFrameDefault+0x45a6) [0x563fce6d03d6]
40  /opt/conda/envs/gdf/bin/python(+0x13f6a2) [0x563fce6dc6a2]
41  /opt/conda/envs/gdf/bin/python(+0x14c96c) [0x563fce6e996c]
42  /opt/conda/envs/gdf/bin/python(_PyEval_EvalFrameDefault+0x45a6) [0x563fce6d03d6]
43  /opt/conda/envs/gdf/bin/python(+0x13f6a2) [0x563fce6dc6a2]
44  /opt/conda/envs/gdf/bin/python(_PyEval_EvalFrameDefault+0x696) [0x563fce6cc4c6]
45  /opt/conda/envs/gdf/bin/python(+0x12df94) [0x563fce6caf94]
46  /opt/conda/envs/gdf/bin/python(_PyFunction_Vectorcall+0xd9) [0x563fce6dc3f9]
47  /opt/conda/envs/gdf/bin/python(_PyEval_EvalFrameDefault+0x696) [0x563fce6cc4c6]
48  /opt/conda/envs/gdf/bin/python(+0x13f6a2) [0x563fce6dc6a2]
49  /opt/conda/envs/gdf/bin/python(_PyEval_EvalFrameDefault+0x3e2) [0x563fce6cc212]
50  /opt/conda/envs/gdf/bin/python(+0x12df94) [0x563fce6caf94]
51  /opt/conda/envs/gdf/bin/python(_PyFunction_Vectorcall+0xd9) [0x563fce6dc3f9]
52  /opt/conda/envs/gdf/bin/python(_PyEval_EvalFrameDefault+0x11f2) [0x563fce6cd022]
53  /opt/conda/envs/gdf/bin/python(+0x12df94) [0x563fce6caf94]
54  /opt/conda/envs/gdf/bin/python(_PyEval_EvalCodeWithName+0x48) [0x563fce6cac68]
55  /opt/conda/envs/gdf/bin/python(PyEval_EvalCodeEx+0x39) [0x563fce6cac19]
56  /opt/conda/envs/gdf/bin/python(PyEval_EvalCode+0x1b) [0x563fce77820b]
57  /opt/conda/envs/gdf/bin/python(+0x2085fa) [0x563fce7a55fa]
58  /opt/conda/envs/gdf/bin/python(+0x204983) [0x563fce7a1983]
59  /opt/conda/envs/gdf/bin/python(PyRun_StringFlags+0x9a) [0x563fce79979a]
60  /opt/conda/envs/gdf/bin/python(PyRun_SimpleStringFlags+0x3c) [0x563fce79968c]
61  /opt/conda/envs/gdf/bin/python(Py_RunMain+0x267) [0x563fce7988c7]
=================================
[dgx13:70896:0:70896] Caught signal 11 (Segmentation fault: address not mapped to object at address 0x448)
==== backtrace (tid:  70896) ====
 0  /opt/conda/envs/gdf/lib/libucs.so.0(ucs_handle_error+0x2fd) [0x7f6dc5c0ff1d]
 1  /opt/conda/envs/gdf/lib/libucs.so.0(+0x29114) [0x7f6dc5c10114]
 2  /opt/conda/envs/gdf/lib/libucs.so.0(+0x292da) [0x7f6dc5c102da]
 3  /usr/lib/x86_64-linux-gnu/libpthread.so.0(+0x14420) [0x7f6e7f333420]
 4  /opt/conda/envs/gdf/lib/libucp.so.0(ucp_mem_type_unpack+0x14) [0x7f6dc5c895d4]
 5  /opt/conda/envs/gdf/lib/libucp.so.0(ucp_rndv_data_handler+0x4e9) [0x7f6dc5cae859]
 6  /opt/conda/envs/gdf/lib/libuct.so.0(+0x2042f) [0x7f6dc5bcb42f]
 7  /opt/conda/envs/gdf/lib/libuct.so.0(+0x23798) [0x7f6dc5bce798]
 8  /opt/conda/envs/gdf/lib/libucs.so.0(ucs_event_set_wait+0xb9) [0x7f6dc5c18989]
 9  /opt/conda/envs/gdf/lib/libuct.so.0(uct_tcp_iface_progress+0x7d) [0x7f6dc5bcd62d]
10  /opt/conda/envs/gdf/lib/libucp.so.0(ucp_worker_progress+0x5a) [0x7f6dc5c86c4a]
11  /opt/conda/envs/gdf/lib/python3.9/site-packages/ucp/_libs/ucx_api.cpython-39-x86_64-linux-gnu.so(+0x2b17a) [0x7f6dc5d3117a]
12  /opt/conda/envs/gdf/bin/python(+0x14420c) [0x56528e9bc20c]
13  /opt/conda/envs/gdf/bin/python(_PyEval_EvalFrameDefault+0x5dc5) [0x56528e9acbf5]
14  /opt/conda/envs/gdf/bin/python(+0x12df94) [0x56528e9a5f94]
15  /opt/conda/envs/gdf/bin/python(_PyFunction_Vectorcall+0xd9) [0x56528e9b73f9]
16  /opt/conda/envs/gdf/bin/python(_PyEval_EvalFrameDefault+0x696) [0x56528e9a74c6]
17  /opt/conda/envs/gdf/bin/python(+0x13f6a2) [0x56528e9b76a2]
18  /opt/conda/envs/gdf/bin/python(+0x14ca43) [0x56528e9c4a43]
19  /opt/conda/envs/gdf/bin/python(+0x2580fc) [0x56528ead00fc]
20  /opt/conda/envs/gdf/bin/python(+0xf248b) [0x56528e96a48b]
21  /opt/conda/envs/gdf/bin/python(+0x1366f3) [0x56528e9ae6f3]
22  /opt/conda/envs/gdf/bin/python(_PyEval_EvalFrameDefault+0x58b4) [0x56528e9ac6e4]
23  /opt/conda/envs/gdf/bin/python(+0x13f6a2) [0x56528e9b76a2]
24  /opt/conda/envs/gdf/bin/python(_PyEval_EvalFrameDefault+0x696) [0x56528e9a74c6]
25  /opt/conda/envs/gdf/bin/python(+0x13f6a2) [0x56528e9b76a2]
26  /opt/conda/envs/gdf/bin/python(_PyEval_EvalFrameDefault+0x696) [0x56528e9a74c6]
27  /opt/conda/envs/gdf/bin/python(+0x13f6a2) [0x56528e9b76a2]
28  /opt/conda/envs/gdf/bin/python(_PyEval_EvalFrameDefault+0x696) [0x56528e9a74c6]
29  /opt/conda/envs/gdf/bin/python(+0x13f6a2) [0x56528e9b76a2]
30  /opt/conda/envs/gdf/bin/python(_PyEval_EvalFrameDefault+0x696) [0x56528e9a74c6]
31  /opt/conda/envs/gdf/bin/python(+0x12df94) [0x56528e9a5f94]
32  /opt/conda/envs/gdf/bin/python(_PyFunction_Vectorcall+0xd9) [0x56528e9b73f9]
33  /opt/conda/envs/gdf/bin/python(_PyEval_EvalFrameDefault+0x4abe) [0x56528e9ab8ee]
34  /opt/conda/envs/gdf/bin/python(+0x12df94) [0x56528e9a5f94]
35  /opt/conda/envs/gdf/bin/python(+0x14c88b) [0x56528e9c488b]
36  /opt/conda/envs/gdf/bin/python(PyObject_Call+0xbc) [0x56528e9c500c]
37  /opt/conda/envs/gdf/bin/python(+0x21073e) [0x56528ea8873e]
38  /opt/conda/envs/gdf/bin/python(_PyObject_MakeTpCall+0x2ec) [0x56528e9af67c]
39  /opt/conda/envs/gdf/bin/python(_PyEval_EvalFrameDefault+0x45a6) [0x56528e9ab3d6]
40  /opt/conda/envs/gdf/bin/python(+0x13f6a2) [0x56528e9b76a2]
41  /opt/conda/envs/gdf/bin/python(+0x14c96c) [0x56528e9c496c]
42  /opt/conda/envs/gdf/bin/python(_PyEval_EvalFrameDefault+0x45a6) [0x56528e9ab3d6]
43  /opt/conda/envs/gdf/bin/python(+0x13f6a2) [0x56528e9b76a2]
44  /opt/conda/envs/gdf/bin/python(_PyEval_EvalFrameDefault+0x696) [0x56528e9a74c6]
45  /opt/conda/envs/gdf/bin/python(+0x12df94) [0x56528e9a5f94]
46  /opt/conda/envs/gdf/bin/python(_PyFunction_Vectorcall+0xd9) [0x56528e9b73f9]
47  /opt/conda/envs/gdf/bin/python(_PyEval_EvalFrameDefault+0x696) [0x56528e9a74c6]
48  /opt/conda/envs/gdf/bin/python(+0x13f6a2) [0x56528e9b76a2]
49  /opt/conda/envs/gdf/bin/python(_PyEval_EvalFrameDefault+0x3e2) [0x56528e9a7212]
50  /opt/conda/envs/gdf/bin/python(+0x12df94) [0x56528e9a5f94]
51  /opt/conda/envs/gdf/bin/python(_PyFunction_Vectorcall+0xd9) [0x56528e9b73f9]
52  /opt/conda/envs/gdf/bin/python(_PyEval_EvalFrameDefault+0x11f2) [0x56528e9a8022]
53  /opt/conda/envs/gdf/bin/python(+0x12df94) [0x56528e9a5f94]
54  /opt/conda/envs/gdf/bin/python(_PyEval_EvalCodeWithName+0x48) [0x56528e9a5c68]
55  /opt/conda/envs/gdf/bin/python(PyEval_EvalCodeEx+0x39) [0x56528e9a5c19]
56  /opt/conda/envs/gdf/bin/python(PyEval_EvalCode+0x1b) [0x56528ea5320b]
57  /opt/conda/envs/gdf/bin/python(+0x2085fa) [0x56528ea805fa]
58  /opt/conda/envs/gdf/bin/python(+0x204983) [0x56528ea7c983]
59  /opt/conda/envs/gdf/bin/python(PyRun_StringFlags+0x9a) [0x56528ea7479a]
60  /opt/conda/envs/gdf/bin/python(PyRun_SimpleStringFlags+0x3c) [0x56528ea7468c]
61  /opt/conda/envs/gdf/bin/python(Py_RunMain+0x267) [0x56528ea738c7]
=================================
[dgx13:70908:0:70908] Caught signal 11 (Segmentation fault: address not mapped to object at address 0x448)
==== backtrace (tid:  70908) ====
 0  /opt/conda/envs/gdf/lib/libucs.so.0(ucs_handle_error+0x2fd) [0x7fd9606aaf1d]
 1  /opt/conda/envs/gdf/lib/libucs.so.0(+0x29114) [0x7fd9606ab114]
 2  /opt/conda/envs/gdf/lib/libucs.so.0(+0x292da) [0x7fd9606ab2da]
 3  /usr/lib/x86_64-linux-gnu/libpthread.so.0(+0x14420) [0x7fd9f1f1c420]
 4  /opt/conda/envs/gdf/lib/libucp.so.0(ucp_mem_type_unpack+0x14) [0x7fd9607245d4]
 5  /opt/conda/envs/gdf/lib/libucp.so.0(ucp_rndv_data_handler+0x4e9) [0x7fd960749859]
 6  /opt/conda/envs/gdf/lib/libuct.so.0(+0x2042f) [0x7fd96066642f]
 7  /opt/conda/envs/gdf/lib/libuct.so.0(+0x23798) [0x7fd960669798]
 8  /opt/conda/envs/gdf/lib/libucs.so.0(ucs_event_set_wait+0xb9) [0x7fd9606b3989]
 9  /opt/conda/envs/gdf/lib/libuct.so.0(uct_tcp_iface_progress+0x7d) [0x7fd96066862d]
10  /opt/conda/envs/gdf/lib/libucp.so.0(ucp_worker_progress+0x5a) [0x7fd960721c4a]
11  /opt/conda/envs/gdf/lib/python3.9/site-packages/ucp/_libs/ucx_api.cpython-39-x86_64-linux-gnu.so(+0x2b17a) [0x7fd9607cc17a]
12  /opt/conda/envs/gdf/bin/python(+0x14420c) [0x5654a7ed820c]
13  /opt/conda/envs/gdf/bin/python(_PyEval_EvalFrameDefault+0x5dc5) [0x5654a7ec8bf5]
14  /opt/conda/envs/gdf/bin/python(+0x12df94) [0x5654a7ec1f94]
15  /opt/conda/envs/gdf/bin/python(_PyFunction_Vectorcall+0xd9) [0x5654a7ed33f9]
16  /opt/conda/envs/gdf/bin/python(_PyEval_EvalFrameDefault+0x696) [0x5654a7ec34c6]
17  /opt/conda/envs/gdf/bin/python(+0x13f6a2) [0x5654a7ed36a2]
18  /opt/conda/envs/gdf/bin/python(+0x14ca43) [0x5654a7ee0a43]
19  /opt/conda/envs/gdf/bin/python(+0x2580fc) [0x5654a7fec0fc]
20  /opt/conda/envs/gdf/bin/python(+0xf248b) [0x5654a7e8648b]
21  /opt/conda/envs/gdf/bin/python(+0x1366f3) [0x5654a7eca6f3]
22  /opt/conda/envs/gdf/bin/python(_PyEval_EvalFrameDefault+0x58b4) [0x5654a7ec86e4]
23  /opt/conda/envs/gdf/bin/python(+0x13f6a2) [0x5654a7ed36a2]
24  /opt/conda/envs/gdf/bin/python(_PyEval_EvalFrameDefault+0x696) [0x5654a7ec34c6]
25  /opt/conda/envs/gdf/bin/python(+0x13f6a2) [0x5654a7ed36a2]
26  /opt/conda/envs/gdf/bin/python(_PyEval_EvalFrameDefault+0x696) [0x5654a7ec34c6]
27  /opt/conda/envs/gdf/bin/python(+0x13f6a2) [0x5654a7ed36a2]
28  /opt/conda/envs/gdf/bin/python(_PyEval_EvalFrameDefault+0x696) [0x5654a7ec34c6]
29  /opt/conda/envs/gdf/bin/python(+0x13f6a2) [0x5654a7ed36a2]
30  /opt/conda/envs/gdf/bin/python(_PyEval_EvalFrameDefault+0x696) [0x5654a7ec34c6]
31  /opt/conda/envs/gdf/bin/python(+0x12df94) [0x5654a7ec1f94]
32  /opt/conda/envs/gdf/bin/python(_PyFunction_Vectorcall+0xd9) [0x5654a7ed33f9]
33  /opt/conda/envs/gdf/bin/python(_PyEval_EvalFrameDefault+0x4abe) [0x5654a7ec78ee]
34  /opt/conda/envs/gdf/bin/python(+0x12df94) [0x5654a7ec1f94]
35  /opt/conda/envs/gdf/bin/python(+0x14c88b) [0x5654a7ee088b]
36  /opt/conda/envs/gdf/bin/python(PyObject_Call+0xbc) [0x5654a7ee100c]
37  /opt/conda/envs/gdf/bin/python(+0x21073e) [0x5654a7fa473e]
38  /opt/conda/envs/gdf/bin/python(_PyObject_MakeTpCall+0x2ec) [0x5654a7ecb67c]
39  /opt/conda/envs/gdf/bin/python(_PyEval_EvalFrameDefault+0x45a6) [0x5654a7ec73d6]
40  /opt/conda/envs/gdf/bin/python(+0x13f6a2) [0x5654a7ed36a2]
41  /opt/conda/envs/gdf/bin/python(+0x14c96c) [0x5654a7ee096c]
42  /opt/conda/envs/gdf/bin/python(_PyEval_EvalFrameDefault+0x45a6) [0x5654a7ec73d6]
43  /opt/conda/envs/gdf/bin/python(+0x13f6a2) [0x5654a7ed36a2]
44  /opt/conda/envs/gdf/bin/python(_PyEval_EvalFrameDefault+0x696) [0x5654a7ec34c6]
45  /opt/conda/envs/gdf/bin/python(+0x12df94) [0x5654a7ec1f94]
46  /opt/conda/envs/gdf/bin/python(_PyFunction_Vectorcall+0xd9) [0x5654a7ed33f9]
47  /opt/conda/envs/gdf/bin/python(_PyEval_EvalFrameDefault+0x696) [0x5654a7ec34c6]
48  /opt/conda/envs/gdf/bin/python(+0x13f6a2) [0x5654a7ed36a2]
49  /opt/conda/envs/gdf/bin/python(_PyEval_EvalFrameDefault+0x3e2) [0x5654a7ec3212]
50  /opt/conda/envs/gdf/bin/python(+0x12df94) [0x5654a7ec1f94]
51  /opt/conda/envs/gdf/bin/python(_PyFunction_Vectorcall+0xd9) [0x5654a7ed33f9]
52  /opt/conda/envs/gdf/bin/python(_PyEval_EvalFrameDefault+0x11f2) [0x5654a7ec4022]
53  /opt/conda/envs/gdf/bin/python(+0x12df94) [0x5654a7ec1f94]
54  /opt/conda/envs/gdf/bin/python(_PyEval_EvalCodeWithName+0x48) [0x5654a7ec1c68]
55  /opt/conda/envs/gdf/bin/python(PyEval_EvalCodeEx+0x39) [0x5654a7ec1c19]
56  /opt/conda/envs/gdf/bin/python(PyEval_EvalCode+0x1b) [0x5654a7f6f20b]
57  /opt/conda/envs/gdf/bin/python(+0x2085fa) [0x5654a7f9c5fa]
58  /opt/conda/envs/gdf/bin/python(+0x204983) [0x5654a7f98983]
59  /opt/conda/envs/gdf/bin/python(PyRun_StringFlags+0x9a) [0x5654a7f9079a]
60  /opt/conda/envs/gdf/bin/python(PyRun_SimpleStringFlags+0x3c) [0x5654a7f9068c]
61  /opt/conda/envs/gdf/bin/python(Py_RunMain+0x267) [0x5654a7f8f8c7]
=================================
2023-08-11 06:19:50,524 - distributed.worker - ERROR - failed during get data with ucx://127.0.0.1:55709 -> ucx://127.0.0.1:51275
Traceback (most recent call last):
  File "/opt/conda/envs/gdf/lib/python3.9/site-packages/distributed/comm/ucx.py", line 333, in write
    await self.ep.send(each_frame)
  File "/opt/conda/envs/gdf/lib/python3.9/site-packages/ucp/core.py", line 650, in send
    return await comm.tag_send(self._ep, buffer, nbytes, tag, name=log)
ucp._libs.exceptions.UCXError: <[Send #007] ep: 0x7f20c4500140, tag: 0xe337e276754e2040, nbytes: 50000000, type: <class 'cupy.ndarray'>>: Connection reset by remote peer

During handling of the above exception, another exception occurred:

Traceback (most recent call last):
  File "/opt/conda/envs/gdf/lib/python3.9/site-packages/distributed/worker.py", line 1792, in get_data
    compressed = await comm.write(msg, serializers=serializers)
  File "/opt/conda/envs/gdf/lib/python3.9/site-packages/distributed/utils.py", line 752, in wrapper
    return await func(*args, **kwargs)
  File "/opt/conda/envs/gdf/lib/python3.9/site-packages/distributed/comm/ucx.py", line 337, in write
    raise CommClosedError("While writing, the connection was closed")
distributed.comm.core.CommClosedError: While writing, the connection was closed
2023-08-11 06:19:50,525 - distributed.worker - ERROR - failed during get data with ucx://127.0.0.1:55709 -> ucx://127.0.0.1:53679
Traceback (most recent call last):
  File "/opt/conda/envs/gdf/lib/python3.9/site-packages/distributed/comm/ucx.py", line 333, in write
    await self.ep.send(each_frame)
  File "/opt/conda/envs/gdf/lib/python3.9/site-packages/ucp/core.py", line 650, in send
    return await comm.tag_send(self._ep, buffer, nbytes, tag, name=log)
ucp._libs.exceptions.UCXError: <[Send #007] ep: 0x7f20c4500380, tag: 0x355da980f5c0f19f, nbytes: 50000000, type: <class 'cupy.ndarray'>>: Connection reset by remote peer

During handling of the above exception, another exception occurred:

Traceback (most recent call last):
  File "/opt/conda/envs/gdf/lib/python3.9/site-packages/distributed/worker.py", line 1792, in get_data
    compressed = await comm.write(msg, serializers=serializers)
  File "/opt/conda/envs/gdf/lib/python3.9/site-packages/distributed/utils.py", line 752, in wrapper
    return await func(*args, **kwargs)
  File "/opt/conda/envs/gdf/lib/python3.9/site-packages/distributed/comm/ucx.py", line 337, in write
    raise CommClosedError("While writing, the connection was closed")
distributed.comm.core.CommClosedError: While writing, the connection was closed
2023-08-11 06:19:50,604 - distributed.nanny - WARNING - Restarting worker
2023-08-11 06:19:50,605 - distributed.nanny - WARNING - Restarting worker
2023-08-11 06:19:50,656 - distributed.worker - ERROR - failed during get data with ucx://127.0.0.1:51723 -> ucx://127.0.0.1:50589
Traceback (most recent call last):
  File "/opt/conda/envs/gdf/lib/python3.9/site-packages/distributed/comm/ucx.py", line 333, in write
    await self.ep.send(each_frame)
  File "/opt/conda/envs/gdf/lib/python3.9/site-packages/ucp/core.py", line 650, in send
    return await comm.tag_send(self._ep, buffer, nbytes, tag, name=log)
ucp._libs.exceptions.UCXError: <[Send #007] ep: 0x7f3a1c790240, tag: 0xfdd1b592d592eda3, nbytes: 50000000, type: <class 'cupy.ndarray'>>: Connection reset by remote peer

During handling of the above exception, another exception occurred:

Traceback (most recent call last):
  File "/opt/conda/envs/gdf/lib/python3.9/site-packages/distributed/worker.py", line 1792, in get_data
    compressed = await comm.write(msg, serializers=serializers)
  File "/opt/conda/envs/gdf/lib/python3.9/site-packages/distributed/utils.py", line 752, in wrapper
    return await func(*args, **kwargs)
  File "/opt/conda/envs/gdf/lib/python3.9/site-packages/distributed/comm/ucx.py", line 337, in write
    raise CommClosedError("While writing, the connection was closed")
distributed.comm.core.CommClosedError: While writing, the connection was closed
2023-08-11 06:19:50,704 - distributed.nanny - WARNING - Restarting worker
2023-08-11 06:19:52,092 - distributed.preloading - INFO - Creating preload: dask_cuda.initialize
2023-08-11 06:19:52,092 - distributed.preloading - INFO - Import preload module: dask_cuda.initialize
2023-08-11 06:19:52,097 - distributed.preloading - INFO - Creating preload: dask_cuda.initialize
2023-08-11 06:19:52,097 - distributed.preloading - INFO - Import preload module: dask_cuda.initialize
2023-08-11 06:19:52,194 - distributed.preloading - INFO - Creating preload: dask_cuda.initialize
2023-08-11 06:19:52,194 - distributed.preloading - INFO - Import preload module: dask_cuda.initialize
[dgx13:71011:0:71011] Caught signal 11 (Segmentation fault: address not mapped to object at address 0x448)
==== backtrace (tid:  71011) ====
 0  /opt/conda/envs/gdf/lib/libucs.so.0(ucs_handle_error+0x2fd) [0x7f7897501f1d]
 1  /opt/conda/envs/gdf/lib/libucs.so.0(+0x29114) [0x7f7897502114]
 2  /opt/conda/envs/gdf/lib/libucs.so.0(+0x292da) [0x7f78975022da]
 3  /usr/lib/x86_64-linux-gnu/libpthread.so.0(+0x14420) [0x7f793abfa420]
 4  /opt/conda/envs/gdf/lib/libucp.so.0(ucp_mem_type_unpack+0x14) [0x7f789757b5d4]
 5  /opt/conda/envs/gdf/lib/libucp.so.0(ucp_rndv_data_handler+0x4e9) [0x7f78975a0859]
 6  /opt/conda/envs/gdf/lib/libuct.so.0(+0x2042f) [0x7f78974bd42f]
 7  /opt/conda/envs/gdf/lib/libuct.so.0(+0x23798) [0x7f78974c0798]
 8  /opt/conda/envs/gdf/lib/libucs.so.0(ucs_event_set_wait+0xb9) [0x7f789750a989]
 9  /opt/conda/envs/gdf/lib/libuct.so.0(uct_tcp_iface_progress+0x7d) [0x7f78974bf62d]
10  /opt/conda/envs/gdf/lib/libucp.so.0(ucp_worker_progress+0x5a) [0x7f7897578c4a]
11  /opt/conda/envs/gdf/lib/python3.9/site-packages/ucp/_libs/ucx_api.cpython-39-x86_64-linux-gnu.so(+0x2b17a) [0x7f789762317a]
12  /opt/conda/envs/gdf/bin/python(+0x14420c) [0x558f8dbea20c]
13  /opt/conda/envs/gdf/bin/python(_PyEval_EvalFrameDefault+0x5dc5) [0x558f8dbdabf5]
14  /opt/conda/envs/gdf/bin/python(+0x12df94) [0x558f8dbd3f94]
15  /opt/conda/envs/gdf/bin/python(_PyFunction_Vectorcall+0xd9) [0x558f8dbe53f9]
16  /opt/conda/envs/gdf/bin/python(_PyEval_EvalFrameDefault+0x696) [0x558f8dbd54c6]
17  /opt/conda/envs/gdf/bin/python(+0x13f6a2) [0x558f8dbe56a2]
18  /opt/conda/envs/gdf/bin/python(+0x14ca43) [0x558f8dbf2a43]
19  /opt/conda/envs/gdf/bin/python(+0x2580fc) [0x558f8dcfe0fc]
20  /opt/conda/envs/gdf/bin/python(+0xf248b) [0x558f8db9848b]
21  /opt/conda/envs/gdf/bin/python(+0x1366f3) [0x558f8dbdc6f3]
22  /opt/conda/envs/gdf/bin/python(_PyEval_EvalFrameDefault+0x58b4) [0x558f8dbda6e4]
23  /opt/conda/envs/gdf/bin/python(+0x13f6a2) [0x558f8dbe56a2]
24  /opt/conda/envs/gdf/bin/python(_PyEval_EvalFrameDefault+0x696) [0x558f8dbd54c6]
25  /opt/conda/envs/gdf/bin/python(+0x13f6a2) [0x558f8dbe56a2]
26  /opt/conda/envs/gdf/bin/python(_PyEval_EvalFrameDefault+0x696) [0x558f8dbd54c6]
27  /opt/conda/envs/gdf/bin/python(+0x13f6a2) [0x558f8dbe56a2]
28  /opt/conda/envs/gdf/bin/python(_PyEval_EvalFrameDefault+0x696) [0x558f8dbd54c6]
29  /opt/conda/envs/gdf/bin/python(+0x13f6a2) [0x558f8dbe56a2]
30  /opt/conda/envs/gdf/bin/python(_PyEval_EvalFrameDefault+0x696) [0x558f8dbd54c6]
31  /opt/conda/envs/gdf/bin/python(+0x12df94) [0x558f8dbd3f94]
32  /opt/conda/envs/gdf/bin/python(_PyFunction_Vectorcall+0xd9) [0x558f8dbe53f9]
33  /opt/conda/envs/gdf/bin/python(_PyEval_EvalFrameDefault+0x4abe) [0x558f8dbd98ee]
34  /opt/conda/envs/gdf/bin/python(+0x12df94) [0x558f8dbd3f94]
35  /opt/conda/envs/gdf/bin/python(+0x14c88b) [0x558f8dbf288b]
36  /opt/conda/envs/gdf/bin/python(PyObject_Call+0xbc) [0x558f8dbf300c]
37  /opt/conda/envs/gdf/bin/python(+0x21073e) [0x558f8dcb673e]
38  /opt/conda/envs/gdf/bin/python(_PyObject_MakeTpCall+0x2ec) [0x558f8dbdd67c]
39  /opt/conda/envs/gdf/bin/python(_PyEval_EvalFrameDefault+0x45a6) [0x558f8dbd93d6]
40  /opt/conda/envs/gdf/bin/python(+0x13f6a2) [0x558f8dbe56a2]
41  /opt/conda/envs/gdf/bin/python(+0x14c96c) [0x558f8dbf296c]
42  /opt/conda/envs/gdf/bin/python(_PyEval_EvalFrameDefault+0x45a6) [0x558f8dbd93d6]
43  /opt/conda/envs/gdf/bin/python(+0x13f6a2) [0x558f8dbe56a2]
44  /opt/conda/envs/gdf/bin/python(_PyEval_EvalFrameDefault+0x696) [0x558f8dbd54c6]
45  /opt/conda/envs/gdf/bin/python(+0x12df94) [0x558f8dbd3f94]
46  /opt/conda/envs/gdf/bin/python(_PyFunction_Vectorcall+0xd9) [0x558f8dbe53f9]
47  /opt/conda/envs/gdf/bin/python(_PyEval_EvalFrameDefault+0x696) [0x558f8dbd54c6]
48  /opt/conda/envs/gdf/bin/python(+0x13f6a2) [0x558f8dbe56a2]
49  /opt/conda/envs/gdf/bin/python(_PyEval_EvalFrameDefault+0x3e2) [0x558f8dbd5212]
50  /opt/conda/envs/gdf/bin/python(+0x12df94) [0x558f8dbd3f94]
51  /opt/conda/envs/gdf/bin/python(_PyFunction_Vectorcall+0xd9) [0x558f8dbe53f9]
52  /opt/conda/envs/gdf/bin/python(_PyEval_EvalFrameDefault+0x11f2) [0x558f8dbd6022]
53  /opt/conda/envs/gdf/bin/python(+0x12df94) [0x558f8dbd3f94]
54  /opt/conda/envs/gdf/bin/python(_PyEval_EvalCodeWithName+0x48) [0x558f8dbd3c68]
55  /opt/conda/envs/gdf/bin/python(PyEval_EvalCodeEx+0x39) [0x558f8dbd3c19]
56  /opt/conda/envs/gdf/bin/python(PyEval_EvalCode+0x1b) [0x558f8dc8120b]
57  /opt/conda/envs/gdf/bin/python(+0x2085fa) [0x558f8dcae5fa]
58  /opt/conda/envs/gdf/bin/python(+0x204983) [0x558f8dcaa983]
59  /opt/conda/envs/gdf/bin/python(PyRun_StringFlags+0x9a) [0x558f8dca279a]
60  /opt/conda/envs/gdf/bin/python(PyRun_SimpleStringFlags+0x3c) [0x558f8dca268c]
61  /opt/conda/envs/gdf/bin/python(Py_RunMain+0x267) [0x558f8dca18c7]
=================================
2023-08-11 06:19:55,395 - distributed.worker - ERROR - failed during get data with ucx://127.0.0.1:51723 -> ucx://127.0.0.1:42295
Traceback (most recent call last):
  File "/opt/conda/envs/gdf/lib/python3.9/site-packages/distributed/comm/ucx.py", line 333, in write
    await self.ep.send(each_frame)
  File "/opt/conda/envs/gdf/lib/python3.9/site-packages/ucp/core.py", line 650, in send
    return await comm.tag_send(self._ep, buffer, nbytes, tag, name=log)
ucp._libs.exceptions.UCXError: <[Send #007] ep: 0x7f3a1c790100, tag: 0x3feb9e8ce7187368, nbytes: 50000000, type: <class 'cupy.ndarray'>>: Connection reset by remote peer

During handling of the above exception, another exception occurred:

Traceback (most recent call last):
  File "/opt/conda/envs/gdf/lib/python3.9/site-packages/distributed/worker.py", line 1792, in get_data
    compressed = await comm.write(msg, serializers=serializers)
  File "/opt/conda/envs/gdf/lib/python3.9/site-packages/distributed/utils.py", line 752, in wrapper
    return await func(*args, **kwargs)
  File "/opt/conda/envs/gdf/lib/python3.9/site-packages/distributed/comm/ucx.py", line 337, in write
    raise CommClosedError("While writing, the connection was closed")
distributed.comm.core.CommClosedError: While writing, the connection was closed
2023-08-11 06:19:55,439 - distributed.nanny - WARNING - Restarting worker
[dgx13:71008:0:71008] Caught signal 11 (Segmentation fault: address not mapped to object at address 0x448)
==== backtrace (tid:  71008) ====
 0  /opt/conda/envs/gdf/lib/libucs.so.0(ucs_handle_error+0x2fd) [0x7ffb3805df1d]
 1  /opt/conda/envs/gdf/lib/libucs.so.0(+0x29114) [0x7ffb3805e114]
 2  /opt/conda/envs/gdf/lib/libucs.so.0(+0x292da) [0x7ffb3805e2da]
 3  /usr/lib/x86_64-linux-gnu/libpthread.so.0(+0x14420) [0x7ffbc8c7a420]
 4  /opt/conda/envs/gdf/lib/libucp.so.0(ucp_mem_type_unpack+0x14) [0x7ffb2557b5d4]
 5  /opt/conda/envs/gdf/lib/libucp.so.0(ucp_rndv_data_handler+0x4e9) [0x7ffb255a0859]
 6  /opt/conda/envs/gdf/lib/libuct.so.0(+0x2042f) [0x7ffb2551942f]
 7  /opt/conda/envs/gdf/lib/libuct.so.0(+0x23798) [0x7ffb2551c798]
 8  /opt/conda/envs/gdf/lib/libucs.so.0(ucs_event_set_wait+0xb9) [0x7ffb38066989]
 9  /opt/conda/envs/gdf/lib/libuct.so.0(uct_tcp_iface_progress+0x7d) [0x7ffb2551b62d]
10  /opt/conda/envs/gdf/lib/libucp.so.0(ucp_worker_progress+0x5a) [0x7ffb25578c4a]
11  /opt/conda/envs/gdf/lib/python3.9/site-packages/ucp/_libs/ucx_api.cpython-39-x86_64-linux-gnu.so(+0x2b17a) [0x7ffb2562317a]
12  /opt/conda/envs/gdf/bin/python(+0x14420c) [0x5562e4d1620c]
13  /opt/conda/envs/gdf/bin/python(_PyEval_EvalFrameDefault+0x5dc5) [0x5562e4d06bf5]
14  /opt/conda/envs/gdf/bin/python(+0x12df94) [0x5562e4cfff94]
15  /opt/conda/envs/gdf/bin/python(_PyFunction_Vectorcall+0xd9) [0x5562e4d113f9]
16  /opt/conda/envs/gdf/bin/python(_PyEval_EvalFrameDefault+0x696) [0x5562e4d014c6]
17  /opt/conda/envs/gdf/bin/python(+0x13f6a2) [0x5562e4d116a2]
18  /opt/conda/envs/gdf/bin/python(+0x14ca43) [0x5562e4d1ea43]
19  /opt/conda/envs/gdf/bin/python(+0x2580fc) [0x5562e4e2a0fc]
20  /opt/conda/envs/gdf/bin/python(+0xf248b) [0x5562e4cc448b]
21  /opt/conda/envs/gdf/bin/python(+0x1366f3) [0x5562e4d086f3]
22  /opt/conda/envs/gdf/bin/python(_PyEval_EvalFrameDefault+0x58b4) [0x5562e4d066e4]
23  /opt/conda/envs/gdf/bin/python(+0x13f6a2) [0x5562e4d116a2]
24  /opt/conda/envs/gdf/bin/python(_PyEval_EvalFrameDefault+0x696) [0x5562e4d014c6]
25  /opt/conda/envs/gdf/bin/python(+0x13f6a2) [0x5562e4d116a2]
26  /opt/conda/envs/gdf/bin/python(_PyEval_EvalFrameDefault+0x696) [0x5562e4d014c6]
27  /opt/conda/envs/gdf/bin/python(+0x13f6a2) [0x5562e4d116a2]
28  /opt/conda/envs/gdf/bin/python(_PyEval_EvalFrameDefault+0x696) [0x5562e4d014c6]
29  /opt/conda/envs/gdf/bin/python(+0x13f6a2) [0x5562e4d116a2]
30  /opt/conda/envs/gdf/bin/python(_PyEval_EvalFrameDefault+0x696) [0x5562e4d014c6]
31  /opt/conda/envs/gdf/bin/python(+0x12df94) [0x5562e4cfff94]
32  /opt/conda/envs/gdf/bin/python(_PyFunction_Vectorcall+0xd9) [0x5562e4d113f9]
33  /opt/conda/envs/gdf/bin/python(_PyEval_EvalFrameDefault+0x4abe) [0x5562e4d058ee]
34  /opt/conda/envs/gdf/bin/python(+0x12df94) [0x5562e4cfff94]
35  /opt/conda/envs/gdf/bin/python(+0x14c88b) [0x5562e4d1e88b]
36  /opt/conda/envs/gdf/bin/python(PyObject_Call+0xbc) [0x5562e4d1f00c]
37  /opt/conda/envs/gdf/bin/python(+0x21073e) [0x5562e4de273e]
38  /opt/conda/envs/gdf/bin/python(_PyObject_MakeTpCall+0x2ec) [0x5562e4d0967c]
39  /opt/conda/envs/gdf/bin/python(_PyEval_EvalFrameDefault+0x45a6) [0x5562e4d053d6]
40  /opt/conda/envs/gdf/bin/python(+0x13f6a2) [0x5562e4d116a2]
41  /opt/conda/envs/gdf/bin/python(+0x14c96c) [0x5562e4d1e96c]
42  /opt/conda/envs/gdf/bin/python(_PyEval_EvalFrameDefault+0x45a6) [0x5562e4d053d6]
43  /opt/conda/envs/gdf/bin/python(+0x13f6a2) [0x5562e4d116a2]
44  /opt/conda/envs/gdf/bin/python(_PyEval_EvalFrameDefault+0x696) [0x5562e4d014c6]
45  /opt/conda/envs/gdf/bin/python(+0x12df94) [0x5562e4cfff94]
46  /opt/conda/envs/gdf/bin/python(_PyFunction_Vectorcall+0xd9) [0x5562e4d113f9]
47  /opt/conda/envs/gdf/bin/python(_PyEval_EvalFrameDefault+0x696) [0x5562e4d014c6]
48  /opt/conda/envs/gdf/bin/python(+0x13f6a2) [0x5562e4d116a2]
49  /opt/conda/envs/gdf/bin/python(_PyEval_EvalFrameDefault+0x3e2) [0x5562e4d01212]
50  /opt/conda/envs/gdf/bin/python(+0x12df94) [0x5562e4cfff94]
51  /opt/conda/envs/gdf/bin/python(_PyFunction_Vectorcall+0xd9) [0x5562e4d113f9]
52  /opt/conda/envs/gdf/bin/python(_PyEval_EvalFrameDefault+0x11f2) [0x5562e4d02022]
53  /opt/conda/envs/gdf/bin/python(+0x12df94) [0x5562e4cfff94]
54  /opt/conda/envs/gdf/bin/python(_PyEval_EvalCodeWithName+0x48) [0x5562e4cffc68]
55  /opt/conda/envs/gdf/bin/python(PyEval_EvalCodeEx+0x39) [0x5562e4cffc19]
56  /opt/conda/envs/gdf/bin/python(PyEval_EvalCode+0x1b) [0x5562e4dad20b]
57  /opt/conda/envs/gdf/bin/python(+0x2085fa) [0x5562e4dda5fa]
58  /opt/conda/envs/gdf/bin/python(+0x204983) [0x5562e4dd6983]
59  /opt/conda/envs/gdf/bin/python(PyRun_StringFlags+0x9a) [0x5562e4dce79a]
60  /opt/conda/envs/gdf/bin/python(PyRun_SimpleStringFlags+0x3c) [0x5562e4dce68c]
61  /opt/conda/envs/gdf/bin/python(Py_RunMain+0x267) [0x5562e4dcd8c7]
=================================
2023-08-11 06:19:55,871 - distributed.worker - ERROR - failed during get data with ucx://127.0.0.1:42389 -> ucx://127.0.0.1:39529
Traceback (most recent call last):
  File "/opt/conda/envs/gdf/lib/python3.9/site-packages/distributed/comm/ucx.py", line 333, in write
    await self.ep.send(each_frame)
  File "/opt/conda/envs/gdf/lib/python3.9/site-packages/ucp/core.py", line 650, in send
    return await comm.tag_send(self._ep, buffer, nbytes, tag, name=log)
ucp._libs.exceptions.UCXError: <[Send #007] ep: 0x7f60a1d1b280, tag: 0xa82fbe960177c8b9, nbytes: 50000000, type: <class 'cupy.ndarray'>>: Connection reset by remote peer

During handling of the above exception, another exception occurred:

Traceback (most recent call last):
  File "/opt/conda/envs/gdf/lib/python3.9/site-packages/distributed/worker.py", line 1792, in get_data
    compressed = await comm.write(msg, serializers=serializers)
  File "/opt/conda/envs/gdf/lib/python3.9/site-packages/distributed/utils.py", line 752, in wrapper
    return await func(*args, **kwargs)
  File "/opt/conda/envs/gdf/lib/python3.9/site-packages/distributed/comm/ucx.py", line 337, in write
    raise CommClosedError("While writing, the connection was closed")
distributed.comm.core.CommClosedError: While writing, the connection was closed
2023-08-11 06:19:55,909 - distributed.nanny - WARNING - Restarting worker
[dgx13:70916:0:70916] Caught signal 11 (Segmentation fault: address not mapped to object at address 0x448)
==== backtrace (tid:  70916) ====
 0  /opt/conda/envs/gdf/lib/libucs.so.0(ucs_handle_error+0x2fd) [0x7f10fcd4cf1d]
 1  /opt/conda/envs/gdf/lib/libucs.so.0(+0x29114) [0x7f10fcd4d114]
 2  /opt/conda/envs/gdf/lib/libucs.so.0(+0x292da) [0x7f10fcd4d2da]
 3  /usr/lib/x86_64-linux-gnu/libpthread.so.0(+0x14420) [0x7f118e5a9420]
 4  /opt/conda/envs/gdf/lib/libucp.so.0(ucp_mem_type_unpack+0x14) [0x7f10fcdc65d4]
 5  /opt/conda/envs/gdf/lib/libucp.so.0(ucp_rndv_data_handler+0x4e9) [0x7f10fcdeb859]
 6  /opt/conda/envs/gdf/lib/libuct.so.0(+0x2042f) [0x7f10fcd0842f]
 7  /opt/conda/envs/gdf/lib/libuct.so.0(+0x23798) [0x7f10fcd0b798]
 8  /opt/conda/envs/gdf/lib/libucs.so.0(ucs_event_set_wait+0xb9) [0x7f10fcd55989]
 9  /opt/conda/envs/gdf/lib/libuct.so.0(uct_tcp_iface_progress+0x7d) [0x7f10fcd0a62d]
10  /opt/conda/envs/gdf/lib/libucp.so.0(ucp_worker_progress+0x5a) [0x7f10fcdc3c4a]
11  /opt/conda/envs/gdf/lib/python3.9/site-packages/ucp/_libs/ucx_api.cpython-39-x86_64-linux-gnu.so(+0x2b17a) [0x7f10fce6e17a]
12  /opt/conda/envs/gdf/bin/python(+0x14420c) [0x562f7655a20c]
13  /opt/conda/envs/gdf/bin/python(_PyEval_EvalFrameDefault+0x5dc5) [0x562f7654abf5]
14  /opt/conda/envs/gdf/bin/python(+0x12df94) [0x562f76543f94]
15  /opt/conda/envs/gdf/bin/python(_PyFunction_Vectorcall+0xd9) [0x562f765553f9]
16  /opt/conda/envs/gdf/bin/python(_PyEval_EvalFrameDefault+0x696) [0x562f765454c6]
17  /opt/conda/envs/gdf/bin/python(+0x13f6a2) [0x562f765556a2]
18  /opt/conda/envs/gdf/bin/python(+0x14ca43) [0x562f76562a43]
19  /opt/conda/envs/gdf/bin/python(+0x2580fc) [0x562f7666e0fc]
20  /opt/conda/envs/gdf/bin/python(+0xf248b) [0x562f7650848b]
21  /opt/conda/envs/gdf/bin/python(+0x1366f3) [0x562f7654c6f3]
22  /opt/conda/envs/gdf/bin/python(_PyEval_EvalFrameDefault+0x58b4) [0x562f7654a6e4]
23  /opt/conda/envs/gdf/bin/python(+0x13f6a2) [0x562f765556a2]
24  /opt/conda/envs/gdf/bin/python(_PyEval_EvalFrameDefault+0x696) [0x562f765454c6]
25  /opt/conda/envs/gdf/bin/python(+0x13f6a2) [0x562f765556a2]
26  /opt/conda/envs/gdf/bin/python(_PyEval_EvalFrameDefault+0x696) [0x562f765454c6]
27  /opt/conda/envs/gdf/bin/python(+0x13f6a2) [0x562f765556a2]
28  /opt/conda/envs/gdf/bin/python(_PyEval_EvalFrameDefault+0x696) [0x562f765454c6]
29  /opt/conda/envs/gdf/bin/python(+0x13f6a2) [0x562f765556a2]
30  /opt/conda/envs/gdf/bin/python(_PyEval_EvalFrameDefault+0x696) [0x562f765454c6]
31  /opt/conda/envs/gdf/bin/python(+0x12df94) [0x562f76543f94]
32  /opt/conda/envs/gdf/bin/python(_PyFunction_Vectorcall+0xd9) [0x562f765553f9]
33  /opt/conda/envs/gdf/bin/python(_PyEval_EvalFrameDefault+0x4abe) [0x562f765498ee]
34  /opt/conda/envs/gdf/bin/python(+0x12df94) [0x562f76543f94]
35  /opt/conda/envs/gdf/bin/python(+0x14c88b) [0x562f7656288b]
36  /opt/conda/envs/gdf/bin/python(PyObject_Call+0xbc) [0x562f7656300c]
37  /opt/conda/envs/gdf/bin/python(+0x21073e) [0x562f7662673e]
38  /opt/conda/envs/gdf/bin/python(_PyObject_MakeTpCall+0x2ec) [0x562f7654d67c]
39  /opt/conda/envs/gdf/bin/python(_PyEval_EvalFrameDefault+0x45a6) [0x562f765493d6]
40  /opt/conda/envs/gdf/bin/python(+0x13f6a2) [0x562f765556a2]
41  /opt/conda/envs/gdf/bin/python(+0x14c96c) [0x562f7656296c]
42  /opt/conda/envs/gdf/bin/python(_PyEval_EvalFrameDefault+0x45a6) [0x562f765493d6]
43  /opt/conda/envs/gdf/bin/python(+0x13f6a2) [0x562f765556a2]
44  /opt/conda/envs/gdf/bin/python(_PyEval_EvalFrameDefault+0x696) [0x562f765454c6]
45  /opt/conda/envs/gdf/bin/python(+0x12df94) [0x562f76543f94]
46  /opt/conda/envs/gdf/bin/python(_PyFunction_Vectorcall+0xd9) [0x562f765553f9]
47  /opt/conda/envs/gdf/bin/python(_PyEval_EvalFrameDefault+0x696) [0x562f765454c6]
48  /opt/conda/envs/gdf/bin/python(+0x13f6a2) [0x562f765556a2]
49  /opt/conda/envs/gdf/bin/python(_PyEval_EvalFrameDefault+0x3e2) [0x562f76545212]
50  /opt/conda/envs/gdf/bin/python(+0x12df94) [0x562f76543f94]
51  /opt/conda/envs/gdf/bin/python(_PyFunction_Vectorcall+0xd9) [0x562f765553f9]
52  /opt/conda/envs/gdf/bin/python(_PyEval_EvalFrameDefault+0x11f2) [0x562f76546022]
53  /opt/conda/envs/gdf/bin/python(+0x12df94) [0x562f76543f94]
54  /opt/conda/envs/gdf/bin/python(_PyEval_EvalCodeWithName+0x48) [0x562f76543c68]
55  /opt/conda/envs/gdf/bin/python(PyEval_EvalCodeEx+0x39) [0x562f76543c19]
56  /opt/conda/envs/gdf/bin/python(PyEval_EvalCode+0x1b) [0x562f765f120b]
57  /opt/conda/envs/gdf/bin/python(+0x2085fa) [0x562f7661e5fa]
58  /opt/conda/envs/gdf/bin/python(+0x204983) [0x562f7661a983]
59  /opt/conda/envs/gdf/bin/python(PyRun_StringFlags+0x9a) [0x562f7661279a]
60  /opt/conda/envs/gdf/bin/python(PyRun_SimpleStringFlags+0x3c) [0x562f7661268c]
61  /opt/conda/envs/gdf/bin/python(Py_RunMain+0x267) [0x562f766118c7]
=================================
2023-08-11 06:19:56,168 - distributed.worker - ERROR - failed during get data with ucx://127.0.0.1:42389 -> ucx://127.0.0.1:34735
Traceback (most recent call last):
  File "/opt/conda/envs/gdf/lib/python3.9/site-packages/distributed/comm/ucx.py", line 333, in write
    await self.ep.send(each_frame)
  File "/opt/conda/envs/gdf/lib/python3.9/site-packages/ucp/core.py", line 650, in send
    return await comm.tag_send(self._ep, buffer, nbytes, tag, name=log)
ucp._libs.exceptions.UCXError: <[Send #007] ep: 0x7f60a1d1b280, tag: 0xf0e7b6dcc50f2442, nbytes: 50000000, type: <class 'cupy.ndarray'>>: Connection reset by remote peer

During handling of the above exception, another exception occurred:

Traceback (most recent call last):
  File "/opt/conda/envs/gdf/lib/python3.9/site-packages/distributed/worker.py", line 1792, in get_data
    compressed = await comm.write(msg, serializers=serializers)
  File "/opt/conda/envs/gdf/lib/python3.9/site-packages/distributed/utils.py", line 752, in wrapper
    return await func(*args, **kwargs)
  File "/opt/conda/envs/gdf/lib/python3.9/site-packages/distributed/comm/ucx.py", line 337, in write
    raise CommClosedError("While writing, the connection was closed")
distributed.comm.core.CommClosedError: While writing, the connection was closed
2023-08-11 06:19:56,220 - distributed.nanny - WARNING - Restarting worker
2023-08-11 06:19:56,922 - distributed.preloading - INFO - Creating preload: dask_cuda.initialize
2023-08-11 06:19:56,922 - distributed.preloading - INFO - Import preload module: dask_cuda.initialize
2023-08-11 06:19:57,328 - distributed.preloading - INFO - Creating preload: dask_cuda.initialize
2023-08-11 06:19:57,329 - distributed.preloading - INFO - Import preload module: dask_cuda.initialize
2023-08-11 06:19:57,631 - distributed.preloading - INFO - Creating preload: dask_cuda.initialize
2023-08-11 06:19:57,631 - distributed.preloading - INFO - Import preload module: dask_cuda.initialize
/opt/conda/envs/gdf/lib/python3.9/multiprocessing/resource_tracker.py:216: UserWarning: resource_tracker: There appear to be 48 leaked semaphore objects to clean up at shutdown
  warnings.warn('resource_tracker: There appear to be %d '
