2023-06-16 06:00:06,269 - distributed.preloading - INFO - Creating preload: dask_cuda.initialize
2023-06-16 06:00:06,270 - distributed.preloading - INFO - Import preload module: dask_cuda.initialize
2023-06-16 06:00:06,301 - distributed.preloading - INFO - Creating preload: dask_cuda.initialize
2023-06-16 06:00:06,301 - distributed.preloading - INFO - Import preload module: dask_cuda.initialize
2023-06-16 06:00:06,368 - distributed.preloading - INFO - Creating preload: dask_cuda.initialize
2023-06-16 06:00:06,368 - distributed.preloading - INFO - Import preload module: dask_cuda.initialize
2023-06-16 06:00:06,377 - distributed.preloading - INFO - Creating preload: dask_cuda.initialize
2023-06-16 06:00:06,377 - distributed.preloading - INFO - Import preload module: dask_cuda.initialize
2023-06-16 06:00:06,392 - distributed.preloading - INFO - Creating preload: dask_cuda.initialize
2023-06-16 06:00:06,392 - distributed.preloading - INFO - Import preload module: dask_cuda.initialize
2023-06-16 06:00:06,425 - distributed.preloading - INFO - Creating preload: dask_cuda.initialize
2023-06-16 06:00:06,425 - distributed.preloading - INFO - Import preload module: dask_cuda.initialize
2023-06-16 06:00:06,435 - distributed.preloading - INFO - Creating preload: dask_cuda.initialize
2023-06-16 06:00:06,436 - distributed.preloading - INFO - Import preload module: dask_cuda.initialize
2023-06-16 06:00:06,442 - distributed.preloading - INFO - Creating preload: dask_cuda.initialize
2023-06-16 06:00:06,442 - distributed.preloading - INFO - Import preload module: dask_cuda.initialize
[dgx13:77194:0:77194] Caught signal 11 (Segmentation fault: address not mapped to object at address 0x448)
==== backtrace (tid:  77194) ====
 0  /opt/conda/envs/gdf/lib/libucs.so.0(ucs_handle_error+0x2fd) [0x7f02dc3c8f1d]
 1  /opt/conda/envs/gdf/lib/libucs.so.0(+0x29114) [0x7f02dc3c9114]
 2  /opt/conda/envs/gdf/lib/libucs.so.0(+0x292da) [0x7f02dc3c92da]
 3  /usr/lib/x86_64-linux-gnu/libpthread.so.0(+0x14420) [0x7f036ebbe420]
 4  /opt/conda/envs/gdf/lib/libucp.so.0(ucp_mem_type_unpack+0x14) [0x7f02dc4425d4]
 5  /opt/conda/envs/gdf/lib/libucp.so.0(ucp_rndv_data_handler+0x4e9) [0x7f02dc467859]
 6  /opt/conda/envs/gdf/lib/libuct.so.0(+0x2042f) [0x7f02dc38442f]
 7  /opt/conda/envs/gdf/lib/libuct.so.0(+0x23798) [0x7f02dc387798]
 8  /opt/conda/envs/gdf/lib/libucs.so.0(ucs_event_set_wait+0xb9) [0x7f02dc3d1989]
 9  /opt/conda/envs/gdf/lib/libuct.so.0(uct_tcp_iface_progress+0x7d) [0x7f02dc38662d]
10  /opt/conda/envs/gdf/lib/libucp.so.0(ucp_worker_progress+0x5a) [0x7f02dc43fc4a]
11  /opt/conda/envs/gdf/lib/python3.9/site-packages/ucp/_libs/ucx_api.cpython-39-x86_64-linux-gnu.so(+0x2b17a) [0x7f02dc4ea17a]
12  /opt/conda/envs/gdf/bin/python(+0x13eb08) [0x55fab255bb08]
13  /opt/conda/envs/gdf/bin/python(_PyEval_EvalFrameDefault+0x5f82) [0x55fab254c112]
14  /opt/conda/envs/gdf/bin/python(+0x12827a) [0x55fab254527a]
15  /opt/conda/envs/gdf/bin/python(_PyFunction_Vectorcall+0xd5) [0x55fab2556c05]
16  /opt/conda/envs/gdf/bin/python(_PyEval_EvalFrameDefault+0x68b) [0x55fab254681b]
17  /opt/conda/envs/gdf/bin/python(+0x14e70e) [0x55fab256b70e]
18  /opt/conda/envs/gdf/lib/python3.9/lib-dynload/_asyncio.cpython-39-x86_64-linux-gnu.so(+0x82fe) [0x7f02ee7652fe]
19  /opt/conda/envs/gdf/bin/python(_PyObject_MakeTpCall+0x2fc) [0x55fab254f2bc]
20  /opt/conda/envs/gdf/bin/python(+0xe5817) [0x55fab2502817]
21  /opt/conda/envs/gdf/bin/python(+0x130f83) [0x55fab254df83]
22  /opt/conda/envs/gdf/bin/python(_PyEval_EvalFrameDefault+0x5ba6) [0x55fab254bd36]
23  /opt/conda/envs/gdf/bin/python(+0x139ef3) [0x55fab2556ef3]
24  /opt/conda/envs/gdf/bin/python(_PyEval_EvalFrameDefault+0x68b) [0x55fab254681b]
25  /opt/conda/envs/gdf/bin/python(+0x139ef3) [0x55fab2556ef3]
26  /opt/conda/envs/gdf/bin/python(_PyEval_EvalFrameDefault+0x68b) [0x55fab254681b]
27  /opt/conda/envs/gdf/bin/python(+0x139ef3) [0x55fab2556ef3]
28  /opt/conda/envs/gdf/bin/python(_PyEval_EvalFrameDefault+0x68b) [0x55fab254681b]
29  /opt/conda/envs/gdf/bin/python(+0x139ef3) [0x55fab2556ef3]
30  /opt/conda/envs/gdf/bin/python(_PyEval_EvalFrameDefault+0x68b) [0x55fab254681b]
31  /opt/conda/envs/gdf/bin/python(+0x12827a) [0x55fab254527a]
32  /opt/conda/envs/gdf/bin/python(_PyFunction_Vectorcall+0xd5) [0x55fab2556c05]
33  /opt/conda/envs/gdf/bin/python(_PyEval_EvalFrameDefault+0x4e17) [0x55fab254afa7]
34  /opt/conda/envs/gdf/bin/python(+0x12827a) [0x55fab254527a]
35  /opt/conda/envs/gdf/bin/python(+0x147935) [0x55fab2564935]
36  /opt/conda/envs/gdf/bin/python(PyObject_Call+0xb4) [0x55fab2565104]
37  /opt/conda/envs/gdf/bin/python(+0x20efc8) [0x55fab262bfc8]
38  /opt/conda/envs/gdf/bin/python(_PyObject_MakeTpCall+0x2fc) [0x55fab254f2bc]
39  /opt/conda/envs/gdf/bin/python(_PyEval_EvalFrameDefault+0x402b) [0x55fab254a1bb]
40  /opt/conda/envs/gdf/bin/python(+0x139ef3) [0x55fab2556ef3]
41  /opt/conda/envs/gdf/bin/python(+0x147c72) [0x55fab2564c72]
42  /opt/conda/envs/gdf/bin/python(_PyEval_EvalFrameDefault+0x402b) [0x55fab254a1bb]
43  /opt/conda/envs/gdf/bin/python(+0x139ef3) [0x55fab2556ef3]
44  /opt/conda/envs/gdf/bin/python(_PyEval_EvalFrameDefault+0x68b) [0x55fab254681b]
45  /opt/conda/envs/gdf/bin/python(+0x12827a) [0x55fab254527a]
46  /opt/conda/envs/gdf/bin/python(_PyFunction_Vectorcall+0xd5) [0x55fab2556c05]
47  /opt/conda/envs/gdf/bin/python(_PyEval_EvalFrameDefault+0x68b) [0x55fab254681b]
48  /opt/conda/envs/gdf/bin/python(+0x139ef3) [0x55fab2556ef3]
49  /opt/conda/envs/gdf/bin/python(_PyEval_EvalFrameDefault+0x3d8) [0x55fab2546568]
50  /opt/conda/envs/gdf/bin/python(+0x12827a) [0x55fab254527a]
51  /opt/conda/envs/gdf/bin/python(_PyFunction_Vectorcall+0xd5) [0x55fab2556c05]
52  /opt/conda/envs/gdf/bin/python(_PyEval_EvalFrameDefault+0x123b) [0x55fab25473cb]
53  /opt/conda/envs/gdf/bin/python(+0x12827a) [0x55fab254527a]
54  /opt/conda/envs/gdf/bin/python(_PyEval_EvalCodeWithName+0x47) [0x55fab2544f07]
55  /opt/conda/envs/gdf/bin/python(PyEval_EvalCodeEx+0x39) [0x55fab2544eb9]
56  /opt/conda/envs/gdf/bin/python(PyEval_EvalCode+0x1b) [0x55fab25f58bb]
57  /opt/conda/envs/gdf/bin/python(+0x206adc) [0x55fab2623adc]
58  /opt/conda/envs/gdf/bin/python(+0x202c24) [0x55fab261fc24]
59  /opt/conda/envs/gdf/bin/python(PyRun_StringFlags+0x9d) [0x55fab26177ed]
60  /opt/conda/envs/gdf/bin/python(PyRun_SimpleStringFlags+0x3d) [0x55fab26176bd]
61  /opt/conda/envs/gdf/bin/python(Py_RunMain+0x262) [0x55fab26168a2]
=================================
[dgx13:77209:0:77209] Caught signal 11 (Segmentation fault: address not mapped to object at address 0x448)
==== backtrace (tid:  77209) ====
 0  /opt/conda/envs/gdf/lib/libucs.so.0(ucs_handle_error+0x2fd) [0x7febecee8f1d]
 1  /opt/conda/envs/gdf/lib/libucs.so.0(+0x29114) [0x7febecee9114]
 2  /opt/conda/envs/gdf/lib/libucs.so.0(+0x292da) [0x7febecee92da]
 3  /usr/lib/x86_64-linux-gnu/libpthread.so.0(+0x14420) [0x7fec7f6de420]
 4  /opt/conda/envs/gdf/lib/libucp.so.0(ucp_mem_type_unpack+0x14) [0x7febecf625d4]
 5  /opt/conda/envs/gdf/lib/libucp.so.0(ucp_rndv_data_handler+0x4e9) [0x7febecf87859]
 6  /opt/conda/envs/gdf/lib/libuct.so.0(+0x2042f) [0x7febecea442f]
 7  /opt/conda/envs/gdf/lib/libuct.so.0(+0x23798) [0x7febecea7798]
 8  /opt/conda/envs/gdf/lib/libucs.so.0(ucs_event_set_wait+0xb9) [0x7febecef1989]
 9  /opt/conda/envs/gdf/lib/libuct.so.0(uct_tcp_iface_progress+0x7d) [0x7febecea662d]
10  /opt/conda/envs/gdf/lib/libucp.so.0(ucp_worker_progress+0x5a) [0x7febecf5fc4a]
11  /opt/conda/envs/gdf/lib/python3.9/site-packages/ucp/_libs/ucx_api.cpython-39-x86_64-linux-gnu.so(+0x2b17a) [0x7febed00a17a]
12  /opt/conda/envs/gdf/bin/python(+0x13eb08) [0x55b9b0115b08]
13  /opt/conda/envs/gdf/bin/python(_PyEval_EvalFrameDefault+0x5f82) [0x55b9b0106112]
14  /opt/conda/envs/gdf/bin/python(+0x12827a) [0x55b9b00ff27a]
15  /opt/conda/envs/gdf/bin/python(_PyFunction_Vectorcall+0xd5) [0x55b9b0110c05]
16  /opt/conda/envs/gdf/bin/python(_PyEval_EvalFrameDefault+0x68b) [0x55b9b010081b]
17  /opt/conda/envs/gdf/bin/python(+0x139ef3) [0x55b9b0110ef3]
18  /opt/conda/envs/gdf/bin/python(+0x147a16) [0x55b9b011ea16]
19  /opt/conda/envs/gdf/bin/python(+0x2579b1) [0x55b9b022e9b1]
20  /opt/conda/envs/gdf/bin/python(+0xe5817) [0x55b9b00bc817]
21  /opt/conda/envs/gdf/bin/python(+0x130f83) [0x55b9b0107f83]
22  /opt/conda/envs/gdf/bin/python(_PyEval_EvalFrameDefault+0x5ba6) [0x55b9b0105d36]
23  /opt/conda/envs/gdf/bin/python(+0x139ef3) [0x55b9b0110ef3]
24  /opt/conda/envs/gdf/bin/python(_PyEval_EvalFrameDefault+0x68b) [0x55b9b010081b]
25  /opt/conda/envs/gdf/bin/python(+0x139ef3) [0x55b9b0110ef3]
26  /opt/conda/envs/gdf/bin/python(_PyEval_EvalFrameDefault+0x68b) [0x55b9b010081b]
27  /opt/conda/envs/gdf/bin/python(+0x139ef3) [0x55b9b0110ef3]
28  /opt/conda/envs/gdf/bin/python(_PyEval_EvalFrameDefault+0x68b) [0x55b9b010081b]
29  /opt/conda/envs/gdf/bin/python(+0x139ef3) [0x55b9b0110ef3]
30  /opt/conda/envs/gdf/bin/python(_PyEval_EvalFrameDefault+0x68b) [0x55b9b010081b]
31  /opt/conda/envs/gdf/bin/python(+0x12827a) [0x55b9b00ff27a]
32  /opt/conda/envs/gdf/bin/python(_PyFunction_Vectorcall+0xd5) [0x55b9b0110c05]
33  /opt/conda/envs/gdf/bin/python(_PyEval_EvalFrameDefault+0x4e17) [0x55b9b0104fa7]
34  /opt/conda/envs/gdf/bin/python(+0x12827a) [0x55b9b00ff27a]
35  /opt/conda/envs/gdf/bin/python(+0x147935) [0x55b9b011e935]
36  /opt/conda/envs/gdf/bin/python(PyObject_Call+0xb4) [0x55b9b011f104]
37  /opt/conda/envs/gdf/bin/python(+0x20efc8) [0x55b9b01e5fc8]
38  /opt/conda/envs/gdf/bin/python(_PyObject_MakeTpCall+0x2fc) [0x55b9b01092bc]
39  /opt/conda/envs/gdf/bin/python(_PyEval_EvalFrameDefault+0x402b) [0x55b9b01041bb]
40  /opt/conda/envs/gdf/bin/python(+0x139ef3) [0x55b9b0110ef3]
41  /opt/conda/envs/gdf/bin/python(+0x147c72) [0x55b9b011ec72]
42  /opt/conda/envs/gdf/bin/python(_PyEval_EvalFrameDefault+0x402b) [0x55b9b01041bb]
43  /opt/conda/envs/gdf/bin/python(+0x139ef3) [0x55b9b0110ef3]
44  /opt/conda/envs/gdf/bin/python(_PyEval_EvalFrameDefault+0x68b) [0x55b9b010081b]
45  /opt/conda/envs/gdf/bin/python(+0x12827a) [0x55b9b00ff27a]
46  /opt/conda/envs/gdf/bin/python(_PyFunction_Vectorcall+0xd5) [0x55b9b0110c05]
47  /opt/conda/envs/gdf/bin/python(_PyEval_EvalFrameDefault+0x68b) [0x55b9b010081b]
48  /opt/conda/envs/gdf/bin/python(+0x139ef3) [0x55b9b0110ef3]
49  /opt/conda/envs/gdf/bin/python(_PyEval_EvalFrameDefault+0x3d8) [0x55b9b0100568]
50  /opt/conda/envs/gdf/bin/python(+0x12827a) [0x55b9b00ff27a]
51  /opt/conda/envs/gdf/bin/python(_PyFunction_Vectorcall+0xd5) [0x55b9b0110c05]
52  /opt/conda/envs/gdf/bin/python(_PyEval_EvalFrameDefault+0x123b) [0x55b9b01013cb]
53  /opt/conda/envs/gdf/bin/python(+0x12827a) [0x55b9b00ff27a]
54  /opt/conda/envs/gdf/bin/python(_PyEval_EvalCodeWithName+0x47) [0x55b9b00fef07]
55  /opt/conda/envs/gdf/bin/python(PyEval_EvalCodeEx+0x39) [0x55b9b00feeb9]
56  /opt/conda/envs/gdf/bin/python(PyEval_EvalCode+0x1b) [0x55b9b01af8bb]
57  /opt/conda/envs/gdf/bin/python(+0x206adc) [0x55b9b01ddadc]
58  /opt/conda/envs/gdf/bin/python(+0x202c24) [0x55b9b01d9c24]
59  /opt/conda/envs/gdf/bin/python(PyRun_StringFlags+0x9d) [0x55b9b01d17ed]
60  /opt/conda/envs/gdf/bin/python(PyRun_SimpleStringFlags+0x3d) [0x55b9b01d16bd]
61  /opt/conda/envs/gdf/bin/python(Py_RunMain+0x262) [0x55b9b01d08a2]
=================================
[dgx13:77215:0:77215] Caught signal 11 (Segmentation fault: address not mapped to object at address 0x448)
==== backtrace (tid:  77215) ====
 0  /opt/conda/envs/gdf/lib/libucs.so.0(ucs_handle_error+0x2fd) [0x7f3c4c948f1d]
 1  /opt/conda/envs/gdf/lib/libucs.so.0(+0x29114) [0x7f3c4c949114]
 2  /opt/conda/envs/gdf/lib/libucs.so.0(+0x292da) [0x7f3c4c9492da]
 3  /usr/lib/x86_64-linux-gnu/libpthread.so.0(+0x14420) [0x7f3cdf159420]
 4  /opt/conda/envs/gdf/lib/libucp.so.0(ucp_mem_type_unpack+0x14) [0x7f3c4c9c25d4]
 5  /opt/conda/envs/gdf/lib/libucp.so.0(ucp_rndv_data_handler+0x4e9) [0x7f3c4c9e7859]
 6  /opt/conda/envs/gdf/lib/libuct.so.0(+0x2042f) [0x7f3c4c90442f]
 7  /opt/conda/envs/gdf/lib/libuct.so.0(+0x23798) [0x7f3c4c907798]
 8  /opt/conda/envs/gdf/lib/libucs.so.0(ucs_event_set_wait+0xb9) [0x7f3c4c951989]
 9  /opt/conda/envs/gdf/lib/libuct.so.0(uct_tcp_iface_progress+0x7d) [0x7f3c4c90662d]
10  /opt/conda/envs/gdf/lib/libucp.so.0(ucp_worker_progress+0x5a) [0x7f3c4c9bfc4a]
11  /opt/conda/envs/gdf/lib/python3.9/site-packages/ucp/_libs/ucx_api.cpython-39-x86_64-linux-gnu.so(+0x2b17a) [0x7f3c4ca6a17a]
12  /opt/conda/envs/gdf/bin/python(+0x13eb08) [0x561ef502bb08]
13  /opt/conda/envs/gdf/bin/python(_PyEval_EvalFrameDefault+0x5f82) [0x561ef501c112]
14  /opt/conda/envs/gdf/bin/python(+0x12827a) [0x561ef501527a]
15  /opt/conda/envs/gdf/bin/python(_PyFunction_Vectorcall+0xd5) [0x561ef5026c05]
16  /opt/conda/envs/gdf/bin/python(_PyEval_EvalFrameDefault+0x68b) [0x561ef501681b]
17  /opt/conda/envs/gdf/bin/python(+0x139ef3) [0x561ef5026ef3]
18  /opt/conda/envs/gdf/bin/python(+0x147a16) [0x561ef5034a16]
19  /opt/conda/envs/gdf/bin/python(+0x2579b1) [0x561ef51449b1]
20  /opt/conda/envs/gdf/bin/python(+0xe5817) [0x561ef4fd2817]
21  /opt/conda/envs/gdf/bin/python(+0x130f83) [0x561ef501df83]
22  /opt/conda/envs/gdf/bin/python(_PyEval_EvalFrameDefault+0x5ba6) [0x561ef501bd36]
23  /opt/conda/envs/gdf/bin/python(+0x139ef3) [0x561ef5026ef3]
24  /opt/conda/envs/gdf/bin/python(_PyEval_EvalFrameDefault+0x68b) [0x561ef501681b]
25  /opt/conda/envs/gdf/bin/python(+0x139ef3) [0x561ef5026ef3]
26  /opt/conda/envs/gdf/bin/python(_PyEval_EvalFrameDefault+0x68b) [0x561ef501681b]
27  /opt/conda/envs/gdf/bin/python(+0x139ef3) [0x561ef5026ef3]
28  /opt/conda/envs/gdf/bin/python(_PyEval_EvalFrameDefault+0x68b) [0x561ef501681b]
29  /opt/conda/envs/gdf/bin/python(+0x139ef3) [0x561ef5026ef3]
30  /opt/conda/envs/gdf/bin/python(_PyEval_EvalFrameDefault+0x68b) [0x561ef501681b]
31  /opt/conda/envs/gdf/bin/python(+0x12827a) [0x561ef501527a]
32  /opt/conda/envs/gdf/bin/python(_PyFunction_Vectorcall+0xd5) [0x561ef5026c05]
33  /opt/conda/envs/gdf/bin/python(_PyEval_EvalFrameDefault+0x4e17) [0x561ef501afa7]
34  /opt/conda/envs/gdf/bin/python(+0x12827a) [0x561ef501527a]
35  /opt/conda/envs/gdf/bin/python(+0x147935) [0x561ef5034935]
36  /opt/conda/envs/gdf/bin/python(PyObject_Call+0xb4) [0x561ef5035104]
37  /opt/conda/envs/gdf/bin/python(+0x20efc8) [0x561ef50fbfc8]
38  /opt/conda/envs/gdf/bin/python(_PyObject_MakeTpCall+0x2fc) [0x561ef501f2bc]
39  /opt/conda/envs/gdf/bin/python(_PyEval_EvalFrameDefault+0x402b) [0x561ef501a1bb]
40  /opt/conda/envs/gdf/bin/python(+0x139ef3) [0x561ef5026ef3]
41  /opt/conda/envs/gdf/bin/python(+0x147c72) [0x561ef5034c72]
42  /opt/conda/envs/gdf/bin/python(_PyEval_EvalFrameDefault+0x402b) [0x561ef501a1bb]
43  /opt/conda/envs/gdf/bin/python(+0x139ef3) [0x561ef5026ef3]
44  /opt/conda/envs/gdf/bin/python(_PyEval_EvalFrameDefault+0x68b) [0x561ef501681b]
45  /opt/conda/envs/gdf/bin/python(+0x12827a) [0x561ef501527a]
46  /opt/conda/envs/gdf/bin/python(_PyFunction_Vectorcall+0xd5) [0x561ef5026c05]
47  /opt/conda/envs/gdf/bin/python(_PyEval_EvalFrameDefault+0x68b) [0x561ef501681b]
48  /opt/conda/envs/gdf/bin/python(+0x139ef3) [0x561ef5026ef3]
49  /opt/conda/envs/gdf/bin/python(_PyEval_EvalFrameDefault+0x3d8) [0x561ef5016568]
50  /opt/conda/envs/gdf/bin/python(+0x12827a) [0x561ef501527a]
51  /opt/conda/envs/gdf/bin/python(_PyFunction_Vectorcall+0xd5) [0x561ef5026c05]
52  /opt/conda/envs/gdf/bin/python(_PyEval_EvalFrameDefault+0x123b) [0x561ef50173cb]
53  /opt/conda/envs/gdf/bin/python(+0x12827a) [0x561ef501527a]
54  /opt/conda/envs/gdf/bin/python(_PyEval_EvalCodeWithName+0x47) [0x561ef5014f07]
55  /opt/conda/envs/gdf/bin/python(PyEval_EvalCodeEx+0x39) [0x561ef5014eb9]
56  /opt/conda/envs/gdf/bin/python(PyEval_EvalCode+0x1b) [0x561ef50c58bb]
57  /opt/conda/envs/gdf/bin/python(+0x206adc) [0x561ef50f3adc]
58  /opt/conda/envs/gdf/bin/python(+0x202c24) [0x561ef50efc24]
59  /opt/conda/envs/gdf/bin/python(PyRun_StringFlags+0x9d) [0x561ef50e77ed]
60  /opt/conda/envs/gdf/bin/python(PyRun_SimpleStringFlags+0x3d) [0x561ef50e76bd]
61  /opt/conda/envs/gdf/bin/python(Py_RunMain+0x262) [0x561ef50e68a2]
=================================
[dgx13:77212:0:77212] Caught signal 11 (Segmentation fault: address not mapped to object at address 0x448)
==== backtrace (tid:  77212) ====
 0  /opt/conda/envs/gdf/lib/libucs.so.0(ucs_handle_error+0x2fd) [0x7fdb446ccf1d]
 1  /opt/conda/envs/gdf/lib/libucs.so.0(+0x29114) [0x7fdb446cd114]
 2  /opt/conda/envs/gdf/lib/libucs.so.0(+0x292da) [0x7fdb446cd2da]
 3  /usr/lib/x86_64-linux-gnu/libpthread.so.0(+0x14420) [0x7fdbd6d85420]
 4  /opt/conda/envs/gdf/lib/libucp.so.0(ucp_mem_type_unpack+0x14) [0x7fdb447465d4]
 5  /opt/conda/envs/gdf/lib/libucp.so.0(ucp_rndv_data_handler+0x4e9) [0x7fdb4476b859]
 6  /opt/conda/envs/gdf/lib/libuct.so.0(+0x2042f) [0x7fdb4468842f]
 7  /opt/conda/envs/gdf/lib/libuct.so.0(+0x23798) [0x7fdb4468b798]
 8  /opt/conda/envs/gdf/lib/libucs.so.0(ucs_event_set_wait+0xb9) [0x7fdb446d5989]
 9  /opt/conda/envs/gdf/lib/libuct.so.0(uct_tcp_iface_progress+0x7d) [0x7fdb4468a62d]
10  /opt/conda/envs/gdf/lib/libucp.so.0(ucp_worker_progress+0x5a) [0x7fdb44743c4a]
11  /opt/conda/envs/gdf/lib/python3.9/site-packages/ucp/_libs/ucx_api.cpython-39-x86_64-linux-gnu.so(+0x2b17a) [0x7fdb447ee17a]
12  /opt/conda/envs/gdf/bin/python(+0x13eb08) [0x560fbf721b08]
13  /opt/conda/envs/gdf/bin/python(_PyEval_EvalFrameDefault+0x5f82) [0x560fbf712112]
14  /opt/conda/envs/gdf/bin/python(+0x12827a) [0x560fbf70b27a]
15  /opt/conda/envs/gdf/bin/python(_PyFunction_Vectorcall+0xd5) [0x560fbf71cc05]
16  /opt/conda/envs/gdf/bin/python(_PyEval_EvalFrameDefault+0x68b) [0x560fbf70c81b]
17  /opt/conda/envs/gdf/bin/python(+0x14e70e) [0x560fbf73170e]
18  /opt/conda/envs/gdf/lib/python3.9/lib-dynload/_asyncio.cpython-39-x86_64-linux-gnu.so(+0x82fe) [0x7fdb5692c2fe]
19  /opt/conda/envs/gdf/bin/python(_PyObject_MakeTpCall+0x2fc) [0x560fbf7152bc]
20  /opt/conda/envs/gdf/bin/python(+0xe5817) [0x560fbf6c8817]
21  /opt/conda/envs/gdf/bin/python(+0x130f83) [0x560fbf713f83]
22  /opt/conda/envs/gdf/bin/python(_PyEval_EvalFrameDefault+0x5ba6) [0x560fbf711d36]
23  /opt/conda/envs/gdf/bin/python(+0x139ef3) [0x560fbf71cef3]
24  /opt/conda/envs/gdf/bin/python(_PyEval_EvalFrameDefault+0x68b) [0x560fbf70c81b]
25  /opt/conda/envs/gdf/bin/python(+0x139ef3) [0x560fbf71cef3]
26  /opt/conda/envs/gdf/bin/python(_PyEval_EvalFrameDefault+0x68b) [0x560fbf70c81b]
27  /opt/conda/envs/gdf/bin/python(+0x139ef3) [0x560fbf71cef3]
28  /opt/conda/envs/gdf/bin/python(_PyEval_EvalFrameDefault+0x68b) [0x560fbf70c81b]
29  /opt/conda/envs/gdf/bin/python(+0x139ef3) [0x560fbf71cef3]
30  /opt/conda/envs/gdf/bin/python(_PyEval_EvalFrameDefault+0x68b) [0x560fbf70c81b]
31  /opt/conda/envs/gdf/bin/python(+0x12827a) [0x560fbf70b27a]
32  /opt/conda/envs/gdf/bin/python(_PyFunction_Vectorcall+0xd5) [0x560fbf71cc05]
33  /opt/conda/envs/gdf/bin/python(_PyEval_EvalFrameDefault+0x4e17) [0x560fbf710fa7]
34  /opt/conda/envs/gdf/bin/python(+0x12827a) [0x560fbf70b27a]
35  /opt/conda/envs/gdf/bin/python(+0x147935) [0x560fbf72a935]
36  /opt/conda/envs/gdf/bin/python(PyObject_Call+0xb4) [0x560fbf72b104]
37  /opt/conda/envs/gdf/bin/python(+0x20efc8) [0x560fbf7f1fc8]
38  /opt/conda/envs/gdf/bin/python(_PyObject_MakeTpCall+0x2fc) [0x560fbf7152bc]
39  /opt/conda/envs/gdf/bin/python(_PyEval_EvalFrameDefault+0x402b) [0x560fbf7101bb]
40  /opt/conda/envs/gdf/bin/python(+0x139ef3) [0x560fbf71cef3]
41  /opt/conda/envs/gdf/bin/python(+0x147c72) [0x560fbf72ac72]
42  /opt/conda/envs/gdf/bin/python(_PyEval_EvalFrameDefault+0x402b) [0x560fbf7101bb]
43  /opt/conda/envs/gdf/bin/python(+0x139ef3) [0x560fbf71cef3]
44  /opt/conda/envs/gdf/bin/python(_PyEval_EvalFrameDefault+0x68b) [0x560fbf70c81b]
45  /opt/conda/envs/gdf/bin/python(+0x12827a) [0x560fbf70b27a]
46  /opt/conda/envs/gdf/bin/python(_PyFunction_Vectorcall+0xd5) [0x560fbf71cc05]
47  /opt/conda/envs/gdf/bin/python(_PyEval_EvalFrameDefault+0x68b) [0x560fbf70c81b]
48  /opt/conda/envs/gdf/bin/python(+0x139ef3) [0x560fbf71cef3]
49  /opt/conda/envs/gdf/bin/python(_PyEval_EvalFrameDefault+0x3d8) [0x560fbf70c568]
50  /opt/conda/envs/gdf/bin/python(+0x12827a) [0x560fbf70b27a]
51  /opt/conda/envs/gdf/bin/python(_PyFunction_Vectorcall+0xd5) [0x560fbf71cc05]
52  /opt/conda/envs/gdf/bin/python(_PyEval_EvalFrameDefault+0x123b) [0x560fbf70d3cb]
53  /opt/conda/envs/gdf/bin/python(+0x12827a) [0x560fbf70b27a]
54  /opt/conda/envs/gdf/bin/python(_PyEval_EvalCodeWithName+0x47) [0x560fbf70af07]
55  /opt/conda/envs/gdf/bin/python(PyEval_EvalCodeEx+0x39) [0x560fbf70aeb9]
56  /opt/conda/envs/gdf/bin/python(PyEval_EvalCode+0x1b) [0x560fbf7bb8bb]
57  /opt/conda/envs/gdf/bin/python(+0x206adc) [0x560fbf7e9adc]
58  /opt/conda/envs/gdf/bin/python(+0x202c24) [0x560fbf7e5c24]
59  /opt/conda/envs/gdf/bin/python(PyRun_StringFlags+0x9d) [0x560fbf7dd7ed]
60  /opt/conda/envs/gdf/bin/python(PyRun_SimpleStringFlags+0x3d) [0x560fbf7dd6bd]
61  /opt/conda/envs/gdf/bin/python(Py_RunMain+0x262) [0x560fbf7dc8a2]
=================================
[dgx13:77218:0:77218] Caught signal 11 (Segmentation fault: address not mapped to object at address 0x448)
==== backtrace (tid:  77218) ====
 0  /opt/conda/envs/gdf/lib/libucs.so.0(ucs_handle_error+0x2fd) [0x7fc1b47d2f1d]
 1  /opt/conda/envs/gdf/lib/libucs.so.0(+0x29114) [0x7fc1b47d3114]
 2  /opt/conda/envs/gdf/lib/libucs.so.0(+0x292da) [0x7fc1b47d32da]
 3  /usr/lib/x86_64-linux-gnu/libpthread.so.0(+0x14420) [0x7fc246fc7420]
 4  /opt/conda/envs/gdf/lib/libucp.so.0(ucp_mem_type_unpack+0x14) [0x7fc1b484c5d4]
 5  /opt/conda/envs/gdf/lib/libucp.so.0(ucp_rndv_data_handler+0x4e9) [0x7fc1b4871859]
 6  /opt/conda/envs/gdf/lib/libuct.so.0(+0x2042f) [0x7fc1b478e42f]
 7  /opt/conda/envs/gdf/lib/libuct.so.0(+0x23798) [0x7fc1b4791798]
 8  /opt/conda/envs/gdf/lib/libucs.so.0(ucs_event_set_wait+0xb9) [0x7fc1b47db989]
 9  /opt/conda/envs/gdf/lib/libuct.so.0(uct_tcp_iface_progress+0x7d) [0x7fc1b479062d]
10  /opt/conda/envs/gdf/lib/libucp.so.0(ucp_worker_progress+0x5a) [0x7fc1b4849c4a]
11  /opt/conda/envs/gdf/lib/python3.9/site-packages/ucp/_libs/ucx_api.cpython-39-x86_64-linux-gnu.so(+0x2b17a) [0x7fc1b48f417a]
12  /opt/conda/envs/gdf/bin/python(+0x13eb08) [0x558380d7ab08]
13  /opt/conda/envs/gdf/bin/python(_PyEval_EvalFrameDefault+0x5f82) [0x558380d6b112]
14  /opt/conda/envs/gdf/bin/python(+0x12827a) [0x558380d6427a]
15  /opt/conda/envs/gdf/bin/python(_PyFunction_Vectorcall+0xd5) [0x558380d75c05]
16  /opt/conda/envs/gdf/bin/python(_PyEval_EvalFrameDefault+0x68b) [0x558380d6581b]
17  /opt/conda/envs/gdf/bin/python(+0x139ef3) [0x558380d75ef3]
18  /opt/conda/envs/gdf/bin/python(+0x147a16) [0x558380d83a16]
19  /opt/conda/envs/gdf/bin/python(+0x2579b1) [0x558380e939b1]
20  /opt/conda/envs/gdf/bin/python(+0xe5817) [0x558380d21817]
21  /opt/conda/envs/gdf/bin/python(+0x130f83) [0x558380d6cf83]
22  /opt/conda/envs/gdf/bin/python(_PyEval_EvalFrameDefault+0x5ba6) [0x558380d6ad36]
23  /opt/conda/envs/gdf/bin/python(+0x139ef3) [0x558380d75ef3]
24  /opt/conda/envs/gdf/bin/python(_PyEval_EvalFrameDefault+0x68b) [0x558380d6581b]
25  /opt/conda/envs/gdf/bin/python(+0x139ef3) [0x558380d75ef3]
26  /opt/conda/envs/gdf/bin/python(_PyEval_EvalFrameDefault+0x68b) [0x558380d6581b]
27  /opt/conda/envs/gdf/bin/python(+0x139ef3) [0x558380d75ef3]
28  /opt/conda/envs/gdf/bin/python(_PyEval_EvalFrameDefault+0x68b) [0x558380d6581b]
29  /opt/conda/envs/gdf/bin/python(+0x139ef3) [0x558380d75ef3]
30  /opt/conda/envs/gdf/bin/python(_PyEval_EvalFrameDefault+0x68b) [0x558380d6581b]
31  /opt/conda/envs/gdf/bin/python(+0x12827a) [0x558380d6427a]
32  /opt/conda/envs/gdf/bin/python(_PyFunction_Vectorcall+0xd5) [0x558380d75c05]
33  /opt/conda/envs/gdf/bin/python(_PyEval_EvalFrameDefault+0x4e17) [0x558380d69fa7]
34  /opt/conda/envs/gdf/bin/python(+0x12827a) [0x558380d6427a]
35  /opt/conda/envs/gdf/bin/python(+0x147935) [0x558380d83935]
36  /opt/conda/envs/gdf/bin/python(PyObject_Call+0xb4) [0x558380d84104]
37  /opt/conda/envs/gdf/bin/python(+0x20efc8) [0x558380e4afc8]
38  /opt/conda/envs/gdf/bin/python(_PyObject_MakeTpCall+0x2fc) [0x558380d6e2bc]
39  /opt/conda/envs/gdf/bin/python(_PyEval_EvalFrameDefault+0x402b) [0x558380d691bb]
40  /opt/conda/envs/gdf/bin/python(+0x139ef3) [0x558380d75ef3]
41  /opt/conda/envs/gdf/bin/python(+0x147c72) [0x558380d83c72]
42  /opt/conda/envs/gdf/bin/python(_PyEval_EvalFrameDefault+0x402b) [0x558380d691bb]
43  /opt/conda/envs/gdf/bin/python(+0x139ef3) [0x558380d75ef3]
44  /opt/conda/envs/gdf/bin/python(_PyEval_EvalFrameDefault+0x68b) [0x558380d6581b]
45  /opt/conda/envs/gdf/bin/python(+0x12827a) [0x558380d6427a]
46  /opt/conda/envs/gdf/bin/python(_PyFunction_Vectorcall+0xd5) [0x558380d75c05]
47  /opt/conda/envs/gdf/bin/python(_PyEval_EvalFrameDefault+0x68b) [0x558380d6581b]
48  /opt/conda/envs/gdf/bin/python(+0x139ef3) [0x558380d75ef3]
49  /opt/conda/envs/gdf/bin/python(_PyEval_EvalFrameDefault+0x3d8) [0x558380d65568]
50  /opt/conda/envs/gdf/bin/python(+0x12827a) [0x558380d6427a]
51  /opt/conda/envs/gdf/bin/python(_PyFunction_Vectorcall+0xd5) [0x558380d75c05]
52  /opt/conda/envs/gdf/bin/python(_PyEval_EvalFrameDefault+0x123b) [0x558380d663cb]
53  /opt/conda/envs/gdf/bin/python(+0x12827a) [0x558380d6427a]
54  /opt/conda/envs/gdf/bin/python(_PyEval_EvalCodeWithName+0x47) [0x558380d63f07]
55  /opt/conda/envs/gdf/bin/python(PyEval_EvalCodeEx+0x39) [0x558380d63eb9]
56  /opt/conda/envs/gdf/bin/python(PyEval_EvalCode+0x1b) [0x558380e148bb]
57  /opt/conda/envs/gdf/bin/python(+0x206adc) [0x558380e42adc]
58  /opt/conda/envs/gdf/bin/python(+0x202c24) [0x558380e3ec24]
59  /opt/conda/envs/gdf/bin/python(PyRun_StringFlags+0x9d) [0x558380e367ed]
60  /opt/conda/envs/gdf/bin/python(PyRun_SimpleStringFlags+0x3d) [0x558380e366bd]
61  /opt/conda/envs/gdf/bin/python(Py_RunMain+0x262) [0x558380e358a2]
=================================
Task exception was never retrieved
future: <Task finished name='Task-306' coro=<_listener_handler_coroutine() done, defined at /opt/conda/envs/gdf/lib/python3.9/site-packages/ucp/core.py:128> exception=UCXError('<stream_recv>: Connection reset by remote peer')>
Traceback (most recent call last):
  File "/opt/conda/envs/gdf/lib/python3.9/site-packages/ucp/core.py", line 143, in _listener_handler_coroutine
    peer_info = await exchange_peer_info(
  File "/opt/conda/envs/gdf/lib/python3.9/site-packages/ucp/core.py", line 52, in exchange_peer_info
    await comm.stream_recv(endpoint, peer_info_arr, peer_info_arr.nbytes)
ucp._libs.exceptions.UCXError: <stream_recv>: Connection reset by remote peer
2023-06-16 06:00:10,393 - distributed.worker - ERROR - Worker stream died during communication: ucx://127.0.0.1:60155
Traceback (most recent call last):
  File "/opt/conda/envs/gdf/lib/python3.9/site-packages/distributed/comm/ucx.py", line 349, in read
    await self.ep.recv(msg)
  File "/opt/conda/envs/gdf/lib/python3.9/site-packages/ucp/core.py", line 725, in recv
    ret = await comm.tag_recv(self._ep, buffer, nbytes, tag, name=log)
ucp._libs.exceptions.UCXCanceled: <[Recv #000] ep: 0x7f8518868200, tag: 0x95a156dbc48514b2, nbytes: 16, type: <class 'numpy.ndarray'>>: 

During handling of the above exception, another exception occurred:

Traceback (most recent call last):
  File "/opt/conda/envs/gdf/lib/python3.9/site-packages/distributed/comm/core.py", line 329, in connect
    handshake = await wait_for(comm.read(), time_left())
  File "/opt/conda/envs/gdf/lib/python3.9/site-packages/distributed/utils.py", line 1849, in wait_for
    return await asyncio.wait_for(fut, timeout)
  File "/opt/conda/envs/gdf/lib/python3.9/asyncio/tasks.py", line 479, in wait_for
    return fut.result()
  File "/opt/conda/envs/gdf/lib/python3.9/site-packages/distributed/utils.py", line 752, in wrapper
    return await func(*args, **kwargs)
  File "/opt/conda/envs/gdf/lib/python3.9/site-packages/distributed/comm/ucx.py", line 367, in read
    raise CommClosedError(
distributed.comm.core.CommClosedError: Connection closed by writer.
Inner exception: UCXCanceled("<[Recv #000] ep: 0x7f8518868200, tag: 0x95a156dbc48514b2, nbytes: 16, type: <class 'numpy.ndarray'>>: ")

The above exception was the direct cause of the following exception:

Traceback (most recent call last):
  File "/opt/conda/envs/gdf/lib/python3.9/site-packages/distributed/worker.py", line 2066, in gather_dep
    response = await get_data_from_worker(
  File "/opt/conda/envs/gdf/lib/python3.9/site-packages/distributed/worker.py", line 2889, in get_data_from_worker
    comm = await rpc.connect(worker)
  File "/opt/conda/envs/gdf/lib/python3.9/site-packages/distributed/core.py", line 1506, in connect
    return await connect_attempt
  File "/opt/conda/envs/gdf/lib/python3.9/site-packages/distributed/core.py", line 1427, in _connect
    comm = await connect(
  File "/opt/conda/envs/gdf/lib/python3.9/site-packages/distributed/comm/core.py", line 334, in connect
    raise OSError(
OSError: Timed out during handshake while connecting to ucx://127.0.0.1:60155 after 30 s
2023-06-16 06:00:10,394 - distributed.worker - ERROR - Worker stream died during communication: ucx://127.0.0.1:60155
Traceback (most recent call last):
  File "/opt/conda/envs/gdf/lib/python3.9/site-packages/distributed/comm/ucx.py", line 349, in read
    await self.ep.recv(msg)
  File "/opt/conda/envs/gdf/lib/python3.9/site-packages/ucp/core.py", line 725, in recv
    ret = await comm.tag_recv(self._ep, buffer, nbytes, tag, name=log)
ucp._libs.exceptions.UCXCanceled: <[Recv #000] ep: 0x7fdb54f96200, tag: 0xbd8150f48fc0760c, nbytes: 16, type: <class 'numpy.ndarray'>>: 

During handling of the above exception, another exception occurred:

Traceback (most recent call last):
  File "/opt/conda/envs/gdf/lib/python3.9/site-packages/distributed/comm/core.py", line 329, in connect
    handshake = await wait_for(comm.read(), time_left())
  File "/opt/conda/envs/gdf/lib/python3.9/site-packages/distributed/utils.py", line 1849, in wait_for
    return await asyncio.wait_for(fut, timeout)
  File "/opt/conda/envs/gdf/lib/python3.9/asyncio/tasks.py", line 479, in wait_for
    return fut.result()
  File "/opt/conda/envs/gdf/lib/python3.9/site-packages/distributed/utils.py", line 752, in wrapper
    return await func(*args, **kwargs)
  File "/opt/conda/envs/gdf/lib/python3.9/site-packages/distributed/comm/ucx.py", line 367, in read
    raise CommClosedError(
distributed.comm.core.CommClosedError: Connection closed by writer.
Inner exception: UCXCanceled("<[Recv #000] ep: 0x7fdb54f96200, tag: 0xbd8150f48fc0760c, nbytes: 16, type: <class 'numpy.ndarray'>>: ")

The above exception was the direct cause of the following exception:

Traceback (most recent call last):
  File "/opt/conda/envs/gdf/lib/python3.9/site-packages/distributed/worker.py", line 2066, in gather_dep
    response = await get_data_from_worker(
  File "/opt/conda/envs/gdf/lib/python3.9/site-packages/distributed/worker.py", line 2889, in get_data_from_worker
    comm = await rpc.connect(worker)
  File "/opt/conda/envs/gdf/lib/python3.9/site-packages/distributed/core.py", line 1506, in connect
    return await connect_attempt
  File "/opt/conda/envs/gdf/lib/python3.9/site-packages/distributed/core.py", line 1427, in _connect
    comm = await connect(
  File "/opt/conda/envs/gdf/lib/python3.9/site-packages/distributed/comm/core.py", line 334, in connect
    raise OSError(
OSError: Timed out during handshake while connecting to ucx://127.0.0.1:60155 after 30 s
2023-06-16 06:00:10,414 - distributed.worker - ERROR - failed during get data with ucx://127.0.0.1:49835 -> ucx://127.0.0.1:40123
Traceback (most recent call last):
  File "/opt/conda/envs/gdf/lib/python3.9/site-packages/distributed/comm/ucx.py", line 333, in write
    await self.ep.send(each_frame)
  File "/opt/conda/envs/gdf/lib/python3.9/site-packages/ucp/core.py", line 650, in send
    return await comm.tag_send(self._ep, buffer, nbytes, tag, name=log)
ucp._libs.exceptions.UCXError: <[Send #007] ep: 0x7f8518868380, tag: 0x73a89ee5dd048ec8, nbytes: 50000000, type: <class 'cupy.ndarray'>>: Connection reset by remote peer

During handling of the above exception, another exception occurred:

Traceback (most recent call last):
  File "/opt/conda/envs/gdf/lib/python3.9/site-packages/distributed/worker.py", line 1792, in get_data
    compressed = await comm.write(msg, serializers=serializers)
  File "/opt/conda/envs/gdf/lib/python3.9/site-packages/distributed/utils.py", line 752, in wrapper
    return await func(*args, **kwargs)
  File "/opt/conda/envs/gdf/lib/python3.9/site-packages/distributed/comm/ucx.py", line 337, in write
    raise CommClosedError("While writing, the connection was closed")
distributed.comm.core.CommClosedError: While writing, the connection was closed
2023-06-16 06:00:10,416 - distributed.worker - ERROR - Worker stream died during communication: ucx://127.0.0.1:40123
Traceback (most recent call last):
  File "/opt/conda/envs/gdf/lib/python3.9/site-packages/distributed/comm/ucx.py", line 349, in read
    await self.ep.recv(msg)
  File "/opt/conda/envs/gdf/lib/python3.9/site-packages/ucp/core.py", line 725, in recv
    ret = await comm.tag_recv(self._ep, buffer, nbytes, tag, name=log)
ucp._libs.exceptions.UCXCanceled: <[Recv #000] ep: 0x7fdb54f96140, tag: 0x944ddd53dd9aa97, nbytes: 16, type: <class 'numpy.ndarray'>>: 

During handling of the above exception, another exception occurred:

Traceback (most recent call last):
  File "/opt/conda/envs/gdf/lib/python3.9/site-packages/distributed/comm/core.py", line 329, in connect
    handshake = await wait_for(comm.read(), time_left())
  File "/opt/conda/envs/gdf/lib/python3.9/site-packages/distributed/utils.py", line 1849, in wait_for
    return await asyncio.wait_for(fut, timeout)
  File "/opt/conda/envs/gdf/lib/python3.9/asyncio/tasks.py", line 479, in wait_for
    return fut.result()
  File "/opt/conda/envs/gdf/lib/python3.9/site-packages/distributed/utils.py", line 752, in wrapper
    return await func(*args, **kwargs)
  File "/opt/conda/envs/gdf/lib/python3.9/site-packages/distributed/comm/ucx.py", line 367, in read
    raise CommClosedError(
distributed.comm.core.CommClosedError: Connection closed by writer.
Inner exception: UCXCanceled("<[Recv #000] ep: 0x7fdb54f96140, tag: 0x944ddd53dd9aa97, nbytes: 16, type: <class 'numpy.ndarray'>>: ")

The above exception was the direct cause of the following exception:

Traceback (most recent call last):
  File "/opt/conda/envs/gdf/lib/python3.9/site-packages/distributed/worker.py", line 2066, in gather_dep
    response = await get_data_from_worker(
  File "/opt/conda/envs/gdf/lib/python3.9/site-packages/distributed/worker.py", line 2889, in get_data_from_worker
    comm = await rpc.connect(worker)
  File "/opt/conda/envs/gdf/lib/python3.9/site-packages/distributed/core.py", line 1506, in connect
    return await connect_attempt
  File "/opt/conda/envs/gdf/lib/python3.9/site-packages/distributed/core.py", line 1427, in _connect
    comm = await connect(
  File "/opt/conda/envs/gdf/lib/python3.9/site-packages/distributed/comm/core.py", line 334, in connect
    raise OSError(
OSError: Timed out during handshake while connecting to ucx://127.0.0.1:40123 after 30 s
2023-06-16 06:00:10,419 - distributed.worker - ERROR - failed during get data with ucx://127.0.0.1:49835 -> ucx://127.0.0.1:56787
Traceback (most recent call last):
  File "/opt/conda/envs/gdf/lib/python3.9/site-packages/distributed/comm/ucx.py", line 333, in write
    await self.ep.send(each_frame)
  File "/opt/conda/envs/gdf/lib/python3.9/site-packages/ucp/core.py", line 650, in send
    return await comm.tag_send(self._ep, buffer, nbytes, tag, name=log)
ucp._libs.exceptions.UCXError: <[Send #007] ep: 0x7f8518868300, tag: 0xc39a990699df6a09, nbytes: 50000000, type: <class 'cupy.ndarray'>>: Connection reset by remote peer

During handling of the above exception, another exception occurred:

Traceback (most recent call last):
  File "/opt/conda/envs/gdf/lib/python3.9/site-packages/distributed/worker.py", line 1792, in get_data
    compressed = await comm.write(msg, serializers=serializers)
  File "/opt/conda/envs/gdf/lib/python3.9/site-packages/distributed/utils.py", line 752, in wrapper
    return await func(*args, **kwargs)
  File "/opt/conda/envs/gdf/lib/python3.9/site-packages/distributed/comm/ucx.py", line 337, in write
    raise CommClosedError("While writing, the connection was closed")
distributed.comm.core.CommClosedError: While writing, the connection was closed
2023-06-16 06:00:10,419 - distributed.worker - ERROR - Worker stream died during communication: ucx://127.0.0.1:56787
Traceback (most recent call last):
  File "/opt/conda/envs/gdf/lib/python3.9/site-packages/distributed/comm/ucx.py", line 349, in read
    await self.ep.recv(msg)
  File "/opt/conda/envs/gdf/lib/python3.9/site-packages/ucp/core.py", line 725, in recv
    ret = await comm.tag_recv(self._ep, buffer, nbytes, tag, name=log)
ucp._libs.exceptions.UCXCanceled: <[Recv #003] ep: 0x7f85188681c0, tag: 0x500d2c22c8c14f88, nbytes: 16, type: <class 'numpy.ndarray'>>: 

During handling of the above exception, another exception occurred:

Traceback (most recent call last):
  File "/opt/conda/envs/gdf/lib/python3.9/site-packages/distributed/worker.py", line 2066, in gather_dep
    response = await get_data_from_worker(
  File "/opt/conda/envs/gdf/lib/python3.9/site-packages/distributed/worker.py", line 2892, in get_data_from_worker
    response = await send_recv(
  File "/opt/conda/envs/gdf/lib/python3.9/site-packages/distributed/core.py", line 1024, in send_recv
    response = await comm.read(deserializers=deserializers)
  File "/opt/conda/envs/gdf/lib/python3.9/site-packages/distributed/utils.py", line 752, in wrapper
    return await func(*args, **kwargs)
  File "/opt/conda/envs/gdf/lib/python3.9/site-packages/distributed/comm/ucx.py", line 367, in read
    raise CommClosedError(
distributed.comm.core.CommClosedError: Connection closed by writer.
Inner exception: UCXCanceled("<[Recv #003] ep: 0x7f85188681c0, tag: 0x500d2c22c8c14f88, nbytes: 16, type: <class 'numpy.ndarray'>>: ")
2023-06-16 06:00:10,433 - distributed.worker - ERROR - failed during get data with ucx://127.0.0.1:49835 -> ucx://127.0.0.1:36201
Traceback (most recent call last):
  File "/opt/conda/envs/gdf/lib/python3.9/site-packages/distributed/comm/ucx.py", line 349, in read
    await self.ep.recv(msg)
  File "/opt/conda/envs/gdf/lib/python3.9/site-packages/ucp/core.py", line 725, in recv
    ret = await comm.tag_recv(self._ep, buffer, nbytes, tag, name=log)
ucp._libs.exceptions.UCXCanceled: <[Recv #006] ep: 0x7f8518868240, tag: 0x10490463cb777a87, nbytes: 16, type: <class 'numpy.ndarray'>>: 

During handling of the above exception, another exception occurred:

Traceback (most recent call last):
  File "/opt/conda/envs/gdf/lib/python3.9/site-packages/distributed/worker.py", line 1793, in get_data
    response = await comm.read(deserializers=serializers)
  File "/opt/conda/envs/gdf/lib/python3.9/site-packages/distributed/utils.py", line 752, in wrapper
    return await func(*args, **kwargs)
  File "/opt/conda/envs/gdf/lib/python3.9/site-packages/distributed/comm/ucx.py", line 367, in read
    raise CommClosedError(
distributed.comm.core.CommClosedError: Connection closed by writer.
Inner exception: UCXCanceled("<[Recv #006] ep: 0x7f8518868240, tag: 0x10490463cb777a87, nbytes: 16, type: <class 'numpy.ndarray'>>: ")
2023-06-16 06:00:10,433 - distributed.worker - ERROR - failed during get data with ucx://127.0.0.1:57435 -> ucx://127.0.0.1:36201
Traceback (most recent call last):
  File "/opt/conda/envs/gdf/lib/python3.9/site-packages/distributed/comm/ucx.py", line 333, in write
    await self.ep.send(each_frame)
  File "/opt/conda/envs/gdf/lib/python3.9/site-packages/ucp/core.py", line 650, in send
    return await comm.tag_send(self._ep, buffer, nbytes, tag, name=log)
ucp._libs.exceptions.UCXError: <[Send #007] ep: 0x7fdb54f963c0, tag: 0x86d921a986b0ce79, nbytes: 50000000, type: <class 'cupy.ndarray'>>: Connection reset by remote peer

During handling of the above exception, another exception occurred:

Traceback (most recent call last):
  File "/opt/conda/envs/gdf/lib/python3.9/site-packages/distributed/worker.py", line 1792, in get_data
    compressed = await comm.write(msg, serializers=serializers)
  File "/opt/conda/envs/gdf/lib/python3.9/site-packages/distributed/utils.py", line 752, in wrapper
    return await func(*args, **kwargs)
  File "/opt/conda/envs/gdf/lib/python3.9/site-packages/distributed/comm/ucx.py", line 337, in write
    raise CommClosedError("While writing, the connection was closed")
distributed.comm.core.CommClosedError: While writing, the connection was closed
2023-06-16 06:00:10,433 - distributed.worker - ERROR - Worker stream died during communication: ucx://127.0.0.1:36201
Traceback (most recent call last):
  File "/opt/conda/envs/gdf/lib/python3.9/site-packages/distributed/comm/ucx.py", line 349, in read
    await self.ep.recv(msg)
  File "/opt/conda/envs/gdf/lib/python3.9/site-packages/ucp/core.py", line 725, in recv
    ret = await comm.tag_recv(self._ep, buffer, nbytes, tag, name=log)
ucp._libs.exceptions.UCXCanceled: <[Recv #008] ep: 0x7f8518868180, tag: 0xf23b0bb1a9e81326, nbytes: 16, type: <class 'numpy.ndarray'>>: 

During handling of the above exception, another exception occurred:

Traceback (most recent call last):
  File "/opt/conda/envs/gdf/lib/python3.9/site-packages/distributed/worker.py", line 2066, in gather_dep
    response = await get_data_from_worker(
  File "/opt/conda/envs/gdf/lib/python3.9/site-packages/distributed/worker.py", line 2892, in get_data_from_worker
    response = await send_recv(
  File "/opt/conda/envs/gdf/lib/python3.9/site-packages/distributed/core.py", line 1024, in send_recv
    response = await comm.read(deserializers=deserializers)
  File "/opt/conda/envs/gdf/lib/python3.9/site-packages/distributed/utils.py", line 752, in wrapper
    return await func(*args, **kwargs)
  File "/opt/conda/envs/gdf/lib/python3.9/site-packages/distributed/comm/ucx.py", line 367, in read
    raise CommClosedError(
distributed.comm.core.CommClosedError: Connection closed by writer.
Inner exception: UCXCanceled("<[Recv #008] ep: 0x7f8518868180, tag: 0xf23b0bb1a9e81326, nbytes: 16, type: <class 'numpy.ndarray'>>: ")
2023-06-16 06:00:10,433 - distributed.worker - ERROR - Worker stream died during communication: ucx://127.0.0.1:36201
Traceback (most recent call last):
  File "/opt/conda/envs/gdf/lib/python3.9/site-packages/distributed/comm/ucx.py", line 349, in read
    await self.ep.recv(msg)
  File "/opt/conda/envs/gdf/lib/python3.9/site-packages/ucp/core.py", line 725, in recv
    ret = await comm.tag_recv(self._ep, buffer, nbytes, tag, name=log)
ucp._libs.exceptions.UCXCanceled: <[Recv #003] ep: 0x7fdb54f96240, tag: 0xd5fd5a8f97d4ebfa, nbytes: 16, type: <class 'numpy.ndarray'>>: 

During handling of the above exception, another exception occurred:

Traceback (most recent call last):
  File "/opt/conda/envs/gdf/lib/python3.9/site-packages/distributed/worker.py", line 2066, in gather_dep
    response = await get_data_from_worker(
  File "/opt/conda/envs/gdf/lib/python3.9/site-packages/distributed/worker.py", line 2892, in get_data_from_worker
    response = await send_recv(
  File "/opt/conda/envs/gdf/lib/python3.9/site-packages/distributed/core.py", line 1024, in send_recv
    response = await comm.read(deserializers=deserializers)
  File "/opt/conda/envs/gdf/lib/python3.9/site-packages/distributed/utils.py", line 752, in wrapper
    return await func(*args, **kwargs)
  File "/opt/conda/envs/gdf/lib/python3.9/site-packages/distributed/comm/ucx.py", line 367, in read
    raise CommClosedError(
distributed.comm.core.CommClosedError: Connection closed by writer.
Inner exception: UCXCanceled("<[Recv #003] ep: 0x7fdb54f96240, tag: 0xd5fd5a8f97d4ebfa, nbytes: 16, type: <class 'numpy.ndarray'>>: ")
2023-06-16 06:00:10,435 - distributed.worker - ERROR - Worker stream died during communication: ucx://127.0.0.1:36201
Traceback (most recent call last):
  File "/opt/conda/envs/gdf/lib/python3.9/site-packages/distributed/comm/ucx.py", line 349, in read
    await self.ep.recv(msg)
  File "/opt/conda/envs/gdf/lib/python3.9/site-packages/ucp/core.py", line 725, in recv
    ret = await comm.tag_recv(self._ep, buffer, nbytes, tag, name=log)
ucp._libs.exceptions.UCXCanceled: <[Recv #000] ep: 0x7fc003785280, tag: 0x95f8f0b4b28e67cf, nbytes: 16, type: <class 'numpy.ndarray'>>: 

During handling of the above exception, another exception occurred:

Traceback (most recent call last):
  File "/opt/conda/envs/gdf/lib/python3.9/site-packages/distributed/comm/core.py", line 329, in connect
    handshake = await wait_for(comm.read(), time_left())
  File "/opt/conda/envs/gdf/lib/python3.9/site-packages/distributed/utils.py", line 1849, in wait_for
    return await asyncio.wait_for(fut, timeout)
  File "/opt/conda/envs/gdf/lib/python3.9/asyncio/tasks.py", line 479, in wait_for
    return fut.result()
  File "/opt/conda/envs/gdf/lib/python3.9/site-packages/distributed/utils.py", line 752, in wrapper
    return await func(*args, **kwargs)
  File "/opt/conda/envs/gdf/lib/python3.9/site-packages/distributed/comm/ucx.py", line 367, in read
    raise CommClosedError(
distributed.comm.core.CommClosedError: Connection closed by writer.
Inner exception: UCXCanceled("<[Recv #000] ep: 0x7fc003785280, tag: 0x95f8f0b4b28e67cf, nbytes: 16, type: <class 'numpy.ndarray'>>: ")

The above exception was the direct cause of the following exception:

Traceback (most recent call last):
  File "/opt/conda/envs/gdf/lib/python3.9/site-packages/distributed/worker.py", line 2066, in gather_dep
    response = await get_data_from_worker(
  File "/opt/conda/envs/gdf/lib/python3.9/site-packages/distributed/worker.py", line 2889, in get_data_from_worker
    comm = await rpc.connect(worker)
  File "/opt/conda/envs/gdf/lib/python3.9/site-packages/distributed/core.py", line 1506, in connect
    return await connect_attempt
  File "/opt/conda/envs/gdf/lib/python3.9/site-packages/distributed/core.py", line 1427, in _connect
    comm = await connect(
  File "/opt/conda/envs/gdf/lib/python3.9/site-packages/distributed/comm/core.py", line 334, in connect
    raise OSError(
OSError: Timed out during handshake while connecting to ucx://127.0.0.1:36201 after 30 s
2023-06-16 06:00:10,438 - distributed.nanny - WARNING - Restarting worker
2023-06-16 06:00:10,485 - distributed.nanny - WARNING - Restarting worker
2023-06-16 06:00:10,530 - distributed.nanny - WARNING - Restarting worker
2023-06-16 06:00:10,563 - distributed.nanny - WARNING - Restarting worker
2023-06-16 06:00:10,593 - distributed.worker - ERROR - Worker stream died during communication: ucx://127.0.0.1:45507
Traceback (most recent call last):
  File "/opt/conda/envs/gdf/lib/python3.9/site-packages/distributed/comm/ucx.py", line 349, in read
    await self.ep.recv(msg)
  File "/opt/conda/envs/gdf/lib/python3.9/site-packages/ucp/core.py", line 725, in recv
    ret = await comm.tag_recv(self._ep, buffer, nbytes, tag, name=log)
ucp._libs.exceptions.UCXCanceled: <[Recv #013] ep: 0x7fc003785180, tag: 0x11d5125a45c58e4d, nbytes: 16, type: <class 'numpy.ndarray'>>: 

During handling of the above exception, another exception occurred:

Traceback (most recent call last):
  File "/opt/conda/envs/gdf/lib/python3.9/site-packages/distributed/worker.py", line 2066, in gather_dep
    response = await get_data_from_worker(
  File "/opt/conda/envs/gdf/lib/python3.9/site-packages/distributed/worker.py", line 2892, in get_data_from_worker
    response = await send_recv(
  File "/opt/conda/envs/gdf/lib/python3.9/site-packages/distributed/core.py", line 1024, in send_recv
    response = await comm.read(deserializers=deserializers)
  File "/opt/conda/envs/gdf/lib/python3.9/site-packages/distributed/utils.py", line 752, in wrapper
    return await func(*args, **kwargs)
  File "/opt/conda/envs/gdf/lib/python3.9/site-packages/distributed/comm/ucx.py", line 367, in read
    raise CommClosedError(
distributed.comm.core.CommClosedError: Connection closed by writer.
Inner exception: UCXCanceled("<[Recv #013] ep: 0x7fc003785180, tag: 0x11d5125a45c58e4d, nbytes: 16, type: <class 'numpy.ndarray'>>: ")
2023-06-16 06:00:10,593 - distributed.worker - ERROR - failed during get data with ucx://127.0.0.1:57435 -> ucx://127.0.0.1:45507
Traceback (most recent call last):
  File "/opt/conda/envs/gdf/lib/python3.9/site-packages/distributed/comm/ucx.py", line 333, in write
    await self.ep.send(each_frame)
  File "/opt/conda/envs/gdf/lib/python3.9/site-packages/ucp/core.py", line 650, in send
    return await comm.tag_send(self._ep, buffer, nbytes, tag, name=log)
ucp._libs.exceptions.UCXError: <[Send #007] ep: 0x7fdb54f96280, tag: 0x9827b64f49eb56d0, nbytes: 50000000, type: <class 'cupy.ndarray'>>: Connection reset by remote peer

During handling of the above exception, another exception occurred:

Traceback (most recent call last):
  File "/opt/conda/envs/gdf/lib/python3.9/site-packages/distributed/worker.py", line 1792, in get_data
    compressed = await comm.write(msg, serializers=serializers)
  File "/opt/conda/envs/gdf/lib/python3.9/site-packages/distributed/utils.py", line 752, in wrapper
    return await func(*args, **kwargs)
  File "/opt/conda/envs/gdf/lib/python3.9/site-packages/distributed/comm/ucx.py", line 337, in write
    raise CommClosedError("While writing, the connection was closed")
distributed.comm.core.CommClosedError: While writing, the connection was closed
2023-06-16 06:00:10,593 - distributed.worker - ERROR - Worker stream died during communication: ucx://127.0.0.1:45507
Traceback (most recent call last):
  File "/opt/conda/envs/gdf/lib/python3.9/site-packages/distributed/comm/ucx.py", line 391, in read
    await self.ep.recv(each_frame)
  File "/opt/conda/envs/gdf/lib/python3.9/site-packages/ucp/core.py", line 725, in recv
    ret = await comm.tag_recv(self._ep, buffer, nbytes, tag, name=log)
ucp._libs.exceptions.UCXError: <[Recv #007] ep: 0x7fdb54f961c0, tag: 0xae22b8bdca734387, nbytes: 50000000, type: <class 'rmm._lib.device_buffer.DeviceBuffer'>>: Connection reset by remote peer

During handling of the above exception, another exception occurred:

Traceback (most recent call last):
  File "/opt/conda/envs/gdf/lib/python3.9/site-packages/distributed/worker.py", line 2066, in gather_dep
    response = await get_data_from_worker(
  File "/opt/conda/envs/gdf/lib/python3.9/site-packages/distributed/worker.py", line 2892, in get_data_from_worker
    response = await send_recv(
  File "/opt/conda/envs/gdf/lib/python3.9/site-packages/distributed/core.py", line 1024, in send_recv
    response = await comm.read(deserializers=deserializers)
  File "/opt/conda/envs/gdf/lib/python3.9/site-packages/distributed/utils.py", line 752, in wrapper
    return await func(*args, **kwargs)
  File "/opt/conda/envs/gdf/lib/python3.9/site-packages/distributed/comm/ucx.py", line 397, in read
    raise CommClosedError(
distributed.comm.core.CommClosedError: Connection closed by writer.
Inner exception: UCXError("<[Recv #007] ep: 0x7fdb54f961c0, tag: 0xae22b8bdca734387, nbytes: 50000000, type: <class 'rmm._lib.device_buffer.DeviceBuffer'>>: Connection reset by remote peer")
2023-06-16 06:00:10,631 - distributed.nanny - WARNING - Restarting worker
2023-06-16 06:00:11,949 - distributed.preloading - INFO - Creating preload: dask_cuda.initialize
2023-06-16 06:00:11,949 - distributed.preloading - INFO - Import preload module: dask_cuda.initialize
2023-06-16 06:00:12,016 - distributed.preloading - INFO - Creating preload: dask_cuda.initialize
2023-06-16 06:00:12,016 - distributed.preloading - INFO - Import preload module: dask_cuda.initialize
2023-06-16 06:00:12,023 - distributed.preloading - INFO - Creating preload: dask_cuda.initialize
2023-06-16 06:00:12,023 - distributed.preloading - INFO - Import preload module: dask_cuda.initialize
2023-06-16 06:00:12,116 - distributed.preloading - INFO - Creating preload: dask_cuda.initialize
2023-06-16 06:00:12,116 - distributed.preloading - INFO - Import preload module: dask_cuda.initialize
2023-06-16 06:00:12,192 - distributed.preloading - INFO - Creating preload: dask_cuda.initialize
2023-06-16 06:00:12,192 - distributed.preloading - INFO - Import preload module: dask_cuda.initialize
2023-06-16 06:00:40,209 - distributed.worker - ERROR - Worker stream died during communication: ucx://127.0.0.1:56787
Traceback (most recent call last):
  File "/opt/conda/envs/gdf/lib/python3.9/site-packages/distributed/comm/ucx.py", line 466, in connect
    ep = await ucp.create_endpoint(ip, port)
  File "/opt/conda/envs/gdf/lib/python3.9/site-packages/ucp/core.py", line 1004, in create_endpoint
    return await _get_ctx().create_endpoint(
  File "/opt/conda/envs/gdf/lib/python3.9/site-packages/ucp/core.py", line 316, in create_endpoint
    peer_info = await exchange_peer_info(
  File "/opt/conda/envs/gdf/lib/python3.9/site-packages/ucp/core.py", line 54, in exchange_peer_info
    await comm.stream_recv(endpoint, peer_info_arr, peer_info_arr.nbytes)
asyncio.exceptions.CancelledError

During handling of the above exception, another exception occurred:

Traceback (most recent call last):
  File "/opt/conda/envs/gdf/lib/python3.9/asyncio/tasks.py", line 490, in wait_for
    return fut.result()
asyncio.exceptions.CancelledError

The above exception was the direct cause of the following exception:

Traceback (most recent call last):
  File "/opt/conda/envs/gdf/lib/python3.9/site-packages/distributed/comm/core.py", line 292, in connect
    comm = await wait_for(
  File "/opt/conda/envs/gdf/lib/python3.9/site-packages/distributed/utils.py", line 1849, in wait_for
    return await asyncio.wait_for(fut, timeout)
  File "/opt/conda/envs/gdf/lib/python3.9/asyncio/tasks.py", line 492, in wait_for
    raise exceptions.TimeoutError() from exc
asyncio.exceptions.TimeoutError

The above exception was the direct cause of the following exception:

Traceback (most recent call last):
  File "/opt/conda/envs/gdf/lib/python3.9/site-packages/distributed/worker.py", line 2066, in gather_dep
    response = await get_data_from_worker(
  File "/opt/conda/envs/gdf/lib/python3.9/site-packages/distributed/worker.py", line 2889, in get_data_from_worker
    comm = await rpc.connect(worker)
  File "/opt/conda/envs/gdf/lib/python3.9/site-packages/distributed/core.py", line 1506, in connect
    return await connect_attempt
  File "/opt/conda/envs/gdf/lib/python3.9/site-packages/distributed/core.py", line 1427, in _connect
    comm = await connect(
  File "/opt/conda/envs/gdf/lib/python3.9/site-packages/distributed/comm/core.py", line 318, in connect
    raise OSError(
OSError: Timed out trying to connect to ucx://127.0.0.1:56787 after 30 s
[dgx13:77351:0:77351] Caught signal 11 (Segmentation fault: address not mapped to object at address 0x448)
==== backtrace (tid:  77351) ====
 0  /opt/conda/envs/gdf/lib/libucs.so.0(ucs_handle_error+0x2fd) [0x7fe604e36f1d]
 1  /opt/conda/envs/gdf/lib/libucs.so.0(+0x29114) [0x7fe604e37114]
 2  /opt/conda/envs/gdf/lib/libucs.so.0(+0x292da) [0x7fe604e372da]
 3  /usr/lib/x86_64-linux-gnu/libpthread.so.0(+0x14420) [0x7fe6a563d420]
 4  /opt/conda/envs/gdf/lib/libucp.so.0(ucp_mem_type_unpack+0x14) [0x7fe604eb05d4]
 5  /opt/conda/envs/gdf/lib/libucp.so.0(ucp_rndv_data_handler+0x4e9) [0x7fe604ed5859]
 6  /opt/conda/envs/gdf/lib/libuct.so.0(+0x2042f) [0x7fe604df242f]
 7  /opt/conda/envs/gdf/lib/libuct.so.0(+0x23798) [0x7fe604df5798]
 8  /opt/conda/envs/gdf/lib/libucs.so.0(ucs_event_set_wait+0xb9) [0x7fe604e3f989]
 9  /opt/conda/envs/gdf/lib/libuct.so.0(uct_tcp_iface_progress+0x7d) [0x7fe604df462d]
10  /opt/conda/envs/gdf/lib/libucp.so.0(ucp_worker_progress+0x5a) [0x7fe604eadc4a]
11  /opt/conda/envs/gdf/lib/python3.9/site-packages/ucp/_libs/ucx_api.cpython-39-x86_64-linux-gnu.so(+0x2b17a) [0x7fe604f5817a]
12  /opt/conda/envs/gdf/bin/python(+0x13eb08) [0x55562f529b08]
13  /opt/conda/envs/gdf/bin/python(_PyEval_EvalFrameDefault+0x5f82) [0x55562f51a112]
14  /opt/conda/envs/gdf/bin/python(+0x12827a) [0x55562f51327a]
15  /opt/conda/envs/gdf/bin/python(_PyFunction_Vectorcall+0xd5) [0x55562f524c05]
16  /opt/conda/envs/gdf/bin/python(_PyEval_EvalFrameDefault+0x68b) [0x55562f51481b]
17  /opt/conda/envs/gdf/bin/python(+0x139ef3) [0x55562f524ef3]
18  /opt/conda/envs/gdf/bin/python(+0x147a16) [0x55562f532a16]
19  /opt/conda/envs/gdf/bin/python(+0x2579b1) [0x55562f6429b1]
20  /opt/conda/envs/gdf/bin/python(+0xe5817) [0x55562f4d0817]
21  /opt/conda/envs/gdf/bin/python(+0x130f83) [0x55562f51bf83]
22  /opt/conda/envs/gdf/bin/python(_PyEval_EvalFrameDefault+0x5ba6) [0x55562f519d36]
23  /opt/conda/envs/gdf/bin/python(+0x139ef3) [0x55562f524ef3]
24  /opt/conda/envs/gdf/bin/python(_PyEval_EvalFrameDefault+0x68b) [0x55562f51481b]
25  /opt/conda/envs/gdf/bin/python(+0x139ef3) [0x55562f524ef3]
26  /opt/conda/envs/gdf/bin/python(_PyEval_EvalFrameDefault+0x68b) [0x55562f51481b]
27  /opt/conda/envs/gdf/bin/python(+0x139ef3) [0x55562f524ef3]
28  /opt/conda/envs/gdf/bin/python(_PyEval_EvalFrameDefault+0x68b) [0x55562f51481b]
29  /opt/conda/envs/gdf/bin/python(+0x139ef3) [0x55562f524ef3]
30  /opt/conda/envs/gdf/bin/python(_PyEval_EvalFrameDefault+0x68b) [0x55562f51481b]
31  /opt/conda/envs/gdf/bin/python(+0x12827a) [0x55562f51327a]
32  /opt/conda/envs/gdf/bin/python(_PyFunction_Vectorcall+0xd5) [0x55562f524c05]
33  /opt/conda/envs/gdf/bin/python(_PyEval_EvalFrameDefault+0x4e17) [0x55562f518fa7]
34  /opt/conda/envs/gdf/bin/python(+0x12827a) [0x55562f51327a]
35  /opt/conda/envs/gdf/bin/python(+0x147935) [0x55562f532935]
36  /opt/conda/envs/gdf/bin/python(PyObject_Call+0xb4) [0x55562f533104]
37  /opt/conda/envs/gdf/bin/python(+0x20efc8) [0x55562f5f9fc8]
38  /opt/conda/envs/gdf/bin/python(_PyObject_MakeTpCall+0x2fc) [0x55562f51d2bc]
39  /opt/conda/envs/gdf/bin/python(_PyEval_EvalFrameDefault+0x402b) [0x55562f5181bb]
40  /opt/conda/envs/gdf/bin/python(+0x139ef3) [0x55562f524ef3]
41  /opt/conda/envs/gdf/bin/python(+0x147c72) [0x55562f532c72]
42  /opt/conda/envs/gdf/bin/python(_PyEval_EvalFrameDefault+0x402b) [0x55562f5181bb]
43  /opt/conda/envs/gdf/bin/python(+0x139ef3) [0x55562f524ef3]
44  /opt/conda/envs/gdf/bin/python(_PyEval_EvalFrameDefault+0x68b) [0x55562f51481b]
45  /opt/conda/envs/gdf/bin/python(+0x12827a) [0x55562f51327a]
46  /opt/conda/envs/gdf/bin/python(_PyFunction_Vectorcall+0xd5) [0x55562f524c05]
47  /opt/conda/envs/gdf/bin/python(_PyEval_EvalFrameDefault+0x68b) [0x55562f51481b]
48  /opt/conda/envs/gdf/bin/python(+0x139ef3) [0x55562f524ef3]
49  /opt/conda/envs/gdf/bin/python(_PyEval_EvalFrameDefault+0x3d8) [0x55562f514568]
50  /opt/conda/envs/gdf/bin/python(+0x12827a) [0x55562f51327a]
51  /opt/conda/envs/gdf/bin/python(_PyFunction_Vectorcall+0xd5) [0x55562f524c05]
52  /opt/conda/envs/gdf/bin/python(_PyEval_EvalFrameDefault+0x123b) [0x55562f5153cb]
53  /opt/conda/envs/gdf/bin/python(+0x12827a) [0x55562f51327a]
54  /opt/conda/envs/gdf/bin/python(_PyEval_EvalCodeWithName+0x47) [0x55562f512f07]
55  /opt/conda/envs/gdf/bin/python(PyEval_EvalCodeEx+0x39) [0x55562f512eb9]
56  /opt/conda/envs/gdf/bin/python(PyEval_EvalCode+0x1b) [0x55562f5c38bb]
57  /opt/conda/envs/gdf/bin/python(+0x206adc) [0x55562f5f1adc]
58  /opt/conda/envs/gdf/bin/python(+0x202c24) [0x55562f5edc24]
59  /opt/conda/envs/gdf/bin/python(PyRun_StringFlags+0x9d) [0x55562f5e57ed]
60  /opt/conda/envs/gdf/bin/python(PyRun_SimpleStringFlags+0x3d) [0x55562f5e56bd]
61  /opt/conda/envs/gdf/bin/python(Py_RunMain+0x262) [0x55562f5e48a2]
=================================
[dgx13:77354:0:77354] Caught signal 11 (Segmentation fault: address not mapped to object at address 0x448)
==== backtrace (tid:  77354) ====
 0  /opt/conda/envs/gdf/lib/libucs.so.0(ucs_handle_error+0x2fd) [0x7fca557e7f1d]
 1  /opt/conda/envs/gdf/lib/libucs.so.0(+0x29114) [0x7fca557e8114]
 2  /opt/conda/envs/gdf/lib/libucs.so.0(+0x292da) [0x7fca557e82da]
 3  /usr/lib/x86_64-linux-gnu/libpthread.so.0(+0x14420) [0x7fcafa00a420]
 4  /opt/conda/envs/gdf/lib/libucp.so.0(ucp_mem_type_unpack+0x14) [0x7fca558615d4]
 5  /opt/conda/envs/gdf/lib/libucp.so.0(ucp_rndv_data_handler+0x4e9) [0x7fca55886859]
 6  /opt/conda/envs/gdf/lib/libuct.so.0(+0x2042f) [0x7fca557a342f]
 7  /opt/conda/envs/gdf/lib/libuct.so.0(+0x23798) [0x7fca557a6798]
 8  /opt/conda/envs/gdf/lib/libucs.so.0(ucs_event_set_wait+0xb9) [0x7fca557f0989]
 9  /opt/conda/envs/gdf/lib/libuct.so.0(uct_tcp_iface_progress+0x7d) [0x7fca557a562d]
10  /opt/conda/envs/gdf/lib/libucp.so.0(ucp_worker_progress+0x5a) [0x7fca5585ec4a]
11  /opt/conda/envs/gdf/lib/python3.9/site-packages/ucp/_libs/ucx_api.cpython-39-x86_64-linux-gnu.so(+0x2b17a) [0x7fca559a217a]
12  /opt/conda/envs/gdf/bin/python(+0x13eb08) [0x55e434dc3b08]
13  /opt/conda/envs/gdf/bin/python(_PyEval_EvalFrameDefault+0x5f82) [0x55e434db4112]
14  /opt/conda/envs/gdf/bin/python(+0x12827a) [0x55e434dad27a]
15  /opt/conda/envs/gdf/bin/python(_PyFunction_Vectorcall+0xd5) [0x55e434dbec05]
16  /opt/conda/envs/gdf/bin/python(_PyEval_EvalFrameDefault+0x68b) [0x55e434dae81b]
17  /opt/conda/envs/gdf/bin/python(+0x14e70e) [0x55e434dd370e]
18  /opt/conda/envs/gdf/lib/python3.9/lib-dynload/_asyncio.cpython-39-x86_64-linux-gnu.so(+0x82fe) [0x7fca79bae2fe]
19  /opt/conda/envs/gdf/bin/python(_PyObject_MakeTpCall+0x2fc) [0x55e434db72bc]
20  /opt/conda/envs/gdf/bin/python(+0xe5817) [0x55e434d6a817]
21  /opt/conda/envs/gdf/bin/python(+0x130f83) [0x55e434db5f83]
22  /opt/conda/envs/gdf/bin/python(_PyEval_EvalFrameDefault+0x5ba6) [0x55e434db3d36]
23  /opt/conda/envs/gdf/bin/python(+0x139ef3) [0x55e434dbeef3]
24  /opt/conda/envs/gdf/bin/python(_PyEval_EvalFrameDefault+0x68b) [0x55e434dae81b]
25  /opt/conda/envs/gdf/bin/python(+0x139ef3) [0x55e434dbeef3]
26  /opt/conda/envs/gdf/bin/python(_PyEval_EvalFrameDefault+0x68b) [0x55e434dae81b]
27  /opt/conda/envs/gdf/bin/python(+0x139ef3) [0x55e434dbeef3]
28  /opt/conda/envs/gdf/bin/python(_PyEval_EvalFrameDefault+0x68b) [0x55e434dae81b]
29  /opt/conda/envs/gdf/bin/python(+0x139ef3) [0x55e434dbeef3]
30  /opt/conda/envs/gdf/bin/python(_PyEval_EvalFrameDefault+0x68b) [0x55e434dae81b]
31  /opt/conda/envs/gdf/bin/python(+0x12827a) [0x55e434dad27a]
32  /opt/conda/envs/gdf/bin/python(_PyFunction_Vectorcall+0xd5) [0x55e434dbec05]
33  /opt/conda/envs/gdf/bin/python(_PyEval_EvalFrameDefault+0x4e17) [0x55e434db2fa7]
34  /opt/conda/envs/gdf/bin/python(+0x12827a) [0x55e434dad27a]
35  /opt/conda/envs/gdf/bin/python(+0x147935) [0x55e434dcc935]
36  /opt/conda/envs/gdf/bin/python(PyObject_Call+0xb4) [0x55e434dcd104]
37  /opt/conda/envs/gdf/bin/python(+0x20efc8) [0x55e434e93fc8]
38  /opt/conda/envs/gdf/bin/python(_PyObject_MakeTpCall+0x2fc) [0x55e434db72bc]
39  /opt/conda/envs/gdf/bin/python(_PyEval_EvalFrameDefault+0x402b) [0x55e434db21bb]
40  /opt/conda/envs/gdf/bin/python(+0x139ef3) [0x55e434dbeef3]
41  /opt/conda/envs/gdf/bin/python(+0x147c72) [0x55e434dccc72]
42  /opt/conda/envs/gdf/bin/python(_PyEval_EvalFrameDefault+0x402b) [0x55e434db21bb]
43  /opt/conda/envs/gdf/bin/python(+0x139ef3) [0x55e434dbeef3]
44  /opt/conda/envs/gdf/bin/python(_PyEval_EvalFrameDefault+0x68b) [0x55e434dae81b]
45  /opt/conda/envs/gdf/bin/python(+0x12827a) [0x55e434dad27a]
46  /opt/conda/envs/gdf/bin/python(_PyFunction_Vectorcall+0xd5) [0x55e434dbec05]
47  /opt/conda/envs/gdf/bin/python(_PyEval_EvalFrameDefault+0x68b) [0x55e434dae81b]
48  /opt/conda/envs/gdf/bin/python(+0x139ef3) [0x55e434dbeef3]
49  /opt/conda/envs/gdf/bin/python(_PyEval_EvalFrameDefault+0x3d8) [0x55e434dae568]
50  /opt/conda/envs/gdf/bin/python(+0x12827a) [0x55e434dad27a]
51  /opt/conda/envs/gdf/bin/python(_PyFunction_Vectorcall+0xd5) [0x55e434dbec05]
52  /opt/conda/envs/gdf/bin/python(_PyEval_EvalFrameDefault+0x123b) [0x55e434daf3cb]
53  /opt/conda/envs/gdf/bin/python(+0x12827a) [0x55e434dad27a]
54  /opt/conda/envs/gdf/bin/python(_PyEval_EvalCodeWithName+0x47) [0x55e434dacf07]
55  /opt/conda/envs/gdf/bin/python(PyEval_EvalCodeEx+0x39) [0x55e434daceb9]
56  /opt/conda/envs/gdf/bin/python(PyEval_EvalCode+0x1b) [0x55e434e5d8bb]
57  /opt/conda/envs/gdf/bin/python(+0x206adc) [0x55e434e8badc]
58  /opt/conda/envs/gdf/bin/python(+0x202c24) [0x55e434e87c24]
59  /opt/conda/envs/gdf/bin/python(PyRun_StringFlags+0x9d) [0x55e434e7f7ed]
60  /opt/conda/envs/gdf/bin/python(PyRun_SimpleStringFlags+0x3d) [0x55e434e7f6bd]
61  /opt/conda/envs/gdf/bin/python(Py_RunMain+0x262) [0x55e434e7e8a2]
=================================
[dgx13:77357:0:77357] Caught signal 11 (Segmentation fault: address not mapped to object at address 0x448)
==== backtrace (tid:  77357) ====
 0  /opt/conda/envs/gdf/lib/libucs.so.0(ucs_handle_error+0x2fd) [0x7f7b795b7f1d]
 1  /opt/conda/envs/gdf/lib/libucs.so.0(+0x29114) [0x7f7b795b8114]
 2  /opt/conda/envs/gdf/lib/libucs.so.0(+0x292da) [0x7f7b795b82da]
 3  /usr/lib/x86_64-linux-gnu/libpthread.so.0(+0x14420) [0x7f7c1dde2420]
 4  /opt/conda/envs/gdf/lib/libucp.so.0(ucp_mem_type_unpack+0x14) [0x7f7b796315d4]
 5  /opt/conda/envs/gdf/lib/libucp.so.0(ucp_rndv_data_handler+0x4e9) [0x7f7b79656859]
 6  /opt/conda/envs/gdf/lib/libuct.so.0(+0x2042f) [0x7f7b7957342f]
 7  /opt/conda/envs/gdf/lib/libuct.so.0(+0x23798) [0x7f7b79576798]
 8  /opt/conda/envs/gdf/lib/libucs.so.0(ucs_event_set_wait+0xb9) [0x7f7b795c0989]
 9  /opt/conda/envs/gdf/lib/libuct.so.0(uct_tcp_iface_progress+0x7d) [0x7f7b7957562d]
10  /opt/conda/envs/gdf/lib/libucp.so.0(ucp_worker_progress+0x5a) [0x7f7b7962ec4a]
11  /opt/conda/envs/gdf/lib/python3.9/site-packages/ucp/_libs/ucx_api.cpython-39-x86_64-linux-gnu.so(+0x2b17a) [0x7f7b796d917a]
12  /opt/conda/envs/gdf/bin/python(+0x13eb08) [0x55b2f49fcb08]
13  /opt/conda/envs/gdf/bin/python(_PyEval_EvalFrameDefault+0x5f82) [0x55b2f49ed112]
14  /opt/conda/envs/gdf/bin/python(+0x12827a) [0x55b2f49e627a]
15  /opt/conda/envs/gdf/bin/python(_PyFunction_Vectorcall+0xd5) [0x55b2f49f7c05]
16  /opt/conda/envs/gdf/bin/python(_PyEval_EvalFrameDefault+0x68b) [0x55b2f49e781b]
17  /opt/conda/envs/gdf/bin/python(+0x139ef3) [0x55b2f49f7ef3]
18  /opt/conda/envs/gdf/bin/python(+0x147a16) [0x55b2f4a05a16]
19  /opt/conda/envs/gdf/bin/python(+0x2579b1) [0x55b2f4b159b1]
20  /opt/conda/envs/gdf/bin/python(+0xe5817) [0x55b2f49a3817]
21  /opt/conda/envs/gdf/bin/python(+0x130f83) [0x55b2f49eef83]
22  /opt/conda/envs/gdf/bin/python(_PyEval_EvalFrameDefault+0x5ba6) [0x55b2f49ecd36]
23  /opt/conda/envs/gdf/bin/python(+0x139ef3) [0x55b2f49f7ef3]
24  /opt/conda/envs/gdf/bin/python(_PyEval_EvalFrameDefault+0x68b) [0x55b2f49e781b]
25  /opt/conda/envs/gdf/bin/python(+0x139ef3) [0x55b2f49f7ef3]
26  /opt/conda/envs/gdf/bin/python(_PyEval_EvalFrameDefault+0x68b) [0x55b2f49e781b]
27  /opt/conda/envs/gdf/bin/python(+0x139ef3) [0x55b2f49f7ef3]
28  /opt/conda/envs/gdf/bin/python(_PyEval_EvalFrameDefault+0x68b) [0x55b2f49e781b]
29  /opt/conda/envs/gdf/bin/python(+0x139ef3) [0x55b2f49f7ef3]
30  /opt/conda/envs/gdf/bin/python(_PyEval_EvalFrameDefault+0x68b) [0x55b2f49e781b]
31  /opt/conda/envs/gdf/bin/python(+0x12827a) [0x55b2f49e627a]
32  /opt/conda/envs/gdf/bin/python(_PyFunction_Vectorcall+0xd5) [0x55b2f49f7c05]
33  /opt/conda/envs/gdf/bin/python(_PyEval_EvalFrameDefault+0x4e17) [0x55b2f49ebfa7]
34  /opt/conda/envs/gdf/bin/python(+0x12827a) [0x55b2f49e627a]
35  /opt/conda/envs/gdf/bin/python(+0x147935) [0x55b2f4a05935]
36  /opt/conda/envs/gdf/bin/python(PyObject_Call+0xb4) [0x55b2f4a06104]
37  /opt/conda/envs/gdf/bin/python(+0x20efc8) [0x55b2f4accfc8]
38  /opt/conda/envs/gdf/bin/python(_PyObject_MakeTpCall+0x2fc) [0x55b2f49f02bc]
39  /opt/conda/envs/gdf/bin/python(_PyEval_EvalFrameDefault+0x402b) [0x55b2f49eb1bb]
40  /opt/conda/envs/gdf/bin/python(+0x139ef3) [0x55b2f49f7ef3]
41  /opt/conda/envs/gdf/bin/python(+0x147c72) [0x55b2f4a05c72]
42  /opt/conda/envs/gdf/bin/python(_PyEval_EvalFrameDefault+0x402b) [0x55b2f49eb1bb]
43  /opt/conda/envs/gdf/bin/python(+0x139ef3) [0x55b2f49f7ef3]
44  /opt/conda/envs/gdf/bin/python(_PyEval_EvalFrameDefault+0x68b) [0x55b2f49e781b]
45  /opt/conda/envs/gdf/bin/python(+0x12827a) [0x55b2f49e627a]
46  /opt/conda/envs/gdf/bin/python(_PyFunction_Vectorcall+0xd5) [0x55b2f49f7c05]
47  /opt/conda/envs/gdf/bin/python(_PyEval_EvalFrameDefault+0x68b) [0x55b2f49e781b]
48  /opt/conda/envs/gdf/bin/python(+0x139ef3) [0x55b2f49f7ef3]
49  /opt/conda/envs/gdf/bin/python(_PyEval_EvalFrameDefault+0x3d8) [0x55b2f49e7568]
50  /opt/conda/envs/gdf/bin/python(+0x12827a) [0x55b2f49e627a]
51  /opt/conda/envs/gdf/bin/python(_PyFunction_Vectorcall+0xd5) [0x55b2f49f7c05]
52  /opt/conda/envs/gdf/bin/python(_PyEval_EvalFrameDefault+0x123b) [0x55b2f49e83cb]
53  /opt/conda/envs/gdf/bin/python(+0x12827a) [0x55b2f49e627a]
54  /opt/conda/envs/gdf/bin/python(_PyEval_EvalCodeWithName+0x47) [0x55b2f49e5f07]
55  /opt/conda/envs/gdf/bin/python(PyEval_EvalCodeEx+0x39) [0x55b2f49e5eb9]
56  /opt/conda/envs/gdf/bin/python(PyEval_EvalCode+0x1b) [0x55b2f4a968bb]
57  /opt/conda/envs/gdf/bin/python(+0x206adc) [0x55b2f4ac4adc]
58  /opt/conda/envs/gdf/bin/python(+0x202c24) [0x55b2f4ac0c24]
59  /opt/conda/envs/gdf/bin/python(PyRun_StringFlags+0x9d) [0x55b2f4ab87ed]
60  /opt/conda/envs/gdf/bin/python(PyRun_SimpleStringFlags+0x3d) [0x55b2f4ab86bd]
61  /opt/conda/envs/gdf/bin/python(Py_RunMain+0x262) [0x55b2f4ab78a2]
=================================
2023-06-16 06:00:41,088 - distributed.worker - ERROR - failed during get data with ucx://127.0.0.1:41819 -> ucx://127.0.0.1:38639
Traceback (most recent call last):
  File "/opt/conda/envs/gdf/lib/python3.9/site-packages/distributed/comm/ucx.py", line 333, in write
    await self.ep.send(each_frame)
  File "/opt/conda/envs/gdf/lib/python3.9/site-packages/ucp/core.py", line 650, in send
    return await comm.tag_send(self._ep, buffer, nbytes, tag, name=log)
ucp._libs.exceptions.UCXError: <[Send #007] ep: 0x7fc003785380, tag: 0x79fb7743ac231e53, nbytes: 50000000, type: <class 'cupy.ndarray'>>: Connection reset by remote peer

During handling of the above exception, another exception occurred:

Traceback (most recent call last):
  File "/opt/conda/envs/gdf/lib/python3.9/site-packages/distributed/worker.py", line 1792, in get_data
    compressed = await comm.write(msg, serializers=serializers)
  File "/opt/conda/envs/gdf/lib/python3.9/site-packages/distributed/utils.py", line 752, in wrapper
    return await func(*args, **kwargs)
  File "/opt/conda/envs/gdf/lib/python3.9/site-packages/distributed/comm/ucx.py", line 337, in write
    raise CommClosedError("While writing, the connection was closed")
distributed.comm.core.CommClosedError: While writing, the connection was closed
2023-06-16 06:00:41,088 - distributed.worker - ERROR - failed during get data with ucx://127.0.0.1:49835 -> ucx://127.0.0.1:38639
Traceback (most recent call last):
  File "/opt/conda/envs/gdf/lib/python3.9/site-packages/distributed/comm/ucx.py", line 333, in write
    await self.ep.send(each_frame)
  File "/opt/conda/envs/gdf/lib/python3.9/site-packages/ucp/core.py", line 650, in send
    return await comm.tag_send(self._ep, buffer, nbytes, tag, name=log)
ucp._libs.exceptions.UCXError: <[Send #007] ep: 0x7f8518868240, tag: 0x890709973b1584eb, nbytes: 50000000, type: <class 'cupy.ndarray'>>: Connection reset by remote peer

During handling of the above exception, another exception occurred:

Traceback (most recent call last):
  File "/opt/conda/envs/gdf/lib/python3.9/site-packages/distributed/worker.py", line 1792, in get_data
    compressed = await comm.write(msg, serializers=serializers)
  File "/opt/conda/envs/gdf/lib/python3.9/site-packages/distributed/utils.py", line 752, in wrapper
    return await func(*args, **kwargs)
  File "/opt/conda/envs/gdf/lib/python3.9/site-packages/distributed/comm/ucx.py", line 337, in write
    raise CommClosedError("While writing, the connection was closed")
distributed.comm.core.CommClosedError: While writing, the connection was closed
2023-06-16 06:00:41,096 - distributed.worker - ERROR - failed during get data with ucx://127.0.0.1:41819 -> ucx://127.0.0.1:38727
Traceback (most recent call last):
  File "/opt/conda/envs/gdf/lib/python3.9/site-packages/distributed/comm/ucx.py", line 333, in write
    await self.ep.send(each_frame)
  File "/opt/conda/envs/gdf/lib/python3.9/site-packages/ucp/core.py", line 650, in send
    return await comm.tag_send(self._ep, buffer, nbytes, tag, name=log)
ucp._libs.exceptions.UCXError: <[Send #007] ep: 0x7fc003785280, tag: 0x4555988597bf352c, nbytes: 50000000, type: <class 'cupy.ndarray'>>: Connection reset by remote peer

During handling of the above exception, another exception occurred:

Traceback (most recent call last):
  File "/opt/conda/envs/gdf/lib/python3.9/site-packages/distributed/worker.py", line 1792, in get_data
    compressed = await comm.write(msg, serializers=serializers)
  File "/opt/conda/envs/gdf/lib/python3.9/site-packages/distributed/utils.py", line 752, in wrapper
    return await func(*args, **kwargs)
  File "/opt/conda/envs/gdf/lib/python3.9/site-packages/distributed/comm/ucx.py", line 337, in write
    raise CommClosedError("While writing, the connection was closed")
distributed.comm.core.CommClosedError: While writing, the connection was closed
2023-06-16 06:00:41,097 - distributed.worker - ERROR - failed during get data with ucx://127.0.0.1:41819 -> ucx://127.0.0.1:46581
Traceback (most recent call last):
  File "/opt/conda/envs/gdf/lib/python3.9/site-packages/distributed/comm/ucx.py", line 333, in write
    await self.ep.send(each_frame)
  File "/opt/conda/envs/gdf/lib/python3.9/site-packages/ucp/core.py", line 650, in send
    return await comm.tag_send(self._ep, buffer, nbytes, tag, name=log)
ucp._libs.exceptions.UCXError: <[Send #007] ep: 0x7fc003785300, tag: 0xbd7c2554dfcfa423, nbytes: 50000000, type: <class 'cupy.ndarray'>>: Connection reset by remote peer

During handling of the above exception, another exception occurred:

Traceback (most recent call last):
  File "/opt/conda/envs/gdf/lib/python3.9/site-packages/distributed/worker.py", line 1792, in get_data
    compressed = await comm.write(msg, serializers=serializers)
  File "/opt/conda/envs/gdf/lib/python3.9/site-packages/distributed/utils.py", line 752, in wrapper
    return await func(*args, **kwargs)
  File "/opt/conda/envs/gdf/lib/python3.9/site-packages/distributed/comm/ucx.py", line 337, in write
    raise CommClosedError("While writing, the connection was closed")
distributed.comm.core.CommClosedError: While writing, the connection was closed
Task exception was never retrieved
future: <Task finished name='Task-7508' coro=<_listener_handler_coroutine() done, defined at /opt/conda/envs/gdf/lib/python3.9/site-packages/ucp/core.py:128> exception=UCXError('<stream_send>: Connection reset by remote peer')>
Traceback (most recent call last):
  File "/opt/conda/envs/gdf/lib/python3.9/site-packages/ucp/core.py", line 143, in _listener_handler_coroutine
    peer_info = await exchange_peer_info(
  File "/opt/conda/envs/gdf/lib/python3.9/site-packages/ucp/core.py", line 51, in exchange_peer_info
    await comm.stream_send(endpoint, my_info_arr, my_info_arr.nbytes)
ucp._libs.exceptions.UCXError: <stream_send>: Connection reset by remote peer
Task exception was never retrieved
future: <Task finished name='Task-6135' coro=<_listener_handler_coroutine() done, defined at /opt/conda/envs/gdf/lib/python3.9/site-packages/ucp/core.py:128> exception=UCXError('<stream_send>: Connection reset by remote peer')>
Traceback (most recent call last):
  File "/opt/conda/envs/gdf/lib/python3.9/site-packages/ucp/core.py", line 143, in _listener_handler_coroutine
    peer_info = await exchange_peer_info(
  File "/opt/conda/envs/gdf/lib/python3.9/site-packages/ucp/core.py", line 51, in exchange_peer_info
    await comm.stream_send(endpoint, my_info_arr, my_info_arr.nbytes)
ucp._libs.exceptions.UCXError: <stream_send>: Connection reset by remote peer
2023-06-16 06:00:41,137 - distributed.nanny - WARNING - Restarting worker
2023-06-16 06:00:41,214 - distributed.nanny - WARNING - Restarting worker
2023-06-16 06:00:41,215 - distributed.nanny - WARNING - Restarting worker
2023-06-16 06:00:42,531 - distributed.preloading - INFO - Creating preload: dask_cuda.initialize
2023-06-16 06:00:42,531 - distributed.preloading - INFO - Import preload module: dask_cuda.initialize
2023-06-16 06:00:42,617 - distributed.preloading - INFO - Creating preload: dask_cuda.initialize
2023-06-16 06:00:42,618 - distributed.preloading - INFO - Import preload module: dask_cuda.initialize
2023-06-16 06:00:42,648 - distributed.preloading - INFO - Creating preload: dask_cuda.initialize
2023-06-16 06:00:42,648 - distributed.preloading - INFO - Import preload module: dask_cuda.initialize
/opt/conda/envs/gdf/lib/python3.9/multiprocessing/resource_tracker.py:216: UserWarning: resource_tracker: There appear to be 48 leaked semaphore objects to clean up at shutdown
  warnings.warn('resource_tracker: There appear to be %d '
