2023-05-29 05:47:20,771 - distributed.preloading - INFO - Creating preload: dask_cuda.initialize
2023-05-29 05:47:20,771 - distributed.preloading - INFO - Import preload module: dask_cuda.initialize
2023-05-29 05:47:20,773 - distributed.preloading - INFO - Creating preload: dask_cuda.initialize
2023-05-29 05:47:20,773 - distributed.preloading - INFO - Import preload module: dask_cuda.initialize
2023-05-29 05:47:20,778 - distributed.preloading - INFO - Creating preload: dask_cuda.initialize
2023-05-29 05:47:20,779 - distributed.preloading - INFO - Import preload module: dask_cuda.initialize
2023-05-29 05:47:20,779 - distributed.preloading - INFO - Creating preload: dask_cuda.initialize
2023-05-29 05:47:20,779 - distributed.preloading - INFO - Import preload module: dask_cuda.initialize
2023-05-29 05:47:20,781 - distributed.preloading - INFO - Creating preload: dask_cuda.initialize
2023-05-29 05:47:20,781 - distributed.preloading - INFO - Import preload module: dask_cuda.initialize
2023-05-29 05:47:20,787 - distributed.preloading - INFO - Creating preload: dask_cuda.initialize
2023-05-29 05:47:20,787 - distributed.preloading - INFO - Import preload module: dask_cuda.initialize
2023-05-29 05:47:20,792 - distributed.preloading - INFO - Creating preload: dask_cuda.initialize
2023-05-29 05:47:20,792 - distributed.preloading - INFO - Import preload module: dask_cuda.initialize
2023-05-29 05:47:20,810 - distributed.preloading - INFO - Creating preload: dask_cuda.initialize
2023-05-29 05:47:20,810 - distributed.preloading - INFO - Import preload module: dask_cuda.initialize
[dgx13:68371:0:68371] Caught signal 11 (Segmentation fault: address not mapped to object at address 0x448)
==== backtrace (tid:  68371) ====
 0  /opt/conda/envs/gdf/lib/libucs.so.0(ucs_handle_error+0x2dc) [0x7fd12778011c]
 1  /opt/conda/envs/gdf/lib/libucs.so.0(+0x302ff) [0x7fd1277802ff]
 2  /opt/conda/envs/gdf/lib/libucs.so.0(+0x30634) [0x7fd127780634]
 3  /usr/lib/x86_64-linux-gnu/libpthread.so.0(+0x14420) [0x7fd1e0175420]
 4  /opt/conda/envs/gdf/lib/libucp.so.0(ucp_mem_type_unpack+0x1b) [0x7fd12780128b]
 5  /opt/conda/envs/gdf/lib/libucp.so.0(ucp_rndv_data_handler+0x508) [0x7fd12782b0b8]
 6  /opt/conda/envs/gdf/lib/libuct.so.0(+0x216a7) [0x7fd1277326a7]
 7  /opt/conda/envs/gdf/lib/libuct.so.0(+0x21c28) [0x7fd127732c28]
 8  /opt/conda/envs/gdf/lib/libuct.so.0(+0x240fc) [0x7fd1277350fc]
 9  /opt/conda/envs/gdf/lib/libucs.so.0(ucs_event_set_wait+0xf9) [0x7fd12778a639]
10  /opt/conda/envs/gdf/lib/libuct.so.0(uct_tcp_iface_progress+0x7b) [0x7fd1277351ab]
11  /opt/conda/envs/gdf/lib/libucp.so.0(ucp_worker_progress+0x6a) [0x7fd1277fdf1a]
12  /opt/conda/envs/gdf/lib/python3.9/site-packages/ucp/_libs/ucx_api.cpython-39-x86_64-linux-gnu.so(+0x286e1) [0x7fd1278ad6e1]
13  /opt/conda/envs/gdf/bin/python(+0x13eb08) [0x55ebebfcbb08]
14  /opt/conda/envs/gdf/bin/python(_PyEval_EvalFrameDefault+0x5f82) [0x55ebebfbc112]
15  /opt/conda/envs/gdf/bin/python(+0x12827a) [0x55ebebfb527a]
16  /opt/conda/envs/gdf/bin/python(_PyFunction_Vectorcall+0xd5) [0x55ebebfc6c05]
17  /opt/conda/envs/gdf/bin/python(_PyEval_EvalFrameDefault+0x68b) [0x55ebebfb681b]
18  /opt/conda/envs/gdf/bin/python(+0x14e70e) [0x55ebebfdb70e]
19  /opt/conda/envs/gdf/lib/python3.9/lib-dynload/_asyncio.cpython-39-x86_64-linux-gnu.so(+0x82fe) [0x7fd15fb912fe]
20  /opt/conda/envs/gdf/bin/python(_PyObject_MakeTpCall+0x2fc) [0x55ebebfbf2bc]
21  /opt/conda/envs/gdf/bin/python(+0xe5817) [0x55ebebf72817]
22  /opt/conda/envs/gdf/bin/python(+0x130f83) [0x55ebebfbdf83]
23  /opt/conda/envs/gdf/bin/python(_PyEval_EvalFrameDefault+0x5ba6) [0x55ebebfbbd36]
24  /opt/conda/envs/gdf/bin/python(+0x139ef3) [0x55ebebfc6ef3]
25  /opt/conda/envs/gdf/bin/python(_PyEval_EvalFrameDefault+0x68b) [0x55ebebfb681b]
26  /opt/conda/envs/gdf/bin/python(+0x139ef3) [0x55ebebfc6ef3]
27  /opt/conda/envs/gdf/bin/python(_PyEval_EvalFrameDefault+0x68b) [0x55ebebfb681b]
28  /opt/conda/envs/gdf/bin/python(+0x139ef3) [0x55ebebfc6ef3]
29  /opt/conda/envs/gdf/bin/python(_PyEval_EvalFrameDefault+0x68b) [0x55ebebfb681b]
30  /opt/conda/envs/gdf/bin/python(+0x139ef3) [0x55ebebfc6ef3]
31  /opt/conda/envs/gdf/bin/python(_PyEval_EvalFrameDefault+0x68b) [0x55ebebfb681b]
32  /opt/conda/envs/gdf/bin/python(+0x12827a) [0x55ebebfb527a]
33  /opt/conda/envs/gdf/bin/python(_PyFunction_Vectorcall+0xd5) [0x55ebebfc6c05]
34  /opt/conda/envs/gdf/bin/python(_PyEval_EvalFrameDefault+0x4e17) [0x55ebebfbafa7]
35  /opt/conda/envs/gdf/bin/python(+0x12827a) [0x55ebebfb527a]
36  /opt/conda/envs/gdf/bin/python(+0x147935) [0x55ebebfd4935]
37  /opt/conda/envs/gdf/bin/python(PyObject_Call+0xb4) [0x55ebebfd5104]
38  /opt/conda/envs/gdf/bin/python(+0x20efc8) [0x55ebec09bfc8]
39  /opt/conda/envs/gdf/bin/python(_PyObject_MakeTpCall+0x2fc) [0x55ebebfbf2bc]
40  /opt/conda/envs/gdf/bin/python(_PyEval_EvalFrameDefault+0x402b) [0x55ebebfba1bb]
41  /opt/conda/envs/gdf/bin/python(+0x139ef3) [0x55ebebfc6ef3]
42  /opt/conda/envs/gdf/bin/python(+0x147c72) [0x55ebebfd4c72]
43  /opt/conda/envs/gdf/bin/python(_PyEval_EvalFrameDefault+0x402b) [0x55ebebfba1bb]
44  /opt/conda/envs/gdf/bin/python(+0x139ef3) [0x55ebebfc6ef3]
45  /opt/conda/envs/gdf/bin/python(_PyEval_EvalFrameDefault+0x68b) [0x55ebebfb681b]
46  /opt/conda/envs/gdf/bin/python(+0x12827a) [0x55ebebfb527a]
47  /opt/conda/envs/gdf/bin/python(_PyFunction_Vectorcall+0xd5) [0x55ebebfc6c05]
48  /opt/conda/envs/gdf/bin/python(_PyEval_EvalFrameDefault+0x68b) [0x55ebebfb681b]
49  /opt/conda/envs/gdf/bin/python(+0x139ef3) [0x55ebebfc6ef3]
50  /opt/conda/envs/gdf/bin/python(_PyEval_EvalFrameDefault+0x3d8) [0x55ebebfb6568]
51  /opt/conda/envs/gdf/bin/python(+0x12827a) [0x55ebebfb527a]
52  /opt/conda/envs/gdf/bin/python(_PyFunction_Vectorcall+0xd5) [0x55ebebfc6c05]
53  /opt/conda/envs/gdf/bin/python(_PyEval_EvalFrameDefault+0x123b) [0x55ebebfb73cb]
54  /opt/conda/envs/gdf/bin/python(+0x12827a) [0x55ebebfb527a]
55  /opt/conda/envs/gdf/bin/python(_PyEval_EvalCodeWithName+0x47) [0x55ebebfb4f07]
56  /opt/conda/envs/gdf/bin/python(PyEval_EvalCodeEx+0x39) [0x55ebebfb4eb9]
57  /opt/conda/envs/gdf/bin/python(PyEval_EvalCode+0x1b) [0x55ebec0658bb]
58  /opt/conda/envs/gdf/bin/python(+0x206adc) [0x55ebec093adc]
59  /opt/conda/envs/gdf/bin/python(+0x202c24) [0x55ebec08fc24]
60  /opt/conda/envs/gdf/bin/python(PyRun_StringFlags+0x9d) [0x55ebec0877ed]
61  /opt/conda/envs/gdf/bin/python(PyRun_SimpleStringFlags+0x3d) [0x55ebec0876bd]
=================================
[dgx13:68389:0:68389] Caught signal 11 (Segmentation fault: address not mapped to object at address 0x448)
==== backtrace (tid:  68389) ====
 0  /opt/conda/envs/gdf/lib/libucs.so.0(ucs_handle_error+0x2dc) [0x7fbb05db711c]
 1  /opt/conda/envs/gdf/lib/libucs.so.0(+0x302ff) [0x7fbb05db72ff]
 2  /opt/conda/envs/gdf/lib/libucs.so.0(+0x30634) [0x7fbb05db7634]
 3  /usr/lib/x86_64-linux-gnu/libpthread.so.0(+0x14420) [0x7fbbc07ad420]
 4  /opt/conda/envs/gdf/lib/libucp.so.0(ucp_mem_type_unpack+0x1b) [0x7fbb05e3828b]
 5  /opt/conda/envs/gdf/lib/libucp.so.0(ucp_rndv_data_handler+0x508) [0x7fbb05e620b8]
 6  /opt/conda/envs/gdf/lib/libuct.so.0(+0x216a7) [0x7fbb05d696a7]
 7  /opt/conda/envs/gdf/lib/libuct.so.0(+0x21c28) [0x7fbb05d69c28]
 8  /opt/conda/envs/gdf/lib/libuct.so.0(+0x240fc) [0x7fbb05d6c0fc]
 9  /opt/conda/envs/gdf/lib/libucs.so.0(ucs_event_set_wait+0xf9) [0x7fbb05dc1639]
10  /opt/conda/envs/gdf/lib/libuct.so.0(uct_tcp_iface_progress+0x7b) [0x7fbb05d6c1ab]
11  /opt/conda/envs/gdf/lib/libucp.so.0(ucp_worker_progress+0x6a) [0x7fbb05e34f1a]
12  /opt/conda/envs/gdf/lib/python3.9/site-packages/ucp/_libs/ucx_api.cpython-39-x86_64-linux-gnu.so(+0x286e1) [0x7fbb05ee46e1]
13  /opt/conda/envs/gdf/bin/python(+0x13eb08) [0x559f8f228b08]
14  /opt/conda/envs/gdf/bin/python(_PyEval_EvalFrameDefault+0x5f82) [0x559f8f219112]
15  /opt/conda/envs/gdf/bin/python(+0x12827a) [0x559f8f21227a]
16  /opt/conda/envs/gdf/bin/python(_PyFunction_Vectorcall+0xd5) [0x559f8f223c05]
17  /opt/conda/envs/gdf/bin/python(_PyEval_EvalFrameDefault+0x68b) [0x559f8f21381b]
18  /opt/conda/envs/gdf/bin/python(+0x139ef3) [0x559f8f223ef3]
19  /opt/conda/envs/gdf/bin/python(+0x147a16) [0x559f8f231a16]
20  /opt/conda/envs/gdf/bin/python(+0x2579b1) [0x559f8f3419b1]
21  /opt/conda/envs/gdf/bin/python(+0xe5817) [0x559f8f1cf817]
22  /opt/conda/envs/gdf/bin/python(+0x130f83) [0x559f8f21af83]
23  /opt/conda/envs/gdf/bin/python(_PyEval_EvalFrameDefault+0x5ba6) [0x559f8f218d36]
24  /opt/conda/envs/gdf/bin/python(+0x139ef3) [0x559f8f223ef3]
25  /opt/conda/envs/gdf/bin/python(_PyEval_EvalFrameDefault+0x68b) [0x559f8f21381b]
26  /opt/conda/envs/gdf/bin/python(+0x139ef3) [0x559f8f223ef3]
27  /opt/conda/envs/gdf/bin/python(_PyEval_EvalFrameDefault+0x68b) [0x559f8f21381b]
28  /opt/conda/envs/gdf/bin/python(+0x139ef3) [0x559f8f223ef3]
29  /opt/conda/envs/gdf/bin/python(_PyEval_EvalFrameDefault+0x68b) [0x559f8f21381b]
30  /opt/conda/envs/gdf/bin/python(+0x139ef3) [0x559f8f223ef3]
31  /opt/conda/envs/gdf/bin/python(_PyEval_EvalFrameDefault+0x68b) [0x559f8f21381b]
32  /opt/conda/envs/gdf/bin/python(+0x12827a) [0x559f8f21227a]
33  /opt/conda/envs/gdf/bin/python(_PyFunction_Vectorcall+0xd5) [0x559f8f223c05]
34  /opt/conda/envs/gdf/bin/python(_PyEval_EvalFrameDefault+0x4e17) [0x559f8f217fa7]
35  /opt/conda/envs/gdf/bin/python(+0x12827a) [0x559f8f21227a]
36  /opt/conda/envs/gdf/bin/python(+0x147935) [0x559f8f231935]
37  /opt/conda/envs/gdf/bin/python(PyObject_Call+0xb4) [0x559f8f232104]
38  /opt/conda/envs/gdf/bin/python(+0x20efc8) [0x559f8f2f8fc8]
39  /opt/conda/envs/gdf/bin/python(_PyObject_MakeTpCall+0x2fc) [0x559f8f21c2bc]
40  /opt/conda/envs/gdf/bin/python(_PyEval_EvalFrameDefault+0x402b) [0x559f8f2171bb]
41  /opt/conda/envs/gdf/bin/python(+0x139ef3) [0x559f8f223ef3]
42  /opt/conda/envs/gdf/bin/python(+0x147c72) [0x559f8f231c72]
43  /opt/conda/envs/gdf/bin/python(_PyEval_EvalFrameDefault+0x402b) [0x559f8f2171bb]
44  /opt/conda/envs/gdf/bin/python(+0x139ef3) [0x559f8f223ef3]
45  /opt/conda/envs/gdf/bin/python(_PyEval_EvalFrameDefault+0x68b) [0x559f8f21381b]
46  /opt/conda/envs/gdf/bin/python(+0x12827a) [0x559f8f21227a]
47  /opt/conda/envs/gdf/bin/python(_PyFunction_Vectorcall+0xd5) [0x559f8f223c05]
48  /opt/conda/envs/gdf/bin/python(_PyEval_EvalFrameDefault+0x68b) [0x559f8f21381b]
49  /opt/conda/envs/gdf/bin/python(+0x139ef3) [0x559f8f223ef3]
50  /opt/conda/envs/gdf/bin/python(_PyEval_EvalFrameDefault+0x3d8) [0x559f8f213568]
51  /opt/conda/envs/gdf/bin/python(+0x12827a) [0x559f8f21227a]
52  /opt/conda/envs/gdf/bin/python(_PyFunction_Vectorcall+0xd5) [0x559f8f223c05]
53  /opt/conda/envs/gdf/bin/python(_PyEval_EvalFrameDefault+0x123b) [0x559f8f2143cb]
54  /opt/conda/envs/gdf/bin/python(+0x12827a) [0x559f8f21227a]
55  /opt/conda/envs/gdf/bin/python(_PyEval_EvalCodeWithName+0x47) [0x559f8f211f07]
56  /opt/conda/envs/gdf/bin/python(PyEval_EvalCodeEx+0x39) [0x559f8f211eb9]
57  /opt/conda/envs/gdf/bin/python(PyEval_EvalCode+0x1b) [0x559f8f2c28bb]
58  /opt/conda/envs/gdf/bin/python(+0x206adc) [0x559f8f2f0adc]
59  /opt/conda/envs/gdf/bin/python(+0x202c24) [0x559f8f2ecc24]
60  /opt/conda/envs/gdf/bin/python(PyRun_StringFlags+0x9d) [0x559f8f2e47ed]
61  /opt/conda/envs/gdf/bin/python(PyRun_SimpleStringFlags+0x3d) [0x559f8f2e46bd]
=================================
[dgx13:68384:0:68384] Caught signal 11 (Segmentation fault: address not mapped to object at address 0x448)
==== backtrace (tid:  68384) ====
 0  /opt/conda/envs/gdf/lib/libucs.so.0(ucs_handle_error+0x2dc) [0x7f82756cd11c]
 1  /opt/conda/envs/gdf/lib/libucs.so.0(+0x302ff) [0x7f82756cd2ff]
 2  /opt/conda/envs/gdf/lib/libucs.so.0(+0x30634) [0x7f82756cd634]
 3  /usr/lib/x86_64-linux-gnu/libpthread.so.0(+0x14420) [0x7f831a0c4420]
 4  /opt/conda/envs/gdf/lib/libucp.so.0(ucp_mem_type_unpack+0x1b) [0x7f827574e28b]
 5  /opt/conda/envs/gdf/lib/libucp.so.0(ucp_rndv_data_handler+0x508) [0x7f82757780b8]
 6  /opt/conda/envs/gdf/lib/libuct.so.0(+0x216a7) [0x7f827567f6a7]
 7  /opt/conda/envs/gdf/lib/libuct.so.0(+0x21c28) [0x7f827567fc28]
 8  /opt/conda/envs/gdf/lib/libuct.so.0(+0x240fc) [0x7f82756820fc]
 9  /opt/conda/envs/gdf/lib/libucs.so.0(ucs_event_set_wait+0xf9) [0x7f82756d7639]
10  /opt/conda/envs/gdf/lib/libuct.so.0(uct_tcp_iface_progress+0x7b) [0x7f82756821ab]
11  /opt/conda/envs/gdf/lib/libucp.so.0(ucp_worker_progress+0x6a) [0x7f827574af1a]
12  /opt/conda/envs/gdf/lib/python3.9/site-packages/ucp/_libs/ucx_api.cpython-39-x86_64-linux-gnu.so(+0x286e1) [0x7f82757fa6e1]
13  /opt/conda/envs/gdf/bin/python(+0x13eb08) [0x55af14831b08]
14  /opt/conda/envs/gdf/bin/python(_PyEval_EvalFrameDefault+0x5f82) [0x55af14822112]
15  /opt/conda/envs/gdf/bin/python(+0x12827a) [0x55af1481b27a]
16  /opt/conda/envs/gdf/bin/python(_PyFunction_Vectorcall+0xd5) [0x55af1482cc05]
17  /opt/conda/envs/gdf/bin/python(_PyEval_EvalFrameDefault+0x68b) [0x55af1481c81b]
18  /opt/conda/envs/gdf/bin/python(+0x14e70e) [0x55af1484170e]
19  /opt/conda/envs/gdf/lib/python3.9/lib-dynload/_asyncio.cpython-39-x86_64-linux-gnu.so(+0x82fe) [0x7f8299ade2fe]
20  /opt/conda/envs/gdf/bin/python(_PyObject_MakeTpCall+0x2fc) [0x55af148252bc]
21  /opt/conda/envs/gdf/bin/python(+0xe5817) [0x55af147d8817]
22  /opt/conda/envs/gdf/bin/python(+0x130f83) [0x55af14823f83]
23  /opt/conda/envs/gdf/bin/python(_PyEval_EvalFrameDefault+0x5ba6) [0x55af14821d36]
24  /opt/conda/envs/gdf/bin/python(+0x139ef3) [0x55af1482cef3]
25  /opt/conda/envs/gdf/bin/python(_PyEval_EvalFrameDefault+0x68b) [0x55af1481c81b]
26  /opt/conda/envs/gdf/bin/python(+0x139ef3) [0x55af1482cef3]
27  /opt/conda/envs/gdf/bin/python(_PyEval_EvalFrameDefault+0x68b) [0x55af1481c81b]
28  /opt/conda/envs/gdf/bin/python(+0x139ef3) [0x55af1482cef3]
29  /opt/conda/envs/gdf/bin/python(_PyEval_EvalFrameDefault+0x68b) [0x55af1481c81b]
30  /opt/conda/envs/gdf/bin/python(+0x139ef3) [0x55af1482cef3]
31  /opt/conda/envs/gdf/bin/python(_PyEval_EvalFrameDefault+0x68b) [0x55af1481c81b]
32  /opt/conda/envs/gdf/bin/python(+0x12827a) [0x55af1481b27a]
33  /opt/conda/envs/gdf/bin/python(_PyFunction_Vectorcall+0xd5) [0x55af1482cc05]
34  /opt/conda/envs/gdf/bin/python(_PyEval_EvalFrameDefault+0x4e17) [0x55af14820fa7]
35  /opt/conda/envs/gdf/bin/python(+0x12827a) [0x55af1481b27a]
36  /opt/conda/envs/gdf/bin/python(+0x147935) [0x55af1483a935]
37  /opt/conda/envs/gdf/bin/python(PyObject_Call+0xb4) [0x55af1483b104]
38  /opt/conda/envs/gdf/bin/python(+0x20efc8) [0x55af14901fc8]
39  /opt/conda/envs/gdf/bin/python(_PyObject_MakeTpCall+0x2fc) [0x55af148252bc]
40  /opt/conda/envs/gdf/bin/python(_PyEval_EvalFrameDefault+0x402b) [0x55af148201bb]
41  /opt/conda/envs/gdf/bin/python(+0x139ef3) [0x55af1482cef3]
42  /opt/conda/envs/gdf/bin/python(+0x147c72) [0x55af1483ac72]
43  /opt/conda/envs/gdf/bin/python(_PyEval_EvalFrameDefault+0x402b) [0x55af148201bb]
44  /opt/conda/envs/gdf/bin/python(+0x139ef3) [0x55af1482cef3]
45  /opt/conda/envs/gdf/bin/python(_PyEval_EvalFrameDefault+0x68b) [0x55af1481c81b]
46  /opt/conda/envs/gdf/bin/python(+0x12827a) [0x55af1481b27a]
47  /opt/conda/envs/gdf/bin/python(_PyFunction_Vectorcall+0xd5) [0x55af1482cc05]
48  /opt/conda/envs/gdf/bin/python(_PyEval_EvalFrameDefault+0x68b) [0x55af1481c81b]
49  /opt/conda/envs/gdf/bin/python(+0x139ef3) [0x55af1482cef3]
50  /opt/conda/envs/gdf/bin/python(_PyEval_EvalFrameDefault+0x3d8) [0x55af1481c568]
51  /opt/conda/envs/gdf/bin/python(+0x12827a) [0x55af1481b27a]
52  /opt/conda/envs/gdf/bin/python(_PyFunction_Vectorcall+0xd5) [0x55af1482cc05]
53  /opt/conda/envs/gdf/bin/python(_PyEval_EvalFrameDefault+0x123b) [0x55af1481d3cb]
54  /opt/conda/envs/gdf/bin/python(+0x12827a) [0x55af1481b27a]
55  /opt/conda/envs/gdf/bin/python(_PyEval_EvalCodeWithName+0x47) [0x55af1481af07]
56  /opt/conda/envs/gdf/bin/python(PyEval_EvalCodeEx+0x39) [0x55af1481aeb9]
57  /opt/conda/envs/gdf/bin/python(PyEval_EvalCode+0x1b) [0x55af148cb8bb]
58  /opt/conda/envs/gdf/bin/python(+0x206adc) [0x55af148f9adc]
59  /opt/conda/envs/gdf/bin/python(+0x202c24) [0x55af148f5c24]
60  /opt/conda/envs/gdf/bin/python(PyRun_StringFlags+0x9d) [0x55af148ed7ed]
61  /opt/conda/envs/gdf/bin/python(PyRun_SimpleStringFlags+0x3d) [0x55af148ed6bd]
=================================
[dgx13:68392:0:68392] Caught signal 11 (Segmentation fault: address not mapped to object at address 0x448)
==== backtrace (tid:  68392) ====
 0  /opt/conda/envs/gdf/lib/libucs.so.0(ucs_handle_error+0x2dc) [0x7f798404511c]
 1  /opt/conda/envs/gdf/lib/libucs.so.0(+0x302ff) [0x7f79840452ff]
 2  /opt/conda/envs/gdf/lib/libucs.so.0(+0x30634) [0x7f7984045634]
 3  /usr/lib/x86_64-linux-gnu/libpthread.so.0(+0x14420) [0x7f7a24534420]
 4  /opt/conda/envs/gdf/lib/libucp.so.0(ucp_mem_type_unpack+0x1b) [0x7f7981b5f28b]
 5  /opt/conda/envs/gdf/lib/libucp.so.0(ucp_rndv_data_handler+0x508) [0x7f7981b890b8]
 6  /opt/conda/envs/gdf/lib/libuct.so.0(+0x216a7) [0x7f7981af56a7]
 7  /opt/conda/envs/gdf/lib/libuct.so.0(+0x21c28) [0x7f7981af5c28]
 8  /opt/conda/envs/gdf/lib/libuct.so.0(+0x240fc) [0x7f7981af80fc]
 9  /opt/conda/envs/gdf/lib/libucs.so.0(ucs_event_set_wait+0xf9) [0x7f798404f639]
10  /opt/conda/envs/gdf/lib/libuct.so.0(uct_tcp_iface_progress+0x7b) [0x7f7981af81ab]
11  /opt/conda/envs/gdf/lib/libucp.so.0(ucp_worker_progress+0x6a) [0x7f7981b5bf1a]
12  /opt/conda/envs/gdf/lib/python3.9/site-packages/ucp/_libs/ucx_api.cpython-39-x86_64-linux-gnu.so(+0x286e1) [0x7f7981c0b6e1]
13  /opt/conda/envs/gdf/bin/python(+0x13eb08) [0x556d7fdeeb08]
14  /opt/conda/envs/gdf/bin/python(_PyEval_EvalFrameDefault+0x5f82) [0x556d7fddf112]
15  /opt/conda/envs/gdf/bin/python(+0x12827a) [0x556d7fdd827a]
16  /opt/conda/envs/gdf/bin/python(_PyFunction_Vectorcall+0xd5) [0x556d7fde9c05]
17  /opt/conda/envs/gdf/bin/python(_PyEval_EvalFrameDefault+0x68b) [0x556d7fdd981b]
18  /opt/conda/envs/gdf/bin/python(+0x14e70e) [0x556d7fdfe70e]
19  /opt/conda/envs/gdf/lib/python3.9/lib-dynload/_asyncio.cpython-39-x86_64-linux-gnu.so(+0x82fe) [0x7f79a3f482fe]
20  /opt/conda/envs/gdf/bin/python(_PyObject_MakeTpCall+0x2fc) [0x556d7fde22bc]
21  /opt/conda/envs/gdf/bin/python(+0xe5817) [0x556d7fd95817]
22  /opt/conda/envs/gdf/bin/python(+0x130f83) [0x556d7fde0f83]
23  /opt/conda/envs/gdf/bin/python(_PyEval_EvalFrameDefault+0x5ba6) [0x556d7fdded36]
24  /opt/conda/envs/gdf/bin/python(+0x139ef3) [0x556d7fde9ef3]
25  /opt/conda/envs/gdf/bin/python(_PyEval_EvalFrameDefault+0x68b) [0x556d7fdd981b]
26  /opt/conda/envs/gdf/bin/python(+0x139ef3) [0x556d7fde9ef3]
27  /opt/conda/envs/gdf/bin/python(_PyEval_EvalFrameDefault+0x68b) [0x556d7fdd981b]
28  /opt/conda/envs/gdf/bin/python(+0x139ef3) [0x556d7fde9ef3]
29  /opt/conda/envs/gdf/bin/python(_PyEval_EvalFrameDefault+0x68b) [0x556d7fdd981b]
30  /opt/conda/envs/gdf/bin/python(+0x139ef3) [0x556d7fde9ef3]
31  /opt/conda/envs/gdf/bin/python(_PyEval_EvalFrameDefault+0x68b) [0x556d7fdd981b]
32  /opt/conda/envs/gdf/bin/python(+0x12827a) [0x556d7fdd827a]
33  /opt/conda/envs/gdf/bin/python(_PyFunction_Vectorcall+0xd5) [0x556d7fde9c05]
34  /opt/conda/envs/gdf/bin/python(_PyEval_EvalFrameDefault+0x4e17) [0x556d7fdddfa7]
35  /opt/conda/envs/gdf/bin/python(+0x12827a) [0x556d7fdd827a]
36  /opt/conda/envs/gdf/bin/python(+0x147935) [0x556d7fdf7935]
37  /opt/conda/envs/gdf/bin/python(PyObject_Call+0xb4) [0x556d7fdf8104]
38  /opt/conda/envs/gdf/bin/python(+0x20efc8) [0x556d7febefc8]
39  /opt/conda/envs/gdf/bin/python(_PyObject_MakeTpCall+0x2fc) [0x556d7fde22bc]
40  /opt/conda/envs/gdf/bin/python(_PyEval_EvalFrameDefault+0x402b) [0x556d7fddd1bb]
41  /opt/conda/envs/gdf/bin/python(+0x139ef3) [0x556d7fde9ef3]
42  /opt/conda/envs/gdf/bin/python(+0x147c72) [0x556d7fdf7c72]
43  /opt/conda/envs/gdf/bin/python(_PyEval_EvalFrameDefault+0x402b) [0x556d7fddd1bb]
44  /opt/conda/envs/gdf/bin/python(+0x139ef3) [0x556d7fde9ef3]
45  /opt/conda/envs/gdf/bin/python(_PyEval_EvalFrameDefault+0x68b) [0x556d7fdd981b]
46  /opt/conda/envs/gdf/bin/python(+0x12827a) [0x556d7fdd827a]
47  /opt/conda/envs/gdf/bin/python(_PyFunction_Vectorcall+0xd5) [0x556d7fde9c05]
48  /opt/conda/envs/gdf/bin/python(_PyEval_EvalFrameDefault+0x68b) [0x556d7fdd981b]
49  /opt/conda/envs/gdf/bin/python(+0x139ef3) [0x556d7fde9ef3]
50  /opt/conda/envs/gdf/bin/python(_PyEval_EvalFrameDefault+0x3d8) [0x556d7fdd9568]
51  /opt/conda/envs/gdf/bin/python(+0x12827a) [0x556d7fdd827a]
52  /opt/conda/envs/gdf/bin/python(_PyFunction_Vectorcall+0xd5) [0x556d7fde9c05]
53  /opt/conda/envs/gdf/bin/python(_PyEval_EvalFrameDefault+0x123b) [0x556d7fdda3cb]
54  /opt/conda/envs/gdf/bin/python(+0x12827a) [0x556d7fdd827a]
55  /opt/conda/envs/gdf/bin/python(_PyEval_EvalCodeWithName+0x47) [0x556d7fdd7f07]
56  /opt/conda/envs/gdf/bin/python(PyEval_EvalCodeEx+0x39) [0x556d7fdd7eb9]
57  /opt/conda/envs/gdf/bin/python(PyEval_EvalCode+0x1b) [0x556d7fe888bb]
58  /opt/conda/envs/gdf/bin/python(+0x206adc) [0x556d7feb6adc]
59  /opt/conda/envs/gdf/bin/python(+0x202c24) [0x556d7feb2c24]
60  /opt/conda/envs/gdf/bin/python(PyRun_StringFlags+0x9d) [0x556d7feaa7ed]
61  /opt/conda/envs/gdf/bin/python(PyRun_SimpleStringFlags+0x3d) [0x556d7feaa6bd]
=================================
2023-05-29 05:47:29,679 - distributed.worker - ERROR - Worker stream died during communication: ucx://127.0.0.1:49799
Traceback (most recent call last):
  File "/opt/conda/envs/gdf/lib/python3.9/site-packages/distributed/comm/ucx.py", line 391, in read
    await self.ep.recv(each_frame)
  File "/opt/conda/envs/gdf/lib/python3.9/site-packages/ucp/core.py", line 725, in recv
    ret = await comm.tag_recv(self._ep, buffer, nbytes, tag, name=log)
ucp._libs.exceptions.UCXCanceled: <[Recv #008] ep: 0x7f1b34c6c200, tag: 0xfebef333193152a5, nbytes: 100000000, type: <class 'rmm._lib.device_buffer.DeviceBuffer'>>: 

During handling of the above exception, another exception occurred:

Traceback (most recent call last):
  File "/opt/conda/envs/gdf/lib/python3.9/site-packages/distributed/worker.py", line 2066, in gather_dep
    response = await get_data_from_worker(
  File "/opt/conda/envs/gdf/lib/python3.9/site-packages/distributed/worker.py", line 2892, in get_data_from_worker
    response = await send_recv(
  File "/opt/conda/envs/gdf/lib/python3.9/site-packages/distributed/core.py", line 1024, in send_recv
    response = await comm.read(deserializers=deserializers)
  File "/opt/conda/envs/gdf/lib/python3.9/site-packages/distributed/utils.py", line 752, in wrapper
    return await func(*args, **kwargs)
  File "/opt/conda/envs/gdf/lib/python3.9/site-packages/distributed/comm/ucx.py", line 397, in read
    raise CommClosedError(
distributed.comm.core.CommClosedError: Connection closed by writer.
Inner exception: UCXCanceled("<[Recv #008] ep: 0x7f1b34c6c200, tag: 0xfebef333193152a5, nbytes: 100000000, type: <class 'rmm._lib.device_buffer.DeviceBuffer'>>: ")
2023-05-29 05:47:29,679 - distributed.worker - ERROR - Worker stream died during communication: ucx://127.0.0.1:49799
Traceback (most recent call last):
  File "/opt/conda/envs/gdf/lib/python3.9/site-packages/distributed/comm/ucx.py", line 349, in read
    await self.ep.recv(msg)
  File "/opt/conda/envs/gdf/lib/python3.9/site-packages/ucp/core.py", line 725, in recv
    ret = await comm.tag_recv(self._ep, buffer, nbytes, tag, name=log)
ucp._libs.exceptions.UCXCanceled: <[Recv #003] ep: 0x7fccf80c2240, tag: 0x846a2390047b4445, nbytes: 16, type: <class 'numpy.ndarray'>>: 

During handling of the above exception, another exception occurred:

Traceback (most recent call last):
  File "/opt/conda/envs/gdf/lib/python3.9/site-packages/distributed/worker.py", line 2066, in gather_dep
    response = await get_data_from_worker(
  File "/opt/conda/envs/gdf/lib/python3.9/site-packages/distributed/worker.py", line 2892, in get_data_from_worker
    response = await send_recv(
  File "/opt/conda/envs/gdf/lib/python3.9/site-packages/distributed/core.py", line 1024, in send_recv
    response = await comm.read(deserializers=deserializers)
  File "/opt/conda/envs/gdf/lib/python3.9/site-packages/distributed/utils.py", line 752, in wrapper
    return await func(*args, **kwargs)
  File "/opt/conda/envs/gdf/lib/python3.9/site-packages/distributed/comm/ucx.py", line 367, in read
    raise CommClosedError(
distributed.comm.core.CommClosedError: Connection closed by writer.
Inner exception: UCXCanceled("<[Recv #003] ep: 0x7fccf80c2240, tag: 0x846a2390047b4445, nbytes: 16, type: <class 'numpy.ndarray'>>: ")
Task exception was never retrieved
future: <Task finished name='Task-861' coro=<_listener_handler_coroutine() done, defined at /opt/conda/envs/gdf/lib/python3.9/site-packages/ucp/core.py:128> exception=UCXError('<stream_recv>: Endpoint timeout')>
Traceback (most recent call last):
  File "/opt/conda/envs/gdf/lib/python3.9/site-packages/ucp/core.py", line 143, in _listener_handler_coroutine
    peer_info = await exchange_peer_info(
  File "/opt/conda/envs/gdf/lib/python3.9/site-packages/ucp/core.py", line 52, in exchange_peer_info
    await comm.stream_recv(endpoint, peer_info_arr, peer_info_arr.nbytes)
ucp._libs.exceptions.UCXError: <stream_recv>: Endpoint timeout
2023-05-29 05:47:29,738 - distributed.nanny - WARNING - Restarting worker
2023-05-29 05:47:29,741 - distributed.worker - ERROR - Worker stream died during communication: ucx://127.0.0.1:46069
Traceback (most recent call last):
  File "/opt/conda/envs/gdf/lib/python3.9/site-packages/distributed/comm/ucx.py", line 349, in read
    await self.ep.recv(msg)
  File "/opt/conda/envs/gdf/lib/python3.9/site-packages/ucp/core.py", line 725, in recv
    ret = await comm.tag_recv(self._ep, buffer, nbytes, tag, name=log)
ucp._libs.exceptions.UCXCanceled: <[Recv #003] ep: 0x7fccf80c21c0, tag: 0x90b5c02e5cfa2c5a, nbytes: 16, type: <class 'numpy.ndarray'>>: 

During handling of the above exception, another exception occurred:

Traceback (most recent call last):
  File "/opt/conda/envs/gdf/lib/python3.9/site-packages/distributed/worker.py", line 2066, in gather_dep
    response = await get_data_from_worker(
  File "/opt/conda/envs/gdf/lib/python3.9/site-packages/distributed/worker.py", line 2892, in get_data_from_worker
    response = await send_recv(
  File "/opt/conda/envs/gdf/lib/python3.9/site-packages/distributed/core.py", line 1024, in send_recv
    response = await comm.read(deserializers=deserializers)
  File "/opt/conda/envs/gdf/lib/python3.9/site-packages/distributed/utils.py", line 752, in wrapper
    return await func(*args, **kwargs)
  File "/opt/conda/envs/gdf/lib/python3.9/site-packages/distributed/comm/ucx.py", line 367, in read
    raise CommClosedError(
distributed.comm.core.CommClosedError: Connection closed by writer.
Inner exception: UCXCanceled("<[Recv #003] ep: 0x7fccf80c21c0, tag: 0x90b5c02e5cfa2c5a, nbytes: 16, type: <class 'numpy.ndarray'>>: ")
2023-05-29 05:47:29,756 - distributed.worker - ERROR - Worker stream died during communication: ucx://127.0.0.1:44435
Traceback (most recent call last):
  File "/opt/conda/envs/gdf/lib/python3.9/site-packages/distributed/comm/ucx.py", line 391, in read
    await self.ep.recv(each_frame)
  File "/opt/conda/envs/gdf/lib/python3.9/site-packages/ucp/core.py", line 708, in recv
    self._ep.raise_on_error()
  File "ucp/_libs/ucx_endpoint.pyx", line 355, in ucp._libs.ucx_api.UCXEndpoint.raise_on_error
ucp._libs.exceptions.UCXError: Endpoint 0x7f3430579280 error: Endpoint timeout

During handling of the above exception, another exception occurred:

Traceback (most recent call last):
  File "/opt/conda/envs/gdf/lib/python3.9/site-packages/distributed/worker.py", line 2066, in gather_dep
    response = await get_data_from_worker(
  File "/opt/conda/envs/gdf/lib/python3.9/site-packages/distributed/worker.py", line 2892, in get_data_from_worker
    response = await send_recv(
  File "/opt/conda/envs/gdf/lib/python3.9/site-packages/distributed/core.py", line 1024, in send_recv
    response = await comm.read(deserializers=deserializers)
  File "/opt/conda/envs/gdf/lib/python3.9/site-packages/distributed/utils.py", line 752, in wrapper
    return await func(*args, **kwargs)
  File "/opt/conda/envs/gdf/lib/python3.9/site-packages/distributed/comm/ucx.py", line 397, in read
    raise CommClosedError(
distributed.comm.core.CommClosedError: Connection closed by writer.
Inner exception: UCXError('Endpoint 0x7f3430579280 error: Endpoint timeout')
2023-05-29 05:47:29,758 - distributed.worker - ERROR - failed during get data with ucx://127.0.0.1:47511 -> ucx://127.0.0.1:44435
Traceback (most recent call last):
  File "/opt/conda/envs/gdf/lib/python3.9/site-packages/distributed/worker.py", line 1792, in get_data
    compressed = await comm.write(msg, serializers=serializers)
  File "/opt/conda/envs/gdf/lib/python3.9/site-packages/distributed/utils.py", line 752, in wrapper
    return await func(*args, **kwargs)
  File "/opt/conda/envs/gdf/lib/python3.9/site-packages/distributed/comm/ucx.py", line 289, in write
    raise CommClosedError("Endpoint is closed -- unable to send message")
distributed.comm.core.CommClosedError: Endpoint is closed -- unable to send message
2023-05-29 05:47:29,750 - distributed.worker - ERROR - failed during get data with ucx://127.0.0.1:47671 -> ucx://127.0.0.1:46069
Traceback (most recent call last):
  File "/opt/conda/envs/gdf/lib/python3.9/site-packages/distributed/comm/ucx.py", line 333, in write
    await self.ep.send(each_frame)
  File "/opt/conda/envs/gdf/lib/python3.9/site-packages/ucp/core.py", line 650, in send
    return await comm.tag_send(self._ep, buffer, nbytes, tag, name=log)
ucp._libs.exceptions.UCXError: <[Send #007] ep: 0x7f1b34c6c340, tag: 0x268d5439ab64c394, nbytes: 100000000, type: <class 'cudf.core.buffer.buffer.Buffer'>>: Endpoint timeout

During handling of the above exception, another exception occurred:

Traceback (most recent call last):
  File "/opt/conda/envs/gdf/lib/python3.9/site-packages/distributed/worker.py", line 1792, in get_data
    compressed = await comm.write(msg, serializers=serializers)
  File "/opt/conda/envs/gdf/lib/python3.9/site-packages/distributed/utils.py", line 752, in wrapper
    return await func(*args, **kwargs)
  File "/opt/conda/envs/gdf/lib/python3.9/site-packages/distributed/comm/ucx.py", line 337, in write
    raise CommClosedError("While writing, the connection was closed")
distributed.comm.core.CommClosedError: While writing, the connection was closed
2023-05-29 05:47:29,765 - distributed.worker - ERROR - Worker stream died during communication: ucx://127.0.0.1:46069
Traceback (most recent call last):
  File "/opt/conda/envs/gdf/lib/python3.9/site-packages/distributed/comm/ucx.py", line 391, in read
    await self.ep.recv(each_frame)
  File "/opt/conda/envs/gdf/lib/python3.9/site-packages/ucp/core.py", line 708, in recv
    self._ep.raise_on_error()
  File "ucp/_libs/ucx_endpoint.pyx", line 355, in ucp._libs.ucx_api.UCXEndpoint.raise_on_error
ucp._libs.exceptions.UCXError: Endpoint 0x7f3430579200 error: Endpoint timeout

During handling of the above exception, another exception occurred:

Traceback (most recent call last):
  File "/opt/conda/envs/gdf/lib/python3.9/site-packages/distributed/worker.py", line 2066, in gather_dep
    response = await get_data_from_worker(
  File "/opt/conda/envs/gdf/lib/python3.9/site-packages/distributed/worker.py", line 2892, in get_data_from_worker
    response = await send_recv(
  File "/opt/conda/envs/gdf/lib/python3.9/site-packages/distributed/core.py", line 1024, in send_recv
    response = await comm.read(deserializers=deserializers)
  File "/opt/conda/envs/gdf/lib/python3.9/site-packages/distributed/utils.py", line 752, in wrapper
    return await func(*args, **kwargs)
  File "/opt/conda/envs/gdf/lib/python3.9/site-packages/distributed/comm/ucx.py", line 397, in read
    raise CommClosedError(
distributed.comm.core.CommClosedError: Connection closed by writer.
Inner exception: UCXError('Endpoint 0x7f3430579200 error: Endpoint timeout')
2023-05-29 05:47:29,765 - distributed.worker - ERROR - failed during get data with ucx://127.0.0.1:51175 -> ucx://127.0.0.1:46069
Traceback (most recent call last):
  File "/opt/conda/envs/gdf/lib/python3.9/site-packages/distributed/comm/ucx.py", line 315, in write
    await self.ep.send(struct.pack("?Q", False, nframes))
  File "/opt/conda/envs/gdf/lib/python3.9/site-packages/ucp/core.py", line 629, in send
    self._ep.raise_on_error()
  File "ucp/_libs/ucx_endpoint.pyx", line 355, in ucp._libs.ucx_api.UCXEndpoint.raise_on_error
ucp._libs.exceptions.UCXError: Endpoint 0x7f7fb13ce380 error: Endpoint timeout

During handling of the above exception, another exception occurred:

Traceback (most recent call last):
  File "/opt/conda/envs/gdf/lib/python3.9/site-packages/distributed/worker.py", line 1792, in get_data
    compressed = await comm.write(msg, serializers=serializers)
  File "/opt/conda/envs/gdf/lib/python3.9/site-packages/distributed/utils.py", line 752, in wrapper
    return await func(*args, **kwargs)
  File "/opt/conda/envs/gdf/lib/python3.9/site-packages/distributed/comm/ucx.py", line 337, in write
    raise CommClosedError("While writing, the connection was closed")
distributed.comm.core.CommClosedError: While writing, the connection was closed
2023-05-29 05:47:29,767 - distributed.worker - ERROR - Worker stream died during communication: ucx://127.0.0.1:49799
Traceback (most recent call last):
  File "/opt/conda/envs/gdf/lib/python3.9/site-packages/distributed/comm/ucx.py", line 391, in read
    await self.ep.recv(each_frame)
  File "/opt/conda/envs/gdf/lib/python3.9/site-packages/ucp/core.py", line 725, in recv
    ret = await comm.tag_recv(self._ep, buffer, nbytes, tag, name=log)
ucp._libs.exceptions.UCXCanceled: <[Recv #008] ep: 0x7f7fb13ce200, tag: 0x89a65d7b2b884928, nbytes: 100000000, type: <class 'rmm._lib.device_buffer.DeviceBuffer'>>: 

During handling of the above exception, another exception occurred:

Traceback (most recent call last):
  File "/opt/conda/envs/gdf/lib/python3.9/site-packages/distributed/worker.py", line 2066, in gather_dep
    response = await get_data_from_worker(
  File "/opt/conda/envs/gdf/lib/python3.9/site-packages/distributed/worker.py", line 2892, in get_data_from_worker
    response = await send_recv(
  File "/opt/conda/envs/gdf/lib/python3.9/site-packages/distributed/core.py", line 1024, in send_recv
    response = await comm.read(deserializers=deserializers)
  File "/opt/conda/envs/gdf/lib/python3.9/site-packages/distributed/utils.py", line 752, in wrapper
    return await func(*args, **kwargs)
  File "/opt/conda/envs/gdf/lib/python3.9/site-packages/distributed/comm/ucx.py", line 397, in read
    raise CommClosedError(
distributed.comm.core.CommClosedError: Connection closed by writer.
Inner exception: UCXCanceled("<[Recv #008] ep: 0x7f7fb13ce200, tag: 0x89a65d7b2b884928, nbytes: 100000000, type: <class 'rmm._lib.device_buffer.DeviceBuffer'>>: ")
2023-05-29 05:47:29,768 - distributed.worker - ERROR - Worker stream died during communication: ucx://127.0.0.1:49799
Traceback (most recent call last):
  File "/opt/conda/envs/gdf/lib/python3.9/site-packages/distributed/worker.py", line 2066, in gather_dep
    response = await get_data_from_worker(
  File "/opt/conda/envs/gdf/lib/python3.9/site-packages/distributed/worker.py", line 2907, in get_data_from_worker
    await comm.write("OK")
  File "/opt/conda/envs/gdf/lib/python3.9/site-packages/distributed/utils.py", line 752, in wrapper
    return await func(*args, **kwargs)
  File "/opt/conda/envs/gdf/lib/python3.9/site-packages/distributed/comm/ucx.py", line 289, in write
    raise CommClosedError("Endpoint is closed -- unable to send message")
distributed.comm.core.CommClosedError: Endpoint is closed -- unable to send message
2023-05-29 05:47:29,770 - distributed.worker - ERROR - failed during get data with ucx://127.0.0.1:47511 -> ucx://127.0.0.1:46069
Traceback (most recent call last):
  File "/opt/conda/envs/gdf/lib/python3.9/site-packages/distributed/worker.py", line 1792, in get_data
    compressed = await comm.write(msg, serializers=serializers)
  File "/opt/conda/envs/gdf/lib/python3.9/site-packages/distributed/utils.py", line 752, in wrapper
    return await func(*args, **kwargs)
  File "/opt/conda/envs/gdf/lib/python3.9/site-packages/distributed/comm/ucx.py", line 289, in write
    raise CommClosedError("Endpoint is closed -- unable to send message")
distributed.comm.core.CommClosedError: Endpoint is closed -- unable to send message
2023-05-29 05:47:29,771 - distributed.worker - ERROR - Worker stream died during communication: ucx://127.0.0.1:44435
Traceback (most recent call last):
  File "/opt/conda/envs/gdf/lib/python3.9/site-packages/distributed/worker.py", line 2066, in gather_dep
    response = await get_data_from_worker(
  File "/opt/conda/envs/gdf/lib/python3.9/site-packages/distributed/worker.py", line 2892, in get_data_from_worker
    response = await send_recv(
  File "/opt/conda/envs/gdf/lib/python3.9/site-packages/distributed/core.py", line 1022, in send_recv
    await comm.write(msg, serializers=serializers, on_error="raise")
  File "/opt/conda/envs/gdf/lib/python3.9/site-packages/distributed/utils.py", line 752, in wrapper
    return await func(*args, **kwargs)
  File "/opt/conda/envs/gdf/lib/python3.9/site-packages/distributed/comm/ucx.py", line 289, in write
    raise CommClosedError("Endpoint is closed -- unable to send message")
distributed.comm.core.CommClosedError: Endpoint is closed -- unable to send message
2023-05-29 05:47:29,771 - distributed.worker - ERROR - Worker stream died during communication: ucx://127.0.0.1:46069
Traceback (most recent call last):
  File "/opt/conda/envs/gdf/lib/python3.9/site-packages/distributed/worker.py", line 2066, in gather_dep
    response = await get_data_from_worker(
  File "/opt/conda/envs/gdf/lib/python3.9/site-packages/distributed/worker.py", line 2892, in get_data_from_worker
    response = await send_recv(
  File "/opt/conda/envs/gdf/lib/python3.9/site-packages/distributed/core.py", line 1022, in send_recv
    await comm.write(msg, serializers=serializers, on_error="raise")
  File "/opt/conda/envs/gdf/lib/python3.9/site-packages/distributed/utils.py", line 752, in wrapper
    return await func(*args, **kwargs)
  File "/opt/conda/envs/gdf/lib/python3.9/site-packages/distributed/comm/ucx.py", line 289, in write
    raise CommClosedError("Endpoint is closed -- unable to send message")
distributed.comm.core.CommClosedError: Endpoint is closed -- unable to send message
2023-05-29 05:47:29,774 - distributed.worker - ERROR - failed during get data with ucx://127.0.0.1:51175 -> ucx://127.0.0.1:44435
Traceback (most recent call last):
  File "/opt/conda/envs/gdf/lib/python3.9/site-packages/distributed/worker.py", line 1792, in get_data
    compressed = await comm.write(msg, serializers=serializers)
  File "/opt/conda/envs/gdf/lib/python3.9/site-packages/distributed/utils.py", line 752, in wrapper
    return await func(*args, **kwargs)
  File "/opt/conda/envs/gdf/lib/python3.9/site-packages/distributed/comm/ucx.py", line 289, in write
    raise CommClosedError("Endpoint is closed -- unable to send message")
distributed.comm.core.CommClosedError: Endpoint is closed -- unable to send message
2023-05-29 05:47:29,767 - distributed.worker - ERROR - Worker stream died during communication: ucx://127.0.0.1:46069
Traceback (most recent call last):
  File "/opt/conda/envs/gdf/lib/python3.9/site-packages/distributed/comm/ucx.py", line 349, in read
    await self.ep.recv(msg)
  File "/opt/conda/envs/gdf/lib/python3.9/site-packages/ucp/core.py", line 725, in recv
    ret = await comm.tag_recv(self._ep, buffer, nbytes, tag, name=log)
ucp._libs.exceptions.UCXCanceled: <[Recv #003] ep: 0x7f1b34c6c240, tag: 0xa8ab76e0b9291a85, nbytes: 16, type: <class 'numpy.ndarray'>>: 

During handling of the above exception, another exception occurred:

Traceback (most recent call last):
  File "/opt/conda/envs/gdf/lib/python3.9/site-packages/distributed/worker.py", line 2066, in gather_dep
    response = await get_data_from_worker(
  File "/opt/conda/envs/gdf/lib/python3.9/site-packages/distributed/worker.py", line 2892, in get_data_from_worker
    response = await send_recv(
  File "/opt/conda/envs/gdf/lib/python3.9/site-packages/distributed/core.py", line 1024, in send_recv
    response = await comm.read(deserializers=deserializers)
  File "/opt/conda/envs/gdf/lib/python3.9/site-packages/distributed/utils.py", line 752, in wrapper
    return await func(*args, **kwargs)
  File "/opt/conda/envs/gdf/lib/python3.9/site-packages/distributed/comm/ucx.py", line 367, in read
    raise CommClosedError(
distributed.comm.core.CommClosedError: Connection closed by writer.
Inner exception: UCXCanceled("<[Recv #003] ep: 0x7f1b34c6c240, tag: 0xa8ab76e0b9291a85, nbytes: 16, type: <class 'numpy.ndarray'>>: ")
[dgx13:68375:0:68375] Caught signal 11 (Segmentation fault: address not mapped to object at address 0x448)
==== backtrace (tid:  68375) ====
 0  /opt/conda/envs/gdf/lib/libucs.so.0(ucs_handle_error+0x2dc) [0x7f34308de11c]
 1  /opt/conda/envs/gdf/lib/libucs.so.0(+0x302ff) [0x7f34308de2ff]
 2  /opt/conda/envs/gdf/lib/libucs.so.0(+0x30634) [0x7f34308de634]
 3  /usr/lib/x86_64-linux-gnu/libpthread.so.0(+0x14420) [0x7f34c32b2420]
 4  /opt/conda/envs/gdf/lib/libucp.so.0(ucp_mem_type_unpack+0x1b) [0x7f343095f28b]
 5  /opt/conda/envs/gdf/lib/libucp.so.0(ucp_rndv_data_handler+0x508) [0x7f34309890b8]
 6  /opt/conda/envs/gdf/lib/libuct.so.0(+0x216a7) [0x7f34308906a7]
 7  /opt/conda/envs/gdf/lib/libuct.so.0(+0x21c28) [0x7f3430890c28]
 8  /opt/conda/envs/gdf/lib/libuct.so.0(+0x240fc) [0x7f34308930fc]
 9  /opt/conda/envs/gdf/lib/libucs.so.0(ucs_event_set_wait+0xf9) [0x7f34308e8639]
10  /opt/conda/envs/gdf/lib/libuct.so.0(uct_tcp_iface_progress+0x7b) [0x7f34308931ab]
11  /opt/conda/envs/gdf/lib/libucp.so.0(ucp_worker_progress+0x6a) [0x7f343095bf1a]
12  /opt/conda/envs/gdf/lib/python3.9/site-packages/ucp/_libs/ucx_api.cpython-39-x86_64-linux-gnu.so(+0x286e1) [0x7f3430a0b6e1]
13  /opt/conda/envs/gdf/bin/python(+0x13eb08) [0x55bbbb95db08]
14  /opt/conda/envs/gdf/bin/python(_PyEval_EvalFrameDefault+0x5f82) [0x55bbbb94e112]
15  /opt/conda/envs/gdf/bin/python(+0x12827a) [0x55bbbb94727a]
16  /opt/conda/envs/gdf/bin/python(_PyFunction_Vectorcall+0xd5) [0x55bbbb958c05]
17  /opt/conda/envs/gdf/bin/python(_PyEval_EvalFrameDefault+0x68b) [0x55bbbb94881b]
18  /opt/conda/envs/gdf/bin/python(+0x139ef3) [0x55bbbb958ef3]
19  /opt/conda/envs/gdf/bin/python(+0x147a16) [0x55bbbb966a16]
20  /opt/conda/envs/gdf/bin/python(+0x2579b1) [0x55bbbba769b1]
21  /opt/conda/envs/gdf/bin/python(+0xe5817) [0x55bbbb904817]
22  /opt/conda/envs/gdf/bin/python(+0x130f83) [0x55bbbb94ff83]
23  /opt/conda/envs/gdf/bin/python(_PyEval_EvalFrameDefault+0x5ba6) [0x55bbbb94dd36]
24  /opt/conda/envs/gdf/bin/python(+0x139ef3) [0x55bbbb958ef3]
25  /opt/conda/envs/gdf/bin/python(_PyEval_EvalFrameDefault+0x68b) [0x55bbbb94881b]
26  /opt/conda/envs/gdf/bin/python(+0x139ef3) [0x55bbbb958ef3]
27  /opt/conda/envs/gdf/bin/python(_PyEval_EvalFrameDefault+0x68b) [0x55bbbb94881b]
28  /opt/conda/envs/gdf/bin/python(+0x139ef3) [0x55bbbb958ef3]
29  /opt/conda/envs/gdf/bin/python(_PyEval_EvalFrameDefault+0x68b) [0x55bbbb94881b]
30  /opt/conda/envs/gdf/bin/python(+0x139ef3) [0x55bbbb958ef3]
31  /opt/conda/envs/gdf/bin/python(_PyEval_EvalFrameDefault+0x68b) [0x55bbbb94881b]
32  /opt/conda/envs/gdf/bin/python(+0x12827a) [0x55bbbb94727a]
33  /opt/conda/envs/gdf/bin/python(_PyFunction_Vectorcall+0xd5) [0x55bbbb958c05]
34  /opt/conda/envs/gdf/bin/python(_PyEval_EvalFrameDefault+0x4e17) [0x55bbbb94cfa7]
35  /opt/conda/envs/gdf/bin/python(+0x12827a) [0x55bbbb94727a]
36  /opt/conda/envs/gdf/bin/python(+0x147935) [0x55bbbb966935]
37  /opt/conda/envs/gdf/bin/python(PyObject_Call+0xb4) [0x55bbbb967104]
38  /opt/conda/envs/gdf/bin/python(+0x20efc8) [0x55bbbba2dfc8]
39  /opt/conda/envs/gdf/bin/python(_PyObject_MakeTpCall+0x2fc) [0x55bbbb9512bc]
40  /opt/conda/envs/gdf/bin/python(_PyEval_EvalFrameDefault+0x402b) [0x55bbbb94c1bb]
41  /opt/conda/envs/gdf/bin/python(+0x139ef3) [0x55bbbb958ef3]
42  /opt/conda/envs/gdf/bin/python(+0x147c72) [0x55bbbb966c72]
43  /opt/conda/envs/gdf/bin/python(_PyEval_EvalFrameDefault+0x402b) [0x55bbbb94c1bb]
44  /opt/conda/envs/gdf/bin/python(+0x139ef3) [0x55bbbb958ef3]
45  /opt/conda/envs/gdf/bin/python(_PyEval_EvalFrameDefault+0x68b) [0x55bbbb94881b]
46  /opt/conda/envs/gdf/bin/python(+0x12827a) [0x55bbbb94727a]
47  /opt/conda/envs/gdf/bin/python(_PyFunction_Vectorcall+0xd5) [0x55bbbb958c05]
48  /opt/conda/envs/gdf/bin/python(_PyEval_EvalFrameDefault+0x68b) [0x55bbbb94881b]
49  /opt/conda/envs/gdf/bin/python(+0x139ef3) [0x55bbbb958ef3]
50  /opt/conda/envs/gdf/bin/python(_PyEval_EvalFrameDefault+0x3d8) [0x55bbbb948568]
51  /opt/conda/envs/gdf/bin/python(+0x12827a) [0x55bbbb94727a]
52  /opt/conda/envs/gdf/bin/python(_PyFunction_Vectorcall+0xd5) [0x55bbbb958c05]
53  /opt/conda/envs/gdf/bin/python(_PyEval_EvalFrameDefault+0x123b) [0x55bbbb9493cb]
54  /opt/conda/envs/gdf/bin/python(+0x12827a) [0x55bbbb94727a]
55  /opt/conda/envs/gdf/bin/python(_PyEval_EvalCodeWithName+0x47) [0x55bbbb946f07]
56  /opt/conda/envs/gdf/bin/python(PyEval_EvalCodeEx+0x39) [0x55bbbb946eb9]
57  /opt/conda/envs/gdf/bin/python(PyEval_EvalCode+0x1b) [0x55bbbb9f78bb]
58  /opt/conda/envs/gdf/bin/python(+0x206adc) [0x55bbbba25adc]
59  /opt/conda/envs/gdf/bin/python(+0x202c24) [0x55bbbba21c24]
60  /opt/conda/envs/gdf/bin/python(PyRun_StringFlags+0x9d) [0x55bbbba197ed]
61  /opt/conda/envs/gdf/bin/python(PyRun_SimpleStringFlags+0x3d) [0x55bbbba196bd]
=================================
2023-05-29 05:47:29,843 - distributed.nanny - WARNING - Restarting worker
2023-05-29 05:47:29,871 - distributed.worker - ERROR - Worker stream died during communication: ucx://127.0.0.1:44435
Traceback (most recent call last):
  File "/opt/conda/envs/gdf/lib/python3.9/site-packages/distributed/comm/ucx.py", line 391, in read
    await self.ep.recv(each_frame)
  File "/opt/conda/envs/gdf/lib/python3.9/site-packages/ucp/core.py", line 725, in recv
    ret = await comm.tag_recv(self._ep, buffer, nbytes, tag, name=log)
ucp._libs.exceptions.UCXCanceled: <[Recv #009] ep: 0x7fccf80c2200, tag: 0xbe406fc6833a0db5, nbytes: 100000000, type: <class 'rmm._lib.device_buffer.DeviceBuffer'>>: 

During handling of the above exception, another exception occurred:

Traceback (most recent call last):
  File "/opt/conda/envs/gdf/lib/python3.9/site-packages/distributed/worker.py", line 2066, in gather_dep
    response = await get_data_from_worker(
  File "/opt/conda/envs/gdf/lib/python3.9/site-packages/distributed/worker.py", line 2892, in get_data_from_worker
    response = await send_recv(
  File "/opt/conda/envs/gdf/lib/python3.9/site-packages/distributed/core.py", line 1024, in send_recv
    response = await comm.read(deserializers=deserializers)
  File "/opt/conda/envs/gdf/lib/python3.9/site-packages/distributed/utils.py", line 752, in wrapper
    return await func(*args, **kwargs)
  File "/opt/conda/envs/gdf/lib/python3.9/site-packages/distributed/comm/ucx.py", line 397, in read
    raise CommClosedError(
distributed.comm.core.CommClosedError: Connection closed by writer.
Inner exception: UCXCanceled("<[Recv #009] ep: 0x7fccf80c2200, tag: 0xbe406fc6833a0db5, nbytes: 100000000, type: <class 'rmm._lib.device_buffer.DeviceBuffer'>>: ")
2023-05-29 05:47:29,919 - distributed.nanny - WARNING - Restarting worker
2023-05-29 05:47:29,921 - distributed.nanny - WARNING - Restarting worker
2023-05-29 05:47:30,111 - distributed.worker - ERROR - failed during get data with ucx://127.0.0.1:45995 -> ucx://127.0.0.1:47511
Traceback (most recent call last):
  File "/opt/conda/envs/gdf/lib/python3.9/site-packages/distributed/comm/ucx.py", line 333, in write
    await self.ep.send(each_frame)
  File "/opt/conda/envs/gdf/lib/python3.9/site-packages/ucp/core.py", line 650, in send
    return await comm.tag_send(self._ep, buffer, nbytes, tag, name=log)
ucp._libs.exceptions.UCXError: <[Send #007] ep: 0x7fccf80c2100, tag: 0x56ab1e59dc9e9d5, nbytes: 100000000, type: <class 'cudf.core.buffer.buffer.Buffer'>>: Endpoint timeout

During handling of the above exception, another exception occurred:

Traceback (most recent call last):
  File "/opt/conda/envs/gdf/lib/python3.9/site-packages/distributed/worker.py", line 1792, in get_data
    compressed = await comm.write(msg, serializers=serializers)
  File "/opt/conda/envs/gdf/lib/python3.9/site-packages/distributed/utils.py", line 752, in wrapper
    return await func(*args, **kwargs)
  File "/opt/conda/envs/gdf/lib/python3.9/site-packages/distributed/comm/ucx.py", line 337, in write
    raise CommClosedError("While writing, the connection was closed")
distributed.comm.core.CommClosedError: While writing, the connection was closed
2023-05-29 05:47:30,112 - distributed.worker - ERROR - Worker stream died during communication: ucx://127.0.0.1:47511
Traceback (most recent call last):
  File "/opt/conda/envs/gdf/lib/python3.9/site-packages/distributed/comm/ucx.py", line 391, in read
    await self.ep.recv(each_frame)
  File "/opt/conda/envs/gdf/lib/python3.9/site-packages/ucp/core.py", line 725, in recv
    ret = await comm.tag_recv(self._ep, buffer, nbytes, tag, name=log)
ucp._libs.exceptions.UCXError: <[Recv #007] ep: 0x7fccf80c2140, tag: 0x4253af3cbfb29a7d, nbytes: 100000000, type: <class 'rmm._lib.device_buffer.DeviceBuffer'>>: Endpoint timeout

During handling of the above exception, another exception occurred:

Traceback (most recent call last):
  File "/opt/conda/envs/gdf/lib/python3.9/site-packages/distributed/worker.py", line 2066, in gather_dep
    response = await get_data_from_worker(
  File "/opt/conda/envs/gdf/lib/python3.9/site-packages/distributed/worker.py", line 2892, in get_data_from_worker
    response = await send_recv(
  File "/opt/conda/envs/gdf/lib/python3.9/site-packages/distributed/core.py", line 1024, in send_recv
    response = await comm.read(deserializers=deserializers)
  File "/opt/conda/envs/gdf/lib/python3.9/site-packages/distributed/utils.py", line 752, in wrapper
    return await func(*args, **kwargs)
  File "/opt/conda/envs/gdf/lib/python3.9/site-packages/distributed/comm/ucx.py", line 397, in read
    raise CommClosedError(
distributed.comm.core.CommClosedError: Connection closed by writer.
Inner exception: UCXError("<[Recv #007] ep: 0x7fccf80c2140, tag: 0x4253af3cbfb29a7d, nbytes: 100000000, type: <class 'rmm._lib.device_buffer.DeviceBuffer'>>: Endpoint timeout")
2023-05-29 05:47:30,162 - distributed.nanny - WARNING - Restarting worker
2023-05-29 05:47:30,170 - distributed.worker - ERROR - failed during get data with ucx://127.0.0.1:47671 -> ucx://127.0.0.1:47511
Traceback (most recent call last):
  File "/opt/conda/envs/gdf/lib/python3.9/site-packages/distributed/comm/ucx.py", line 333, in write
    await self.ep.send(each_frame)
  File "/opt/conda/envs/gdf/lib/python3.9/site-packages/ucp/core.py", line 650, in send
    return await comm.tag_send(self._ep, buffer, nbytes, tag, name=log)
ucp._libs.exceptions.UCXError: <[Send #007] ep: 0x7f1b34c6c2c0, tag: 0x7ffe9ca91d32b2e4, nbytes: 100000000, type: <class 'cudf.core.buffer.buffer.Buffer'>>: Endpoint timeout

During handling of the above exception, another exception occurred:

Traceback (most recent call last):
  File "/opt/conda/envs/gdf/lib/python3.9/site-packages/distributed/worker.py", line 1792, in get_data
    compressed = await comm.write(msg, serializers=serializers)
  File "/opt/conda/envs/gdf/lib/python3.9/site-packages/distributed/utils.py", line 752, in wrapper
    return await func(*args, **kwargs)
  File "/opt/conda/envs/gdf/lib/python3.9/site-packages/distributed/comm/ucx.py", line 337, in write
    raise CommClosedError("While writing, the connection was closed")
distributed.comm.core.CommClosedError: While writing, the connection was closed
2023-05-29 05:47:30,213 - distributed.worker - ERROR - Worker stream died during communication: ucx://127.0.0.1:47511
Traceback (most recent call last):
  File "/opt/conda/envs/gdf/lib/python3.9/site-packages/distributed/comm/ucx.py", line 391, in read
    await self.ep.recv(each_frame)
  File "/opt/conda/envs/gdf/lib/python3.9/site-packages/ucp/core.py", line 725, in recv
    ret = await comm.tag_recv(self._ep, buffer, nbytes, tag, name=log)
ucp._libs.exceptions.UCXError: <[Recv #007] ep: 0x7f1b34c6c100, tag: 0xb1e784b5137e202b, nbytes: 100000000, type: <class 'rmm._lib.device_buffer.DeviceBuffer'>>: Endpoint timeout

During handling of the above exception, another exception occurred:

Traceback (most recent call last):
  File "/opt/conda/envs/gdf/lib/python3.9/site-packages/distributed/worker.py", line 2066, in gather_dep
    response = await get_data_from_worker(
  File "/opt/conda/envs/gdf/lib/python3.9/site-packages/distributed/worker.py", line 2892, in get_data_from_worker
    response = await send_recv(
  File "/opt/conda/envs/gdf/lib/python3.9/site-packages/distributed/core.py", line 1024, in send_recv
    response = await comm.read(deserializers=deserializers)
  File "/opt/conda/envs/gdf/lib/python3.9/site-packages/distributed/utils.py", line 752, in wrapper
    return await func(*args, **kwargs)
  File "/opt/conda/envs/gdf/lib/python3.9/site-packages/distributed/comm/ucx.py", line 397, in read
    raise CommClosedError(
distributed.comm.core.CommClosedError: Connection closed by writer.
Inner exception: UCXError("<[Recv #007] ep: 0x7f1b34c6c100, tag: 0xb1e784b5137e202b, nbytes: 100000000, type: <class 'rmm._lib.device_buffer.DeviceBuffer'>>: Endpoint timeout")
2023-05-29 05:47:31,385 - distributed.preloading - INFO - Creating preload: dask_cuda.initialize
2023-05-29 05:47:31,386 - distributed.preloading - INFO - Import preload module: dask_cuda.initialize
2023-05-29 05:47:31,463 - distributed.preloading - INFO - Creating preload: dask_cuda.initialize
2023-05-29 05:47:31,463 - distributed.preloading - INFO - Import preload module: dask_cuda.initialize
2023-05-29 05:47:31,568 - distributed.preloading - INFO - Creating preload: dask_cuda.initialize
2023-05-29 05:47:31,568 - distributed.preloading - INFO - Import preload module: dask_cuda.initialize
2023-05-29 05:47:31,600 - distributed.preloading - INFO - Creating preload: dask_cuda.initialize
2023-05-29 05:47:31,601 - distributed.preloading - INFO - Import preload module: dask_cuda.initialize
2023-05-29 05:47:31,787 - distributed.preloading - INFO - Creating preload: dask_cuda.initialize
2023-05-29 05:47:31,787 - distributed.preloading - INFO - Import preload module: dask_cuda.initialize
[dgx13:68903:0:68903] Caught signal 11 (Segmentation fault: address not mapped to object at address 0x448)
==== backtrace (tid:  68903) ====
 0  /opt/conda/envs/gdf/lib/libucs.so.0(ucs_handle_error+0x2dc) [0x7fd8a772811c]
 1  /opt/conda/envs/gdf/lib/libucs.so.0(+0x302ff) [0x7fd8a77282ff]
 2  /opt/conda/envs/gdf/lib/libucs.so.0(+0x30634) [0x7fd8a7728634]
 3  /usr/lib/x86_64-linux-gnu/libpthread.so.0(+0x14420) [0x7fd95fff8420]
 4  /opt/conda/envs/gdf/lib/libucp.so.0(ucp_mem_type_unpack+0x1b) [0x7fd8a77a928b]
 5  /opt/conda/envs/gdf/lib/libucp.so.0(ucp_rndv_data_handler+0x508) [0x7fd8a77d30b8]
 6  /opt/conda/envs/gdf/lib/libuct.so.0(+0x216a7) [0x7fd8a76da6a7]
 7  /opt/conda/envs/gdf/lib/libuct.so.0(+0x21c28) [0x7fd8a76dac28]
 8  /opt/conda/envs/gdf/lib/libuct.so.0(+0x240fc) [0x7fd8a76dd0fc]
 9  /opt/conda/envs/gdf/lib/libucs.so.0(ucs_event_set_wait+0xf9) [0x7fd8a7732639]
10  /opt/conda/envs/gdf/lib/libuct.so.0(uct_tcp_iface_progress+0x7b) [0x7fd8a76dd1ab]
11  /opt/conda/envs/gdf/lib/libucp.so.0(ucp_worker_progress+0x6a) [0x7fd8a77a5f1a]
12  /opt/conda/envs/gdf/lib/python3.9/site-packages/ucp/_libs/ucx_api.cpython-39-x86_64-linux-gnu.so(+0x286e1) [0x7fd8a78556e1]
13  /opt/conda/envs/gdf/bin/python(+0x13eb08) [0x56062c3fab08]
14  /opt/conda/envs/gdf/bin/python(_PyEval_EvalFrameDefault+0x5f82) [0x56062c3eb112]
15  /opt/conda/envs/gdf/bin/python(+0x12827a) [0x56062c3e427a]
16  /opt/conda/envs/gdf/bin/python(_PyFunction_Vectorcall+0xd5) [0x56062c3f5c05]
17  /opt/conda/envs/gdf/bin/python(_PyEval_EvalFrameDefault+0x68b) [0x56062c3e581b]
18  /opt/conda/envs/gdf/bin/python(+0x139ef3) [0x56062c3f5ef3]
19  /opt/conda/envs/gdf/bin/python(+0x147a16) [0x56062c403a16]
20  /opt/conda/envs/gdf/bin/python(+0x2579b1) [0x56062c5139b1]
21  /opt/conda/envs/gdf/bin/python(+0xe5817) [0x56062c3a1817]
22  /opt/conda/envs/gdf/bin/python(+0x130f83) [0x56062c3ecf83]
23  /opt/conda/envs/gdf/bin/python(_PyEval_EvalFrameDefault+0x5ba6) [0x56062c3ead36]
24  /opt/conda/envs/gdf/bin/python(+0x139ef3) [0x56062c3f5ef3]
25  /opt/conda/envs/gdf/bin/python(_PyEval_EvalFrameDefault+0x68b) [0x56062c3e581b]
26  /opt/conda/envs/gdf/bin/python(+0x139ef3) [0x56062c3f5ef3]
27  /opt/conda/envs/gdf/bin/python(_PyEval_EvalFrameDefault+0x68b) [0x56062c3e581b]
28  /opt/conda/envs/gdf/bin/python(+0x139ef3) [0x56062c3f5ef3]
29  /opt/conda/envs/gdf/bin/python(_PyEval_EvalFrameDefault+0x68b) [0x56062c3e581b]
30  /opt/conda/envs/gdf/bin/python(+0x139ef3) [0x56062c3f5ef3]
31  /opt/conda/envs/gdf/bin/python(_PyEval_EvalFrameDefault+0x68b) [0x56062c3e581b]
32  /opt/conda/envs/gdf/bin/python(+0x12827a) [0x56062c3e427a]
33  /opt/conda/envs/gdf/bin/python(_PyFunction_Vectorcall+0xd5) [0x56062c3f5c05]
34  /opt/conda/envs/gdf/bin/python(_PyEval_EvalFrameDefault+0x4e17) [0x56062c3e9fa7]
35  /opt/conda/envs/gdf/bin/python(+0x12827a) [0x56062c3e427a]
36  /opt/conda/envs/gdf/bin/python(+0x147935) [0x56062c403935]
37  /opt/conda/envs/gdf/bin/python(PyObject_Call+0xb4) [0x56062c404104]
38  /opt/conda/envs/gdf/bin/python(+0x20efc8) [0x56062c4cafc8]
39  /opt/conda/envs/gdf/bin/python(_PyObject_MakeTpCall+0x2fc) [0x56062c3ee2bc]
40  /opt/conda/envs/gdf/bin/python(_PyEval_EvalFrameDefault+0x402b) [0x56062c3e91bb]
41  /opt/conda/envs/gdf/bin/python(+0x139ef3) [0x56062c3f5ef3]
42  /opt/conda/envs/gdf/bin/python(+0x147c72) [0x56062c403c72]
43  /opt/conda/envs/gdf/bin/python(_PyEval_EvalFrameDefault+0x402b) [0x56062c3e91bb]
44  /opt/conda/envs/gdf/bin/python(+0x139ef3) [0x56062c3f5ef3]
45  /opt/conda/envs/gdf/bin/python(_PyEval_EvalFrameDefault+0x68b) [0x56062c3e581b]
46  /opt/conda/envs/gdf/bin/python(+0x12827a) [0x56062c3e427a]
47  /opt/conda/envs/gdf/bin/python(_PyFunction_Vectorcall+0xd5) [0x56062c3f5c05]
48  /opt/conda/envs/gdf/bin/python(_PyEval_EvalFrameDefault+0x68b) [0x56062c3e581b]
49  /opt/conda/envs/gdf/bin/python(+0x139ef3) [0x56062c3f5ef3]
50  /opt/conda/envs/gdf/bin/python(_PyEval_EvalFrameDefault+0x3d8) [0x56062c3e5568]
51  /opt/conda/envs/gdf/bin/python(+0x12827a) [0x56062c3e427a]
52  /opt/conda/envs/gdf/bin/python(_PyFunction_Vectorcall+0xd5) [0x56062c3f5c05]
53  /opt/conda/envs/gdf/bin/python(_PyEval_EvalFrameDefault+0x123b) [0x56062c3e63cb]
54  /opt/conda/envs/gdf/bin/python(+0x12827a) [0x56062c3e427a]
55  /opt/conda/envs/gdf/bin/python(_PyEval_EvalCodeWithName+0x47) [0x56062c3e3f07]
56  /opt/conda/envs/gdf/bin/python(PyEval_EvalCodeEx+0x39) [0x56062c3e3eb9]
57  /opt/conda/envs/gdf/bin/python(PyEval_EvalCode+0x1b) [0x56062c4948bb]
58  /opt/conda/envs/gdf/bin/python(+0x206adc) [0x56062c4c2adc]
59  /opt/conda/envs/gdf/bin/python(+0x202c24) [0x56062c4bec24]
60  /opt/conda/envs/gdf/bin/python(PyRun_StringFlags+0x9d) [0x56062c4b67ed]
61  /opt/conda/envs/gdf/bin/python(PyRun_SimpleStringFlags+0x3d) [0x56062c4b66bd]
=================================
2023-05-29 05:47:33,002 - distributed.worker - ERROR - failed during get data with ucx://127.0.0.1:45995 -> ucx://127.0.0.1:33031
Traceback (most recent call last):
  File "/opt/conda/envs/gdf/lib/python3.9/site-packages/distributed/comm/ucx.py", line 333, in write
    await self.ep.send(each_frame)
  File "/opt/conda/envs/gdf/lib/python3.9/site-packages/ucp/core.py", line 650, in send
    return await comm.tag_send(self._ep, buffer, nbytes, tag, name=log)
ucp._libs.exceptions.UCXError: <[Send #007] ep: 0x7fccf80c2140, tag: 0xab5e759957e5f804, nbytes: 100000000, type: <class 'cudf.core.buffer.buffer.Buffer'>>: Endpoint timeout

During handling of the above exception, another exception occurred:

Traceback (most recent call last):
  File "/opt/conda/envs/gdf/lib/python3.9/site-packages/distributed/worker.py", line 1792, in get_data
    compressed = await comm.write(msg, serializers=serializers)
  File "/opt/conda/envs/gdf/lib/python3.9/site-packages/distributed/utils.py", line 752, in wrapper
    return await func(*args, **kwargs)
  File "/opt/conda/envs/gdf/lib/python3.9/site-packages/distributed/comm/ucx.py", line 337, in write
    raise CommClosedError("While writing, the connection was closed")
distributed.comm.core.CommClosedError: While writing, the connection was closed
2023-05-29 05:47:33,043 - distributed.nanny - WARNING - Restarting worker
[dgx13:68917:0:68917] Caught signal 11 (Segmentation fault: address not mapped to object at address 0x448)
==== backtrace (tid:  68917) ====
 0  /opt/conda/envs/gdf/lib/libucs.so.0(ucs_handle_error+0x2dc) [0x7efec77dd11c]
 1  /opt/conda/envs/gdf/lib/libucs.so.0(+0x302ff) [0x7efec77dd2ff]
 2  /opt/conda/envs/gdf/lib/libucs.so.0(+0x30634) [0x7efec77dd634]
 3  /usr/lib/x86_64-linux-gnu/libpthread.so.0(+0x14420) [0x7eff80091420]
 4  /opt/conda/envs/gdf/lib/libucp.so.0(ucp_mem_type_unpack+0x1b) [0x7efec785e28b]
 5  /opt/conda/envs/gdf/lib/libucp.so.0(ucp_rndv_data_handler+0x508) [0x7efec78880b8]
 6  /opt/conda/envs/gdf/lib/libuct.so.0(+0x216a7) [0x7efec778f6a7]
 7  /opt/conda/envs/gdf/lib/libuct.so.0(+0x21c28) [0x7efec778fc28]
 8  /opt/conda/envs/gdf/lib/libuct.so.0(+0x240fc) [0x7efec77920fc]
 9  /opt/conda/envs/gdf/lib/libucs.so.0(ucs_event_set_wait+0xf9) [0x7efec77e7639]
10  /opt/conda/envs/gdf/lib/libuct.so.0(uct_tcp_iface_progress+0x7b) [0x7efec77921ab]
11  /opt/conda/envs/gdf/lib/libucp.so.0(ucp_worker_progress+0x6a) [0x7efec785af1a]
12  /opt/conda/envs/gdf/lib/python3.9/site-packages/ucp/_libs/ucx_api.cpython-39-x86_64-linux-gnu.so(+0x286e1) [0x7efec790a6e1]
13  /opt/conda/envs/gdf/bin/python(+0x13eb08) [0x55840aefbb08]
14  /opt/conda/envs/gdf/bin/python(_PyEval_EvalFrameDefault+0x5f82) [0x55840aeec112]
15  /opt/conda/envs/gdf/bin/python(+0x12827a) [0x55840aee527a]
16  /opt/conda/envs/gdf/bin/python(_PyFunction_Vectorcall+0xd5) [0x55840aef6c05]
17  /opt/conda/envs/gdf/bin/python(_PyEval_EvalFrameDefault+0x68b) [0x55840aee681b]
18  /opt/conda/envs/gdf/bin/python(+0x139ef3) [0x55840aef6ef3]
19  /opt/conda/envs/gdf/bin/python(+0x147a16) [0x55840af04a16]
20  /opt/conda/envs/gdf/bin/python(+0x2579b1) [0x55840b0149b1]
21  /opt/conda/envs/gdf/bin/python(+0xe5817) [0x55840aea2817]
22  /opt/conda/envs/gdf/bin/python(+0x130f83) [0x55840aeedf83]
23  /opt/conda/envs/gdf/bin/python(_PyEval_EvalFrameDefault+0x5ba6) [0x55840aeebd36]
24  /opt/conda/envs/gdf/bin/python(+0x139ef3) [0x55840aef6ef3]
25  /opt/conda/envs/gdf/bin/python(_PyEval_EvalFrameDefault+0x68b) [0x55840aee681b]
26  /opt/conda/envs/gdf/bin/python(+0x139ef3) [0x55840aef6ef3]
27  /opt/conda/envs/gdf/bin/python(_PyEval_EvalFrameDefault+0x68b) [0x55840aee681b]
28  /opt/conda/envs/gdf/bin/python(+0x139ef3) [0x55840aef6ef3]
29  /opt/conda/envs/gdf/bin/python(_PyEval_EvalFrameDefault+0x68b) [0x55840aee681b]
30  /opt/conda/envs/gdf/bin/python(+0x139ef3) [0x55840aef6ef3]
31  /opt/conda/envs/gdf/bin/python(_PyEval_EvalFrameDefault+0x68b) [0x55840aee681b]
32  /opt/conda/envs/gdf/bin/python(+0x12827a) [0x55840aee527a]
33  /opt/conda/envs/gdf/bin/python(_PyFunction_Vectorcall+0xd5) [0x55840aef6c05]
34  /opt/conda/envs/gdf/bin/python(_PyEval_EvalFrameDefault+0x4e17) [0x55840aeeafa7]
35  /opt/conda/envs/gdf/bin/python(+0x12827a) [0x55840aee527a]
36  /opt/conda/envs/gdf/bin/python(+0x147935) [0x55840af04935]
37  /opt/conda/envs/gdf/bin/python(PyObject_Call+0xb4) [0x55840af05104]
38  /opt/conda/envs/gdf/bin/python(+0x20efc8) [0x55840afcbfc8]
39  /opt/conda/envs/gdf/bin/python(_PyObject_MakeTpCall+0x2fc) [0x55840aeef2bc]
40  /opt/conda/envs/gdf/bin/python(_PyEval_EvalFrameDefault+0x402b) [0x55840aeea1bb]
41  /opt/conda/envs/gdf/bin/python(+0x139ef3) [0x55840aef6ef3]
42  /opt/conda/envs/gdf/bin/python(+0x147c72) [0x55840af04c72]
43  /opt/conda/envs/gdf/bin/python(_PyEval_EvalFrameDefault+0x402b) [0x55840aeea1bb]
44  /opt/conda/envs/gdf/bin/python(+0x139ef3) [0x55840aef6ef3]
45  /opt/conda/envs/gdf/bin/python(_PyEval_EvalFrameDefault+0x68b) [0x55840aee681b]
46  /opt/conda/envs/gdf/bin/python(+0x12827a) [0x55840aee527a]
47  /opt/conda/envs/gdf/bin/python(_PyFunction_Vectorcall+0xd5) [0x55840aef6c05]
48  /opt/conda/envs/gdf/bin/python(_PyEval_EvalFrameDefault+0x68b) [0x55840aee681b]
49  /opt/conda/envs/gdf/bin/python(+0x139ef3) [0x55840aef6ef3]
50  /opt/conda/envs/gdf/bin/python(_PyEval_EvalFrameDefault+0x3d8) [0x55840aee6568]
51  /opt/conda/envs/gdf/bin/python(+0x12827a) [0x55840aee527a]
52  /opt/conda/envs/gdf/bin/python(_PyFunction_Vectorcall+0xd5) [0x55840aef6c05]
53  /opt/conda/envs/gdf/bin/python(_PyEval_EvalFrameDefault+0x123b) [0x55840aee73cb]
54  /opt/conda/envs/gdf/bin/python(+0x12827a) [0x55840aee527a]
55  /opt/conda/envs/gdf/bin/python(_PyEval_EvalCodeWithName+0x47) [0x55840aee4f07]
56  /opt/conda/envs/gdf/bin/python(PyEval_EvalCodeEx+0x39) [0x55840aee4eb9]
57  /opt/conda/envs/gdf/bin/python(PyEval_EvalCode+0x1b) [0x55840af958bb]
58  /opt/conda/envs/gdf/bin/python(+0x206adc) [0x55840afc3adc]
59  /opt/conda/envs/gdf/bin/python(+0x202c24) [0x55840afbfc24]
60  /opt/conda/envs/gdf/bin/python(PyRun_StringFlags+0x9d) [0x55840afb77ed]
61  /opt/conda/envs/gdf/bin/python(PyRun_SimpleStringFlags+0x3d) [0x55840afb76bd]
=================================
2023-05-29 05:47:33,416 - distributed.worker - ERROR - failed during get data with ucx://127.0.0.1:45995 -> ucx://127.0.0.1:57111
Traceback (most recent call last):
  File "/opt/conda/envs/gdf/lib/python3.9/site-packages/distributed/comm/ucx.py", line 333, in write
    await self.ep.send(each_frame)
  File "/opt/conda/envs/gdf/lib/python3.9/site-packages/ucp/core.py", line 650, in send
    return await comm.tag_send(self._ep, buffer, nbytes, tag, name=log)
ucp._libs.exceptions.UCXError: <[Send #007] ep: 0x7fccf80c2140, tag: 0x462c6eac15e63ff9, nbytes: 100000000, type: <class 'cudf.core.buffer.buffer.Buffer'>>: Endpoint timeout

During handling of the above exception, another exception occurred:

Traceback (most recent call last):
  File "/opt/conda/envs/gdf/lib/python3.9/site-packages/distributed/worker.py", line 1792, in get_data
    compressed = await comm.write(msg, serializers=serializers)
  File "/opt/conda/envs/gdf/lib/python3.9/site-packages/distributed/utils.py", line 752, in wrapper
    return await func(*args, **kwargs)
  File "/opt/conda/envs/gdf/lib/python3.9/site-packages/distributed/comm/ucx.py", line 337, in write
    raise CommClosedError("While writing, the connection was closed")
distributed.comm.core.CommClosedError: While writing, the connection was closed
2023-05-29 05:47:33,457 - distributed.nanny - WARNING - Restarting worker
2023-05-29 05:47:34,596 - distributed.preloading - INFO - Creating preload: dask_cuda.initialize
2023-05-29 05:47:34,596 - distributed.preloading - INFO - Import preload module: dask_cuda.initialize
2023-05-29 05:47:35,052 - distributed.preloading - INFO - Creating preload: dask_cuda.initialize
2023-05-29 05:47:35,052 - distributed.preloading - INFO - Import preload module: dask_cuda.initialize
/opt/conda/envs/gdf/lib/python3.9/multiprocessing/resource_tracker.py:216: UserWarning: resource_tracker: There appear to be 48 leaked semaphore objects to clean up at shutdown
  warnings.warn('resource_tracker: There appear to be %d '
