2023-04-29 06:12:11,791 - distributed.preloading - INFO - Creating preload: dask_cuda.initialize
2023-04-29 06:12:11,791 - distributed.preloading - INFO - Import preload module: dask_cuda.initialize
2023-04-29 06:12:11,806 - distributed.preloading - INFO - Creating preload: dask_cuda.initialize
2023-04-29 06:12:11,806 - distributed.preloading - INFO - Import preload module: dask_cuda.initialize
2023-04-29 06:12:11,809 - distributed.preloading - INFO - Creating preload: dask_cuda.initialize
2023-04-29 06:12:11,809 - distributed.preloading - INFO - Import preload module: dask_cuda.initialize
2023-04-29 06:12:11,856 - distributed.preloading - INFO - Creating preload: dask_cuda.initialize
2023-04-29 06:12:11,856 - distributed.preloading - INFO - Import preload module: dask_cuda.initialize
2023-04-29 06:12:11,901 - distributed.preloading - INFO - Creating preload: dask_cuda.initialize
2023-04-29 06:12:11,901 - distributed.preloading - INFO - Import preload module: dask_cuda.initialize
2023-04-29 06:12:11,904 - distributed.preloading - INFO - Creating preload: dask_cuda.initialize
2023-04-29 06:12:11,904 - distributed.preloading - INFO - Import preload module: dask_cuda.initialize
2023-04-29 06:12:11,905 - distributed.preloading - INFO - Creating preload: dask_cuda.initialize
2023-04-29 06:12:11,905 - distributed.preloading - INFO - Import preload module: dask_cuda.initialize
2023-04-29 06:12:11,907 - distributed.preloading - INFO - Creating preload: dask_cuda.initialize
2023-04-29 06:12:11,907 - distributed.preloading - INFO - Import preload module: dask_cuda.initialize
[dgx13:1152 :0:1152] Caught signal 11 (Segmentation fault: address not mapped to object at address 0x448)
==== backtrace (tid:   1152) ====
 0  /opt/conda/envs/gdf/lib/libucs.so.0(ucs_handle_error+0x2dc) [0x7ff6751fedec]
 1  /opt/conda/envs/gdf/lib/libucs.so.0(+0x31fcf) [0x7ff6751fefcf]
 2  /opt/conda/envs/gdf/lib/libucs.so.0(+0x32304) [0x7ff6751ff304]
 3  /usr/lib/x86_64-linux-gnu/libpthread.so.0(+0x14420) [0x7ff7184f0420]
 4  /opt/conda/envs/gdf/lib/libucp.so.0(ucp_mem_type_unpack+0x18) [0x7ff67528e838]
 5  /opt/conda/envs/gdf/lib/libucp.so.0(ucp_rndv_data_handler+0x508) [0x7ff6752c30d8]
 6  /opt/conda/envs/gdf/lib/libuct.so.0(+0x23457) [0x7ff6751ae457]
 7  /opt/conda/envs/gdf/lib/libuct.so.0(+0x23a38) [0x7ff6751aea38]
 8  /opt/conda/envs/gdf/lib/libuct.so.0(+0x260fc) [0x7ff6751b10fc]
 9  /opt/conda/envs/gdf/lib/libucs.so.0(ucs_event_set_wait+0xf9) [0x7ff67520a4d9]
10  /opt/conda/envs/gdf/lib/libuct.so.0(uct_tcp_iface_progress+0x7b) [0x7ff6751b11ab]
11  /opt/conda/envs/gdf/lib/libucp.so.0(ucp_worker_progress+0x6a) [0x7ff67528acaa]
12  /opt/conda/envs/gdf/lib/python3.9/site-packages/ucp/_libs/ucx_api.cpython-39-x86_64-linux-gnu.so(+0x286e1) [0x7ff67534d6e1]
13  /opt/conda/envs/gdf/bin/python(+0x13eb08) [0x55d19234fb08]
14  /opt/conda/envs/gdf/bin/python(_PyEval_EvalFrameDefault+0x5f82) [0x55d192340112]
15  /opt/conda/envs/gdf/bin/python(+0x12827a) [0x55d19233927a]
16  /opt/conda/envs/gdf/bin/python(_PyFunction_Vectorcall+0xd5) [0x55d19234ac05]
17  /opt/conda/envs/gdf/bin/python(_PyEval_EvalFrameDefault+0x68b) [0x55d19233a81b]
18  /opt/conda/envs/gdf/bin/python(+0x139ef3) [0x55d19234aef3]
19  /opt/conda/envs/gdf/bin/python(+0x147a16) [0x55d192358a16]
20  /opt/conda/envs/gdf/bin/python(+0x2579b1) [0x55d1924689b1]
21  /opt/conda/envs/gdf/bin/python(+0xe5817) [0x55d1922f6817]
22  /opt/conda/envs/gdf/bin/python(+0x130f83) [0x55d192341f83]
23  /opt/conda/envs/gdf/bin/python(_PyEval_EvalFrameDefault+0x5ba6) [0x55d19233fd36]
24  /opt/conda/envs/gdf/bin/python(+0x139ef3) [0x55d19234aef3]
25  /opt/conda/envs/gdf/bin/python(_PyEval_EvalFrameDefault+0x68b) [0x55d19233a81b]
26  /opt/conda/envs/gdf/bin/python(+0x139ef3) [0x55d19234aef3]
27  /opt/conda/envs/gdf/bin/python(_PyEval_EvalFrameDefault+0x68b) [0x55d19233a81b]
28  /opt/conda/envs/gdf/bin/python(+0x139ef3) [0x55d19234aef3]
29  /opt/conda/envs/gdf/bin/python(_PyEval_EvalFrameDefault+0x68b) [0x55d19233a81b]
30  /opt/conda/envs/gdf/bin/python(+0x139ef3) [0x55d19234aef3]
31  /opt/conda/envs/gdf/bin/python(_PyEval_EvalFrameDefault+0x68b) [0x55d19233a81b]
32  /opt/conda/envs/gdf/bin/python(+0x12827a) [0x55d19233927a]
33  /opt/conda/envs/gdf/bin/python(_PyFunction_Vectorcall+0xd5) [0x55d19234ac05]
34  /opt/conda/envs/gdf/bin/python(_PyEval_EvalFrameDefault+0x4e17) [0x55d19233efa7]
35  /opt/conda/envs/gdf/bin/python(+0x12827a) [0x55d19233927a]
36  /opt/conda/envs/gdf/bin/python(+0x147935) [0x55d192358935]
37  /opt/conda/envs/gdf/bin/python(PyObject_Call+0xb4) [0x55d192359104]
38  /opt/conda/envs/gdf/bin/python(+0x20efc8) [0x55d19241ffc8]
39  /opt/conda/envs/gdf/bin/python(_PyObject_MakeTpCall+0x2fc) [0x55d1923432bc]
40  /opt/conda/envs/gdf/bin/python(_PyEval_EvalFrameDefault+0x402b) [0x55d19233e1bb]
41  /opt/conda/envs/gdf/bin/python(+0x139ef3) [0x55d19234aef3]
42  /opt/conda/envs/gdf/bin/python(+0x147c72) [0x55d192358c72]
43  /opt/conda/envs/gdf/bin/python(_PyEval_EvalFrameDefault+0x402b) [0x55d19233e1bb]
44  /opt/conda/envs/gdf/bin/python(+0x139ef3) [0x55d19234aef3]
45  /opt/conda/envs/gdf/bin/python(_PyEval_EvalFrameDefault+0x68b) [0x55d19233a81b]
46  /opt/conda/envs/gdf/bin/python(+0x12827a) [0x55d19233927a]
47  /opt/conda/envs/gdf/bin/python(_PyFunction_Vectorcall+0xd5) [0x55d19234ac05]
48  /opt/conda/envs/gdf/bin/python(_PyEval_EvalFrameDefault+0x68b) [0x55d19233a81b]
49  /opt/conda/envs/gdf/bin/python(+0x139ef3) [0x55d19234aef3]
50  /opt/conda/envs/gdf/bin/python(_PyEval_EvalFrameDefault+0x3d8) [0x55d19233a568]
51  /opt/conda/envs/gdf/bin/python(+0x12827a) [0x55d19233927a]
52  /opt/conda/envs/gdf/bin/python(_PyFunction_Vectorcall+0xd5) [0x55d19234ac05]
53  /opt/conda/envs/gdf/bin/python(_PyEval_EvalFrameDefault+0x123b) [0x55d19233b3cb]
54  /opt/conda/envs/gdf/bin/python(+0x12827a) [0x55d19233927a]
55  /opt/conda/envs/gdf/bin/python(_PyEval_EvalCodeWithName+0x47) [0x55d192338f07]
56  /opt/conda/envs/gdf/bin/python(PyEval_EvalCodeEx+0x39) [0x55d192338eb9]
57  /opt/conda/envs/gdf/bin/python(PyEval_EvalCode+0x1b) [0x55d1923e98bb]
58  /opt/conda/envs/gdf/bin/python(+0x206adc) [0x55d192417adc]
59  /opt/conda/envs/gdf/bin/python(+0x202c24) [0x55d192413c24]
60  /opt/conda/envs/gdf/bin/python(PyRun_StringFlags+0x9d) [0x55d19240b7ed]
61  /opt/conda/envs/gdf/bin/python(PyRun_SimpleStringFlags+0x3d) [0x55d19240b6bd]
=================================
[dgx13:1144 :0:1144] Caught signal 11 (Segmentation fault: address not mapped to object at address 0x448)
==== backtrace (tid:   1144) ====
 0  /opt/conda/envs/gdf/lib/libucs.so.0(ucs_handle_error+0x2dc) [0x7f14ac4f2dec]
 1  /opt/conda/envs/gdf/lib/libucs.so.0(+0x31fcf) [0x7f14ac4f2fcf]
 2  /opt/conda/envs/gdf/lib/libucs.so.0(+0x32304) [0x7f14ac4f3304]
 3  /usr/lib/x86_64-linux-gnu/libpthread.so.0(+0x14420) [0x7f153d93c420]
 4  /opt/conda/envs/gdf/lib/libucp.so.0(ucp_mem_type_unpack+0x18) [0x7f14ac582838]
 5  /opt/conda/envs/gdf/lib/libucp.so.0(ucp_rndv_data_handler+0x508) [0x7f14ac5b70d8]
 6  /opt/conda/envs/gdf/lib/libuct.so.0(+0x23457) [0x7f14ac4a2457]
 7  /opt/conda/envs/gdf/lib/libuct.so.0(+0x23a38) [0x7f14ac4a2a38]
 8  /opt/conda/envs/gdf/lib/libuct.so.0(+0x260fc) [0x7f14ac4a50fc]
 9  /opt/conda/envs/gdf/lib/libucs.so.0(ucs_event_set_wait+0xf9) [0x7f14ac4fe4d9]
10  /opt/conda/envs/gdf/lib/libuct.so.0(uct_tcp_iface_progress+0x7b) [0x7f14ac4a51ab]
11  /opt/conda/envs/gdf/lib/libucp.so.0(ucp_worker_progress+0x6a) [0x7f14ac57ecaa]
12  /opt/conda/envs/gdf/lib/python3.9/site-packages/ucp/_libs/ucx_api.cpython-39-x86_64-linux-gnu.so(+0x286e1) [0x7f14ac6416e1]
13  /opt/conda/envs/gdf/bin/python(+0x13eb08) [0x56259f7d1b08]
14  /opt/conda/envs/gdf/bin/python(_PyEval_EvalFrameDefault+0x5f82) [0x56259f7c2112]
15  /opt/conda/envs/gdf/bin/python(+0x12827a) [0x56259f7bb27a]
16  /opt/conda/envs/gdf/bin/python(_PyFunction_Vectorcall+0xd5) [0x56259f7ccc05]
17  /opt/conda/envs/gdf/bin/python(_PyEval_EvalFrameDefault+0x68b) [0x56259f7bc81b]
18  /opt/conda/envs/gdf/bin/python(+0x14e70e) [0x56259f7e170e]
19  /opt/conda/envs/gdf/lib/python3.9/lib-dynload/_asyncio.cpython-39-x86_64-linux-gnu.so(+0x82fe) [0x7f14bd1d72fe]
20  /opt/conda/envs/gdf/bin/python(_PyObject_MakeTpCall+0x2fc) [0x56259f7c52bc]
21  /opt/conda/envs/gdf/bin/python(+0xe5817) [0x56259f778817]
22  /opt/conda/envs/gdf/bin/python(+0x130f83) [0x56259f7c3f83]
23  /opt/conda/envs/gdf/bin/python(_PyEval_EvalFrameDefault+0x5ba6) [0x56259f7c1d36]
24  /opt/conda/envs/gdf/bin/python(+0x139ef3) [0x56259f7ccef3]
25  /opt/conda/envs/gdf/bin/python(_PyEval_EvalFrameDefault+0x68b) [0x56259f7bc81b]
26  /opt/conda/envs/gdf/bin/python(+0x139ef3) [0x56259f7ccef3]
27  /opt/conda/envs/gdf/bin/python(_PyEval_EvalFrameDefault+0x68b) [0x56259f7bc81b]
28  /opt/conda/envs/gdf/bin/python(+0x139ef3) [0x56259f7ccef3]
29  /opt/conda/envs/gdf/bin/python(_PyEval_EvalFrameDefault+0x68b) [0x56259f7bc81b]
30  /opt/conda/envs/gdf/bin/python(+0x139ef3) [0x56259f7ccef3]
31  /opt/conda/envs/gdf/bin/python(_PyEval_EvalFrameDefault+0x68b) [0x56259f7bc81b]
32  /opt/conda/envs/gdf/bin/python(+0x12827a) [0x56259f7bb27a]
33  /opt/conda/envs/gdf/bin/python(_PyFunction_Vectorcall+0xd5) [0x56259f7ccc05]
34  /opt/conda/envs/gdf/bin/python(_PyEval_EvalFrameDefault+0x4e17) [0x56259f7c0fa7]
35  /opt/conda/envs/gdf/bin/python(+0x12827a) [0x56259f7bb27a]
36  /opt/conda/envs/gdf/bin/python(+0x147935) [0x56259f7da935]
37  /opt/conda/envs/gdf/bin/python(PyObject_Call+0xb4) [0x56259f7db104]
38  /opt/conda/envs/gdf/bin/python(+0x20efc8) [0x56259f8a1fc8]
39  /opt/conda/envs/gdf/bin/python(_PyObject_MakeTpCall+0x2fc) [0x56259f7c52bc]
40  /opt/conda/envs/gdf/bin/python(_PyEval_EvalFrameDefault+0x402b) [0x56259f7c01bb]
41  /opt/conda/envs/gdf/bin/python(+0x139ef3) [0x56259f7ccef3]
42  /opt/conda/envs/gdf/bin/python(+0x147c72) [0x56259f7dac72]
43  /opt/conda/envs/gdf/bin/python(_PyEval_EvalFrameDefault+0x402b) [0x56259f7c01bb]
44  /opt/conda/envs/gdf/bin/python(+0x139ef3) [0x56259f7ccef3]
45  /opt/conda/envs/gdf/bin/python(_PyEval_EvalFrameDefault+0x68b) [0x56259f7bc81b]
46  /opt/conda/envs/gdf/bin/python(+0x12827a) [0x56259f7bb27a]
47  /opt/conda/envs/gdf/bin/python(_PyFunction_Vectorcall+0xd5) [0x56259f7ccc05]
48  /opt/conda/envs/gdf/bin/python(_PyEval_EvalFrameDefault+0x68b) [0x56259f7bc81b]
49  /opt/conda/envs/gdf/bin/python(+0x139ef3) [0x56259f7ccef3]
50  /opt/conda/envs/gdf/bin/python(_PyEval_EvalFrameDefault+0x3d8) [0x56259f7bc568]
51  /opt/conda/envs/gdf/bin/python(+0x12827a) [0x56259f7bb27a]
52  /opt/conda/envs/gdf/bin/python(_PyFunction_Vectorcall+0xd5) [0x56259f7ccc05]
53  /opt/conda/envs/gdf/bin/python(_PyEval_EvalFrameDefault+0x123b) [0x56259f7bd3cb]
54  /opt/conda/envs/gdf/bin/python(+0x12827a) [0x56259f7bb27a]
55  /opt/conda/envs/gdf/bin/python(_PyEval_EvalCodeWithName+0x47) [0x56259f7baf07]
56  /opt/conda/envs/gdf/bin/python(PyEval_EvalCodeEx+0x39) [0x56259f7baeb9]
57  /opt/conda/envs/gdf/bin/python(PyEval_EvalCode+0x1b) [0x56259f86b8bb]
58  /opt/conda/envs/gdf/bin/python(+0x206adc) [0x56259f899adc]
59  /opt/conda/envs/gdf/bin/python(+0x202c24) [0x56259f895c24]
60  /opt/conda/envs/gdf/bin/python(PyRun_StringFlags+0x9d) [0x56259f88d7ed]
61  /opt/conda/envs/gdf/bin/python(PyRun_SimpleStringFlags+0x3d) [0x56259f88d6bd]
=================================
[dgx13:1148 :0:1148] Caught signal 11 (Segmentation fault: address not mapped to object at address 0x448)
==== backtrace (tid:   1148) ====
 0  /opt/conda/envs/gdf/lib/libucs.so.0(ucs_handle_error+0x2dc) [0x7fa4e5a28dec]
 1  /opt/conda/envs/gdf/lib/libucs.so.0(+0x31fcf) [0x7fa4e5a28fcf]
 2  /opt/conda/envs/gdf/lib/libucs.so.0(+0x32304) [0x7fa4e5a29304]
 3  /usr/lib/x86_64-linux-gnu/libpthread.so.0(+0x14420) [0x7fa58acf9420]
 4  /opt/conda/envs/gdf/lib/libucp.so.0(ucp_mem_type_unpack+0x18) [0x7fa4e5ab8838]
 5  /opt/conda/envs/gdf/lib/libucp.so.0(ucp_rndv_data_handler+0x508) [0x7fa4e5aed0d8]
 6  /opt/conda/envs/gdf/lib/libuct.so.0(+0x23457) [0x7fa4e59d8457]
 7  /opt/conda/envs/gdf/lib/libuct.so.0(+0x23a38) [0x7fa4e59d8a38]
 8  /opt/conda/envs/gdf/lib/libuct.so.0(+0x260fc) [0x7fa4e59db0fc]
 9  /opt/conda/envs/gdf/lib/libucs.so.0(ucs_event_set_wait+0xf9) [0x7fa4e5a344d9]
10  /opt/conda/envs/gdf/lib/libuct.so.0(uct_tcp_iface_progress+0x7b) [0x7fa4e59db1ab]
11  /opt/conda/envs/gdf/lib/libucp.so.0(ucp_worker_progress+0x6a) [0x7fa4e5ab4caa]
12  /opt/conda/envs/gdf/lib/python3.9/site-packages/ucp/_libs/ucx_api.cpython-39-x86_64-linux-gnu.so(+0x286e1) [0x7fa4e5b776e1]
13  /opt/conda/envs/gdf/bin/python(+0x13eb08) [0x5566bdecdb08]
14  /opt/conda/envs/gdf/bin/python(_PyEval_EvalFrameDefault+0x5f82) [0x5566bdebe112]
15  /opt/conda/envs/gdf/bin/python(+0x12827a) [0x5566bdeb727a]
16  /opt/conda/envs/gdf/bin/python(_PyFunction_Vectorcall+0xd5) [0x5566bdec8c05]
17  /opt/conda/envs/gdf/bin/python(_PyEval_EvalFrameDefault+0x68b) [0x5566bdeb881b]
18  /opt/conda/envs/gdf/bin/python(+0x14e70e) [0x5566bdedd70e]
19  /opt/conda/envs/gdf/lib/python3.9/lib-dynload/_asyncio.cpython-39-x86_64-linux-gnu.so(+0x82fe) [0x7fa50a5982fe]
20  /opt/conda/envs/gdf/bin/python(_PyObject_MakeTpCall+0x2fc) [0x5566bdec12bc]
21  /opt/conda/envs/gdf/bin/python(+0xe5817) [0x5566bde74817]
22  /opt/conda/envs/gdf/bin/python(+0x130f83) [0x5566bdebff83]
23  /opt/conda/envs/gdf/bin/python(_PyEval_EvalFrameDefault+0x5ba6) [0x5566bdebdd36]
24  /opt/conda/envs/gdf/bin/python(+0x139ef3) [0x5566bdec8ef3]
25  /opt/conda/envs/gdf/bin/python(_PyEval_EvalFrameDefault+0x68b) [0x5566bdeb881b]
26  /opt/conda/envs/gdf/bin/python(+0x139ef3) [0x5566bdec8ef3]
27  /opt/conda/envs/gdf/bin/python(_PyEval_EvalFrameDefault+0x68b) [0x5566bdeb881b]
28  /opt/conda/envs/gdf/bin/python(+0x139ef3) [0x5566bdec8ef3]
29  /opt/conda/envs/gdf/bin/python(_PyEval_EvalFrameDefault+0x68b) [0x5566bdeb881b]
30  /opt/conda/envs/gdf/bin/python(+0x139ef3) [0x5566bdec8ef3]
31  /opt/conda/envs/gdf/bin/python(_PyEval_EvalFrameDefault+0x68b) [0x5566bdeb881b]
32  /opt/conda/envs/gdf/bin/python(+0x12827a) [0x5566bdeb727a]
33  /opt/conda/envs/gdf/bin/python(_PyFunction_Vectorcall+0xd5) [0x5566bdec8c05]
34  /opt/conda/envs/gdf/bin/python(_PyEval_EvalFrameDefault+0x4e17) [0x5566bdebcfa7]
35  /opt/conda/envs/gdf/bin/python(+0x12827a) [0x5566bdeb727a]
36  /opt/conda/envs/gdf/bin/python(+0x147935) [0x5566bded6935]
37  /opt/conda/envs/gdf/bin/python(PyObject_Call+0xb4) [0x5566bded7104]
38  /opt/conda/envs/gdf/bin/python(+0x20efc8) [0x5566bdf9dfc8]
39  /opt/conda/envs/gdf/bin/python(_PyObject_MakeTpCall+0x2fc) [0x5566bdec12bc]
40  /opt/conda/envs/gdf/bin/python(_PyEval_EvalFrameDefault+0x402b) [0x5566bdebc1bb]
41  /opt/conda/envs/gdf/bin/python(+0x139ef3) [0x5566bdec8ef3]
42  /opt/conda/envs/gdf/bin/python(+0x147c72) [0x5566bded6c72]
43  /opt/conda/envs/gdf/bin/python(_PyEval_EvalFrameDefault+0x402b) [0x5566bdebc1bb]
44  /opt/conda/envs/gdf/bin/python(+0x139ef3) [0x5566bdec8ef3]
45  /opt/conda/envs/gdf/bin/python(_PyEval_EvalFrameDefault+0x68b) [0x5566bdeb881b]
46  /opt/conda/envs/gdf/bin/python(+0x12827a) [0x5566bdeb727a]
47  /opt/conda/envs/gdf/bin/python(_PyFunction_Vectorcall+0xd5) [0x5566bdec8c05]
48  /opt/conda/envs/gdf/bin/python(_PyEval_EvalFrameDefault+0x68b) [0x5566bdeb881b]
49  /opt/conda/envs/gdf/bin/python(+0x139ef3) [0x5566bdec8ef3]
50  /opt/conda/envs/gdf/bin/python(_PyEval_EvalFrameDefault+0x3d8) [0x5566bdeb8568]
51  /opt/conda/envs/gdf/bin/python(+0x12827a) [0x5566bdeb727a]
52  /opt/conda/envs/gdf/bin/python(_PyFunction_Vectorcall+0xd5) [0x5566bdec8c05]
53  /opt/conda/envs/gdf/bin/python(_PyEval_EvalFrameDefault+0x123b) [0x5566bdeb93cb]
54  /opt/conda/envs/gdf/bin/python(+0x12827a) [0x5566bdeb727a]
55  /opt/conda/envs/gdf/bin/python(_PyEval_EvalCodeWithName+0x47) [0x5566bdeb6f07]
56  /opt/conda/envs/gdf/bin/python(PyEval_EvalCodeEx+0x39) [0x5566bdeb6eb9]
57  /opt/conda/envs/gdf/bin/python(PyEval_EvalCode+0x1b) [0x5566bdf678bb]
58  /opt/conda/envs/gdf/bin/python(+0x206adc) [0x5566bdf95adc]
59  /opt/conda/envs/gdf/bin/python(+0x202c24) [0x5566bdf91c24]
60  /opt/conda/envs/gdf/bin/python(PyRun_StringFlags+0x9d) [0x5566bdf897ed]
61  /opt/conda/envs/gdf/bin/python(PyRun_SimpleStringFlags+0x3d) [0x5566bdf896bd]
=================================
2023-04-29 06:12:14,993 - distributed.worker - ERROR - failed during get data with ucx://127.0.0.1:44545 -> ucx://127.0.0.1:57391
Traceback (most recent call last):
  File "/opt/conda/envs/gdf/lib/python3.9/site-packages/distributed/comm/ucx.py", line 333, in write
    await self.ep.send(each_frame)
  File "/opt/conda/envs/gdf/lib/python3.9/site-packages/ucp/core.py", line 650, in send
    return await comm.tag_send(self._ep, buffer, nbytes, tag, name=log)
ucp._libs.exceptions.UCXError: <[Send #007] ep: 0x7fb371dee300, tag: 0xa16491641efbba8b, nbytes: 50000000, type: <class 'cupy.ndarray'>>: Connection reset by remote peer

During handling of the above exception, another exception occurred:

Traceback (most recent call last):
  File "/opt/conda/envs/gdf/lib/python3.9/site-packages/distributed/worker.py", line 1792, in get_data
    compressed = await comm.write(msg, serializers=serializers)
  File "/opt/conda/envs/gdf/lib/python3.9/site-packages/distributed/utils.py", line 752, in wrapper
    return await func(*args, **kwargs)
  File "/opt/conda/envs/gdf/lib/python3.9/site-packages/distributed/comm/ucx.py", line 337, in write
    raise CommClosedError("While writing, the connection was closed")
distributed.comm.core.CommClosedError: While writing, the connection was closed
Task exception was never retrieved
future: <Task finished name='Task-289' coro=<_listener_handler_coroutine() done, defined at /opt/conda/envs/gdf/lib/python3.9/site-packages/ucp/core.py:128> exception=UCXError('<stream_send>: Connection reset by remote peer')>
Traceback (most recent call last):
  File "/opt/conda/envs/gdf/lib/python3.9/site-packages/ucp/core.py", line 143, in _listener_handler_coroutine
    peer_info = await exchange_peer_info(
  File "/opt/conda/envs/gdf/lib/python3.9/site-packages/ucp/core.py", line 51, in exchange_peer_info
    await comm.stream_send(endpoint, my_info_arr, my_info_arr.nbytes)
ucp._libs.exceptions.UCXError: <stream_send>: Connection reset by remote peer
2023-04-29 06:12:14,997 - distributed.worker - ERROR - Worker stream died during communication: ucx://127.0.0.1:57391
Traceback (most recent call last):
  File "/opt/conda/envs/gdf/lib/python3.9/site-packages/distributed/comm/ucx.py", line 349, in read
    await self.ep.recv(msg)
  File "/opt/conda/envs/gdf/lib/python3.9/site-packages/ucp/core.py", line 725, in recv
    ret = await comm.tag_recv(self._ep, buffer, nbytes, tag, name=log)
ucp._libs.exceptions.UCXCanceled: <[Recv #000] ep: 0x7faad744f140, tag: 0xd69e7240e511b0bb, nbytes: 16, type: <class 'numpy.ndarray'>>: 

During handling of the above exception, another exception occurred:

Traceback (most recent call last):
  File "/opt/conda/envs/gdf/lib/python3.9/site-packages/distributed/comm/core.py", line 329, in connect
    handshake = await wait_for(comm.read(), time_left())
  File "/opt/conda/envs/gdf/lib/python3.9/site-packages/distributed/utils.py", line 1849, in wait_for
    return await asyncio.wait_for(fut, timeout)
  File "/opt/conda/envs/gdf/lib/python3.9/asyncio/tasks.py", line 479, in wait_for
    return fut.result()
  File "/opt/conda/envs/gdf/lib/python3.9/site-packages/distributed/utils.py", line 752, in wrapper
    return await func(*args, **kwargs)
  File "/opt/conda/envs/gdf/lib/python3.9/site-packages/distributed/comm/ucx.py", line 367, in read
    raise CommClosedError(
distributed.comm.core.CommClosedError: Connection closed by writer.
Inner exception: UCXCanceled("<[Recv #000] ep: 0x7faad744f140, tag: 0xd69e7240e511b0bb, nbytes: 16, type: <class 'numpy.ndarray'>>: ")

The above exception was the direct cause of the following exception:

Traceback (most recent call last):
  File "/opt/conda/envs/gdf/lib/python3.9/site-packages/distributed/worker.py", line 2066, in gather_dep
    response = await get_data_from_worker(
  File "/opt/conda/envs/gdf/lib/python3.9/site-packages/distributed/worker.py", line 2889, in get_data_from_worker
    comm = await rpc.connect(worker)
  File "/opt/conda/envs/gdf/lib/python3.9/site-packages/distributed/core.py", line 1506, in connect
    return await connect_attempt
  File "/opt/conda/envs/gdf/lib/python3.9/site-packages/distributed/core.py", line 1427, in _connect
    comm = await connect(
  File "/opt/conda/envs/gdf/lib/python3.9/site-packages/distributed/comm/core.py", line 334, in connect
    raise OSError(
OSError: Timed out during handshake while connecting to ucx://127.0.0.1:57391 after 30 s
[dgx13:1157 :0:1157] Caught signal 11 (Segmentation fault: address not mapped to object at address 0x448)
==== backtrace (tid:   1157) ====
 0  /opt/conda/envs/gdf/lib/libucs.so.0(ucs_handle_error+0x2dc) [0x7fa114124dec]
 1  /opt/conda/envs/gdf/lib/libucs.so.0(+0x31fcf) [0x7fa114124fcf]
 2  /opt/conda/envs/gdf/lib/libucs.so.0(+0x32304) [0x7fa114125304]
 3  /usr/lib/x86_64-linux-gnu/libpthread.so.0(+0x14420) [0x7fa1b3412420]
 4  /opt/conda/envs/gdf/lib/libucp.so.0(ucp_mem_type_unpack+0x18) [0x7fa1141b4838]
 5  /opt/conda/envs/gdf/lib/libucp.so.0(ucp_rndv_data_handler+0x508) [0x7fa1141e90d8]
 6  /opt/conda/envs/gdf/lib/libuct.so.0(+0x23457) [0x7fa1140d4457]
 7  /opt/conda/envs/gdf/lib/libuct.so.0(+0x23a38) [0x7fa1140d4a38]
 8  /opt/conda/envs/gdf/lib/libuct.so.0(+0x260fc) [0x7fa1140d70fc]
 9  /opt/conda/envs/gdf/lib/libucs.so.0(ucs_event_set_wait+0xf9) [0x7fa1141304d9]
10  /opt/conda/envs/gdf/lib/libuct.so.0(uct_tcp_iface_progress+0x7b) [0x7fa1140d71ab]
11  /opt/conda/envs/gdf/lib/libucp.so.0(ucp_worker_progress+0x6a) [0x7fa1141b0caa]
12  /opt/conda/envs/gdf/lib/python3.9/site-packages/ucp/_libs/ucx_api.cpython-39-x86_64-linux-gnu.so(+0x286e1) [0x7fa1142736e1]
13  /opt/conda/envs/gdf/bin/python(+0x13eb08) [0x55bf455b6b08]
14  /opt/conda/envs/gdf/bin/python(_PyEval_EvalFrameDefault+0x5f82) [0x55bf455a7112]
15  /opt/conda/envs/gdf/bin/python(+0x12827a) [0x55bf455a027a]
16  /opt/conda/envs/gdf/bin/python(_PyFunction_Vectorcall+0xd5) [0x55bf455b1c05]
17  /opt/conda/envs/gdf/bin/python(_PyEval_EvalFrameDefault+0x68b) [0x55bf455a181b]
18  /opt/conda/envs/gdf/bin/python(+0x14e70e) [0x55bf455c670e]
19  /opt/conda/envs/gdf/lib/python3.9/lib-dynload/_asyncio.cpython-39-x86_64-linux-gnu.so(+0x82fe) [0x7fa132cb42fe]
20  /opt/conda/envs/gdf/bin/python(_PyObject_MakeTpCall+0x2fc) [0x55bf455aa2bc]
21  /opt/conda/envs/gdf/bin/python(+0xe5817) [0x55bf4555d817]
22  /opt/conda/envs/gdf/bin/python(+0x130f83) [0x55bf455a8f83]
23  /opt/conda/envs/gdf/bin/python(_PyEval_EvalFrameDefault+0x5ba6) [0x55bf455a6d36]
24  /opt/conda/envs/gdf/bin/python(+0x139ef3) [0x55bf455b1ef3]
25  /opt/conda/envs/gdf/bin/python(_PyEval_EvalFrameDefault+0x68b) [0x55bf455a181b]
26  /opt/conda/envs/gdf/bin/python(+0x139ef3) [0x55bf455b1ef3]
27  /opt/conda/envs/gdf/bin/python(_PyEval_EvalFrameDefault+0x68b) [0x55bf455a181b]
28  /opt/conda/envs/gdf/bin/python(+0x139ef3) [0x55bf455b1ef3]
29  /opt/conda/envs/gdf/bin/python(_PyEval_EvalFrameDefault+0x68b) [0x55bf455a181b]
30  /opt/conda/envs/gdf/bin/python(+0x139ef3) [0x55bf455b1ef3]
31  /opt/conda/envs/gdf/bin/python(_PyEval_EvalFrameDefault+0x68b) [0x55bf455a181b]
32  /opt/conda/envs/gdf/bin/python(+0x12827a) [0x55bf455a027a]
33  /opt/conda/envs/gdf/bin/python(_PyFunction_Vectorcall+0xd5) [0x55bf455b1c05]
34  /opt/conda/envs/gdf/bin/python(_PyEval_EvalFrameDefault+0x4e17) [0x55bf455a5fa7]
35  /opt/conda/envs/gdf/bin/python(+0x12827a) [0x55bf455a027a]
36  /opt/conda/envs/gdf/bin/python(+0x147935) [0x55bf455bf935]
37  /opt/conda/envs/gdf/bin/python(PyObject_Call+0xb4) [0x55bf455c0104]
38  /opt/conda/envs/gdf/bin/python(+0x20efc8) [0x55bf45686fc8]
39  /opt/conda/envs/gdf/bin/python(_PyObject_MakeTpCall+0x2fc) [0x55bf455aa2bc]
40  /opt/conda/envs/gdf/bin/python(_PyEval_EvalFrameDefault+0x402b) [0x55bf455a51bb]
41  /opt/conda/envs/gdf/bin/python(+0x139ef3) [0x55bf455b1ef3]
42  /opt/conda/envs/gdf/bin/python(+0x147c72) [0x55bf455bfc72]
43  /opt/conda/envs/gdf/bin/python(_PyEval_EvalFrameDefault+0x402b) [0x55bf455a51bb]
44  /opt/conda/envs/gdf/bin/python(+0x139ef3) [0x55bf455b1ef3]
45  /opt/conda/envs/gdf/bin/python(_PyEval_EvalFrameDefault+0x68b) [0x55bf455a181b]
46  /opt/conda/envs/gdf/bin/python(+0x12827a) [0x55bf455a027a]
47  /opt/conda/envs/gdf/bin/python(_PyFunction_Vectorcall+0xd5) [0x55bf455b1c05]
48  /opt/conda/envs/gdf/bin/python(_PyEval_EvalFrameDefault+0x68b) [0x55bf455a181b]
49  /opt/conda/envs/gdf/bin/python(+0x139ef3) [0x55bf455b1ef3]
50  /opt/conda/envs/gdf/bin/python(_PyEval_EvalFrameDefault+0x3d8) [0x55bf455a1568]
51  /opt/conda/envs/gdf/bin/python(+0x12827a) [0x55bf455a027a]
52  /opt/conda/envs/gdf/bin/python(_PyFunction_Vectorcall+0xd5) [0x55bf455b1c05]
53  /opt/conda/envs/gdf/bin/python(_PyEval_EvalFrameDefault+0x123b) [0x55bf455a23cb]
54  /opt/conda/envs/gdf/bin/python(+0x12827a) [0x55bf455a027a]
55  /opt/conda/envs/gdf/bin/python(_PyEval_EvalCodeWithName+0x47) [0x55bf4559ff07]
56  /opt/conda/envs/gdf/bin/python(PyEval_EvalCodeEx+0x39) [0x55bf4559feb9]
57  /opt/conda/envs/gdf/bin/python(PyEval_EvalCode+0x1b) [0x55bf456508bb]
58  /opt/conda/envs/gdf/bin/python(+0x206adc) [0x55bf4567eadc]
59  /opt/conda/envs/gdf/bin/python(+0x202c24) [0x55bf4567ac24]
60  /opt/conda/envs/gdf/bin/python(PyRun_StringFlags+0x9d) [0x55bf456727ed]
61  /opt/conda/envs/gdf/bin/python(PyRun_SimpleStringFlags+0x3d) [0x55bf456726bd]
=================================
2023-04-29 06:12:15,047 - distributed.worker - ERROR - Worker stream died during communication: ucx://127.0.0.1:45353
Traceback (most recent call last):
  File "/opt/conda/envs/gdf/lib/python3.9/site-packages/distributed/comm/ucx.py", line 391, in read
    await self.ep.recv(each_frame)
  File "/opt/conda/envs/gdf/lib/python3.9/site-packages/ucp/core.py", line 725, in recv
    ret = await comm.tag_recv(self._ep, buffer, nbytes, tag, name=log)
ucp._libs.exceptions.UCXError: <[Recv #007] ep: 0x7f35d42ea100, tag: 0xa280637ec7815a27, nbytes: 50000000, type: <class 'rmm._lib.device_buffer.DeviceBuffer'>>: Connection reset by remote peer

During handling of the above exception, another exception occurred:

Traceback (most recent call last):
  File "/opt/conda/envs/gdf/lib/python3.9/site-packages/distributed/worker.py", line 2066, in gather_dep
    response = await get_data_from_worker(
  File "/opt/conda/envs/gdf/lib/python3.9/site-packages/distributed/worker.py", line 2892, in get_data_from_worker
    response = await send_recv(
  File "/opt/conda/envs/gdf/lib/python3.9/site-packages/distributed/core.py", line 1024, in send_recv
    response = await comm.read(deserializers=deserializers)
  File "/opt/conda/envs/gdf/lib/python3.9/site-packages/distributed/utils.py", line 752, in wrapper
    return await func(*args, **kwargs)
  File "/opt/conda/envs/gdf/lib/python3.9/site-packages/distributed/comm/ucx.py", line 397, in read
    raise CommClosedError(
distributed.comm.core.CommClosedError: Connection closed by writer.
Inner exception: UCXError("<[Recv #007] ep: 0x7f35d42ea100, tag: 0xa280637ec7815a27, nbytes: 50000000, type: <class 'rmm._lib.device_buffer.DeviceBuffer'>>: Connection reset by remote peer")
2023-04-29 06:12:15,048 - distributed.worker - ERROR - Worker stream died during communication: ucx://127.0.0.1:45353
Traceback (most recent call last):
  File "/opt/conda/envs/gdf/lib/python3.9/site-packages/distributed/comm/ucx.py", line 349, in read
    await self.ep.recv(msg)
  File "/opt/conda/envs/gdf/lib/python3.9/site-packages/ucp/core.py", line 725, in recv
    ret = await comm.tag_recv(self._ep, buffer, nbytes, tag, name=log)
ucp._libs.exceptions.UCXCanceled: <[Recv #003] ep: 0x7fb371dee180, tag: 0x24c678d31b73cb54, nbytes: 16, type: <class 'numpy.ndarray'>>: 

During handling of the above exception, another exception occurred:

Traceback (most recent call last):
  File "/opt/conda/envs/gdf/lib/python3.9/site-packages/distributed/worker.py", line 2066, in gather_dep
    response = await get_data_from_worker(
  File "/opt/conda/envs/gdf/lib/python3.9/site-packages/distributed/worker.py", line 2892, in get_data_from_worker
    response = await send_recv(
  File "/opt/conda/envs/gdf/lib/python3.9/site-packages/distributed/core.py", line 1024, in send_recv
    response = await comm.read(deserializers=deserializers)
  File "/opt/conda/envs/gdf/lib/python3.9/site-packages/distributed/utils.py", line 752, in wrapper
    return await func(*args, **kwargs)
  File "/opt/conda/envs/gdf/lib/python3.9/site-packages/distributed/comm/ucx.py", line 367, in read
    raise CommClosedError(
distributed.comm.core.CommClosedError: Connection closed by writer.
Inner exception: UCXCanceled("<[Recv #003] ep: 0x7fb371dee180, tag: 0x24c678d31b73cb54, nbytes: 16, type: <class 'numpy.ndarray'>>: ")
2023-04-29 06:12:15,049 - distributed.worker - ERROR - failed during get data with ucx://127.0.0.1:35103 -> ucx://127.0.0.1:45353
Traceback (most recent call last):
  File "/opt/conda/envs/gdf/lib/python3.9/site-packages/distributed/comm/ucx.py", line 333, in write
    await self.ep.send(each_frame)
  File "/opt/conda/envs/gdf/lib/python3.9/site-packages/ucp/core.py", line 650, in send
    return await comm.tag_send(self._ep, buffer, nbytes, tag, name=log)
ucp._libs.exceptions.UCXError: <[Send #007] ep: 0x7f35d42ea1c0, tag: 0x416bd2f7176056af, nbytes: 50000000, type: <class 'cupy.ndarray'>>: Connection reset by remote peer

During handling of the above exception, another exception occurred:

Traceback (most recent call last):
  File "/opt/conda/envs/gdf/lib/python3.9/site-packages/distributed/worker.py", line 1792, in get_data
    compressed = await comm.write(msg, serializers=serializers)
  File "/opt/conda/envs/gdf/lib/python3.9/site-packages/distributed/utils.py", line 752, in wrapper
    return await func(*args, **kwargs)
  File "/opt/conda/envs/gdf/lib/python3.9/site-packages/distributed/comm/ucx.py", line 337, in write
    raise CommClosedError("While writing, the connection was closed")
distributed.comm.core.CommClosedError: While writing, the connection was closed
2023-04-29 06:12:15,049 - distributed.worker - ERROR - failed during get data with ucx://127.0.0.1:35103 -> ucx://127.0.0.1:36759
Traceback (most recent call last):
  File "/opt/conda/envs/gdf/lib/python3.9/site-packages/distributed/comm/ucx.py", line 333, in write
    await self.ep.send(each_frame)
  File "/opt/conda/envs/gdf/lib/python3.9/site-packages/ucp/core.py", line 650, in send
    return await comm.tag_send(self._ep, buffer, nbytes, tag, name=log)
ucp._libs.exceptions.UCXError: <[Send #007] ep: 0x7f35d42ea200, tag: 0x3028e6ef5ebc3bff, nbytes: 50000000, type: <class 'cupy.ndarray'>>: Connection reset by remote peer

During handling of the above exception, another exception occurred:

Traceback (most recent call last):
  File "/opt/conda/envs/gdf/lib/python3.9/site-packages/distributed/worker.py", line 1792, in get_data
    compressed = await comm.write(msg, serializers=serializers)
  File "/opt/conda/envs/gdf/lib/python3.9/site-packages/distributed/utils.py", line 752, in wrapper
    return await func(*args, **kwargs)
  File "/opt/conda/envs/gdf/lib/python3.9/site-packages/distributed/comm/ucx.py", line 337, in write
    raise CommClosedError("While writing, the connection was closed")
distributed.comm.core.CommClosedError: While writing, the connection was closed
2023-04-29 06:12:15,050 - distributed.worker - ERROR - failed during get data with ucx://127.0.0.1:52227 -> ucx://127.0.0.1:45353
Traceback (most recent call last):
  File "/opt/conda/envs/gdf/lib/python3.9/site-packages/distributed/comm/ucx.py", line 333, in write
    await self.ep.send(each_frame)
  File "/opt/conda/envs/gdf/lib/python3.9/site-packages/ucp/core.py", line 650, in send
    return await comm.tag_send(self._ep, buffer, nbytes, tag, name=log)
ucp._libs.exceptions.UCXError: <[Send #007] ep: 0x7fb695e102c0, tag: 0xb319ed9823fb8316, nbytes: 50000000, type: <class 'cupy.ndarray'>>: Connection reset by remote peer

During handling of the above exception, another exception occurred:

Traceback (most recent call last):
  File "/opt/conda/envs/gdf/lib/python3.9/site-packages/distributed/worker.py", line 1792, in get_data
    compressed = await comm.write(msg, serializers=serializers)
  File "/opt/conda/envs/gdf/lib/python3.9/site-packages/distributed/utils.py", line 752, in wrapper
    return await func(*args, **kwargs)
  File "/opt/conda/envs/gdf/lib/python3.9/site-packages/distributed/comm/ucx.py", line 337, in write
    raise CommClosedError("While writing, the connection was closed")
distributed.comm.core.CommClosedError: While writing, the connection was closed
2023-04-29 06:12:15,051 - distributed.worker - ERROR - Worker stream died during communication: ucx://127.0.0.1:45353
Traceback (most recent call last):
  File "/opt/conda/envs/gdf/lib/python3.9/site-packages/distributed/comm/ucx.py", line 349, in read
    await self.ep.recv(msg)
  File "/opt/conda/envs/gdf/lib/python3.9/site-packages/ucp/core.py", line 725, in recv
    ret = await comm.tag_recv(self._ep, buffer, nbytes, tag, name=log)
ucp._libs.exceptions.UCXCanceled: <[Recv #003] ep: 0x7fb695e101c0, tag: 0x5fbf2af1ec454c0a, nbytes: 16, type: <class 'numpy.ndarray'>>: 

During handling of the above exception, another exception occurred:

Traceback (most recent call last):
  File "/opt/conda/envs/gdf/lib/python3.9/site-packages/distributed/worker.py", line 2066, in gather_dep
    response = await get_data_from_worker(
  File "/opt/conda/envs/gdf/lib/python3.9/site-packages/distributed/worker.py", line 2892, in get_data_from_worker
    response = await send_recv(
  File "/opt/conda/envs/gdf/lib/python3.9/site-packages/distributed/core.py", line 1024, in send_recv
    response = await comm.read(deserializers=deserializers)
  File "/opt/conda/envs/gdf/lib/python3.9/site-packages/distributed/utils.py", line 752, in wrapper
    return await func(*args, **kwargs)
  File "/opt/conda/envs/gdf/lib/python3.9/site-packages/distributed/comm/ucx.py", line 367, in read
    raise CommClosedError(
distributed.comm.core.CommClosedError: Connection closed by writer.
Inner exception: UCXCanceled("<[Recv #003] ep: 0x7fb695e101c0, tag: 0x5fbf2af1ec454c0a, nbytes: 16, type: <class 'numpy.ndarray'>>: ")
2023-04-29 06:12:15,052 - distributed.worker - ERROR - Worker stream died during communication: ucx://127.0.0.1:36759
Traceback (most recent call last):
  File "/opt/conda/envs/gdf/lib/python3.9/site-packages/distributed/comm/ucx.py", line 349, in read
    await self.ep.recv(msg)
  File "/opt/conda/envs/gdf/lib/python3.9/site-packages/ucp/core.py", line 725, in recv
    ret = await comm.tag_recv(self._ep, buffer, nbytes, tag, name=log)
ucp._libs.exceptions.UCXCanceled: <[Recv #003] ep: 0x7fb695e10180, tag: 0x140f1095b7b2148, nbytes: 16, type: <class 'numpy.ndarray'>>: 

During handling of the above exception, another exception occurred:

Traceback (most recent call last):
  File "/opt/conda/envs/gdf/lib/python3.9/site-packages/distributed/worker.py", line 2066, in gather_dep
    response = await get_data_from_worker(
  File "/opt/conda/envs/gdf/lib/python3.9/site-packages/distributed/worker.py", line 2892, in get_data_from_worker
    response = await send_recv(
  File "/opt/conda/envs/gdf/lib/python3.9/site-packages/distributed/core.py", line 1024, in send_recv
    response = await comm.read(deserializers=deserializers)
  File "/opt/conda/envs/gdf/lib/python3.9/site-packages/distributed/utils.py", line 752, in wrapper
    return await func(*args, **kwargs)
  File "/opt/conda/envs/gdf/lib/python3.9/site-packages/distributed/comm/ucx.py", line 367, in read
    raise CommClosedError(
distributed.comm.core.CommClosedError: Connection closed by writer.
Inner exception: UCXCanceled("<[Recv #003] ep: 0x7fb695e10180, tag: 0x140f1095b7b2148, nbytes: 16, type: <class 'numpy.ndarray'>>: ")
2023-04-29 06:12:15,062 - distributed.nanny - WARNING - Restarting worker
2023-04-29 06:12:15,164 - distributed.nanny - WARNING - Restarting worker
2023-04-29 06:12:15,166 - distributed.nanny - WARNING - Restarting worker
2023-04-29 06:12:15,167 - distributed.worker - ERROR - Worker stream died during communication: ucx://127.0.0.1:39515
Traceback (most recent call last):
  File "/opt/conda/envs/gdf/lib/python3.9/site-packages/distributed/comm/ucx.py", line 391, in read
    await self.ep.recv(each_frame)
  File "/opt/conda/envs/gdf/lib/python3.9/site-packages/ucp/core.py", line 725, in recv
    ret = await comm.tag_recv(self._ep, buffer, nbytes, tag, name=log)
ucp._libs.exceptions.UCXError: <[Recv #007] ep: 0x7faad744f1c0, tag: 0x57132227913e2be6, nbytes: 50000000, type: <class 'rmm._lib.device_buffer.DeviceBuffer'>>: Connection reset by remote peer

During handling of the above exception, another exception occurred:

Traceback (most recent call last):
  File "/opt/conda/envs/gdf/lib/python3.9/site-packages/distributed/worker.py", line 2066, in gather_dep
    response = await get_data_from_worker(
  File "/opt/conda/envs/gdf/lib/python3.9/site-packages/distributed/worker.py", line 2892, in get_data_from_worker
    response = await send_recv(
  File "/opt/conda/envs/gdf/lib/python3.9/site-packages/distributed/core.py", line 1024, in send_recv
    response = await comm.read(deserializers=deserializers)
  File "/opt/conda/envs/gdf/lib/python3.9/site-packages/distributed/utils.py", line 752, in wrapper
    return await func(*args, **kwargs)
  File "/opt/conda/envs/gdf/lib/python3.9/site-packages/distributed/comm/ucx.py", line 397, in read
    raise CommClosedError(
distributed.comm.core.CommClosedError: Connection closed by writer.
Inner exception: UCXError("<[Recv #007] ep: 0x7faad744f1c0, tag: 0x57132227913e2be6, nbytes: 50000000, type: <class 'rmm._lib.device_buffer.DeviceBuffer'>>: Connection reset by remote peer")
2023-04-29 06:12:15,167 - distributed.worker - ERROR - Worker stream died during communication: ucx://127.0.0.1:39515
Traceback (most recent call last):
  File "/opt/conda/envs/gdf/lib/python3.9/site-packages/distributed/comm/ucx.py", line 349, in read
    await self.ep.recv(msg)
  File "/opt/conda/envs/gdf/lib/python3.9/site-packages/ucp/core.py", line 725, in recv
    ret = await comm.tag_recv(self._ep, buffer, nbytes, tag, name=log)
ucp._libs.exceptions.UCXCanceled: <[Recv #003] ep: 0x7fb695e10140, tag: 0xd728579369b34115, nbytes: 16, type: <class 'numpy.ndarray'>>: 

During handling of the above exception, another exception occurred:

Traceback (most recent call last):
  File "/opt/conda/envs/gdf/lib/python3.9/site-packages/distributed/worker.py", line 2066, in gather_dep
    response = await get_data_from_worker(
  File "/opt/conda/envs/gdf/lib/python3.9/site-packages/distributed/worker.py", line 2892, in get_data_from_worker
    response = await send_recv(
  File "/opt/conda/envs/gdf/lib/python3.9/site-packages/distributed/core.py", line 1024, in send_recv
    response = await comm.read(deserializers=deserializers)
  File "/opt/conda/envs/gdf/lib/python3.9/site-packages/distributed/utils.py", line 752, in wrapper
    return await func(*args, **kwargs)
  File "/opt/conda/envs/gdf/lib/python3.9/site-packages/distributed/comm/ucx.py", line 367, in read
    raise CommClosedError(
distributed.comm.core.CommClosedError: Connection closed by writer.
Inner exception: UCXCanceled("<[Recv #003] ep: 0x7fb695e10140, tag: 0xd728579369b34115, nbytes: 16, type: <class 'numpy.ndarray'>>: ")
2023-04-29 06:12:15,167 - distributed.worker - ERROR - failed during get data with ucx://127.0.0.1:44545 -> ucx://127.0.0.1:39515
Traceback (most recent call last):
  File "/opt/conda/envs/gdf/lib/python3.9/site-packages/distributed/comm/ucx.py", line 333, in write
    await self.ep.send(each_frame)
  File "/opt/conda/envs/gdf/lib/python3.9/site-packages/ucp/core.py", line 650, in send
    return await comm.tag_send(self._ep, buffer, nbytes, tag, name=log)
ucp._libs.exceptions.UCXError: <[Send #007] ep: 0x7fb371dee280, tag: 0x1fa6904d0f32ca3, nbytes: 50000000, type: <class 'cupy.ndarray'>>: Connection reset by remote peer

During handling of the above exception, another exception occurred:

Traceback (most recent call last):
  File "/opt/conda/envs/gdf/lib/python3.9/site-packages/distributed/worker.py", line 1792, in get_data
    compressed = await comm.write(msg, serializers=serializers)
  File "/opt/conda/envs/gdf/lib/python3.9/site-packages/distributed/utils.py", line 752, in wrapper
    return await func(*args, **kwargs)
  File "/opt/conda/envs/gdf/lib/python3.9/site-packages/distributed/comm/ucx.py", line 337, in write
    raise CommClosedError("While writing, the connection was closed")
distributed.comm.core.CommClosedError: While writing, the connection was closed
2023-04-29 06:12:15,167 - distributed.worker - ERROR - Worker stream died during communication: ucx://127.0.0.1:39515
Traceback (most recent call last):
  File "/opt/conda/envs/gdf/lib/python3.9/site-packages/distributed/comm/ucx.py", line 349, in read
    await self.ep.recv(msg)
  File "/opt/conda/envs/gdf/lib/python3.9/site-packages/ucp/core.py", line 725, in recv
    ret = await comm.tag_recv(self._ep, buffer, nbytes, tag, name=log)
ucp._libs.exceptions.UCXCanceled: <[Recv #003] ep: 0x7f35d42ea180, tag: 0x2216c90f62f63d8d, nbytes: 16, type: <class 'numpy.ndarray'>>: 

During handling of the above exception, another exception occurred:

Traceback (most recent call last):
  File "/opt/conda/envs/gdf/lib/python3.9/site-packages/distributed/worker.py", line 2066, in gather_dep
    response = await get_data_from_worker(
  File "/opt/conda/envs/gdf/lib/python3.9/site-packages/distributed/worker.py", line 2892, in get_data_from_worker
    response = await send_recv(
  File "/opt/conda/envs/gdf/lib/python3.9/site-packages/distributed/core.py", line 1024, in send_recv
    response = await comm.read(deserializers=deserializers)
  File "/opt/conda/envs/gdf/lib/python3.9/site-packages/distributed/utils.py", line 752, in wrapper
    return await func(*args, **kwargs)
  File "/opt/conda/envs/gdf/lib/python3.9/site-packages/distributed/comm/ucx.py", line 367, in read
    raise CommClosedError(
distributed.comm.core.CommClosedError: Connection closed by writer.
Inner exception: UCXCanceled("<[Recv #003] ep: 0x7f35d42ea180, tag: 0x2216c90f62f63d8d, nbytes: 16, type: <class 'numpy.ndarray'>>: ")
2023-04-29 06:12:15,168 - distributed.worker - ERROR - Worker stream died during communication: ucx://127.0.0.1:39515
Traceback (most recent call last):
  File "/opt/conda/envs/gdf/lib/python3.9/site-packages/distributed/comm/ucx.py", line 349, in read
    await self.ep.recv(msg)
  File "/opt/conda/envs/gdf/lib/python3.9/site-packages/ucp/core.py", line 725, in recv
    ret = await comm.tag_recv(self._ep, buffer, nbytes, tag, name=log)
ucp._libs.exceptions.UCXCanceled: <[Recv #003] ep: 0x7fb371dee1c0, tag: 0xc7c2356c94683ea1, nbytes: 16, type: <class 'numpy.ndarray'>>: 

During handling of the above exception, another exception occurred:

Traceback (most recent call last):
  File "/opt/conda/envs/gdf/lib/python3.9/site-packages/distributed/worker.py", line 2066, in gather_dep
    response = await get_data_from_worker(
  File "/opt/conda/envs/gdf/lib/python3.9/site-packages/distributed/worker.py", line 2892, in get_data_from_worker
    response = await send_recv(
  File "/opt/conda/envs/gdf/lib/python3.9/site-packages/distributed/core.py", line 1024, in send_recv
    response = await comm.read(deserializers=deserializers)
  File "/opt/conda/envs/gdf/lib/python3.9/site-packages/distributed/utils.py", line 752, in wrapper
    return await func(*args, **kwargs)
  File "/opt/conda/envs/gdf/lib/python3.9/site-packages/distributed/comm/ucx.py", line 367, in read
    raise CommClosedError(
distributed.comm.core.CommClosedError: Connection closed by writer.
Inner exception: UCXCanceled("<[Recv #003] ep: 0x7fb371dee1c0, tag: 0xc7c2356c94683ea1, nbytes: 16, type: <class 'numpy.ndarray'>>: ")
2023-04-29 06:12:15,224 - distributed.nanny - WARNING - Restarting worker
2023-04-29 06:12:16,593 - distributed.preloading - INFO - Creating preload: dask_cuda.initialize
2023-04-29 06:12:16,593 - distributed.preloading - INFO - Import preload module: dask_cuda.initialize
2023-04-29 06:12:16,645 - distributed.preloading - INFO - Creating preload: dask_cuda.initialize
2023-04-29 06:12:16,645 - distributed.preloading - INFO - Import preload module: dask_cuda.initialize
2023-04-29 06:12:16,702 - distributed.preloading - INFO - Creating preload: dask_cuda.initialize
2023-04-29 06:12:16,702 - distributed.preloading - INFO - Import preload module: dask_cuda.initialize
2023-04-29 06:12:16,799 - distributed.preloading - INFO - Creating preload: dask_cuda.initialize
2023-04-29 06:12:16,799 - distributed.preloading - INFO - Import preload module: dask_cuda.initialize
[dgx13:1307 :0:1307] Caught signal 11 (Segmentation fault: address not mapped to object at address 0x448)
==== backtrace (tid:   1307) ====
 0  /opt/conda/envs/gdf/lib/libucs.so.0(ucs_handle_error+0x2dc) [0x7f1161df5dec]
 1  /opt/conda/envs/gdf/lib/libucs.so.0(+0x31fcf) [0x7f1161df5fcf]
 2  /opt/conda/envs/gdf/lib/libucs.so.0(+0x32304) [0x7f1161df6304]
 3  /usr/lib/x86_64-linux-gnu/libpthread.so.0(+0x14420) [0x7f12030e9420]
 4  /opt/conda/envs/gdf/lib/libucp.so.0(ucp_mem_type_unpack+0x18) [0x7f1161e85838]
 5  /opt/conda/envs/gdf/lib/libucp.so.0(ucp_rndv_data_handler+0x508) [0x7f1161eba0d8]
 6  /opt/conda/envs/gdf/lib/libuct.so.0(+0x23457) [0x7f1161da5457]
 7  /opt/conda/envs/gdf/lib/libuct.so.0(+0x23a38) [0x7f1161da5a38]
 8  /opt/conda/envs/gdf/lib/libuct.so.0(+0x260fc) [0x7f1161da80fc]
 9  /opt/conda/envs/gdf/lib/libucs.so.0(ucs_event_set_wait+0xf9) [0x7f1161e014d9]
10  /opt/conda/envs/gdf/lib/libuct.so.0(uct_tcp_iface_progress+0x7b) [0x7f1161da81ab]
11  /opt/conda/envs/gdf/lib/libucp.so.0(ucp_worker_progress+0x6a) [0x7f1161e81caa]
12  /opt/conda/envs/gdf/lib/python3.9/site-packages/ucp/_libs/ucx_api.cpython-39-x86_64-linux-gnu.so(+0x286e1) [0x7f1161f446e1]
13  /opt/conda/envs/gdf/bin/python(+0x13eb08) [0x55c955222b08]
14  /opt/conda/envs/gdf/bin/python(_PyEval_EvalFrameDefault+0x5f82) [0x55c955213112]
15  /opt/conda/envs/gdf/bin/python(+0x12827a) [0x55c95520c27a]
16  /opt/conda/envs/gdf/bin/python(_PyFunction_Vectorcall+0xd5) [0x55c95521dc05]
17  /opt/conda/envs/gdf/bin/python(_PyEval_EvalFrameDefault+0x68b) [0x55c95520d81b]
18  /opt/conda/envs/gdf/bin/python(+0x14e70e) [0x55c95523270e]
19  /opt/conda/envs/gdf/lib/python3.9/lib-dynload/_asyncio.cpython-39-x86_64-linux-gnu.so(+0x82fe) [0x7f11829892fe]
20  /opt/conda/envs/gdf/bin/python(_PyObject_MakeTpCall+0x2fc) [0x55c9552162bc]
21  /opt/conda/envs/gdf/bin/python(+0xe5817) [0x55c9551c9817]
22  /opt/conda/envs/gdf/bin/python(+0x130f83) [0x55c955214f83]
23  /opt/conda/envs/gdf/bin/python(_PyEval_EvalFrameDefault+0x5ba6) [0x55c955212d36]
24  /opt/conda/envs/gdf/bin/python(+0x139ef3) [0x55c95521def3]
25  /opt/conda/envs/gdf/bin/python(_PyEval_EvalFrameDefault+0x68b) [0x55c95520d81b]
26  /opt/conda/envs/gdf/bin/python(+0x139ef3) [0x55c95521def3]
27  /opt/conda/envs/gdf/bin/python(_PyEval_EvalFrameDefault+0x68b) [0x55c95520d81b]
28  /opt/conda/envs/gdf/bin/python(+0x139ef3) [0x55c95521def3]
29  /opt/conda/envs/gdf/bin/python(_PyEval_EvalFrameDefault+0x68b) [0x55c95520d81b]
30  /opt/conda/envs/gdf/bin/python(+0x139ef3) [0x55c95521def3]
31  /opt/conda/envs/gdf/bin/python(_PyEval_EvalFrameDefault+0x68b) [0x55c95520d81b]
32  /opt/conda/envs/gdf/bin/python(+0x12827a) [0x55c95520c27a]
33  /opt/conda/envs/gdf/bin/python(_PyFunction_Vectorcall+0xd5) [0x55c95521dc05]
34  /opt/conda/envs/gdf/bin/python(_PyEval_EvalFrameDefault+0x4e17) [0x55c955211fa7]
35  /opt/conda/envs/gdf/bin/python(+0x12827a) [0x55c95520c27a]
36  /opt/conda/envs/gdf/bin/python(+0x147935) [0x55c95522b935]
37  /opt/conda/envs/gdf/bin/python(PyObject_Call+0xb4) [0x55c95522c104]
38  /opt/conda/envs/gdf/bin/python(+0x20efc8) [0x55c9552f2fc8]
39  /opt/conda/envs/gdf/bin/python(_PyObject_MakeTpCall+0x2fc) [0x55c9552162bc]
40  /opt/conda/envs/gdf/bin/python(_PyEval_EvalFrameDefault+0x402b) [0x55c9552111bb]
41  /opt/conda/envs/gdf/bin/python(+0x139ef3) [0x55c95521def3]
42  /opt/conda/envs/gdf/bin/python(+0x147c72) [0x55c95522bc72]
43  /opt/conda/envs/gdf/bin/python(_PyEval_EvalFrameDefault+0x402b) [0x55c9552111bb]
44  /opt/conda/envs/gdf/bin/python(+0x139ef3) [0x55c95521def3]
45  /opt/conda/envs/gdf/bin/python(_PyEval_EvalFrameDefault+0x68b) [0x55c95520d81b]
46  /opt/conda/envs/gdf/bin/python(+0x12827a) [0x55c95520c27a]
47  /opt/conda/envs/gdf/bin/python(_PyFunction_Vectorcall+0xd5) [0x55c95521dc05]
48  /opt/conda/envs/gdf/bin/python(_PyEval_EvalFrameDefault+0x68b) [0x55c95520d81b]
49  /opt/conda/envs/gdf/bin/python(+0x139ef3) [0x55c95521def3]
50  /opt/conda/envs/gdf/bin/python(_PyEval_EvalFrameDefault+0x3d8) [0x55c95520d568]
51  /opt/conda/envs/gdf/bin/python(+0x12827a) [0x55c95520c27a]
52  /opt/conda/envs/gdf/bin/python(_PyFunction_Vectorcall+0xd5) [0x55c95521dc05]
53  /opt/conda/envs/gdf/bin/python(_PyEval_EvalFrameDefault+0x123b) [0x55c95520e3cb]
54  /opt/conda/envs/gdf/bin/python(+0x12827a) [0x55c95520c27a]
55  /opt/conda/envs/gdf/bin/python(_PyEval_EvalCodeWithName+0x47) [0x55c95520bf07]
56  /opt/conda/envs/gdf/bin/python(PyEval_EvalCodeEx+0x39) [0x55c95520beb9]
57  /opt/conda/envs/gdf/bin/python(PyEval_EvalCode+0x1b) [0x55c9552bc8bb]
58  /opt/conda/envs/gdf/bin/python(+0x206adc) [0x55c9552eaadc]
59  /opt/conda/envs/gdf/bin/python(+0x202c24) [0x55c9552e6c24]
60  /opt/conda/envs/gdf/bin/python(PyRun_StringFlags+0x9d) [0x55c9552de7ed]
61  /opt/conda/envs/gdf/bin/python(PyRun_SimpleStringFlags+0x3d) [0x55c9552de6bd]
=================================
[dgx13:1304 :0:1304] Caught signal 11 (Segmentation fault: address not mapped to object at address 0x448)
==== backtrace (tid:   1304) ====
 0  /opt/conda/envs/gdf/lib/libucs.so.0(ucs_handle_error+0x2dc) [0x7f17a73cbdec]
 1  /opt/conda/envs/gdf/lib/libucs.so.0(+0x31fcf) [0x7f17a73cbfcf]
 2  /opt/conda/envs/gdf/lib/libucs.so.0(+0x32304) [0x7f17a73cc304]
 3  /usr/lib/x86_64-linux-gnu/libpthread.so.0(+0x14420) [0x7f184a6c2420]
 4  /opt/conda/envs/gdf/lib/libucp.so.0(ucp_mem_type_unpack+0x18) [0x7f17a745b838]
 5  /opt/conda/envs/gdf/lib/libucp.so.0(ucp_rndv_data_handler+0x508) [0x7f17a74900d8]
 6  /opt/conda/envs/gdf/lib/libuct.so.0(+0x23457) [0x7f17a737b457]
 7  /opt/conda/envs/gdf/lib/libuct.so.0(+0x23a38) [0x7f17a737ba38]
 8  /opt/conda/envs/gdf/lib/libuct.so.0(+0x260fc) [0x7f17a737e0fc]
 9  /opt/conda/envs/gdf/lib/libucs.so.0(ucs_event_set_wait+0xf9) [0x7f17a73d74d9]
10  /opt/conda/envs/gdf/lib/libuct.so.0(uct_tcp_iface_progress+0x7b) [0x7f17a737e1ab]
11  /opt/conda/envs/gdf/lib/libucp.so.0(ucp_worker_progress+0x6a) [0x7f17a7457caa]
12  /opt/conda/envs/gdf/lib/python3.9/site-packages/ucp/_libs/ucx_api.cpython-39-x86_64-linux-gnu.so(+0x286e1) [0x7f17a751a6e1]
13  /opt/conda/envs/gdf/bin/python(+0x13eb08) [0x5630536bfb08]
14  /opt/conda/envs/gdf/bin/python(_PyEval_EvalFrameDefault+0x5f82) [0x5630536b0112]
15  /opt/conda/envs/gdf/bin/python(+0x12827a) [0x5630536a927a]
16  /opt/conda/envs/gdf/bin/python(_PyFunction_Vectorcall+0xd5) [0x5630536bac05]
17  /opt/conda/envs/gdf/bin/python(_PyEval_EvalFrameDefault+0x68b) [0x5630536aa81b]
18  /opt/conda/envs/gdf/bin/python(+0x139ef3) [0x5630536baef3]
19  /opt/conda/envs/gdf/bin/python(+0x147a16) [0x5630536c8a16]
20  /opt/conda/envs/gdf/bin/python(+0x2579b1) [0x5630537d89b1]
21  /opt/conda/envs/gdf/bin/python(+0xe5817) [0x563053666817]
22  /opt/conda/envs/gdf/bin/python(+0x130f83) [0x5630536b1f83]
23  /opt/conda/envs/gdf/bin/python(_PyEval_EvalFrameDefault+0x5ba6) [0x5630536afd36]
24  /opt/conda/envs/gdf/bin/python(+0x139ef3) [0x5630536baef3]
25  /opt/conda/envs/gdf/bin/python(_PyEval_EvalFrameDefault+0x68b) [0x5630536aa81b]
26  /opt/conda/envs/gdf/bin/python(+0x139ef3) [0x5630536baef3]
27  /opt/conda/envs/gdf/bin/python(_PyEval_EvalFrameDefault+0x68b) [0x5630536aa81b]
28  /opt/conda/envs/gdf/bin/python(+0x139ef3) [0x5630536baef3]
29  /opt/conda/envs/gdf/bin/python(_PyEval_EvalFrameDefault+0x68b) [0x5630536aa81b]
30  /opt/conda/envs/gdf/bin/python(+0x139ef3) [0x5630536baef3]
31  /opt/conda/envs/gdf/bin/python(_PyEval_EvalFrameDefault+0x68b) [0x5630536aa81b]
32  /opt/conda/envs/gdf/bin/python(+0x12827a) [0x5630536a927a]
33  /opt/conda/envs/gdf/bin/python(_PyFunction_Vectorcall+0xd5) [0x5630536bac05]
34  /opt/conda/envs/gdf/bin/python(_PyEval_EvalFrameDefault+0x4e17) [0x5630536aefa7]
35  /opt/conda/envs/gdf/bin/python(+0x12827a) [0x5630536a927a]
36  /opt/conda/envs/gdf/bin/python(+0x147935) [0x5630536c8935]
37  /opt/conda/envs/gdf/bin/python(PyObject_Call+0xb4) [0x5630536c9104]
38  /opt/conda/envs/gdf/bin/python(+0x20efc8) [0x56305378ffc8]
39  /opt/conda/envs/gdf/bin/python(_PyObject_MakeTpCall+0x2fc) [0x5630536b32bc]
40  /opt/conda/envs/gdf/bin/python(_PyEval_EvalFrameDefault+0x402b) [0x5630536ae1bb]
41  /opt/conda/envs/gdf/bin/python(+0x139ef3) [0x5630536baef3]
42  /opt/conda/envs/gdf/bin/python(+0x147c72) [0x5630536c8c72]
43  /opt/conda/envs/gdf/bin/python(_PyEval_EvalFrameDefault+0x402b) [0x5630536ae1bb]
44  /opt/conda/envs/gdf/bin/python(+0x139ef3) [0x5630536baef3]
45  /opt/conda/envs/gdf/bin/python(_PyEval_EvalFrameDefault+0x68b) [0x5630536aa81b]
46  /opt/conda/envs/gdf/bin/python(+0x12827a) [0x5630536a927a]
47  /opt/conda/envs/gdf/bin/python(_PyFunction_Vectorcall+0xd5) [0x5630536bac05]
48  /opt/conda/envs/gdf/bin/python(_PyEval_EvalFrameDefault+0x68b) [0x5630536aa81b]
49  /opt/conda/envs/gdf/bin/python(+0x139ef3) [0x5630536baef3]
50  /opt/conda/envs/gdf/bin/python(_PyEval_EvalFrameDefault+0x3d8) [0x5630536aa568]
51  /opt/conda/envs/gdf/bin/python(+0x12827a) [0x5630536a927a]
52  /opt/conda/envs/gdf/bin/python(_PyFunction_Vectorcall+0xd5) [0x5630536bac05]
53  /opt/conda/envs/gdf/bin/python(_PyEval_EvalFrameDefault+0x123b) [0x5630536ab3cb]
54  /opt/conda/envs/gdf/bin/python(+0x12827a) [0x5630536a927a]
55  /opt/conda/envs/gdf/bin/python(_PyEval_EvalCodeWithName+0x47) [0x5630536a8f07]
56  /opt/conda/envs/gdf/bin/python(PyEval_EvalCodeEx+0x39) [0x5630536a8eb9]
57  /opt/conda/envs/gdf/bin/python(PyEval_EvalCode+0x1b) [0x5630537598bb]
58  /opt/conda/envs/gdf/bin/python(+0x206adc) [0x563053787adc]
59  /opt/conda/envs/gdf/bin/python(+0x202c24) [0x563053783c24]
60  /opt/conda/envs/gdf/bin/python(PyRun_StringFlags+0x9d) [0x56305377b7ed]
61  /opt/conda/envs/gdf/bin/python(PyRun_SimpleStringFlags+0x3d) [0x56305377b6bd]
=================================
[dgx13:1298 :0:1298] Caught signal 11 (Segmentation fault: address not mapped to object at address 0x448)
==== backtrace (tid:   1298) ====
 0  /opt/conda/envs/gdf/lib/libucs.so.0(ucs_handle_error+0x2dc) [0x7fcfc907bdec]
 1  /opt/conda/envs/gdf/lib/libucs.so.0(+0x31fcf) [0x7fcfc907bfcf]
 2  /opt/conda/envs/gdf/lib/libucs.so.0(+0x32304) [0x7fcfc907c304]
 3  /usr/lib/x86_64-linux-gnu/libpthread.so.0(+0x14420) [0x7fd068366420]
 4  /opt/conda/envs/gdf/lib/libucp.so.0(ucp_mem_type_unpack+0x18) [0x7fcfc910b838]
 5  /opt/conda/envs/gdf/lib/libucp.so.0(ucp_rndv_data_handler+0x508) [0x7fcfc91400d8]
 6  /opt/conda/envs/gdf/lib/libuct.so.0(+0x23457) [0x7fcfc902b457]
 7  /opt/conda/envs/gdf/lib/libuct.so.0(+0x23a38) [0x7fcfc902ba38]
 8  /opt/conda/envs/gdf/lib/libuct.so.0(+0x260fc) [0x7fcfc902e0fc]
 9  /opt/conda/envs/gdf/lib/libucs.so.0(ucs_event_set_wait+0xf9) [0x7fcfc90874d9]
10  /opt/conda/envs/gdf/lib/libuct.so.0(uct_tcp_iface_progress+0x7b) [0x7fcfc902e1ab]
11  /opt/conda/envs/gdf/lib/libucp.so.0(ucp_worker_progress+0x6a) [0x7fcfc9107caa]
12  /opt/conda/envs/gdf/lib/python3.9/site-packages/ucp/_libs/ucx_api.cpython-39-x86_64-linux-gnu.so(+0x286e1) [0x7fcfc91ca6e1]
13  /opt/conda/envs/gdf/bin/python(+0x13eb08) [0x55caa433bb08]
14  /opt/conda/envs/gdf/bin/python(_PyEval_EvalFrameDefault+0x5f82) [0x55caa432c112]
15  /opt/conda/envs/gdf/bin/python(+0x12827a) [0x55caa432527a]
16  /opt/conda/envs/gdf/bin/python(_PyFunction_Vectorcall+0xd5) [0x55caa4336c05]
17  /opt/conda/envs/gdf/bin/python(_PyEval_EvalFrameDefault+0x68b) [0x55caa432681b]
18  /opt/conda/envs/gdf/bin/python(+0x139ef3) [0x55caa4336ef3]
19  /opt/conda/envs/gdf/bin/python(+0x147a16) [0x55caa4344a16]
20  /opt/conda/envs/gdf/bin/python(+0x2579b1) [0x55caa44549b1]
21  /opt/conda/envs/gdf/bin/python(+0xe5817) [0x55caa42e2817]
22  /opt/conda/envs/gdf/bin/python(+0x130f83) [0x55caa432df83]
23  /opt/conda/envs/gdf/bin/python(_PyEval_EvalFrameDefault+0x5ba6) [0x55caa432bd36]
24  /opt/conda/envs/gdf/bin/python(+0x139ef3) [0x55caa4336ef3]
25  /opt/conda/envs/gdf/bin/python(_PyEval_EvalFrameDefault+0x68b) [0x55caa432681b]
26  /opt/conda/envs/gdf/bin/python(+0x139ef3) [0x55caa4336ef3]
27  /opt/conda/envs/gdf/bin/python(_PyEval_EvalFrameDefault+0x68b) [0x55caa432681b]
28  /opt/conda/envs/gdf/bin/python(+0x139ef3) [0x55caa4336ef3]
29  /opt/conda/envs/gdf/bin/python(_PyEval_EvalFrameDefault+0x68b) [0x55caa432681b]
30  /opt/conda/envs/gdf/bin/python(+0x139ef3) [0x55caa4336ef3]
31  /opt/conda/envs/gdf/bin/python(_PyEval_EvalFrameDefault+0x68b) [0x55caa432681b]
32  /opt/conda/envs/gdf/bin/python(+0x12827a) [0x55caa432527a]
33  /opt/conda/envs/gdf/bin/python(_PyFunction_Vectorcall+0xd5) [0x55caa4336c05]
34  /opt/conda/envs/gdf/bin/python(_PyEval_EvalFrameDefault+0x4e17) [0x55caa432afa7]
35  /opt/conda/envs/gdf/bin/python(+0x12827a) [0x55caa432527a]
36  /opt/conda/envs/gdf/bin/python(+0x147935) [0x55caa4344935]
37  /opt/conda/envs/gdf/bin/python(PyObject_Call+0xb4) [0x55caa4345104]
38  /opt/conda/envs/gdf/bin/python(+0x20efc8) [0x55caa440bfc8]
39  /opt/conda/envs/gdf/bin/python(_PyObject_MakeTpCall+0x2fc) [0x55caa432f2bc]
40  /opt/conda/envs/gdf/bin/python(_PyEval_EvalFrameDefault+0x402b) [0x55caa432a1bb]
41  /opt/conda/envs/gdf/bin/python(+0x139ef3) [0x55caa4336ef3]
42  /opt/conda/envs/gdf/bin/python(+0x147c72) [0x55caa4344c72]
43  /opt/conda/envs/gdf/bin/python(_PyEval_EvalFrameDefault+0x402b) [0x55caa432a1bb]
44  /opt/conda/envs/gdf/bin/python(+0x139ef3) [0x55caa4336ef3]
45  /opt/conda/envs/gdf/bin/python(_PyEval_EvalFrameDefault+0x68b) [0x55caa432681b]
46  /opt/conda/envs/gdf/bin/python(+0x12827a) [0x55caa432527a]
47  /opt/conda/envs/gdf/bin/python(_PyFunction_Vectorcall+0xd5) [0x55caa4336c05]
48  /opt/conda/envs/gdf/bin/python(_PyEval_EvalFrameDefault+0x68b) [0x55caa432681b]
49  /opt/conda/envs/gdf/bin/python(+0x139ef3) [0x55caa4336ef3]
50  /opt/conda/envs/gdf/bin/python(_PyEval_EvalFrameDefault+0x3d8) [0x55caa4326568]
51  /opt/conda/envs/gdf/bin/python(+0x12827a) [0x55caa432527a]
52  /opt/conda/envs/gdf/bin/python(_PyFunction_Vectorcall+0xd5) [0x55caa4336c05]
53  /opt/conda/envs/gdf/bin/python(_PyEval_EvalFrameDefault+0x123b) [0x55caa43273cb]
54  /opt/conda/envs/gdf/bin/python(+0x12827a) [0x55caa432527a]
55  /opt/conda/envs/gdf/bin/python(_PyEval_EvalCodeWithName+0x47) [0x55caa4324f07]
56  /opt/conda/envs/gdf/bin/python(PyEval_EvalCodeEx+0x39) [0x55caa4324eb9]
57  /opt/conda/envs/gdf/bin/python(PyEval_EvalCode+0x1b) [0x55caa43d58bb]
58  /opt/conda/envs/gdf/bin/python(+0x206adc) [0x55caa4403adc]
59  /opt/conda/envs/gdf/bin/python(+0x202c24) [0x55caa43ffc24]
60  /opt/conda/envs/gdf/bin/python(PyRun_StringFlags+0x9d) [0x55caa43f77ed]
61  /opt/conda/envs/gdf/bin/python(PyRun_SimpleStringFlags+0x3d) [0x55caa43f76bd]
=================================
2023-04-29 06:12:18,124 - distributed.worker - ERROR - failed during get data with ucx://127.0.0.1:59131 -> ucx://127.0.0.1:56451
Traceback (most recent call last):
  File "/opt/conda/envs/gdf/lib/python3.9/site-packages/distributed/comm/ucx.py", line 333, in write
    await self.ep.send(each_frame)
  File "/opt/conda/envs/gdf/lib/python3.9/site-packages/ucp/core.py", line 650, in send
    return await comm.tag_send(self._ep, buffer, nbytes, tag, name=log)
ucp._libs.exceptions.UCXError: <[Send #007] ep: 0x7faad744f140, tag: 0x475a2ea7f05b05ba, nbytes: 50000000, type: <class 'cupy.ndarray'>>: Connection reset by remote peer

During handling of the above exception, another exception occurred:

Traceback (most recent call last):
  File "/opt/conda/envs/gdf/lib/python3.9/site-packages/distributed/worker.py", line 1792, in get_data
    compressed = await comm.write(msg, serializers=serializers)
  File "/opt/conda/envs/gdf/lib/python3.9/site-packages/distributed/utils.py", line 752, in wrapper
    return await func(*args, **kwargs)
  File "/opt/conda/envs/gdf/lib/python3.9/site-packages/distributed/comm/ucx.py", line 337, in write
    raise CommClosedError("While writing, the connection was closed")
distributed.comm.core.CommClosedError: While writing, the connection was closed
2023-04-29 06:12:18,138 - distributed.worker - ERROR - failed during get data with ucx://127.0.0.1:52227 -> ucx://127.0.0.1:56451
Traceback (most recent call last):
  File "/opt/conda/envs/gdf/lib/python3.9/site-packages/distributed/comm/ucx.py", line 349, in read
    await self.ep.recv(msg)
  File "/opt/conda/envs/gdf/lib/python3.9/site-packages/ucp/core.py", line 725, in recv
    ret = await comm.tag_recv(self._ep, buffer, nbytes, tag, name=log)
ucp._libs.exceptions.UCXCanceled: <[Recv #006] ep: 0x7fb695e101c0, tag: 0x5c2ebe37e785e471, nbytes: 16, type: <class 'numpy.ndarray'>>: 

During handling of the above exception, another exception occurred:

Traceback (most recent call last):
  File "/opt/conda/envs/gdf/lib/python3.9/site-packages/distributed/worker.py", line 1793, in get_data
    response = await comm.read(deserializers=serializers)
  File "/opt/conda/envs/gdf/lib/python3.9/site-packages/distributed/utils.py", line 752, in wrapper
    return await func(*args, **kwargs)
  File "/opt/conda/envs/gdf/lib/python3.9/site-packages/distributed/comm/ucx.py", line 367, in read
    raise CommClosedError(
distributed.comm.core.CommClosedError: Connection closed by writer.
Inner exception: UCXCanceled("<[Recv #006] ep: 0x7fb695e101c0, tag: 0x5c2ebe37e785e471, nbytes: 16, type: <class 'numpy.ndarray'>>: ")
2023-04-29 06:12:18,167 - distributed.nanny - WARNING - Restarting worker
2023-04-29 06:12:18,215 - distributed.worker - ERROR - failed during get data with ucx://127.0.0.1:59131 -> ucx://127.0.0.1:57879
Traceback (most recent call last):
  File "/opt/conda/envs/gdf/lib/python3.9/site-packages/distributed/comm/ucx.py", line 333, in write
    await self.ep.send(each_frame)
  File "/opt/conda/envs/gdf/lib/python3.9/site-packages/ucp/core.py", line 650, in send
    return await comm.tag_send(self._ep, buffer, nbytes, tag, name=log)
ucp._libs.exceptions.UCXError: <[Send #007] ep: 0x7faad744f380, tag: 0x23e7c1bbb6517064, nbytes: 50000000, type: <class 'cupy.ndarray'>>: Connection reset by remote peer

During handling of the above exception, another exception occurred:

Traceback (most recent call last):
  File "/opt/conda/envs/gdf/lib/python3.9/site-packages/distributed/worker.py", line 1792, in get_data
    compressed = await comm.write(msg, serializers=serializers)
  File "/opt/conda/envs/gdf/lib/python3.9/site-packages/distributed/utils.py", line 752, in wrapper
    return await func(*args, **kwargs)
  File "/opt/conda/envs/gdf/lib/python3.9/site-packages/distributed/comm/ucx.py", line 337, in write
    raise CommClosedError("While writing, the connection was closed")
distributed.comm.core.CommClosedError: While writing, the connection was closed
2023-04-29 06:12:18,215 - distributed.worker - ERROR - failed during get data with ucx://127.0.0.1:52227 -> ucx://127.0.0.1:50927
Traceback (most recent call last):
  File "/opt/conda/envs/gdf/lib/python3.9/site-packages/distributed/comm/ucx.py", line 333, in write
    await self.ep.send(each_frame)
  File "/opt/conda/envs/gdf/lib/python3.9/site-packages/ucp/core.py", line 650, in send
    return await comm.tag_send(self._ep, buffer, nbytes, tag, name=log)
ucp._libs.exceptions.UCXError: <[Send #007] ep: 0x7fb695e102c0, tag: 0x13fb170b4a94ecf8, nbytes: 50000000, type: <class 'cupy.ndarray'>>: Connection reset by remote peer

During handling of the above exception, another exception occurred:

Traceback (most recent call last):
  File "/opt/conda/envs/gdf/lib/python3.9/site-packages/distributed/worker.py", line 1792, in get_data
    compressed = await comm.write(msg, serializers=serializers)
  File "/opt/conda/envs/gdf/lib/python3.9/site-packages/distributed/utils.py", line 752, in wrapper
    return await func(*args, **kwargs)
  File "/opt/conda/envs/gdf/lib/python3.9/site-packages/distributed/comm/ucx.py", line 337, in write
    raise CommClosedError("While writing, the connection was closed")
distributed.comm.core.CommClosedError: While writing, the connection was closed
2023-04-29 06:12:18,216 - distributed.worker - ERROR - failed during get data with ucx://127.0.0.1:59131 -> ucx://127.0.0.1:50927
Traceback (most recent call last):
  File "/opt/conda/envs/gdf/lib/python3.9/site-packages/distributed/comm/ucx.py", line 333, in write
    await self.ep.send(each_frame)
  File "/opt/conda/envs/gdf/lib/python3.9/site-packages/ucp/core.py", line 650, in send
    return await comm.tag_send(self._ep, buffer, nbytes, tag, name=log)
ucp._libs.exceptions.UCXError: <[Send #007] ep: 0x7faad744f240, tag: 0x80f6387a3fe3f100, nbytes: 50000000, type: <class 'cupy.ndarray'>>: Connection reset by remote peer

During handling of the above exception, another exception occurred:

Traceback (most recent call last):
  File "/opt/conda/envs/gdf/lib/python3.9/site-packages/distributed/worker.py", line 1792, in get_data
    compressed = await comm.write(msg, serializers=serializers)
  File "/opt/conda/envs/gdf/lib/python3.9/site-packages/distributed/utils.py", line 752, in wrapper
    return await func(*args, **kwargs)
  File "/opt/conda/envs/gdf/lib/python3.9/site-packages/distributed/comm/ucx.py", line 337, in write
    raise CommClosedError("While writing, the connection was closed")
distributed.comm.core.CommClosedError: While writing, the connection was closed
2023-04-29 06:12:18,270 - distributed.nanny - WARNING - Restarting worker
2023-04-29 06:12:18,303 - distributed.nanny - WARNING - Restarting worker
2023-04-29 06:12:19,594 - distributed.preloading - INFO - Creating preload: dask_cuda.initialize
2023-04-29 06:12:19,594 - distributed.preloading - INFO - Import preload module: dask_cuda.initialize
2023-04-29 06:12:19,614 - distributed.preloading - INFO - Creating preload: dask_cuda.initialize
2023-04-29 06:12:19,614 - distributed.preloading - INFO - Import preload module: dask_cuda.initialize
2023-04-29 06:12:19,650 - distributed.preloading - INFO - Creating preload: dask_cuda.initialize
2023-04-29 06:12:19,650 - distributed.preloading - INFO - Import preload module: dask_cuda.initialize
/opt/conda/envs/gdf/lib/python3.9/multiprocessing/resource_tracker.py:216: UserWarning: resource_tracker: There appear to be 48 leaked semaphore objects to clean up at shutdown
  warnings.warn('resource_tracker: There appear to be %d '
