[dgx13:70468:0:70468] Caught signal 11 (Segmentation fault: address not mapped to object at address 0x448)
==== backtrace (tid:  70468) ====
 0  /opt/conda/envs/gdf/lib/libucs.so.0(ucs_handle_error+0x2fd) [0x7fc7430b2f1d]
 1  /opt/conda/envs/gdf/lib/libucs.so.0(+0x29114) [0x7fc7430b3114]
 2  /opt/conda/envs/gdf/lib/libucs.so.0(+0x292da) [0x7fc7430b32da]
 3  /usr/lib/x86_64-linux-gnu/libpthread.so.0(+0x14420) [0x7fc7e378a420]
 4  /opt/conda/envs/gdf/lib/libucp.so.0(ucp_mem_type_unpack+0x14) [0x7fc74312c5d4]
 5  /opt/conda/envs/gdf/lib/libucp.so.0(ucp_rndv_data_handler+0x4e9) [0x7fc743151859]
 6  /opt/conda/envs/gdf/lib/libuct.so.0(+0x2042f) [0x7fc74306e42f]
 7  /opt/conda/envs/gdf/lib/libuct.so.0(+0x23798) [0x7fc743071798]
 8  /opt/conda/envs/gdf/lib/libucs.so.0(ucs_event_set_wait+0xb9) [0x7fc7430bb989]
 9  /opt/conda/envs/gdf/lib/libuct.so.0(uct_tcp_iface_progress+0x7d) [0x7fc74307062d]
10  /opt/conda/envs/gdf/lib/libucp.so.0(ucp_worker_progress+0x5a) [0x7fc743129c4a]
11  /opt/conda/envs/gdf/lib/python3.9/site-packages/ucp/_libs/ucx_api.cpython-39-x86_64-linux-gnu.so(+0x37aaa) [0x7fc7431e0aaa]
12  /opt/conda/envs/gdf/bin/python(_PyEval_EvalFrameDefault+0x45a6) [0x55ac32a123d6]
13  /opt/conda/envs/gdf/bin/python(+0x12df94) [0x55ac32a0cf94]
14  /opt/conda/envs/gdf/bin/python(_PyFunction_Vectorcall+0xd9) [0x55ac32a1e3f9]
15  /opt/conda/envs/gdf/bin/python(_PyEval_EvalFrameDefault+0x696) [0x55ac32a0e4c6]
16  /opt/conda/envs/gdf/bin/python(+0x1e2612) [0x55ac32ac1612]
17  /opt/conda/envs/gdf/lib/python3.9/lib-dynload/_asyncio.cpython-39-x86_64-linux-gnu.so(+0x81e9) [0x7fc76429b1e9]
18  /opt/conda/envs/gdf/bin/python(_PyObject_MakeTpCall+0x2ec) [0x55ac32a1667c]
19  /opt/conda/envs/gdf/bin/python(+0xf248b) [0x55ac329d148b]
20  /opt/conda/envs/gdf/bin/python(+0x1366f3) [0x55ac32a156f3]
21  /opt/conda/envs/gdf/bin/python(_PyEval_EvalFrameDefault+0x58b4) [0x55ac32a136e4]
22  /opt/conda/envs/gdf/bin/python(+0x13f6a2) [0x55ac32a1e6a2]
23  /opt/conda/envs/gdf/bin/python(_PyEval_EvalFrameDefault+0x696) [0x55ac32a0e4c6]
24  /opt/conda/envs/gdf/bin/python(+0x13f6a2) [0x55ac32a1e6a2]
25  /opt/conda/envs/gdf/bin/python(_PyEval_EvalFrameDefault+0x696) [0x55ac32a0e4c6]
26  /opt/conda/envs/gdf/bin/python(+0x13f6a2) [0x55ac32a1e6a2]
27  /opt/conda/envs/gdf/bin/python(_PyEval_EvalFrameDefault+0x696) [0x55ac32a0e4c6]
28  /opt/conda/envs/gdf/bin/python(+0x13f6a2) [0x55ac32a1e6a2]
29  /opt/conda/envs/gdf/bin/python(_PyEval_EvalFrameDefault+0x696) [0x55ac32a0e4c6]
30  /opt/conda/envs/gdf/bin/python(+0x12df94) [0x55ac32a0cf94]
31  /opt/conda/envs/gdf/bin/python(_PyFunction_Vectorcall+0xd9) [0x55ac32a1e3f9]
32  /opt/conda/envs/gdf/bin/python(_PyEval_EvalFrameDefault+0x11f2) [0x55ac32a0f022]
33  /opt/conda/envs/gdf/bin/python(+0x12df94) [0x55ac32a0cf94]
34  /opt/conda/envs/gdf/bin/python(+0x14c88b) [0x55ac32a2b88b]
35  /opt/conda/envs/gdf/bin/python(PyObject_Call+0xbc) [0x55ac32a2c00c]
36  /opt/conda/envs/gdf/bin/python(+0x21073e) [0x55ac32aef73e]
37  /opt/conda/envs/gdf/bin/python(_PyObject_MakeTpCall+0x2ec) [0x55ac32a1667c]
38  /opt/conda/envs/gdf/bin/python(_PyEval_EvalFrameDefault+0x45a6) [0x55ac32a123d6]
39  /opt/conda/envs/gdf/bin/python(+0x13f6a2) [0x55ac32a1e6a2]
40  /opt/conda/envs/gdf/bin/python(+0x14c96c) [0x55ac32a2b96c]
41  /opt/conda/envs/gdf/bin/python(_PyEval_EvalFrameDefault+0x45a6) [0x55ac32a123d6]
42  /opt/conda/envs/gdf/bin/python(+0x13f6a2) [0x55ac32a1e6a2]
43  /opt/conda/envs/gdf/bin/python(_PyEval_EvalFrameDefault+0x696) [0x55ac32a0e4c6]
44  /opt/conda/envs/gdf/bin/python(+0x12df94) [0x55ac32a0cf94]
45  /opt/conda/envs/gdf/bin/python(_PyFunction_Vectorcall+0xd9) [0x55ac32a1e3f9]
46  /opt/conda/envs/gdf/bin/python(_PyEval_EvalFrameDefault+0x696) [0x55ac32a0e4c6]
47  /opt/conda/envs/gdf/bin/python(+0x13f6a2) [0x55ac32a1e6a2]
48  /opt/conda/envs/gdf/bin/python(_PyEval_EvalFrameDefault+0x3e2) [0x55ac32a0e212]
49  /opt/conda/envs/gdf/bin/python(+0x12df94) [0x55ac32a0cf94]
50  /opt/conda/envs/gdf/bin/python(_PyFunction_Vectorcall+0xd9) [0x55ac32a1e3f9]
51  /opt/conda/envs/gdf/bin/python(_PyEval_EvalFrameDefault+0x11f2) [0x55ac32a0f022]
52  /opt/conda/envs/gdf/bin/python(+0x12df94) [0x55ac32a0cf94]
53  /opt/conda/envs/gdf/bin/python(_PyEval_EvalCodeWithName+0x48) [0x55ac32a0cc68]
54  /opt/conda/envs/gdf/bin/python(PyEval_EvalCodeEx+0x39) [0x55ac32a0cc19]
55  /opt/conda/envs/gdf/bin/python(PyEval_EvalCode+0x1b) [0x55ac32aba20b]
56  /opt/conda/envs/gdf/bin/python(+0x2085fa) [0x55ac32ae75fa]
57  /opt/conda/envs/gdf/bin/python(+0x204983) [0x55ac32ae3983]
58  /opt/conda/envs/gdf/bin/python(PyRun_StringFlags+0x9a) [0x55ac32adb79a]
59  /opt/conda/envs/gdf/bin/python(PyRun_SimpleStringFlags+0x3c) [0x55ac32adb68c]
60  /opt/conda/envs/gdf/bin/python(Py_RunMain+0x267) [0x55ac32ada8c7]
61  /opt/conda/envs/gdf/bin/python(Py_BytesMain+0x37) [0x55ac32aae047]
=================================
[dgx13:70460:0:70460] Caught signal 11 (Segmentation fault: address not mapped to object at address 0x448)
==== backtrace (tid:  70460) ====
 0  /opt/conda/envs/gdf/lib/libucs.so.0(ucs_handle_error+0x2fd) [0x7fc091cf1f1d]
 1  /opt/conda/envs/gdf/lib/libucs.so.0(+0x29114) [0x7fc091cf2114]
 2  /opt/conda/envs/gdf/lib/libucs.so.0(+0x292da) [0x7fc091cf22da]
 3  /usr/lib/x86_64-linux-gnu/libpthread.so.0(+0x14420) [0x7fc1363b4420]
 4  /opt/conda/envs/gdf/lib/libucp.so.0(ucp_mem_type_unpack+0x14) [0x7fc091d6b5d4]
 5  /opt/conda/envs/gdf/lib/libucp.so.0(ucp_rndv_data_handler+0x4e9) [0x7fc091d90859]
 6  /opt/conda/envs/gdf/lib/libuct.so.0(+0x2042f) [0x7fc091cad42f]
 7  /opt/conda/envs/gdf/lib/libuct.so.0(+0x23798) [0x7fc091cb0798]
 8  /opt/conda/envs/gdf/lib/libucs.so.0(ucs_event_set_wait+0xb9) [0x7fc091cfa989]
 9  /opt/conda/envs/gdf/lib/libuct.so.0(uct_tcp_iface_progress+0x7d) [0x7fc091caf62d]
10  /opt/conda/envs/gdf/lib/libucp.so.0(ucp_worker_progress+0x5a) [0x7fc091d68c4a]
11  /opt/conda/envs/gdf/lib/python3.9/site-packages/ucp/_libs/ucx_api.cpython-39-x86_64-linux-gnu.so(+0x37aaa) [0x7fc091e1faaa]
12  /opt/conda/envs/gdf/bin/python(_PyEval_EvalFrameDefault+0x45a6) [0x55809df713d6]
13  /opt/conda/envs/gdf/bin/python(+0x12df94) [0x55809df6bf94]
14  /opt/conda/envs/gdf/bin/python(_PyFunction_Vectorcall+0xd9) [0x55809df7d3f9]
15  /opt/conda/envs/gdf/bin/python(_PyEval_EvalFrameDefault+0x696) [0x55809df6d4c6]
16  /opt/conda/envs/gdf/bin/python(+0x13f6a2) [0x55809df7d6a2]
17  /opt/conda/envs/gdf/bin/python(+0x14ca43) [0x55809df8aa43]
18  /opt/conda/envs/gdf/bin/python(+0x2580fc) [0x55809e0960fc]
19  /opt/conda/envs/gdf/bin/python(+0xf248b) [0x55809df3048b]
20  /opt/conda/envs/gdf/bin/python(+0x1366f3) [0x55809df746f3]
21  /opt/conda/envs/gdf/bin/python(_PyEval_EvalFrameDefault+0x58b4) [0x55809df726e4]
22  /opt/conda/envs/gdf/bin/python(+0x13f6a2) [0x55809df7d6a2]
23  /opt/conda/envs/gdf/bin/python(_PyEval_EvalFrameDefault+0x696) [0x55809df6d4c6]
24  /opt/conda/envs/gdf/bin/python(+0x13f6a2) [0x55809df7d6a2]
25  /opt/conda/envs/gdf/bin/python(_PyEval_EvalFrameDefault+0x696) [0x55809df6d4c6]
26  /opt/conda/envs/gdf/bin/python(+0x13f6a2) [0x55809df7d6a2]
27  /opt/conda/envs/gdf/bin/python(_PyEval_EvalFrameDefault+0x696) [0x55809df6d4c6]
28  /opt/conda/envs/gdf/bin/python(+0x13f6a2) [0x55809df7d6a2]
29  /opt/conda/envs/gdf/bin/python(_PyEval_EvalFrameDefault+0x696) [0x55809df6d4c6]
30  /opt/conda/envs/gdf/bin/python(+0x12df94) [0x55809df6bf94]
31  /opt/conda/envs/gdf/bin/python(_PyFunction_Vectorcall+0xd9) [0x55809df7d3f9]
32  /opt/conda/envs/gdf/bin/python(_PyEval_EvalFrameDefault+0x11f2) [0x55809df6e022]
33  /opt/conda/envs/gdf/bin/python(+0x12df94) [0x55809df6bf94]
34  /opt/conda/envs/gdf/bin/python(+0x14c88b) [0x55809df8a88b]
35  /opt/conda/envs/gdf/bin/python(PyObject_Call+0xbc) [0x55809df8b00c]
36  /opt/conda/envs/gdf/bin/python(+0x21073e) [0x55809e04e73e]
37  /opt/conda/envs/gdf/bin/python(_PyObject_MakeTpCall+0x2ec) [0x55809df7567c]
38  /opt/conda/envs/gdf/bin/python(_PyEval_EvalFrameDefault+0x45a6) [0x55809df713d6]
39  /opt/conda/envs/gdf/bin/python(+0x13f6a2) [0x55809df7d6a2]
40  /opt/conda/envs/gdf/bin/python(+0x14c96c) [0x55809df8a96c]
41  /opt/conda/envs/gdf/bin/python(_PyEval_EvalFrameDefault+0x45a6) [0x55809df713d6]
42  /opt/conda/envs/gdf/bin/python(+0x13f6a2) [0x55809df7d6a2]
43  /opt/conda/envs/gdf/bin/python(_PyEval_EvalFrameDefault+0x696) [0x55809df6d4c6]
44  /opt/conda/envs/gdf/bin/python(+0x12df94) [0x55809df6bf94]
45  /opt/conda/envs/gdf/bin/python(_PyFunction_Vectorcall+0xd9) [0x55809df7d3f9]
46  /opt/conda/envs/gdf/bin/python(_PyEval_EvalFrameDefault+0x696) [0x55809df6d4c6]
47  /opt/conda/envs/gdf/bin/python(+0x13f6a2) [0x55809df7d6a2]
48  /opt/conda/envs/gdf/bin/python(_PyEval_EvalFrameDefault+0x3e2) [0x55809df6d212]
49  /opt/conda/envs/gdf/bin/python(+0x12df94) [0x55809df6bf94]
50  /opt/conda/envs/gdf/bin/python(_PyFunction_Vectorcall+0xd9) [0x55809df7d3f9]
51  /opt/conda/envs/gdf/bin/python(_PyEval_EvalFrameDefault+0x11f2) [0x55809df6e022]
52  /opt/conda/envs/gdf/bin/python(+0x12df94) [0x55809df6bf94]
53  /opt/conda/envs/gdf/bin/python(_PyEval_EvalCodeWithName+0x48) [0x55809df6bc68]
54  /opt/conda/envs/gdf/bin/python(PyEval_EvalCodeEx+0x39) [0x55809df6bc19]
55  /opt/conda/envs/gdf/bin/python(PyEval_EvalCode+0x1b) [0x55809e01920b]
56  /opt/conda/envs/gdf/bin/python(+0x2085fa) [0x55809e0465fa]
57  /opt/conda/envs/gdf/bin/python(+0x204983) [0x55809e042983]
58  /opt/conda/envs/gdf/bin/python(PyRun_StringFlags+0x9a) [0x55809e03a79a]
59  /opt/conda/envs/gdf/bin/python(PyRun_SimpleStringFlags+0x3c) [0x55809e03a68c]
60  /opt/conda/envs/gdf/bin/python(Py_RunMain+0x267) [0x55809e0398c7]
61  /opt/conda/envs/gdf/bin/python(Py_BytesMain+0x37) [0x55809e00d047]
=================================
[dgx13:70478:0:70478] Caught signal 11 (Segmentation fault: address not mapped to object at address 0x448)
==== backtrace (tid:  70478) ====
 0  /opt/conda/envs/gdf/lib/libucs.so.0(ucs_handle_error+0x2fd) [0x7fdcf3d61f1d]
 1  /opt/conda/envs/gdf/lib/libucs.so.0(+0x29114) [0x7fdcf3d62114]
 2  /opt/conda/envs/gdf/lib/libucs.so.0(+0x292da) [0x7fdcf3d622da]
 3  /usr/lib/x86_64-linux-gnu/libpthread.so.0(+0x14420) [0x7fdd9a461420]
 4  /opt/conda/envs/gdf/lib/libucp.so.0(ucp_mem_type_unpack+0x14) [0x7fdcf3ddb5d4]
 5  /opt/conda/envs/gdf/lib/libucp.so.0(ucp_rndv_data_handler+0x4e9) [0x7fdcf3e00859]
 6  /opt/conda/envs/gdf/lib/libuct.so.0(+0x2042f) [0x7fdcf3d1d42f]
 7  /opt/conda/envs/gdf/lib/libuct.so.0(+0x23798) [0x7fdcf3d20798]
 8  /opt/conda/envs/gdf/lib/libucs.so.0(ucs_event_set_wait+0xb9) [0x7fdcf3d6a989]
 9  /opt/conda/envs/gdf/lib/libuct.so.0(uct_tcp_iface_progress+0x7d) [0x7fdcf3d1f62d]
10  /opt/conda/envs/gdf/lib/libucp.so.0(ucp_worker_progress+0x5a) [0x7fdcf3dd8c4a]
11  /opt/conda/envs/gdf/lib/python3.9/site-packages/ucp/_libs/ucx_api.cpython-39-x86_64-linux-gnu.so(+0x37aaa) [0x7fdcf3e8faaa]
12  /opt/conda/envs/gdf/bin/python(_PyEval_EvalFrameDefault+0x45a6) [0x55f22a0f83d6]
13  /opt/conda/envs/gdf/bin/python(+0x12df94) [0x55f22a0f2f94]
14  /opt/conda/envs/gdf/bin/python(_PyFunction_Vectorcall+0xd9) [0x55f22a1043f9]
15  /opt/conda/envs/gdf/bin/python(_PyEval_EvalFrameDefault+0x696) [0x55f22a0f44c6]
16  /opt/conda/envs/gdf/bin/python(+0x13f6a2) [0x55f22a1046a2]
17  /opt/conda/envs/gdf/bin/python(+0x14ca43) [0x55f22a111a43]
18  /opt/conda/envs/gdf/bin/python(+0x2580fc) [0x55f22a21d0fc]
19  /opt/conda/envs/gdf/bin/python(+0xf248b) [0x55f22a0b748b]
20  /opt/conda/envs/gdf/bin/python(+0x1366f3) [0x55f22a0fb6f3]
21  /opt/conda/envs/gdf/bin/python(_PyEval_EvalFrameDefault+0x58b4) [0x55f22a0f96e4]
22  /opt/conda/envs/gdf/bin/python(+0x13f6a2) [0x55f22a1046a2]
23  /opt/conda/envs/gdf/bin/python(_PyEval_EvalFrameDefault+0x696) [0x55f22a0f44c6]
24  /opt/conda/envs/gdf/bin/python(+0x13f6a2) [0x55f22a1046a2]
25  /opt/conda/envs/gdf/bin/python(_PyEval_EvalFrameDefault+0x696) [0x55f22a0f44c6]
26  /opt/conda/envs/gdf/bin/python(+0x13f6a2) [0x55f22a1046a2]
27  /opt/conda/envs/gdf/bin/python(_PyEval_EvalFrameDefault+0x696) [0x55f22a0f44c6]
28  /opt/conda/envs/gdf/bin/python(+0x13f6a2) [0x55f22a1046a2]
29  /opt/conda/envs/gdf/bin/python(_PyEval_EvalFrameDefault+0x696) [0x55f22a0f44c6]
30  /opt/conda/envs/gdf/bin/python(+0x12df94) [0x55f22a0f2f94]
31  /opt/conda/envs/gdf/bin/python(_PyFunction_Vectorcall+0xd9) [0x55f22a1043f9]
32  /opt/conda/envs/gdf/bin/python(_PyEval_EvalFrameDefault+0x11f2) [0x55f22a0f5022]
33  /opt/conda/envs/gdf/bin/python(+0x12df94) [0x55f22a0f2f94]
34  /opt/conda/envs/gdf/bin/python(+0x14c88b) [0x55f22a11188b]
35  /opt/conda/envs/gdf/bin/python(PyObject_Call+0xbc) [0x55f22a11200c]
36  /opt/conda/envs/gdf/bin/python(+0x21073e) [0x55f22a1d573e]
37  /opt/conda/envs/gdf/bin/python(_PyObject_MakeTpCall+0x2ec) [0x55f22a0fc67c]
38  /opt/conda/envs/gdf/bin/python(_PyEval_EvalFrameDefault+0x45a6) [0x55f22a0f83d6]
39  /opt/conda/envs/gdf/bin/python(+0x13f6a2) [0x55f22a1046a2]
40  /opt/conda/envs/gdf/bin/python(+0x14c96c) [0x55f22a11196c]
41  /opt/conda/envs/gdf/bin/python(_PyEval_EvalFrameDefault+0x45a6) [0x55f22a0f83d6]
42  /opt/conda/envs/gdf/bin/python(+0x13f6a2) [0x55f22a1046a2]
43  /opt/conda/envs/gdf/bin/python(_PyEval_EvalFrameDefault+0x696) [0x55f22a0f44c6]
44  /opt/conda/envs/gdf/bin/python(+0x12df94) [0x55f22a0f2f94]
45  /opt/conda/envs/gdf/bin/python(_PyFunction_Vectorcall+0xd9) [0x55f22a1043f9]
46  /opt/conda/envs/gdf/bin/python(_PyEval_EvalFrameDefault+0x696) [0x55f22a0f44c6]
47  /opt/conda/envs/gdf/bin/python(+0x13f6a2) [0x55f22a1046a2]
48  /opt/conda/envs/gdf/bin/python(_PyEval_EvalFrameDefault+0x3e2) [0x55f22a0f4212]
49  /opt/conda/envs/gdf/bin/python(+0x12df94) [0x55f22a0f2f94]
50  /opt/conda/envs/gdf/bin/python(_PyFunction_Vectorcall+0xd9) [0x55f22a1043f9]
51  /opt/conda/envs/gdf/bin/python(_PyEval_EvalFrameDefault+0x11f2) [0x55f22a0f5022]
52  /opt/conda/envs/gdf/bin/python(+0x12df94) [0x55f22a0f2f94]
53  /opt/conda/envs/gdf/bin/python(_PyEval_EvalCodeWithName+0x48) [0x55f22a0f2c68]
54  /opt/conda/envs/gdf/bin/python(PyEval_EvalCodeEx+0x39) [0x55f22a0f2c19]
55  /opt/conda/envs/gdf/bin/python(PyEval_EvalCode+0x1b) [0x55f22a1a020b]
56  /opt/conda/envs/gdf/bin/python(+0x2085fa) [0x55f22a1cd5fa]
57  /opt/conda/envs/gdf/bin/python(+0x204983) [0x55f22a1c9983]
58  /opt/conda/envs/gdf/bin/python(PyRun_StringFlags+0x9a) [0x55f22a1c179a]
59  /opt/conda/envs/gdf/bin/python(PyRun_SimpleStringFlags+0x3c) [0x55f22a1c168c]
60  /opt/conda/envs/gdf/bin/python(Py_RunMain+0x267) [0x55f22a1c08c7]
61  /opt/conda/envs/gdf/bin/python(Py_BytesMain+0x37) [0x55f22a194047]
=================================
2023-08-23 06:56:30,619 - distributed.worker - ERROR - Worker stream died during communication: ucx://127.0.0.1:34429
Traceback (most recent call last):
  File "/opt/conda/envs/gdf/lib/python3.9/site-packages/distributed/comm/ucx.py", line 354, in read
    await self.ep.recv(msg)
  File "/opt/conda/envs/gdf/lib/python3.9/site-packages/ucp/core.py", line 725, in recv
    ret = await comm.tag_recv(self._ep, buffer, nbytes, tag, name=log)
ucp._libs.exceptions.UCXCanceled: <[Recv #008] ep: 0x7ff8897e9180, tag: 0x3c5fdc07821369e9, nbytes: 16, type: <class 'numpy.ndarray'>>: 

During handling of the above exception, another exception occurred:

Traceback (most recent call last):
  File "/opt/conda/envs/gdf/lib/python3.9/site-packages/distributed/worker.py", line 2073, in gather_dep
    response = await get_data_from_worker(
  File "/opt/conda/envs/gdf/lib/python3.9/site-packages/distributed/worker.py", line 2866, in get_data_from_worker
    response = await send_recv(
  File "/opt/conda/envs/gdf/lib/python3.9/site-packages/distributed/core.py", line 1115, in send_recv
    response = await comm.read(deserializers=deserializers)
  File "/opt/conda/envs/gdf/lib/python3.9/site-packages/distributed/utils.py", line 803, in wrapper
    return await func(*args, **kwargs)
  File "/opt/conda/envs/gdf/lib/python3.9/site-packages/distributed/comm/ucx.py", line 372, in read
    raise CommClosedError(
distributed.comm.core.CommClosedError: Connection closed by writer.
Inner exception: UCXCanceled("<[Recv #008] ep: 0x7ff8897e9180, tag: 0x3c5fdc07821369e9, nbytes: 16, type: <class 'numpy.ndarray'>>: ")
2023-08-23 06:56:30,621 - distributed.worker - ERROR - failed during get data with ucx://127.0.0.1:44025 -> ucx://127.0.0.1:34429
Traceback (most recent call last):
  File "/opt/conda/envs/gdf/lib/python3.9/site-packages/distributed/comm/ucx.py", line 354, in read
    await self.ep.recv(msg)
  File "/opt/conda/envs/gdf/lib/python3.9/site-packages/ucp/core.py", line 725, in recv
    ret = await comm.tag_recv(self._ep, buffer, nbytes, tag, name=log)
ucp._libs.exceptions.UCXCanceled: <[Recv #006] ep: 0x7f5941cca340, tag: 0x4e3aa464fc201d33, nbytes: 16, type: <class 'numpy.ndarray'>>: 

During handling of the above exception, another exception occurred:

Traceback (most recent call last):
  File "/opt/conda/envs/gdf/lib/python3.9/site-packages/distributed/worker.py", line 1800, in get_data
    response = await comm.read(deserializers=serializers)
  File "/opt/conda/envs/gdf/lib/python3.9/site-packages/distributed/utils.py", line 803, in wrapper
    return await func(*args, **kwargs)
  File "/opt/conda/envs/gdf/lib/python3.9/site-packages/distributed/comm/ucx.py", line 372, in read
    raise CommClosedError(
distributed.comm.core.CommClosedError: Connection closed by writer.
Inner exception: UCXCanceled("<[Recv #006] ep: 0x7f5941cca340, tag: 0x4e3aa464fc201d33, nbytes: 16, type: <class 'numpy.ndarray'>>: ")
2023-08-23 06:56:30,623 - distributed.worker - ERROR - Worker stream died during communication: ucx://127.0.0.1:34429
Traceback (most recent call last):
  File "/opt/conda/envs/gdf/lib/python3.9/site-packages/distributed/comm/ucx.py", line 354, in read
    await self.ep.recv(msg)
  File "/opt/conda/envs/gdf/lib/python3.9/site-packages/ucp/core.py", line 725, in recv
    ret = await comm.tag_recv(self._ep, buffer, nbytes, tag, name=log)
ucp._libs.exceptions.UCXCanceled: <[Recv #008] ep: 0x7f5941cca140, tag: 0xb249fc011d2aeb30, nbytes: 16, type: <class 'numpy.ndarray'>>: 

During handling of the above exception, another exception occurred:

Traceback (most recent call last):
  File "/opt/conda/envs/gdf/lib/python3.9/site-packages/distributed/worker.py", line 2073, in gather_dep
    response = await get_data_from_worker(
  File "/opt/conda/envs/gdf/lib/python3.9/site-packages/distributed/worker.py", line 2866, in get_data_from_worker
    response = await send_recv(
  File "/opt/conda/envs/gdf/lib/python3.9/site-packages/distributed/core.py", line 1115, in send_recv
    response = await comm.read(deserializers=deserializers)
  File "/opt/conda/envs/gdf/lib/python3.9/site-packages/distributed/utils.py", line 803, in wrapper
    return await func(*args, **kwargs)
  File "/opt/conda/envs/gdf/lib/python3.9/site-packages/distributed/comm/ucx.py", line 372, in read
    raise CommClosedError(
distributed.comm.core.CommClosedError: Connection closed by writer.
Inner exception: UCXCanceled("<[Recv #008] ep: 0x7f5941cca140, tag: 0xb249fc011d2aeb30, nbytes: 16, type: <class 'numpy.ndarray'>>: ")
2023-08-23 06:56:30,643 - distributed.worker - ERROR - Worker stream died during communication: ucx://127.0.0.1:40785
Traceback (most recent call last):
  File "/opt/conda/envs/gdf/lib/python3.9/site-packages/distributed/comm/ucx.py", line 354, in read
    await self.ep.recv(msg)
  File "/opt/conda/envs/gdf/lib/python3.9/site-packages/ucp/core.py", line 725, in recv
    ret = await comm.tag_recv(self._ep, buffer, nbytes, tag, name=log)
ucp._libs.exceptions.UCXCanceled: <[Recv #003] ep: 0x7f5941cca200, tag: 0xca2cae56810c5b5, nbytes: 16, type: <class 'numpy.ndarray'>>: 

During handling of the above exception, another exception occurred:

Traceback (most recent call last):
  File "/opt/conda/envs/gdf/lib/python3.9/site-packages/distributed/worker.py", line 2073, in gather_dep
    response = await get_data_from_worker(
  File "/opt/conda/envs/gdf/lib/python3.9/site-packages/distributed/worker.py", line 2866, in get_data_from_worker
    response = await send_recv(
  File "/opt/conda/envs/gdf/lib/python3.9/site-packages/distributed/core.py", line 1115, in send_recv
    response = await comm.read(deserializers=deserializers)
  File "/opt/conda/envs/gdf/lib/python3.9/site-packages/distributed/utils.py", line 803, in wrapper
    return await func(*args, **kwargs)
  File "/opt/conda/envs/gdf/lib/python3.9/site-packages/distributed/comm/ucx.py", line 372, in read
    raise CommClosedError(
distributed.comm.core.CommClosedError: Connection closed by writer.
Inner exception: UCXCanceled("<[Recv #003] ep: 0x7f5941cca200, tag: 0xca2cae56810c5b5, nbytes: 16, type: <class 'numpy.ndarray'>>: ")
2023-08-23 06:56:30,644 - distributed.worker - ERROR - Worker stream died during communication: ucx://127.0.0.1:40785
Traceback (most recent call last):
  File "/opt/conda/envs/gdf/lib/python3.9/site-packages/distributed/comm/ucx.py", line 354, in read
    await self.ep.recv(msg)
  File "/opt/conda/envs/gdf/lib/python3.9/site-packages/ucp/core.py", line 725, in recv
    ret = await comm.tag_recv(self._ep, buffer, nbytes, tag, name=log)
ucp._libs.exceptions.UCXCanceled: <[Recv #003] ep: 0x7f973ce25280, tag: 0xf590fe4d19a2492, nbytes: 16, type: <class 'numpy.ndarray'>>: 

During handling of the above exception, another exception occurred:

Traceback (most recent call last):
  File "/opt/conda/envs/gdf/lib/python3.9/site-packages/distributed/worker.py", line 2073, in gather_dep
    response = await get_data_from_worker(
  File "/opt/conda/envs/gdf/lib/python3.9/site-packages/distributed/worker.py", line 2866, in get_data_from_worker
    response = await send_recv(
  File "/opt/conda/envs/gdf/lib/python3.9/site-packages/distributed/core.py", line 1115, in send_recv
    response = await comm.read(deserializers=deserializers)
  File "/opt/conda/envs/gdf/lib/python3.9/site-packages/distributed/utils.py", line 803, in wrapper
    return await func(*args, **kwargs)
  File "/opt/conda/envs/gdf/lib/python3.9/site-packages/distributed/comm/ucx.py", line 372, in read
    raise CommClosedError(
distributed.comm.core.CommClosedError: Connection closed by writer.
Inner exception: UCXCanceled("<[Recv #003] ep: 0x7f973ce25280, tag: 0xf590fe4d19a2492, nbytes: 16, type: <class 'numpy.ndarray'>>: ")
2023-08-23 06:56:30,644 - distributed.worker - ERROR - failed during get data with ucx://127.0.0.1:42099 -> ucx://127.0.0.1:43689
Traceback (most recent call last):
  File "/opt/conda/envs/gdf/lib/python3.9/site-packages/distributed/comm/ucx.py", line 338, in write
    await self.ep.send(each_frame)
  File "/opt/conda/envs/gdf/lib/python3.9/site-packages/ucp/core.py", line 650, in send
    return await comm.tag_send(self._ep, buffer, nbytes, tag, name=log)
ucp._libs.exceptions.UCXError: <[Send #007] ep: 0x7f8a98e6d200, tag: 0xabfac8ca3fdfa3f, nbytes: 50000000, type: <class 'cupy.ndarray'>>: Connection reset by remote peer

During handling of the above exception, another exception occurred:

Traceback (most recent call last):
  File "/opt/conda/envs/gdf/lib/python3.9/site-packages/distributed/worker.py", line 1799, in get_data
    compressed = await comm.write(msg, serializers=serializers)
  File "/opt/conda/envs/gdf/lib/python3.9/site-packages/distributed/utils.py", line 803, in wrapper
    return await func(*args, **kwargs)
  File "/opt/conda/envs/gdf/lib/python3.9/site-packages/distributed/comm/ucx.py", line 342, in write
    raise CommClosedError("While writing, the connection was closed")
distributed.comm.core.CommClosedError: While writing, the connection was closed
2023-08-23 06:56:30,645 - distributed.worker - ERROR - Worker stream died during communication: ucx://127.0.0.1:43689
Traceback (most recent call last):
  File "/opt/conda/envs/gdf/lib/python3.9/site-packages/distributed/comm/ucx.py", line 354, in read
    await self.ep.recv(msg)
  File "/opt/conda/envs/gdf/lib/python3.9/site-packages/ucp/core.py", line 725, in recv
    ret = await comm.tag_recv(self._ep, buffer, nbytes, tag, name=log)
ucp._libs.exceptions.UCXCanceled: <[Recv #000] ep: 0x7f973ce25240, tag: 0x146a03daef838a5d, nbytes: 16, type: <class 'numpy.ndarray'>>: 

During handling of the above exception, another exception occurred:

Traceback (most recent call last):
  File "/opt/conda/envs/gdf/lib/python3.9/site-packages/distributed/worker.py", line 2073, in gather_dep
    response = await get_data_from_worker(
  File "/opt/conda/envs/gdf/lib/python3.9/site-packages/distributed/worker.py", line 2863, in get_data_from_worker
    comm = await rpc.connect(worker)
  File "/opt/conda/envs/gdf/lib/python3.9/site-packages/distributed/core.py", line 1600, in connect
    return connect_attempt.result()
  File "/opt/conda/envs/gdf/lib/python3.9/site-packages/distributed/core.py", line 1526, in _connect
    comm = await connect(
  File "/opt/conda/envs/gdf/lib/python3.9/site-packages/distributed/comm/core.py", line 377, in connect
    handshake = await comm.read()
  File "/opt/conda/envs/gdf/lib/python3.9/site-packages/distributed/utils.py", line 803, in wrapper
    return await func(*args, **kwargs)
  File "/opt/conda/envs/gdf/lib/python3.9/site-packages/distributed/comm/ucx.py", line 372, in read
    raise CommClosedError(
distributed.comm.core.CommClosedError: Connection closed by writer.
Inner exception: UCXCanceled("<[Recv #000] ep: 0x7f973ce25240, tag: 0x146a03daef838a5d, nbytes: 16, type: <class 'numpy.ndarray'>>: ")
2023-08-23 06:56:30,646 - distributed.worker - ERROR - failed during get data with ucx://127.0.0.1:42099 -> ucx://127.0.0.1:40785
Traceback (most recent call last):
  File "/opt/conda/envs/gdf/lib/python3.9/site-packages/distributed/comm/ucx.py", line 338, in write
    await self.ep.send(each_frame)
  File "/opt/conda/envs/gdf/lib/python3.9/site-packages/ucp/core.py", line 650, in send
    return await comm.tag_send(self._ep, buffer, nbytes, tag, name=log)
ucp._libs.exceptions.UCXError: <[Send #007] ep: 0x7f8a98e6d280, tag: 0x969e10b6505d8fbe, nbytes: 50000000, type: <class 'cupy.ndarray'>>: Connection reset by remote peer

During handling of the above exception, another exception occurred:

Traceback (most recent call last):
  File "/opt/conda/envs/gdf/lib/python3.9/site-packages/distributed/worker.py", line 1799, in get_data
    compressed = await comm.write(msg, serializers=serializers)
  File "/opt/conda/envs/gdf/lib/python3.9/site-packages/distributed/utils.py", line 803, in wrapper
    return await func(*args, **kwargs)
  File "/opt/conda/envs/gdf/lib/python3.9/site-packages/distributed/comm/ucx.py", line 342, in write
    raise CommClosedError("While writing, the connection was closed")
distributed.comm.core.CommClosedError: While writing, the connection was closed
2023-08-23 06:56:30,646 - distributed.worker - ERROR - Worker stream died during communication: ucx://127.0.0.1:43689
Traceback (most recent call last):
  File "/opt/conda/envs/gdf/lib/python3.9/site-packages/distributed/comm/ucx.py", line 396, in read
    await self.ep.recv(each_frame)
  File "/opt/conda/envs/gdf/lib/python3.9/site-packages/ucp/core.py", line 725, in recv
    ret = await comm.tag_recv(self._ep, buffer, nbytes, tag, name=log)
ucp._libs.exceptions.UCXError: <[Recv #007] ep: 0x7f8a98e6d180, tag: 0x379dd09a611997ad, nbytes: 50000000, type: <class 'rmm._lib.device_buffer.DeviceBuffer'>>: Connection reset by remote peer

During handling of the above exception, another exception occurred:

Traceback (most recent call last):
  File "/opt/conda/envs/gdf/lib/python3.9/site-packages/distributed/worker.py", line 2073, in gather_dep
    response = await get_data_from_worker(
  File "/opt/conda/envs/gdf/lib/python3.9/site-packages/distributed/worker.py", line 2866, in get_data_from_worker
    response = await send_recv(
  File "/opt/conda/envs/gdf/lib/python3.9/site-packages/distributed/core.py", line 1115, in send_recv
    response = await comm.read(deserializers=deserializers)
  File "/opt/conda/envs/gdf/lib/python3.9/site-packages/distributed/utils.py", line 803, in wrapper
    return await func(*args, **kwargs)
  File "/opt/conda/envs/gdf/lib/python3.9/site-packages/distributed/comm/ucx.py", line 402, in read
    raise CommClosedError(
distributed.comm.core.CommClosedError: Connection closed by writer.
Inner exception: UCXError("<[Recv #007] ep: 0x7f8a98e6d180, tag: 0x379dd09a611997ad, nbytes: 50000000, type: <class 'rmm._lib.device_buffer.DeviceBuffer'>>: Connection reset by remote peer")
2023-08-23 06:56:30,647 - distributed.worker - ERROR - Worker stream died during communication: ucx://127.0.0.1:40785
Traceback (most recent call last):
  File "/opt/conda/envs/gdf/lib/python3.9/site-packages/distributed/comm/ucx.py", line 354, in read
    await self.ep.recv(msg)
  File "/opt/conda/envs/gdf/lib/python3.9/site-packages/ucp/core.py", line 725, in recv
    ret = await comm.tag_recv(self._ep, buffer, nbytes, tag, name=log)
ucp._libs.exceptions.UCXCanceled: <[Recv #003] ep: 0x7f8a98e6d140, tag: 0x5edb9de9f1f0aed3, nbytes: 16, type: <class 'numpy.ndarray'>>: 

During handling of the above exception, another exception occurred:

Traceback (most recent call last):
  File "/opt/conda/envs/gdf/lib/python3.9/site-packages/distributed/worker.py", line 2073, in gather_dep
    response = await get_data_from_worker(
  File "/opt/conda/envs/gdf/lib/python3.9/site-packages/distributed/worker.py", line 2866, in get_data_from_worker
    response = await send_recv(
  File "/opt/conda/envs/gdf/lib/python3.9/site-packages/distributed/core.py", line 1115, in send_recv
    response = await comm.read(deserializers=deserializers)
  File "/opt/conda/envs/gdf/lib/python3.9/site-packages/distributed/utils.py", line 803, in wrapper
    return await func(*args, **kwargs)
  File "/opt/conda/envs/gdf/lib/python3.9/site-packages/distributed/comm/ucx.py", line 372, in read
    raise CommClosedError(
distributed.comm.core.CommClosedError: Connection closed by writer.
Inner exception: UCXCanceled("<[Recv #003] ep: 0x7f8a98e6d140, tag: 0x5edb9de9f1f0aed3, nbytes: 16, type: <class 'numpy.ndarray'>>: ")
2023-08-23 06:56:30,659 - distributed.nanny - WARNING - Restarting worker
2023-08-23 06:56:30,733 - distributed.worker - ERROR - failed during get data with ucx://127.0.0.1:40813 -> ucx://127.0.0.1:34429
Traceback (most recent call last):
  File "/opt/conda/envs/gdf/lib/python3.9/site-packages/distributed/comm/ucx.py", line 338, in write
    await self.ep.send(each_frame)
  File "/opt/conda/envs/gdf/lib/python3.9/site-packages/ucp/core.py", line 650, in send
    return await comm.tag_send(self._ep, buffer, nbytes, tag, name=log)
ucp._libs.exceptions.UCXError: <[Send #007] ep: 0x7fd6849f1300, tag: 0xa6fbfd1b17dc7734, nbytes: 50000000, type: <class 'cupy.ndarray'>>: Connection reset by remote peer

During handling of the above exception, another exception occurred:

Traceback (most recent call last):
  File "/opt/conda/envs/gdf/lib/python3.9/site-packages/distributed/worker.py", line 1799, in get_data
    compressed = await comm.write(msg, serializers=serializers)
  File "/opt/conda/envs/gdf/lib/python3.9/site-packages/distributed/utils.py", line 803, in wrapper
    return await func(*args, **kwargs)
  File "/opt/conda/envs/gdf/lib/python3.9/site-packages/distributed/comm/ucx.py", line 342, in write
    raise CommClosedError("While writing, the connection was closed")
distributed.comm.core.CommClosedError: While writing, the connection was closed
[dgx13:70472:0:70472] Caught signal 11 (Segmentation fault: address not mapped to object at address 0x448)
==== backtrace (tid:  70472) ====
 0  /opt/conda/envs/gdf/lib/libucs.so.0(ucs_handle_error+0x2fd) [0x7fd684c85f1d]
 1  /opt/conda/envs/gdf/lib/libucs.so.0(+0x29114) [0x7fd684c86114]
 2  /opt/conda/envs/gdf/lib/libucs.so.0(+0x292da) [0x7fd684c862da]
 3  /usr/lib/x86_64-linux-gnu/libpthread.so.0(+0x14420) [0x7fd725365420]
 4  /opt/conda/envs/gdf/lib/libucp.so.0(ucp_mem_type_unpack+0x14) [0x7fd684cff5d4]
 5  /opt/conda/envs/gdf/lib/libucp.so.0(ucp_rndv_data_handler+0x4e9) [0x7fd684d24859]
 6  /opt/conda/envs/gdf/lib/libuct.so.0(+0x2042f) [0x7fd684c4142f]
 7  /opt/conda/envs/gdf/lib/libuct.so.0(+0x23798) [0x7fd684c44798]
 8  /opt/conda/envs/gdf/lib/libucs.so.0(ucs_event_set_wait+0xb9) [0x7fd684c8e989]
 9  /opt/conda/envs/gdf/lib/libuct.so.0(uct_tcp_iface_progress+0x7d) [0x7fd684c4362d]
10  /opt/conda/envs/gdf/lib/libucp.so.0(ucp_worker_progress+0x5a) [0x7fd684cfcc4a]
11  /opt/conda/envs/gdf/lib/python3.9/site-packages/ucp/_libs/ucx_api.cpython-39-x86_64-linux-gnu.so(+0x37aaa) [0x7fd684db3aaa]
12  /opt/conda/envs/gdf/bin/python(_PyEval_EvalFrameDefault+0x45a6) [0x56061d2c23d6]
13  /opt/conda/envs/gdf/bin/python(+0x12df94) [0x56061d2bcf94]
14  /opt/conda/envs/gdf/bin/python(_PyFunction_Vectorcall+0xd9) [0x56061d2ce3f9]
15  /opt/conda/envs/gdf/bin/python(_PyEval_EvalFrameDefault+0x696) [0x56061d2be4c6]
16  /opt/conda/envs/gdf/bin/python(+0x1e2612) [0x56061d371612]
17  /opt/conda/envs/gdf/lib/python3.9/lib-dynload/_asyncio.cpython-39-x86_64-linux-gnu.so(+0x81e9) [0x7fd7181e41e9]
18  /opt/conda/envs/gdf/bin/python(_PyObject_MakeTpCall+0x2ec) [0x56061d2c667c]
19  /opt/conda/envs/gdf/bin/python(+0xf248b) [0x56061d28148b]
20  /opt/conda/envs/gdf/bin/python(+0x1366f3) [0x56061d2c56f3]
21  /opt/conda/envs/gdf/bin/python(_PyEval_EvalFrameDefault+0x58b4) [0x56061d2c36e4]
22  /opt/conda/envs/gdf/bin/python(+0x13f6a2) [0x56061d2ce6a2]
23  /opt/conda/envs/gdf/bin/python(_PyEval_EvalFrameDefault+0x696) [0x56061d2be4c6]
24  /opt/conda/envs/gdf/bin/python(+0x13f6a2) [0x56061d2ce6a2]
25  /opt/conda/envs/gdf/bin/python(_PyEval_EvalFrameDefault+0x696) [0x56061d2be4c6]
26  /opt/conda/envs/gdf/bin/python(+0x13f6a2) [0x56061d2ce6a2]
27  /opt/conda/envs/gdf/bin/python(_PyEval_EvalFrameDefault+0x696) [0x56061d2be4c6]
28  /opt/conda/envs/gdf/bin/python(+0x13f6a2) [0x56061d2ce6a2]
29  /opt/conda/envs/gdf/bin/python(_PyEval_EvalFrameDefault+0x696) [0x56061d2be4c6]
30  /opt/conda/envs/gdf/bin/python(+0x12df94) [0x56061d2bcf94]
31  /opt/conda/envs/gdf/bin/python(_PyFunction_Vectorcall+0xd9) [0x56061d2ce3f9]
32  /opt/conda/envs/gdf/bin/python(_PyEval_EvalFrameDefault+0x11f2) [0x56061d2bf022]
33  /opt/conda/envs/gdf/bin/python(+0x12df94) [0x56061d2bcf94]
34  /opt/conda/envs/gdf/bin/python(+0x14c88b) [0x56061d2db88b]
35  /opt/conda/envs/gdf/bin/python(PyObject_Call+0xbc) [0x56061d2dc00c]
36  /opt/conda/envs/gdf/bin/python(+0x21073e) [0x56061d39f73e]
37  /opt/conda/envs/gdf/bin/python(_PyObject_MakeTpCall+0x2ec) [0x56061d2c667c]
38  /opt/conda/envs/gdf/bin/python(_PyEval_EvalFrameDefault+0x45a6) [0x56061d2c23d6]
39  /opt/conda/envs/gdf/bin/python(+0x13f6a2) [0x56061d2ce6a2]
40  /opt/conda/envs/gdf/bin/python(+0x14c96c) [0x56061d2db96c]
41  /opt/conda/envs/gdf/bin/python(_PyEval_EvalFrameDefault+0x45a6) [0x56061d2c23d6]
42  /opt/conda/envs/gdf/bin/python(+0x13f6a2) [0x56061d2ce6a2]
43  /opt/conda/envs/gdf/bin/python(_PyEval_EvalFrameDefault+0x696) [0x56061d2be4c6]
44  /opt/conda/envs/gdf/bin/python(+0x12df94) [0x56061d2bcf94]
45  /opt/conda/envs/gdf/bin/python(_PyFunction_Vectorcall+0xd9) [0x56061d2ce3f9]
46  /opt/conda/envs/gdf/bin/python(_PyEval_EvalFrameDefault+0x696) [0x56061d2be4c6]
47  /opt/conda/envs/gdf/bin/python(+0x13f6a2) [0x56061d2ce6a2]
48  /opt/conda/envs/gdf/bin/python(_PyEval_EvalFrameDefault+0x3e2) [0x56061d2be212]
49  /opt/conda/envs/gdf/bin/python(+0x12df94) [0x56061d2bcf94]
50  /opt/conda/envs/gdf/bin/python(_PyFunction_Vectorcall+0xd9) [0x56061d2ce3f9]
51  /opt/conda/envs/gdf/bin/python(_PyEval_EvalFrameDefault+0x11f2) [0x56061d2bf022]
52  /opt/conda/envs/gdf/bin/python(+0x12df94) [0x56061d2bcf94]
53  /opt/conda/envs/gdf/bin/python(_PyEval_EvalCodeWithName+0x48) [0x56061d2bcc68]
54  /opt/conda/envs/gdf/bin/python(PyEval_EvalCodeEx+0x39) [0x56061d2bcc19]
55  /opt/conda/envs/gdf/bin/python(PyEval_EvalCode+0x1b) [0x56061d36a20b]
56  /opt/conda/envs/gdf/bin/python(+0x2085fa) [0x56061d3975fa]
57  /opt/conda/envs/gdf/bin/python(+0x204983) [0x56061d393983]
58  /opt/conda/envs/gdf/bin/python(PyRun_StringFlags+0x9a) [0x56061d38b79a]
59  /opt/conda/envs/gdf/bin/python(PyRun_SimpleStringFlags+0x3c) [0x56061d38b68c]
60  /opt/conda/envs/gdf/bin/python(Py_RunMain+0x267) [0x56061d38a8c7]
61  /opt/conda/envs/gdf/bin/python(Py_BytesMain+0x37) [0x56061d35e047]
=================================
2023-08-23 06:56:30,756 - distributed.nanny - WARNING - Restarting worker
2023-08-23 06:56:30,757 - distributed.nanny - WARNING - Restarting worker
2023-08-23 06:56:30,966 - distributed.worker - ERROR - failed during get data with ucx://127.0.0.1:44025 -> ucx://127.0.0.1:40813
Traceback (most recent call last):
  File "/opt/conda/envs/gdf/lib/python3.9/site-packages/distributed/comm/ucx.py", line 338, in write
    await self.ep.send(each_frame)
  File "/opt/conda/envs/gdf/lib/python3.9/site-packages/ucp/core.py", line 650, in send
    return await comm.tag_send(self._ep, buffer, nbytes, tag, name=log)
ucp._libs.exceptions.UCXError: <[Send #007] ep: 0x7f5941cca300, tag: 0xafaa762e432a61f8, nbytes: 50000000, type: <class 'cupy.ndarray'>>: Connection reset by remote peer

During handling of the above exception, another exception occurred:

Traceback (most recent call last):
  File "/opt/conda/envs/gdf/lib/python3.9/site-packages/distributed/worker.py", line 1799, in get_data
    compressed = await comm.write(msg, serializers=serializers)
  File "/opt/conda/envs/gdf/lib/python3.9/site-packages/distributed/utils.py", line 803, in wrapper
    return await func(*args, **kwargs)
  File "/opt/conda/envs/gdf/lib/python3.9/site-packages/distributed/comm/ucx.py", line 342, in write
    raise CommClosedError("While writing, the connection was closed")
distributed.comm.core.CommClosedError: While writing, the connection was closed
2023-08-23 06:56:30,967 - distributed.worker - ERROR - Worker stream died during communication: ucx://127.0.0.1:40813
Traceback (most recent call last):
  File "/opt/conda/envs/gdf/lib/python3.9/site-packages/distributed/comm/ucx.py", line 396, in read
    await self.ep.recv(each_frame)
  File "/opt/conda/envs/gdf/lib/python3.9/site-packages/ucp/core.py", line 725, in recv
    ret = await comm.tag_recv(self._ep, buffer, nbytes, tag, name=log)
ucp._libs.exceptions.UCXError: <[Recv #007] ep: 0x7f5941cca100, tag: 0x79d1db9c88fd3ace, nbytes: 50000000, type: <class 'rmm._lib.device_buffer.DeviceBuffer'>>: Connection reset by remote peer

During handling of the above exception, another exception occurred:

Traceback (most recent call last):
  File "/opt/conda/envs/gdf/lib/python3.9/site-packages/distributed/worker.py", line 2073, in gather_dep
    response = await get_data_from_worker(
  File "/opt/conda/envs/gdf/lib/python3.9/site-packages/distributed/worker.py", line 2866, in get_data_from_worker
    response = await send_recv(
  File "/opt/conda/envs/gdf/lib/python3.9/site-packages/distributed/core.py", line 1115, in send_recv
    response = await comm.read(deserializers=deserializers)
  File "/opt/conda/envs/gdf/lib/python3.9/site-packages/distributed/utils.py", line 803, in wrapper
    return await func(*args, **kwargs)
  File "/opt/conda/envs/gdf/lib/python3.9/site-packages/distributed/comm/ucx.py", line 402, in read
    raise CommClosedError(
distributed.comm.core.CommClosedError: Connection closed by writer.
Inner exception: UCXError("<[Recv #007] ep: 0x7f5941cca100, tag: 0x79d1db9c88fd3ace, nbytes: 50000000, type: <class 'rmm._lib.device_buffer.DeviceBuffer'>>: Connection reset by remote peer")
2023-08-23 06:56:30,973 - distributed.worker - ERROR - Worker stream died during communication: ucx://127.0.0.1:40813
Traceback (most recent call last):
  File "/opt/conda/envs/gdf/lib/python3.9/site-packages/distributed/comm/ucx.py", line 471, in connect
    ep = await ucp.create_endpoint(ip, port)
  File "/opt/conda/envs/gdf/lib/python3.9/site-packages/ucp/core.py", line 1004, in create_endpoint
    return await _get_ctx().create_endpoint(
  File "/opt/conda/envs/gdf/lib/python3.9/site-packages/ucp/core.py", line 316, in create_endpoint
    peer_info = await exchange_peer_info(
  File "/opt/conda/envs/gdf/lib/python3.9/site-packages/ucp/core.py", line 54, in exchange_peer_info
    await comm.stream_recv(endpoint, peer_info_arr, peer_info_arr.nbytes)
ucp._libs.exceptions.UCXError: <stream_recv>: Connection reset by remote peer

During handling of the above exception, another exception occurred:

Traceback (most recent call last):
  File "/opt/conda/envs/gdf/lib/python3.9/site-packages/distributed/comm/core.py", line 342, in connect
    comm = await wait_for(
  File "/opt/conda/envs/gdf/lib/python3.9/site-packages/distributed/utils.py", line 1927, in wait_for
    return await asyncio.wait_for(fut, timeout)
  File "/opt/conda/envs/gdf/lib/python3.9/asyncio/tasks.py", line 479, in wait_for
    return fut.result()
  File "/opt/conda/envs/gdf/lib/python3.9/site-packages/distributed/comm/ucx.py", line 473, in connect
    raise CommClosedError("Connection closed before handshake completed")
distributed.comm.core.CommClosedError: Connection closed before handshake completed

During handling of the above exception, another exception occurred:

Traceback (most recent call last):
  File "/opt/conda/envs/gdf/lib/python3.9/site-packages/distributed/core.py", line 1526, in _connect
    comm = await connect(
  File "/opt/conda/envs/gdf/lib/python3.9/site-packages/distributed/comm/core.py", line 366, in connect
    await asyncio.sleep(backoff)
  File "/opt/conda/envs/gdf/lib/python3.9/asyncio/tasks.py", line 652, in sleep
    return await future
asyncio.exceptions.CancelledError

During handling of the above exception, another exception occurred:

Traceback (most recent call last):
  File "/opt/conda/envs/gdf/lib/python3.9/site-packages/distributed/core.py", line 1600, in connect
    return connect_attempt.result()
asyncio.exceptions.CancelledError

During handling of the above exception, another exception occurred:

Traceback (most recent call last):
  File "/opt/conda/envs/gdf/lib/python3.9/site-packages/distributed/worker.py", line 2073, in gather_dep
    response = await get_data_from_worker(
  File "/opt/conda/envs/gdf/lib/python3.9/site-packages/distributed/worker.py", line 2863, in get_data_from_worker
    comm = await rpc.connect(worker)
  File "/opt/conda/envs/gdf/lib/python3.9/site-packages/distributed/core.py", line 1603, in connect
    raise CommClosedError(reason)
distributed.comm.core.CommClosedError: Address removed.
2023-08-23 06:56:30,975 - distributed.worker - ERROR - Worker stream died during communication: ucx://127.0.0.1:40813
Traceback (most recent call last):
  File "/opt/conda/envs/gdf/lib/python3.9/site-packages/distributed/core.py", line 1526, in _connect
    comm = await connect(
  File "/opt/conda/envs/gdf/lib/python3.9/site-packages/distributed/comm/core.py", line 342, in connect
    comm = await wait_for(
  File "/opt/conda/envs/gdf/lib/python3.9/site-packages/distributed/utils.py", line 1927, in wait_for
    return await asyncio.wait_for(fut, timeout)
  File "/opt/conda/envs/gdf/lib/python3.9/asyncio/tasks.py", line 466, in wait_for
    await waiter
asyncio.exceptions.CancelledError

During handling of the above exception, another exception occurred:

Traceback (most recent call last):
  File "/opt/conda/envs/gdf/lib/python3.9/site-packages/distributed/core.py", line 1600, in connect
    return connect_attempt.result()
asyncio.exceptions.CancelledError

During handling of the above exception, another exception occurred:

Traceback (most recent call last):
  File "/opt/conda/envs/gdf/lib/python3.9/site-packages/distributed/worker.py", line 2073, in gather_dep
    response = await get_data_from_worker(
  File "/opt/conda/envs/gdf/lib/python3.9/site-packages/distributed/worker.py", line 2863, in get_data_from_worker
    comm = await rpc.connect(worker)
  File "/opt/conda/envs/gdf/lib/python3.9/site-packages/distributed/core.py", line 1603, in connect
    raise CommClosedError(reason)
distributed.comm.core.CommClosedError: Address removed.
2023-08-23 06:56:31,033 - distributed.nanny - WARNING - Restarting worker
/opt/conda/envs/gdf/lib/python3.9/multiprocessing/resource_tracker.py:216: UserWarning: resource_tracker: There appear to be 48 leaked semaphore objects to clean up at shutdown
  warnings.warn('resource_tracker: There appear to be %d '
