[dgx13:73526:0:73526] Caught signal 11 (Segmentation fault: address not mapped to object at address 0x448)
==== backtrace (tid:  73526) ====
 0  /opt/conda/envs/gdf/lib/libucs.so.0(ucs_handle_error+0x2fd) [0x7f71a4ae306d]
 1  /opt/conda/envs/gdf/lib/libucs.so.0(+0x2a264) [0x7f71a4ae3264]
 2  /opt/conda/envs/gdf/lib/libucs.so.0(+0x2a42a) [0x7f71a4ae342a]
 3  /usr/lib/x86_64-linux-gnu/libpthread.so.0(+0x14420) [0x7f7245cb8420]
 4  /opt/conda/envs/gdf/lib/libucp.so.0(ucp_mem_type_unpack+0x14) [0x7f71a4b616a4]
 5  /opt/conda/envs/gdf/lib/libucp.so.0(ucp_rndv_data_handler+0x4e9) [0x7f71a4b8a829]
 6  /opt/conda/envs/gdf/lib/./libuct.so.0(+0x2146f) [0x7f71a4a9d46f]
 7  /opt/conda/envs/gdf/lib/./libuct.so.0(+0x248c8) [0x7f71a4aa08c8]
 8  /opt/conda/envs/gdf/lib/libucs.so.0(ucs_event_set_wait+0xb9) [0x7f71a4aec499]
 9  /opt/conda/envs/gdf/lib/./libuct.so.0(uct_tcp_iface_progress+0x7d) [0x7f71a4a9f66d]
10  /opt/conda/envs/gdf/lib/libucp.so.0(ucp_worker_progress+0x5a) [0x7f71a4b5e8ca]
11  /opt/conda/envs/gdf/lib/python3.9/site-packages/ucp/_libs/ucx_api.cpython-39-x86_64-linux-gnu.so(+0x3206a) [0x7f71a4c1706a]
12  /opt/conda/envs/gdf/bin/python(_PyEval_EvalFrameDefault+0x37cb) [0x5648cbea86fb]
13  /opt/conda/envs/gdf/bin/python(+0x12f094) [0x5648cbea4094]
14  /opt/conda/envs/gdf/bin/python(_PyFunction_Vectorcall+0xd9) [0x5648cbeb5519]
15  /opt/conda/envs/gdf/bin/python(_PyEval_EvalFrameDefault+0x696) [0x5648cbea55c6]
16  /opt/conda/envs/gdf/bin/python(+0x1e3162) [0x5648cbf58162]
17  /opt/conda/envs/gdf/lib/python3.9/lib-dynload/_asyncio.cpython-39-x86_64-linux-gnu.so(+0x81e9) [0x7f7237cc61e9]
18  /opt/conda/envs/gdf/bin/python(_PyObject_MakeTpCall+0x2ec) [0x5648cbead77c]
19  /opt/conda/envs/gdf/bin/python(+0xead05) [0x5648cbe5fd05]
20  /opt/conda/envs/gdf/bin/python(+0x1377f3) [0x5648cbeac7f3]
21  /opt/conda/envs/gdf/bin/python(_PyEval_EvalFrameDefault+0x59f9) [0x5648cbeaa929]
22  /opt/conda/envs/gdf/bin/python(+0x1407c2) [0x5648cbeb57c2]
23  /opt/conda/envs/gdf/bin/python(_PyEval_EvalFrameDefault+0x696) [0x5648cbea55c6]
24  /opt/conda/envs/gdf/bin/python(+0x1407c2) [0x5648cbeb57c2]
25  /opt/conda/envs/gdf/bin/python(_PyEval_EvalFrameDefault+0x696) [0x5648cbea55c6]
26  /opt/conda/envs/gdf/bin/python(+0x1407c2) [0x5648cbeb57c2]
27  /opt/conda/envs/gdf/bin/python(_PyEval_EvalFrameDefault+0x696) [0x5648cbea55c6]
28  /opt/conda/envs/gdf/bin/python(+0x1407c2) [0x5648cbeb57c2]
29  /opt/conda/envs/gdf/bin/python(_PyEval_EvalFrameDefault+0x696) [0x5648cbea55c6]
30  /opt/conda/envs/gdf/bin/python(+0x12f094) [0x5648cbea4094]
31  /opt/conda/envs/gdf/bin/python(_PyFunction_Vectorcall+0xd9) [0x5648cbeb5519]
32  /opt/conda/envs/gdf/bin/python(_PyEval_EvalFrameDefault+0x11f8) [0x5648cbea6128]
33  /opt/conda/envs/gdf/bin/python(+0x12f094) [0x5648cbea4094]
34  /opt/conda/envs/gdf/bin/python(+0x14dccb) [0x5648cbec2ccb]
35  /opt/conda/envs/gdf/bin/python(PyObject_Call+0xbc) [0x5648cbec344c]
36  /opt/conda/envs/gdf/bin/python(+0x21110e) [0x5648cbf8610e]
37  /opt/conda/envs/gdf/bin/python(_PyObject_MakeTpCall+0x2ec) [0x5648cbead77c]
38  /opt/conda/envs/gdf/bin/python(_PyEval_EvalFrameDefault+0x37cb) [0x5648cbea86fb]
39  /opt/conda/envs/gdf/bin/python(+0x1407c2) [0x5648cbeb57c2]
40  /opt/conda/envs/gdf/bin/python(+0x14ddac) [0x5648cbec2dac]
41  /opt/conda/envs/gdf/bin/python(_PyEval_EvalFrameDefault+0x37cb) [0x5648cbea86fb]
42  /opt/conda/envs/gdf/bin/python(+0x1407c2) [0x5648cbeb57c2]
43  /opt/conda/envs/gdf/bin/python(_PyEval_EvalFrameDefault+0x696) [0x5648cbea55c6]
44  /opt/conda/envs/gdf/bin/python(+0x12f094) [0x5648cbea4094]
45  /opt/conda/envs/gdf/bin/python(_PyFunction_Vectorcall+0xd9) [0x5648cbeb5519]
46  /opt/conda/envs/gdf/bin/python(_PyEval_EvalFrameDefault+0x696) [0x5648cbea55c6]
47  /opt/conda/envs/gdf/bin/python(+0x1407c2) [0x5648cbeb57c2]
48  /opt/conda/envs/gdf/bin/python(_PyEval_EvalFrameDefault+0x3e2) [0x5648cbea5312]
49  /opt/conda/envs/gdf/bin/python(+0x12f094) [0x5648cbea4094]
50  /opt/conda/envs/gdf/bin/python(_PyFunction_Vectorcall+0xd9) [0x5648cbeb5519]
51  /opt/conda/envs/gdf/bin/python(_PyEval_EvalFrameDefault+0x11f8) [0x5648cbea6128]
52  /opt/conda/envs/gdf/bin/python(+0x12f094) [0x5648cbea4094]
53  /opt/conda/envs/gdf/bin/python(_PyEval_EvalCodeWithName+0x48) [0x5648cbea3d68]
54  /opt/conda/envs/gdf/bin/python(PyEval_EvalCodeEx+0x39) [0x5648cbea3d19]
55  /opt/conda/envs/gdf/bin/python(PyEval_EvalCode+0x1b) [0x5648cbf5107b]
56  /opt/conda/envs/gdf/bin/python(+0x208fca) [0x5648cbf7dfca]
57  /opt/conda/envs/gdf/bin/python(+0x205353) [0x5648cbf7a353]
58  /opt/conda/envs/gdf/bin/python(PyRun_StringFlags+0x9a) [0x5648cbf7216a]
59  /opt/conda/envs/gdf/bin/python(PyRun_SimpleStringFlags+0x3c) [0x5648cbf7205c]
60  /opt/conda/envs/gdf/bin/python(Py_RunMain+0x267) [0x5648cbf71297]
61  /opt/conda/envs/gdf/bin/python(Py_BytesMain+0x37) [0x5648cbf44f07]
=================================
2023-11-14 07:07:02,009 - distributed.worker - ERROR - failed during get data with ucx://127.0.0.1:54165 -> ucx://127.0.0.1:33573
Traceback (most recent call last):
  File "/opt/conda/envs/gdf/lib/python3.9/site-packages/distributed/comm/ucx.py", line 338, in write
    await self.ep.send(each_frame)
  File "/opt/conda/envs/gdf/lib/python3.9/site-packages/ucp/core.py", line 650, in send
    return await comm.tag_send(self._ep, buffer, nbytes, tag, name=log)
ucp._libs.exceptions.UCXError: <[Send #007] ep: 0x7f1f0953d100, tag: 0xf9a84d02b4520809, nbytes: 800000000, type: <class 'cudf.core.buffer.buffer.Buffer'>>: Connection reset by remote peer

During handling of the above exception, another exception occurred:

Traceback (most recent call last):
  File "/opt/conda/envs/gdf/lib/python3.9/site-packages/distributed/worker.py", line 1782, in get_data
    compressed = await comm.write(msg, serializers=serializers)
  File "/opt/conda/envs/gdf/lib/python3.9/site-packages/distributed/utils.py", line 803, in wrapper
    return await func(*args, **kwargs)
  File "/opt/conda/envs/gdf/lib/python3.9/site-packages/distributed/comm/ucx.py", line 342, in write
    raise CommClosedError("While writing, the connection was closed")
distributed.comm.core.CommClosedError: While writing, the connection was closed
2023-11-14 07:07:02,010 - distributed.worker - ERROR - failed during get data with ucx://127.0.0.1:33319 -> ucx://127.0.0.1:33573
Traceback (most recent call last):
  File "/opt/conda/envs/gdf/lib/python3.9/site-packages/distributed/comm/ucx.py", line 338, in write
    await self.ep.send(each_frame)
  File "/opt/conda/envs/gdf/lib/python3.9/site-packages/ucp/core.py", line 650, in send
    return await comm.tag_send(self._ep, buffer, nbytes, tag, name=log)
ucp._libs.exceptions.UCXError: <[Send #007] ep: 0x7f55d2d0b100, tag: 0x3cb8baf0b1f33dcc, nbytes: 800000000, type: <class 'cudf.core.buffer.buffer.Buffer'>>: Connection reset by remote peer

During handling of the above exception, another exception occurred:

Traceback (most recent call last):
  File "/opt/conda/envs/gdf/lib/python3.9/site-packages/distributed/worker.py", line 1782, in get_data
    compressed = await comm.write(msg, serializers=serializers)
  File "/opt/conda/envs/gdf/lib/python3.9/site-packages/distributed/utils.py", line 803, in wrapper
    return await func(*args, **kwargs)
  File "/opt/conda/envs/gdf/lib/python3.9/site-packages/distributed/comm/ucx.py", line 342, in write
    raise CommClosedError("While writing, the connection was closed")
distributed.comm.core.CommClosedError: While writing, the connection was closed
Task exception was never retrieved
future: <Task finished name='Task-781' coro=<_listener_handler_coroutine() done, defined at /opt/conda/envs/gdf/lib/python3.9/site-packages/ucp/core.py:128> exception=UCXError('<stream_send>: Connection reset by remote peer')>
Traceback (most recent call last):
  File "/opt/conda/envs/gdf/lib/python3.9/site-packages/ucp/core.py", line 143, in _listener_handler_coroutine
    peer_info = await exchange_peer_info(
  File "/opt/conda/envs/gdf/lib/python3.9/site-packages/ucp/core.py", line 51, in exchange_peer_info
    await comm.stream_send(endpoint, my_info_arr, my_info_arr.nbytes)
ucp._libs.exceptions.UCXError: <stream_send>: Connection reset by remote peer
[dgx13:73530:0:73530] Caught signal 11 (Segmentation fault: address not mapped to object at address 0x448)
==== backtrace (tid:  73530) ====
 0  /opt/conda/envs/gdf/lib/libucs.so.0(ucs_handle_error+0x2fd) [0x7f78ac43106d]
 1  /opt/conda/envs/gdf/lib/libucs.so.0(+0x2a264) [0x7f78ac431264]
 2  /opt/conda/envs/gdf/lib/libucs.so.0(+0x2a42a) [0x7f78ac43142a]
 3  /usr/lib/x86_64-linux-gnu/libpthread.so.0(+0x14420) [0x7f794d769420]
 4  /opt/conda/envs/gdf/lib/libucp.so.0(ucp_mem_type_unpack+0x14) [0x7f78ac4af6a4]
 5  /opt/conda/envs/gdf/lib/libucp.so.0(ucp_rndv_data_handler+0x4e9) [0x7f78ac4d8829]
 6  /opt/conda/envs/gdf/lib/./libuct.so.0(+0x2146f) [0x7f78ac3eb46f]
 7  /opt/conda/envs/gdf/lib/./libuct.so.0(+0x248c8) [0x7f78ac3ee8c8]
 8  /opt/conda/envs/gdf/lib/libucs.so.0(ucs_event_set_wait+0xb9) [0x7f78ac43a499]
 9  /opt/conda/envs/gdf/lib/./libuct.so.0(uct_tcp_iface_progress+0x7d) [0x7f78ac3ed66d]
10  /opt/conda/envs/gdf/lib/libucp.so.0(ucp_worker_progress+0x5a) [0x7f78ac4ac8ca]
11  /opt/conda/envs/gdf/lib/python3.9/site-packages/ucp/_libs/ucx_api.cpython-39-x86_64-linux-gnu.so(+0x3206a) [0x7f78ac56506a]
12  /opt/conda/envs/gdf/bin/python(_PyEval_EvalFrameDefault+0x37cb) [0x5571f0d676fb]
13  /opt/conda/envs/gdf/bin/python(+0x12f094) [0x5571f0d63094]
14  /opt/conda/envs/gdf/bin/python(_PyFunction_Vectorcall+0xd9) [0x5571f0d74519]
15  /opt/conda/envs/gdf/bin/python(_PyEval_EvalFrameDefault+0x696) [0x5571f0d645c6]
16  /opt/conda/envs/gdf/bin/python(+0x1e3162) [0x5571f0e17162]
17  /opt/conda/envs/gdf/lib/python3.9/lib-dynload/_asyncio.cpython-39-x86_64-linux-gnu.so(+0x81e9) [0x7f79437901e9]
18  /opt/conda/envs/gdf/bin/python(_PyObject_MakeTpCall+0x2ec) [0x5571f0d6c77c]
19  /opt/conda/envs/gdf/bin/python(+0xead05) [0x5571f0d1ed05]
20  /opt/conda/envs/gdf/bin/python(+0x1377f3) [0x5571f0d6b7f3]
21  /opt/conda/envs/gdf/bin/python(_PyEval_EvalFrameDefault+0x59f9) [0x5571f0d69929]
22  /opt/conda/envs/gdf/bin/python(+0x1407c2) [0x5571f0d747c2]
23  /opt/conda/envs/gdf/bin/python(_PyEval_EvalFrameDefault+0x696) [0x5571f0d645c6]
24  /opt/conda/envs/gdf/bin/python(+0x1407c2) [0x5571f0d747c2]
25  /opt/conda/envs/gdf/bin/python(_PyEval_EvalFrameDefault+0x696) [0x5571f0d645c6]
26  /opt/conda/envs/gdf/bin/python(+0x1407c2) [0x5571f0d747c2]
27  /opt/conda/envs/gdf/bin/python(_PyEval_EvalFrameDefault+0x696) [0x5571f0d645c6]
28  /opt/conda/envs/gdf/bin/python(+0x1407c2) [0x5571f0d747c2]
29  /opt/conda/envs/gdf/bin/python(_PyEval_EvalFrameDefault+0x696) [0x5571f0d645c6]
30  /opt/conda/envs/gdf/bin/python(+0x12f094) [0x5571f0d63094]
31  /opt/conda/envs/gdf/bin/python(_PyFunction_Vectorcall+0xd9) [0x5571f0d74519]
32  /opt/conda/envs/gdf/bin/python(_PyEval_EvalFrameDefault+0x11f8) [0x5571f0d65128]
33  /opt/conda/envs/gdf/bin/python(+0x12f094) [0x5571f0d63094]
34  /opt/conda/envs/gdf/bin/python(+0x14dccb) [0x5571f0d81ccb]
35  /opt/conda/envs/gdf/bin/python(PyObject_Call+0xbc) [0x5571f0d8244c]
36  /opt/conda/envs/gdf/bin/python(+0x21110e) [0x5571f0e4510e]
37  /opt/conda/envs/gdf/bin/python(_PyObject_MakeTpCall+0x2ec) [0x5571f0d6c77c]
38  /opt/conda/envs/gdf/bin/python(_PyEval_EvalFrameDefault+0x37cb) [0x5571f0d676fb]
39  /opt/conda/envs/gdf/bin/python(+0x1407c2) [0x5571f0d747c2]
40  /opt/conda/envs/gdf/bin/python(+0x14ddac) [0x5571f0d81dac]
41  /opt/conda/envs/gdf/bin/python(_PyEval_EvalFrameDefault+0x37cb) [0x5571f0d676fb]
42  /opt/conda/envs/gdf/bin/python(+0x1407c2) [0x5571f0d747c2]
43  /opt/conda/envs/gdf/bin/python(_PyEval_EvalFrameDefault+0x696) [0x5571f0d645c6]
44  /opt/conda/envs/gdf/bin/python(+0x12f094) [0x5571f0d63094]
45  /opt/conda/envs/gdf/bin/python(_PyFunction_Vectorcall+0xd9) [0x5571f0d74519]
46  /opt/conda/envs/gdf/bin/python(_PyEval_EvalFrameDefault+0x696) [0x5571f0d645c6]
47  /opt/conda/envs/gdf/bin/python(+0x1407c2) [0x5571f0d747c2]
48  /opt/conda/envs/gdf/bin/python(_PyEval_EvalFrameDefault+0x3e2) [0x5571f0d64312]
49  /opt/conda/envs/gdf/bin/python(+0x12f094) [0x5571f0d63094]
50  /opt/conda/envs/gdf/bin/python(_PyFunction_Vectorcall+0xd9) [0x5571f0d74519]
51  /opt/conda/envs/gdf/bin/python(_PyEval_EvalFrameDefault+0x11f8) [0x5571f0d65128]
52  /opt/conda/envs/gdf/bin/python(+0x12f094) [0x5571f0d63094]
53  /opt/conda/envs/gdf/bin/python(_PyEval_EvalCodeWithName+0x48) [0x5571f0d62d68]
54  /opt/conda/envs/gdf/bin/python(PyEval_EvalCodeEx+0x39) [0x5571f0d62d19]
55  /opt/conda/envs/gdf/bin/python(PyEval_EvalCode+0x1b) [0x5571f0e1007b]
56  /opt/conda/envs/gdf/bin/python(+0x208fca) [0x5571f0e3cfca]
57  /opt/conda/envs/gdf/bin/python(+0x205353) [0x5571f0e39353]
58  /opt/conda/envs/gdf/bin/python(PyRun_StringFlags+0x9a) [0x5571f0e3116a]
59  /opt/conda/envs/gdf/bin/python(PyRun_SimpleStringFlags+0x3c) [0x5571f0e3105c]
60  /opt/conda/envs/gdf/bin/python(Py_RunMain+0x267) [0x5571f0e30297]
61  /opt/conda/envs/gdf/bin/python(Py_BytesMain+0x37) [0x5571f0e03f07]
=================================
[dgx13:73534:0:73534] Caught signal 11 (Segmentation fault: address not mapped to object at address 0x448)
[dgx13:73543:0:73543] Caught signal 11 (Segmentation fault: address not mapped to object at address 0x448)
==== backtrace (tid:  73534) ====
 0  /opt/conda/envs/gdf/lib/libucs.so.0(ucs_handle_error+0x2fd) [0x7f329d2e406d]
 1  /opt/conda/envs/gdf/lib/libucs.so.0(+0x2a264) [0x7f329d2e4264]
 2  /opt/conda/envs/gdf/lib/libucs.so.0(+0x2a42a) [0x7f329d2e442a]
 3  /usr/lib/x86_64-linux-gnu/libpthread.so.0(+0x14420) [0x7f3342635420]
 4  /opt/conda/envs/gdf/lib/libucp.so.0(ucp_mem_type_unpack+0x14) [0x7f329d3626a4]
 5  /opt/conda/envs/gdf/lib/libucp.so.0(ucp_rndv_data_handler+0x4e9) [0x7f329d38b829]
 6  /opt/conda/envs/gdf/lib/./libuct.so.0(+0x2146f) [0x7f329d29e46f]
 7  /opt/conda/envs/gdf/lib/./libuct.so.0(+0x248c8) [0x7f329d2a18c8]
 8  /opt/conda/envs/gdf/lib/libucs.so.0(ucs_event_set_wait+0xb9) [0x7f329d2ed499]
 9  /opt/conda/envs/gdf/lib/./libuct.so.0(uct_tcp_iface_progress+0x7d) [0x7f329d2a066d]
10  /opt/conda/envs/gdf/lib/libucp.so.0(ucp_worker_progress+0x5a) [0x7f329d35f8ca]
11  /opt/conda/envs/gdf/lib/python3.9/site-packages/ucp/_libs/ucx_api.cpython-39-x86_64-linux-gnu.so(+0x3206a) [0x7f329d41806a]
12  /opt/conda/envs/gdf/bin/python(_PyEval_EvalFrameDefault+0x37cb) [0x5561f365a6fb]
13  /opt/conda/envs/gdf/bin/python(+0x12f094) [0x5561f3656094]
14  /opt/conda/envs/gdf/bin/python(_PyFunction_Vectorcall+0xd9) [0x5561f3667519]
15  /opt/conda/envs/gdf/bin/python(_PyEval_EvalFrameDefault+0x696) [0x5561f36575c6]
16  /opt/conda/envs/gdf/bin/python(+0x1e3162) [0x5561f370a162]
17  /opt/conda/envs/gdf/lib/python3.9/lib-dynload/_asyncio.cpython-39-x86_64-linux-gnu.so(+0x81e9) [0x7f333865f1e9]
18  /opt/conda/envs/gdf/bin/python(_PyObject_MakeTpCall+0x2ec) [0x5561f365f77c]
19  /opt/conda/envs/gdf/bin/python(+0xead05) [0x5561f3611d05]
20  /opt/conda/envs/gdf/bin/python(+0x1377f3) [0x5561f365e7f3]
21  /opt/conda/envs/gdf/bin/python(_PyEval_EvalFrameDefault+0x59f9) [0x5561f365c929]
22  /opt/conda/envs/gdf/bin/python(+0x1407c2) [0x5561f36677c2]
23  /opt/conda/envs/gdf/bin/python(_PyEval_EvalFrameDefault+0x696) [0x5561f36575c6]
24  /opt/conda/envs/gdf/bin/python(+0x1407c2) [0x5561f36677c2]
25  /opt/conda/envs/gdf/bin/python(_PyEval_EvalFrameDefault+0x696) [0x5561f36575c6]
26  /opt/conda/envs/gdf/bin/python(+0x1407c2) [0x5561f36677c2]
27  /opt/conda/envs/gdf/bin/python(_PyEval_EvalFrameDefault+0x696) [0x5561f36575c6]
28  /opt/conda/envs/gdf/bin/python(+0x1407c2) [0x5561f36677c2]
29  /opt/conda/envs/gdf/bin/python(_PyEval_EvalFrameDefault+0x696) [0x5561f36575c6]
30  /opt/conda/envs/gdf/bin/python(+0x12f094) [0x5561f3656094]
31  /opt/conda/envs/gdf/bin/python(_PyFunction_Vectorcall+0xd9) [0x5561f3667519]
32  /opt/conda/envs/gdf/bin/python(_PyEval_EvalFrameDefault+0x11f8) [0x5561f3658128]
33  /opt/conda/envs/gdf/bin/python(+0x12f094) [0x5561f3656094]
34  /opt/conda/envs/gdf/bin/python(+0x14dccb) [0x5561f3674ccb]
35  /opt/conda/envs/gdf/bin/python(PyObject_Call+0xbc) [0x5561f367544c]
36  /opt/conda/envs/gdf/bin/python(+0x21110e) [0x5561f373810e]
37  /opt/conda/envs/gdf/bin/python(_PyObject_MakeTpCall+0x2ec) [0x5561f365f77c]
38  /opt/conda/envs/gdf/bin/python(_PyEval_EvalFrameDefault+0x37cb) [0x5561f365a6fb]
39  /opt/conda/envs/gdf/bin/python(+0x1407c2) [0x5561f36677c2]
40  /opt/conda/envs/gdf/bin/python(+0x14ddac) [0x5561f3674dac]
41  /opt/conda/envs/gdf/bin/python(_PyEval_EvalFrameDefault+0x37cb) [0x5561f365a6fb]
42  /opt/conda/envs/gdf/bin/python(+0x1407c2) [0x5561f36677c2]
43  /opt/conda/envs/gdf/bin/python(_PyEval_EvalFrameDefault+0x696) [0x5561f36575c6]
44  /opt/conda/envs/gdf/bin/python(+0x12f094) [0x5561f3656094]
45  /opt/conda/envs/gdf/bin/python(_PyFunction_Vectorcall+0xd9) [0x5561f3667519]
46  /opt/conda/envs/gdf/bin/python(_PyEval_EvalFrameDefault+0x696) [0x5561f36575c6]
47  /opt/conda/envs/gdf/bin/python(+0x1407c2) [0x5561f36677c2]
48  /opt/conda/envs/gdf/bin/python(_PyEval_EvalFrameDefault+0x3e2) [0x5561f3657312]
49  /opt/conda/envs/gdf/bin/python(+0x12f094) [0x5561f3656094]
50  /opt/conda/envs/gdf/bin/python(_PyFunction_Vectorcall+0xd9) [0x5561f3667519]
51  /opt/conda/envs/gdf/bin/python(_PyEval_EvalFrameDefault+0x11f8) [0x5561f3658128]
52  /opt/conda/envs/gdf/bin/python(+0x12f094) [0x5561f3656094]
53  /opt/conda/envs/gdf/bin/python(_PyEval_EvalCodeWithName+0x48) [0x5561f3655d68]
54  /opt/conda/envs/gdf/bin/python(PyEval_EvalCodeEx+0x39) [0x5561f3655d19]
55  /opt/conda/envs/gdf/bin/python(PyEval_EvalCode+0x1b) [0x5561f370307b]
56  /opt/conda/envs/gdf/bin/python(+0x208fca) [0x5561f372ffca]
57  /opt/conda/envs/gdf/bin/python(+0x205353) [0x5561f372c353]
58  /opt/conda/envs/gdf/bin/python(PyRun_StringFlags+0x9a) [0x5561f372416a]
59  /opt/conda/envs/gdf/bin/python(PyRun_SimpleStringFlags+0x3c) [0x5561f372405c]
60  /opt/conda/envs/gdf/bin/python(Py_RunMain+0x267) [0x5561f3723297]
61  /opt/conda/envs/gdf/bin/python(Py_BytesMain+0x37) [0x5561f36f6f07]
=================================
==== backtrace (tid:  73543) ====
 0  /opt/conda/envs/gdf/lib/libucs.so.0(ucs_handle_error+0x2fd) [0x7f1f1c04906d]
 1  /opt/conda/envs/gdf/lib/libucs.so.0(+0x2a264) [0x7f1f1c049264]
 2  /opt/conda/envs/gdf/lib/libucs.so.0(+0x2a42a) [0x7f1f1c04942a]
 3  /usr/lib/x86_64-linux-gnu/libpthread.so.0(+0x14420) [0x7f1faf377420]
 4  /opt/conda/envs/gdf/lib/libucp.so.0(ucp_mem_type_unpack+0x14) [0x7f1f1c0c76a4]
 5  /opt/conda/envs/gdf/lib/libucp.so.0(ucp_rndv_data_handler+0x4e9) [0x7f1f1c0f0829]
 6  /opt/conda/envs/gdf/lib/./libuct.so.0(+0x2146f) [0x7f1f09fe446f]
 7  /opt/conda/envs/gdf/lib/./libuct.so.0(+0x248c8) [0x7f1f09fe78c8]
 8  /opt/conda/envs/gdf/lib/libucs.so.0(ucs_event_set_wait+0xb9) [0x7f1f1c052499]
 9  /opt/conda/envs/gdf/lib/./libuct.so.0(uct_tcp_iface_progress+0x7d) [0x7f1f09fe666d]
10  /opt/conda/envs/gdf/lib/libucp.so.0(ucp_worker_progress+0x5a) [0x7f1f1c0c48ca]
11  /opt/conda/envs/gdf/lib/python3.9/site-packages/ucp/_libs/ucx_api.cpython-39-x86_64-linux-gnu.so(+0x3206a) [0x7f1f1c17d06a]
12  /opt/conda/envs/gdf/bin/python(_PyEval_EvalFrameDefault+0x37cb) [0x564e2befc6fb]
13  /opt/conda/envs/gdf/bin/python(+0x12f094) [0x564e2bef8094]
14  /opt/conda/envs/gdf/bin/python(_PyFunction_Vectorcall+0xd9) [0x564e2bf09519]
15  /opt/conda/envs/gdf/bin/python(_PyEval_EvalFrameDefault+0x696) [0x564e2bef95c6]
16  /opt/conda/envs/gdf/bin/python(+0x1e3162) [0x564e2bfac162]
17  /opt/conda/envs/gdf/lib/python3.9/lib-dynload/_asyncio.cpython-39-x86_64-linux-gnu.so(+0x81e9) [0x7f1fa53901e9]
18  /opt/conda/envs/gdf/bin/python(_PyObject_MakeTpCall+0x2ec) [0x564e2bf0177c]
19  /opt/conda/envs/gdf/bin/python(+0xead05) [0x564e2beb3d05]
20  /opt/conda/envs/gdf/bin/python(+0x1377f3) [0x564e2bf007f3]
21  /opt/conda/envs/gdf/bin/python(_PyEval_EvalFrameDefault+0x59f9) [0x564e2befe929]
22  /opt/conda/envs/gdf/bin/python(+0x1407c2) [0x564e2bf097c2]
23  /opt/conda/envs/gdf/bin/python(_PyEval_EvalFrameDefault+0x696) [0x564e2bef95c6]
24  /opt/conda/envs/gdf/bin/python(+0x1407c2) [0x564e2bf097c2]
25  /opt/conda/envs/gdf/bin/python(_PyEval_EvalFrameDefault+0x696) [0x564e2bef95c6]
26  /opt/conda/envs/gdf/bin/python(+0x1407c2) [0x564e2bf097c2]
27  /opt/conda/envs/gdf/bin/python(_PyEval_EvalFrameDefault+0x696) [0x564e2bef95c6]
28  /opt/conda/envs/gdf/bin/python(+0x1407c2) [0x564e2bf097c2]
29  /opt/conda/envs/gdf/bin/python(_PyEval_EvalFrameDefault+0x696) [0x564e2bef95c6]
30  /opt/conda/envs/gdf/bin/python(+0x12f094) [0x564e2bef8094]
31  /opt/conda/envs/gdf/bin/python(_PyFunction_Vectorcall+0xd9) [0x564e2bf09519]
32  /opt/conda/envs/gdf/bin/python(_PyEval_EvalFrameDefault+0x11f8) [0x564e2befa128]
33  /opt/conda/envs/gdf/bin/python(+0x12f094) [0x564e2bef8094]
34  /opt/conda/envs/gdf/bin/python(+0x14dccb) [0x564e2bf16ccb]
35  /opt/conda/envs/gdf/bin/python(PyObject_Call+0xbc) [0x564e2bf1744c]
36  /opt/conda/envs/gdf/bin/python(+0x21110e) [0x564e2bfda10e]
37  /opt/conda/envs/gdf/bin/python(_PyObject_MakeTpCall+0x2ec) [0x564e2bf0177c]
38  /opt/conda/envs/gdf/bin/python(_PyEval_EvalFrameDefault+0x37cb) [0x564e2befc6fb]
39  /opt/conda/envs/gdf/bin/python(+0x1407c2) [0x564e2bf097c2]
40  /opt/conda/envs/gdf/bin/python(+0x14ddac) [0x564e2bf16dac]
41  /opt/conda/envs/gdf/bin/python(_PyEval_EvalFrameDefault+0x37cb) [0x564e2befc6fb]
42  /opt/conda/envs/gdf/bin/python(+0x1407c2) [0x564e2bf097c2]
43  /opt/conda/envs/gdf/bin/python(_PyEval_EvalFrameDefault+0x696) [0x564e2bef95c6]
44  /opt/conda/envs/gdf/bin/python(+0x12f094) [0x564e2bef8094]
45  /opt/conda/envs/gdf/bin/python(_PyFunction_Vectorcall+0xd9) [0x564e2bf09519]
46  /opt/conda/envs/gdf/bin/python(_PyEval_EvalFrameDefault+0x696) [0x564e2bef95c6]
47  /opt/conda/envs/gdf/bin/python(+0x1407c2) [0x564e2bf097c2]
48  /opt/conda/envs/gdf/bin/python(_PyEval_EvalFrameDefault+0x3e2) [0x564e2bef9312]
49  /opt/conda/envs/gdf/bin/python(+0x12f094) [0x564e2bef8094]
50  /opt/conda/envs/gdf/bin/python(_PyFunction_Vectorcall+0xd9) [0x564e2bf09519]
51  /opt/conda/envs/gdf/bin/python(_PyEval_EvalFrameDefault+0x11f8) [0x564e2befa128]
52  /opt/conda/envs/gdf/bin/python(+0x12f094) [0x564e2bef8094]
53  /opt/conda/envs/gdf/bin/python(_PyEval_EvalCodeWithName+0x48) [0x564e2bef7d68]
54  /opt/conda/envs/gdf/bin/python(PyEval_EvalCodeEx+0x39) [0x564e2bef7d19]
55  /opt/conda/envs/gdf/bin/python(PyEval_EvalCode+0x1b) [0x564e2bfa507b]
56  /opt/conda/envs/gdf/bin/python(+0x208fca) [0x564e2bfd1fca]
57  /opt/conda/envs/gdf/bin/python(+0x205353) [0x564e2bfce353]
58  /opt/conda/envs/gdf/bin/python(PyRun_StringFlags+0x9a) [0x564e2bfc616a]
59  /opt/conda/envs/gdf/bin/python(PyRun_SimpleStringFlags+0x3c) [0x564e2bfc605c]
60  /opt/conda/envs/gdf/bin/python(Py_RunMain+0x267) [0x564e2bfc5297]
61  /opt/conda/envs/gdf/bin/python(Py_BytesMain+0x37) [0x564e2bf98f07]
=================================
[dgx13:73522:0:73522] Caught signal 11 (Segmentation fault: address not mapped to object at address 0x448)
==== backtrace (tid:  73522) ====
 0  /opt/conda/envs/gdf/lib/libucs.so.0(ucs_handle_error+0x2fd) [0x7f9dc8a0706d]
 1  /opt/conda/envs/gdf/lib/libucs.so.0(+0x2a264) [0x7f9dc8a07264]
 2  /opt/conda/envs/gdf/lib/libucs.so.0(+0x2a42a) [0x7f9dc8a0742a]
 3  /usr/lib/x86_64-linux-gnu/libpthread.so.0(+0x14420) [0x7f9e5bd42420]
 4  /opt/conda/envs/gdf/lib/libucp.so.0(ucp_mem_type_unpack+0x14) [0x7f9dc8a856a4]
 5  /opt/conda/envs/gdf/lib/libucp.so.0(ucp_rndv_data_handler+0x4e9) [0x7f9dc8aae829]
 6  /opt/conda/envs/gdf/lib/./libuct.so.0(+0x2146f) [0x7f9dc89c146f]
 7  /opt/conda/envs/gdf/lib/./libuct.so.0(+0x248c8) [0x7f9dc89c48c8]
 8  /opt/conda/envs/gdf/lib/libucs.so.0(ucs_event_set_wait+0xb9) [0x7f9dc8a10499]
 9  /opt/conda/envs/gdf/lib/./libuct.so.0(uct_tcp_iface_progress+0x7d) [0x7f9dc89c366d]
10  /opt/conda/envs/gdf/lib/libucp.so.0(ucp_worker_progress+0x5a) [0x7f9dc8a828ca]
11  /opt/conda/envs/gdf/lib/python3.9/site-packages/ucp/_libs/ucx_api.cpython-39-x86_64-linux-gnu.so(+0x3206a) [0x7f9dc8b3b06a]
12  /opt/conda/envs/gdf/bin/python(_PyEval_EvalFrameDefault+0x37cb) [0x5563653496fb]
13  /opt/conda/envs/gdf/bin/python(+0x12f094) [0x556365345094]
14  /opt/conda/envs/gdf/bin/python(_PyFunction_Vectorcall+0xd9) [0x556365356519]
15  /opt/conda/envs/gdf/bin/python(_PyEval_EvalFrameDefault+0x696) [0x5563653465c6]
16  /opt/conda/envs/gdf/bin/python(+0x1e3162) [0x5563653f9162]
17  /opt/conda/envs/gdf/lib/python3.9/lib-dynload/_asyncio.cpython-39-x86_64-linux-gnu.so(+0x81e9) [0x7f9e51d851e9]
18  /opt/conda/envs/gdf/bin/python(_PyObject_MakeTpCall+0x2ec) [0x55636534e77c]
19  /opt/conda/envs/gdf/bin/python(+0xead05) [0x556365300d05]
20  /opt/conda/envs/gdf/bin/python(+0x1377f3) [0x55636534d7f3]
21  /opt/conda/envs/gdf/bin/python(_PyEval_EvalFrameDefault+0x59f9) [0x55636534b929]
22  /opt/conda/envs/gdf/bin/python(+0x1407c2) [0x5563653567c2]
23  /opt/conda/envs/gdf/bin/python(_PyEval_EvalFrameDefault+0x696) [0x5563653465c6]
24  /opt/conda/envs/gdf/bin/python(+0x1407c2) [0x5563653567c2]
25  /opt/conda/envs/gdf/bin/python(_PyEval_EvalFrameDefault+0x696) [0x5563653465c6]
26  /opt/conda/envs/gdf/bin/python(+0x1407c2) [0x5563653567c2]
27  /opt/conda/envs/gdf/bin/python(_PyEval_EvalFrameDefault+0x696) [0x5563653465c6]
28  /opt/conda/envs/gdf/bin/python(+0x1407c2) [0x5563653567c2]
29  /opt/conda/envs/gdf/bin/python(_PyEval_EvalFrameDefault+0x696) [0x5563653465c6]
30  /opt/conda/envs/gdf/bin/python(+0x12f094) [0x556365345094]
31  /opt/conda/envs/gdf/bin/python(_PyFunction_Vectorcall+0xd9) [0x556365356519]
32  /opt/conda/envs/gdf/bin/python(_PyEval_EvalFrameDefault+0x11f8) [0x556365347128]
33  /opt/conda/envs/gdf/bin/python(+0x12f094) [0x556365345094]
34  /opt/conda/envs/gdf/bin/python(+0x14dccb) [0x556365363ccb]
35  /opt/conda/envs/gdf/bin/python(PyObject_Call+0xbc) [0x55636536444c]
36  /opt/conda/envs/gdf/bin/python(+0x21110e) [0x55636542710e]
37  /opt/conda/envs/gdf/bin/python(_PyObject_MakeTpCall+0x2ec) [0x55636534e77c]
38  /opt/conda/envs/gdf/bin/python(_PyEval_EvalFrameDefault+0x37cb) [0x5563653496fb]
39  /opt/conda/envs/gdf/bin/python(+0x1407c2) [0x5563653567c2]
40  /opt/conda/envs/gdf/bin/python(+0x14ddac) [0x556365363dac]
41  /opt/conda/envs/gdf/bin/python(_PyEval_EvalFrameDefault+0x37cb) [0x5563653496fb]
42  /opt/conda/envs/gdf/bin/python(+0x1407c2) [0x5563653567c2]
43  /opt/conda/envs/gdf/bin/python(_PyEval_EvalFrameDefault+0x696) [0x5563653465c6]
44  /opt/conda/envs/gdf/bin/python(+0x12f094) [0x556365345094]
45  /opt/conda/envs/gdf/bin/python(_PyFunction_Vectorcall+0xd9) [0x556365356519]
46  /opt/conda/envs/gdf/bin/python(_PyEval_EvalFrameDefault+0x696) [0x5563653465c6]
47  /opt/conda/envs/gdf/bin/python(+0x1407c2) [0x5563653567c2]
48  /opt/conda/envs/gdf/bin/python(_PyEval_EvalFrameDefault+0x3e2) [0x556365346312]
49  /opt/conda/envs/gdf/bin/python(+0x12f094) [0x556365345094]
50  /opt/conda/envs/gdf/bin/python(_PyFunction_Vectorcall+0xd9) [0x556365356519]
51  /opt/conda/envs/gdf/bin/python(_PyEval_EvalFrameDefault+0x11f8) [0x556365347128]
52  /opt/conda/envs/gdf/bin/python(+0x12f094) [0x556365345094]
53  /opt/conda/envs/gdf/bin/python(_PyEval_EvalCodeWithName+0x48) [0x556365344d68]
54  /opt/conda/envs/gdf/bin/python(PyEval_EvalCodeEx+0x39) [0x556365344d19]
55  /opt/conda/envs/gdf/bin/python(PyEval_EvalCode+0x1b) [0x5563653f207b]
56  /opt/conda/envs/gdf/bin/python(+0x208fca) [0x55636541efca]
57  /opt/conda/envs/gdf/bin/python(+0x205353) [0x55636541b353]
58  /opt/conda/envs/gdf/bin/python(PyRun_StringFlags+0x9a) [0x55636541316a]
59  /opt/conda/envs/gdf/bin/python(PyRun_SimpleStringFlags+0x3c) [0x55636541305c]
60  /opt/conda/envs/gdf/bin/python(Py_RunMain+0x267) [0x556365412297]
61  /opt/conda/envs/gdf/bin/python(Py_BytesMain+0x37) [0x5563653e5f07]
=================================
2023-11-14 07:07:04,971 - distributed.worker - ERROR - Worker stream died during communication: ucx://127.0.0.1:54165
Traceback (most recent call last):
  File "/opt/conda/envs/gdf/lib/python3.9/site-packages/distributed/comm/ucx.py", line 354, in read
    await self.ep.recv(msg)
  File "/opt/conda/envs/gdf/lib/python3.9/site-packages/ucp/core.py", line 725, in recv
    ret = await comm.tag_recv(self._ep, buffer, nbytes, tag, name=log)
ucp._libs.exceptions.UCXCanceled: <[Recv #000] ep: 0x7f2f115b1200, tag: 0x5d38d68f6c4154ac, nbytes: 16, type: <class 'numpy.ndarray'>>: 

During handling of the above exception, another exception occurred:

Traceback (most recent call last):
  File "/opt/conda/envs/gdf/lib/python3.9/site-packages/distributed/worker.py", line 2059, in gather_dep
    response = await get_data_from_worker(
  File "/opt/conda/envs/gdf/lib/python3.9/site-packages/distributed/worker.py", line 2849, in get_data_from_worker
    comm = await rpc.connect(worker)
  File "/opt/conda/envs/gdf/lib/python3.9/site-packages/distributed/core.py", line 1626, in connect
    return connect_attempt.result()
  File "/opt/conda/envs/gdf/lib/python3.9/site-packages/distributed/core.py", line 1516, in _connect
    comm = await connect(
  File "/opt/conda/envs/gdf/lib/python3.9/site-packages/distributed/comm/core.py", line 377, in connect
    handshake = await comm.read()
  File "/opt/conda/envs/gdf/lib/python3.9/site-packages/distributed/utils.py", line 803, in wrapper
    return await func(*args, **kwargs)
  File "/opt/conda/envs/gdf/lib/python3.9/site-packages/distributed/comm/ucx.py", line 372, in read
    raise CommClosedError(
distributed.comm.core.CommClosedError: Connection closed by writer.
Inner exception: UCXCanceled("<[Recv #000] ep: 0x7f2f115b1200, tag: 0x5d38d68f6c4154ac, nbytes: 16, type: <class 'numpy.ndarray'>>: ")
2023-11-14 07:07:04,976 - distributed.worker - ERROR - Worker stream died during communication: ucx://127.0.0.1:54165
Traceback (most recent call last):
  File "/opt/conda/envs/gdf/lib/python3.9/site-packages/distributed/comm/ucx.py", line 471, in connect
    ep = await ucp.create_endpoint(ip, port)
  File "/opt/conda/envs/gdf/lib/python3.9/site-packages/ucp/core.py", line 1004, in create_endpoint
    return await _get_ctx().create_endpoint(
  File "/opt/conda/envs/gdf/lib/python3.9/site-packages/ucp/core.py", line 316, in create_endpoint
    peer_info = await exchange_peer_info(
  File "/opt/conda/envs/gdf/lib/python3.9/site-packages/ucp/core.py", line 54, in exchange_peer_info
    await comm.stream_recv(endpoint, peer_info_arr, peer_info_arr.nbytes)
ucp._libs.exceptions.UCXNotConnected: <stream_recv>: 

During handling of the above exception, another exception occurred:

Traceback (most recent call last):
  File "/opt/conda/envs/gdf/lib/python3.9/site-packages/distributed/comm/core.py", line 342, in connect
    comm = await wait_for(
  File "/opt/conda/envs/gdf/lib/python3.9/site-packages/distributed/utils.py", line 1920, in wait_for
    return await asyncio.wait_for(fut, timeout)
  File "/opt/conda/envs/gdf/lib/python3.9/asyncio/tasks.py", line 479, in wait_for
    return fut.result()
  File "/opt/conda/envs/gdf/lib/python3.9/site-packages/distributed/comm/ucx.py", line 473, in connect
    raise CommClosedError("Connection closed before handshake completed")
distributed.comm.core.CommClosedError: Connection closed before handshake completed

During handling of the above exception, another exception occurred:

Traceback (most recent call last):
  File "/opt/conda/envs/gdf/lib/python3.9/site-packages/distributed/core.py", line 1516, in _connect
    comm = await connect(
  File "/opt/conda/envs/gdf/lib/python3.9/site-packages/distributed/comm/core.py", line 366, in connect
    await asyncio.sleep(backoff)
  File "/opt/conda/envs/gdf/lib/python3.9/asyncio/tasks.py", line 652, in sleep
    return await future
asyncio.exceptions.CancelledError

During handling of the above exception, another exception occurred:

Traceback (most recent call last):
  File "/opt/conda/envs/gdf/lib/python3.9/site-packages/distributed/core.py", line 1626, in connect
    return connect_attempt.result()
asyncio.exceptions.CancelledError

During handling of the above exception, another exception occurred:

Traceback (most recent call last):
  File "/opt/conda/envs/gdf/lib/python3.9/site-packages/distributed/worker.py", line 2059, in gather_dep
    response = await get_data_from_worker(
  File "/opt/conda/envs/gdf/lib/python3.9/site-packages/distributed/worker.py", line 2849, in get_data_from_worker
    comm = await rpc.connect(worker)
  File "/opt/conda/envs/gdf/lib/python3.9/site-packages/distributed/core.py", line 1628, in connect
    raise CommClosedError(reason)
distributed.comm.core.CommClosedError: Address removed.
2023-11-14 07:07:05,028 - distributed.worker - ERROR - Worker stream died during communication: ucx://127.0.0.1:45471
Traceback (most recent call last):
  File "/opt/conda/envs/gdf/lib/python3.9/site-packages/distributed/comm/ucx.py", line 354, in read
    await self.ep.recv(msg)
  File "/opt/conda/envs/gdf/lib/python3.9/site-packages/ucp/core.py", line 725, in recv
    ret = await comm.tag_recv(self._ep, buffer, nbytes, tag, name=log)
ucp._libs.exceptions.UCXCanceled: <[Recv #000] ep: 0x7f2f115b1240, tag: 0x808b33a0df9afe85, nbytes: 16, type: <class 'numpy.ndarray'>>: 

During handling of the above exception, another exception occurred:

Traceback (most recent call last):
  File "/opt/conda/envs/gdf/lib/python3.9/site-packages/distributed/worker.py", line 2059, in gather_dep
    response = await get_data_from_worker(
  File "/opt/conda/envs/gdf/lib/python3.9/site-packages/distributed/worker.py", line 2849, in get_data_from_worker
    comm = await rpc.connect(worker)
  File "/opt/conda/envs/gdf/lib/python3.9/site-packages/distributed/core.py", line 1626, in connect
    return connect_attempt.result()
  File "/opt/conda/envs/gdf/lib/python3.9/site-packages/distributed/core.py", line 1516, in _connect
    comm = await connect(
  File "/opt/conda/envs/gdf/lib/python3.9/site-packages/distributed/comm/core.py", line 377, in connect
    handshake = await comm.read()
  File "/opt/conda/envs/gdf/lib/python3.9/site-packages/distributed/utils.py", line 803, in wrapper
    return await func(*args, **kwargs)
  File "/opt/conda/envs/gdf/lib/python3.9/site-packages/distributed/comm/ucx.py", line 372, in read
    raise CommClosedError(
distributed.comm.core.CommClosedError: Connection closed by writer.
Inner exception: UCXCanceled("<[Recv #000] ep: 0x7f2f115b1240, tag: 0x808b33a0df9afe85, nbytes: 16, type: <class 'numpy.ndarray'>>: ")
2023-11-14 07:07:05,032 - distributed.worker - ERROR - Worker stream died during communication: ucx://127.0.0.1:45471
Traceback (most recent call last):
  File "/opt/conda/envs/gdf/lib/python3.9/site-packages/distributed/comm/ucx.py", line 471, in connect
    ep = await ucp.create_endpoint(ip, port)
  File "/opt/conda/envs/gdf/lib/python3.9/site-packages/ucp/core.py", line 1004, in create_endpoint
    return await _get_ctx().create_endpoint(
  File "/opt/conda/envs/gdf/lib/python3.9/site-packages/ucp/core.py", line 316, in create_endpoint
    peer_info = await exchange_peer_info(
  File "/opt/conda/envs/gdf/lib/python3.9/site-packages/ucp/core.py", line 54, in exchange_peer_info
    await comm.stream_recv(endpoint, peer_info_arr, peer_info_arr.nbytes)
ucp._libs.exceptions.UCXNotConnected: <stream_recv>: 

During handling of the above exception, another exception occurred:

Traceback (most recent call last):
  File "/opt/conda/envs/gdf/lib/python3.9/site-packages/distributed/comm/core.py", line 342, in connect
    comm = await wait_for(
  File "/opt/conda/envs/gdf/lib/python3.9/site-packages/distributed/utils.py", line 1920, in wait_for
    return await asyncio.wait_for(fut, timeout)
  File "/opt/conda/envs/gdf/lib/python3.9/asyncio/tasks.py", line 479, in wait_for
    return fut.result()
  File "/opt/conda/envs/gdf/lib/python3.9/site-packages/distributed/comm/ucx.py", line 473, in connect
    raise CommClosedError("Connection closed before handshake completed")
distributed.comm.core.CommClosedError: Connection closed before handshake completed

During handling of the above exception, another exception occurred:

Traceback (most recent call last):
  File "/opt/conda/envs/gdf/lib/python3.9/site-packages/distributed/core.py", line 1516, in _connect
    comm = await connect(
  File "/opt/conda/envs/gdf/lib/python3.9/site-packages/distributed/comm/core.py", line 366, in connect
    await asyncio.sleep(backoff)
  File "/opt/conda/envs/gdf/lib/python3.9/asyncio/tasks.py", line 652, in sleep
    return await future
asyncio.exceptions.CancelledError

During handling of the above exception, another exception occurred:

Traceback (most recent call last):
  File "/opt/conda/envs/gdf/lib/python3.9/site-packages/distributed/core.py", line 1626, in connect
    return connect_attempt.result()
asyncio.exceptions.CancelledError

During handling of the above exception, another exception occurred:

Traceback (most recent call last):
  File "/opt/conda/envs/gdf/lib/python3.9/site-packages/distributed/worker.py", line 2059, in gather_dep
    response = await get_data_from_worker(
  File "/opt/conda/envs/gdf/lib/python3.9/site-packages/distributed/worker.py", line 2849, in get_data_from_worker
    comm = await rpc.connect(worker)
  File "/opt/conda/envs/gdf/lib/python3.9/site-packages/distributed/core.py", line 1628, in connect
    raise CommClosedError(reason)
distributed.comm.core.CommClosedError: Address removed.
2023-11-14 07:07:05,076 - distributed.worker - ERROR - failed during get data with ucx://127.0.0.1:44861 -> ucx://127.0.0.1:57985
Traceback (most recent call last):
  File "/opt/conda/envs/gdf/lib/python3.9/site-packages/distributed/comm/ucx.py", line 338, in write
    await self.ep.send(each_frame)
  File "/opt/conda/envs/gdf/lib/python3.9/site-packages/ucp/core.py", line 650, in send
    return await comm.tag_send(self._ep, buffer, nbytes, tag, name=log)
ucp._libs.exceptions.UCXError: <[Send #007] ep: 0x7f73d062c140, tag: 0x26b9d014df5deb5b, nbytes: 100000000, type: <class 'cudf.core.buffer.buffer.Buffer'>>: Connection reset by remote peer

During handling of the above exception, another exception occurred:

Traceback (most recent call last):
  File "/opt/conda/envs/gdf/lib/python3.9/site-packages/distributed/worker.py", line 1782, in get_data
    compressed = await comm.write(msg, serializers=serializers)
  File "/opt/conda/envs/gdf/lib/python3.9/site-packages/distributed/utils.py", line 803, in wrapper
    return await func(*args, **kwargs)
  File "/opt/conda/envs/gdf/lib/python3.9/site-packages/distributed/comm/ucx.py", line 342, in write
    raise CommClosedError("While writing, the connection was closed")
distributed.comm.core.CommClosedError: While writing, the connection was closed
Task exception was never retrieved
future: <Task finished name='Task-1192' coro=<_listener_handler_coroutine() done, defined at /opt/conda/envs/gdf/lib/python3.9/site-packages/ucp/core.py:128> exception=UCXError('<stream_recv>: Connection reset by remote peer')>
Traceback (most recent call last):
  File "/opt/conda/envs/gdf/lib/python3.9/site-packages/ucp/core.py", line 143, in _listener_handler_coroutine
    peer_info = await exchange_peer_info(
  File "/opt/conda/envs/gdf/lib/python3.9/site-packages/ucp/core.py", line 52, in exchange_peer_info
    await comm.stream_recv(endpoint, peer_info_arr, peer_info_arr.nbytes)
ucp._libs.exceptions.UCXError: <stream_recv>: Connection reset by remote peer
2023-11-14 07:07:05,107 - distributed.worker - ERROR - failed during get data with ucx://127.0.0.1:33319 -> ucx://127.0.0.1:57985
Traceback (most recent call last):
  File "/opt/conda/envs/gdf/lib/python3.9/site-packages/distributed/comm/ucx.py", line 338, in write
    await self.ep.send(each_frame)
  File "/opt/conda/envs/gdf/lib/python3.9/site-packages/ucp/core.py", line 650, in send
    return await comm.tag_send(self._ep, buffer, nbytes, tag, name=log)
ucp._libs.exceptions.UCXError: <[Send #007] ep: 0x7f55d2d0b140, tag: 0x67ca6c1a076cb755, nbytes: 100000000, type: <class 'cudf.core.buffer.buffer.Buffer'>>: Connection reset by remote peer

During handling of the above exception, another exception occurred:

Traceback (most recent call last):
  File "/opt/conda/envs/gdf/lib/python3.9/site-packages/distributed/worker.py", line 1782, in get_data
    compressed = await comm.write(msg, serializers=serializers)
  File "/opt/conda/envs/gdf/lib/python3.9/site-packages/distributed/utils.py", line 803, in wrapper
    return await func(*args, **kwargs)
  File "/opt/conda/envs/gdf/lib/python3.9/site-packages/distributed/comm/ucx.py", line 342, in write
    raise CommClosedError("While writing, the connection was closed")
distributed.comm.core.CommClosedError: While writing, the connection was closed
2023-11-14 07:07:05,338 - distributed.worker - ERROR - Worker stream died during communication: ucx://127.0.0.1:45203
Traceback (most recent call last):
  File "/opt/conda/envs/gdf/lib/python3.9/site-packages/distributed/comm/ucx.py", line 396, in read
    await self.ep.recv(each_frame)
  File "/opt/conda/envs/gdf/lib/python3.9/site-packages/ucp/core.py", line 725, in recv
    ret = await comm.tag_recv(self._ep, buffer, nbytes, tag, name=log)
ucp._libs.exceptions.UCXError: <[Recv #007] ep: 0x7f2f115b11c0, tag: 0x4e6acdee589c1207, nbytes: 100000000, type: <class 'rmm._lib.device_buffer.DeviceBuffer'>>: Connection reset by remote peer

During handling of the above exception, another exception occurred:

Traceback (most recent call last):
  File "/opt/conda/envs/gdf/lib/python3.9/site-packages/distributed/worker.py", line 2059, in gather_dep
    response = await get_data_from_worker(
  File "/opt/conda/envs/gdf/lib/python3.9/site-packages/distributed/worker.py", line 2852, in get_data_from_worker
    response = await send_recv(
  File "/opt/conda/envs/gdf/lib/python3.9/site-packages/distributed/core.py", line 1106, in send_recv
    response = await comm.read(deserializers=deserializers)
  File "/opt/conda/envs/gdf/lib/python3.9/site-packages/distributed/utils.py", line 803, in wrapper
    return await func(*args, **kwargs)
  File "/opt/conda/envs/gdf/lib/python3.9/site-packages/distributed/comm/ucx.py", line 402, in read
    raise CommClosedError(
distributed.comm.core.CommClosedError: Connection closed by writer.
Inner exception: UCXError("<[Recv #007] ep: 0x7f2f115b11c0, tag: 0x4e6acdee589c1207, nbytes: 100000000, type: <class 'rmm._lib.device_buffer.DeviceBuffer'>>: Connection reset by remote peer")
2023-11-14 07:07:05,340 - distributed.worker - ERROR - failed during get data with ucx://127.0.0.1:44861 -> ucx://127.0.0.1:45203
Traceback (most recent call last):
  File "/opt/conda/envs/gdf/lib/python3.9/site-packages/distributed/comm/ucx.py", line 338, in write
    await self.ep.send(each_frame)
  File "/opt/conda/envs/gdf/lib/python3.9/site-packages/ucp/core.py", line 650, in send
    return await comm.tag_send(self._ep, buffer, nbytes, tag, name=log)
ucp._libs.exceptions.UCXError: <[Send #007] ep: 0x7f73d062c200, tag: 0xd2d8e1d13ada39ae, nbytes: 100000000, type: <class 'cudf.core.buffer.buffer.Buffer'>>: Connection reset by remote peer

During handling of the above exception, another exception occurred:

Traceback (most recent call last):
  File "/opt/conda/envs/gdf/lib/python3.9/site-packages/distributed/worker.py", line 1782, in get_data
    compressed = await comm.write(msg, serializers=serializers)
  File "/opt/conda/envs/gdf/lib/python3.9/site-packages/distributed/utils.py", line 803, in wrapper
    return await func(*args, **kwargs)
  File "/opt/conda/envs/gdf/lib/python3.9/site-packages/distributed/comm/ucx.py", line 342, in write
    raise CommClosedError("While writing, the connection was closed")
distributed.comm.core.CommClosedError: While writing, the connection was closed
2023-11-14 07:07:05,342 - distributed.worker - ERROR - Worker stream died during communication: ucx://127.0.0.1:45203
Traceback (most recent call last):
  File "/opt/conda/envs/gdf/lib/python3.9/site-packages/distributed/comm/ucx.py", line 471, in connect
    ep = await ucp.create_endpoint(ip, port)
  File "/opt/conda/envs/gdf/lib/python3.9/site-packages/ucp/core.py", line 1004, in create_endpoint
    return await _get_ctx().create_endpoint(
  File "/opt/conda/envs/gdf/lib/python3.9/site-packages/ucp/core.py", line 316, in create_endpoint
    peer_info = await exchange_peer_info(
  File "/opt/conda/envs/gdf/lib/python3.9/site-packages/ucp/core.py", line 54, in exchange_peer_info
    await comm.stream_recv(endpoint, peer_info_arr, peer_info_arr.nbytes)
ucp._libs.exceptions.UCXError: <stream_recv>: Connection reset by remote peer

During handling of the above exception, another exception occurred:

Traceback (most recent call last):
  File "/opt/conda/envs/gdf/lib/python3.9/site-packages/distributed/comm/core.py", line 342, in connect
    comm = await wait_for(
  File "/opt/conda/envs/gdf/lib/python3.9/site-packages/distributed/utils.py", line 1920, in wait_for
    return await asyncio.wait_for(fut, timeout)
  File "/opt/conda/envs/gdf/lib/python3.9/asyncio/tasks.py", line 479, in wait_for
    return fut.result()
  File "/opt/conda/envs/gdf/lib/python3.9/site-packages/distributed/comm/ucx.py", line 473, in connect
    raise CommClosedError("Connection closed before handshake completed")
distributed.comm.core.CommClosedError: Connection closed before handshake completed

During handling of the above exception, another exception occurred:

Traceback (most recent call last):
  File "/opt/conda/envs/gdf/lib/python3.9/site-packages/distributed/core.py", line 1516, in _connect
    comm = await connect(
  File "/opt/conda/envs/gdf/lib/python3.9/site-packages/distributed/comm/core.py", line 366, in connect
    await asyncio.sleep(backoff)
  File "/opt/conda/envs/gdf/lib/python3.9/asyncio/tasks.py", line 652, in sleep
    return await future
asyncio.exceptions.CancelledError

During handling of the above exception, another exception occurred:

Traceback (most recent call last):
  File "/opt/conda/envs/gdf/lib/python3.9/site-packages/distributed/core.py", line 1626, in connect
    return connect_attempt.result()
asyncio.exceptions.CancelledError

During handling of the above exception, another exception occurred:

Traceback (most recent call last):
  File "/opt/conda/envs/gdf/lib/python3.9/site-packages/distributed/worker.py", line 2059, in gather_dep
    response = await get_data_from_worker(
  File "/opt/conda/envs/gdf/lib/python3.9/site-packages/distributed/worker.py", line 2849, in get_data_from_worker
    comm = await rpc.connect(worker)
  File "/opt/conda/envs/gdf/lib/python3.9/site-packages/distributed/core.py", line 1628, in connect
    raise CommClosedError(reason)
distributed.comm.core.CommClosedError: Address removed.
2023-11-14 07:07:13,292 - distributed.nanny - WARNING - Restarting worker
2023-11-14 07:07:32,212 - distributed.worker - ERROR - Worker stream died during communication: ucx://127.0.0.1:57985
Traceback (most recent call last):
  File "/opt/conda/envs/gdf/lib/python3.9/site-packages/distributed/comm/ucx.py", line 471, in connect
    ep = await ucp.create_endpoint(ip, port)
  File "/opt/conda/envs/gdf/lib/python3.9/site-packages/ucp/core.py", line 1004, in create_endpoint
    return await _get_ctx().create_endpoint(
  File "/opt/conda/envs/gdf/lib/python3.9/site-packages/ucp/core.py", line 316, in create_endpoint
    peer_info = await exchange_peer_info(
  File "/opt/conda/envs/gdf/lib/python3.9/site-packages/ucp/core.py", line 54, in exchange_peer_info
    await comm.stream_recv(endpoint, peer_info_arr, peer_info_arr.nbytes)
asyncio.exceptions.CancelledError

During handling of the above exception, another exception occurred:

Traceback (most recent call last):
  File "/opt/conda/envs/gdf/lib/python3.9/asyncio/tasks.py", line 490, in wait_for
    return fut.result()
asyncio.exceptions.CancelledError

The above exception was the direct cause of the following exception:

Traceback (most recent call last):
  File "/opt/conda/envs/gdf/lib/python3.9/site-packages/distributed/comm/core.py", line 342, in connect
    comm = await wait_for(
  File "/opt/conda/envs/gdf/lib/python3.9/site-packages/distributed/utils.py", line 1920, in wait_for
    return await asyncio.wait_for(fut, timeout)
  File "/opt/conda/envs/gdf/lib/python3.9/asyncio/tasks.py", line 492, in wait_for
    raise exceptions.TimeoutError() from exc
asyncio.exceptions.TimeoutError

The above exception was the direct cause of the following exception:

Traceback (most recent call last):
  File "/opt/conda/envs/gdf/lib/python3.9/site-packages/distributed/worker.py", line 2059, in gather_dep
    response = await get_data_from_worker(
  File "/opt/conda/envs/gdf/lib/python3.9/site-packages/distributed/worker.py", line 2849, in get_data_from_worker
    comm = await rpc.connect(worker)
  File "/opt/conda/envs/gdf/lib/python3.9/site-packages/distributed/core.py", line 1626, in connect
    return connect_attempt.result()
  File "/opt/conda/envs/gdf/lib/python3.9/site-packages/distributed/core.py", line 1516, in _connect
    comm = await connect(
  File "/opt/conda/envs/gdf/lib/python3.9/site-packages/distributed/comm/core.py", line 368, in connect
    raise OSError(
OSError: Timed out trying to connect to ucx://127.0.0.1:57985 after 30 s
2023-11-14 07:07:32,285 - distributed.worker - ERROR - Worker stream died during communication: ucx://127.0.0.1:57985
Traceback (most recent call last):
  File "/opt/conda/envs/gdf/lib/python3.9/site-packages/distributed/comm/ucx.py", line 471, in connect
    ep = await ucp.create_endpoint(ip, port)
  File "/opt/conda/envs/gdf/lib/python3.9/site-packages/ucp/core.py", line 1004, in create_endpoint
    return await _get_ctx().create_endpoint(
  File "/opt/conda/envs/gdf/lib/python3.9/site-packages/ucp/core.py", line 316, in create_endpoint
    peer_info = await exchange_peer_info(
  File "/opt/conda/envs/gdf/lib/python3.9/site-packages/ucp/core.py", line 54, in exchange_peer_info
    await comm.stream_recv(endpoint, peer_info_arr, peer_info_arr.nbytes)
asyncio.exceptions.CancelledError

During handling of the above exception, another exception occurred:

Traceback (most recent call last):
  File "/opt/conda/envs/gdf/lib/python3.9/asyncio/tasks.py", line 490, in wait_for
    return fut.result()
asyncio.exceptions.CancelledError

The above exception was the direct cause of the following exception:

Traceback (most recent call last):
  File "/opt/conda/envs/gdf/lib/python3.9/site-packages/distributed/comm/core.py", line 342, in connect
    comm = await wait_for(
  File "/opt/conda/envs/gdf/lib/python3.9/site-packages/distributed/utils.py", line 1920, in wait_for
    return await asyncio.wait_for(fut, timeout)
  File "/opt/conda/envs/gdf/lib/python3.9/asyncio/tasks.py", line 492, in wait_for
    raise exceptions.TimeoutError() from exc
asyncio.exceptions.TimeoutError

The above exception was the direct cause of the following exception:

Traceback (most recent call last):
  File "/opt/conda/envs/gdf/lib/python3.9/site-packages/distributed/worker.py", line 2059, in gather_dep
    response = await get_data_from_worker(
  File "/opt/conda/envs/gdf/lib/python3.9/site-packages/distributed/worker.py", line 2849, in get_data_from_worker
    comm = await rpc.connect(worker)
  File "/opt/conda/envs/gdf/lib/python3.9/site-packages/distributed/core.py", line 1626, in connect
    return connect_attempt.result()
  File "/opt/conda/envs/gdf/lib/python3.9/site-packages/distributed/core.py", line 1516, in _connect
    comm = await connect(
  File "/opt/conda/envs/gdf/lib/python3.9/site-packages/distributed/comm/core.py", line 368, in connect
    raise OSError(
OSError: Timed out trying to connect to ucx://127.0.0.1:57985 after 30 s
[dgx13:73693:0:73693] Caught signal 11 (Segmentation fault: address not mapped to object at address 0x448)
==== backtrace (tid:  73693) ====
 0  /opt/conda/envs/gdf/lib/libucs.so.0(ucs_handle_error+0x2fd) [0x7fc49f4e406d]
 1  /opt/conda/envs/gdf/lib/libucs.so.0(+0x2a264) [0x7fc49f4e4264]
 2  /opt/conda/envs/gdf/lib/libucs.so.0(+0x2a42a) [0x7fc49f4e442a]
 3  /usr/lib/x86_64-linux-gnu/libpthread.so.0(+0x14420) [0x7fc550719420]
 4  /opt/conda/envs/gdf/lib/libucp.so.0(ucp_mem_type_unpack+0x14) [0x7fc49f5626a4]
 5  /opt/conda/envs/gdf/lib/libucp.so.0(ucp_rndv_data_handler+0x4e9) [0x7fc49f58b829]
 6  /opt/conda/envs/gdf/lib/./libuct.so.0(+0x2146f) [0x7fc4b002746f]
 7  /opt/conda/envs/gdf/lib/./libuct.so.0(+0x248c8) [0x7fc4b002a8c8]
 8  /opt/conda/envs/gdf/lib/libucs.so.0(ucs_event_set_wait+0xb9) [0x7fc49f4ed499]
 9  /opt/conda/envs/gdf/lib/./libuct.so.0(uct_tcp_iface_progress+0x7d) [0x7fc4b002966d]
10  /opt/conda/envs/gdf/lib/libucp.so.0(ucp_worker_progress+0x5a) [0x7fc49f55f8ca]
11  /opt/conda/envs/gdf/lib/python3.9/site-packages/ucp/_libs/ucx_api.cpython-39-x86_64-linux-gnu.so(+0x3206a) [0x7fc49f61806a]
12  /opt/conda/envs/gdf/bin/python(_PyEval_EvalFrameDefault+0x37cb) [0x559dd0be36fb]
13  /opt/conda/envs/gdf/bin/python(+0x12f094) [0x559dd0bdf094]
14  /opt/conda/envs/gdf/bin/python(_PyFunction_Vectorcall+0xd9) [0x559dd0bf0519]
15  /opt/conda/envs/gdf/bin/python(_PyEval_EvalFrameDefault+0x696) [0x559dd0be05c6]
16  /opt/conda/envs/gdf/bin/python(+0x1407c2) [0x559dd0bf07c2]
17  /opt/conda/envs/gdf/bin/python(+0x14de83) [0x559dd0bfde83]
18  /opt/conda/envs/gdf/bin/python(+0x258b2c) [0x559dd0d08b2c]
19  /opt/conda/envs/gdf/bin/python(+0xead05) [0x559dd0b9ad05]
20  /opt/conda/envs/gdf/bin/python(+0x1377f3) [0x559dd0be77f3]
21  /opt/conda/envs/gdf/bin/python(_PyEval_EvalFrameDefault+0x59f9) [0x559dd0be5929]
22  /opt/conda/envs/gdf/bin/python(+0x1407c2) [0x559dd0bf07c2]
23  /opt/conda/envs/gdf/bin/python(_PyEval_EvalFrameDefault+0x696) [0x559dd0be05c6]
24  /opt/conda/envs/gdf/bin/python(+0x1407c2) [0x559dd0bf07c2]
25  /opt/conda/envs/gdf/bin/python(_PyEval_EvalFrameDefault+0x696) [0x559dd0be05c6]
26  /opt/conda/envs/gdf/bin/python(+0x1407c2) [0x559dd0bf07c2]
27  /opt/conda/envs/gdf/bin/python(_PyEval_EvalFrameDefault+0x696) [0x559dd0be05c6]
28  /opt/conda/envs/gdf/bin/python(+0x1407c2) [0x559dd0bf07c2]
29  /opt/conda/envs/gdf/bin/python(_PyEval_EvalFrameDefault+0x696) [0x559dd0be05c6]
30  /opt/conda/envs/gdf/bin/python(+0x12f094) [0x559dd0bdf094]
31  /opt/conda/envs/gdf/bin/python(_PyFunction_Vectorcall+0xd9) [0x559dd0bf0519]
32  /opt/conda/envs/gdf/bin/python(_PyEval_EvalFrameDefault+0x11f8) [0x559dd0be1128]
33  /opt/conda/envs/gdf/bin/python(+0x12f094) [0x559dd0bdf094]
34  /opt/conda/envs/gdf/bin/python(+0x14dccb) [0x559dd0bfdccb]
35  /opt/conda/envs/gdf/bin/python(PyObject_Call+0xbc) [0x559dd0bfe44c]
36  /opt/conda/envs/gdf/bin/python(+0x21110e) [0x559dd0cc110e]
37  /opt/conda/envs/gdf/bin/python(_PyObject_MakeTpCall+0x2ec) [0x559dd0be877c]
38  /opt/conda/envs/gdf/bin/python(_PyEval_EvalFrameDefault+0x37cb) [0x559dd0be36fb]
39  /opt/conda/envs/gdf/bin/python(+0x1407c2) [0x559dd0bf07c2]
40  /opt/conda/envs/gdf/bin/python(+0x14ddac) [0x559dd0bfddac]
41  /opt/conda/envs/gdf/bin/python(_PyEval_EvalFrameDefault+0x37cb) [0x559dd0be36fb]
42  /opt/conda/envs/gdf/bin/python(+0x1407c2) [0x559dd0bf07c2]
43  /opt/conda/envs/gdf/bin/python(_PyEval_EvalFrameDefault+0x696) [0x559dd0be05c6]
44  /opt/conda/envs/gdf/bin/python(+0x12f094) [0x559dd0bdf094]
45  /opt/conda/envs/gdf/bin/python(_PyFunction_Vectorcall+0xd9) [0x559dd0bf0519]
46  /opt/conda/envs/gdf/bin/python(_PyEval_EvalFrameDefault+0x696) [0x559dd0be05c6]
47  /opt/conda/envs/gdf/bin/python(+0x1407c2) [0x559dd0bf07c2]
48  /opt/conda/envs/gdf/bin/python(_PyEval_EvalFrameDefault+0x3e2) [0x559dd0be0312]
49  /opt/conda/envs/gdf/bin/python(+0x12f094) [0x559dd0bdf094]
50  /opt/conda/envs/gdf/bin/python(_PyFunction_Vectorcall+0xd9) [0x559dd0bf0519]
51  /opt/conda/envs/gdf/bin/python(_PyEval_EvalFrameDefault+0x11f8) [0x559dd0be1128]
52  /opt/conda/envs/gdf/bin/python(+0x12f094) [0x559dd0bdf094]
53  /opt/conda/envs/gdf/bin/python(_PyEval_EvalCodeWithName+0x48) [0x559dd0bded68]
54  /opt/conda/envs/gdf/bin/python(PyEval_EvalCodeEx+0x39) [0x559dd0bded19]
55  /opt/conda/envs/gdf/bin/python(PyEval_EvalCode+0x1b) [0x559dd0c8c07b]
56  /opt/conda/envs/gdf/bin/python(+0x208fca) [0x559dd0cb8fca]
57  /opt/conda/envs/gdf/bin/python(+0x205353) [0x559dd0cb5353]
58  /opt/conda/envs/gdf/bin/python(PyRun_StringFlags+0x9a) [0x559dd0cad16a]
59  /opt/conda/envs/gdf/bin/python(PyRun_SimpleStringFlags+0x3c) [0x559dd0cad05c]
60  /opt/conda/envs/gdf/bin/python(Py_RunMain+0x267) [0x559dd0cac297]
61  /opt/conda/envs/gdf/bin/python(Py_BytesMain+0x37) [0x559dd0c7ff07]
=================================
2023-11-14 07:07:33,510 - distributed.worker - WARNING - Compute Failed
Key:       ('group-simple-shuffle-84a0276e6a854cf0d6c4324869a61d39', 4)
Function:  shuffle_group
args:      (                 key   payload
0         1218863339  99051695
1         1252208751  78953234
2          652278035  81293845
3         1253618300  74974697
4         1202090160  62919800
...              ...       ...
99999995    50213713  72068972
99999996  1249206659  33160153
99999997  1259655348  40095643
99999998  1252540937  33956372
99999999  1212812172  90324512

[100000000 rows x 2 columns], ['key'], 0, 8, 8, False, 8)
kwargs:    {}
Exception: "MemoryError('std::bad_alloc: out_of_memory: RMM failure at:/opt/conda/envs/gdf/include/rmm/mr/device/pool_memory_resource.hpp:201: Maximum pool size exceeded')"

2023-11-14 07:07:33,557 - distributed.worker - WARNING - Compute Failed
Key:       ('group-simple-shuffle-84a0276e6a854cf0d6c4324869a61d39', 6)
Function:  shuffle_group
args:      (                 key   payload
0         1418863339  99051695
1         1452208751  78953234
2          677278035  81293845
3         1453618300  74974697
4         1402090160  62919800
...              ...       ...
99999995    75213713  72068972
99999996  1449206659  33160153
99999997  1459655348  40095643
99999998  1452540937  33956372
99999999  1412812172  90324512

[100000000 rows x 2 columns], ['key'], 0, 8, 8, False, 8)
kwargs:    {}
Exception: "MemoryError('std::bad_alloc: out_of_memory: RMM failure at:/opt/conda/envs/gdf/include/rmm/mr/device/pool_memory_resource.hpp:201: Maximum pool size exceeded')"

2023-11-14 07:07:33,854 - distributed.worker - ERROR - failed during get data with ucx://127.0.0.1:44861 -> ucx://127.0.0.1:41147
Traceback (most recent call last):
  File "/opt/conda/envs/gdf/lib/python3.9/site-packages/distributed/comm/ucx.py", line 354, in read
    await self.ep.recv(msg)
  File "/opt/conda/envs/gdf/lib/python3.9/site-packages/ucp/core.py", line 725, in recv
    ret = await comm.tag_recv(self._ep, buffer, nbytes, tag, name=log)
ucp._libs.exceptions.UCXCanceled: <[Recv #006] ep: 0x7f73d062c280, tag: 0xee185086dbf04cdf, nbytes: 16, type: <class 'numpy.ndarray'>>: 

During handling of the above exception, another exception occurred:

Traceback (most recent call last):
  File "/opt/conda/envs/gdf/lib/python3.9/site-packages/distributed/worker.py", line 1783, in get_data
    response = await comm.read(deserializers=serializers)
  File "/opt/conda/envs/gdf/lib/python3.9/site-packages/distributed/utils.py", line 803, in wrapper
    return await func(*args, **kwargs)
  File "/opt/conda/envs/gdf/lib/python3.9/site-packages/distributed/comm/ucx.py", line 372, in read
    raise CommClosedError(
distributed.comm.core.CommClosedError: Connection closed by writer.
Inner exception: UCXCanceled("<[Recv #006] ep: 0x7f73d062c280, tag: 0xee185086dbf04cdf, nbytes: 16, type: <class 'numpy.ndarray'>>: ")
2023-11-14 07:07:33,857 - distributed.worker - ERROR - failed during get data with ucx://127.0.0.1:33319 -> ucx://127.0.0.1:41147
Traceback (most recent call last):
  File "/opt/conda/envs/gdf/lib/python3.9/site-packages/distributed/comm/ucx.py", line 338, in write
    await self.ep.send(each_frame)
  File "/opt/conda/envs/gdf/lib/python3.9/site-packages/ucp/core.py", line 650, in send
    return await comm.tag_send(self._ep, buffer, nbytes, tag, name=log)
ucp._libs.exceptions.UCXError: <[Send #007] ep: 0x7f55d2d0b400, tag: 0xa6efaf1b015c3096, nbytes: 800000000, type: <class 'cudf.core.buffer.buffer.Buffer'>>: Connection reset by remote peer

During handling of the above exception, another exception occurred:

Traceback (most recent call last):
  File "/opt/conda/envs/gdf/lib/python3.9/site-packages/distributed/worker.py", line 1782, in get_data
    compressed = await comm.write(msg, serializers=serializers)
  File "/opt/conda/envs/gdf/lib/python3.9/site-packages/distributed/utils.py", line 803, in wrapper
    return await func(*args, **kwargs)
  File "/opt/conda/envs/gdf/lib/python3.9/site-packages/distributed/comm/ucx.py", line 342, in write
    raise CommClosedError("While writing, the connection was closed")
distributed.comm.core.CommClosedError: While writing, the connection was closed
Traceback (most recent call last):
  File "cupy/cuda/memory.pyx", line 740, in cupy.cuda.memory.alloc
  File "/opt/conda/envs/gdf/lib/python3.9/site-packages/rmm/allocators/cupy.py", line 37, in rmm_cupy_allocator
    buf = librmm.device_buffer.DeviceBuffer(size=nbytes, stream=stream)
  File "device_buffer.pyx", line 85, in rmm._lib.device_buffer.DeviceBuffer.__cinit__
MemoryError: std::bad_alloc: out_of_memory: RMM failure at:/opt/conda/envs/gdf/include/rmm/mr/device/pool_memory_resource.hpp:201: Maximum pool size exceeded
Exception ignored in: 'cupy.cuda.thrust.cupy_malloc'
Traceback (most recent call last):
  File "cupy/cuda/memory.pyx", line 740, in cupy.cuda.memory.alloc
  File "/opt/conda/envs/gdf/lib/python3.9/site-packages/rmm/allocators/cupy.py", line 37, in rmm_cupy_allocator
    buf = librmm.device_buffer.DeviceBuffer(size=nbytes, stream=stream)
  File "device_buffer.pyx", line 85, in rmm._lib.device_buffer.DeviceBuffer.__cinit__
MemoryError: std::bad_alloc: out_of_memory: RMM failure at:/opt/conda/envs/gdf/include/rmm/mr/device/pool_memory_resource.hpp:201: Maximum pool size exceeded
2023-11-14 07:07:34,285 - distributed.worker - WARNING - Compute Failed
Key:       ('generate-data-5366301a596b755bb8c33997d3ce7726', 0)
Function:  generate_chunk
args:      (0, 100000000, 8, 'build', 0.3, True)
kwargs:    {}
Exception: "RuntimeError('radix_sort: failed on 2nd step: cudaErrorInvalidValue: invalid argument')"

2023-11-14 07:07:35,059 - distributed.nanny - WARNING - Restarting worker
/opt/conda/envs/gdf/lib/python3.9/multiprocessing/resource_tracker.py:216: UserWarning: resource_tracker: There appear to be 24 leaked semaphore objects to clean up at shutdown
  warnings.warn('resource_tracker: There appear to be %d '
