2023-01-19 01:00:19,480 - distributed.preloading - INFO - Creating preload: dask_cuda.initialize
2023-01-19 01:00:19,480 - distributed.preloading - INFO - Import preload module: dask_cuda.initialize
2023-01-19 01:00:19,484 - distributed.preloading - INFO - Creating preload: dask_cuda.initialize
2023-01-19 01:00:19,484 - distributed.preloading - INFO - Import preload module: dask_cuda.initialize
2023-01-19 01:00:19,487 - distributed.preloading - INFO - Creating preload: dask_cuda.initialize
2023-01-19 01:00:19,487 - distributed.preloading - INFO - Import preload module: dask_cuda.initialize
2023-01-19 01:00:19,583 - distributed.preloading - INFO - Creating preload: dask_cuda.initialize
2023-01-19 01:00:19,583 - distributed.preloading - INFO - Import preload module: dask_cuda.initialize
2023-01-19 01:00:19,665 - distributed.preloading - INFO - Creating preload: dask_cuda.initialize
2023-01-19 01:00:19,665 - distributed.preloading - INFO - Creating preload: dask_cuda.initialize
2023-01-19 01:00:19,665 - distributed.preloading - INFO - Import preload module: dask_cuda.initialize
2023-01-19 01:00:19,665 - distributed.preloading - INFO - Creating preload: dask_cuda.initialize
2023-01-19 01:00:19,666 - distributed.preloading - INFO - Import preload module: dask_cuda.initialize
2023-01-19 01:00:19,666 - distributed.preloading - INFO - Import preload module: dask_cuda.initialize
2023-01-19 01:00:19,666 - distributed.preloading - INFO - Creating preload: dask_cuda.initialize
2023-01-19 01:00:19,666 - distributed.preloading - INFO - Import preload module: dask_cuda.initialize
[dgx13:50909:0:50909] Caught signal 11 (Segmentation fault: address not mapped to object at address 0x448)
==== backtrace (tid:  50909) ====
 0  /datasets/pentschev/miniconda3/envs/gdf/lib/libucs.so.0(ucs_handle_error+0x2d4) [0x7f2eb981d1a4]
 1  /datasets/pentschev/miniconda3/envs/gdf/lib/libucs.so.0(+0x2e37f) [0x7f2eb981d37f]
 2  /datasets/pentschev/miniconda3/envs/gdf/lib/libucs.so.0(+0x2e6a4) [0x7f2eb981d6a4]
 3  /lib/x86_64-linux-gnu/libpthread.so.0(+0x12980) [0x7f2f2eeb2980]
 4  /datasets/pentschev/miniconda3/envs/gdf/lib/libucp.so.0(ucp_mem_type_unpack+0x14) [0x7f2eb9aa5e64]
 5  /datasets/pentschev/miniconda3/envs/gdf/lib/libucp.so.0(ucp_rndv_data_handler+0x508) [0x7f2eb9ad8358]
 6  /datasets/pentschev/miniconda3/envs/gdf/lib/libuct.so.0(+0x20b1f) [0x7f2eb95d1b1f]
 7  /datasets/pentschev/miniconda3/envs/gdf/lib/libuct.so.0(+0x210f4) [0x7f2eb95d20f4]
 8  /datasets/pentschev/miniconda3/envs/gdf/lib/libuct.so.0(+0x23548) [0x7f2eb95d4548]
 9  /datasets/pentschev/miniconda3/envs/gdf/lib/libucs.so.0(ucs_event_set_wait+0xb9) [0x7f2eb9827879]
10  /datasets/pentschev/miniconda3/envs/gdf/lib/libuct.so.0(uct_tcp_iface_progress+0x7b) [0x7f2eb95d45eb]
11  /datasets/pentschev/miniconda3/envs/gdf/lib/libucp.so.0(ucp_worker_progress+0x6a) [0x7f2eb9aa242a]
12  /datasets/pentschev/miniconda3/envs/gdf/lib/python3.9/site-packages/ucp/_libs/ucx_api.cpython-39-x86_64-linux-gnu.so(+0x26c79) [0x7f2eb9d5ec79]
13  /datasets/pentschev/miniconda3/envs/gdf/bin/python(+0x141eca) [0x55be6704ceca]
14  /datasets/pentschev/miniconda3/envs/gdf/bin/python(_PyEval_EvalFrameDefault+0x3d99) [0x55be6703a549]
15  /datasets/pentschev/miniconda3/envs/gdf/bin/python(+0x12a7d7) [0x55be670357d7]
16  /datasets/pentschev/miniconda3/envs/gdf/bin/python(_PyFunction_Vectorcall+0xb9) [0x55be67047bb9]
17  /datasets/pentschev/miniconda3/envs/gdf/bin/python(_PyEval_EvalFrameDefault+0x672) [0x55be67036e22]
18  /datasets/pentschev/miniconda3/envs/gdf/bin/python(+0x13cec3) [0x55be67047ec3]
19  /datasets/pentschev/miniconda3/envs/gdf/bin/python(+0x14bc75) [0x55be67056c75]
20  /datasets/pentschev/miniconda3/envs/gdf/bin/python(+0x264071) [0x55be6716f071]
21  /datasets/pentschev/miniconda3/envs/gdf/bin/python(+0xf7187) [0x55be67002187]
22  /datasets/pentschev/miniconda3/envs/gdf/bin/python(+0x133747) [0x55be6703e747]
23  /datasets/pentschev/miniconda3/envs/gdf/bin/python(_PyEval_EvalFrameDefault+0x5f0a) [0x55be6703c6ba]
24  /datasets/pentschev/miniconda3/envs/gdf/bin/python(+0x13cec3) [0x55be67047ec3]
25  /datasets/pentschev/miniconda3/envs/gdf/bin/python(_PyEval_EvalFrameDefault+0x672) [0x55be67036e22]
26  /datasets/pentschev/miniconda3/envs/gdf/bin/python(+0x13cec3) [0x55be67047ec3]
27  /datasets/pentschev/miniconda3/envs/gdf/bin/python(_PyEval_EvalFrameDefault+0x672) [0x55be67036e22]
28  /datasets/pentschev/miniconda3/envs/gdf/bin/python(+0x13cec3) [0x55be67047ec3]
29  /datasets/pentschev/miniconda3/envs/gdf/bin/python(_PyEval_EvalFrameDefault+0x672) [0x55be67036e22]
30  /datasets/pentschev/miniconda3/envs/gdf/bin/python(+0x13cec3) [0x55be67047ec3]
31  /datasets/pentschev/miniconda3/envs/gdf/bin/python(_PyEval_EvalFrameDefault+0x672) [0x55be67036e22]
32  /datasets/pentschev/miniconda3/envs/gdf/bin/python(+0x12a7d7) [0x55be670357d7]
33  /datasets/pentschev/miniconda3/envs/gdf/bin/python(_PyFunction_Vectorcall+0xb9) [0x55be67047bb9]
34  /datasets/pentschev/miniconda3/envs/gdf/bin/python(_PyEval_EvalFrameDefault+0x4cbc) [0x55be6703b46c]
35  /datasets/pentschev/miniconda3/envs/gdf/bin/python(+0x12a7d7) [0x55be670357d7]
36  /datasets/pentschev/miniconda3/envs/gdf/bin/python(+0x14baf8) [0x55be67056af8]
37  /datasets/pentschev/miniconda3/envs/gdf/bin/python(PyObject_Call+0xb4) [0x55be67057254]
38  /datasets/pentschev/miniconda3/envs/gdf/bin/python(+0x21b8b8) [0x55be671268b8]
39  /datasets/pentschev/miniconda3/envs/gdf/bin/python(_PyObject_MakeTpCall+0x347) [0x55be6703fa57]
40  /datasets/pentschev/miniconda3/envs/gdf/bin/python(_PyEval_EvalFrameDefault+0x3d99) [0x55be6703a549]
41  /datasets/pentschev/miniconda3/envs/gdf/bin/python(+0x13cec3) [0x55be67047ec3]
42  /datasets/pentschev/miniconda3/envs/gdf/bin/python(+0x14bb91) [0x55be67056b91]
43  /datasets/pentschev/miniconda3/envs/gdf/bin/python(_PyEval_EvalFrameDefault+0x3d99) [0x55be6703a549]
44  /datasets/pentschev/miniconda3/envs/gdf/bin/python(+0x13cec3) [0x55be67047ec3]
45  /datasets/pentschev/miniconda3/envs/gdf/bin/python(_PyEval_EvalFrameDefault+0x672) [0x55be67036e22]
46  /datasets/pentschev/miniconda3/envs/gdf/bin/python(+0x12a7d7) [0x55be670357d7]
47  /datasets/pentschev/miniconda3/envs/gdf/bin/python(_PyFunction_Vectorcall+0xb9) [0x55be67047bb9]
48  /datasets/pentschev/miniconda3/envs/gdf/bin/python(_PyEval_EvalFrameDefault+0x672) [0x55be67036e22]
49  /datasets/pentschev/miniconda3/envs/gdf/bin/python(+0x13cec3) [0x55be67047ec3]
50  /datasets/pentschev/miniconda3/envs/gdf/bin/python(_PyEval_EvalFrameDefault+0x3c3) [0x55be67036b73]
51  /datasets/pentschev/miniconda3/envs/gdf/bin/python(+0x12a7d7) [0x55be670357d7]
52  /datasets/pentschev/miniconda3/envs/gdf/bin/python(_PyFunction_Vectorcall+0xb9) [0x55be67047bb9]
53  /datasets/pentschev/miniconda3/envs/gdf/bin/python(_PyEval_EvalFrameDefault+0x11df) [0x55be6703798f]
54  /datasets/pentschev/miniconda3/envs/gdf/bin/python(+0x12a7d7) [0x55be670357d7]
55  /datasets/pentschev/miniconda3/envs/gdf/bin/python(_PyEval_EvalCodeWithName+0x47) [0x55be67035497]
56  /datasets/pentschev/miniconda3/envs/gdf/bin/python(PyEval_EvalCodeEx+0x39) [0x55be67035449]
57  /datasets/pentschev/miniconda3/envs/gdf/bin/python(PyEval_EvalCode+0x1b) [0x55be670efddb]
58  /datasets/pentschev/miniconda3/envs/gdf/bin/python(+0x213409) [0x55be6711e409]
59  /datasets/pentschev/miniconda3/envs/gdf/bin/python(+0x20f5a4) [0x55be6711a5a4]
60  /datasets/pentschev/miniconda3/envs/gdf/bin/python(PyRun_StringFlags+0x9d) [0x55be6711227d]
61  /datasets/pentschev/miniconda3/envs/gdf/bin/python(PyRun_SimpleStringFlags+0x3d) [0x55be6711214d]
=================================
2023-01-19 01:00:27,818 - distributed.worker - ERROR - failed during get data with ucx://127.0.0.1:34649 -> ucx://127.0.0.1:59859
Traceback (most recent call last):
  File "/datasets/pentschev/miniconda3/envs/gdf/lib/python3.9/site-packages/distributed/comm/ucx.py", line 333, in write
    await self.ep.send(each_frame)
  File "/datasets/pentschev/miniconda3/envs/gdf/lib/python3.9/site-packages/ucp/core.py", line 650, in send
    return await comm.tag_send(self._ep, buffer, nbytes, tag, name=log)
ucp._libs.exceptions.UCXError: <[Send #007] ep: 0x7f57d2d35100, tag: 0x1beb6fac6b2da099, nbytes: 800000000, type: <class 'cudf.core.buffer.buffer.Buffer'>>: Connection reset by remote peer

During handling of the above exception, another exception occurred:

Traceback (most recent call last):
  File "/datasets/pentschev/miniconda3/envs/gdf/lib/python3.9/site-packages/distributed/worker.py", line 1766, in get_data
    compressed = await comm.write(msg, serializers=serializers)
  File "/datasets/pentschev/miniconda3/envs/gdf/lib/python3.9/site-packages/distributed/utils.py", line 741, in wrapper
    return await func(*args, **kwargs)
  File "/datasets/pentschev/miniconda3/envs/gdf/lib/python3.9/site-packages/distributed/comm/ucx.py", line 337, in write
    raise CommClosedError("While writing, the connection was closed")
distributed.comm.core.CommClosedError: While writing, the connection was closed
2023-01-19 01:00:27,911 - distributed.nanny - WARNING - Restarting worker
[dgx13:50911:0:50911] Caught signal 11 (Segmentation fault: address not mapped to object at address 0x448)
==== backtrace (tid:  50911) ====
 0  /datasets/pentschev/miniconda3/envs/gdf/lib/libucs.so.0(ucs_handle_error+0x2d4) [0x7fdf4c8371a4]
 1  /datasets/pentschev/miniconda3/envs/gdf/lib/libucs.so.0(+0x2e37f) [0x7fdf4c83737f]
 2  /datasets/pentschev/miniconda3/envs/gdf/lib/libucs.so.0(+0x2e6a4) [0x7fdf4c8376a4]
 3  /lib/x86_64-linux-gnu/libpthread.so.0(+0x12980) [0x7fdfcff6f980]
 4  /datasets/pentschev/miniconda3/envs/gdf/lib/libucp.so.0(ucp_mem_type_unpack+0x14) [0x7fdf4cabfe64]
 5  /datasets/pentschev/miniconda3/envs/gdf/lib/libucp.so.0(ucp_rndv_data_handler+0x508) [0x7fdf4caf2358]
 6  /datasets/pentschev/miniconda3/envs/gdf/lib/libuct.so.0(+0x20b1f) [0x7fdf4c5ebb1f]
 7  /datasets/pentschev/miniconda3/envs/gdf/lib/libuct.so.0(+0x210f4) [0x7fdf4c5ec0f4]
 8  /datasets/pentschev/miniconda3/envs/gdf/lib/libuct.so.0(+0x23548) [0x7fdf4c5ee548]
 9  /datasets/pentschev/miniconda3/envs/gdf/lib/libucs.so.0(ucs_event_set_wait+0xb9) [0x7fdf4c841879]
10  /datasets/pentschev/miniconda3/envs/gdf/lib/libuct.so.0(uct_tcp_iface_progress+0x7b) [0x7fdf4c5ee5eb]
11  /datasets/pentschev/miniconda3/envs/gdf/lib/libucp.so.0(ucp_worker_progress+0x6a) [0x7fdf4cabc42a]
12  /datasets/pentschev/miniconda3/envs/gdf/lib/python3.9/site-packages/ucp/_libs/ucx_api.cpython-39-x86_64-linux-gnu.so(+0x26c79) [0x7fdf4cd78c79]
13  /datasets/pentschev/miniconda3/envs/gdf/bin/python(+0x141eca) [0x56545bfadeca]
14  /datasets/pentschev/miniconda3/envs/gdf/bin/python(_PyEval_EvalFrameDefault+0x3d99) [0x56545bf9b549]
15  /datasets/pentschev/miniconda3/envs/gdf/bin/python(+0x12a7d7) [0x56545bf967d7]
16  /datasets/pentschev/miniconda3/envs/gdf/bin/python(_PyFunction_Vectorcall+0xb9) [0x56545bfa8bb9]
17  /datasets/pentschev/miniconda3/envs/gdf/bin/python(_PyEval_EvalFrameDefault+0x672) [0x56545bf97e22]
18  /datasets/pentschev/miniconda3/envs/gdf/bin/python(+0x153244) [0x56545bfbf244]
19  /datasets/pentschev/miniconda3/envs/gdf/lib/python3.9/lib-dynload/_asyncio.cpython-39-x86_64-linux-gnu.so(+0x8301) [0x7fdf6a5a3301]
20  /datasets/pentschev/miniconda3/envs/gdf/bin/python(_PyObject_MakeTpCall+0x347) [0x56545bfa0a57]
21  /datasets/pentschev/miniconda3/envs/gdf/bin/python(+0xf7187) [0x56545bf63187]
22  /datasets/pentschev/miniconda3/envs/gdf/bin/python(+0x133747) [0x56545bf9f747]
23  /datasets/pentschev/miniconda3/envs/gdf/bin/python(_PyEval_EvalFrameDefault+0x5f0a) [0x56545bf9d6ba]
24  /datasets/pentschev/miniconda3/envs/gdf/bin/python(+0x13cec3) [0x56545bfa8ec3]
25  /datasets/pentschev/miniconda3/envs/gdf/bin/python(_PyEval_EvalFrameDefault+0x672) [0x56545bf97e22]
26  /datasets/pentschev/miniconda3/envs/gdf/bin/python(+0x13cec3) [0x56545bfa8ec3]
27  /datasets/pentschev/miniconda3/envs/gdf/bin/python(_PyEval_EvalFrameDefault+0x672) [0x56545bf97e22]
28  /datasets/pentschev/miniconda3/envs/gdf/bin/python(+0x13cec3) [0x56545bfa8ec3]
29  /datasets/pentschev/miniconda3/envs/gdf/bin/python(_PyEval_EvalFrameDefault+0x672) [0x56545bf97e22]
30  /datasets/pentschev/miniconda3/envs/gdf/bin/python(+0x13cec3) [0x56545bfa8ec3]
31  /datasets/pentschev/miniconda3/envs/gdf/bin/python(_PyEval_EvalFrameDefault+0x672) [0x56545bf97e22]
32  /datasets/pentschev/miniconda3/envs/gdf/bin/python(+0x12a7d7) [0x56545bf967d7]
33  /datasets/pentschev/miniconda3/envs/gdf/bin/python(_PyFunction_Vectorcall+0xb9) [0x56545bfa8bb9]
34  /datasets/pentschev/miniconda3/envs/gdf/bin/python(_PyEval_EvalFrameDefault+0x4cbc) [0x56545bf9c46c]
35  /datasets/pentschev/miniconda3/envs/gdf/bin/python(+0x12a7d7) [0x56545bf967d7]
36  /datasets/pentschev/miniconda3/envs/gdf/bin/python(+0x14baf8) [0x56545bfb7af8]
37  /datasets/pentschev/miniconda3/envs/gdf/bin/python(PyObject_Call+0xb4) [0x56545bfb8254]
38  /datasets/pentschev/miniconda3/envs/gdf/bin/python(+0x21b8b8) [0x56545c0878b8]
39  /datasets/pentschev/miniconda3/envs/gdf/bin/python(_PyObject_MakeTpCall+0x347) [0x56545bfa0a57]
40  /datasets/pentschev/miniconda3/envs/gdf/bin/python(_PyEval_EvalFrameDefault+0x3d99) [0x56545bf9b549]
41  /datasets/pentschev/miniconda3/envs/gdf/bin/python(+0x13cec3) [0x56545bfa8ec3]
42  /datasets/pentschev/miniconda3/envs/gdf/bin/python(+0x14bb91) [0x56545bfb7b91]
43  /datasets/pentschev/miniconda3/envs/gdf/bin/python(_PyEval_EvalFrameDefault+0x3d99) [0x56545bf9b549]
44  /datasets/pentschev/miniconda3/envs/gdf/bin/python(+0x13cec3) [0x56545bfa8ec3]
45  /datasets/pentschev/miniconda3/envs/gdf/bin/python(_PyEval_EvalFrameDefault+0x672) [0x56545bf97e22]
46  /datasets/pentschev/miniconda3/envs/gdf/bin/python(+0x12a7d7) [0x56545bf967d7]
47  /datasets/pentschev/miniconda3/envs/gdf/bin/python(_PyFunction_Vectorcall+0xb9) [0x56545bfa8bb9]
48  /datasets/pentschev/miniconda3/envs/gdf/bin/python(_PyEval_EvalFrameDefault+0x672) [0x56545bf97e22]
49  /datasets/pentschev/miniconda3/envs/gdf/bin/python(+0x13cec3) [0x56545bfa8ec3]
50  /datasets/pentschev/miniconda3/envs/gdf/bin/python(_PyEval_EvalFrameDefault+0x3c3) [0x56545bf97b73]
51  /datasets/pentschev/miniconda3/envs/gdf/bin/python(+0x12a7d7) [0x56545bf967d7]
52  /datasets/pentschev/miniconda3/envs/gdf/bin/python(_PyFunction_Vectorcall+0xb9) [0x56545bfa8bb9]
53  /datasets/pentschev/miniconda3/envs/gdf/bin/python(_PyEval_EvalFrameDefault+0x11df) [0x56545bf9898f]
54  /datasets/pentschev/miniconda3/envs/gdf/bin/python(+0x12a7d7) [0x56545bf967d7]
55  /datasets/pentschev/miniconda3/envs/gdf/bin/python(_PyEval_EvalCodeWithName+0x47) [0x56545bf96497]
56  /datasets/pentschev/miniconda3/envs/gdf/bin/python(PyEval_EvalCodeEx+0x39) [0x56545bf96449]
57  /datasets/pentschev/miniconda3/envs/gdf/bin/python(PyEval_EvalCode+0x1b) [0x56545c050ddb]
58  /datasets/pentschev/miniconda3/envs/gdf/bin/python(+0x213409) [0x56545c07f409]
59  /datasets/pentschev/miniconda3/envs/gdf/bin/python(+0x20f5a4) [0x56545c07b5a4]
60  /datasets/pentschev/miniconda3/envs/gdf/bin/python(PyRun_StringFlags+0x9d) [0x56545c07327d]
61  /datasets/pentschev/miniconda3/envs/gdf/bin/python(PyRun_SimpleStringFlags+0x3d) [0x56545c07314d]
=================================
[dgx13:50888:0:50888] Caught signal 11 (Segmentation fault: address not mapped to object at address 0x448)
==== backtrace (tid:  50888) ====
 0  /datasets/pentschev/miniconda3/envs/gdf/lib/libucs.so.0(ucs_handle_error+0x2d4) [0x7f3e751a81a4]
 1  /datasets/pentschev/miniconda3/envs/gdf/lib/libucs.so.0(+0x2e37f) [0x7f3e751a837f]
 2  /datasets/pentschev/miniconda3/envs/gdf/lib/libucs.so.0(+0x2e6a4) [0x7f3e751a86a4]
 3  /lib/x86_64-linux-gnu/libpthread.so.0(+0x12980) [0x7f3ef883a980]
 4  /datasets/pentschev/miniconda3/envs/gdf/lib/libucp.so.0(ucp_mem_type_unpack+0x14) [0x7f3e75430e64]
 5  /datasets/pentschev/miniconda3/envs/gdf/lib/libucp.so.0(ucp_rndv_data_handler+0x508) [0x7f3e75463358]
 6  /datasets/pentschev/miniconda3/envs/gdf/lib/libuct.so.0(+0x20b1f) [0x7f3e74f5cb1f]
 7  /datasets/pentschev/miniconda3/envs/gdf/lib/libuct.so.0(+0x210f4) [0x7f3e74f5d0f4]
 8  /datasets/pentschev/miniconda3/envs/gdf/lib/libuct.so.0(+0x23548) [0x7f3e74f5f548]
 9  /datasets/pentschev/miniconda3/envs/gdf/lib/libucs.so.0(ucs_event_set_wait+0xb9) [0x7f3e751b2879]
10  /datasets/pentschev/miniconda3/envs/gdf/lib/libuct.so.0(uct_tcp_iface_progress+0x7b) [0x7f3e74f5f5eb]
11  /datasets/pentschev/miniconda3/envs/gdf/lib/libucp.so.0(ucp_worker_progress+0x6a) [0x7f3e7542d42a]
12  /datasets/pentschev/miniconda3/envs/gdf/lib/python3.9/site-packages/ucp/_libs/ucx_api.cpython-39-x86_64-linux-gnu.so(+0x26c79) [0x7f3e756e9c79]
13  /datasets/pentschev/miniconda3/envs/gdf/bin/python(+0x141eca) [0x560166b8deca]
14  /datasets/pentschev/miniconda3/envs/gdf/bin/python(_PyEval_EvalFrameDefault+0x3d99) [0x560166b7b549]
15  /datasets/pentschev/miniconda3/envs/gdf/bin/python(+0x12a7d7) [0x560166b767d7]
16  /datasets/pentschev/miniconda3/envs/gdf/bin/python(_PyFunction_Vectorcall+0xb9) [0x560166b88bb9]
17  /datasets/pentschev/miniconda3/envs/gdf/bin/python(_PyEval_EvalFrameDefault+0x672) [0x560166b77e22]
18  /datasets/pentschev/miniconda3/envs/gdf/bin/python(+0x13cec3) [0x560166b88ec3]
19  /datasets/pentschev/miniconda3/envs/gdf/bin/python(+0x14bc75) [0x560166b97c75]
20  /datasets/pentschev/miniconda3/envs/gdf/bin/python(+0x264071) [0x560166cb0071]
21  /datasets/pentschev/miniconda3/envs/gdf/bin/python(+0xf7187) [0x560166b43187]
22  /datasets/pentschev/miniconda3/envs/gdf/bin/python(+0x133747) [0x560166b7f747]
23  /datasets/pentschev/miniconda3/envs/gdf/bin/python(_PyEval_EvalFrameDefault+0x5f0a) [0x560166b7d6ba]
24  /datasets/pentschev/miniconda3/envs/gdf/bin/python(+0x13cec3) [0x560166b88ec3]
25  /datasets/pentschev/miniconda3/envs/gdf/bin/python(_PyEval_EvalFrameDefault+0x672) [0x560166b77e22]
26  /datasets/pentschev/miniconda3/envs/gdf/bin/python(+0x13cec3) [0x560166b88ec3]
27  /datasets/pentschev/miniconda3/envs/gdf/bin/python(_PyEval_EvalFrameDefault+0x672) [0x560166b77e22]
28  /datasets/pentschev/miniconda3/envs/gdf/bin/python(+0x13cec3) [0x560166b88ec3]
29  /datasets/pentschev/miniconda3/envs/gdf/bin/python(_PyEval_EvalFrameDefault+0x672) [0x560166b77e22]
30  /datasets/pentschev/miniconda3/envs/gdf/bin/python(+0x13cec3) [0x560166b88ec3]
31  /datasets/pentschev/miniconda3/envs/gdf/bin/python(_PyEval_EvalFrameDefault+0x672) [0x560166b77e22]
32  /datasets/pentschev/miniconda3/envs/gdf/bin/python(+0x12a7d7) [0x560166b767d7]
33  /datasets/pentschev/miniconda3/envs/gdf/bin/python(_PyFunction_Vectorcall+0xb9) [0x560166b88bb9]
34  /datasets/pentschev/miniconda3/envs/gdf/bin/python(_PyEval_EvalFrameDefault+0x4cbc) [0x560166b7c46c]
35  /datasets/pentschev/miniconda3/envs/gdf/bin/python(+0x12a7d7) [0x560166b767d7]
36  /datasets/pentschev/miniconda3/envs/gdf/bin/python(+0x14baf8) [0x560166b97af8]
37  /datasets/pentschev/miniconda3/envs/gdf/bin/python(PyObject_Call+0xb4) [0x560166b98254]
38  /datasets/pentschev/miniconda3/envs/gdf/bin/python(+0x21b8b8) [0x560166c678b8]
39  /datasets/pentschev/miniconda3/envs/gdf/bin/python(_PyObject_MakeTpCall+0x347) [0x560166b80a57]
40  /datasets/pentschev/miniconda3/envs/gdf/bin/python(_PyEval_EvalFrameDefault+0x3d99) [0x560166b7b549]
41  /datasets/pentschev/miniconda3/envs/gdf/bin/python(+0x13cec3) [0x560166b88ec3]
42  /datasets/pentschev/miniconda3/envs/gdf/bin/python(+0x14bb91) [0x560166b97b91]
43  /datasets/pentschev/miniconda3/envs/gdf/bin/python(_PyEval_EvalFrameDefault+0x3d99) [0x560166b7b549]
44  /datasets/pentschev/miniconda3/envs/gdf/bin/python(+0x13cec3) [0x560166b88ec3]
45  /datasets/pentschev/miniconda3/envs/gdf/bin/python(_PyEval_EvalFrameDefault+0x672) [0x560166b77e22]
46  /datasets/pentschev/miniconda3/envs/gdf/bin/python(+0x12a7d7) [0x560166b767d7]
47  /datasets/pentschev/miniconda3/envs/gdf/bin/python(_PyFunction_Vectorcall+0xb9) [0x560166b88bb9]
48  /datasets/pentschev/miniconda3/envs/gdf/bin/python(_PyEval_EvalFrameDefault+0x672) [0x560166b77e22]
49  /datasets/pentschev/miniconda3/envs/gdf/bin/python(+0x13cec3) [0x560166b88ec3]
50  /datasets/pentschev/miniconda3/envs/gdf/bin/python(_PyEval_EvalFrameDefault+0x3c3) [0x560166b77b73]
51  /datasets/pentschev/miniconda3/envs/gdf/bin/python(+0x12a7d7) [0x560166b767d7]
52  /datasets/pentschev/miniconda3/envs/gdf/bin/python(_PyFunction_Vectorcall+0xb9) [0x560166b88bb9]
53  /datasets/pentschev/miniconda3/envs/gdf/bin/python(_PyEval_EvalFrameDefault+0x11df) [0x560166b7898f]
54  /datasets/pentschev/miniconda3/envs/gdf/bin/python(+0x12a7d7) [0x560166b767d7]
55  /datasets/pentschev/miniconda3/envs/gdf/bin/python(_PyEval_EvalCodeWithName+0x47) [0x560166b76497]
56  /datasets/pentschev/miniconda3/envs/gdf/bin/python(PyEval_EvalCodeEx+0x39) [0x560166b76449]
57  /datasets/pentschev/miniconda3/envs/gdf/bin/python(PyEval_EvalCode+0x1b) [0x560166c30ddb]
58  /datasets/pentschev/miniconda3/envs/gdf/bin/python(+0x213409) [0x560166c5f409]
59  /datasets/pentschev/miniconda3/envs/gdf/bin/python(+0x20f5a4) [0x560166c5b5a4]
60  /datasets/pentschev/miniconda3/envs/gdf/bin/python(PyRun_StringFlags+0x9d) [0x560166c5327d]
61  /datasets/pentschev/miniconda3/envs/gdf/bin/python(PyRun_SimpleStringFlags+0x3d) [0x560166c5314d]
=================================
[dgx13:50893:0:50893] Caught signal 11 (Segmentation fault: address not mapped to object at address 0x448)
==== backtrace (tid:  50893) ====
 0  /datasets/pentschev/miniconda3/envs/gdf/lib/libucs.so.0(ucs_handle_error+0x2d4) [0x7fb061ae51a4]
 1  /datasets/pentschev/miniconda3/envs/gdf/lib/libucs.so.0(+0x2e37f) [0x7fb061ae537f]
 2  /datasets/pentschev/miniconda3/envs/gdf/lib/libucs.so.0(+0x2e6a4) [0x7fb061ae56a4]
 3  /lib/x86_64-linux-gnu/libpthread.so.0(+0x12980) [0x7fb0e51ee980]
 4  /datasets/pentschev/miniconda3/envs/gdf/lib/libucp.so.0(ucp_mem_type_unpack+0x14) [0x7fb061d6de64]
 5  /datasets/pentschev/miniconda3/envs/gdf/lib/libucp.so.0(ucp_rndv_data_handler+0x508) [0x7fb061da0358]
 6  /datasets/pentschev/miniconda3/envs/gdf/lib/libuct.so.0(+0x20b1f) [0x7fb061899b1f]
 7  /datasets/pentschev/miniconda3/envs/gdf/lib/libuct.so.0(+0x210f4) [0x7fb06189a0f4]
 8  /datasets/pentschev/miniconda3/envs/gdf/lib/libuct.so.0(+0x23548) [0x7fb06189c548]
 9  /datasets/pentschev/miniconda3/envs/gdf/lib/libucs.so.0(ucs_event_set_wait+0xb9) [0x7fb061aef879]
10  /datasets/pentschev/miniconda3/envs/gdf/lib/libuct.so.0(uct_tcp_iface_progress+0x7b) [0x7fb06189c5eb]
11  /datasets/pentschev/miniconda3/envs/gdf/lib/libucp.so.0(ucp_worker_progress+0x6a) [0x7fb061d6a42a]
12  /datasets/pentschev/miniconda3/envs/gdf/lib/python3.9/site-packages/ucp/_libs/ucx_api.cpython-39-x86_64-linux-gnu.so(+0x26c79) [0x7fb07409dc79]
13  /datasets/pentschev/miniconda3/envs/gdf/bin/python(+0x141eca) [0x55e277d30eca]
14  /datasets/pentschev/miniconda3/envs/gdf/bin/python(_PyEval_EvalFrameDefault+0x3d99) [0x55e277d1e549]
15  /datasets/pentschev/miniconda3/envs/gdf/bin/python(+0x12a7d7) [0x55e277d197d7]
16  /datasets/pentschev/miniconda3/envs/gdf/bin/python(_PyFunction_Vectorcall+0xb9) [0x55e277d2bbb9]
17  /datasets/pentschev/miniconda3/envs/gdf/bin/python(_PyEval_EvalFrameDefault+0x672) [0x55e277d1ae22]
18  /datasets/pentschev/miniconda3/envs/gdf/bin/python(+0x13cec3) [0x55e277d2bec3]
19  /datasets/pentschev/miniconda3/envs/gdf/bin/python(+0x14bc75) [0x55e277d3ac75]
20  /datasets/pentschev/miniconda3/envs/gdf/bin/python(+0x264071) [0x55e277e53071]
21  /datasets/pentschev/miniconda3/envs/gdf/bin/python(+0xf7187) [0x55e277ce6187]
22  /datasets/pentschev/miniconda3/envs/gdf/bin/python(+0x133747) [0x55e277d22747]
23  /datasets/pentschev/miniconda3/envs/gdf/bin/python(_PyEval_EvalFrameDefault+0x5f0a) [0x55e277d206ba]
24  /datasets/pentschev/miniconda3/envs/gdf/bin/python(+0x13cec3) [0x55e277d2bec3]
25  /datasets/pentschev/miniconda3/envs/gdf/bin/python(_PyEval_EvalFrameDefault+0x672) [0x55e277d1ae22]
26  /datasets/pentschev/miniconda3/envs/gdf/bin/python(+0x13cec3) [0x55e277d2bec3]
27  /datasets/pentschev/miniconda3/envs/gdf/bin/python(_PyEval_EvalFrameDefault+0x672) [0x55e277d1ae22]
28  /datasets/pentschev/miniconda3/envs/gdf/bin/python(+0x13cec3) [0x55e277d2bec3]
29  /datasets/pentschev/miniconda3/envs/gdf/bin/python(_PyEval_EvalFrameDefault+0x672) [0x55e277d1ae22]
30  /datasets/pentschev/miniconda3/envs/gdf/bin/python(+0x13cec3) [0x55e277d2bec3]
31  /datasets/pentschev/miniconda3/envs/gdf/bin/python(_PyEval_EvalFrameDefault+0x672) [0x55e277d1ae22]
32  /datasets/pentschev/miniconda3/envs/gdf/bin/python(+0x12a7d7) [0x55e277d197d7]
33  /datasets/pentschev/miniconda3/envs/gdf/bin/python(_PyFunction_Vectorcall+0xb9) [0x55e277d2bbb9]
34  /datasets/pentschev/miniconda3/envs/gdf/bin/python(_PyEval_EvalFrameDefault+0x4cbc) [0x55e277d1f46c]
35  /datasets/pentschev/miniconda3/envs/gdf/bin/python(+0x12a7d7) [0x55e277d197d7]
36  /datasets/pentschev/miniconda3/envs/gdf/bin/python(+0x14baf8) [0x55e277d3aaf8]
37  /datasets/pentschev/miniconda3/envs/gdf/bin/python(PyObject_Call+0xb4) [0x55e277d3b254]
38  /datasets/pentschev/miniconda3/envs/gdf/bin/python(+0x21b8b8) [0x55e277e0a8b8]
39  /datasets/pentschev/miniconda3/envs/gdf/bin/python(_PyObject_MakeTpCall+0x347) [0x55e277d23a57]
40  /datasets/pentschev/miniconda3/envs/gdf/bin/python(_PyEval_EvalFrameDefault+0x3d99) [0x55e277d1e549]
41  /datasets/pentschev/miniconda3/envs/gdf/bin/python(+0x13cec3) [0x55e277d2bec3]
42  /datasets/pentschev/miniconda3/envs/gdf/bin/python(+0x14bb91) [0x55e277d3ab91]
43  /datasets/pentschev/miniconda3/envs/gdf/bin/python(_PyEval_EvalFrameDefault+0x3d99) [0x55e277d1e549]
44  /datasets/pentschev/miniconda3/envs/gdf/bin/python(+0x13cec3) [0x55e277d2bec3]
45  /datasets/pentschev/miniconda3/envs/gdf/bin/python(_PyEval_EvalFrameDefault+0x672) [0x55e277d1ae22]
46  /datasets/pentschev/miniconda3/envs/gdf/bin/python(+0x12a7d7) [0x55e277d197d7]
47  /datasets/pentschev/miniconda3/envs/gdf/bin/python(_PyFunction_Vectorcall+0xb9) [0x55e277d2bbb9]
48  /datasets/pentschev/miniconda3/envs/gdf/bin/python(_PyEval_EvalFrameDefault+0x672) [0x55e277d1ae22]
49  /datasets/pentschev/miniconda3/envs/gdf/bin/python(+0x13cec3) [0x55e277d2bec3]
50  /datasets/pentschev/miniconda3/envs/gdf/bin/python(_PyEval_EvalFrameDefault+0x3c3) [0x55e277d1ab73]
51  /datasets/pentschev/miniconda3/envs/gdf/bin/python(+0x12a7d7) [0x55e277d197d7]
52  /datasets/pentschev/miniconda3/envs/gdf/bin/python(_PyFunction_Vectorcall+0xb9) [0x55e277d2bbb9]
53  /datasets/pentschev/miniconda3/envs/gdf/bin/python(_PyEval_EvalFrameDefault+0x11df) [0x55e277d1b98f]
54  /datasets/pentschev/miniconda3/envs/gdf/bin/python(+0x12a7d7) [0x55e277d197d7]
55  /datasets/pentschev/miniconda3/envs/gdf/bin/python(_PyEval_EvalCodeWithName+0x47) [0x55e277d19497]
56  /datasets/pentschev/miniconda3/envs/gdf/bin/python(PyEval_EvalCodeEx+0x39) [0x55e277d19449]
57  /datasets/pentschev/miniconda3/envs/gdf/bin/python(PyEval_EvalCode+0x1b) [0x55e277dd3ddb]
58  /datasets/pentschev/miniconda3/envs/gdf/bin/python(+0x213409) [0x55e277e02409]
59  /datasets/pentschev/miniconda3/envs/gdf/bin/python(+0x20f5a4) [0x55e277dfe5a4]
60  /datasets/pentschev/miniconda3/envs/gdf/bin/python(PyRun_StringFlags+0x9d) [0x55e277df627d]
61  /datasets/pentschev/miniconda3/envs/gdf/bin/python(PyRun_SimpleStringFlags+0x3d) [0x55e277df614d]
=================================
[dgx13:50906:0:50906] Caught signal 11 (Segmentation fault: address not mapped to object at address 0x448)
==== backtrace (tid:  50906) ====
 0  /datasets/pentschev/miniconda3/envs/gdf/lib/libucs.so.0(ucs_handle_error+0x2d4) [0x7fc6782781a4]
 1  /datasets/pentschev/miniconda3/envs/gdf/lib/libucs.so.0(+0x2e37f) [0x7fc67827837f]
 2  /datasets/pentschev/miniconda3/envs/gdf/lib/libucs.so.0(+0x2e6a4) [0x7fc6782786a4]
 3  /lib/x86_64-linux-gnu/libpthread.so.0(+0x12980) [0x7fc6ed917980]
 4  /datasets/pentschev/miniconda3/envs/gdf/lib/libucp.so.0(ucp_mem_type_unpack+0x14) [0x7fc678500e64]
 5  /datasets/pentschev/miniconda3/envs/gdf/lib/libucp.so.0(ucp_rndv_data_handler+0x508) [0x7fc678533358]
 6  /datasets/pentschev/miniconda3/envs/gdf/lib/libuct.so.0(+0x20b1f) [0x7fc67802cb1f]
 7  /datasets/pentschev/miniconda3/envs/gdf/lib/libuct.so.0(+0x210f4) [0x7fc67802d0f4]
 8  /datasets/pentschev/miniconda3/envs/gdf/lib/libuct.so.0(+0x23548) [0x7fc67802f548]
 9  /datasets/pentschev/miniconda3/envs/gdf/lib/libucs.so.0(ucs_event_set_wait+0xb9) [0x7fc678282879]
10  /datasets/pentschev/miniconda3/envs/gdf/lib/libuct.so.0(uct_tcp_iface_progress+0x7b) [0x7fc67802f5eb]
11  /datasets/pentschev/miniconda3/envs/gdf/lib/libucp.so.0(ucp_worker_progress+0x6a) [0x7fc6784fd42a]
12  /datasets/pentschev/miniconda3/envs/gdf/lib/python3.9/site-packages/ucp/_libs/ucx_api.cpython-39-x86_64-linux-gnu.so(+0x26c79) [0x7fc6787b9c79]
13  /datasets/pentschev/miniconda3/envs/gdf/bin/python(+0x141eca) [0x556aac76beca]
14  /datasets/pentschev/miniconda3/envs/gdf/bin/python(_PyEval_EvalFrameDefault+0x3d99) [0x556aac759549]
15  /datasets/pentschev/miniconda3/envs/gdf/bin/python(+0x12a7d7) [0x556aac7547d7]
16  /datasets/pentschev/miniconda3/envs/gdf/bin/python(_PyFunction_Vectorcall+0xb9) [0x556aac766bb9]
17  /datasets/pentschev/miniconda3/envs/gdf/bin/python(_PyEval_EvalFrameDefault+0x672) [0x556aac755e22]
18  /datasets/pentschev/miniconda3/envs/gdf/bin/python(+0x13cec3) [0x556aac766ec3]
19  /datasets/pentschev/miniconda3/envs/gdf/bin/python(+0x14bc75) [0x556aac775c75]
20  /datasets/pentschev/miniconda3/envs/gdf/bin/python(+0x264071) [0x556aac88e071]
21  /datasets/pentschev/miniconda3/envs/gdf/bin/python(+0xf7187) [0x556aac721187]
22  /datasets/pentschev/miniconda3/envs/gdf/bin/python(+0x133747) [0x556aac75d747]
23  /datasets/pentschev/miniconda3/envs/gdf/bin/python(_PyEval_EvalFrameDefault+0x5f0a) [0x556aac75b6ba]
24  /datasets/pentschev/miniconda3/envs/gdf/bin/python(+0x13cec3) [0x556aac766ec3]
25  /datasets/pentschev/miniconda3/envs/gdf/bin/python(_PyEval_EvalFrameDefault+0x672) [0x556aac755e22]
26  /datasets/pentschev/miniconda3/envs/gdf/bin/python(+0x13cec3) [0x556aac766ec3]
27  /datasets/pentschev/miniconda3/envs/gdf/bin/python(_PyEval_EvalFrameDefault+0x672) [0x556aac755e22]
28  /datasets/pentschev/miniconda3/envs/gdf/bin/python(+0x13cec3) [0x556aac766ec3]
29  /datasets/pentschev/miniconda3/envs/gdf/bin/python(_PyEval_EvalFrameDefault+0x672) [0x556aac755e22]
30  /datasets/pentschev/miniconda3/envs/gdf/bin/python(+0x13cec3) [0x556aac766ec3]
31  /datasets/pentschev/miniconda3/envs/gdf/bin/python(_PyEval_EvalFrameDefault+0x672) [0x556aac755e22]
32  /datasets/pentschev/miniconda3/envs/gdf/bin/python(+0x12a7d7) [0x556aac7547d7]
33  /datasets/pentschev/miniconda3/envs/gdf/bin/python(_PyFunction_Vectorcall+0xb9) [0x556aac766bb9]
34  /datasets/pentschev/miniconda3/envs/gdf/bin/python(_PyEval_EvalFrameDefault+0x4cbc) [0x556aac75a46c]
35  /datasets/pentschev/miniconda3/envs/gdf/bin/python(+0x12a7d7) [0x556aac7547d7]
36  /datasets/pentschev/miniconda3/envs/gdf/bin/python(+0x14baf8) [0x556aac775af8]
37  /datasets/pentschev/miniconda3/envs/gdf/bin/python(PyObject_Call+0xb4) [0x556aac776254]
38  /datasets/pentschev/miniconda3/envs/gdf/bin/python(+0x21b8b8) [0x556aac8458b8]
39  /datasets/pentschev/miniconda3/envs/gdf/bin/python(_PyObject_MakeTpCall+0x347) [0x556aac75ea57]
40  /datasets/pentschev/miniconda3/envs/gdf/bin/python(_PyEval_EvalFrameDefault+0x3d99) [0x556aac759549]
41  /datasets/pentschev/miniconda3/envs/gdf/bin/python(+0x13cec3) [0x556aac766ec3]
42  /datasets/pentschev/miniconda3/envs/gdf/bin/python(+0x14bb91) [0x556aac775b91]
43  /datasets/pentschev/miniconda3/envs/gdf/bin/python(_PyEval_EvalFrameDefault+0x3d99) [0x556aac759549]
44  /datasets/pentschev/miniconda3/envs/gdf/bin/python(+0x13cec3) [0x556aac766ec3]
45  /datasets/pentschev/miniconda3/envs/gdf/bin/python(_PyEval_EvalFrameDefault+0x672) [0x556aac755e22]
46  /datasets/pentschev/miniconda3/envs/gdf/bin/python(+0x12a7d7) [0x556aac7547d7]
47  /datasets/pentschev/miniconda3/envs/gdf/bin/python(_PyFunction_Vectorcall+0xb9) [0x556aac766bb9]
48  /datasets/pentschev/miniconda3/envs/gdf/bin/python(_PyEval_EvalFrameDefault+0x672) [0x556aac755e22]
49  /datasets/pentschev/miniconda3/envs/gdf/bin/python(+0x13cec3) [0x556aac766ec3]
50  /datasets/pentschev/miniconda3/envs/gdf/bin/python(_PyEval_EvalFrameDefault+0x3c3) [0x556aac755b73]
51  /datasets/pentschev/miniconda3/envs/gdf/bin/python(+0x12a7d7) [0x556aac7547d7]
52  /datasets/pentschev/miniconda3/envs/gdf/bin/python(_PyFunction_Vectorcall+0xb9) [0x556aac766bb9]
53  /datasets/pentschev/miniconda3/envs/gdf/bin/python(_PyEval_EvalFrameDefault+0x11df) [0x556aac75698f]
54  /datasets/pentschev/miniconda3/envs/gdf/bin/python(+0x12a7d7) [0x556aac7547d7]
55  /datasets/pentschev/miniconda3/envs/gdf/bin/python(_PyEval_EvalCodeWithName+0x47) [0x556aac754497]
56  /datasets/pentschev/miniconda3/envs/gdf/bin/python(PyEval_EvalCodeEx+0x39) [0x556aac754449]
57  /datasets/pentschev/miniconda3/envs/gdf/bin/python(PyEval_EvalCode+0x1b) [0x556aac80eddb]
58  /datasets/pentschev/miniconda3/envs/gdf/bin/python(+0x213409) [0x556aac83d409]
59  /datasets/pentschev/miniconda3/envs/gdf/bin/python(+0x20f5a4) [0x556aac8395a4]
60  /datasets/pentschev/miniconda3/envs/gdf/bin/python(PyRun_StringFlags+0x9d) [0x556aac83127d]
61  /datasets/pentschev/miniconda3/envs/gdf/bin/python(PyRun_SimpleStringFlags+0x3d) [0x556aac83114d]
=================================
2023-01-19 01:00:28,366 - distributed.worker - ERROR - failed during get data with ucx://127.0.0.1:34649 -> ucx://127.0.0.1:51751
Traceback (most recent call last):
  File "/datasets/pentschev/miniconda3/envs/gdf/lib/python3.9/site-packages/distributed/comm/ucx.py", line 333, in write
    await self.ep.send(each_frame)
  File "/datasets/pentschev/miniconda3/envs/gdf/lib/python3.9/site-packages/ucp/core.py", line 650, in send
    return await comm.tag_send(self._ep, buffer, nbytes, tag, name=log)
ucp._libs.exceptions.UCXError: <[Send #007] ep: 0x7f57d2d352c0, tag: 0xd11909bdb0923649, nbytes: 100000000, type: <class 'cudf.core.buffer.buffer.Buffer'>>: Connection reset by remote peer

During handling of the above exception, another exception occurred:

Traceback (most recent call last):
  File "/datasets/pentschev/miniconda3/envs/gdf/lib/python3.9/site-packages/distributed/worker.py", line 1766, in get_data
    compressed = await comm.write(msg, serializers=serializers)
  File "/datasets/pentschev/miniconda3/envs/gdf/lib/python3.9/site-packages/distributed/utils.py", line 741, in wrapper
    return await func(*args, **kwargs)
  File "/datasets/pentschev/miniconda3/envs/gdf/lib/python3.9/site-packages/distributed/comm/ucx.py", line 337, in write
    raise CommClosedError("While writing, the connection was closed")
distributed.comm.core.CommClosedError: While writing, the connection was closed
2023-01-19 01:00:28,366 - distributed.worker - ERROR - Worker stream died during communication: ucx://127.0.0.1:51751
Traceback (most recent call last):
  File "/datasets/pentschev/miniconda3/envs/gdf/lib/python3.9/site-packages/distributed/comm/ucx.py", line 349, in read
    await self.ep.recv(msg)
  File "/datasets/pentschev/miniconda3/envs/gdf/lib/python3.9/site-packages/ucp/core.py", line 725, in recv
    ret = await comm.tag_recv(self._ep, buffer, nbytes, tag, name=log)
ucp._libs.exceptions.UCXCanceled: <[Recv #003] ep: 0x7f57d2d35100, tag: 0x6f182c56ae1b9e3, nbytes: 16, type: <class 'numpy.ndarray'>>: 

During handling of the above exception, another exception occurred:

Traceback (most recent call last):
  File "/datasets/pentschev/miniconda3/envs/gdf/lib/python3.9/site-packages/distributed/worker.py", line 2058, in gather_dep
    response = await get_data_from_worker(
  File "/datasets/pentschev/miniconda3/envs/gdf/lib/python3.9/site-packages/distributed/worker.py", line 2872, in get_data_from_worker
    return await retry_operation(_get_data, operation="get_data_from_worker")
  File "/datasets/pentschev/miniconda3/envs/gdf/lib/python3.9/site-packages/distributed/utils_comm.py", line 419, in retry_operation
    return await retry(
  File "/datasets/pentschev/miniconda3/envs/gdf/lib/python3.9/site-packages/distributed/utils_comm.py", line 404, in retry
    return await coro()
  File "/datasets/pentschev/miniconda3/envs/gdf/lib/python3.9/site-packages/distributed/worker.py", line 2852, in _get_data
    response = await send_recv(
  File "/datasets/pentschev/miniconda3/envs/gdf/lib/python3.9/site-packages/distributed/core.py", line 986, in send_recv
    response = await comm.read(deserializers=deserializers)
  File "/datasets/pentschev/miniconda3/envs/gdf/lib/python3.9/site-packages/distributed/utils.py", line 741, in wrapper
    return await func(*args, **kwargs)
  File "/datasets/pentschev/miniconda3/envs/gdf/lib/python3.9/site-packages/distributed/comm/ucx.py", line 367, in read
    raise CommClosedError(
distributed.comm.core.CommClosedError: Connection closed by writer.
Inner exception: UCXCanceled("<[Recv #003] ep: 0x7f57d2d35100, tag: 0x6f182c56ae1b9e3, nbytes: 16, type: <class 'numpy.ndarray'>>: ")
2023-01-19 01:00:28,366 - distributed.worker - ERROR - Worker stream died during communication: ucx://127.0.0.1:51751
Traceback (most recent call last):
  File "/datasets/pentschev/miniconda3/envs/gdf/lib/python3.9/site-packages/distributed/comm/ucx.py", line 349, in read
    await self.ep.recv(msg)
  File "/datasets/pentschev/miniconda3/envs/gdf/lib/python3.9/site-packages/ucp/core.py", line 725, in recv
    ret = await comm.tag_recv(self._ep, buffer, nbytes, tag, name=log)
ucp._libs.exceptions.UCXCanceled: <[Recv #000] ep: 0x7f1fb40a1100, tag: 0xa2b8a1a540c57fcd, nbytes: 16, type: <class 'numpy.ndarray'>>: 

During handling of the above exception, another exception occurred:

Traceback (most recent call last):
  File "/datasets/pentschev/miniconda3/envs/gdf/lib/python3.9/site-packages/distributed/comm/core.py", line 328, in connect
    handshake = await asyncio.wait_for(comm.read(), time_left())
  File "/datasets/pentschev/miniconda3/envs/gdf/lib/python3.9/asyncio/tasks.py", line 479, in wait_for
    return fut.result()
  File "/datasets/pentschev/miniconda3/envs/gdf/lib/python3.9/site-packages/distributed/utils.py", line 741, in wrapper
    return await func(*args, **kwargs)
  File "/datasets/pentschev/miniconda3/envs/gdf/lib/python3.9/site-packages/distributed/comm/ucx.py", line 367, in read
    raise CommClosedError(
distributed.comm.core.CommClosedError: Connection closed by writer.
Inner exception: UCXCanceled("<[Recv #000] ep: 0x7f1fb40a1100, tag: 0xa2b8a1a540c57fcd, nbytes: 16, type: <class 'numpy.ndarray'>>: ")

The above exception was the direct cause of the following exception:

Traceback (most recent call last):
  File "/datasets/pentschev/miniconda3/envs/gdf/lib/python3.9/site-packages/distributed/worker.py", line 2058, in gather_dep
    response = await get_data_from_worker(
  File "/datasets/pentschev/miniconda3/envs/gdf/lib/python3.9/site-packages/distributed/worker.py", line 2872, in get_data_from_worker
    return await retry_operation(_get_data, operation="get_data_from_worker")
  File "/datasets/pentschev/miniconda3/envs/gdf/lib/python3.9/site-packages/distributed/utils_comm.py", line 419, in retry_operation
    return await retry(
  File "/datasets/pentschev/miniconda3/envs/gdf/lib/python3.9/site-packages/distributed/utils_comm.py", line 404, in retry
    return await coro()
  File "/datasets/pentschev/miniconda3/envs/gdf/lib/python3.9/site-packages/distributed/worker.py", line 2849, in _get_data
    comm = await rpc.connect(worker)
  File "/datasets/pentschev/miniconda3/envs/gdf/lib/python3.9/site-packages/distributed/core.py", line 1439, in connect
    return await connect_attempt
  File "/datasets/pentschev/miniconda3/envs/gdf/lib/python3.9/site-packages/distributed/core.py", line 1375, in _connect
    comm = await connect(
  File "/datasets/pentschev/miniconda3/envs/gdf/lib/python3.9/site-packages/distributed/comm/core.py", line 333, in connect
    raise OSError(
OSError: Timed out during handshake while connecting to ucx://127.0.0.1:51751 after 30 s
2023-01-19 01:00:28,372 - distributed.worker - ERROR - Worker stream died during communication: ucx://127.0.0.1:40237
Traceback (most recent call last):
  File "/datasets/pentschev/miniconda3/envs/gdf/lib/python3.9/site-packages/distributed/comm/ucx.py", line 349, in read
    await self.ep.recv(msg)
  File "/datasets/pentschev/miniconda3/envs/gdf/lib/python3.9/site-packages/ucp/core.py", line 725, in recv
    ret = await comm.tag_recv(self._ep, buffer, nbytes, tag, name=log)
ucp._libs.exceptions.UCXCanceled: <[Recv #003] ep: 0x7f1fb40a1240, tag: 0xf586d6984111f671, nbytes: 16, type: <class 'numpy.ndarray'>>: 

During handling of the above exception, another exception occurred:

Traceback (most recent call last):
  File "/datasets/pentschev/miniconda3/envs/gdf/lib/python3.9/site-packages/distributed/worker.py", line 2058, in gather_dep
    response = await get_data_from_worker(
  File "/datasets/pentschev/miniconda3/envs/gdf/lib/python3.9/site-packages/distributed/worker.py", line 2872, in get_data_from_worker
    return await retry_operation(_get_data, operation="get_data_from_worker")
  File "/datasets/pentschev/miniconda3/envs/gdf/lib/python3.9/site-packages/distributed/utils_comm.py", line 419, in retry_operation
    return await retry(
  File "/datasets/pentschev/miniconda3/envs/gdf/lib/python3.9/site-packages/distributed/utils_comm.py", line 404, in retry
    return await coro()
  File "/datasets/pentschev/miniconda3/envs/gdf/lib/python3.9/site-packages/distributed/worker.py", line 2852, in _get_data
    response = await send_recv(
  File "/datasets/pentschev/miniconda3/envs/gdf/lib/python3.9/site-packages/distributed/core.py", line 986, in send_recv
    response = await comm.read(deserializers=deserializers)
  File "/datasets/pentschev/miniconda3/envs/gdf/lib/python3.9/site-packages/distributed/utils.py", line 741, in wrapper
    return await func(*args, **kwargs)
  File "/datasets/pentschev/miniconda3/envs/gdf/lib/python3.9/site-packages/distributed/comm/ucx.py", line 367, in read
    raise CommClosedError(
distributed.comm.core.CommClosedError: Connection closed by writer.
Inner exception: UCXCanceled("<[Recv #003] ep: 0x7f1fb40a1240, tag: 0xf586d6984111f671, nbytes: 16, type: <class 'numpy.ndarray'>>: ")
2023-01-19 01:00:28,389 - distributed.worker - ERROR - failed during get data with ucx://127.0.0.1:51837 -> ucx://127.0.0.1:40237
Traceback (most recent call last):
  File "/datasets/pentschev/miniconda3/envs/gdf/lib/python3.9/site-packages/distributed/comm/ucx.py", line 333, in write
    await self.ep.send(each_frame)
  File "/datasets/pentschev/miniconda3/envs/gdf/lib/python3.9/site-packages/ucp/core.py", line 650, in send
    return await comm.tag_send(self._ep, buffer, nbytes, tag, name=log)
ucp._libs.exceptions.UCXError: <[Send #007] ep: 0x7feab82d71c0, tag: 0xc8cd171bb0dcd6ab, nbytes: 100000000, type: <class 'cudf.core.buffer.buffer.Buffer'>>: Endpoint timeout

During handling of the above exception, another exception occurred:

Traceback (most recent call last):
  File "/datasets/pentschev/miniconda3/envs/gdf/lib/python3.9/site-packages/distributed/worker.py", line 1766, in get_data
    compressed = await comm.write(msg, serializers=serializers)
  File "/datasets/pentschev/miniconda3/envs/gdf/lib/python3.9/site-packages/distributed/utils.py", line 741, in wrapper
    return await func(*args, **kwargs)
  File "/datasets/pentschev/miniconda3/envs/gdf/lib/python3.9/site-packages/distributed/comm/ucx.py", line 337, in write
    raise CommClosedError("While writing, the connection was closed")
distributed.comm.core.CommClosedError: While writing, the connection was closed
2023-01-19 01:00:28,374 - distributed.worker - ERROR - failed during get data with ucx://127.0.0.1:34649 -> ucx://127.0.0.1:40237
Traceback (most recent call last):
  File "/datasets/pentschev/miniconda3/envs/gdf/lib/python3.9/site-packages/distributed/comm/ucx.py", line 333, in write
    await self.ep.send(each_frame)
  File "/datasets/pentschev/miniconda3/envs/gdf/lib/python3.9/site-packages/ucp/core.py", line 650, in send
    return await comm.tag_send(self._ep, buffer, nbytes, tag, name=log)
ucp._libs.exceptions.UCXError: <[Send #007] ep: 0x7f57d2d35340, tag: 0x90e17d7dfbf6125b, nbytes: 100000000, type: <class 'cudf.core.buffer.buffer.Buffer'>>: Connection reset by remote peer

During handling of the above exception, another exception occurred:

Traceback (most recent call last):
  File "/datasets/pentschev/miniconda3/envs/gdf/lib/python3.9/site-packages/distributed/worker.py", line 1766, in get_data
    compressed = await comm.write(msg, serializers=serializers)
  File "/datasets/pentschev/miniconda3/envs/gdf/lib/python3.9/site-packages/distributed/utils.py", line 741, in wrapper
    return await func(*args, **kwargs)
  File "/datasets/pentschev/miniconda3/envs/gdf/lib/python3.9/site-packages/distributed/comm/ucx.py", line 337, in write
    raise CommClosedError("While writing, the connection was closed")
distributed.comm.core.CommClosedError: While writing, the connection was closed
2023-01-19 01:00:28,426 - distributed.worker - ERROR - Worker stream died during communication: ucx://127.0.0.1:40237
Traceback (most recent call last):
  File "/datasets/pentschev/miniconda3/envs/gdf/lib/python3.9/site-packages/distributed/comm/ucx.py", line 391, in read
    await self.ep.recv(each_frame)
  File "/datasets/pentschev/miniconda3/envs/gdf/lib/python3.9/site-packages/ucp/core.py", line 725, in recv
    ret = await comm.tag_recv(self._ep, buffer, nbytes, tag, name=log)
ucp._libs.exceptions.UCXError: <[Recv #007] ep: 0x7f57d2d35180, tag: 0x83e04d8241d257ea, nbytes: 100000000, type: <class 'rmm._lib.device_buffer.DeviceBuffer'>>: Connection reset by remote peer

During handling of the above exception, another exception occurred:

Traceback (most recent call last):
  File "/datasets/pentschev/miniconda3/envs/gdf/lib/python3.9/site-packages/distributed/worker.py", line 2058, in gather_dep
    response = await get_data_from_worker(
  File "/datasets/pentschev/miniconda3/envs/gdf/lib/python3.9/site-packages/distributed/worker.py", line 2872, in get_data_from_worker
    return await retry_operation(_get_data, operation="get_data_from_worker")
  File "/datasets/pentschev/miniconda3/envs/gdf/lib/python3.9/site-packages/distributed/utils_comm.py", line 419, in retry_operation
    return await retry(
  File "/datasets/pentschev/miniconda3/envs/gdf/lib/python3.9/site-packages/distributed/utils_comm.py", line 404, in retry
    return await coro()
  File "/datasets/pentschev/miniconda3/envs/gdf/lib/python3.9/site-packages/distributed/worker.py", line 2852, in _get_data
    response = await send_recv(
  File "/datasets/pentschev/miniconda3/envs/gdf/lib/python3.9/site-packages/distributed/core.py", line 986, in send_recv
    response = await comm.read(deserializers=deserializers)
  File "/datasets/pentschev/miniconda3/envs/gdf/lib/python3.9/site-packages/distributed/utils.py", line 741, in wrapper
    return await func(*args, **kwargs)
  File "/datasets/pentschev/miniconda3/envs/gdf/lib/python3.9/site-packages/distributed/comm/ucx.py", line 397, in read
    raise CommClosedError(
distributed.comm.core.CommClosedError: Connection closed by writer.
Inner exception: UCXError("<[Recv #007] ep: 0x7f57d2d35180, tag: 0x83e04d8241d257ea, nbytes: 100000000, type: <class 'rmm._lib.device_buffer.DeviceBuffer'>>: Connection reset by remote peer")
2023-01-19 01:00:28,495 - distributed.worker - ERROR - Worker stream died during communication: ucx://127.0.0.1:59415
Traceback (most recent call last):
  File "/datasets/pentschev/miniconda3/envs/gdf/lib/python3.9/site-packages/distributed/comm/ucx.py", line 391, in read
    await self.ep.recv(each_frame)
  File "/datasets/pentschev/miniconda3/envs/gdf/lib/python3.9/site-packages/ucp/core.py", line 725, in recv
    ret = await comm.tag_recv(self._ep, buffer, nbytes, tag, name=log)
ucp._libs.exceptions.UCXCanceled: <[Recv #008] ep: 0x7f57d2d35240, tag: 0xa142cd8e07370483, nbytes: 100000000, type: <class 'rmm._lib.device_buffer.DeviceBuffer'>>: 

During handling of the above exception, another exception occurred:

Traceback (most recent call last):
  File "/datasets/pentschev/miniconda3/envs/gdf/lib/python3.9/site-packages/distributed/worker.py", line 2058, in gather_dep
    response = await get_data_from_worker(
  File "/datasets/pentschev/miniconda3/envs/gdf/lib/python3.9/site-packages/distributed/worker.py", line 2872, in get_data_from_worker
    return await retry_operation(_get_data, operation="get_data_from_worker")
  File "/datasets/pentschev/miniconda3/envs/gdf/lib/python3.9/site-packages/distributed/utils_comm.py", line 419, in retry_operation
    return await retry(
  File "/datasets/pentschev/miniconda3/envs/gdf/lib/python3.9/site-packages/distributed/utils_comm.py", line 404, in retry
    return await coro()
  File "/datasets/pentschev/miniconda3/envs/gdf/lib/python3.9/site-packages/distributed/worker.py", line 2852, in _get_data
    response = await send_recv(
  File "/datasets/pentschev/miniconda3/envs/gdf/lib/python3.9/site-packages/distributed/core.py", line 986, in send_recv
    response = await comm.read(deserializers=deserializers)
  File "/datasets/pentschev/miniconda3/envs/gdf/lib/python3.9/site-packages/distributed/utils.py", line 741, in wrapper
    return await func(*args, **kwargs)
  File "/datasets/pentschev/miniconda3/envs/gdf/lib/python3.9/site-packages/distributed/comm/ucx.py", line 397, in read
    raise CommClosedError(
distributed.comm.core.CommClosedError: Connection closed by writer.
Inner exception: UCXCanceled("<[Recv #008] ep: 0x7f57d2d35240, tag: 0xa142cd8e07370483, nbytes: 100000000, type: <class 'rmm._lib.device_buffer.DeviceBuffer'>>: ")
2023-01-19 01:00:28,499 - distributed.worker - ERROR - failed during get data with ucx://127.0.0.1:55121 -> ucx://127.0.0.1:59415
Traceback (most recent call last):
  File "/datasets/pentschev/miniconda3/envs/gdf/lib/python3.9/site-packages/distributed/comm/ucx.py", line 333, in write
    await self.ep.send(each_frame)
  File "/datasets/pentschev/miniconda3/envs/gdf/lib/python3.9/site-packages/ucp/core.py", line 650, in send
    return await comm.tag_send(self._ep, buffer, nbytes, tag, name=log)
ucp._libs.exceptions.UCXError: <[Send #007] ep: 0x7f1fb40a1300, tag: 0x9022df380e117f76, nbytes: 100000000, type: <class 'cudf.core.buffer.buffer.Buffer'>>: Connection reset by remote peer

During handling of the above exception, another exception occurred:

Traceback (most recent call last):
  File "/datasets/pentschev/miniconda3/envs/gdf/lib/python3.9/site-packages/distributed/worker.py", line 1766, in get_data
    compressed = await comm.write(msg, serializers=serializers)
  File "/datasets/pentschev/miniconda3/envs/gdf/lib/python3.9/site-packages/distributed/utils.py", line 741, in wrapper
    return await func(*args, **kwargs)
  File "/datasets/pentschev/miniconda3/envs/gdf/lib/python3.9/site-packages/distributed/comm/ucx.py", line 337, in write
    raise CommClosedError("While writing, the connection was closed")
distributed.comm.core.CommClosedError: While writing, the connection was closed
2023-01-19 01:00:28,500 - distributed.worker - ERROR - failed during get data with ucx://127.0.0.1:55121 -> ucx://127.0.0.1:54869
Traceback (most recent call last):
  File "/datasets/pentschev/miniconda3/envs/gdf/lib/python3.9/site-packages/distributed/comm/ucx.py", line 333, in write
    await self.ep.send(each_frame)
  File "/datasets/pentschev/miniconda3/envs/gdf/lib/python3.9/site-packages/ucp/core.py", line 650, in send
    return await comm.tag_send(self._ep, buffer, nbytes, tag, name=log)
ucp._libs.exceptions.UCXError: <[Send #007] ep: 0x7f1fb40a1280, tag: 0xcf7f1e1eddc49ee, nbytes: 100000000, type: <class 'cudf.core.buffer.buffer.Buffer'>>: Connection reset by remote peer

During handling of the above exception, another exception occurred:

Traceback (most recent call last):
  File "/datasets/pentschev/miniconda3/envs/gdf/lib/python3.9/site-packages/distributed/worker.py", line 1766, in get_data
    compressed = await comm.write(msg, serializers=serializers)
  File "/datasets/pentschev/miniconda3/envs/gdf/lib/python3.9/site-packages/distributed/utils.py", line 741, in wrapper
    return await func(*args, **kwargs)
  File "/datasets/pentschev/miniconda3/envs/gdf/lib/python3.9/site-packages/distributed/comm/ucx.py", line 337, in write
    raise CommClosedError("While writing, the connection was closed")
distributed.comm.core.CommClosedError: While writing, the connection was closed
2023-01-19 01:00:28,500 - distributed.worker - ERROR - Worker stream died during communication: ucx://127.0.0.1:59415
Traceback (most recent call last):
  File "/datasets/pentschev/miniconda3/envs/gdf/lib/python3.9/site-packages/distributed/comm/ucx.py", line 391, in read
    await self.ep.recv(each_frame)
  File "/datasets/pentschev/miniconda3/envs/gdf/lib/python3.9/site-packages/ucp/core.py", line 725, in recv
    ret = await comm.tag_recv(self._ep, buffer, nbytes, tag, name=log)
ucp._libs.exceptions.UCXError: <[Recv #007] ep: 0x7f1fb40a1140, tag: 0x63ecee5ea6ec0ef4, nbytes: 100000000, type: <class 'rmm._lib.device_buffer.DeviceBuffer'>>: Connection reset by remote peer

During handling of the above exception, another exception occurred:

Traceback (most recent call last):
  File "/datasets/pentschev/miniconda3/envs/gdf/lib/python3.9/site-packages/distributed/worker.py", line 2058, in gather_dep
    response = await get_data_from_worker(
  File "/datasets/pentschev/miniconda3/envs/gdf/lib/python3.9/site-packages/distributed/worker.py", line 2872, in get_data_from_worker
    return await retry_operation(_get_data, operation="get_data_from_worker")
  File "/datasets/pentschev/miniconda3/envs/gdf/lib/python3.9/site-packages/distributed/utils_comm.py", line 419, in retry_operation
    return await retry(
  File "/datasets/pentschev/miniconda3/envs/gdf/lib/python3.9/site-packages/distributed/utils_comm.py", line 404, in retry
    return await coro()
  File "/datasets/pentschev/miniconda3/envs/gdf/lib/python3.9/site-packages/distributed/worker.py", line 2852, in _get_data
    response = await send_recv(
  File "/datasets/pentschev/miniconda3/envs/gdf/lib/python3.9/site-packages/distributed/core.py", line 986, in send_recv
    response = await comm.read(deserializers=deserializers)
  File "/datasets/pentschev/miniconda3/envs/gdf/lib/python3.9/site-packages/distributed/utils.py", line 741, in wrapper
    return await func(*args, **kwargs)
  File "/datasets/pentschev/miniconda3/envs/gdf/lib/python3.9/site-packages/distributed/comm/ucx.py", line 397, in read
    raise CommClosedError(
distributed.comm.core.CommClosedError: Connection closed by writer.
Inner exception: UCXError("<[Recv #007] ep: 0x7f1fb40a1140, tag: 0x63ecee5ea6ec0ef4, nbytes: 100000000, type: <class 'rmm._lib.device_buffer.DeviceBuffer'>>: Connection reset by remote peer")
2023-01-19 01:00:28,501 - distributed.worker - ERROR - Worker stream died during communication: ucx://127.0.0.1:54869
Traceback (most recent call last):
  File "/datasets/pentschev/miniconda3/envs/gdf/lib/python3.9/site-packages/distributed/comm/ucx.py", line 391, in read
    await self.ep.recv(each_frame)
  File "/datasets/pentschev/miniconda3/envs/gdf/lib/python3.9/site-packages/ucp/core.py", line 725, in recv
    ret = await comm.tag_recv(self._ep, buffer, nbytes, tag, name=log)
ucp._libs.exceptions.UCXError: <[Recv #007] ep: 0x7f1fb40a1200, tag: 0x112f49b5e4bf2f4c, nbytes: 100000000, type: <class 'rmm._lib.device_buffer.DeviceBuffer'>>: Connection reset by remote peer

During handling of the above exception, another exception occurred:

Traceback (most recent call last):
  File "/datasets/pentschev/miniconda3/envs/gdf/lib/python3.9/site-packages/distributed/worker.py", line 2058, in gather_dep
    response = await get_data_from_worker(
  File "/datasets/pentschev/miniconda3/envs/gdf/lib/python3.9/site-packages/distributed/worker.py", line 2872, in get_data_from_worker
    return await retry_operation(_get_data, operation="get_data_from_worker")
  File "/datasets/pentschev/miniconda3/envs/gdf/lib/python3.9/site-packages/distributed/utils_comm.py", line 419, in retry_operation
    return await retry(
  File "/datasets/pentschev/miniconda3/envs/gdf/lib/python3.9/site-packages/distributed/utils_comm.py", line 404, in retry
    return await coro()
  File "/datasets/pentschev/miniconda3/envs/gdf/lib/python3.9/site-packages/distributed/worker.py", line 2852, in _get_data
    response = await send_recv(
  File "/datasets/pentschev/miniconda3/envs/gdf/lib/python3.9/site-packages/distributed/core.py", line 986, in send_recv
    response = await comm.read(deserializers=deserializers)
  File "/datasets/pentschev/miniconda3/envs/gdf/lib/python3.9/site-packages/distributed/utils.py", line 741, in wrapper
    return await func(*args, **kwargs)
  File "/datasets/pentschev/miniconda3/envs/gdf/lib/python3.9/site-packages/distributed/comm/ucx.py", line 397, in read
    raise CommClosedError(
distributed.comm.core.CommClosedError: Connection closed by writer.
Inner exception: UCXError("<[Recv #007] ep: 0x7f1fb40a1200, tag: 0x112f49b5e4bf2f4c, nbytes: 100000000, type: <class 'rmm._lib.device_buffer.DeviceBuffer'>>: Connection reset by remote peer")
2023-01-19 01:00:28,506 - distributed.nanny - WARNING - Restarting worker
2023-01-19 01:00:28,565 - distributed.nanny - WARNING - Restarting worker
2023-01-19 01:00:28,582 - distributed.worker - ERROR - Worker stream died during communication: ucx://127.0.0.1:54869
Traceback (most recent call last):
  File "/datasets/pentschev/miniconda3/envs/gdf/lib/python3.9/site-packages/distributed/comm/ucx.py", line 349, in read
    await self.ep.recv(msg)
  File "/datasets/pentschev/miniconda3/envs/gdf/lib/python3.9/site-packages/ucp/core.py", line 725, in recv
    ret = await comm.tag_recv(self._ep, buffer, nbytes, tag, name=log)
ucp._libs.exceptions.UCXCanceled: <[Recv #000] ep: 0x7feab82d7340, tag: 0xad5955d5b4775631, nbytes: 16, type: <class 'numpy.ndarray'>>: 

During handling of the above exception, another exception occurred:

Traceback (most recent call last):
  File "/datasets/pentschev/miniconda3/envs/gdf/lib/python3.9/site-packages/distributed/comm/core.py", line 328, in connect
    handshake = await asyncio.wait_for(comm.read(), time_left())
  File "/datasets/pentschev/miniconda3/envs/gdf/lib/python3.9/asyncio/tasks.py", line 479, in wait_for
    return fut.result()
  File "/datasets/pentschev/miniconda3/envs/gdf/lib/python3.9/site-packages/distributed/utils.py", line 741, in wrapper
    return await func(*args, **kwargs)
  File "/datasets/pentschev/miniconda3/envs/gdf/lib/python3.9/site-packages/distributed/comm/ucx.py", line 367, in read
    raise CommClosedError(
distributed.comm.core.CommClosedError: Connection closed by writer.
Inner exception: UCXCanceled("<[Recv #000] ep: 0x7feab82d7340, tag: 0xad5955d5b4775631, nbytes: 16, type: <class 'numpy.ndarray'>>: ")

The above exception was the direct cause of the following exception:

Traceback (most recent call last):
  File "/datasets/pentschev/miniconda3/envs/gdf/lib/python3.9/site-packages/distributed/worker.py", line 2058, in gather_dep
    response = await get_data_from_worker(
  File "/datasets/pentschev/miniconda3/envs/gdf/lib/python3.9/site-packages/distributed/worker.py", line 2872, in get_data_from_worker
    return await retry_operation(_get_data, operation="get_data_from_worker")
  File "/datasets/pentschev/miniconda3/envs/gdf/lib/python3.9/site-packages/distributed/utils_comm.py", line 419, in retry_operation
    return await retry(
  File "/datasets/pentschev/miniconda3/envs/gdf/lib/python3.9/site-packages/distributed/utils_comm.py", line 404, in retry
    return await coro()
  File "/datasets/pentschev/miniconda3/envs/gdf/lib/python3.9/site-packages/distributed/worker.py", line 2849, in _get_data
    comm = await rpc.connect(worker)
  File "/datasets/pentschev/miniconda3/envs/gdf/lib/python3.9/site-packages/distributed/core.py", line 1439, in connect
    return await connect_attempt
  File "/datasets/pentschev/miniconda3/envs/gdf/lib/python3.9/site-packages/distributed/core.py", line 1375, in _connect
    comm = await connect(
  File "/datasets/pentschev/miniconda3/envs/gdf/lib/python3.9/site-packages/distributed/comm/core.py", line 333, in connect
    raise OSError(
OSError: Timed out during handshake while connecting to ucx://127.0.0.1:54869 after 30 s
2023-01-19 01:00:28,964 - distributed.nanny - WARNING - Restarting worker
2023-01-19 01:00:29,008 - distributed.nanny - WARNING - Restarting worker
2023-01-19 01:00:29,956 - distributed.preloading - INFO - Creating preload: dask_cuda.initialize
2023-01-19 01:00:29,956 - distributed.preloading - INFO - Import preload module: dask_cuda.initialize
2023-01-19 01:00:30,329 - distributed.preloading - INFO - Creating preload: dask_cuda.initialize
2023-01-19 01:00:30,329 - distributed.preloading - INFO - Import preload module: dask_cuda.initialize
2023-01-19 01:00:30,379 - distributed.preloading - INFO - Creating preload: dask_cuda.initialize
2023-01-19 01:00:30,379 - distributed.preloading - INFO - Import preload module: dask_cuda.initialize
2023-01-19 01:00:30,907 - distributed.preloading - INFO - Creating preload: dask_cuda.initialize
2023-01-19 01:00:30,908 - distributed.preloading - INFO - Import preload module: dask_cuda.initialize
2023-01-19 01:00:30,943 - distributed.preloading - INFO - Creating preload: dask_cuda.initialize
2023-01-19 01:00:30,944 - distributed.preloading - INFO - Import preload module: dask_cuda.initialize
2023-01-19 01:00:58,050 - distributed.worker - ERROR - Worker stream died during communication: ucx://127.0.0.1:51751
Traceback (most recent call last):
  File "/datasets/pentschev/miniconda3/envs/gdf/lib/python3.9/site-packages/distributed/comm/ucx.py", line 466, in connect
    ep = await ucp.create_endpoint(ip, port)
  File "/datasets/pentschev/miniconda3/envs/gdf/lib/python3.9/site-packages/ucp/core.py", line 1004, in create_endpoint
    return await _get_ctx().create_endpoint(
  File "/datasets/pentschev/miniconda3/envs/gdf/lib/python3.9/site-packages/ucp/core.py", line 316, in create_endpoint
    peer_info = await exchange_peer_info(
  File "/datasets/pentschev/miniconda3/envs/gdf/lib/python3.9/site-packages/ucp/core.py", line 54, in exchange_peer_info
    await comm.stream_recv(endpoint, peer_info_arr, peer_info_arr.nbytes)
asyncio.exceptions.CancelledError

During handling of the above exception, another exception occurred:

Traceback (most recent call last):
  File "/datasets/pentschev/miniconda3/envs/gdf/lib/python3.9/asyncio/tasks.py", line 490, in wait_for
    return fut.result()
asyncio.exceptions.CancelledError

The above exception was the direct cause of the following exception:

Traceback (most recent call last):
  File "/datasets/pentschev/miniconda3/envs/gdf/lib/python3.9/site-packages/distributed/comm/core.py", line 291, in connect
    comm = await asyncio.wait_for(
  File "/datasets/pentschev/miniconda3/envs/gdf/lib/python3.9/asyncio/tasks.py", line 492, in wait_for
    raise exceptions.TimeoutError() from exc
asyncio.exceptions.TimeoutError

The above exception was the direct cause of the following exception:

Traceback (most recent call last):
  File "/datasets/pentschev/miniconda3/envs/gdf/lib/python3.9/site-packages/distributed/worker.py", line 2058, in gather_dep
    response = await get_data_from_worker(
  File "/datasets/pentschev/miniconda3/envs/gdf/lib/python3.9/site-packages/distributed/worker.py", line 2872, in get_data_from_worker
    return await retry_operation(_get_data, operation="get_data_from_worker")
  File "/datasets/pentschev/miniconda3/envs/gdf/lib/python3.9/site-packages/distributed/utils_comm.py", line 419, in retry_operation
    return await retry(
  File "/datasets/pentschev/miniconda3/envs/gdf/lib/python3.9/site-packages/distributed/utils_comm.py", line 404, in retry
    return await coro()
  File "/datasets/pentschev/miniconda3/envs/gdf/lib/python3.9/site-packages/distributed/worker.py", line 2849, in _get_data
    comm = await rpc.connect(worker)
  File "/datasets/pentschev/miniconda3/envs/gdf/lib/python3.9/site-packages/distributed/core.py", line 1439, in connect
    return await connect_attempt
  File "/datasets/pentschev/miniconda3/envs/gdf/lib/python3.9/site-packages/distributed/core.py", line 1375, in _connect
    comm = await connect(
  File "/datasets/pentschev/miniconda3/envs/gdf/lib/python3.9/site-packages/distributed/comm/core.py", line 317, in connect
    raise OSError(
OSError: Timed out trying to connect to ucx://127.0.0.1:51751 after 30 s
2023-01-19 01:00:58,051 - distributed.worker - ERROR - Worker stream died during communication: ucx://127.0.0.1:59415
Traceback (most recent call last):
  File "/datasets/pentschev/miniconda3/envs/gdf/lib/python3.9/site-packages/distributed/comm/ucx.py", line 466, in connect
    ep = await ucp.create_endpoint(ip, port)
  File "/datasets/pentschev/miniconda3/envs/gdf/lib/python3.9/site-packages/ucp/core.py", line 1004, in create_endpoint
    return await _get_ctx().create_endpoint(
  File "/datasets/pentschev/miniconda3/envs/gdf/lib/python3.9/site-packages/ucp/core.py", line 316, in create_endpoint
    peer_info = await exchange_peer_info(
  File "/datasets/pentschev/miniconda3/envs/gdf/lib/python3.9/site-packages/ucp/core.py", line 54, in exchange_peer_info
    await comm.stream_recv(endpoint, peer_info_arr, peer_info_arr.nbytes)
asyncio.exceptions.CancelledError

During handling of the above exception, another exception occurred:

Traceback (most recent call last):
  File "/datasets/pentschev/miniconda3/envs/gdf/lib/python3.9/asyncio/tasks.py", line 490, in wait_for
    return fut.result()
asyncio.exceptions.CancelledError

The above exception was the direct cause of the following exception:

Traceback (most recent call last):
  File "/datasets/pentschev/miniconda3/envs/gdf/lib/python3.9/site-packages/distributed/comm/core.py", line 291, in connect
    comm = await asyncio.wait_for(
  File "/datasets/pentschev/miniconda3/envs/gdf/lib/python3.9/asyncio/tasks.py", line 492, in wait_for
    raise exceptions.TimeoutError() from exc
asyncio.exceptions.TimeoutError

The above exception was the direct cause of the following exception:

Traceback (most recent call last):
  File "/datasets/pentschev/miniconda3/envs/gdf/lib/python3.9/site-packages/distributed/worker.py", line 2058, in gather_dep
    response = await get_data_from_worker(
  File "/datasets/pentschev/miniconda3/envs/gdf/lib/python3.9/site-packages/distributed/worker.py", line 2872, in get_data_from_worker
    return await retry_operation(_get_data, operation="get_data_from_worker")
  File "/datasets/pentschev/miniconda3/envs/gdf/lib/python3.9/site-packages/distributed/utils_comm.py", line 419, in retry_operation
    return await retry(
  File "/datasets/pentschev/miniconda3/envs/gdf/lib/python3.9/site-packages/distributed/utils_comm.py", line 404, in retry
    return await coro()
  File "/datasets/pentschev/miniconda3/envs/gdf/lib/python3.9/site-packages/distributed/worker.py", line 2849, in _get_data
    comm = await rpc.connect(worker)
  File "/datasets/pentschev/miniconda3/envs/gdf/lib/python3.9/site-packages/distributed/core.py", line 1439, in connect
    return await connect_attempt
  File "/datasets/pentschev/miniconda3/envs/gdf/lib/python3.9/site-packages/distributed/core.py", line 1375, in _connect
    comm = await connect(
  File "/datasets/pentschev/miniconda3/envs/gdf/lib/python3.9/site-packages/distributed/comm/core.py", line 317, in connect
    raise OSError(
OSError: Timed out trying to connect to ucx://127.0.0.1:59415 after 30 s
2023-01-19 01:00:58,051 - distributed.worker - ERROR - Worker stream died during communication: ucx://127.0.0.1:40237
Traceback (most recent call last):
  File "/datasets/pentschev/miniconda3/envs/gdf/lib/python3.9/site-packages/distributed/comm/ucx.py", line 466, in connect
    ep = await ucp.create_endpoint(ip, port)
  File "/datasets/pentschev/miniconda3/envs/gdf/lib/python3.9/site-packages/ucp/core.py", line 1004, in create_endpoint
    return await _get_ctx().create_endpoint(
  File "/datasets/pentschev/miniconda3/envs/gdf/lib/python3.9/site-packages/ucp/core.py", line 316, in create_endpoint
    peer_info = await exchange_peer_info(
  File "/datasets/pentschev/miniconda3/envs/gdf/lib/python3.9/site-packages/ucp/core.py", line 54, in exchange_peer_info
    await comm.stream_recv(endpoint, peer_info_arr, peer_info_arr.nbytes)
asyncio.exceptions.CancelledError

During handling of the above exception, another exception occurred:

Traceback (most recent call last):
  File "/datasets/pentschev/miniconda3/envs/gdf/lib/python3.9/asyncio/tasks.py", line 490, in wait_for
    return fut.result()
asyncio.exceptions.CancelledError

The above exception was the direct cause of the following exception:

Traceback (most recent call last):
  File "/datasets/pentschev/miniconda3/envs/gdf/lib/python3.9/site-packages/distributed/comm/core.py", line 291, in connect
    comm = await asyncio.wait_for(
  File "/datasets/pentschev/miniconda3/envs/gdf/lib/python3.9/asyncio/tasks.py", line 492, in wait_for
    raise exceptions.TimeoutError() from exc
asyncio.exceptions.TimeoutError

The above exception was the direct cause of the following exception:

Traceback (most recent call last):
  File "/datasets/pentschev/miniconda3/envs/gdf/lib/python3.9/site-packages/distributed/worker.py", line 2058, in gather_dep
    response = await get_data_from_worker(
  File "/datasets/pentschev/miniconda3/envs/gdf/lib/python3.9/site-packages/distributed/worker.py", line 2872, in get_data_from_worker
    return await retry_operation(_get_data, operation="get_data_from_worker")
  File "/datasets/pentschev/miniconda3/envs/gdf/lib/python3.9/site-packages/distributed/utils_comm.py", line 419, in retry_operation
    return await retry(
  File "/datasets/pentschev/miniconda3/envs/gdf/lib/python3.9/site-packages/distributed/utils_comm.py", line 404, in retry
    return await coro()
  File "/datasets/pentschev/miniconda3/envs/gdf/lib/python3.9/site-packages/distributed/worker.py", line 2849, in _get_data
    comm = await rpc.connect(worker)
  File "/datasets/pentschev/miniconda3/envs/gdf/lib/python3.9/site-packages/distributed/core.py", line 1439, in connect
    return await connect_attempt
  File "/datasets/pentschev/miniconda3/envs/gdf/lib/python3.9/site-packages/distributed/core.py", line 1375, in _connect
    comm = await connect(
  File "/datasets/pentschev/miniconda3/envs/gdf/lib/python3.9/site-packages/distributed/comm/core.py", line 317, in connect
    raise OSError(
OSError: Timed out trying to connect to ucx://127.0.0.1:40237 after 30 s
/datasets/pentschev/miniconda3/envs/gdf/lib/python3.9/multiprocessing/resource_tracker.py:216: UserWarning: resource_tracker: There appear to be 48 leaked semaphore objects to clean up at shutdown
  warnings.warn('resource_tracker: There appear to be %d '
